Workbook

Sheet Main Page
B2: SCHEDULE OF EVENTS | F2: Links
B3: Time | C3: High School | D3: Middle School | F3: High School Round Robin
B4: 9:45 - 10:00 a.m. CDT | C4: Opening Ceremony | D4: Opening Ceremony | F4: High School Double Elimination
B5: 10:05 - 10:45 a.m. CDT | C5: Round Robin 1 | D5: Round Robin 1 | F5: Middle School Round Robin
B6: 10:45 - 11:15 a.m. CDT | C6: Round Robin 2 | D6: Round Robin 2 | F6: Middle School Swiss
B7: 11:15 - 11:45 a.m. CDT | C7: Round Robin 3 | D7: Round Robin 3 | F7: Round Robin Schedule
B8: 11:45 - 12:15 p.m. CDT | C8: Round Robin 4 | D8: Lunch
B9: 12:15 - 12:45 p.m. CDT | C9: Round Robin 5 | D9: Lunch (Continued)
B10: 12:45 - 1:30 p.m. CDT | C10: Lunch | D10: Swiss 1
B11: 2:00 - 2:30 p.m. CDT | C11: Double Elimination 1 | D11: Swiss 2
B12: 2:30 - 3:00 p.m. CDT | C12: Double Elimination 2 | D12: Swiss 3
B13: 3:00 - 3:30 p.m. CDT | C13: Double Elimination 3 | D13: Swiss 4
B14: 3:30 - 4:00 p.m. CDT | C14: Double Elimination 4 | D14: Swiss 5
B15: 4:00 - 4:30 p.m. CDT | C15: Double Elimination 5 | D15: Break
B16: 4:30 - 5:10 p.m. CDT | C16: Break | D16: Middle School Finals
B17: 5:10 - 5:50 p.m. CDT | C17: Double Elimination 6 | D17: N/A
B18: 5:50 - 6:30 p.m. CDT | C18: Double Elimination 7 | D18: N/A
B19: 6:30 - 7:10 p.m. CDT | C19: Double Elimination 8 | D19: N/A | F19: CLASH Science Bowl
B20: 7:10 - 7:50 p.m. CDT | C20: High School Finals 1 | D20: N/A | F20: Hosted by HUSB
B21: 7:50 - 8:30 p.m. CDT | C21: High School Finals 2 | D21: N/A | F21: Sponsored by IsoBowl
B22: 8:40-8:55 p.m. CDT | C22: Closing Ceremony | D22: Closing Ceremony

Sheet HS RR
B2: BOHR | C2: Collierville HS B | E2: WWPS B | G2: School of Chemistry | I2: Clang! Cloom! Clash! | K2: Round Rock | M2: WWPN | O2: Points | P2: Wins | Q2: Draws | R2: Losses | S2: Score | U2: GALILEO | V2: Benjamin Franklin | X2: Lynbroke | Z2: CCA A | AB2: Re2rement Home | AD2: Wheaton | AF2: Chattahoochee B | AH2: Points | AI2: Wins | AJ2: Draws | AK2: Losses | AL2: Score
B3: Collierville HS B | E3: 34 | F3: =if(E3>C4,"W",if(E3<C4,"L",if(isblank(E3),"","T"))) -> W | G3: 14 | H3: =if(G3>C5,"W",if(G3<C5,"L",if(isblank(G3),"","T"))) -> L | I3: 18 | J3: =if(I3>C6,"W",if(I3<C6,"L",if(isblank(I3),"","T"))) -> L | K3: 52 | L3: =if(K3>C7,"W",if(K3<C7,"L",if(isblank(K3),"","T"))) -> W | M3: -4 | N3: =if(M3>C8,"W",if(M3<C8,"L",if(isblank(C8),"","T"))) -> L | O3: =SUM(C3:N3) -> 114 | P3: =COUNTIF(C3:N3, "*W*") -> 2 | Q3: =COUNTIF(C3:N3, "*T*") -> 0 | R3: =COUNTIF(C3:N3, "*L*") -> 3 | S3: =0.015*SUM(O3:O8)+IF(F3="W",150+E3,IF(F3="T",100+E3,IF(F3="L",IF((C4-E3)<80,80-(C4-E3),0),0)))+IF(H3="W",150+G3,IF(H3="T",100+G3,IF(H3="L",IF((C5-G3)<80,80-(C5-G3),0),0)))+IF(J3="W",150+I3,IF(J3="T",100+I3,IF(J3="L",IF((C6-I3)<80,80-(C6-I3),0),0)))+IF(L3="W",150+K3,IF(L3="T",100+K3,IF(L3="L",IF((C7-K3)<80,80-(C7-K3),0),0)))+IF(N3="W",150+M3,IF(N3="T",100+M3,IF(N3="L",IF((C8-M3)<80,80-(C8-M3),0),0))) -> 421.76 | U3: Benjamin Franklin | X3: 46 | Y3: =if(X3>V4,"W",if(X3<V4,"L",if(isblank(X3),"","T"))) -> L | Z3: 22 | AA3: =if(Z3>V5,"W",if(Z3<V5,"L",if(isblank(Z3),"","T"))) -> L | AB3: 24 | AC3: =if(AB3>V6,"W",if(AB3<V6,"L",if(isblank(AB3),"","T"))) -> L | AD3: 16 | AE3: =if(AD3>V7,"W",if(AD3<V7,"L",if(isblank(AD3),"","T"))) -> L | AF3: 56 | AG3: =if(AF3>V8,"W",if(AF3<V8,"L",if(isblank(V8),"","T"))) -> W | AH3: =SUM(V3:AG3) -> 164 | AI3: =COUNTIF(V3:AG3, "*W*") -> 1 | AJ3: =COUNTIF(V3:AG3, "*T*") -> 0 | AK3: =COUNTIF(V3:AG3, "*L*") -> 4 | AL3: =0.015*SUM(AH3:AH8)+IF(Y3="W",150+X3,IF(Y3="T",100+X3,IF(Y3="L",IF((V4-X3)<80,80-(V4-X3),0),0)))+IF(AA3="W",150+Z3,IF(AA3="T",100+Z3,IF(AA3="L",IF((V5-Z3)<80,80-(V5-Z3),0),0)))+IF(AC3="W",150+AB3,IF(AC3="T",100+AB3,IF(AC3="L",IF((V6-AB3)<80,80-(V6-AB3),0),0)))+IF(AE3="W",150+AD3,IF(AE3="T",100+AD3,IF(AE3="L",IF((V7-AD3)<80,80-(V7-AD3),0),0)))+IF(AG3="W",150+AF3,IF(AG3="T",100+AF3,IF(AG3="L",IF((V8-AF3)<80,80-(V8-AF3),0),0))) -> 251.26
B4: WWPS B | C4: 4 | D4: =if(E3<C4,"W",if(E3>C4,"L",if(isblank(C4),"","T"))) -> L | G4: 14 | H4: =if(G4>E5,"W",if(G4<E5,"L",if(isblank(G4),"","T"))) -> L | I4: 0 | J4: =if(I4>E6,"W",if(I4<E6,"L",if(isblank(I4),"","T"))) -> L | K4: 26 | L4: =if(K4>E7,"W",if(K4<E7,"L",if(isblank(K4),"","T"))) -> W | M4: 4 | N4: =if(M4>E8,"W",if(M4<E8,"L",if(isblank(M4),"","T"))) -> L | O4: =SUM(C4:N4) -> 48 | P4: =COUNTIF(C4:N4, "*W*") -> 1 | Q4: =COUNTIF(C4:N4, "*T*") -> 0 | R4: =COUNTIF(C4:N4, "*L*") -> 4 | S4: =0.015*SUM(O3:O8)+IF(D4="W",150+C4,IF(D4="T",100+C4,IF(D4="L",IF((E3-C4)<80,80-(E3-C4),0),0)))+IF(H4="W",150+G4,IF(H4="T",100+G4,IF(H4="L",IF((E5-G4)<80,80-(E5-G4),0),0)))+IF(J4="W",150+I4,IF(J4="T",100+I4,IF(J4="L",IF((E6-I4)<80,80-(E6-I4),0),0)))+IF(L4="W",150+K4,IF(L4="T",100+K4,IF(L4="L",IF((E7-K4)<80,80-(E7-K4),0),0)))+IF(N4="W",150+M4,IF(N4="T",100+M4,IF(N4="L",IF((E8-M4)<80,80-(E8-M4),0),0))) -> 261.76 | U4: Lynbroke | V4: 118 | W4: =if(X3<V4,"W",if(X3>V4,"L",if(isblank(V4),"","T"))) -> W | Z4: 106 | AA4: =if(Z4>X5,"W",if(Z4<X5,"L",if(isblank(Z4),"","T"))) -> W | AB4: 140 | AC4: =if(AB4>X6,"W",if(AB4<X6,"L",if(isblank(AB4),"","T"))) -> W | AD4: 100 | AE4: =if(AD4>X7,"W",if(AD4<X7,"L",if(isblank(AD4),"","T"))) -> W | AF4: 184 | AG4: =if(AF4>X8,"W",if(AF4<X8,"L",if(isblank(AF4),"","T"))) -> W | AH4: =SUM(V4:AG4) -> 648 | AI4: =COUNTIF(V4:AG4, "*W*") -> 5 | AJ4: =COUNTIF(V4:AG4, "*T*") -> 0 | AK4: =COUNTIF(V4:AG4, "*L*") -> 0 | AL4: =0.015*SUM(AH3:AH8)+IF(W4="W",150+V4,IF(W4="T",100+V4,IF(W4="L",IF((X3-V4)<80,80-(X3-V4),0),0)))+IF(AA4="W",150+Z4,IF(AA4="T",100+Z4,IF(AA4="L",IF((X5-Z4)<80,80-(X5-Z4),0),0)))+IF(AC4="W",150+AB4,IF(AC4="T",100+AB4,IF(AC4="L",IF((X6-AB4)<80,80-(X6-AB4),0),0)))+IF(AE4="W",150+AD4,IF(AE4="T",100+AD4,IF(AE4="L",IF((X7-AD4)<80,80-(X7-AD4),0),0)))+IF(AG4="W",150+AF4,IF(AG4="T",100+AF4,IF(AG4="L",IF((X8-AF4)<80,80-(X8-AF4),0),0))) -> 1435.26
B5: School of Chemistry | C5: 160 | D5: =if(G3<C5,"W",if(G3>C5,"L",if(isblank(C5),"","T"))) -> W | E5: 180 | F5: =if(G4<E5,"W",if(G4>E5,"L",if(isblank(E5),"","T"))) -> W | I5: 42 | J5: =if(I5>G6,"W",if(I5<G6,"L",if(isblank(I5),"","T"))) -> L | K5: 156 | L5: =if(K5>G7,"W",if(K5<G7,"L",if(isblank(K5),"","T"))) -> W | M5: 92 | N5: =if(M5>G8,"W",if(M5<G8,"L",if(isblank(M5),"","T"))) -> L | O5: =SUM(C5:N5) -> 630 | P5: =COUNTIF(C5:N5, "*W*") -> 3 | Q5: =COUNTIF(C5:N5, "*T*") -> 0 | R5: =COUNTIF(C5:N5, "*L*") -> 2 | S5: =0.015*SUM(O3:O8)+IF(D5="W",150+C5,IF(D5="T",100+C5,IF(D5="L",IF((G3-C5)<80,80-(G3-C5),0),0)))+IF(F5="W",150+E5,IF(F5="T",100+E5,IF(F5="L",IF((G4-E5)<80,80-(G4-E5),0),0)))+IF(J5="W",150+I5,IF(J5="T",100+I5,IF(J5="L",IF((G6-I5)<80,80-(G6-I5),0),0)))+IF(L5="W",150+K5,IF(L5="T",100+K5,IF(L5="L",IF((G7-K5)<80,80-(G7-K5),0),0)))+IF(N5="W",150+M5,IF(N5="T",100+M5,IF(N5="L",IF((G8-M5)<80,80-(G8-M5),0),0))) -> 1023.76 | U5: CCA A | V5: 126 | W5: =if(Z3<V5,"W",if(Z3>V5,"L",if(isblank(V5),"","T"))) -> W | X5: 60 | Y5: =if(Z4<X5,"W",if(Z4>X5,"L",if(isblank(X5),"","T"))) -> L | AB5: 42 | AC5: =if(AB5>Z6,"W",if(AB5<Z6,"L",if(isblank(AB5),"","T"))) -> L | AD5: 80 | AE5: =if(AD5>Z7,"W",if(AD5<Z7,"L",if(isblank(AD5),"","T"))) -> L | AF5: 128 | AG5: =if(AF5>Z8,"W",if(AF5<Z8,"L",if(isblank(AF5),"","T"))) -> W | AH5: =SUM(V5:AG5) -> 436 | AI5: =COUNTIF(V5:AG5, "*W*") -> 2 | AJ5: =COUNTIF(V5:AG5, "*T*") -> 0 | AK5: =COUNTIF(V5:AG5, "*L*") -> 3 | AL5: =0.015*SUM(AH3:AH8)+IF(W5="W",150+V5,IF(W5="T",100+V5,IF(W5="L",IF((Z3-V5)<80,80-(Z3-V5),0),0)))+IF(Y5="W",150+X5,IF(Y5="T",100+X5,IF(Y5="L",IF((Z4-X5)<80,80-(Z4-X5),0),0)))+IF(AC5="W",150+AB5,IF(AC5="T",100+AB5,IF(AC5="L",IF((Z6-AB5)<80,80-(Z6-AB5),0),0)))+IF(AE5="W",150+AD5,IF(AE5="T",100+AD5,IF(AE5="L",IF((Z7-AD5)<80,80-(Z7-AD5),0),0)))+IF(AG5="W",150+AF5,IF(AG5="T",100+AF5,IF(AG5="L",IF((Z8-AF5)<80,80-(Z8-AF5),0),0))) -> 717.26
B6: Clang! Cloom! Clash! | C6: 180 | D6: =if(I3<C6,"W",if(I3>C6,"L",if(isblank(C6),"","T"))) -> W | E6: 204 | F6: =if(I4<E6,"W",if(I4>E6,"L",if(isblank(E6),"","T"))) -> W | G6: 170 | H6: =if(I5<G6,"W",if(I5>G6,"L",if(isblank(G6),"","T"))) -> W | K6: 164 | L6: =if(K6>I7,"W",if(K6<I7,"L",if(isblank(K6),"","T"))) -> W | M6: 134 | N6: =if(M6>I8,"W",if(M6<I8,"L",if(isblank(M6),"","T"))) -> W | O6: =SUM(C6:N6) -> 852 | P6: =COUNTIF(C6:N6, "*W*") -> 5 | Q6: =COUNTIF(C6:N6, "*T*") -> 0 | R6: =COUNTIF(C6:N6, "*L*") -> 0 | S6: =0.015*SUM(O3:O8)+IF(D6="W",150+C6,IF(D6="T",100+C6,IF(D6="L",IF((I3-C6)<80,80-(I3-C6),0),0)))+IF(F6="W",150+E6,IF(F6="T",100+E6,IF(F6="L",IF((I4-E6)<80,80-(I4-E6),0),0)))+IF(H6="W",150+G6,IF(H6="T",100+G6,IF(H6="L",IF((I5-G6)<80,80-(I5-G6),0),0)))+IF(L6="W",150+K6,IF(L6="T",100+K6,IF(L6="L",IF((I7-K6)<80,80-(I7-K6),0),0)))+IF(N6="W",150+M6,IF(N6="T",100+M6,IF(N6="L",IF((I8-M6)<80,80-(I8-M6),0),0))) -> 1637.76 | U6: Re2rement Home | V6: 152 | W6: =if(AB3<V6,"W",if(AB3>V6,"L",if(isblank(V6),"","T"))) -> W | X6: 102 | Y6: =if(AB4<X6,"W",if(AB4>X6,"L",if(isblank(X6),"","T"))) -> L | Z6: 104 | AA6: =if(AB5<Z6,"W",if(AB5>Z6,"L",if(isblank(Z6),"","T"))) -> W | AD6: 110 | AE6: =if(AD6>AB7,"W",if(AD6<AB7,"L",if(isblank(AD6),"","T"))) -> W | AF6: 118 | AG6: =if(AF6>AB8,"W",if(AF6<AB8,"L",if(isblank(AF6),"","T"))) -> W | AH6: =SUM(V6:AG6) -> 586 | AI6: =COUNTIF(V6:AG6, "*W*") -> 4 | AJ6: =COUNTIF(V6:AG6, "*T*") -> 0 | AK6: =COUNTIF(V6:AG6, "*L*") -> 1 | AL6: =0.015*SUM(AH3:AH8)+IF(W6="W",150+V6,IF(W6="T",100+V6,IF(W6="L",IF((AB3-V6)<80,80-(AB3-V6),0),0)))+IF(Y6="W",150+X6,IF(Y6="T",100+X6,IF(Y6="L",IF((AB4-X6)<80,80-(AB4-X6),0),0)))+IF(AA6="W",150+Z6,IF(AA6="T",100+Z6,IF(AA6="L",IF((AB5-Z6)<80,80-(AB5-Z6),0),0)))+IF(AE6="W",150+AD6,IF(AE6="T",100+AD6,IF(AE6="L",IF((AB7-AD6)<80,80-(AB7-AD6),0),0)))+IF(AG6="W",150+AF6,IF(AG6="T",100+AF6,IF(AG6="L",IF((AB8-AF6)<80,80-(AB8-AF6),0),0))) -> 1163.26
B7: Round Rock | C7: 0 | D7: =if(K3<C7,"W",if(K3>C7,"L",if(isblank(C7),"","T"))) -> L | E7: 0 | F7: =if(K4<E7,"W",if(K4>E7,"L",if(isblank(E7),"","T"))) -> L | G7: 0 | H7: =if(K5<G7,"W",if(K5>G7,"L",if(isblank(G7),"","T"))) -> L | I7: 22 | J7: =if(K6<I7,"W",if(K6>I7,"L",if(isblank(I7),"","T"))) -> L | M7: 0 | N7: =if(M7>K8,"W",if(M7<K8,"L",if(isblank(M7),"","T"))) -> L | O7: =SUM(C7:N7) -> 22 | P7: =COUNTIF(C7:N7, "*W*") -> 0 | Q7: =COUNTIF(C7:N7, "*T*") -> 0 | R7: =COUNTIF(C7:N7, "*L*") -> 5 | S7: =0.015*SUM(O3:O8)+IF(D7="W",150+C7,IF(D7="T",100+C7,IF(D7="L",IF((K3-C7)<80,80-(K3-C7),0),0)))+IF(F7="W",150+E7,IF(F7="T",100+E7,IF(F7="L",IF((K4-E7)<80,80-(K4-E7),0),0)))+IF(H7="W",150+G7,IF(H7="T",100+G7,IF(H7="L",IF((K5-G7)<80,80-(K5-G7),0),0)))+IF(J7="W",150+I7,IF(J7="T",100+I7,IF(J7="L",IF((K6-I7)<80,80-(K6-I7),0),0)))+IF(N7="W",150+M7,IF(N7="T",100+M7,IF(N7="L",IF((K8-M7)<80,80-(K8-M7),0),0))) -> 117.76 | U7: Wheaton | V7: 156 | W7: =if(AD3<V7,"W",if(AD3>V7,"L",if(isblank(V7),"","T"))) -> W | X7: 88 | Y7: =if(AD4<X7,"W",if(AD4>X7,"L",if(isblank(X7),"","T"))) -> L | Z7: 86 | AA7: =if(AD5<Z7,"W",if(AD5>Z7,"L",if(isblank(Z7),"","T"))) -> W | AB7: 84 | AC7: =if(AD6<AB7,"W",if(AD6>AB7,"L",if(isblank(AB7),"","T"))) -> L | AF7: 160 | AG7: =if(AF7>AD8,"W",if(AF7<AD8,"L",if(isblank(AF7),"","T"))) -> W | AH7: =SUM(V7:AG7) -> 574 | AI7: =COUNTIF(V7:AG7, "*W*") -> 3 | AJ7: =COUNTIF(V7:AG7, "*T*") -> 0 | AK7: =COUNTIF(V7:AG7, "*L*") -> 2 | AL7: =0.015*SUM(AH3:AH8)+IF(W7="W",150+V7,IF(W7="T",100+V7,IF(W7="L",IF((AD3-V7)<80,80-(AD3-V7),0),0)))+IF(Y7="W",150+X7,IF(Y7="T",100+X7,IF(Y7="L",IF((AD4-X7)<80,80-(AD4-X7),0),0)))+IF(AA7="W",150+Z7,IF(AA7="T",100+Z7,IF(AA7="L",IF((AD5-Z7)<80,80-(AD5-Z7),0),0)))+IF(AC7="W",150+AB7,IF(AC7="T",100+AB7,IF(AC7="L",IF((AD6-AB7)<80,80-(AD6-AB7),0),0)))+IF(AG7="W",150+AF7,IF(AG7="T",100+AF7,IF(AG7="L",IF((AD8-AF7)<80,80-(AD8-AF7),0),0))) -> 1011.26
B8: WWPN | C8: 130 | D8: =if(M3<C8,"W",if(M3>C8,"L",if(isblank(C8),"","T"))) -> W | E8: 208 | F8: =if(M4<E8,"W",if(M4>E8,"L",if(isblank(E8),"","T"))) -> W | G8: 130 | H8: =if(M5<G8,"W",if(M5>G8,"L",if(isblank(G8),"","T"))) -> W | I8: 72 | J8: =if(M6<I8,"W",if(M6>I8,"L",if(isblank(I8),"","T"))) -> L | K8: 178 | L8: =if(M7<K8,"W",if(M7>K8,"L",if(isblank(K8),"","T"))) -> W | O8: =SUM(C8:N8) -> 718 | P8: =COUNTIF(C8:N8, "*W*") -> 4 | Q8: =COUNTIF(C8:N8, "*T*") -> 0 | R8: =COUNTIF(C8:N8, "*L*") -> 1 | S8: =0.015*SUM(O3:O8)+IF(D8="W",150+C8,IF(D8="T",100+C8,IF(D8="L",IF((M3-C8)<80,80-(M3-C8),0),0)))+IF(F8="W",150+E8,IF(F8="T",100+E8,IF(F8="L",IF((M4-E8)<80,80-(M4-E8),0),0)))+IF(H8="W",150+G8,IF(H8="T",100+G8,IF(H8="L",IF((M5-G8)<80,80-(M5-G8),0),0)))+IF(J8="W",150+I8,IF(J8="T",100+I8,IF(J8="L",IF((M6-I8)<80,80-(M6-I8),0),0)))+IF(L8="W",150+K8,IF(L8="T",100+K8,IF(L8="L",IF((M7-K8)<80,80-(M7-K8),0),0))) -> 1299.76 | U8: Chattahoochee B | V8: 22 | W8: =if(AF3<V8,"W",if(AF3>V8,"L",if(isblank(V8),"","T"))) -> L | X8: 14 | Y8: =if(AF4<X8,"W",if(AF4>X8,"L",if(isblank(X8),"","T"))) -> L | Z8: 0 | AA8: =if(AF5<Z8,"W",if(AF5>Z8,"L",if(isblank(Z8),"","T"))) -> L | AB8: 40 | AC8: =if(AF6<AB8,"W",if(AF6>AB8,"L",if(isblank(AB8),"","T"))) -> L | AD8: 0 | AE8: =if(AF7<AD8,"W",if(AF7>AD8,"L",if(isblank(AD8),"","T"))) -> L | AH8: =SUM(V8:AG8) -> 76 | AI8: =COUNTIF(V8:AG8, "*W*") -> 0 | AJ8: =COUNTIF(V8:AG8, "*T*") -> 0 | AK8: =COUNTIF(V8:AG8, "*L*") -> 5 | AL8: =0.015*SUM(AH3:AH8)+IF(W8="W",150+V8,IF(W8="T",100+V8,IF(W8="L",IF((AF3-V8)<80,80-(AF3-V8),0),0)))+IF(Y8="W",150+X8,IF(Y8="T",100+X8,IF(Y8="L",IF((AF4-X8)<80,80-(AF4-X8),0),0)))+IF(AA8="W",150+Z8,IF(AA8="T",100+Z8,IF(AA8="L",IF((AF5-Z8)<80,80-(AF5-Z8),0),0)))+IF(AC8="W",150+AB8,IF(AC8="T",100+AB8,IF(AC8="L",IF((AF6-AB8)<80,80-(AF6-AB8),0),0)))+IF(AE8="W",150+AD8,IF(AE8="T",100+AD8,IF(AE8="L",IF((AF7-AD8)<80,80-(AF7-AD8),0),0))) -> 85.26
B10: CURIE | C10: Doral Academy | E10: Palo Alto | G10: Arcadia B | I10: Montgomery Blair | K10: Collierville HS A | M10: VMATHs | O10: Points | P10: Wins | Q10: Draws | R10: Losses | S10: Score | U10: HEISENBERG | V10: ASFA | X10: Punahou | Z10: Royal Hogs | AB10: BISV HS B | AD10: Jordan | AF10: University | AH10: Points | AI10: Wins | AJ10: Draws | AK10: Losses | AL10: Score
B11: Doral Academy | E11: 68 | F11: =if(E11>C12,"W",if(E11<C12,"L",if(isblank(E11),"","T"))) -> L | G11: 78 | H11: =if(G11>C13,"W",if(G11<C13,"L",if(isblank(G11),"","T"))) -> L | I11: 72 | J11: =if(I11>C14,"W",if(I11<C14,"L",if(isblank(I11),"","T"))) -> L | K11: 152 | L11: =if(K11>C15,"W",if(K11<C15,"L",if(isblank(K11),"","T"))) -> W | M11: 106 | N11: =if(M11>C16,"W",if(M11<C16,"L",if(isblank(C16),"","T"))) -> W | O11: =SUM(C11:N11) -> 476 | P11: =COUNTIF(C11:N11, "*W*") -> 2 | Q11: =COUNTIF(C11:N11, "*T*") -> 0 | R11: =COUNTIF(C11:N11, "*L*") -> 3 | S11: =0.015*SUM(O11:O16)+IF(F11="W",150+E11,IF(F11="T",100+E11,IF(F11="L",IF((C12-E11)<80,80-(C12-E11),0),0)))+IF(H11="W",150+G11,IF(H11="T",100+G11,IF(H11="L",IF((C13-G11)<80,80-(C13-G11),0),0)))+IF(J11="W",150+I11,IF(J11="T",100+I11,IF(J11="L",IF((C14-I11)<80,80-(C14-I11),0),0)))+IF(L11="W",150+K11,IF(L11="T",100+K11,IF(L11="L",IF((C15-K11)<80,80-(C15-K11),0),0)))+IF(N11="W",150+M11,IF(N11="T",100+M11,IF(N11="L",IF((C16-M11)<80,80-(C16-M11),0),0))) -> 657.38 | U11: ASFA | X11: 114 | Y11: =if(X11>V12,"W",if(X11<V12,"L",if(isblank(X11),"","T"))) -> W | Z11: 68 | AA11: =if(Z11>V13,"W",if(Z11<V13,"L",if(isblank(Z11),"","T"))) -> L | AB11: 162 | AC11: =if(AB11>V14,"W",if(AB11<V14,"L",if(isblank(AB11),"","T"))) -> W | AD11: 160 | AE11: =if(AD11>V15,"W",if(AD11<V15,"L",if(isblank(AD11),"","T"))) -> W | AF11: 112 | AG11: =if(AF11>V16,"W",if(AF11<V16,"L",if(isblank(V16),"","T"))) -> W | AH11: =SUM(V11:AG11) -> 616 | AI11: =COUNTIF(V11:AG11, "*W*") -> 4 | AJ11: =COUNTIF(V11:AG11, "*T*") -> 0 | AK11: =COUNTIF(V11:AG11, "*L*") -> 1 | AL11: =0.015*SUM(AH11:AH16)+IF(Y11="W",150+X11,IF(Y11="T",100+X11,IF(Y11="L",IF((V12-X11)<80,80-(V12-X11),0),0)))+IF(AA11="W",150+Z11,IF(AA11="T",100+Z11,IF(AA11="L",IF((V13-Z11)<80,80-(V13-Z11),0),0)))+IF(AC11="W",150+AB11,IF(AC11="T",100+AB11,IF(AC11="L",IF((V14-AB11)<80,80-(V14-AB11),0),0)))+IF(AE11="W",150+AD11,IF(AE11="T",100+AD11,IF(AE11="L",IF((V15-AD11)<80,80-(V15-AD11),0),0)))+IF(AG11="W",150+AF11,IF(AG11="T",100+AF11,IF(AG11="L",IF((V16-AF11)<80,80-(V16-AF11),0),0))) -> 1215.33
B12: Palo Alto | C12: 148 | D12: =if(E11<C12,"W",if(E11>C12,"L",if(isblank(C12),"","T"))) -> W | G12: 140 | H12: =if(G12>E13,"W",if(G12<E13,"L",if(isblank(G12),"","T"))) -> W | I12: 90 | J12: =if(I12>E14,"W",if(I12<E14,"L",if(isblank(I12),"","T"))) -> L | K12: 140 | L12: =if(K12>E15,"W",if(K12<E15,"L",if(isblank(K12),"","T"))) -> W | M12: 102 | N12: =if(M12>E16,"W",if(M12<E16,"L",if(isblank(M12),"","T"))) -> T | O12: =SUM(C12:N12) -> 620 | P12: =COUNTIF(C12:N12, "*W*") -> 3 | Q12: =COUNTIF(C12:N12, "*T*") -> 1 | R12: =COUNTIF(C12:N12, "*L*") -> 1 | S12: =0.015*SUM(O11:O16)+IF(D12="W",150+C12,IF(D12="T",100+C12,IF(D12="L",IF((E11-C12)<80,80-(E11-C12),0),0)))+IF(H12="W",150+G12,IF(H12="T",100+G12,IF(H12="L",IF((E13-G12)<80,80-(E13-G12),0),0)))+IF(J12="W",150+I12,IF(J12="T",100+I12,IF(J12="L",IF((E14-I12)<80,80-(E14-I12),0),0)))+IF(L12="W",150+K12,IF(L12="T",100+K12,IF(L12="L",IF((E15-K12)<80,80-(E15-K12),0),0)))+IF(N12="W",150+M12,IF(N12="T",100+M12,IF(N12="L",IF((E16-M12)<80,80-(E16-M12),0),0))) -> 1189.38 | U12: Punahou | V12: 74 | W12: =if(X11<V12,"W",if(X11>V12,"L",if(isblank(V12),"","T"))) -> L | Z12: 82 | AA12: =if(Z12>X13,"W",if(Z12<X13,"L",if(isblank(Z12),"","T"))) -> L | AB12: 120 | AC12: =if(AB12>X14,"W",if(AB12<X14,"L",if(isblank(AB12),"","T"))) -> W | AD12: 56 | AE12: =if(AD12>X15,"W",if(AD12<X15,"L",if(isblank(AD12),"","T"))) -> L | AF12: 42 | AG12: =if(AF12>X16,"W",if(AF12<X16,"L",if(isblank(AF12),"","T"))) -> L | AH12: =SUM(V12:AG12) -> 374 | AI12: =COUNTIF(V12:AG12, "*W*") -> 1 | AJ12: =COUNTIF(V12:AG12, "*T*") -> 0 | AK12: =COUNTIF(V12:AG12, "*L*") -> 4 | AL12: =0.015*SUM(AH11:AH16)+IF(W12="W",150+V12,IF(W12="T",100+V12,IF(W12="L",IF((X11-V12)<80,80-(X11-V12),0),0)))+IF(AA12="W",150+Z12,IF(AA12="T",100+Z12,IF(AA12="L",IF((X13-Z12)<80,80-(X13-Z12),0),0)))+IF(AC12="W",150+AB12,IF(AC12="T",100+AB12,IF(AC12="L",IF((X14-AB12)<80,80-(X14-AB12),0),0)))+IF(AE12="W",150+AD12,IF(AE12="T",100+AD12,IF(AE12="L",IF((X15-AD12)<80,80-(X15-AD12),0),0)))+IF(AG12="W",150+AF12,IF(AG12="T",100+AF12,IF(AG12="L",IF((X16-AF12)<80,80-(X16-AF12),0),0))) -> 473.33
B13: Arcadia B | C13: 106 | D13: =if(G11<C13,"W",if(G11>C13,"L",if(isblank(C13),"","T"))) -> W | E13: 86 | F13: =if(G12<E13,"W",if(G12>E13,"L",if(isblank(E13),"","T"))) -> L | I13: 88 | J13: =if(I13>G14,"W",if(I13<G14,"L",if(isblank(I13),"","T"))) -> L | K13: 164 | L13: =if(K13>G15,"W",if(K13<G15,"L",if(isblank(K13),"","T"))) -> W | M13: 130 | N13: =if(M13>G16,"W",if(M13<G16,"L",if(isblank(M13),"","T"))) -> W | O13: =SUM(C13:N13) -> 574 | P13: =COUNTIF(C13:N13, "*W*") -> 3 | Q13: =COUNTIF(C13:N13, "*T*") -> 0 | R13: =COUNTIF(C13:N13, "*L*") -> 2 | S13: =0.015*SUM(O11:O16)+IF(D13="W",150+C13,IF(D13="T",100+C13,IF(D13="L",IF((G11-C13)<80,80-(G11-C13),0),0)))+IF(F13="W",150+E13,IF(F13="T",100+E13,IF(F13="L",IF((G12-E13)<80,80-(G12-E13),0),0)))+IF(J13="W",150+I13,IF(J13="T",100+I13,IF(J13="L",IF((G14-I13)<80,80-(G14-I13),0),0)))+IF(L13="W",150+K13,IF(L13="T",100+K13,IF(L13="L",IF((G15-K13)<80,80-(G15-K13),0),0)))+IF(N13="W",150+M13,IF(N13="T",100+M13,IF(N13="L",IF((G16-M13)<80,80-(G16-M13),0),0))) -> 981.38 | U13: Royal Hogs | V13: 120 | W13: =if(Z11<V13,"W",if(Z11>V13,"L",if(isblank(V13),"","T"))) -> W | X13: 100 | Y13: =if(Z12<X13,"W",if(Z12>X13,"L",if(isblank(X13),"","T"))) -> W | AB13: 84 | AC13: =if(AB13>Z14,"W",if(AB13<Z14,"L",if(isblank(AB13),"","T"))) -> L | AD13: 164 | AE13: =if(AD13>Z15,"W",if(AD13<Z15,"L",if(isblank(AD13),"","T"))) -> W | AF13: 140 | AG13: =if(AF13>Z16,"W",if(AF13<Z16,"L",if(isblank(AF13),"","T"))) -> W | AH13: =SUM(V13:AG13) -> 608 | AI13: =COUNTIF(V13:AG13, "*W*") -> 4 | AJ13: =COUNTIF(V13:AG13, "*T*") -> 0 | AK13: =COUNTIF(V13:AG13, "*L*") -> 1 | AL13: =0.015*SUM(AH11:AH16)+IF(W13="W",150+V13,IF(W13="T",100+V13,IF(W13="L",IF((Z11-V13)<80,80-(Z11-V13),0),0)))+IF(Y13="W",150+X13,IF(Y13="T",100+X13,IF(Y13="L",IF((Z12-X13)<80,80-(Z12-X13),0),0)))+IF(AC13="W",150+AB13,IF(AC13="T",100+AB13,IF(AC13="L",IF((Z14-AB13)<80,80-(Z14-AB13),0),0)))+IF(AE13="W",150+AD13,IF(AE13="T",100+AD13,IF(AE13="L",IF((Z15-AD13)<80,80-(Z15-AD13),0),0)))+IF(AG13="W",150+AF13,IF(AG13="T",100+AF13,IF(AG13="L",IF((Z16-AF13)<80,80-(Z16-AF13),0),0))) -> 1219.33
B14: Montgomery Blair | C14: 148 | D14: =if(I11<C14,"W",if(I11>C14,"L",if(isblank(C14),"","T"))) -> W | E14: 104 | F14: =if(I12<E14,"W",if(I12>E14,"L",if(isblank(E14),"","T"))) -> W | G14: 106 | H14: =if(I13<G14,"W",if(I13>G14,"L",if(isblank(G14),"","T"))) -> W | K14: 156 | L14: =if(K14>I15,"W",if(K14<I15,"L",if(isblank(K14),"","T"))) -> W | M14: 142 | N14: =if(M14>I16,"W",if(M14<I16,"L",if(isblank(M14),"","T"))) -> W | O14: =SUM(C14:N14) -> 656 | P14: =COUNTIF(C14:N14, "*W*") -> 5 | Q14: =COUNTIF(C14:N14, "*T*") -> 0 | R14: =COUNTIF(C14:N14, "*L*") -> 0 | S14: =0.015*SUM(O11:O16)+IF(D14="W",150+C14,IF(D14="T",100+C14,IF(D14="L",IF((I11-C14)<80,80-(I11-C14),0),0)))+IF(F14="W",150+E14,IF(F14="T",100+E14,IF(F14="L",IF((I12-E14)<80,80-(I12-E14),0),0)))+IF(H14="W",150+G14,IF(H14="T",100+G14,IF(H14="L",IF((I13-G14)<80,80-(I13-G14),0),0)))+IF(L14="W",150+K14,IF(L14="T",100+K14,IF(L14="L",IF((I15-K14)<80,80-(I15-K14),0),0)))+IF(N14="W",150+M14,IF(N14="T",100+M14,IF(N14="L",IF((I16-M14)<80,80-(I16-M14),0),0))) -> 1449.38 | U14: BISV HS B | V14: 38 | W14: =if(AB11<V14,"W",if(AB11>V14,"L",if(isblank(V14),"","T"))) -> L | X14: 36 | Y14: =if(AB12<X14,"W",if(AB12>X14,"L",if(isblank(X14),"","T"))) -> L | Z14: 108 | AA14: =if(AB13<Z14,"W",if(AB13>Z14,"L",if(isblank(Z14),"","T"))) -> W | AD14: 90 | AE14: =if(AD14>AB15,"W",if(AD14<AB15,"L",if(isblank(AD14),"","T"))) -> W | AF14: 6 | AG14: =if(AF14>AB16,"W",if(AF14<AB16,"L",if(isblank(AF14),"","T"))) -> L | AH14: =SUM(V14:AG14) -> 278 | AI14: =COUNTIF(V14:AG14, "*W*") -> 2 | AJ14: =COUNTIF(V14:AG14, "*T*") -> 0 | AK14: =COUNTIF(V14:AG14, "*L*") -> 3 | AL14: =0.015*SUM(AH11:AH16)+IF(W14="W",150+V14,IF(W14="T",100+V14,IF(W14="L",IF((AB11-V14)<80,80-(AB11-V14),0),0)))+IF(Y14="W",150+X14,IF(Y14="T",100+X14,IF(Y14="L",IF((AB12-X14)<80,80-(AB12-X14),0),0)))+IF(AA14="W",150+Z14,IF(AA14="T",100+Z14,IF(AA14="L",IF((AB13-Z14)<80,80-(AB13-Z14),0),0)))+IF(AE14="W",150+AD14,IF(AE14="T",100+AD14,IF(AE14="L",IF((AB15-AD14)<80,80-(AB15-AD14),0),0)))+IF(AG14="W",150+AF14,IF(AG14="T",100+AF14,IF(AG14="L",IF((AB16-AF14)<80,80-(AB16-AF14),0),0))) -> 537.33
B15: Collierville HS A | C15: 36 | D15: =if(K11<C15,"W",if(K11>C15,"L",if(isblank(C15),"","T"))) -> L | E15: 8 | F15: =if(K12<E15,"W",if(K12>E15,"L",if(isblank(E15),"","T"))) -> L | G15: 28 | H15: =if(K13<G15,"W",if(K13>G15,"L",if(isblank(G15),"","T"))) -> L | I15: 36 | J15: =if(K14<I15,"W",if(K14>I15,"L",if(isblank(I15),"","T"))) -> L | M15: 44 | N15: =if(M15>K16,"W",if(M15<K16,"L",if(isblank(M15),"","T"))) -> L | O15: =SUM(C15:N15) -> 152 | P15: =COUNTIF(C15:N15, "*W*") -> 0 | Q15: =COUNTIF(C15:N15, "*T*") -> 0 | R15: =COUNTIF(C15:N15, "*L*") -> 5 | S15: =0.015*SUM(O11:O16)+IF(D15="W",150+C15,IF(D15="T",100+C15,IF(D15="L",IF((K11-C15)<80,80-(K11-C15),0),0)))+IF(F15="W",150+E15,IF(F15="T",100+E15,IF(F15="L",IF((K12-E15)<80,80-(K12-E15),0),0)))+IF(H15="W",150+G15,IF(H15="T",100+G15,IF(H15="L",IF((K13-G15)<80,80-(K13-G15),0),0)))+IF(J15="W",150+I15,IF(J15="T",100+I15,IF(J15="L",IF((K14-I15)<80,80-(K14-I15),0),0)))+IF(N15="W",150+M15,IF(N15="T",100+M15,IF(N15="L",IF((K16-M15)<80,80-(K16-M15),0),0))) -> 43.38 | U15: Jordan | V15: 16 | W15: =if(AD11<V15,"W",if(AD11>V15,"L",if(isblank(V15),"","T"))) -> L | X15: 74 | Y15: =if(AD12<X15,"W",if(AD12>X15,"L",if(isblank(X15),"","T"))) -> W | Z15: 48 | AA15: =if(AD13<Z15,"W",if(AD13>Z15,"L",if(isblank(Z15),"","T"))) -> L | AB15: 40 | AC15: =if(AD14<AB15,"W",if(AD14>AB15,"L",if(isblank(AB15),"","T"))) -> L | AF15: 14 | AG15: =if(AF15>AD16,"W",if(AF15<AD16,"L",if(isblank(AF15),"","T"))) -> L | AH15: =SUM(V15:AG15) -> 192 | AI15: =COUNTIF(V15:AG15, "*W*") -> 1 | AJ15: =COUNTIF(V15:AG15, "*T*") -> 0 | AK15: =COUNTIF(V15:AG15, "*L*") -> 4 | AL15: =0.015*SUM(AH11:AH16)+IF(W15="W",150+V15,IF(W15="T",100+V15,IF(W15="L",IF((AD11-V15)<80,80-(AD11-V15),0),0)))+IF(Y15="W",150+X15,IF(Y15="T",100+X15,IF(Y15="L",IF((AD12-X15)<80,80-(AD12-X15),0),0)))+IF(AA15="W",150+Z15,IF(AA15="T",100+Z15,IF(AA15="L",IF((AD13-Z15)<80,80-(AD13-Z15),0),0)))+IF(AC15="W",150+AB15,IF(AC15="T",100+AB15,IF(AC15="L",IF((AD14-AB15)<80,80-(AD14-AB15),0),0)))+IF(AG15="W",150+AF15,IF(AG15="T",100+AF15,IF(AG15="L",IF((AD16-AF15)<80,80-(AD16-AF15),0),0))) -> 293.33
B16: VMATHs | C16: 68 | D16: =if(M11<C16,"W",if(M11>C16,"L",if(isblank(C16),"","T"))) -> L | E16: 102 | F16: =if(M12<E16,"W",if(M12>E16,"L",if(isblank(E16),"","T"))) -> T | G16: 58 | H16: =if(M13<G16,"W",if(M13>G16,"L",if(isblank(G16),"","T"))) -> L | I16: 38 | J16: =if(M14<I16,"W",if(M14>I16,"L",if(isblank(I16),"","T"))) -> L | K16: 148 | L16: =if(M15<K16,"W",if(M15>K16,"L",if(isblank(K16),"","T"))) -> W | O16: =SUM(C16:N16) -> 414 | P16: =COUNTIF(C16:N16, "*W*") -> 1 | Q16: =COUNTIF(C16:N16, "*T*") -> 1 | R16: =COUNTIF(C16:N16, "*L*") -> 3 | S16: =0.015*SUM(O11:O16)+IF(D16="W",150+C16,IF(D16="T",100+C16,IF(D16="L",IF((M11-C16)<80,80-(M11-C16),0),0)))+IF(F16="W",150+E16,IF(F16="T",100+E16,IF(F16="L",IF((M12-E16)<80,80-(M12-E16),0),0)))+IF(H16="W",150+G16,IF(H16="T",100+G16,IF(H16="L",IF((M13-G16)<80,80-(M13-G16),0),0)))+IF(J16="W",150+I16,IF(J16="T",100+I16,IF(J16="L",IF((M14-I16)<80,80-(M14-I16),0),0)))+IF(L16="W",150+K16,IF(L16="T",100+K16,IF(L16="L",IF((M15-K16)<80,80-(M15-K16),0),0))) -> 593.38 | U16: University | V16: -4 | W16: =if(AF11<V16,"W",if(AF11>V16,"L",if(isblank(V16),"","T"))) -> L | X16: 172 | Y16: =if(AF12<X16,"W",if(AF12>X16,"L",if(isblank(X16),"","T"))) -> W | Z16: 40 | AA16: =if(AF13<Z16,"W",if(AF13>Z16,"L",if(isblank(Z16),"","T"))) -> L | AB16: 190 | AC16: =if(AF14<AB16,"W",if(AF14>AB16,"L",if(isblank(AB16),"","T"))) -> W | AD16: 156 | AE16: =if(AF15<AD16,"W",if(AF15>AD16,"L",if(isblank(AD16),"","T"))) -> W | AH16: =SUM(V16:AG16) -> 554 | AI16: =COUNTIF(V16:AG16, "*W*") -> 3 | AJ16: =COUNTIF(V16:AG16, "*T*") -> 0 | AK16: =COUNTIF(V16:AG16, "*L*") -> 2 | AL16: =0.015*SUM(AH11:AH16)+IF(W16="W",150+V16,IF(W16="T",100+V16,IF(W16="L",IF((AF11-V16)<80,80-(AF11-V16),0),0)))+IF(Y16="W",150+X16,IF(Y16="T",100+X16,IF(Y16="L",IF((AF12-X16)<80,80-(AF12-X16),0),0)))+IF(AA16="W",150+Z16,IF(AA16="T",100+Z16,IF(AA16="L",IF((AF13-Z16)<80,80-(AF13-Z16),0),0)))+IF(AC16="W",150+AB16,IF(AC16="T",100+AB16,IF(AC16="L",IF((AF14-AB16)<80,80-(AF14-AB16),0),0)))+IF(AE16="W",150+AD16,IF(AE16="T",100+AD16,IF(AE16="L",IF((AF15-AD16)<80,80-(AF15-AD16),0),0))) -> 1007.33
B18: DIRAC | C18: Enloe | E18: Shallow Walk A | G18: Chattahoochee A | I18: Middleton | K18: Gargy Bomy | M18: BISV HS A | O18: Points | P18: Wins | Q18: Draws | R18: Losses | S18: Score | U18: LAVOISIER | V18: MAAOC | X18: SSP Warriors | Z18: MSJ A | AB18: Foothill | AD18: WWPS A | AF18: SGVG | AH18: Points | AI18: Wins | AJ18: Draws | AK18: Losses | AL18: Score
B19: Enloe | E19: 4 | F19: =if(E19>C20,"W",if(E19<C20,"L",if(isblank(E19),"","T"))) -> L | G19: 90 | H19: =if(G19>C21,"W",if(G19<C21,"L",if(isblank(G19),"","T"))) -> T | I19: 82 | J19: =if(I19>C22,"W",if(I19<C22,"L",if(isblank(I19),"","T"))) -> L | K19: 94 | L19: =if(K19>C23,"W",if(K19<C23,"L",if(isblank(K19),"","T"))) -> W | M19: 68 | N19: =if(M19>C24,"W",if(M19<C24,"L",if(isblank(C24),"","T"))) -> W | O19: =SUM(C19:N19) -> 338 | P19: =COUNTIF(C19:N19, "*W*") -> 2 | Q19: =COUNTIF(C19:N19, "*T*") -> 1 | R19: =COUNTIF(C19:N19, "*L*") -> 2 | S19: =0.015*SUM(O19:O24)+IF(F19="W",150+E19,IF(F19="T",100+E19,IF(F19="L",IF((C20-E19)<80,80-(C20-E19),0),0)))+IF(H19="W",150+G19,IF(H19="T",100+G19,IF(H19="L",IF((C21-G19)<80,80-(C21-G19),0),0)))+IF(J19="W",150+I19,IF(J19="T",100+I19,IF(J19="L",IF((C22-I19)<80,80-(C22-I19),0),0)))+IF(L19="W",150+K19,IF(L19="T",100+K19,IF(L19="L",IF((C23-K19)<80,80-(C23-K19),0),0)))+IF(N19="W",150+M19,IF(N19="T",100+M19,IF(N19="L",IF((C24-M19)<80,80-(C24-M19),0),0))) -> 765.46 | U19: MAAOC | X19: 194 | Y19: =if(X19>V20,"W",if(X19<V20,"L",if(isblank(X19),"","T"))) -> W | Z19: 108 | AA19: =if(Z19>V21,"W",if(Z19<V21,"L",if(isblank(Z19),"","T"))) -> W | AB19: 242 | AC19: =if(AB19>V22,"W",if(AB19<V22,"L",if(isblank(AB19),"","T"))) -> W | AD19: 126 | AE19: =if(AD19>V23,"W",if(AD19<V23,"L",if(isblank(AD19),"","T"))) -> W | AF19: 156 | AG19: =if(AF19>V24,"W",if(AF19<V24,"L",if(isblank(V24),"","T"))) -> W | AH19: =SUM(V19:AG19) -> 826 | AI19: =COUNTIF(V19:AG19, "*W*") -> 5 | AJ19: =COUNTIF(V19:AG19, "*T*") -> 0 | AK19: =COUNTIF(V19:AG19, "*L*") -> 0 | AL19: =0.015*SUM(AH19:AH24)+IF(Y19="W",150+X19,IF(Y19="T",100+X19,IF(Y19="L",IF((V20-X19)<80,80-(V20-X19),0),0)))+IF(AA19="W",150+Z19,IF(AA19="T",100+Z19,IF(AA19="L",IF((V21-Z19)<80,80-(V21-Z19),0),0)))+IF(AC19="W",150+AB19,IF(AC19="T",100+AB19,IF(AC19="L",IF((V22-AB19)<80,80-(V22-AB19),0),0)))+IF(AE19="W",150+AD19,IF(AE19="T",100+AD19,IF(AE19="L",IF((V23-AD19)<80,80-(V23-AD19),0),0)))+IF(AG19="W",150+AF19,IF(AG19="T",100+AF19,IF(AG19="L",IF((V24-AF19)<80,80-(V24-AF19),0),0))) -> 1614.52
B20: Shallow Walk A | C20: 196 | D20: =if(E19<C20,"W",if(E19>C20,"L",if(isblank(C20),"","T"))) -> W | G20: 148 | H20: =if(G20>E21,"W",if(G20<E21,"L",if(isblank(G20),"","T"))) -> W | I20: 190 | J20: =if(I20>E22,"W",if(I20<E22,"L",if(isblank(I20),"","T"))) -> W | K20: 84 | L20: =if(K20>E23,"W",if(K20<E23,"L",if(isblank(K20),"","T"))) -> W | M20: 130 | N20: =if(M20>E24,"W",if(M20<E24,"L",if(isblank(M20),"","T"))) -> W | O20: =SUM(C20:N20) -> 748 | P20: =COUNTIF(C20:N20, "*W*") -> 5 | Q20: =COUNTIF(C20:N20, "*T*") -> 0 | R20: =COUNTIF(C20:N20, "*L*") -> 0 | S20: =0.015*SUM(O19:O24)+IF(D20="W",150+C20,IF(D20="T",100+C20,IF(D20="L",IF((E19-C20)<80,80-(E19-C20),0),0)))+IF(H20="W",150+G20,IF(H20="T",100+G20,IF(H20="L",IF((E21-G20)<80,80-(E21-G20),0),0)))+IF(J20="W",150+I20,IF(J20="T",100+I20,IF(J20="L",IF((E22-I20)<80,80-(E22-I20),0),0)))+IF(L20="W",150+K20,IF(L20="T",100+K20,IF(L20="L",IF((E23-K20)<80,80-(E23-K20),0),0)))+IF(N20="W",150+M20,IF(N20="T",100+M20,IF(N20="L",IF((E24-M20)<80,80-(E24-M20),0),0))) -> 1533.46 | U20: SSP Warriors | V20: 16 | W20: =if(X19<V20,"W",if(X19>V20,"L",if(isblank(V20),"","T"))) -> L | Z20: 10 | AA20: =if(Z20>X21,"W",if(Z20<X21,"L",if(isblank(Z20),"","T"))) -> L | AB20: 10 | AC20: =if(AB20>X22,"W",if(AB20<X22,"L",if(isblank(AB20),"","T"))) -> L | AD20: 20 | AE20: =if(AD20>X23,"W",if(AD20<X23,"L",if(isblank(AD20),"","T"))) -> L | AF20: 38 | AG20: =if(AF20>X24,"W",if(AF20<X24,"L",if(isblank(AF20),"","T"))) -> L | AH20: =SUM(V20:AG20) -> 94 | AI20: =COUNTIF(V20:AG20, "*W*") -> 0 | AJ20: =COUNTIF(V20:AG20, "*T*") -> 0 | AK20: =COUNTIF(V20:AG20, "*L*") -> 5 | AL20: =0.015*SUM(AH19:AH24)+IF(W20="W",150+V20,IF(W20="T",100+V20,IF(W20="L",IF((X19-V20)<80,80-(X19-V20),0),0)))+IF(AA20="W",150+Z20,IF(AA20="T",100+Z20,IF(AA20="L",IF((X21-Z20)<80,80-(X21-Z20),0),0)))+IF(AC20="W",150+AB20,IF(AC20="T",100+AB20,IF(AC20="L",IF((X22-AB20)<80,80-(X22-AB20),0),0)))+IF(AE20="W",150+AD20,IF(AE20="T",100+AD20,IF(AE20="L",IF((X23-AD20)<80,80-(X23-AD20),0),0)))+IF(AG20="W",150+AF20,IF(AG20="T",100+AF20,IF(AG20="L",IF((X24-AF20)<80,80-(X24-AF20),0),0))) -> 82.52
B21: Chattahoochee A | C21: 90 | D21: =if(G19<C21,"W",if(G19>C21,"L",if(isblank(C21),"","T"))) -> T | E21: 22 | F21: =if(G20<E21,"W",if(G20>E21,"L",if(isblank(E21),"","T"))) -> L | I21: 56 | J21: =if(I21>G22,"W",if(I21<G22,"L",if(isblank(I21),"","T"))) -> T | K21: 40 | L21: =if(K21>G23,"W",if(K21<G23,"L",if(isblank(K21),"","T"))) -> L | M21: 74 | N21: =if(M21>G24,"W",if(M21<G24,"L",if(isblank(M21),"","T"))) -> L | O21: =SUM(C21:N21) -> 282 | P21: =COUNTIF(C21:N21, "*W*") -> 0 | Q21: =COUNTIF(C21:N21, "*T*") -> 2 | R21: =COUNTIF(C21:N21, "*L*") -> 3 | S21: =0.015*SUM(O19:O24)+IF(D21="W",150+C21,IF(D21="T",100+C21,IF(D21="L",IF((G19-C21)<80,80-(G19-C21),0),0)))+IF(F21="W",150+E21,IF(F21="T",100+E21,IF(F21="L",IF((G20-E21)<80,80-(G20-E21),0),0)))+IF(J21="W",150+I21,IF(J21="T",100+I21,IF(J21="L",IF((G22-I21)<80,80-(G22-I21),0),0)))+IF(L21="W",150+K21,IF(L21="T",100+K21,IF(L21="L",IF((G23-K21)<80,80-(G23-K21),0),0)))+IF(N21="W",150+M21,IF(N21="T",100+M21,IF(N21="L",IF((G24-M21)<80,80-(G24-M21),0),0))) -> 493.46 | U21: MSJ A | V21: 98 | W21: =if(Z19<V21,"W",if(Z19>V21,"L",if(isblank(V21),"","T"))) -> L | X21: 138 | Y21: =if(Z20<X21,"W",if(Z20>X21,"L",if(isblank(X21),"","T"))) -> W | AB21: 90 | AC21: =if(AB21>Z22,"W",if(AB21<Z22,"L",if(isblank(AB21),"","T"))) -> W | AD21: 78 | AE21: =if(AD21>Z23,"W",if(AD21<Z23,"L",if(isblank(AD21),"","T"))) -> L | AF21: 182 | AG21: =if(AF21>Z24,"W",if(AF21<Z24,"L",if(isblank(AF21),"","T"))) -> W | AH21: =SUM(V21:AG21) -> 586 | AI21: =COUNTIF(V21:AG21, "*W*") -> 3 | AJ21: =COUNTIF(V21:AG21, "*T*") -> 0 | AK21: =COUNTIF(V21:AG21, "*L*") -> 2 | AL21: =0.015*SUM(AH19:AH24)+IF(W21="W",150+V21,IF(W21="T",100+V21,IF(W21="L",IF((Z19-V21)<80,80-(Z19-V21),0),0)))+IF(Y21="W",150+X21,IF(Y21="T",100+X21,IF(Y21="L",IF((Z20-X21)<80,80-(Z20-X21),0),0)))+IF(AC21="W",150+AB21,IF(AC21="T",100+AB21,IF(AC21="L",IF((Z22-AB21)<80,80-(Z22-AB21),0),0)))+IF(AE21="W",150+AD21,IF(AE21="T",100+AD21,IF(AE21="L",IF((Z23-AD21)<80,80-(Z23-AD21),0),0)))+IF(AG21="W",150+AF21,IF(AG21="T",100+AF21,IF(AG21="L",IF((Z24-AF21)<80,80-(Z24-AF21),0),0))) -> 1006.52
B22: Middleton | C22: 84 | D22: =if(I19<C22,"W",if(I19>C22,"L",if(isblank(C22),"","T"))) -> W | E22: 6 | F22: =if(I20<E22,"W",if(I20>E22,"L",if(isblank(E22),"","T"))) -> L | G22: 56 | H22: =if(I21<G22,"W",if(I21>G22,"L",if(isblank(G22),"","T"))) -> T | K22: 64 | L22: =if(K22>I23,"W",if(K22<I23,"L",if(isblank(K22),"","T"))) -> L | M22: 42 | N22: =if(M22>I24,"W",if(M22<I24,"L",if(isblank(M22),"","T"))) -> L | O22: =SUM(C22:N22) -> 252 | P22: =COUNTIF(C22:N22, "*W*") -> 1 | Q22: =COUNTIF(C22:N22, "*T*") -> 1 | R22: =COUNTIF(C22:N22, "*L*") -> 3 | S22: =0.015*SUM(O19:O24)+IF(D22="W",150+C22,IF(D22="T",100+C22,IF(D22="L",IF((I19-C22)<80,80-(I19-C22),0),0)))+IF(F22="W",150+E22,IF(F22="T",100+E22,IF(F22="L",IF((I20-E22)<80,80-(I20-E22),0),0)))+IF(H22="W",150+G22,IF(H22="T",100+G22,IF(H22="L",IF((I21-G22)<80,80-(I21-G22),0),0)))+IF(L22="W",150+K22,IF(L22="T",100+K22,IF(L22="L",IF((I23-K22)<80,80-(I23-K22),0),0)))+IF(N22="W",150+M22,IF(N22="T",100+M22,IF(N22="L",IF((I24-M22)<80,80-(I24-M22),0),0))) -> 513.46 | U22: Foothill | V22: -6 | W22: =if(AB19<V22,"W",if(AB19>V22,"L",if(isblank(V22),"","T"))) -> L | X22: 74 | Y22: =if(AB20<X22,"W",if(AB20>X22,"L",if(isblank(X22),"","T"))) -> W | Z22: 78 | AA22: =if(AB21<Z22,"W",if(AB21>Z22,"L",if(isblank(Z22),"","T"))) -> L | AD22: 36 | AE22: =if(AD22>AB23,"W",if(AD22<AB23,"L",if(isblank(AD22),"","T"))) -> L | AF22: 40 | AG22: =if(AF22>AB24,"W",if(AF22<AB24,"L",if(isblank(AF22),"","T"))) -> L | AH22: =SUM(V22:AG22) -> 222 | AI22: =COUNTIF(V22:AG22, "*W*") -> 1 | AJ22: =COUNTIF(V22:AG22, "*T*") -> 0 | AK22: =COUNTIF(V22:AG22, "*L*") -> 4 | AL22: =0.015*SUM(AH19:AH24)+IF(W22="W",150+V22,IF(W22="T",100+V22,IF(W22="L",IF((AB19-V22)<80,80-(AB19-V22),0),0)))+IF(Y22="W",150+X22,IF(Y22="T",100+X22,IF(Y22="L",IF((AB20-X22)<80,80-(AB20-X22),0),0)))+IF(AA22="W",150+Z22,IF(AA22="T",100+Z22,IF(AA22="L",IF((AB21-Z22)<80,80-(AB21-Z22),0),0)))+IF(AE22="W",150+AD22,IF(AE22="T",100+AD22,IF(AE22="L",IF((AB23-AD22)<80,80-(AB23-AD22),0),0)))+IF(AG22="W",150+AF22,IF(AG22="T",100+AF22,IF(AG22="L",IF((AB24-AF22)<80,80-(AB24-AF22),0),0))) -> 370.52
B23: Gargy Bomy | C23: 88 | D23: =if(K19<C23,"W",if(K19>C23,"L",if(isblank(C23),"","T"))) -> L | E23: 30 | F23: =if(K20<E23,"W",if(K20>E23,"L",if(isblank(E23),"","T"))) -> L | G23: 72 | H23: =if(K21<G23,"W",if(K21>G23,"L",if(isblank(G23),"","T"))) -> W | I23: 78 | J23: =if(K22<I23,"W",if(K22>I23,"L",if(isblank(I23),"","T"))) -> W | M23: 112 | N23: =if(M23>K24,"W",if(M23<K24,"L",if(isblank(M23),"","T"))) -> W | O23: =SUM(C23:N23) -> 380 | P23: =COUNTIF(C23:N23, "*W*") -> 3 | Q23: =COUNTIF(C23:N23, "*T*") -> 0 | R23: =COUNTIF(C23:N23, "*L*") -> 2 | S23: =0.015*SUM(O19:O24)+IF(D23="W",150+C23,IF(D23="T",100+C23,IF(D23="L",IF((K19-C23)<80,80-(K19-C23),0),0)))+IF(F23="W",150+E23,IF(F23="T",100+E23,IF(F23="L",IF((K20-E23)<80,80-(K20-E23),0),0)))+IF(H23="W",150+G23,IF(H23="T",100+G23,IF(H23="L",IF((K21-G23)<80,80-(K21-G23),0),0)))+IF(J23="W",150+I23,IF(J23="T",100+I23,IF(J23="L",IF((K22-I23)<80,80-(K22-I23),0),0)))+IF(N23="W",150+M23,IF(N23="T",100+M23,IF(N23="L",IF((K24-M23)<80,80-(K24-M23),0),0))) -> 847.46 | U23: WWPS A | V23: 70 | W23: =if(AD19<V23,"W",if(AD19>V23,"L",if(isblank(V23),"","T"))) -> L | X23: 84 | Y23: =if(AD20<X23,"W",if(AD20>X23,"L",if(isblank(X23),"","T"))) -> W | Z23: 120 | AA23: =if(AD21<Z23,"W",if(AD21>Z23,"L",if(isblank(Z23),"","T"))) -> W | AB23: 106 | AC23: =if(AD22<AB23,"W",if(AD22>AB23,"L",if(isblank(AB23),"","T"))) -> W | AF23: 130 | AG23: =if(AF23>AD24,"W",if(AF23<AD24,"L",if(isblank(AF23),"","T"))) -> W | AH23: =SUM(V23:AG23) -> 510 | AI23: =COUNTIF(V23:AG23, "*W*") -> 4 | AJ23: =COUNTIF(V23:AG23, "*T*") -> 0 | AK23: =COUNTIF(V23:AG23, "*L*") -> 1 | AL23: =0.015*SUM(AH19:AH24)+IF(W23="W",150+V23,IF(W23="T",100+V23,IF(W23="L",IF((AD19-V23)<80,80-(AD19-V23),0),0)))+IF(Y23="W",150+X23,IF(Y23="T",100+X23,IF(Y23="L",IF((AD20-X23)<80,80-(AD20-X23),0),0)))+IF(AA23="W",150+Z23,IF(AA23="T",100+Z23,IF(AA23="L",IF((AD21-Z23)<80,80-(AD21-Z23),0),0)))+IF(AC23="W",150+AB23,IF(AC23="T",100+AB23,IF(AC23="L",IF((AD22-AB23)<80,80-(AD22-AB23),0),0)))+IF(AG23="W",150+AF23,IF(AG23="T",100+AF23,IF(AG23="L",IF((AD24-AF23)<80,80-(AD24-AF23),0),0))) -> 1102.52
B24: BISV HS A | C24: 32 | D24: =if(M19<C24,"W",if(M19>C24,"L",if(isblank(C24),"","T"))) -> L | E24: 60 | F24: =if(M20<E24,"W",if(M20>E24,"L",if(isblank(E24),"","T"))) -> L | G24: 90 | H24: =if(M21<G24,"W",if(M21>G24,"L",if(isblank(G24),"","T"))) -> W | I24: 100 | J24: =if(M22<I24,"W",if(M22>I24,"L",if(isblank(I24),"","T"))) -> W | K24: 82 | L24: =if(M23<K24,"W",if(M23>K24,"L",if(isblank(K24),"","T"))) -> L | O24: =SUM(C24:N24) -> 364 | P24: =COUNTIF(C24:N24, "*W*") -> 2 | Q24: =COUNTIF(C24:N24, "*T*") -> 0 | R24: =COUNTIF(C24:N24, "*L*") -> 3 | S24: =0.015*SUM(O19:O24)+IF(D24="W",150+C24,IF(D24="T",100+C24,IF(D24="L",IF((M19-C24)<80,80-(M19-C24),0),0)))+IF(F24="W",150+E24,IF(F24="T",100+E24,IF(F24="L",IF((M20-E24)<80,80-(M20-E24),0),0)))+IF(H24="W",150+G24,IF(H24="T",100+G24,IF(H24="L",IF((M21-G24)<80,80-(M21-G24),0),0)))+IF(J24="W",150+I24,IF(J24="T",100+I24,IF(J24="L",IF((M22-I24)<80,80-(M22-I24),0),0)))+IF(L24="W",150+K24,IF(L24="T",100+K24,IF(L24="L",IF((M23-K24)<80,80-(M23-K24),0),0))) -> 629.46 | U24: SGVG | V24: 22 | W24: =if(AF19<V24,"W",if(AF19>V24,"L",if(isblank(V24),"","T"))) -> L | X24: 106 | Y24: =if(AF20<X24,"W",if(AF20>X24,"L",if(isblank(X24),"","T"))) -> W | Z24: 32 | AA24: =if(AF21<Z24,"W",if(AF21>Z24,"L",if(isblank(Z24),"","T"))) -> L | AB24: 90 | AC24: =if(AF22<AB24,"W",if(AF22>AB24,"L",if(isblank(AB24),"","T"))) -> W | AD24: 80 | AE24: =if(AF23<AD24,"W",if(AF23>AD24,"L",if(isblank(AD24),"","T"))) -> L | AH24: =SUM(V24:AG24) -> 330 | AI24: =COUNTIF(V24:AG24, "*W*") -> 2 | AJ24: =COUNTIF(V24:AG24, "*T*") -> 0 | AK24: =COUNTIF(V24:AG24, "*L*") -> 3 | AL24: =0.015*SUM(AH19:AH24)+IF(W24="W",150+V24,IF(W24="T",100+V24,IF(W24="L",IF((AF19-V24)<80,80-(AF19-V24),0),0)))+IF(Y24="W",150+X24,IF(Y24="T",100+X24,IF(Y24="L",IF((AF20-X24)<80,80-(AF20-X24),0),0)))+IF(AA24="W",150+Z24,IF(AA24="T",100+Z24,IF(AA24="L",IF((AF21-Z24)<80,80-(AF21-Z24),0),0)))+IF(AC24="W",150+AB24,IF(AC24="T",100+AB24,IF(AC24="L",IF((AF22-AB24)<80,80-(AF22-AB24),0),0)))+IF(AE24="W",150+AD24,IF(AE24="T",100+AD24,IF(AE24="L",IF((AF23-AD24)<80,80-(AF23-AD24),0),0))) -> 564.52
B26: FEYNMAN | C26: Lakeside | E26: MSJ B | G26: WWPS C | I26: Shallow Walk B | K26: North Hollywood | M26: Law Abiding Citizens | O26: Points | P26: Wins | Q26: Draws | R26: Losses | S26: Score | U26: NOETHER | V26: MSJ C | X26: North Allegheny | Z26: School of Geology | AB26: School of Biology | AD26: Arcadia A | AF26: CCA B | AH26: Points | AI26: Wins | AJ26: Draws | AK26: Losses | AL26: Score
B27: Lakeside | E27: 60 | F27: =if(E27>C28,"W",if(E27<C28,"L",if(isblank(E27),"","T"))) -> L | G27: 76 | H27: =if(G27>C29,"W",if(G27<C29,"L",if(isblank(G27),"","T"))) -> L | I27: 138 | J27: =if(I27>C30,"W",if(I27<C30,"L",if(isblank(I27),"","T"))) -> W | K27: 74 | L27: =if(K27>C31,"W",if(K27<C31,"L",if(isblank(K27),"","T"))) -> L | M27: 74 | N27: =if(M27>C32,"W",if(M27<C32,"L",if(isblank(C32),"","T"))) -> L | O27: =SUM(C27:N27) -> 422 | P27: =COUNTIF(C27:N27, "*W*") -> 1 | Q27: =COUNTIF(C27:N27, "*T*") -> 0 | R27: =COUNTIF(C27:N27, "*L*") -> 4 | S27: =0.015*SUM(O27:O32)+IF(F27="W",150+E27,IF(F27="T",100+E27,IF(F27="L",IF((C28-E27)<80,80-(C28-E27),0),0)))+IF(H27="W",150+G27,IF(H27="T",100+G27,IF(H27="L",IF((C29-G27)<80,80-(C29-G27),0),0)))+IF(J27="W",150+I27,IF(J27="T",100+I27,IF(J27="L",IF((C30-I27)<80,80-(C30-I27),0),0)))+IF(L27="W",150+K27,IF(L27="T",100+K27,IF(L27="L",IF((C31-K27)<80,80-(C31-K27),0),0)))+IF(N27="W",150+M27,IF(N27="T",100+M27,IF(N27="L",IF((C32-M27)<80,80-(C32-M27),0),0))) -> 504.32 | U27: MSJ C | X27: 24 | Y27: =if(X27>V28,"W",if(X27<V28,"L",if(isblank(X27),"","T"))) -> L | Z27: 42 | AA27: =if(Z27>V29,"W",if(Z27<V29,"L",if(isblank(Z27),"","T"))) -> L | AB27: 78 | AC27: =if(AB27>V30,"W",if(AB27<V30,"L",if(isblank(AB27),"","T"))) -> L | AD27: 92 | AE27: =if(AD27>V31,"W",if(AD27<V31,"L",if(isblank(AD27),"","T"))) -> W | AF27: 70 | AG27: =if(AF27>V32,"W",if(AF27<V32,"L",if(isblank(V32),"","T"))) -> W | AH27: =SUM(V27:AG27) -> 306 | AI27: =COUNTIF(V27:AG27, "*W*") -> 2 | AJ27: =COUNTIF(V27:AG27, "*T*") -> 0 | AK27: =COUNTIF(V27:AG27, "*L*") -> 3 | AL27: =0.015*SUM(AH27:AH32)+IF(Y27="W",150+X27,IF(Y27="T",100+X27,IF(Y27="L",IF((V28-X27)<80,80-(V28-X27),0),0)))+IF(AA27="W",150+Z27,IF(AA27="T",100+Z27,IF(AA27="L",IF((V29-Z27)<80,80-(V29-Z27),0),0)))+IF(AC27="W",150+AB27,IF(AC27="T",100+AB27,IF(AC27="L",IF((V30-AB27)<80,80-(V30-AB27),0),0)))+IF(AE27="W",150+AD27,IF(AE27="T",100+AD27,IF(AE27="L",IF((V31-AD27)<80,80-(V31-AD27),0),0)))+IF(AG27="W",150+AF27,IF(AG27="T",100+AF27,IF(AG27="L",IF((V32-AF27)<80,80-(V32-AF27),0),0))) -> 532.23
B28: MSJ B | C28: 94 | D28: =if(E27<C28,"W",if(E27>C28,"L",if(isblank(C28),"","T"))) -> W | G28: 154 | H28: =if(G28>E29,"W",if(G28<E29,"L",if(isblank(G28),"","T"))) -> W | I28: 160 | J28: =if(I28>E30,"W",if(I28<E30,"L",if(isblank(I28),"","T"))) -> W | K28: 78 | L28: =if(K28>E31,"W",if(K28<E31,"L",if(isblank(K28),"","T"))) -> W | M28: 58 | N28: =if(M28>E32,"W",if(M28<E32,"L",if(isblank(M28),"","T"))) -> L | O28: =SUM(C28:N28) -> 544 | P28: =COUNTIF(C28:N28, "*W*") -> 4 | Q28: =COUNTIF(C28:N28, "*T*") -> 0 | R28: =COUNTIF(C28:N28, "*L*") -> 1 | S28: =0.015*SUM(O27:O32)+IF(D28="W",150+C28,IF(D28="T",100+C28,IF(D28="L",IF((E27-C28)<80,80-(E27-C28),0),0)))+IF(H28="W",150+G28,IF(H28="T",100+G28,IF(H28="L",IF((E29-G28)<80,80-(E29-G28),0),0)))+IF(J28="W",150+I28,IF(J28="T",100+I28,IF(J28="L",IF((E30-I28)<80,80-(E30-I28),0),0)))+IF(L28="W",150+K28,IF(L28="T",100+K28,IF(L28="L",IF((E31-K28)<80,80-(E31-K28),0),0)))+IF(N28="W",150+M28,IF(N28="T",100+M28,IF(N28="L",IF((E32-M28)<80,80-(E32-M28),0),0))) -> 1126.32 | U28: North Allegheny | V28: 182 | W28: =if(X27<V28,"W",if(X27>V28,"L",if(isblank(V28),"","T"))) -> W | Z28: 58 | AA28: =if(Z28>X29,"W",if(Z28<X29,"L",if(isblank(Z28),"","T"))) -> L | AB28: 194 | AC28: =if(AB28>X30,"W",if(AB28<X30,"L",if(isblank(AB28),"","T"))) -> W | AD28: 120 | AE28: =if(AD28>X31,"W",if(AD28<X31,"L",if(isblank(AD28),"","T"))) -> W | AF28: 214 | AG28: =if(AF28>X32,"W",if(AF28<X32,"L",if(isblank(AF28),"","T"))) -> W | AH28: =SUM(V28:AG28) -> 768 | AI28: =COUNTIF(V28:AG28, "*W*") -> 4 | AJ28: =COUNTIF(V28:AG28, "*T*") -> 0 | AK28: =COUNTIF(V28:AG28, "*L*") -> 1 | AL28: =0.015*SUM(AH27:AH32)+IF(W28="W",150+V28,IF(W28="T",100+V28,IF(W28="L",IF((X27-V28)<80,80-(X27-V28),0),0)))+IF(AA28="W",150+Z28,IF(AA28="T",100+Z28,IF(AA28="L",IF((X29-Z28)<80,80-(X29-Z28),0),0)))+IF(AC28="W",150+AB28,IF(AC28="T",100+AB28,IF(AC28="L",IF((X30-AB28)<80,80-(X30-AB28),0),0)))+IF(AE28="W",150+AD28,IF(AE28="T",100+AD28,IF(AE28="L",IF((X31-AD28)<80,80-(X31-AD28),0),0)))+IF(AG28="W",150+AF28,IF(AG28="T",100+AF28,IF(AG28="L",IF((X32-AF28)<80,80-(X32-AF28),0),0))) -> 1350.23
B29: WWPS C | C29: 106 | D29: =if(G27<C29,"W",if(G27>C29,"L",if(isblank(C29),"","T"))) -> W | E29: 84 | F29: =if(G28<E29,"W",if(G28>E29,"L",if(isblank(E29),"","T"))) -> L | I29: 80 | J29: =if(I29>G30,"W",if(I29<G30,"L",if(isblank(I29),"","T"))) -> W | K29: 62 | L29: =if(K29>G31,"W",if(K29<G31,"L",if(isblank(K29),"","T"))) -> L | M29: 38 | N29: =if(M29>G32,"W",if(M29<G32,"L",if(isblank(M29),"","T"))) -> L | O29: =SUM(C29:N29) -> 370 | P29: =COUNTIF(C29:N29, "*W*") -> 2 | Q29: =COUNTIF(C29:N29, "*T*") -> 0 | R29: =COUNTIF(C29:N29, "*L*") -> 3 | S29: =0.015*SUM(O27:O32)+IF(D29="W",150+C29,IF(D29="T",100+C29,IF(D29="L",IF((G27-C29)<80,80-(G27-C29),0),0)))+IF(F29="W",150+E29,IF(F29="T",100+E29,IF(F29="L",IF((G28-E29)<80,80-(G28-E29),0),0)))+IF(J29="W",150+I29,IF(J29="T",100+I29,IF(J29="L",IF((G30-I29)<80,80-(G30-I29),0),0)))+IF(L29="W",150+K29,IF(L29="T",100+K29,IF(L29="L",IF((G31-K29)<80,80-(G31-K29),0),0)))+IF(N29="W",150+M29,IF(N29="T",100+M29,IF(N29="L",IF((G32-M29)<80,80-(G32-M29),0),0))) -> 536.32 | U29: School of Geology | V29: 168 | W29: =if(Z27<V29,"W",if(Z27>V29,"L",if(isblank(V29),"","T"))) -> W | X29: 160 | Y29: =if(Z28<X29,"W",if(Z28>X29,"L",if(isblank(X29),"","T"))) -> W | AB29: 134 | AC29: =if(AB29>Z30,"W",if(AB29<Z30,"L",if(isblank(AB29),"","T"))) -> W | AD29: 146 | AE29: =if(AD29>Z31,"W",if(AD29<Z31,"L",if(isblank(AD29),"","T"))) -> W | AF29: 156 | AG29: =if(AF29>Z32,"W",if(AF29<Z32,"L",if(isblank(AF29),"","T"))) -> W | AH29: =SUM(V29:AG29) -> 764 | AI29: =COUNTIF(V29:AG29, "*W*") -> 5 | AJ29: =COUNTIF(V29:AG29, "*T*") -> 0 | AK29: =COUNTIF(V29:AG29, "*L*") -> 0 | AL29: =0.015*SUM(AH27:AH32)+IF(W29="W",150+V29,IF(W29="T",100+V29,IF(W29="L",IF((Z27-V29)<80,80-(Z27-V29),0),0)))+IF(Y29="W",150+X29,IF(Y29="T",100+X29,IF(Y29="L",IF((Z28-X29)<80,80-(Z28-X29),0),0)))+IF(AC29="W",150+AB29,IF(AC29="T",100+AB29,IF(AC29="L",IF((Z30-AB29)<80,80-(Z30-AB29),0),0)))+IF(AE29="W",150+AD29,IF(AE29="T",100+AD29,IF(AE29="L",IF((Z31-AD29)<80,80-(Z31-AD29),0),0)))+IF(AG29="W",150+AF29,IF(AG29="T",100+AF29,IF(AG29="L",IF((Z32-AF29)<80,80-(Z32-AF29),0),0))) -> 1554.23
B30: Shallow Walk B | C30: 0 | D30: =if(I27<C30,"W",if(I27>C30,"L",if(isblank(C30),"","T"))) -> L | E30: 0 | F30: =if(I28<E30,"W",if(I28>E30,"L",if(isblank(E30),"","T"))) -> L | G30: 0 | H30: =if(I29<G30,"W",if(I29>G30,"L",if(isblank(G30),"","T"))) -> L | K30: 22 | L30: =if(K30>I31,"W",if(K30<I31,"L",if(isblank(K30),"","T"))) -> L | M30: 0 | N30: =if(M30>I32,"W",if(M30<I32,"L",if(isblank(M30),"","T"))) -> L | O30: =SUM(C30:N30) -> 22 | P30: =COUNTIF(C30:N30, "*W*") -> 0 | Q30: =COUNTIF(C30:N30, "*T*") -> 0 | R30: =COUNTIF(C30:N30, "*L*") -> 5 | S30: =0.015*SUM(O27:O32)+IF(D30="W",150+C30,IF(D30="T",100+C30,IF(D30="L",IF((I27-C30)<80,80-(I27-C30),0),0)))+IF(F30="W",150+E30,IF(F30="T",100+E30,IF(F30="L",IF((I28-E30)<80,80-(I28-E30),0),0)))+IF(H30="W",150+G30,IF(H30="T",100+G30,IF(H30="L",IF((I29-G30)<80,80-(I29-G30),0),0)))+IF(L30="W",150+K30,IF(L30="T",100+K30,IF(L30="L",IF((I31-K30)<80,80-(I31-K30),0),0)))+IF(N30="W",150+M30,IF(N30="T",100+M30,IF(N30="L",IF((I32-M30)<80,80-(I32-M30),0),0))) -> 40.32 | U30: School of Biology | V30: 128 | W30: =if(AB27<V30,"W",if(AB27>V30,"L",if(isblank(V30),"","T"))) -> W | X30: 50 | Y30: =if(AB28<X30,"W",if(AB28>X30,"L",if(isblank(X30),"","T"))) -> L | Z30: 28 | AA30: =if(AB29<Z30,"W",if(AB29>Z30,"L",if(isblank(Z30),"","T"))) -> L | AD30: 50 | AE30: =if(AD30>AB31,"W",if(AD30<AB31,"L",if(isblank(AD30),"","T"))) -> L | AF30: 132 | AG30: =if(AF30>AB32,"W",if(AF30<AB32,"L",if(isblank(AF30),"","T"))) -> W | AH30: =SUM(V30:AG30) -> 388 | AI30: =COUNTIF(V30:AG30, "*W*") -> 2 | AJ30: =COUNTIF(V30:AG30, "*T*") -> 0 | AK30: =COUNTIF(V30:AG30, "*L*") -> 3 | AL30: =0.015*SUM(AH27:AH32)+IF(W30="W",150+V30,IF(W30="T",100+V30,IF(W30="L",IF((AB27-V30)<80,80-(AB27-V30),0),0)))+IF(Y30="W",150+X30,IF(Y30="T",100+X30,IF(Y30="L",IF((AB28-X30)<80,80-(AB28-X30),0),0)))+IF(AA30="W",150+Z30,IF(AA30="T",100+Z30,IF(AA30="L",IF((AB29-Z30)<80,80-(AB29-Z30),0),0)))+IF(AE30="W",150+AD30,IF(AE30="T",100+AD30,IF(AE30="L",IF((AB31-AD30)<80,80-(AB31-AD30),0),0)))+IF(AG30="W",150+AF30,IF(AG30="T",100+AF30,IF(AG30="L",IF((AB32-AF30)<80,80-(AB32-AF30),0),0))) -> 650.23
B31: North Hollywood | C31: 104 | D31: =if(K27<C31,"W",if(K27>C31,"L",if(isblank(C31),"","T"))) -> W | E31: 68 | F31: =if(K28<E31,"W",if(K28>E31,"L",if(isblank(E31),"","T"))) -> L | G31: 164 | H31: =if(K29<G31,"W",if(K29>G31,"L",if(isblank(G31),"","T"))) -> W | I31: 138 | J31: =if(K30<I31,"W",if(K30>I31,"L",if(isblank(I31),"","T"))) -> W | M31: 108 | N31: =if(M31>K32,"W",if(M31<K32,"L",if(isblank(M31),"","T"))) -> W | O31: =SUM(C31:N31) -> 582 | P31: =COUNTIF(C31:N31, "*W*") -> 4 | Q31: =COUNTIF(C31:N31, "*T*") -> 0 | R31: =COUNTIF(C31:N31, "*L*") -> 1 | S31: =0.015*SUM(O27:O32)+IF(D31="W",150+C31,IF(D31="T",100+C31,IF(D31="L",IF((K27-C31)<80,80-(K27-C31),0),0)))+IF(F31="W",150+E31,IF(F31="T",100+E31,IF(F31="L",IF((K28-E31)<80,80-(K28-E31),0),0)))+IF(H31="W",150+G31,IF(H31="T",100+G31,IF(H31="L",IF((K29-G31)<80,80-(K29-G31),0),0)))+IF(J31="W",150+I31,IF(J31="T",100+I31,IF(J31="L",IF((K30-I31)<80,80-(K30-I31),0),0)))+IF(N31="W",150+M31,IF(N31="T",100+M31,IF(N31="L",IF((K32-M31)<80,80-(K32-M31),0),0))) -> 1224.32 | U31: Arcardia A | V31: 90 | W31: =if(AD27<V31,"W",if(AD27>V31,"L",if(isblank(V31),"","T"))) -> L | X31: 40 | Y31: =if(AD28<X31,"W",if(AD28>X31,"L",if(isblank(X31),"","T"))) -> L | Z31: 34 | AA31: =if(AD29<Z31,"W",if(AD29>Z31,"L",if(isblank(Z31),"","T"))) -> L | AB31: 80 | AC31: =if(AD30<AB31,"W",if(AD30>AB31,"L",if(isblank(AB31),"","T"))) -> W | AF31: 146 | AG31: =if(AF31>AD32,"W",if(AF31<AD32,"L",if(isblank(AF31),"","T"))) -> W | AH31: =SUM(V31:AG31) -> 390 | AI31: =COUNTIF(V31:AG31, "*W*") -> 2 | AJ31: =COUNTIF(V31:AG31, "*T*") -> 0 | AK31: =COUNTIF(V31:AG31, "*L*") -> 3 | AL31: =0.015*SUM(AH27:AH32)+IF(W31="W",150+V31,IF(W31="T",100+V31,IF(W31="L",IF((AD27-V31)<80,80-(AD27-V31),0),0)))+IF(Y31="W",150+X31,IF(Y31="T",100+X31,IF(Y31="L",IF((AD28-X31)<80,80-(AD28-X31),0),0)))+IF(AA31="W",150+Z31,IF(AA31="T",100+Z31,IF(AA31="L",IF((AD29-Z31)<80,80-(AD29-Z31),0),0)))+IF(AC31="W",150+AB31,IF(AC31="T",100+AB31,IF(AC31="L",IF((AD30-AB31)<80,80-(AD30-AB31),0),0)))+IF(AG31="W",150+AF31,IF(AG31="T",100+AF31,IF(AG31="L",IF((AD32-AF31)<80,80-(AD32-AF31),0),0))) -> 644.23
B32: Law Abiding Citizens | C32: 124 | D32: =if(M27<C32,"W",if(M27>C32,"L",if(isblank(C32),"","T"))) -> W | E32: 160 | F32: =if(M28<E32,"W",if(M28>E32,"L",if(isblank(E32),"","T"))) -> W | G32: 160 | H32: =if(M29<G32,"W",if(M29>G32,"L",if(isblank(G32),"","T"))) -> W | I32: 202 | J32: =if(M30<I32,"W",if(M30>I32,"L",if(isblank(I32),"","T"))) -> W | K32: 102 | L32: =if(M31<K32,"W",if(M31>K32,"L",if(isblank(K32),"","T"))) -> L | O32: =SUM(C32:N32) -> 748 | P32: =COUNTIF(C32:N32, "*W*") -> 4 | Q32: =COUNTIF(C32:N32, "*T*") -> 0 | R32: =COUNTIF(C32:N32, "*L*") -> 1 | S32: =0.015*SUM(O27:O32)+IF(D32="W",150+C32,IF(D32="T",100+C32,IF(D32="L",IF((M27-C32)<80,80-(M27-C32),0),0)))+IF(F32="W",150+E32,IF(F32="T",100+E32,IF(F32="L",IF((M28-E32)<80,80-(M28-E32),0),0)))+IF(H32="W",150+G32,IF(H32="T",100+G32,IF(H32="L",IF((M29-G32)<80,80-(M29-G32),0),0)))+IF(J32="W",150+I32,IF(J32="T",100+I32,IF(J32="L",IF((M30-I32)<80,80-(M30-I32),0),0)))+IF(L32="W",150+K32,IF(L32="T",100+K32,IF(L32="L",IF((M31-K32)<80,80-(M31-K32),0),0))) -> 1360.32 | U32: CCA B | V32: 16 | W32: =if(AF27<V32,"W",if(AF27>V32,"L",if(isblank(V32),"","T"))) -> L | X32: 14 | Y32: =if(AF28<X32,"W",if(AF28>X32,"L",if(isblank(X32),"","T"))) -> L | Z32: -4 | AA32: =if(AF29<Z32,"W",if(AF29>Z32,"L",if(isblank(Z32),"","T"))) -> L | AB32: 14 | AC32: =if(AF30<AB32,"W",if(AF30>AB32,"L",if(isblank(AB32),"","T"))) -> L | AD32: 26 | AE32: =if(AF31<AD32,"W",if(AF31>AD32,"L",if(isblank(AD32),"","T"))) -> L | AH32: =SUM(V32:AG32) -> 66 | AI32: =COUNTIF(V32:AG32, "*W*") -> 0 | AJ32: =COUNTIF(V32:AG32, "*T*") -> 0 | AK32: =COUNTIF(V32:AG32, "*L*") -> 5 | AL32: =0.015*SUM(AH27:AH32)+IF(W32="W",150+V32,IF(W32="T",100+V32,IF(W32="L",IF((AF27-V32)<80,80-(AF27-V32),0),0)))+IF(Y32="W",150+X32,IF(Y32="T",100+X32,IF(Y32="L",IF((AF28-X32)<80,80-(AF28-X32),0),0)))+IF(AA32="W",150+Z32,IF(AA32="T",100+Z32,IF(AA32="L",IF((AF29-Z32)<80,80-(AF29-Z32),0),0)))+IF(AC32="W",150+AB32,IF(AC32="T",100+AB32,IF(AC32="L",IF((AF30-AB32)<80,80-(AF30-AB32),0),0)))+IF(AE32="W",150+AD32,IF(AE32="T",100+AD32,IF(AE32="L",IF((AF31-AD32)<80,80-(AF31-AD32),0),0))) -> 66.23

Sheet HS DE
F1: DE/SE 1 | H1: DE/SE 2 | J1: DE/SE 3 | L1: DE/SE 4 | N1: DE/SE 5 | P1: DE/SE 6 | R1: DE/SE 7 | T1: DE/SE 8 | V1: Finals 1 and 2
B2: Round Robin Standings
B3: # | C3: Team | D3: Score | F3: Clang! Cloom! Clash! | G3: 180
B4: 1 | C4: {=SORT(Calculation!B3:C69, 2, FALSE)} -> Clang! Cloom! Clash! | D4: 1637.76 | F4: Stage 1 | H4: BYE | J4: Clang! Cloom! Clash! | K4: 138
B5: 2 | C5: MAAOC | D5: 1614.52 | F5: WWPS A | G5: 30
B6: 3 | C6: School of Geology | D6: 1554.23 | J6: Stage 1 | L6: BYE | N6: Clang! Cloom! Clash! | O6: 126
B7: 4 | C7: Shallow Walk A | D7: 1533.46 | F7: North Allegheny | G7: 82
B8: 5 | C8: Montgomery Blair | D8: 1449.38 | F8: Stage 2 | H8: BYE | J8: WWPN | K8: 46
B9: 6 | C9: Lynbroke | D9: 1435.26 | F9: WWPN | G9: 108
B10: 7 | C10: Law Abiding Citizens | D10: 1360.32 | N10: Stage 1 | P10: BYE | R10: Clang! Cloom! Clash! | S10: 46
B11: 8 | C11: North Allegheny | D11: 1350.23 | F11: Montgomery Blair | G11: 100
B12: 9 | C12: WWPN | D12: 1299.76 | F12: Stage 3 | H12: BYE | J12: ASFA | K12: 74
B13: 10 | C13: North Hollywood | D13: 1224.32 | F13: ASFA | G13: 108
B14: 11 | C14: Royal Hogs | D14: 1219.33 | J14: Stage 2 | L14: BYE | N14: ASFA | O14: 36
B15: 12 | C15: ASFA | D15: 1215.33 | F15: Shallow Walk A | G15: 100
B16: 13 | C16: Palo Alto A | D16: 1189.38 | F16: Stage 4 | H16: BYE | J16: Shallow Walk A | K16: 38
B17: 14 | C17: Re2rement Home | D17: 1163.26 | F17: Palo Alto A | G17: 64
B18: 15 | C18: MSJ B | D18: 1126.32 | R18: Stage 1 | T18: BYE | V18: School of Geology | W18: -12 | X18: 18
B19: 16 | C19: WWPS A | D19: 1102.52 | F19: School of Geology | G19: 142
B20: 17 | C20: School of Chemistry | D20: 1023.76 | F20: Stage 5 | H20: BYE | J20: School of Geology | K20: 112
B21: 18 | C21: Wheaton | D21: 1011.26 | F21: Re2remenet Home | G21: 104
B22: 19 | C22: University | D22: 1007.33 | J22: Stage 3 | L22: BYE | N22: School of Geology | O22: 98
B23: 20 | C23: MSJ A | D23: 1006.52 | F23: Lynbroke | G23: 84
B24: 21 | C24: Arcadia B | D24: 981.38 | F24: Stage 6 | H24: BYE | J24: Royal Hogs | K24: 54
B25: 22 | C25: Gargy Bomy | D25: 847.46 | F25: Royal Hogs | G25: 122
B26: 23 | C26: Enloe | D26: 765.46 | N26: Stage 2 | P26: BYE | R26: School of Geology | S26: 58
B27: 24 | C27: CCA A | D27: 717.26 | F27: Law Abiding Citizens | G27: 144
B28: 25 | C28: Doral Academy | D28: 657.38 | F28: Stage 7 | H28: BYE | J28: Law Abiding Citizens | K28: 126 | V28: Finals Stage | Y28: Law Abiding Citizens
B29: 26 | C29: School of Biology | D29: 650.23 | F29: North Hollywood | G29: 56 | Y29: HIGH SCHOOL CHAMPION
B30: 27 | C30: Arcardia A | D30: 644.23 | J30: Stage 4 | L30: BYE | N30: Law Abiding Citizens | O30: 66 | T30: Clang! Cloom! Clash! | U30: 26
B31: 28 | C31: BISV HS A | D31: 629.46 | F31: MAAOOC | G31: 30
B32: 29 | C32: VMATHs | D32: 593.38 | F32: Stage 8 | H32: BYE | J32: MSJ B | K32: 64
B33: 30 | C33: SGVG | D33: 564.52 | F33: MSJ B | G33: 156
B34: 31 | C34: BISV HS B | D34: 537.33 | P34: Law Abiding Citizens | Q34: 102
B35: 32 | C35: WWPS C | D35: 536.32
B36: 33 | C36: MSJ C | D36: 532.23 | L36: Royal Hogs | M36: 36
B37: 34 | C37: Middleton | D37: 513.46 | H37: WWPS A | I37: 68
B38: 35 | C38: Lakeside | D38: 504.32 | F38: School of Chemistry | G38: 84 | H38: Stage 1 | J38: School of Chemistry | K38: 102 | L38: Stage 1 | N38: School of Chemistry | O38: 46 | P38: Stage 1 | R38: Law Abiding Citizens | S38: 78 | T38: Stage 1 | V38: Law Abiding Citizens | W38: 20 | X38: 22
B39: 36 | C39: Chattahoochee A | D39: 493.46 | F39: Stage 9 | H39: School of Chemistry | I39: 104
B40: 37 | C40: Punahou | D40: 473.33 | F40: WWPS C | G40: 52 | J40: Stage 5 | L40: School of Chemistry | M40: 90
...

Sheet MS RR
B2: FLEMING | C2: Space-X | E2: Redwood | G2: BISV A | I2: Granite Ridge | K2: Points | L2: Wins | M2: Draws | N2: Losses | O2: Score | Q2: MENDEL | R2: Hopkins A | T2: Oak Avenue | V2: Wayzata CMS | X2: Collierville MS | Z2: Points | AA2: Wins | AB2: Draws | AC2: Losses | AD2: Score
B3: Space-X | E3: 104 | F3: =if(E3>C4,"W",if(E3<C4,"L",if(isblank(E3),"","T"))) -> L | G3: 98 | H3: =if(G3>C5,"W",if(G3<C5,"L",if(isblank(G3),"","T"))) -> L | I3: 142 | J3: =if(I3>C6,"W",if(I3<C6,"L",if(isblank(I3),"","T"))) -> W | K3: =SUM(C3:J3) -> 344 | L3: =COUNTIF(C3:J3, "*W*") -> 1 | M3: =COUNTIF(C3:J3, "*T*") -> 0 | N3: =COUNTIF(C3:J3, "*L*") -> 2 | O3: =0.015*SUM(K3:K6)+IF(F3="W",150+E3,IF(F3="T",100+E3,IF(F3="L",IF((C4-E3)<80,80-(C4-E3),0),0)))+IF(H3="W",150+G3,IF(H3="T",100+G3,IF(H3="L",IF((C5-G3)<80,80-(C5-G3),0),0)))+IF(J3="W",150+I3,IF(J3="T",100+I3,IF(J3="L",IF((C6-I3)<80,80-(C6-I3),0),0))) -> 450.24 | Q3: Hopkins A | T3: 0 | U3: =if(T3>R4,"W",if(T3<R4,"L",if(isblank(T3),"","T"))) -> L | V3: -12 | W3: =if(V3>R5,"W",if(V3<R5,"L",if(isblank(V3),"","T"))) -> L | X3: 46 | Y3: =if(X3>R6,"W",if(X3<R6,"L",if(isblank(X3),"","T"))) -> W | Z3: =SUM(R3:Y3) -> 34 | AA3: =COUNTIF(R3:Y3, "*W*") -> 1 | AB3: =COUNTIF(R3:Y3, "*T*") -> 0 | AC3: =COUNTIF(R3:Y3, "*L*") -> 2 | AD3: =0.015*SUM(Z3:Z6)+IF(U3="W",150+T3,IF(U3="T",100+T3,IF(U3="L",IF((R4-T3)<80,80-(R4-T3),0),0)))+IF(W3="W",150+V3,IF(W3="T",100+V3,IF(W3="L",IF((R5-V3)<80,80-(R5-V3),0),0)))+IF(Y3="W",150+X3,IF(Y3="T",100+X3,IF(Y3="L",IF((R6-X3)<80,80-(R6-X3),0),0))) -> 212.2
B4: Redwood | C4: 106 | D4: =if(E3<C4,"W",if(E3>C4,"L",if(isblank(C4),"","T"))) -> W | G4: 110 | H4: =if(G4>E5,"W",if(G4<E5,"L",if(isblank(G4),"","T"))) -> L | I4: 204 | J4: =if(I4>E6,"W",if(I4<E6,"L",if(isblank(I4),"","T"))) -> W | K4: =SUM(C4:J4) -> 420 | L4: =COUNTIF(C4:J4, "*W*") -> 2 | M4: =COUNTIF(C4:J4, "*T*") -> 0 | N4: =COUNTIF(C4:J4, "*L*") -> 1 | O4: =0.015*SUM(K3:K6)+IF(D4="W",150+C4,IF(D4="T",100+C4,IF(D4="L",IF((E3-C4)<80,80-(E3-C4),0),0)))+IF(H4="W",150+G4,IF(H4="T",100+G4,IF(H4="L",IF((E5-G4)<80,80-(E5-G4),0),0)))+IF(J4="W",150+I4,IF(J4="T",100+I4,IF(J4="L",IF((E6-I4)<80,80-(E6-I4),0),0))) -> 704.24 | Q4: Oak Avenue | R4: 178 | S4: =if(T3<R4,"W",if(T3>R4,"L",if(isblank(R4),"","T"))) -> W | V4: 84 | W4: =if(V4>T5,"W",if(V4<T5,"L",if(isblank(V4),"","T"))) -> L | X4: 154 | Y4: =if(X4>T6,"W",if(X4<T6,"L",if(isblank(X4),"","T"))) -> W | Z4: =SUM(R4:Y4) -> 416 | AA4: =COUNTIF(R4:Y4, "*W*") -> 2 | AB4: =COUNTIF(R4:Y4, "*T*") -> 0 | AC4: =COUNTIF(R4:Y4, "*L*") -> 1 | AD4: =0.015*SUM(Z3:Z6)+IF(S4="W",150+R4,IF(S4="T",100+R4,IF(S4="L",IF((T3-R4)<80,80-(T3-R4),0),0)))+IF(W4="W",150+V4,IF(W4="T",100+V4,IF(W4="L",IF((T5-V4)<80,80-(T5-V4),0),0)))+IF(Y4="W",150+X4,IF(Y4="T",100+X4,IF(Y4="L",IF((T6-X4)<80,80-(T6-X4),0),0))) -> 698.2
B5: BISV MS A | C5: 116 | D5: =if(G3<C5,"W",if(G3>C5,"L",if(isblank(C5),"","T"))) -> W | E5: 114 | F5: =if(G4<E5,"W",if(G4>E5,"L",if(isblank(E5),"","T"))) -> W | I5: 160 | J5: =if(I5>G6,"W",if(I5<G6,"L",if(isblank(I5),"","T"))) -> W | K5: =SUM(C5:J5) -> 390 | L5: =COUNTIF(C5:J5, "*W*") -> 3 | M5: =COUNTIF(C5:J5, "*T*") -> 0 | N5: =COUNTIF(C5:J5, "*L*") -> 0 | O5: =0.015*SUM(K3:K6)+IF(D5="W",150+C5,IF(D5="T",100+C5,IF(D5="L",IF((G3-C5)<80,80-(G3-C5),0),0)))+IF(F5="W",150+E5,IF(F5="T",100+E5,IF(F5="L",IF((G4-E5)<80,80-(G4-E5),0),0)))+IF(J5="W",150+I5,IF(J5="T",100+I5,IF(J5="L",IF((G6-I5)<80,80-(G6-I5),0),0))) -> 858.24 | Q5: Wayzata CMS | R5: 234 | S5: =if(V3<R5,"W",if(V3>R5,"L",if(isblank(R5),"","T"))) -> W | T5: 114 | U5: =if(V4<T5,"W",if(V4>T5,"L",if(isblank(T5),"","T"))) -> W | X5: 220 | Y5: =if(X5>V6,"W",if(X5<V6,"L",if(isblank(X5),"","T"))) -> W | Z5: =SUM(R5:Y5) -> 568 | AA5: =COUNTIF(R5:Y5, "*W*") -> 3 | AB5: =COUNTIF(R5:Y5, "*T*") -> 0 | AC5: =COUNTIF(R5:Y5, "*L*") -> 0 | AD5: =0.015*SUM(Z3:Z6)+IF(S5="W",150+R5,IF(S5="T",100+R5,IF(S5="L",IF((V3-R5)<80,80-(V3-R5),0),0)))+IF(U5="W",150+T5,IF(U5="T",100+T5,IF(U5="L",IF((V4-T5)<80,80-(V4-T5),0),0)))+IF(Y5="W",150+X5,IF(Y5="T",100+X5,IF(Y5="L",IF((V6-X5)<80,80-(V6-X5),0),0))) -> 1034.2
