Workbook

Sheet Tournament Schedule
B2: SMH Invitational Cup - October 12, 2024
B4: Schedule | F4: Round Robin Pairings
B5: all listed times are in pacific time (PT), public spectators will be permitted after and including DE4 | F5: all listed times are in pacific time (PT)
B7: Start Time | C7: End Time | D7: Description | G7: Start Time | I7: Room 1 | J7: Room 2 | K7: Room 3
B8: 0.36458333 | C8: 0.39583333 | D8: Opening + Round Robin 1 | G8: 0.36458333 | H8: RR1 | I8: 45293 | J8: 45355 | K8: 45418
B9: 0.39930556 | C9: 0.42013889 | D9: Round Robin 2 | G9: 0.39930556 | H9: RR2 | I9: 45327 | J9: 45357 | K9: 45295
B10: 0.42361111 | C10: 0.44444444 | D10: Round Robin 3 | G10: 0.42361111 | H10: RR3 | I10: 45294 | J10: 45387 | K10: 45328
B11: 0.44791667 | C11: 0.46875 | D11: Round Robin 4 | G11: 0.44791667 | H11: RR4 | I11: 45326 | J11: 45297 | K11: 45356
B12: 0.47222222 | C12: 0.49305556 | D12: Round Robin 5 | G12: 0.47222222 | H12: RR5 | I12: 45388 | J12: 45325 | K12: 45296
B14: 0.49305556 | C14: 0.52430556 | D14: Lunch Break | G14: For example, in RR3, the fourth team in each division (e.g. Albatross-4) would play in Room 2 against the fifth team in each division (e.g. Albatross-5).
B16: 0.52430556 | C16: 0.53125 | D16: Halftime Show
B17: 0.53125 | C17: 0.55555556 | D17: Double Elimination 1
B18: 0.55555556 | C18: 0.57986111 | D18: Double Elimination 2 | F18: Important Links
B19: 0.57986111 | C19: 0.60416667 | D19: Double Elimination 3
B21: 0.60416667 | C21: 0.61458333 | D21: Snack Break
G22: Discord server: | I22: https://discord.gg/N87yVFa3vM
B23: 0.61458333 | C23: 0.63541667 | D23: Double Elimination 4 | G23: Official website: | I23: https://dannyridel44.wixsite.com/smh-2024
B24: 0.63541667 | C24: 0.65625 | D24: Double Elimination 5 | G24: Information document: | I24: https://docs.google.com/document/d/1Glpvea5UVq7E2TDXlD65gUDJf5jy65dNA2VTv9YnCy0/edit
B25: 0.65625 | C25: 0.67708333 | D25: Double Elimination 6 / Semifinals
B26: 0.67708333 | C26: 0.71875 | D26: Double Elimination 7 / Grand Final
B27: 0.71875 | C27: 0.73958333 | D27: Boss Fight | G27: Packets: | I27: https://drive.google.com/drive/folders/1fTrzbuWpyHYsNQ-5-Bk_B6v_tF5dz4Az
B28: 0.73958333 | C28: 0.75 | D28: Closing Ceremony

Sheet Round Robin Groups
B2: Field and Round Robin Groups
D5: Albatross | G5: Bottle | J5: Champagne | M5: Daylight
C6: a1 | D6: Clovis North | F6: b1 | G6: California | I6: c1 | J6: 'Iolani | L6: d1 | M6: Middleton 2
C7: a2 | D7: Palo Alto | F7: b2 | G7: ASFA | I7: c2 | J7: Oak Avenue 2 | L7: d2 | M7: Lynbrook 1
C8: a3 | D8: Tokay | F8: b3 | G8: Middleton 1 | I8: c3 | J8: Amador Valley | L8: d3 | M8: Collierville 2
C9: a4 | D9: WWPS 1 | F9: b4 | G9: Collierville 1 | I9: c4 | J9: Arcadia | L9: d4 | M9: Whitney Young
C10: a5 | D10: Saratoga | F10: b5 | G10: TJHSST 1 | I10: c5 | J10: Temple City | L10: d5 | M10: Centennial
C11: a6 | D11: CCA 2 | F11: b6 | G11: Madison West 2 | I11: c6 | J11: Montgomery Blair 1 | L11: d6 | M11: Foothill
D13: Exile | G13: Fiction | J13: Goldrush | M13: Happiness
C14: e1 | D14: Stuyvesant | F14: f1 | G14: CCA 1 | I14: g1 | J14: Madison West 1 | L14: h1 | M14: Choate Rosemary Hall
C15: e2 | D15: Lynbrook 2 | F15: f2 | G15: Frazer 2 | I15: g2 | J15: MSJ 2 | L15: h2 | M15: Niskayuna
C16: e3 | D16: Frazer 1 | F16: f3 | G16: Wayzata | I16: g3 | J16: WWPN | L16: h3 | M16: TJHSST 2
C17: e4 | D17: MSJ 1 | F17: f4 | G17: Harvard Westlake | I17: g4 | J17: WWPS 2 | L17: h4 | M17: Hawken
C18: e5 | D18: Princeton Unified | F18: f5 | G18: Hunter College | I18: g5 | J18: Clements | L18: h5 | M18: Ward Melville
C19: e6 | D19: Montgomery Blair 2 | F19: f6 | G19: Granada Hills | I19: g6 | J19: Oak Avenue 1 | L19: h6 | M19: Lexington

Sheet Round Robin Scoring
B2: Round Robin Scoring
C5: Albatross | K5: Bottle
C6: =sum(D7:I12) -> 2510 | D6: Clovis North | E6: Palo Alto | F6: Tokay | G6: WWPS 1 | H6: Saratoga | I6: CCA 2 | K6: =sum(L7:Q12) -> 2168 | L6: California | M6: ASFA | N6: Middleton 1 | O6: Collierville 1 | P6: TJHSST 1 | Q6: Madison W 2
C7: Clovis North | E7: 104 | F7: 92 | G7: 28 | H7: 92 | I7: 32 | K7: California | M7: 32 | N7: 22 | O7: 82 | P7: 22 | Q7: 66
C8: Palo Alto | D8: 80 | F8: 200 | G8: 144 | H8: 84 | I8: 90 | K8: ASFA | L8: 118 | N8: 64 | O8: 80 | P8: 60 | Q8: 46
C9: Tokay | D9: 50 | E9: 12 | G9: 8 | H9: 18 | I9: 50 | K9: Middleton 1 | L9: 134 | M9: 90 | O9: 130 | P9: 130 | Q9: 194
C10: WWPS 1 | D10: 78 | E10: 78 | F10: 162 | H10: 106 | I10: 122 | K10: Collierville 1 | L10: 38 | M10: 58 | N10: 48 | P10: 46 | Q10: 76
C11: Saratoga | D11: 106 | E11: 74 | F11: 114 | G11: 84 | I11: 122 | K11: TJHSST 1 | L11: 144 | M11: 96 | N11: 68 | O11: 82 | Q11: 156
C12: CCA 2 | D12: 54 | E12: 100 | F12: 108 | G12: 68 | H12: 50 | K12: Madison W 2 | L12: 20 | M12: 28 | N12: 8 | O12: 26 | P12: 4
C14: Champagne | K14: Daylight
C15: =sum(D16:I21) -> 2354 | D15: 'Iolani | E15: Oak Avenue 2 | F15: Amador Valley | G15: Arcadia | H15: Temple City | I15: Blair 1 | K15: =sum(L16:Q21) -> 1978 | L15: Middleton 2 | M15: Lynbrook 1 | N15: Collierville 2 | O15: Whitney Young | P15: Centennial | Q15: Foothill
C16: 'Iolani | E16: 146 | F16: 60 | G16: 106 | H16: 18 | I16: 10 | K16: Middleton 2 | M16: 86 | N16: 48 | O16: 40 | P16: 44 | Q16: 12
C17: Oak Avenue 2 | D17: 8 | F17: 20 | G17: 16 | H17: 12 | I17: 8 | K17: Lynbrook 1 | L17: 96 | N17: 212 | O17: 64 | P17: 114 | Q17: 70
C18: Amador Valley | D18: 28 | E18: 62 | G18: 26 | H18: 50 | I18: 22 | K18: Collierville 2 | L18: 26 | M18: 4 | O18: 8 | P18: 22 | Q18: 18
C19: Arcadia | D19: 72 | E19: 64 | F19: 170 | H19: 126 | I19: 60 | K19: Whitney Young | L19: 82 | M19: 18 | N19: 72 | P19: 70 | Q19: 32
C20: Temple City | D20: 80 | E20: 132 | F20: 76 | G20: 28 | I20: 18 | K20: Centennial | L20: 100 | M20: 54 | N20: 68 | O20: 60 | Q20: 58
C21: Blair 1 | D21: 220 | E21: 188 | F21: 206 | G21: 140 | H21: 182 | K21: Foothill | L21: 80 | M21: 68 | N21: 138 | O21: 130 | P21: 84
C23: Exile | K23: Fiction
C24: =sum(D25:I30) -> 2568 | D24: Stuyvesant | E24: Lynbrook 2 | F24: Frazer 1 | G24: MSJ 1 | H24: Princeton | I24: Blair 2 | K24: =sum(L25:Q30) -> 2534 | L24: CCA 1 | M24: Frazer 2 | N24: Wayzata | O24: H-W | P24: Hunter | Q24: Granada Hills
C25: Stuyvesant | E25: 44 | F25: 56 | G25: 4 | H25: 86 | I25: 50 | K25: CCA 1 | M25: 102 | N25: 80 | O25: 156 | P25: 138 | Q25: 100
C26: Lynbrook 2 | D26: 128 | F26: 122 | G26: 82 | H26: 36 | I26: 86 | K26: Frazer 2 | L26: 100 | N26: 64 | O26: 22 | P26: 176 | Q26: 64
C27: Frazer 1 | D27: 134 | E27: 46 | G27: 80 | H27: 54 | I27: 76 | K27: Wayzata | L27: 92 | M27: 112 | O27: 140 | P27: 126 | Q27: 178
C28: MSJ 1 | D28: 184 | E28: 72 | F28: 142 | H28: 132 | I28: 152 | K28: H-W | L28: 36 | M28: 108 | N28: 74 | P28: 88 | Q28: 54
C29: Princeton | D29: 88 | E29: 166 | F29: 96 | G29: 50 | I29: 74 | K29: Hunter | L29: 30 | M29: 22 | N29: -4 | O29: 12 | Q29: 94
C30: Blair 2 | D30: 76 | E30: 70 | F30: 44 | G30: 22 | H30: 116 | K30: Granada Hills | L30: 28 | M30: 82 | N30: 66 | O30: 144 | P30: 50
C32: Goldrush | K32: Happiness
C33: =sum(D34:I39) -> 2362 | D33: Madison W 1 | E33: MSJ 2 | F33: WWPN | G33: WWPS 2 | H33: Clements | I33: Oak Avenue 1 | K33: =sum(L34:Q39) -> 2538 | L33: Choate | M33: Niskayuna | N33: TJHSST 2 | O33: Hawken | P33: Ward Melville | Q33: Lexington
C34: Madison W 1 | E34: 22 | F34: 14 | G34: 38 | H34: 22 | I34: 50 | K34: Choate | M34: 8 | N34: 4 | O34: 30 | P34: 18 | Q34: 30
C35: MSJ 2 | D35: 118 | F35: 92 | G35: 80 | H35: 90 | I35: 116 | K35: Niskayuna | L35: 144 | N35: 64 | O35: 62 | P35: 68 | Q35: 64
C36: WWPN | D36: 94 | E36: 76 | G36: 124 | H36: 92 | I36: 146 | K36: TJHSST 2 | L36: 138 | M36: 112 | O36: 148 | P36: 88 | Q36: 112
C37: WWPS 2 | D37: 86 | E37: 38 | F37: 66 | H37: 10 | I37: 54 | K37: Hawken | L37: 130 | M37: 46 | N37: 50 | P37: 24 | Q37: 18
C38: Clements | D38: 190 | E38: 92 | F38: 112 | G38: 224 | I38: 162 | K38: Ward Melville | L38: 180 | M38: 110 | N38: 74 | O38: 152 | Q38: 56
C39: Oak Avenue 1 | D39: 20 | E39: 50 | F39: 36 | G39: 52 | H39: -4 | K39: Lexington | L39: 110 | M39: 82 | N39: 106 | O39: 164 | P39: 146

Sheet DE Seeding
B1: Team Rank | C1: Team Name | D1: Group | E1: Championship Points | F1: Raw Points | H1: Round Scores (in no particular order)
B2: 1 | C2: Montgomery Blair 1 | D2: champagne | E2: 10 | F2: =sum(H2:N2) -> 936 | H2: ='Round Robin Scoring'!D21 -> 220 | I2: ='Round Robin Scoring'!E21 -> 188 | J2: ='Round Robin Scoring'!F21 -> 206 | K2: ='Round Robin Scoring'!G21 -> 140 | L2: ='Round Robin Scoring'!H21 -> 182
B3: 2 | C3: Clements | D3: goldrush | E3: 10 | F3: =sum(H3:N3) -> 780 | H3: ='Round Robin Scoring'!D38 -> 190 | I3: ='Round Robin Scoring'!E38 -> 92 | J3: ='Round Robin Scoring'!F38 -> 112 | K3: ='Round Robin Scoring'!G38 -> 224 | L3: ='Round Robin Scoring'!I38 -> 162
B4: 3 | C4: Middleton 1 | D4: bottle | E4: 10 | F4: =sum(H4:N4) -> 678 | H4: ='Round Robin Scoring'!L9 -> 134 | I4: ='Round Robin Scoring'!M9 -> 90 | J4: ='Round Robin Scoring'!O9 -> 130 | K4: ='Round Robin Scoring'!P9 -> 130 | L4: ='Round Robin Scoring'!Q9 -> 194
B5: 4 | C5: Wayzata | D5: fiction | E5: 10 | F5: =sum(H5:N5) -> 648 | H5: ='Round Robin Scoring'!L27 -> 92 | I5: ='Round Robin Scoring'!M27 -> 112 | J5: ='Round Robin Scoring'!O27 -> 140 | K5: ='Round Robin Scoring'!P27 -> 126 | L5: ='Round Robin Scoring'!Q27 -> 178
B6: 5 | C6: TJHSST 2 | D6: happiness | E6: 10 | F6: =sum(H6:N6) -> 598 | H6: ='Round Robin Scoring'!L36 -> 138 | I6: ='Round Robin Scoring'!M36 -> 112 | J6: ='Round Robin Scoring'!O36 -> 148 | K6: ='Round Robin Scoring'!P36 -> 88 | L6: ='Round Robin Scoring'!Q36 -> 112
B7: 6 | C7: Lynbrook 1 | D7: daylight | E7: 10 | F7: =sum(H7:N7) -> 556 | H7: ='Round Robin Scoring'!L17 -> 96 | I7: ='Round Robin Scoring'!N17 -> 212 | J7: ='Round Robin Scoring'!O17 -> 64 | K7: ='Round Robin Scoring'!P17 -> 114 | L7: ='Round Robin Scoring'!Q17 -> 70
B8: 7 | C8: MSJ 1 | D8: exile | E8: 8 | F8: =sum(H8:N8) -> 682 | H8: ='Round Robin Scoring'!D28 -> 184 | I8: ='Round Robin Scoring'!E28 -> 72 | J8: ='Round Robin Scoring'!F28 -> 142 | K8: ='Round Robin Scoring'!H28 -> 132 | L8: ='Round Robin Scoring'!I28 -> 152
B9: 8 | C9: Lexington | D9: happiness | E9: 8 | F9: =sum(H9:N9) -> 608 | H9: ='Round Robin Scoring'!L39 -> 110 | I9: ='Round Robin Scoring'!M39 -> 82 | J9: ='Round Robin Scoring'!N39 -> 106 | K9: ='Round Robin Scoring'!O39 -> 164 | L9: ='Round Robin Scoring'!P39 -> 146
B10: 9 | C10: CCA 1 | D10: fiction | E10: 8 | F10: =sum(H10:N10) -> 576 | H10: ='Round Robin Scoring'!M25 -> 102 | I10: ='Round Robin Scoring'!N25 -> 80 | J10: ='Round Robin Scoring'!O25 -> 156 | K10: ='Round Robin Scoring'!P25 -> 138 | L10: ='Round Robin Scoring'!Q25 -> 100
B11: 10 | C11: WWPS 1 | D11: albatross | E11: 8 | F11: =sum(H11:N11) -> 546 | H11: ='Round Robin Scoring'!D10 -> 78 | I11: ='Round Robin Scoring'!E10 -> 78 | J11: ='Round Robin Scoring'!F10 -> 162 | K11: ='Round Robin Scoring'!H10 -> 106 | L11: ='Round Robin Scoring'!I10 -> 122
B12: 11 | C12: TJHSST 1 | D12: bottle | E12: 8 | F12: =sum(H12:N12) -> 546 | H12: ='Round Robin Scoring'!L11 -> 144 | I12: ='Round Robin Scoring'!M11 -> 96 | J12: ='Round Robin Scoring'!N11 -> 68 | K12: ='Round Robin Scoring'!O11 -> 82 | L12: ='Round Robin Scoring'!Q11 -> 156
B13: 12 | C13: Foothill | D13: daylight | E13: 8 | F13: =sum(H13:N13) -> 500 | H13: ='Round Robin Scoring'!L21 -> 80 | I13: ='Round Robin Scoring'!M21 -> 68 | J13: ='Round Robin Scoring'!N21 -> 138 | K13: ='Round Robin Scoring'!O21 -> 130 | L13: ='Round Robin Scoring'!P21 -> 84
B14: 13 | C14: MSJ 2 | D14: goldrush | E14: 8 | F14: =sum(H14:N14) -> 496 | H14: ='Round Robin Scoring'!D35 -> 118 | I14: ='Round Robin Scoring'!F35 -> 92 | J14: ='Round Robin Scoring'!G35 -> 80 | K14: ='Round Robin Scoring'!H35 -> 90 | L14: ='Round Robin Scoring'!I35 -> 116
B15: 14 | C15: Lynbrook 2 | D15: exile | E15: 8 | F15: =sum(H15:N15) -> 454 | H15: ='Round Robin Scoring'!D26 -> 128 | I15: ='Round Robin Scoring'!F26 -> 122 | J15: ='Round Robin Scoring'!G26 -> 82 | K15: ='Round Robin Scoring'!H26 -> 36 | L15: ='Round Robin Scoring'!I26 -> 86
B16: 15 | C16: Palo Alto | D16: albatross | E16: 6 | F16: =sum(H16:N16) -> 598 | H16: ='Round Robin Scoring'!D8 -> 80 | I16: ='Round Robin Scoring'!F8 -> 200 | J16: ='Round Robin Scoring'!G8 -> 144 | K16: ='Round Robin Scoring'!H8 -> 84 | L16: ='Round Robin Scoring'!I8 -> 90
B17: 16 | C17: Ward Melville | D17: happiness | E17: 6 | F17: =sum(H17:N17) -> 572 | H17: ='Round Robin Scoring'!L38 -> 180 | I17: ='Round Robin Scoring'!M38 -> 110 | J17: ='Round Robin Scoring'!N38 -> 74 | K17: ='Round Robin Scoring'!O38 -> 152 | L17: ='Round Robin Scoring'!Q38 -> 56
B18: 17 | C18: WWPN | D18: goldrush | E18: 6 | F18: =sum(H18:N18) -> 532 | H18: ='Round Robin Scoring'!D36 -> 94 | I18: ='Round Robin Scoring'!E36 -> 76 | J18: ='Round Robin Scoring'!G36 -> 124 | K18: ='Round Robin Scoring'!H36 -> 92 | L18: ='Round Robin Scoring'!I36 -> 146
B19: 18 | C19: Saratoga | D19: albatross | E19: 6 | F19: =sum(H19:N19) -> 500 | H19: ='Round Robin Scoring'!D11 -> 106 | I19: ='Round Robin Scoring'!E11 -> 74 | J19: ='Round Robin Scoring'!F11 -> 114 | K19: ='Round Robin Scoring'!G11 -> 84 | L19: ='Round Robin Scoring'!I11 -> 122
B20: 19 | C20: Arcadia | D20: champagne | E20: 6 | F20: =sum(H20:N20) -> 492 | H20: ='Round Robin Scoring'!D19 -> 72 | I20: ='Round Robin Scoring'!E19 -> 64 | J20: ='Round Robin Scoring'!F19 -> 170 | K20: ='Round Robin Scoring'!H19 -> 126 | L20: ='Round Robin Scoring'!I19 -> 60
B21: 20 | C21: Princeton Unified | D21: exile | E21: 6 | F21: =sum(H21:N21) -> 474 | H21: ='Round Robin Scoring'!D29 -> 88 | I21: ='Round Robin Scoring'!E29 -> 166 | J21: ='Round Robin Scoring'!F29 -> 96 | K21: ='Round Robin Scoring'!G29 -> 50 | L21: ='Round Robin Scoring'!I29 -> 74
B22: 21 | C22: CCA 2 | D22: albatross | E22: 6 | F22: =sum(H22:N22) -> 380 | H22: ='Round Robin Scoring'!D12 -> 54 | I22: ='Round Robin Scoring'!E12 -> 100 | J22: ='Round Robin Scoring'!F12 -> 108 | K22: ='Round Robin Scoring'!G12 -> 68 | L22: ='Round Robin Scoring'!H12 -> 50
B23: 22 | C23: ASFA | D23: bottle | E23: 6 | F23: =sum(H23:N23) -> 368 | H23: ='Round Robin Scoring'!L8 -> 118 | I23: ='Round Robin Scoring'!N8 -> 64 | J23: ='Round Robin Scoring'!O8 -> 80 | K23: ='Round Robin Scoring'!P8 -> 60 | L23: ='Round Robin Scoring'!Q8 -> 46
B24: 23 | C24: 'Iolani | D24: champagne | E24: 6 | F24: =sum(H24:N24) -> 340 | H24: ='Round Robin Scoring'!$E16 -> 146 | I24: ='Round Robin Scoring'!F16 -> 60 | J24: ='Round Robin Scoring'!G16 -> 106 | K24: ='Round Robin Scoring'!H16 -> 18 | L24: ='Round Robin Scoring'!I16 -> 10
B25: 24 | C25: Temple City | D25: champagne | E25: 6 | F25: =sum(H25:N25) -> 334 | H25: ='Round Robin Scoring'!D20 -> 80 | I25: ='Round Robin Scoring'!E20 -> 132 | J25: ='Round Robin Scoring'!F20 -> 76 | K25: ='Round Robin Scoring'!G20 -> 28 | L25: ='Round Robin Scoring'!I20 -> 18
B26: 25 | C26: Whitney Young | D26: daylight | E26: 6 | F26: =sum(H26:N26) -> 274 | H26: ='Round Robin Scoring'!L19 -> 82 | I26: ='Round Robin Scoring'!M19 -> 18 | J26: ='Round Robin Scoring'!N19 -> 72 | K26: ='Round Robin Scoring'!P19 -> 70 | L26: ='Round Robin Scoring'!Q19 -> 32
B27: 26 | C27: Niskayuna | D27: happiness | E27: 4 | F27: =sum(H27:N27) -> 402 | H27: ='Round Robin Scoring'!L35 -> 144 | I27: ='Round Robin Scoring'!N35 -> 64 | J27: ='Round Robin Scoring'!O35 -> 62 | K27: ='Round Robin Scoring'!P35 -> 68 | L27: ='Round Robin Scoring'!Q35 -> 64
B28: 27 | C28: Frazer 1 | D28: exile | E28: 4 | F28: =sum(H28:N28) -> 390 | H28: ='Round Robin Scoring'!D27 -> 134 | I28: ='Round Robin Scoring'!E27 -> 46 | J28: ='Round Robin Scoring'!G27 -> 80 | K28: ='Round Robin Scoring'!H27 -> 54 | L28: ='Round Robin Scoring'!I27 -> 76
B29: 28 | C29: Granada Hills | D29: fiction | E29: 4 | F29: =sum(H29:N29) -> 370 | H29: ='Round Robin Scoring'!L30 -> 28 | I29: ='Round Robin Scoring'!M30 -> 82 | J29: ='Round Robin Scoring'!N30 -> 66 | K29: ='Round Robin Scoring'!O30 -> 144 | L29: ='Round Robin Scoring'!P30 -> 50
B30: 29 | C30: Harvard Westlake | D30: fiction | E30: 4 | F30: =sum(H30:N30) -> 360 | H30: ='Round Robin Scoring'!L28 -> 36 | I30: ='Round Robin Scoring'!M28 -> 108 | J30: ='Round Robin Scoring'!N28 -> 74 | K30: ='Round Robin Scoring'!P28 -> 88 | L30: ='Round Robin Scoring'!Q28 -> 54
B31: 30 | C31: Clovis North | D31: albatross | E31: 4 | F31: =sum(H31:N31) -> 348 | H31: ='Round Robin Scoring'!$E7 -> 104 | I31: ='Round Robin Scoring'!F7 -> 92 | J31: ='Round Robin Scoring'!G7 -> 28 | K31: ='Round Robin Scoring'!H7 -> 92 | L31: ='Round Robin Scoring'!I7 -> 32
B32: 31 | C32: Centennial | D32: daylight | E32: 4 | F32: =sum(H32:N32) -> 340 | H32: ='Round Robin Scoring'!L20 -> 100 | I32: ='Round Robin Scoring'!M20 -> 54 | J32: ='Round Robin Scoring'!N20 -> 68 | K32: ='Round Robin Scoring'!O20 -> 60 | L32: ='Round Robin Scoring'!Q20 -> 58
B33: 32 | C33: Montgomery Blair 2 | D33: exile | E33: 4 | F33: =sum(H33:N33) -> 328 | H33: ='Round Robin Scoring'!D30 -> 76 | I33: ='Round Robin Scoring'!E30 -> 70 | J33: ='Round Robin Scoring'!F30 -> 44 | K33: ='Round Robin Scoring'!G30 -> 22 | L33: ='Round Robin Scoring'!H30 -> 116
B34: 33 | C34: WWPS 2 | D34: goldrush | E34: 4 | F34: =sum(H34:N34) -> 254 | H34: ='Round Robin Scoring'!D37 -> 86 | I34: ='Round Robin Scoring'!E37 -> 38 | J34: ='Round Robin Scoring'!F37 -> 66 | K34: ='Round Robin Scoring'!H37 -> 10 | L34: ='Round Robin Scoring'!I37 -> 54
B35: 34 | C35: California | D35: bottle | E35: 4 | F35: =sum(H35:N35) -> 224 | H35: ='Round Robin Scoring'!M7 -> 32 | I35: ='Round Robin Scoring'!N7 -> 22 | J35: ='Round Robin Scoring'!O7 -> 82 | K35: ='Round Robin Scoring'!P7 -> 22 | L35: ='Round Robin Scoring'!Q7 -> 66
B36: 35 | C36: Frazer 2 | D36: fiction | E36: 2 | F36: =sum(H36:N36) -> 426 | H36: ='Round Robin Scoring'!L26 -> 100 | I36: ='Round Robin Scoring'!N26 -> 64 | J36: ='Round Robin Scoring'!O26 -> 22 | K36: ='Round Robin Scoring'!P26 -> 176 | L36: ='Round Robin Scoring'!Q26 -> 64
B37: 36 | C37: Hawken | D37: happiness | E37: 2 | F37: =sum(H37:N37) -> 268 | H37: ='Round Robin Scoring'!L37 -> 130 | I37: ='Round Robin Scoring'!M37 -> 46 | J37: ='Round Robin Scoring'!N37 -> 50 | K37: ='Round Robin Scoring'!P37 -> 24 | L37: ='Round Robin Scoring'!Q37 -> 18
B38: 37 | C38: Collierville 1 | D38: bottle | E38: 2 | F38: =sum(H38:N38) -> 266 | H38: ='Round Robin Scoring'!L10 -> 38 | I38: ='Round Robin Scoring'!M10 -> 58 | J38: ='Round Robin Scoring'!N10 -> 48 | K38: ='Round Robin Scoring'!P10 -> 46 | L38: ='Round Robin Scoring'!Q10 -> 76
B39: 38 | C39: Middleton 2 | D39: daylight | E39: 2 | F39: =sum(H39:N39) -> 230 | H39: ='Round Robin Scoring'!M16 -> 86 | I39: ='Round Robin Scoring'!N16 -> 48 | J39: ='Round Robin Scoring'!O16 -> 40 | K39: ='Round Robin Scoring'!P16 -> 44 | L39: ='Round Robin Scoring'!Q16 -> 12
B40: 39 | C40: Amador Valley | D40: champagne | E40: 2 | F40: =sum(H40:N40) -> 188 | H40: ='Round Robin Scoring'!D18 -> 28 | I40: ='Round Robin Scoring'!E18 -> 62 | J40: ='Round Robin Scoring'!G18 -> 26 | K40: ='Round Robin Scoring'!H18 -> 50 | L40: ='Round Robin Scoring'!I18 -> 22
...

Sheet Double Elimination Bracket
B1: DE1 | E1: DE2 | G1: DE3 | J1: DE4 | L1: DE5 | N1: DE6 | P1: FINALS BO3
B2: 12:40-13:15 PT | E2: 13:15-13:50 PT | G2: 13:50-14:25 PT | J2: 14:45-15:15 PT | L2: 15:15-15:45 PT | N2: 15:45-16:15 PT | P2: 16:15-17:15 PT | S2: 1st: | T2: Montgomery Blair 1
S3: 2nd: | T3: MSJ 1
A4: 1 | B4: Montgomery Blair 1 | C4: 98 | S4: 3rd: | T4: TJHSST 2
A5: Albatross-1 | G5: Lexington | H5: 10 | S5: 4th: | T5: Lexington
A6: 8 | B6: Lexington | C6: 110 | S6: 5-6th: | T6: Clements, Middleton 1
G7: Albatross-1 | L7: TJHSST 2 | M7: 40
A8: 4 | B8: Wayzata | C8: 46
A9: Albatross-2 | G9: TJHSST 2 | H9: 44
A10: 5 | B10: TJHSST 2 | C10: 100
L11: Cornelia Street | P11: MSJ 1 | Q11: 6 | R11: -8
A12: 2 | B12: Clements | C12: 48 | U12: Mods | V12: 52.81
A13: Bottle-1 | G13: MSJ 1 | H13: 102
A14: 7 | B14: MSJ 1 | C14: 122 | W14: Anurag S
G15: Albatross-2 | L15: MSJ 1 | M15: 104
A16: 3 | B16: Middleton 1 | C16: 128 | P16: Cornelia Street | T16: Montgomery Blair 1 | V16: 31
A17: Bottle-2 | G17: Middleton 1 | H17: 24 | M17: LC-1 | N17: TJHSST 2 | O17: 26
A18: 6 | B18: Lynbrook 1 | C18: 62
I19: LA-1 | J19: Lexington | K19: 96
D20: LB-2 | E20: Lynbrook 1 | F20: 98
A21: 9 | B21: CCA 1 | C21: 78 | E21: Bottle-1 | G21: Lynbrook 1 | H21: 60 | J21: Cornelia Street | L21: Lexington | M21: 54 | N21: Cornelia Street | P21: Montgomery Blair 1 | Q21: 18 | R21: 22
A22: Champagne-1 | E22: Ward Melville | F22: 34
A23: 16 | B23: Ward Melville | C23: 102 | G23: Champagne-1 | J23: Clements | K23: 62
D24: LB-1 | E24: Clements | F24: 74
A25: 12 | B25: Foothill | C25: 18 | E25: Bottle-2 | G25: Clements | H25: 68 | L25: Scott Street | N25: Montgomery Blair 1 | O25: 98
A26: Champagne-2 | E26: MSJ 2 | F26: 28
A27: 13 | B27: MSJ 2 | C27: 50 | I27: LA-2 | J27: Middleton 1 | K27: 66
D28: LA-2 | E28: Wayzata | F28: 52
A29: 10 | B29: WWPS 1 | C29: 60 | E29: Champagne-1 | G29: Palo Alto | H29: 26 | J29: Scott Street | L29: Montgomery Blair 1 | M29: 94
A30: Daylight-1 | E30: Palo Alto | F30: 136
A31: 15 | B31: Palo Alto | C31: 86 | G31: Champagne-2 | J31: Montgomery Blair 1 | K31: 96
D32: LA-1 | E32: Montgomery Blair 1 | F32: 150
A33: 11 | B33: TJHSST 1 | C33: 50 | E33: Champagne-2 | G33: Montgomery Blair 1 | H33: 90
A34: Daylight-2 | E34: Lynbrook 2 | F34: 10
A35: 14 | B35: Lynbrook 2 | C35: 80

Sheet Individual Biology Stats
A1: name | B1: Games Played | C1: Tossups Heard | D1: Buzzes | E1: Points | F1: PP4TUH | G1: Negs | H1: Negs/4TUH | I1: Accuracy
A2: d2 selena y [d2 lynbrook 1] | B2: 5 | C2: 20 | D2: 20 | E2: =F2/4*C2 -> 80 | F2: 16 | G2: =H2/4*C2 -> 0 | H2: 0 | I2: 1
A3: g3 krutharth v [g3 wwpn] | B3: 5 | C3: 20 | D3: 18 | E3: =F3/4*C3 -> 68 | F3: 13.6 | G3: =H3/4*C3 -> 0 | H3: 0 | I3: 0.944
A4: a4 arjun d [a4 wwps 1] | B4: 5 | C4: 20 | D4: 14 | E4: =F4/4*C4 -> 56 | F4: 11.2 | G4: =H4/4*C4 -> 0 | H4: 0 | I4: 1
A5: c6 kian d [c6 blair 1] | B5: 5 | C5: 20 | D5: 15 | E5: =F5/4*C5 -> 52 | F5: 10.4 | G5: =H5/4*C5 -> 1 | H5: 0.2 | I5: 0.933
A6: b1 lucas c [b1 california] | B6: 5 | C6: 20 | D6: 13 | E6: =F6/4*C6 -> 48 | F6: 9.6 | G6: =H6/4*C6 -> 0 | H6: 0 | I6: 0.923
A7: b3 owen w [b3 middleton 1] | B7: 5 | C7: 20 | D7: 16 | E7: =F7/4*C7 -> 48 | F7: 9.6 | G7: =H7/4*C7 -> 2 | H7: 0.4 | I7: 0.875
A8: f4 olivia s [f4 harvard westlake] | B8: 5 | C8: 20 | D8: 14 | E8: =F8/4*C8 -> 40 | F8: 8 | G8: =H8/4*C8 -> 2 | H8: 0.4 | I8: 0.857
A9: h5 anna x [h5 ward melville] | B9: 5 | C9: 20 | D9: 13 | E9: =F9/4*C9 -> 40 | F9: 8 | G9: =H9/4*C9 -> 1 | H9: 0.2 | I9: 0.846
A10: f1 sean y [f1 cca 1] | B10: 5 | C10: 20 | D10: 15 | E10: =F10/4*C10 -> 40 | F10: 8 | G10: =H10/4*C10 -> 2 | H10: 0.4 | I10: 0.8
A11: d5 matthew y [d5 centennial] | B11: 5 | C11: 20 | D11: 11 | E11: =F11/4*C11 -> 36 | F11: 7.2 | G11: =H11/4*C11 -> 1 | H11: 0.2 | I11: 0.909
A12: e6 meghna s [e6 montgomery blair 2] | B12: 5 | C12: 20 | D12: 13 | E12: =F12/4*C12 -> 36 | F12: 7.2 | G12: =H12/4*C12 -> 0 | H12: 0 | I12: 0.692
A13: c4 avani a [c4 arcadia] | B13: 5 | C13: 20 | D13: 13 | E13: 36 | F13: 7.2 | G13: =H13/4*C13 -> 0 | H13: 0 | I13: =8/13 -> 0.61538462
A14: g5 yale z [g5 clements] | B14: 5 | C14: 20 | D14: 8 | E14: =F14/4*C14 -> 32 | F14: 6.4 | G14: =H14/4*C14 -> 0 | H14: 0 | I14: 1
A15: h3 aaryan s [h3 tjhsst 2] | B15: 5 | C15: 20 | D15: 11 | E15: =F15/4*C15 -> 32 | F15: 6.4 | G15: =H15/4*C15 -> 1 | H15: 0.2 | I15: 0.818
A16: e1 philip z [e1 stuyvesant] | B16: 5 | C16: 20 | D16: 8 | E16: =F16/4*C16 -> 28 | F16: 5.6 | G16: =H16/4*C16 -> 0 | H16: 0 | I16: 0.875
A17: g2 aravind m [g2 msj 2] | B17: 5 | C17: 20 | D17: 10 | E17: =F17/4*C17 -> 28 | F17: 5.6 | G17: =H17/4*C17 -> 1 | H17: 0.2 | I17: 0.8
A18: c5 jason l [c5 temple city] | B18: 5 | C18: 20 | D18: 9 | E18: =F18/4*C18 -> 28 | F18: 5.6 | G18: =H18/4*C18 -> 0 | H18: 0 | I18: 0.778
A19: h2 daniel y [h2 niskayuna] | B19: 5 | C19: 20 | D19: 6 | E19: =F19/4*C19 -> 24 | F19: 4.8 | G19: =H19/4*C19 -> 0 | H19: 0 | I19: 1
A20: b4 rehan k [b4 collierville 1] | B20: 5 | C20: 20 | D20: 8 | E20: =F20/4*C20 -> 24 | F20: 4.8 | G20: =H20/4*C20 -> 0 | H20: 0 | I20: 0.75
A21: a3 alexis e [a3 tokay] | B21: 5 | C21: 20 | D21: 9 | E21: =F21/4*C21 -> 24 | F21: 4.8 | G21: =H21/4*C21 -> 0 | H21: 0 | I21: 0.667
A22: a1 renard w [a1 clovis north] | B22: 5 | C22: 20 | D22: 10 | E22: =F22/4*C22 -> 24 | F22: 4.8 | G22: =H22/4*C22 -> 0 | H22: 0 | I22: 0.6
A23: d6 bhagirath(buggy) b [d6 foothill] | B23: 5 | C23: 20 | D23: 17 | E23: =F23/4*C23 -> 24 | F23: 4.8 | G23: =H23/4*C23 -> 4 | H23: 0.8 | I23: 0.588
A24: c1 ryan e [c1 iolani] | B24: 2 | C24: 8 | D24: 5 | E24: =F24/4*C24 -> 20 | F24: 10 | G24: =H24/4*C24 -> 0 | H24: 0 | I24: 1
A25: f6 bianca g [f6 granada] | B25: 5 | C25: 20 | D25: 5 | E25: =F25/4*C25 -> 20 | F25: 4 | G25: =H25/4*C25 -> 0 | H25: 0 | I25: 1
... A42: h6 shreyas e [h6 lexington] | B42: 4 | C42: 16 | D42: 4 | E42: =F42/4*C42 -> 12 | F42: 3 | G42: =H42/4*C42 -> 0 | H42: 0 | I42: 0.75
A43: g1 rohan a [g1 madison west 1] | B43: 4 | C43: 15 | D43: 8 | E43: 12 | F43: 3 | G43: =H43/4*C43 -> 1.875 | H43: 0.5 | I43: 0.625
A44: e4 theenash s [e4 msj 1] | B44: 5 | C44: 20 | D44: 15 | E44: =F44/4*C44 -> 12 | F44: 2.4 | G44: =H44/4*C44 -> 6 | H44: 1.2 | I44: 0.6
A45: g4 rishi p [g4 wwps 2] | B45: 5 | C45: 20 | D45: 11 | E45: =F45/4*C45 -> 12 | F45: 2.4 | G45: =H45/4*C45 -> 3 | H45: 0.6 | I45: 0.545
A46: a2 forrest c [a2 palo alto] | B46: 5 | C46: 20 | D46: 10 | E46: =F46/4*C46 -> 12 | F46: 2.4 | G46: =H46/4*C46 -> 2 | H46: 0.4 | I46: 0.5
A47: e3 jimmy j [e3 frazer 1] | B47: 5 | C47: 20 | D47: 6 | E47: =F47/4*C47 -> 12 | F47: 2.4 | G47: =H47/4*C47 -> 0 | H47: 0 | I47: 0.5
A48: e2 ameyaa r [e2 lynbrook 2] | B48: 5 | C48: 20 | D48: 7 | E48: =F48/4*C48 -> 12 | F48: 2.4 | G48: =H48/4*C48 -> 0 | H48: 0 | I48: 0.429
A49: b6 chandrima s [b6 madison west 2] | B49: 3 | C49: 12 | D49: 2 | E49: =F49/4*C49 -> 8.01 | F49: 2.67 | G49: =H49/4*C49 -> 0 | H49: 0 | I49: 1
A50: h6 owen j [h6 lexington] | B50: 3 | C50: 12 | D50: 2 | E50: =F50/4*C50 -> 8.01 | F50: 2.67 | G50: =H50/4*C50 -> 0 | H50: 0 | I50: 1
A51: f3 warren w [f3 wayzata] | B51: 3 | C51: 12 | D51: 5 | E51: =F51/4*C51 -> 8.01 | F51: 2.67 | G51: =H51/4*C51 -> 0.99 | H51: 0.33 | I51: 0.6
A52: e5 ivy h [e5 princeton unified] | B52: 3 | C52: 12 | D52: 4 | E52: =F52/4*C52 -> 8.01 | F52: 2.67 | G52: =H52/4*C52 -> 0 | H52: 0 | I52: 0.5
A53: d3 bethany c [d3 collierville 2] | B53: 3 | C53: 12 | D53: 5 | E53: =F53/4*C53 -> 8.01 | F53: 2.67 | G53: =H53/4*C53 -> 0 | H53: 0 | I53: 0.4
A54: a1 ethan w [a1 clovis north] | B54: 5 | C54: 20 | D54: 2 | E54: =F54/4*C54 -> 8 | F54: 1.6 | G54: =H54/4*C54 -> 0 | H54: 0 | I54: 1
A55: a6 haiyue m [a6 cca 2] | B55: 5 | C55: 20 | D55: 2 | E55: =F55/4*C55 -> 8 | F55: 1.6 | G55: =H55/4*C55 -> 0 | H55: 0 | I55: 1
... A206: f5 gabe f [f5 hunter] | B206: 5 | C206: 20 | D206: 4 | E206: =F206/4*C206 -> -8 | F206: -1.6 | G206: =H206/4*C206 -> 2 | H206: 0.4 | I206: 0

Sheet Individual Chemistry Stats
A1: name | B1: Games Played | C1: Tossups Heard | D1: Buzzes | E1: Points | F1: PP4TUH | G1: Negs | H1: Negs/4TUH | I1: Accuracy
A2: b3 harry j [b3 middleton 1] | B2: 5 | C2: 20 | D2: 17 | E2: =F2/4*C2 -> 60 | F2: 12 | G2: =H2/4*C2 -> 1 | H2: 0.2 | I2: 0.941
A3: e2 sophia f [e2 lynbrook 2] | B3: 5 | C3: 20 | D3: 14 | E3: =F3/4*C3 -> 52 | F3: 10.4 | G3: =H3/4*C3 -> 0 | H3: 0 | I3: 0.929
A4: f6 kaiyo i [f6 granada] | B4: 5 | C4: 20 | D4: 18 | E4: =F4/4*C4 -> 52 | F4: 10.4 | G4: =H4/4*C4 -> 0 | H4: 0 | I4: 0.722
A5: g5 yale z [g5 clements] | B5: 5 | C5: 20 | D5: 18 | E5: =F5/4*C5 -> 48 | F5: 9.6 | G5: =H5/4*C5 -> 2 | H5: 0.4 | I5: 0.778
A6: a4 sanjay o [a4 wwps 1] | B6: 5 | C6: 20 | D6: 12 | E6: =F6/4*C6 -> 40 | F6: 8 | G6: =H6/4*C6 -> 1 | H6: 0.2 | I6: 0.917
A7: g2 arnav g [g2 msj 2] | B7: 5 | C7: 20 | D7: 12 | E7: =F7/4*C7 -> 40 | F7: 8 | G7: =H7/4*C7 -> 0 | H7: 0 | I7: 0.833
A8: e4 theenash s [e4 msj 1] | B8: 5 | C8: 20 | D8: 15 | E8: =F8/4*C8 -> 40 | F8: 8 | G8: =H8/4*C8 -> 2 | H8: 0.4 | I8: 0.8
A9: c6 yunyi l [c6 blair 1] | B9: 5 | C9: 20 | D9: 11 | E9: =F9/4*C9 -> 36 | F9: 7.2 | G9: =H9/4*C9 -> 1 | H9: 0.2 | I9: 0.909
A10: f3 kevin q [f3 wayzata] | B10: 5 | C10: 20 | D10: 14 | E10: =F10/4*C10 -> 36 | F10: 7.2 | G10: =H10/4*C10 -> 2 | H10: 0.4 | I10: 0.786
A11: g3 krutharth v [g3 wwpn] | B11: 5 | C11: 20 | D11: 16 | E11: =F11/4*C11 -> 36 | F11: 7.2 | G11: =H11/4*C11 -> 3 | H11: 0.6 | I11: 0.75
A12: h6 william j [h6 lexington] | B12: 5 | C12: 20 | D12: 10 | E12: =F12/4*C12 -> 32 | F12: 6.4 | G12: =H12/4*C12 -> 1 | H12: 0.2 | I12: 0.9
A13: e3 jimmy j [e3 frazer 1] | B13: 5 | C13: 20 | D13: 11 | E13: =F13/4*C13 -> 32 | F13: 6.4 | G13: =H13/4*C13 -> 1 | H13: 0.2 | I13: 0.818
... A19: b2 akhil b [b2 asfa] | B19: 5 | C19: 20 | D19: 11 | E19: =F19/4*C19 -> 28 | F19: 5.6 | G19: =H19/4*C19 -> 2 | H19: 0.4 | I19: 0.818
A20: c4 ethan w [c4 arcadia] | B20: 5 | C20: 20 | D20: 13 | E20: =F20/4*C20 -> 28 | F20: 5.6 | G20: =H20/4*C20 -> 2.5 | H20: 0.5 | I20: =9/13 -> 0.69230769
A21: c1 min s [c1 iolani] | B21: 4 | C21: 16 | D21: 11 | E21: =F21/4*C21 -> 28 | F21: 7 | G21: =H21/4*C21 -> 0 | H21: 0 | I21: 0.636
A22: a5 alex g [a5 saratoga] | B22: 5 | C22: 20 | D22: 9 | E22: =F22/4*C22 -> 24 | F22: 4.8 | G22: =H22/4*C22 -> 0 | H22: 0 | I22: 0.667
A23: a1 justin d [a1 clovis north] | B23: 5 | C23: 20 | D23: 14 | E23: =F23/4*C23 -> 24 | F23: 4.8 | G23: =H23/4*C23 -> 3 | H23: 0.6 | I23: 0.643
A24: h4 daniel x [h4 hawken] | B24: 5 | C24: 20 | D24: 11 | E24: =F24/4*C24 -> 24 | F24: 4.8 | G24: =H24/4*C24 -> 1 | H24: 0.2 | I24: 0.636
A25: f1 sean y [f1 cca 1] | B25: 5 | C25: 20 | D25: 13 | E25: =F25/4*C25 -> 24 | F25: 4.8 | G25: =H25/4*C25 -> 2 | H25: 0.4 | I25: 0.615
A26: c5 ethan d [c5 temple city] | B26: 5 | C26: 20 | D26: 11 | E26: =F26/4*C26 -> 24 | F26: 4.8 | G26: =H26/4*C26 -> 0 | H26: 0 | I26: 0.545
A27: d2 selena y [d2 lynbrook 1] | B27: 5 | C27: 20 | D27: 13 | E27: =F27/4*C27 -> 24 | F27: 4.8 | G27: =H27/4*C27 -> 1 | H27: 0.2 | I27: 0.538
A28: e5 josh s [e5 princeton unified] | B28: 5 | C28: 20 | D28: 8 | E28: =F28/4*C28 -> 20 | F28: 4 | G28: =H28/4*C28 -> 1 | H28: 0.2 | I28: 0.75
A29: a2 forrest c [a2 palo alto] | B29: 5 | C29: 20 | D29: 11 | E29: =F29/4*C29 -> 20 | F29: 4 | G29: =H29/4*C29 -> 2 | H29: 0.4 | I29: 0.636
A30: d2 sohil r [d2 lynbrook 1] | B30: 1 | C30: 4 | D30: 4 | E30: =F30/4*C30 -> 16 | F30: 16 | G30: =H30/4*C30 -> 0 | H30: 0 | I30: 1
A31: a6 haiyue m [a6 cca 2] | B31: 5 | C31: 20 | D31: 5 | E31: =F31/4*C31 -> 16 | F31: 3.2 | G31: =H31/4*C31 -> 0 | H31: 0 | I31: 0.8
A32: h1 alex y [h1 choate] | B32: 5 | C32: 20 | D32: 7 | E32: =F32/4*C32 -> 16 | F32: 3.2 | G32: =H32/4*C32 -> 1 | H32: 0.2 | I32: 0.714
... A58: d6 jake n [d6 foothill] | B58: 5 | C58: 20 | D58: 11 | E58: =F58/4*C58 -> 8 | F58: 1.6 | G58: =H58/4*C58 -> 3 | H58: 0.6 | I58: 0.455
A59: c3 aarav j [c3 amador valley] | B59: 5 | C59: 20 | D59: 9 | E59: 8 | F59: =E59/C59*4 -> 1.6 | G59: =H59/4*C59 -> 2.5 | H59: 0.5 | I59: =4/9 -> 0.44444444
A60: d3 sai v [d3 collierville 2] | B60: 4 | C60: 16 | D60: 6 | E60: =F60/4*C60 -> 8 | F60: 2 | G60: =H60/4*C60 -> 0 | H60: 0 | I60: 0.333
A61: g4 divit m [g4 wwps 2] | B61: 5 | C61: 20 | D61: 7 | E61: =F61/4*C61 -> 8 | F61: 1.6 | G61: =H61/4*C61 -> 0 | H61: 0 | I61: 0.286
A62: d5 ryan c [d5 centennial] | B62: 5 | C62: 20 | D62: 10 | E62: =F62/4*C62 -> 8 | F62: 1.6 | G62: =H62/4*C62 -> 0 | H62: 0 | I62: 0.2
A63: a2 andrew w [a2 palo alto] | B63: 5 | C63: 20 | D63: 1 | E63: =F63/4*C63 -> 4 | F63: 0.8 | G63: =H63/4*C63 -> 0 | H63: 0 | I63: 1
A64: a5 arjun k [a5 saratoga] | B64: 5 | C64: 20 | D64: 1 | E64: =F64/4*C64 -> 4 | F64: 0.8 | G64: =H64/4*C64 -> 0 | H64: 0 | I64: 1
A65: b4 rehan k [b4 collierville 1] | B65: 5 | C65: 20 | D65: 1 | E65: =F65/4*C65 -> 4 | F65: 0.8 | G65: =H65/4*C65 -> 0 | H65: 0 | I65: 1
A66: b4 sumin y [b4 collierville 1] | B66: 4 | C66: 16 | D66: 1 | E66: =F66/4*C66 -> 4 | F66: 1 | G66: =H66/4*C66 -> 0 | H66: 0 | I66: 1
A67: c4 kevin w [c4 arcadia] | B67: 2 | C67: 8 | D67: 1 | E67: =F67/4*C67 -> 4 | F67: 2 | G67: =H67/4*C67 -> 0 | H67: 0 | I67: 1
A68: d6 brandon k [d6 foothill] | B68: 1 | C68: 4 | D68: 1 | E68: =F68/4*C68 -> 4 | F68: 4 | G68: =H68/4*C68 -> 0 | H68: 0 | I68: 1
A69: e3 eric l [e3 frazer 1] | B69: 1 | C69: 4 | D69: 1 | E69: =F69/4*C69 -> 4 | F69: 4 | G69: =H69/4*C69 -> 0 | H69: 0 | I69: 1
A70: e6 chris w [e6 montgomery blair 2] | B70: 5 | C70: 20 | D70: 1 | E70: =F70/4*C70 -> 4 | F70: 0.8 | G70: =H70/4*C70 -> 0 | H70: 0 | I70: 1
...

Sheet Individual Physics Stats
A1: name | B1: Games Played | C1: Tossups Heard | D1: Buzzes | E1: Points | F1: PP4TUH | G1: Negs | H1: Negs/4TUH | I1: Accuracy
A2: h5 harry g [h5 ward melville] | B2: 5 | C2: 20 | D2: 13 | E2: =F2/4*C2 -> 52 | F2: 10.4 | G2: =H2/4*C2 -> 0 | H2: 0 | I2: 1
A3: c6 yunyi l [c6 blair 1] | B3: 5 | C3: 20 | D3: 14 | E3: =F3/4*C3 -> 48 | F3: 9.6 | G3: =H3/4*C3 -> 1 | H3: 0.2 | I3: 0.929
A4: a2 forrest c [a2 palo alto] | B4: 5 | C4: 20 | D4: 13 | E4: =F4/4*C4 -> 44 | F4: 8.8 | G4: =H4/4*C4 -> 1 | H4: 0.2 | I4: 0.923
A5: d6 athithan e [d6 foothill] | B5: 5 | C5: 20 | D5: 12 | E5: =F5/4*C5 -> 44 | F5: 8.8 | G5: =H5/4*C5 -> 0 | H5: 0 | I5: 0.917
A6: b3 owen w [b3 middleton 1] | B6: 5 | C6: 20 | D6: 12 | E6: =F6/4*C6 -> 40 | F6: 8 | G6: =H6/4*C6 -> 0 | H6: 0 | I6: 0.833
A7: f3 kevin q [f3 wayzata] | B7: 5 | C7: 20 | D7: 17 | E7: =F7/4*C7 -> 36 | F7: 7.2 | G7: =H7/4*C7 -> 4 | H7: 0.8 | I7: 0.765
A8: g5 alexander f [g5 clements] | B8: 5 | C8: 20 | D8: 9 | E8: =F8/4*C8 -> 32 | F8: 6.4 | G8: =H8/4*C8 -> 0 | H8: 0 | I8: 0.889
A9: d4 andrew k [d4 whitney young] | B9: 5 | C9: 20 | D9: 13 | E9: =F9/4*C9 -> 32 | F9: 6.4 | G9: =H9/4*C9 -> 1 | H9: 0.2 | I9: 0.692
A10: c3 aarav j [c3 amador valley] | B10: 5 | C10: =B10*4 -> 20 | D10: 12 | E10: 32 | F10: =E10/C10*4 -> 6.4 | G10: =H10/4*C10 -> 0 | H10: 0 | I10: =8/12 -> 0.66666667
A11: c4 herrick w [c4 arcadia] | B11: 5 | C11: =B11*4 -> 20 | D11: 9 | E11: 28 | F11: =E11/C11*4 -> 5.6 | G11: =H11/4*C11 -> 1.25 | H11: 0.25 | I11: =8/9 -> 0.88888889
A12: e3 jimmy j [e3 frazer 1] | B12: 5 | C12: 20 | D12: 9 | E12: =F12/4*C12 -> 28 | F12: 5.6 | G12: =H12/4*C12 -> 0 | H12: 0 | I12: 0.778
A13: d1 li y [d1 middleton 2] | B13: 5 | C13: 20 | D13: 11 | E13: =F13/4*C13 -> 28 | F13: 5.6 | G13: =H13/4*C13 -> 0 | H13: 0 | I13: 0.636
A14: a4 jason m [a4 wwps 1] | B14: 5 | C14: 20 | D14: 13 | E14: =F14/4*C14 -> 28 | F14: 5.6 | G14: =H14/4*C14 -> 1 | H14: 0.2 | I14: 0.615
A15: f2 anish p [f2 frazer 2] | B15: 5 | C15: 20 | D15: 6 | E15: =F15/4*C15 -> 24 | F15: 4.8 | G15: =H15/4*C15 -> 0 | H15: 0 | I15: 1
A16: e5 josh s [e5 princeton unified] | B16: 5 | C16: 20 | D16: 11 | E16: =F16/4*C16 -> 24 | F16: 4.8 | G16: =H16/4*C16 -> 2 | H16: 0.4 | I16: 0.727
A17: h2 mihir k [h2 niskayuna] | B17: 5 | C17: 20 | D17: 10 | E17: =F17/4*C17 -> 24 | F17: 4.8 | G17: =H17/4*C17 -> 1 | H17: 0.2 | I17: 0.7
A18: d2 selena y [d2 lynbrook 1] | B18: 5 | C18: 20 | D18: 12 | E18: =F18/4*C18 -> 24 | F18: 4.8 | G18: =H18/4*C18 -> 0 | H18: 0 | I18: 0.5
A19: f1 sean y [f1 cca 1] | B19: 5 | C19: 20 | D19: 5 | E19: =F19/4*C19 -> 20 | F19: 4 | G19: =H19/4*C19 -> 0 | H19: 0 | I19: 1
A20: b5 patrick s [b5 tjhsst 1] | B20: 5 | C20: 20 | D20: 7 | E20: =F20/4*C20 -> 20 | F20: 4 | G20: =H20/4*C20 -> 1 | H20: 0.2 | I20: 0.857
A21: a6 jason y [a6 cca 2] | B21: 5 | C21: 20 | D21: 6 | E21: =F21/4*C21 -> 20 | F21: 4 | G21: =H21/4*C21 -> 0 | H21: 0 | I21: 0.833
A22: e4 rutvik a [e4 msj 1] | B22: 5 | C22: 20 | D22: 9 | E22: =F22/4*C22 -> 20 | F22: 4 | G22: =H22/4*C22 -> 2 | H22: 0.4 | I22: 0.778
A23: a1 ethan w [a1 clovis north] | B23: 5 | C23: 20 | D23: 8 | E23: =F23/4*C23 -> 20 | F23: 4 | G23: =H23/4*C23 -> 1 | H23: 0.2 | I23: 0.75
... A140: c1 min s [c1 iolani] | B140: 4 | C140: 16 | D140: 0 | E140: =F140/4*C140 -> 0 | F140: 0 | G140: =H140/4*C140 -> 0 | H140: 0 | I140: 0
A141: c3 devna b [c3 amador valley] | B141: 2 | C141: =B141*4 -> 8 | D141: 0 | E141: =F141/4*C141 -> 0 | F141: 0 | G141: =H141/4*C141 -> 0 | H141: 0 | I141: 0
A142: c3 helaina h [c3 amador valley] | B142: 4 | C142: =B142*4 -> 16 | D142: 0 | E142: =F142/4*C142 -> 0 | F142: 0 | G142: =H142/4*C142 -> 0 | H142: 0 | I142: 0
A143: c3 samarth j [c3 amador valley] | B143: 5 | C143: =B143*4 -> 20 | D143: 0 | E143: =F143/4*C143 -> 0 | F143: 0 | G143: =H143/4*C143 -> 0 | H143: 0 | I143: 0
A144: c4 avani a [c4 arcadia] | B144: 5 | C144: =B144*4 -> 20 | D144: 0 | E144: =F144/4*C144 -> 0 | F144: 0 | G144: =H144/4*C144 -> 0 | H144: 0 | I144: 0
A145: c4 ethan w [c4 arcadia] | B145: 5 | C145: =B145*4 -> 20 | D145: 1 | E145: =F145/4*C145 -> 0 | F145: 0 | G145: =H145/4*C145 -> 0 | H145: 0 | I145: 0
A146: c4 kevin w [c4 arcadia] | B146: 3 | C146: =B146*4 -> 12 | D146: 0 | E146: =F146/4*C146 -> 0 | F146: 0 | G146: =H146/4*C146 -> 0 | H146: 0 | I146: 0
A147: c4 maxwell k [c4 arcadia] | B147: 3 | C147: 12 | D147: 0 | E147: =F147/4*C147 -> 0 | F147: 0 | G147: =H147/4*C147 -> 0 | H147: 0 | I147: 0
A148: c5 rylan c [c5 temple city] | B148: 3 | C148: 12 | D148: 0 | E148: =F148/4*C148 -> 0 | F148: 0 | G148: =H148/4*C148 -> 0 | H148: 0 | I148: 0
A149: c6 katherine w [c6 blair 1] | B149: 5 | C149: 20 | D149: 0 | E149: =F149/4*C149 -> 0 | F149: 0 | G149: =H149/4*C149 -> 0 | H149: 0 | I149: 0
A150: d2 ian c [d2 lynbrook 1] | B150: 1 | C150: 4 | D150: 0 | E150: =F150/4*C150 -> 0 | F150: 0 | G150: =H150/4*C150 -> 0 | H150: 0 | I150: 0
A151: d3 bethany c [d3 collierville 2] | B151: 3 | C151: 12 | D151: 0 | E151: =F151/4*C151 -> 0 | F151: 0 | G151: =H151/4*C151 -> 0 | H151: 0 | I151: 0
A152: d3 sai v [d3 collierville 2] | B152: 4 | C152: 16 | D152: 2 | E152: =F152/4*C152 -> 0 | F152: 0 | G152: =H152/4*C152 -> 0 | H152: 0 | I152: 0
A153: d4 brennan t [d4 whitney young] | B153: 3 | C153: 12 | D153: 0 | E153: =F153/4*C153 -> 0 | F153: 0 | G153: =H153/4*C153 -> 0 | H153: 0 | I153: 0
A154: d4 david c [d4 whitney young] | B154: 4 | C154: 16 | D154: 1 | E154: =F154/4*C154 -> 0 | F154: 0 | G154: =H154/4*C154 -> 0 | H154: 0 | I154: 0
A155: d4 michael m [d4 whitney young] | B155: 1 | C155: 4 | D155: 0 | E155: =F155/4*C155 -> 0 | F155: 0 | G155: =H155/4*C155 -> 0 | H155: 0 | I155: 0
A156: d4 shirley r [d4 whitney young] | B156: 3 | C156: 12 | D156: 0 | E156: =F156/4*C156 -> 0 | F156: 0 | G156: =H156/4*C156 -> 0 | H156: 0 | I156: 0
...

Sheet Individual Earth and Space Stat
A1: name | B1: Games Played | C1: Tossups Heard | D1: Buzzes | E1: Points | F1: PP4TUH | G1: Negs | H1: Negs/4TUH | I1: Accuracy
A2: e4 roshan a [e4 msj 1] | B2: 5 | C2: 20 | D2: 18 | E2: =F2/4*C2 -> 48 | F2: 9.6 | G2: =H2/4*C2 -> 3 | H2: 0.6 | I2: 0.833
A3: f1 flora j [f1 cca 1] | B3: 5 | C3: 20 | D3: 17 | E3: =F3/4*C3 -> 48 | F3: 9.6 | G3: =H3/4*C3 -> 1 | H3: 0.2 | I3: 0.765
A4: g5 yale z [g5 clements] | B4: 5 | C4: 20 | D4: 16 | E4: =F4/4*C4 -> 44 | F4: 8.8 | G4: =H4/4*C4 -> 2 | H4: 0.4 | I4: 0.813
A5: h6 shreyas e [h6 lexington] | B5: 4 | C5: 16 | D5: 11 | E5: =F5/4*C5 -> 40 | F5: 10 | G5: =H5/4*C5 -> 0 | H5: 0 | I5: 0.909
A6: g2 ishaan k [g2 msj 2] | B6: 5 | C6: 20 | D6: 14 | E6: =F6/4*C6 -> 36 | F6: 7.2 | G6: =H6/4*C6 -> 1 | H6: 0.2 | I6: 0.714
A7: g6 bryce t [g6 oak avenue 1] | B7: 5 | C7: 20 | D7: 14 | E7: =F7/4*C7 -> 36 | F7: 7.2 | G7: =H7/4*C7 -> 1 | H7: 0.2 | I7: 0.714
A8: f3 kevin q [f3 wayzata] | B8: 5 | C8: 20 | D8: 10 | E8: =F8/4*C8 -> 32 | F8: 6.4 | G8: =H8/4*C8 -> 1 | H8: 0.2 | I8: 0.9
A9: e5 josh s [e5 princeton unified] | B9: 5 | C9: 20 | D9: 11 | E9: =F9/4*C9 -> 32 | F9: 6.4 | G9: =H9/4*C9 -> 1 | H9: 0.2 | I9: 0.818
A10: c5 tiger w [c5 temple city] | B10: 5 | C10: 20 | D10: 11 | E10: =F10/4*C10 -> 32 | F10: 6.4 | G10: =H10/4*C10 -> 0 | H10: 0 | I10: 0.727
A11: b3 harry j [b3 middleton 1] | B11: 5 | C11: 20 | D11: 13 | E11: =F11/4*C11 -> 32 | F11: 6.4 | G11: =H11/4*C11 -> 1 | H11: 0.2 | I11: 0.692
A12: f5 camille p [f5 hunter] | B12: 5 | C12: 20 | D12: 8 | E12: =F12/4*C12 -> 28 | F12: 5.6 | G12: =H12/4*C12 -> 0 | H12: 0 | I12: 0.875
A13: b2 akhil b [b2 asfa] | B13: 5 | C13: 20 | D13: 15 | E13: =F13/4*C13 -> 28 | F13: 5.6 | G13: =H13/4*C13 -> 2 | H13: 0.4 | I13: 0.6
... A26: a5 alex g [a5 saratoga] | B26: 5 | C26: 20 | D26: 7 | E26: =F26/4*C26 -> 20 | F26: 4 | G26: =H26/4*C26 -> 1 | H26: 0.2 | I26: 0.857
A27: c4 maxwell k [c4 arcadia] | B27: 4 | C27: =B27*4 -> 16 | D27: 10 | E27: 20 | F27: =E27/C27*4 -> 5 | G27: =H27/4*C27 -> 2.68 | H27: 0.67 | I27: =7/10 -> 0.7
A28: d2 selena y [d2 lynbrook 1] | B28: 5 | C28: 20 | D28: 13 | E28: =F28/4*C28 -> 20 | F28: 4 | G28: =H28/4*C28 -> 2 | H28: 0.4 | I28: 0.538
A29: a6 ishank k [a6 cca 2] | B29: 5 | C29: 20 | D29: 10 | E29: =F29/4*C29 -> 20 | F29: 4 | G29: =H29/4*C29 -> 0 | H29: 0 | I29: 0.5
A30: f2 anthony l [f2 frazer 2] | B30: 5 | C30: 20 | D30: 4 | E30: =F30/4*C30 -> 16 | F30: 3.2 | G30: =H30/4*C30 -> 0 | H30: 0 | I30: 1
A31: a1 ethan w [a1 clovis north] | B31: 5 | C31: 20 | D31: 5 | E31: =F31/4*C31 -> 16 | F31: 3.2 | G31: =H31/4*C31 -> 0 | H31: 0 | I31: 0.8
A32: b5 patrick s [b5 tjhsst 1] | B32: 5 | C32: 20 | D32: 5 | E32: =F32/4*C32 -> 16 | F32: 3.2 | G32: =H32/4*C32 -> 0 | H32: 0 | I32: 0.8
A33: c1 ryan e [c1 iolani] | B33: 2 | C33: 8 | D33: 5 | E33: =F33/4*C33 -> 16 | F33: 8 | G33: =H33/4*C33 -> 0 | H33: 0 | I33: 0.8
A34: c6 katherine w [c6 blair 1] | B34: 5 | C34: 20 | D34: 5 | E34: =F34/4*C34 -> 16 | F34: 3.2 | G34: =H34/4*C34 -> 0 | H34: 0 | I34: 0.8
A35: a2 kevin p [a2 palo alto] | B35: 4 | C35: 16 | D35: 6 | E35: =F35/4*C35 -> 16 | F35: 4 | G35: =H35/4*C35 -> 0 | H35: 0 | I35: 0.667
A36: e2 ameyaa r [e2 lynbrook 2] | B36: 5 | C36: 20 | D36: 6 | E36: =F36/4*C36 -> 16 | F36: 3.2 | G36: =H36/4*C36 -> 0 | H36: 0 | I36: 0.667
A37: e3 abhiram p [e3 frazer 1] | B37: 5 | C37: 20 | D37: 7 | E37: =F37/4*C37 -> 16 | F37: 3.2 | G37: =H37/4*C37 -> 0 | H37: 0 | I37: 0.571
A38: d6 shashank v [d6 foothill] | B38: 5 | C38: 20 | D38: 15 | E38: =F38/4*C38 -> 16 | F38: 3.2 | G38: =H38/4*C38 -> 3 | H38: 0.6 | I38: 0.467
A39: c3 samarth j [c3 amador valley] | B39: 5 | C39: =B39*4 -> 20 | D39: 9 | E39: 16 | F39: =E39/C39*4 -> 3.2 | G39: =H39/4*C39 -> 0 | H39: 0 | I39: =4/9 -> 0.44444444
A40: e6 meghna s [e6 montgomery blair 2] | B40: 5 | C40: 20 | D40: 9 | E40: =F40/4*C40 -> 16 | F40: 3.2 | G40: =H40/4*C40 -> 0 | H40: 0 | I40: 0.444
A41: a3 alexis e [a3 tokay] | B41: 5 | C41: 20 | D41: 10 | E41: =F41/4*C41 -> 16 | F41: 3.2 | G41: =H41/4*C41 -> 0 | H41: 0 | I41: 0.4
A42: f2 anish p [f2 frazer 2] | B42: 5 | C42: 20 | D42: 3 | E42: =F42/4*C42 -> 12 | F42: 2.4 | G42: =H42/4*C42 -> 0 | H42: 0 | I42: 1
A43: a1 renard w [a1 clovis north] | B43: 5 | C43: 20 | D43: 4 | E43: =F43/4*C43 -> 12 | F43: 2.4 | G43: =H43/4*C43 -> 0 | H43: 0 | I43: 0.75
A44: b5 rishabh k [b5 tjhsst 1] | B44: 5 | C44: 20 | D44: 6 | E44: =F44/4*C44 -> 12 | F44: 2.4 | G44: =H44/4*C44 -> 1 | H44: 0.2 | I44: 0.667
A45: h4 daniel x [h4 hawken] | B45: 5 | C45: 20 | D45: 7 | E45: =F45/4*C45 -> 12 | F45: 2.4 | G45: =H45/4*C45 -> 1 | H45: 0.2 | I45: 0.571
A46: c1 hong jin k [c1 iolani] | B46: 5 | C46: 20 | D46: 7 | E46: =F46/4*C46 -> 12 | F46: 2.4 | G46: =H46/4*C46 -> 0 | H46: 0 | I46: 0.429
A47: b1 lucas c [b1 california] | B47: 5 | C47: 20 | D47: 8 | E47: =F47/4*C47 -> 12 | F47: 2.4 | G47: =H47/4*C47 -> 0 | H47: 0 | I47: 0.375
A48: c4 ethan w [c4 arcadia] | B48: 5 | C48: =B48*4 -> 20 | D48: 3 | E48: =F48/4*C48 -> 10 | F48: 2 | G48: =H48/4*C48 -> 0 | H48: 0 | I48: 0.667
A49: a5 quinn g [a5 saratoga] | B49: 3 | C49: 12 | D49: 2 | E49: =F49/4*C49 -> 8.01 | F49: 2.67 | G49: =H49/4*C49 -> 0 | H49: 0 | I49: 1
A50: e5 ivy h [e5 princeton unified] | B50: 3 | C50: 12 | D50: 2 | E50: =F50/4*C50 -> 8.01 | F50: 2.67 | G50: =H50/4*C50 -> 0 | H50: 0 | I50: 1
A51: c5 rylan c [c5 temple city] | B51: 3 | C51: 12 | D51: 3 | E51: =F51/4*C51 -> 8.01 | F51: 2.67 | G51: =H51/4*C51 -> 0 | H51: 0 | I51: 0.667
A52: d3 angeline c [d3 collierville 2] | B52: 3 | C52: 12 | D52: 5 | E52: =F52/4*C52 -> 8.01 | F52: 2.67 | G52: =H52/4*C52 -> 0 | H52: 0 | I52: 0.4
...

Sheet Individual Math Stats
A1: name | B1: Games Played | C1: Tossups Heard | D1: Buzzes | E1: Points | F1: PP4TUH | G1: Negs | H1: Negs/4TUH | I1: Accuracy
A2: b5 rishabh k [b5 tjhsst 1] | B2: 5 | C2: 20 | D2: 16 | E2: =F2/4*C2 -> 52 | F2: 10.4 | G2: =H2/4*C2 -> 0 | H2: 0 | I2: 0.813
A3: f3 kevin q [f3 wayzata] | B3: 5 | C3: 20 | D3: 18 | E3: =F3/4*C3 -> 48 | F3: 9.6 | G3: =H3/4*C3 -> 2 | H3: 0.4 | I3: 0.778
A4: f4 hugh c [f4 harvard westlake] | B4: 5 | C4: 20 | D4: 12 | E4: =F4/4*C4 -> 44 | F4: 8.8 | G4: =H4/4*C4 -> 0 | H4: 0 | I4: 0.917
A5: d1 li y [d1 middleton 2] | B5: 5 | C5: 20 | D5: 12 | E5: =F5/4*C5 -> 40 | F5: 8 | G5: =H5/4*C5 -> 0 | H5: 0 | I5: 0.833
A6: d6 athithan e [d6 foothill] | B6: 5 | C6: 20 | D6: 14 | E6: =F6/4*C6 -> 40 | F6: 8 | G6: =H6/4*C6 -> 1 | H6: 0.2 | I6: 0.786
A7: g3 aprameya t [g3 wwpn] | B7: 5 | C7: 20 | D7: 11 | E7: =F7/4*C7 -> 36 | F7: 7.2 | G7: =H7/4*C7 -> 1 | H7: 0.2 | I7: 0.909
A8: g5 alex s [g5 clements] | B8: 5 | C8: 20 | D8: 10 | E8: =F8/4*C8 -> 36 | F8: 7.2 | G8: =H8/4*C8 -> 0 | H8: 0 | I8: 0.9
A9: h5 harry g [h5 ward melville] | B9: 5 | C9: 20 | D9: 15 | E9: =F9/4*C9 -> 36 | F9: 7.2 | G9: =H9/4*C9 -> 2 | H9: 0.4 | I9: 0.733
A10: e6 chris w [e6 montgomery blair 2] | B10: 5 | C10: 20 | D10: 14 | E10: =F10/4*C10 -> 36 | F10: 7.2 | G10: =H10/4*C10 -> 1 | H10: 0.2 | I10: 0.714
A11: f1 kaden w [f1 cca 1] | B11: 5 | C11: 20 | D11: 10 | E11: =F11/4*C11 -> 32 | F11: 6.4 | G11: =H11/4*C11 -> 0 | H11: 0 | I11: 0.8
A12: h1 alex y [h1 choate] | B12: 5 | C12: 20 | D12: 8 | E12: =F12/4*C12 -> 28 | F12: 5.6 | G12: =H12/4*C12 -> 0 | H12: 0 | I12: 0.875
A13: e5 felicity n [e5 princeton unified] | B13: 5 | C13: 20 | D13: 10 | E13: =F13/4*C13 -> 28 | F13: 5.6 | G13: =H13/4*C13 -> 1 | H13: 0.2 | I13: 0.8
A14: b2 albert c [b2 asfa] | B14: 5 | C14: 20 | D14: 10 | E14: =F14/4*C14 -> 28 | F14: 5.6 | G14: =H14/4*C14 -> 0 | H14: 0 | I14: 0.7
A15: c4 ethan w [c4 arcadia] | B15: 5 | C15: =B15*4 -> 20 | D15: 10 | E15: 28 | F15: =E15/C15*4 -> 5.6 | G15: =H15/4*C15 -> 0 | H15: 0 | I15: =7/10 -> 0.7
A16: e3 abhiram p [e3 frazer 1] | B16: 5 | C16: 20 | D16: 6 | E16: =F16/4*C16 -> 24 | F16: 4.8 | G16: =H16/4*C16 -> 0 | H16: 0 | I16: 1
A17: e2 sophia f [e2 lynbrook 2] | B17: 5 | C17: 20 | D17: 7 | E17: =F17/4*C17 -> 24 | F17: 4.8 | G17: =H17/4*C17 -> 0 | H17: 0 | I17: 0.857
A18: h6 shreyas e [h6 lexington] | B18: 4 | C18: 16 | D18: 9 | E18: =F18/4*C18 -> 24 | F18: 6 | G18: =H18/4*C18 -> 1 | H18: 0.25 | I18: 0.778
A19: a2 andrew w [a2 palo alto] | B19: 5 | C19: 20 | D19: 8 | E19: =F19/4*C19 -> 24 | F19: 4.8 | G19: =H19/4*C19 -> 0 | H19: 0 | I19: 0.75
A20: a6 jason y [a6 cca 2] | B20: 5 | C20: 20 | D20: 9 | E20: =F20/4*C20 -> 24 | F20: 4.8 | G20: =H20/4*C20 -> 0 | H20: 0 | I20: 0.667
A21: a1 justin d [a1 clovis north] | B21: 5 | C21: 20 | D21: 13 | E21: =F21/4*C21 -> 24 | F21: 4.8 | G21: =H21/4*C21 -> 2 | H21: 0.4 | I21: 0.615
A22: f5 gabe f [f5 hunter] | B22: 5 | C22: 20 | D22: 7 | E22: =F22/4*C22 -> 20 | F22: 4 | G22: =H22/4*C22 -> 0 | H22: 0 | I22: 0.714
A23: d5 matthew y [d5 centennial] | B23: 5 | C23: 20 | D23: 8 | E23: =F23/4*C23 -> 20 | F23: 4 | G23: =H23/4*C23 -> 0 | H23: 0 | I23: 0.625
A24: c1 hong jin k [c1 iolani] | B24: 5 | C24: 20 | D24: 12 | E24: =F24/4*C24 -> 20 | F24: 4 | G24: =H24/4*C24 -> 1 | H24: 0.2 | I24: 0.5
A25: g2 ishaan k [g2 msj 2] | B25: 5 | C25: 20 | D25: 16 | E25: =F25/4*C25 -> 20 | F25: 4 | G25: =H25/4*C25 -> 3 | H25: 0.6 | I25: 0.5
A26: f6 will k [f6 granada] | B26: 5 | C26: 20 | D26: 13 | E26: =F26/4*C26 -> 20 | F26: 4 | G26: =H26/4*C26 -> 1 | H26: 0.2 | I26: 0.462
A27: b3 owen w [b3 middleton 1] | B27: 5 | C27: 20 | D27: 4 | E27: =F27/4*C27 -> 16 | F27: 3.2 | G27: =H27/4*C27 -> 0 | H27: 0 | I27: 1
... A67: b6 jiyoon c [b6 madison west 2] | B67: 5 | C67: 20 | D67: 3 | E67: =F67/4*C67 -> 8 | F67: 1.6 | G67: =H67/4*C67 -> 0 | H67: 0 | I67: 0.667
A68: c4 kevin w [c4 arcadia] | B68: 2 | C68: =B68*4 -> 8 | D68: 3 | E68: =F68/4*C68 -> 8 | F68: 4 | G68: =H68/4*C68 -> 0 | H68: 0 | I68: 0.667
A69: e1 julien d [e1 stuyvesant] | B69: 5 | C69: 20 | D69: 3 | E69: =F69/4*C69 -> 8 | F69: 1.6 | G69: =H69/4*C69 -> 0 | H69: 0 | I69: 0.667
A70: g3 krutharth v [g3 wwpn] | B70: 5 | C70: 20 | D70: 3 | E70: =F70/4*C70 -> 8 | F70: 1.6 | G70: =H70/4*C70 -> 0 | H70: 0 | I70: 0.667
A71: g4 aarush p [g4 wwps 2] | B71: 4 | C71: 16 | D71: 3 | E71: =F71/4*C71 -> 8 | F71: 2 | G71: =H71/4*C71 -> 0 | H71: 0 | I71: 0.667
A72: b3 harry j [b3 middleton 1] | B72: 5 | C72: 20 | D72: 5 | E72: =F72/4*C72 -> 8 | F72: 1.6 | G72: =H72/4*C72 -> 0 | H72: 0 | I72: 0.4
A73: c3 aarav j [c3 amador valley] | B73: 5 | C73: =B73*4 -> 20 | D73: 8 | E73: 8 | F73: =E73/C73*4 -> 1.6 | G73: =H73/4*C73 -> 0 | H73: 0 | I73: 0.25
A74: a4 arjun d [a4 wwps 1] | B74: 5 | C74: 20 | D74: 1 | E74: =F74/4*C74 -> 4 | F74: 0.8 | G74: =H74/4*C74 -> 0 | H74: 0 | I74: 1
A75: a4 jason m [a4 wwps 1] | B75: 5 | C75: 20 | D75: 1 | E75: =F75/4*C75 -> 4 | F75: 0.8 | G75: =H75/4*C75 -> 0 | H75: 0 | I75: 1
A76: b1 gleb m [b1 california] | B76: 4 | C76: 16 | D76: 1 | E76: =F76/4*C76 -> 4 | F76: 1 | G76: =H76/4*C76 -> 0 | H76: 0 | I76: 1
A77: b4 kal k [b4 collierville 1] | B77: 5 | C77: 20 | D77: 1 | E77: =F77/4*C77 -> 4 | F77: 0.8 | G77: =H77/4*C77 -> 0 | H77: 0 | I77: 1
A78: c3 samarth j [c3 amador valley] | B78: 5 | C78: =B78*4 -> 20 | D78: 1 | E78: 4 | F78: 0.8 | G78: =H78/4*C78 -> 0 | H78: 0 | I78: =1/1 -> 1
A79: d5 m wafiqah [d5 centennial] | B79: 1 | C79: 4 | D79: 1 | E79: =F79/4*C79 -> 4 | F79: 4 | G79: =H79/4*C79 -> 0 | H79: 0 | I79: 1
...

Sheet Individual Overall Stats
A1: name | B1: Games Played | C1: Tossups Heard | D1: Buzzes | E1: Points | F1: PPG | G1: Negs | H1: NPG | I1: Accuracy
A2: f3 kevin q [f3 wayzata] | B2: 5 | C2: 100 | D2: 69 | E2: =F2/20*C2 -> 172 | F2: 34.4 | G2: =H2/20*C2 -> 10 | H2: 2 | I2: 0.768
A3: g3 krutharth v [g3 wwpn] | B3: 5 | C3: 100 | D3: 57 | E3: =F3/20*C3 -> 156 | F3: 31.2 | G3: =H3/20*C3 -> 5 | H3: 1 | I3: 0.772
A4: d2 selena y [d2 lynbrook 1] | B4: 5 | C4: 100 | D4: 66 | E4: =F4/20*C4 -> 148 | F4: 29.6 | G4: =H4/20*C4 -> 5 | H4: 1 | I4: 0.636
A5: g5 yale z [g5 clements] | B5: 5 | C5: 100 | D5: 48 | E5: =F5/20*C5 -> 140 | F5: 28 | G5: =H5/20*C5 -> 5 | H5: 1 | I5: 0.833
A6: h3 aaryan s [h3 tjhsst 2] | B6: 5 | C6: 100 | D6: 55 | E6: =F6/20*C6 -> 120 | F6: 24 | G6: =H6/20*C6 -> 9 | H6: 1.8 | I6: 0.709
A7: d1 li y [d1 middleton 2] | B7: 5 | C7: 100 | D7: 51 | E7: =F7/20*C7 -> 116 | F7: 23.2 | G7: =H7/20*C7 -> 0 | H7: 0 | I7: 0.569
A8: a2 forrest c [a2 palo alto] | B8: 5 | C8: 100 | D8: 52 | E8: =F8/20*C8 -> 112 | F8: 22.4 | G8: =H8/20*C8 -> 8 | H8: 1.6 | I8: 0.692
A9: b3 owen w [b3 middleton 1] | B9: 5 | C9: 100 | D9: 33 | E9: =F9/20*C9 -> 108 | F9: 21.6 | G9: =H9/20*C9 -> 2 | H9: 0.4 | I9: 0.879
A10: b3 harry j [b3 middleton 1] | B10: 5 | C10: 100 | D10: 38 | E10: =F10/20*C10 -> 108 | F10: 21.6 | G10: =H10/20*C10 -> 2 | H10: 0.4 | I10: 0.763
A11: c6 yunyi l [c6 blair 1] | B11: 5 | C11: 100 | D11: 34 | E11: =F11/20*C11 -> 104 | F11: 20.8 | G11: =H11/20*C11 -> 4 | H11: 0.8 | I11: 0.882
A12: b5 rishabh k [b5 tjhsst 1] | B12: 5 | C12: 100 | D12: 38 | E12: =F12/20*C12 -> 104 | F12: 20.8 | G12: =H12/20*C12 -> 4 | H12: 0.8 | I12: 0.789
A13: h6 william j [h6 lexington] | B13: 5 | C13: 100 | D13: 28 | E13: =F13/20*C13 -> 100 | F13: 20 | G13: =H13/20*C13 -> 1 | H13: 0.2 | I13: 0.929
... A29: b1 lucas c [b1 california] | B29: 5 | C29: 100 | D29: 31 | E29: =F29/20*C29 -> 72 | F29: 14.4 | G29: =H29/20*C29 -> 1 | H29: 0.2 | I29: 0.613
A30: c4 ethan w [c4 arcadia] | B30: 5 | C30: =B30*20 -> 100 | D30: 28 | E30: 68 | F30: =68/100*20 -> 13.6 | G30: =H30/20*C30 -> 2.5 | H30: 0.5 | I30: =19/28 -> 0.67857143
A31: h2 mihir k [h2 niskayuna] | B31: 5 | C31: 100 | D31: 44 | E31: =F31/20*C31 -> 68 | F31: 13.6 | G31: =H31/20*C31 -> 9 | H31: 1.8 | I31: 0.591
A32: g2 ishaan k [g2 msj 2] | B32: 5 | C32: 100 | D32: 39 | E32: =F32/20*C32 -> 68 | F32: 13.6 | G32: =H32/20*C32 -> 6 | H32: 1.2 | I32: 0.59
A33: d5 ryan c [d5 centennial] | B33: 5 | C33: 100 | D33: 42 | E33: =F33/20*C33 -> 68 | F33: 13.6 | G33: =H33/20*C33 -> 3 | H33: 0.6 | I33: 0.476
A34: g2 arnav g [g2 msj 2] | B34: 5 | C34: 100 | D34: 21 | E34: =F34/20*C34 -> 64 | F34: 12.8 | G34: =H34/20*C34 -> 0 | H34: 0 | I34: 0.762
A35: f2 anish p [f2 frazer 2] | B35: 5 | C35: 100 | D35: 24 | E35: =F35/20*C35 -> 64 | F35: 12.8 | G35: =H35/20*C35 -> 1 | H35: 0.2 | I35: 0.708
A36: h4 daniel x [h4 hawken] | B36: 5 | C36: 100 | D36: 31 | E36: =F36/20*C36 -> 64 | F36: 12.8 | G36: =H36/20*C36 -> 3 | H36: 0.6 | I36: 0.613
A37: a1 justin d [a1 clovis north] | B37: 5 | C37: 100 | D37: 36 | E37: =F37/20*C37 -> 64 | F37: 12.8 | G37: =H37/20*C37 -> 6 | H37: 1.2 | I37: 0.611
A38: a3 alexis e [a3 tokay] | B38: 5 | C38: 100 | D38: 35 | E38: =F38/20*C38 -> 64 | F38: 12.8 | G38: =H38/20*C38 -> 0 | H38: 0 | I38: 0.457
A39: b5 patrick s [b5 tjhsst 1] | B39: 5 | C39: 100 | D39: 23 | E39: =F39/20*C39 -> 60 | F39: 12 | G39: =H39/20*C39 -> 3 | H39: 0.6 | I39: 0.783
A40: d5 matthew y [d5 centennial] | B40: 5 | C40: 100 | D40: 24 | E40: =F40/20*C40 -> 60 | F40: 12 | G40: =H40/20*C40 -> 2 | H40: 0.4 | I40: 0.708
A41: h1 alex y [h1 choate] | B41: 5 | C41: 100 | D41: 24 | E41: =F41/20*C41 -> 60 | F41: 12 | G41: =H41/20*C41 -> 2 | H41: 0.4 | I41: 0.708
A42: a5 alex g [a5 saratoga] | B42: 5 | C42: 100 | D42: 28 | E42: =F42/20*C42 -> 60 | F42: 12 | G42: =H42/20*C42 -> 3 | H42: 0.6 | I42: 0.643
A43: c3 aarav j [c3 amador valley] | B43: 5 | C43: =B43*20 -> 100 | D43: 32 | E43: 60 | F43: =60/5 -> 12 | G43: =H43/20*C43 -> 2.5 | H43: 0.5 | I43: =17/32 -> 0.53125
A44: f4 hugh c [f4 harvard westlake] | B44: 5 | C44: 100 | D44: 19 | E44: =F44/20*C44 -> 56 | F44: 11.2 | G44: =H44/20*C44 -> 1 | H44: 0.2 | I44: 0.789
A45: g3 aprameya t [g3 wwpn] | B45: 5 | C45: 100 | D45: 21 | E45: =F45/20*C45 -> 56 | F45: 11.2 | G45: =H45/20*C45 -> 1 | H45: 0.2 | I45: 0.714
A46: e6 chris w [e6 montgomery blair 2] | B46: 5 | C46: 100 | D46: 29 | E46: =F46/20*C46 -> 56 | F46: 11.2 | G46: =H46/20*C46 -> 5 | H46: 1 | I46: 0.655
A47: c1 ryan e [c1 iolani] | B47: 2 | C47: 40 | D47: 18 | E47: =F47/20*C47 -> 52 | F47: 26 | G47: =H47/20*C47 -> 2 | H47: 1 | I47: 0.833
A48: f4 olivia s [f4 harvard westlake] | B48: 5 | C48: 100 | D48: 21 | E48: =F48/20*C48 -> 52 | F48: 10.4 | G48: =H48/20*C48 -> 3 | H48: 0.6 | I48: 0.762
A49: e4 theenash s [e4 msj 1] | B49: 5 | C49: 100 | D49: 34 | E49: =F49/20*C49 -> 52 | F49: 10.4 | G49: =H49/20*C49 -> 10 | H49: 2 | I49: 0.676
A50: f6 kaiyo i [f6 granada] | B50: 5 | C50: 100 | D50: 21 | E50: =F50/20*C50 -> 52 | F50: 10.4 | G50: =H50/20*C50 -> 1 | H50: 0.2 | I50: 0.667
A51: d6 bhagirath(buggy) b [d6 foothill] | B51: 5 | C51: 100 | D51: 26 | E51: =F51/20*C51 -> 52 | F51: 10.4 | G51: =H51/20*C51 -> 4 | H51: 0.8 | I51: 0.654
A52: e6 meghna s [e6 montgomery blair 2] | B52: 5 | C52: 100 | D52: 23 | E52: =F52/20*C52 -> 52 | F52: 10.4 | G52: =H52/20*C52 -> 0 | H52: 0 | I52: 0.565
A53: f2 anthony l [f2 frazer 2] | B53: 5 | C53: 100 | D53: 16 | E53: =F53/20*C53 -> 48 | F53: 9.6 | G53: =H53/20*C53 -> 1 | H53: 0.2 | I53: 0.813
A54: a1 ethan w [a1 clovis north] | B54: 5 | C54: 100 | D54: 17 | E54: =F54/20*C54 -> 48 | F54: 9.6 | G54: =H54/20*C54 -> 1 | H54: 0.2 | I54: 0.765
A55: f1 flora j [f1 cca 1] | B55: 5 | C55: 100 | D55: 17 | E55: =F55/20*C55 -> 48 | F55: 9.6 | G55: =H55/20*C55 -> 1 | H55: 0.2 | I55: 0.765
...

Sheet Team Biology Stats
A1: name | B1: gamesPlayed | C1: TUs Heard | D1: Buzzes | E1: Points | F1: PPG | G1: Negs | H1: NPG | I1: Bonus/Game | J1: Buzzing Accuracy
A2: d2 lynbrook 1 | B2: 5 | C2: 20 | D2: 20 | E2: =F2/4*C2 -> 240 | F2: 48 | G2: =H2/4*C2 -> 0 | H2: 0 | I2: 3.2 | J2: 1
A3: g3 wwpn | B3: 5 | C3: 20 | D3: 18 | E3: =F3/4*C3 -> 208 | F3: 41.6 | G3: =H3/4*C3 -> 0 | H3: 0 | I3: 2.8 | J3: 0.944
A4: a4 wwps 1 | B4: 5 | C4: 20 | D4: 17 | E4: =F4/4*C4 -> 190 | F4: 38 | G4: =H4/4*C4 -> 1 | H4: 0.2 | I4: 2.6 | J4: 0.941
A5: c6 blair 1 | B5: 5 | C5: 20 | D5: 19 | E5: =F5/4*C5 -> 182 | F5: 36.4 | G5: =H5/4*C5 -> 3 | H5: 0.6 | I5: 2.6 | J5: 0.842
A6: f1 cca 1 | B6: 5 | C6: 20 | D6: 18 | E6: =F6/4*C6 -> 162 | F6: 32.4 | G6: =H6/4*C6 -> 2 | H6: 0.4 | I6: 2.2 | J6: 0.833
A7: h3 tjhsst 2 | B7: 5 | C7: 20 | D7: 15 | E7: =F7/4*C7 -> 148 | F7: 29.6 | G7: =H7/4*C7 -> 1 | H7: 0.2 | I7: 2 | J7: 0.867
A8: b3 middleton 1 | B8: 5 | C8: 20 | D8: 17 | E8: =F8/4*C8 -> 148 | F8: 29.6 | G8: =H8/4*C8 -> 2 | H8: 0.4 | I8: 2 | J8: 0.824
A9: g2 msj 2 | B9: 5 | C9: 20 | D9: 16 | E9: =F9/4*C9 -> 134 | F9: 26.8 | G9: =H9/4*C9 -> 1 | H9: 0.2 | I9: 1.8 | J9: 0.733
A10: h2 niskayuna | B10: 5 | C10: 20 | D10: 16 | E10: =F10/4*C10 -> 130 | F10: 26 | G10: =H10/4*C10 -> 2 | H10: 0.4 | I10: 1.8 | J10: 0.75
A11: f4 harvard westlake | B11: 5 | C11: 20 | D11: 15 | E11: =F11/4*C11 -> 126 | F11: 25.2 | G11: =H11/4*C11 -> 3 | H11: 0.6 | I11: 1.8 | J11: 0.8
A12: g5 clements | B12: 5 | C12: 20 | D12: 12 | E12: =F12/4*C12 -> 124 | F12: 24.8 | G12: =H12/4*C12 -> 0 | H12: 0 | I12: 1.6 | J12: 0.917
A13: h6 lexington | B13: 5 | C13: 20 | D13: 13 | E13: =F13/4*C13 -> 124 | F13: 24.8 | G13: =H13/4*C13 -> 0 | H13: 0 | I13: 1.6 | J13: 0.846
... A18: b1 california | B18: 5 | C18: 20 | D18: 14 | E18: =F18/4*C18 -> 108 | F18: 21.6 | G18: =H18/4*C18 -> 0 | H18: 0 | I18: 1.2 | J18: 0.857
A19: c4 arcadia | B19: 5 | C19: 20 | D19: 9 | E19: 102 | F19: =E19/C19*4 -> 20.4 | G19: =H19/4*C19 -> 0 | H19: 0 | I19: =7/5 -> 1.4 | J19: =8/13 -> 0.61538462
A20: e6 montgomery blair 2 | B20: 5 | C20: 20 | D20: 14 | E20: =F20/4*C20 -> 100 | F20: 20 | G20: =H20/4*C20 -> 0 | H20: 0 | I20: 1.2 | J20: 0.714
A21: a5 saratoga | B21: 5 | C21: 20 | D21: 14 | E21: =F21/4*C21 -> 92 | F21: 18.4 | G21: =H21/4*C21 -> 1 | H21: 0.2 | I21: 1.2 | J21: 0.643
A22: a1 clovis north | B22: 5 | C22: 20 | D22: 12 | E22: =F22/4*C22 -> 92 | F22: 18.4 | G22: =H22/4*C22 -> 0 | H22: 0 | I22: 1.2 | J22: 0.667
A23: f6 granada | B23: 5 | C23: 20 | D23: 10 | E23: =F23/4*C23 -> 82 | F23: 16.4 | G23: =H23/4*C23 -> 0 | H23: 0 | I23: 1 | J23: 0.8
A24: h5 ward melville | B24: 5 | C24: 20 | D24: 13 | E24: =F24/4*C24 -> 80 | F24: 16 | G24: =H24/4*C24 -> 1 | H24: 0.2 | I24: 0.8 | J24: 0.846
A25: f3 wayzata | B25: 5 | C25: 20 | D25: 15 | E25: =F25/4*C25 -> 78 | F25: 15.6 | G25: =H25/4*C25 -> 2 | H25: 0.4 | I25: 1 | J25: 0.6
A26: b2 asfa | B26: 5 | C26: 20 | D26: 14 | E26: =F26/4*C26 -> 74 | F26: 14.8 | G26: =H26/4*C26 -> 3 | H26: 0.6 | I26: 1 | J26: 0.643
A27: b4 collierville 1 | B27: 5 | C27: 20 | D27: 10 | E27: =F27/4*C27 -> 72 | F27: 14.4 | G27: =H27/4*C27 -> 0 | H27: 0 | I27: 0.8 | J27: 0.8
A28: a2 palo alto | B28: 5 | C28: 20 | D28: 13 | E28: =F28/4*C28 -> 70 | F28: 14 | G28: =H28/4*C28 -> 2 | H28: 0.4 | I28: 1 | J28: 0.538
A29: c5 temple city | B29: 5 | C29: 20 | D29: 13 | E29: =F29/4*C29 -> 64 | F29: 12.8 | G29: =H29/4*C29 -> 2 | H29: 0.4 | I29: 0.8 | J29: 0.615
A30: d6 foothill | B30: 5 | C30: 20 | D30: 17 | E30: =F30/4*C30 -> 64 | F30: 12.8 | G30: =H30/4*C30 -> 4 | H30: 0.8 | I30: 0.8 | J30: 0.588
A31: c1 iolani | B31: 5 | C31: 20 | D31: 14 | E31: =F31/4*C31 -> 62 | F31: 12.4 | G31: =H31/4*C31 -> 0 | H31: 0 | I31: 0.6 | J31: 0.571
... A40: d4 whitney young | B40: 5 | C40: 20 | D40: 10 | E40: =F40/4*C40 -> 30 | F40: 6 | G40: =H40/4*C40 -> 1 | H40: 0.2 | I40: 0.2 | J40: 0.6
A41: c3 amador valley | B41: 5 | C41: 20 | D41: 9 | E41: 30 | F41: =E41/C41*4 -> 6 | G41: =H41/4*C41 -> 0 | H41: 0 | I41: 0.25 | J41: 0.556
A42: d3 collierville 2 | B42: 5 | C42: 20 | D42: 5 | E42: =F42/4*C42 -> 18 | F42: 3.6 | G42: =H42/4*C42 -> 0 | H42: 0 | I42: 0.2 | J42: 0.4
A43: d1 middleton 2 | B43: 5 | C43: 20 | D43: 8 | E43: =F43/4*C43 -> 18 | F43: 3.6 | G43: =H43/4*C43 -> 0 | H43: 0 | I43: 0.2 | J43: 0.25
A44: f2 frazer 2 | B44: 5 | C44: 20 | D44: 7 | E44: =F44/4*C44 -> 18 | F44: 3.6 | G44: =H44/4*C44 -> 0 | H44: 0 | I44: 0.2 | J44: 0.286
A45: f5 hunter | B45: 5 | C45: 20 | D45: 13 | E45: =F45/4*C45 -> 14 | F45: 2.8 | G45: =H45/4*C45 -> 3 | H45: 0.6 | I45: 0.2 | J45: 0.308
A46: b6 madison west 2 | B46: 5 | C46: 20 | D46: 4 | E46: =F46/4*C46 -> 12 | F46: 2.4 | G46: =H46/4*C46 -> 0 | H46: 0 | I46: 0 | J46: 0.75
A47: g6 oak avenue 1 | B47: 5 | C47: 20 | D47: 8 | E47: =F47/4*C47 -> 12 | F47: 2.4 | G47: =H47/4*C47 -> 0 | H47: 0 | I47: 0 | J47: 0.375
A48: c2 oak avenue 2 | B48: 5 | C48: 20 | D48: 9 | E48: =F48/4*C48 -> 8 | F48: 1.6 | G48: =H48/4*C48 -> 0 | H48: 0 | I48: 0 | J48: 0.222
