Workbook

Sheet Single Elimination
A1: =IFERROR('Hidden Sheet'!B87,"Seed 1") -> North Hollywood | B1: 136
A2: Room 1 | C2: =IFS(B1>B3,A1,B3>B1,A3,B3=B1,) -> North Hollywood | D2: 126
A3: =IFERROR('Hidden Sheet'!E94,"Seed 16") -> University B | B3: 12
C4: Room 1 | E4: =IFS(D2>D6,C2,D2<D6,C6,D2=D6,) -> North Hollywood | F4: 106
A5: =IFERROR('Hidden Sheet'!B94,"Seed 8") -> Clovis North | B5: 82
A6: Room 2 | C6: =IFS(B5>B7,A5,B7>B5,A7,B7=B5,) -> Clovis North | D6: 18
A7: =IFERROR('Hidden Sheet'!E87,"Seed 9") -> Green Hope | B7: 68
E8: Stage 1 | G8: =IFS(F4>F12,E4,F4<F12,E12,F4=F12,) -> North Hollywood | H8: 72
A9: =IFERROR('Hidden Sheet'!B90,"Seed 4") -> Lynbrook A | B9: 100
A10: Room 3 | C10: =IFS(B9>B11,A9,B11>B9,A11,B11=B9,) -> Lynbrook A | D10: 120
A11: =IFERROR('Hidden Sheet'!E91, "Seed 13") -> TJHSST B | B11: 38
C12: Room 2 | E12: =IFS(D10>D14,C10,D10<D14,C14,D10=D14,) -> Lynbrook A | F12: -8
A13: =IFERROR('Hidden Sheet'!B91,"Seed 5") -> Iolani | B13: 78
A14: Room 4 | C14: =IFS(B13>B15,A13,B15>B13,A15,B15=B13,) -> Iolani | D14: -8
A15: =IFERROR('Hidden Sheet'!E90,"Seed 12") -> Jordan | B15: 54
G16: Stage 1 | I16: =IFS(H8>H24,G8,H8<H24,G24,H8=H24,) -> North Hollywood
A17: =IFERROR('Hidden Sheet'!B88,"Seed 2") -> Canyon Crest Academy | B17: 82
A18: Room 5 | C18: =IFS(B17>B19,A17,B19>B17,A19,B19=B17,) -> Canyon Crest Academy | D18: 78
A19: =IFERROR('Hidden Sheet'!E93,"Seed 15") -> McLean A | B19: 34
C20: Room 3 | E20: =IFS(D18>D22,C18,D18<D22,C22,D18=D22,) -> Interlake A | F20: 20
A21: =IFERROR('Hidden Sheet'!B93,"Seed 7") -> Amador Valley A | B21: 58
A22: Room 6 | C22: =IFS(B21>B23,A21,B23>B21,A23,B23=B21,) -> Interlake A | D22: 82
A23: =IFERROR('Hidden Sheet'!E88,"Seed 10") -> Interlake A | B23: 90
E24: Stage 2 | G24: =IFS(F20>F28,E20,F20<F28,E28,F20=F28,) -> Clements | H24: 70
A25: =IFERROR('Hidden Sheet'!B89,"Seed 3") -> WWPN | B25: 86
A26: Room 7 | C26: =IFS(B25>B27,A25,B27>B25,A27,B27=B25,) -> WWPN | D26: 28
A27: =IFERROR('Hidden Sheet'!E92,"Seed 14") -> TJHSST A | B27: 78
C28: Room 4 | E28: =IFS(D26>D30,C26,D26<D30,C30,D26=D30,) -> Clements | F28: 54
A29: =IFERROR('Hidden Sheet'!B92,"Seed 6") -> Clements | B29: 84
A30: Room 8 | C30: =IFS(B29>B31,A29,B31>B29,A31,B31=B29,) -> Clements | D30: 118
A31: =IFERROR('Hidden Sheet'!E89,"Seed 11") -> University A | B31: 76

Sheet Round Robin
B1: Example Group
C4: =B7 -> Team 1 | D4: =B8 -> Team 2 | E4: =B9 -> Team 3 | F4: =B10 -> Team 4 | G4: PPG | H4: Points
J6: Order of Matchups:
B7: Team 1 | G7: =IFERROR(ROUND(AVERAGE(C7:F7),2),) | H7: ='Hidden Sheet'!Y5 | J7: Room 1 | K7: Room 2
B8: Team 2 | G8: =IFERROR(ROUND(AVERAGE(C8:F8),2),) | H8: ='Hidden Sheet'!Z5 | I8: RR1 | J8: Team 1 vs Team 2 | K8: Team 3 vs Team 4 | Q8: 10:30 EST
B9: Team 3 | G9: =IFERROR(ROUND(AVERAGE(C9:F9),2),) | H9: ='Hidden Sheet'!AA5 | I9: RR2 | J9: Team 1 vs Team 3 | K9: Team 2 vs Team 4 | Q9: 11:20 EST
B10: Team 4 | G10: =IFERROR(ROUND(AVERAGE(C10:F10),2),) | H10: ='Hidden Sheet'!AB5 | I10: RR3 | J10: Team 1 vs Team 4 | K10: Team 2 vs Team 3 | Q10: 12:10 EST
B12: Branch | J12: Campbell
C15: =B18 -> Brooklyn Tech A | D15: =B19 -> Canyon Crest Academy | E15: =B20 -> Dulles | F15: =B21 -> Jordan | G15: PPG | H15: Points | K15: =J18 -> Del Norte | L15: =J19 -> North Hollywood | M15: =J20 -> St. Mark's | N15: =J21 -> University A | O15: PPG | P15: Points
B18: Brooklyn Tech A | D18: -8 | E18: 50 | F18: 4 | G18: =IFERROR(ROUND(AVERAGE(C18:F18),2),) -> 15.33 | H18: ='Hidden Sheet'!D5 -> 2 | I18: =CONCATENATE(CONCAT("W: ",COUNTIF('Hidden Sheet'!D2:D4, 2)), (CONCAT(" T: ", COUNTIF('Hidden Sheet'!D2:D4, 1))), CONCAT(" L: ",COUNTIF('Hidden Sheet'!D2:D4, 0))) -> W: 1 T: 0 L: 2 | J18: Del Norte | L18: 10 | M18: 60 | N18: 0 | O18: =IFERROR(ROUND(AVERAGE(K18:N18),2),) -> 23.33 | P18: ='Hidden Sheet'!P5 -> 0 | Q18: =CONCATENATE(CONCAT("W: ",COUNTIF('Hidden Sheet'!P2:P4, 2)), (CONCAT(" T: ", COUNTIF('Hidden Sheet'!P2:P4, 1))), CONCAT(" L: ",COUNTIF('Hidden Sheet'!P2:P4, 0))) -> W: 0 T: 0 L: 3
B19: Canyon Crest Academy | C19: 164 | E19: 176 | F19: 98 | G19: =IFERROR(ROUND(AVERAGE(C19:F19),2),) -> 146 | H19: ='Hidden Sheet'!E5 -> 4 | I19: =CONCATENATE(CONCAT("W: ",COUNTIF('Hidden Sheet'!E2:E4, 2)), (CONCAT(" T: ", COUNTIF('Hidden Sheet'!E2:E4, 1))), CONCAT(" L: ",COUNTIF('Hidden Sheet'!E2:E4, 0))) -> W: 2 T: 0 L: 1 | J19: North Hollywood | K19: 126 | M19: 150 | N19: 180 | O19: =IFERROR(ROUND(AVERAGE(K19:N19),2),) -> 152 | P19: ='Hidden Sheet'!Q5 -> 6 | Q19: =CONCATENATE(CONCAT("W: ",COUNTIF('Hidden Sheet'!Q2:Q4, 2)), (CONCAT(" T: ", COUNTIF('Hidden Sheet'!Q2:Q4, 1))), CONCAT(" L: ",COUNTIF('Hidden Sheet'!Q2:Q4, 0))) -> W: 3 T: 0 L: 0
B20: Dulles | C20: 44 | D20: 32 | F20: 82 | G20: =IFERROR(ROUND(AVERAGE(C20:F20),2),) -> 52.67 | H20: ='Hidden Sheet'!F5 -> 2 | I20: =CONCATENATE(CONCAT("W: ",COUNTIF('Hidden Sheet'!F2:F4, 2)), (CONCAT(" T: ", COUNTIF('Hidden Sheet'!F2:F4, 1))), CONCAT(" L: ",COUNTIF('Hidden Sheet'!F2:F4, 0))) -> W: 1 T: 0 L: 2 | J20: St. Mark's | K20: 82 | L20: 18 | N20: 28 | O20: =IFERROR(ROUND(AVERAGE(K20:N20),2),) -> 42.67 | P20: ='Hidden Sheet'!R5 -> 2 | Q20: =CONCATENATE(CONCAT("W: ",COUNTIF('Hidden Sheet'!R2:R4, 2)), (CONCAT(" T: ", COUNTIF('Hidden Sheet'!R2:R4, 1))), CONCAT(" L: ",COUNTIF('Hidden Sheet'!R2:R4, 0))) -> W: 1 T: 0 L: 2
B21: Jordan | C21: 118 | D21: 114 | E21: 54 | G21: =IFERROR(ROUND(AVERAGE(C21:F21),2),) -> 95.33 | H21: ='Hidden Sheet'!G5 -> 4 | I21: =CONCATENATE(CONCAT("W: ",COUNTIF('Hidden Sheet'!G2:G4, 2)), (CONCAT(" T: ", COUNTIF('Hidden Sheet'!G2:G4, 1))), CONCAT(" L: ",COUNTIF('Hidden Sheet'!G2:G4, 0))) -> W: 2 T: 0 L: 1 | J21: University A | K21: 138 | L21: 32 | M21: 124 | O21: =IFERROR(ROUND(AVERAGE(K21:N21),2),) -> 98 | P21: ='Hidden Sheet'!S5 -> 4 | Q21: =CONCATENATE(CONCAT("W: ",COUNTIF('Hidden Sheet'!S2:S4, 2)), (CONCAT(" T: ", COUNTIF('Hidden Sheet'!S2:S4, 1))), CONCAT(" L: ",COUNTIF('Hidden Sheet'!S2:S4, 0))) -> W: 2 T: 0 L: 1
B23: Goff | J23: Hutchinson
C26: =B29 -> American A | D26: =B30 -> East Brunswick A | E26: =B31 -> WWPN | F26: =B32 -> University B | G26: PPG | H26: Points | K26: =J29 -> Cupertino | L26: =J30 -> Enloe | M26: =J31 -> Iolani | N26: =J32 -> TJHSST B | O26: PPG | P26: Points
B29: American A | D29: -2 | E29: 36 | F29: 42 | G29: =IFERROR(ROUND(AVERAGE(C29:F29),2),) -> 25.33 | H29: ='Hidden Sheet'!D22 -> 2 | I29: =CONCATENATE(CONCAT("W: ",COUNTIF('Hidden Sheet'!D$19:D$21, 2)), (CONCAT(" T: ", COUNTIF('Hidden Sheet'!D$19:D$21, 1))), CONCAT(" L: ",COUNTIF('Hidden Sheet'!D$19:D$21, 0))) -> W: 1 T: 0 L: 2 | J29: Cupertino | L29: 20 | M29: 4 | N29: 4 | O29: =IFERROR(ROUND(AVERAGE(K29:N29),2),) -> 9.33 | P29: ='Hidden Sheet'!P22 -> 0 | Q29: =CONCATENATE(CONCAT("W: ",COUNTIF('Hidden Sheet'!P19:P21, 2)), (CONCAT(" T: ", COUNTIF('Hidden Sheet'!P19:P21, 1))), CONCAT(" L: ",COUNTIF('Hidden Sheet'!P19:P21, 0))) -> W: 0 T: 0 L: 3
B30: East Brunswick A | C30: 62 | E30: 10 | F30: 40 | G30: =IFERROR(ROUND(AVERAGE(C30:F30),2),) -> 37.33 | H30: ='Hidden Sheet'!E22 -> 2 | I30: =CONCATENATE(CONCAT("W: ",COUNTIF('Hidden Sheet'!E$19:E$21, 2)), (CONCAT(" T: ", COUNTIF('Hidden Sheet'!E$19:E$21, 1))), CONCAT(" L: ",COUNTIF('Hidden Sheet'!E$19:E$21, 0))) -> W: 1 T: 0 L: 2 | J30: Enloe | K30: 40 | M30: 14 | N30: 8 | O30: =IFERROR(ROUND(AVERAGE(K30:N30),2),) -> 20.67 | P30: ='Hidden Sheet'!Q22 -> 2 | Q30: =CONCATENATE(CONCAT("W: ",COUNTIF('Hidden Sheet'!Q19:Q21, 2)), (CONCAT(" T: ", COUNTIF('Hidden Sheet'!Q19:Q21, 1))), CONCAT(" L: ",COUNTIF('Hidden Sheet'!Q19:Q21, 0))) -> W: 1 T: 0 L: 2
B31: WWPN | C31: 166 | D31: 108 | F31: 156 | G31: =IFERROR(ROUND(AVERAGE(C31:F31),2),) -> 143.33 | H31: ='Hidden Sheet'!F22 -> 6 | I31: =CONCATENATE(CONCAT("W: ",COUNTIF('Hidden Sheet'!F$19:F$21, 2)), (CONCAT(" T: ", COUNTIF('Hidden Sheet'!F$19:F$21, 1))), CONCAT(" L: ",COUNTIF('Hidden Sheet'!F$19:F$21, 0))) -> W: 3 T: 0 L: 0 | J31: Iolani | K31: 128 | L31: 154 | N31: 88 | O31: =IFERROR(ROUND(AVERAGE(K31:N31),2),) -> 123.33 | P31: ='Hidden Sheet'!R22 -> 6 | Q31: =CONCATENATE(CONCAT("W: ",COUNTIF('Hidden Sheet'!R19:R21, 2)), (CONCAT(" T: ", COUNTIF('Hidden Sheet'!R19:R21, 1))), CONCAT(" L: ",COUNTIF('Hidden Sheet'!R19:R21, 0))) -> W: 3 T: 0 L: 0
B32: University B | C32: 30 | D32: 70 | E32: 18 | G32: =IFERROR(ROUND(AVERAGE(C32:F32),2),) -> 39.33 | H32: ='Hidden Sheet'!G22 -> 2 | I32: =CONCATENATE(CONCAT("W: ",COUNTIF('Hidden Sheet'!G$19:G$21, 2)), (CONCAT(" T: ", COUNTIF('Hidden Sheet'!G$19:G$21, 1))), CONCAT(" L: ",COUNTIF('Hidden Sheet'!G$19:G$21, 0))) -> W: 1 T: 0 L: 2 | J32: TJHSST B | K32: 68 | L32: 142 | M32: 64 | O32: =IFERROR(ROUND(AVERAGE(K32:N32),2),) -> 91.33 | P32: ='Hidden Sheet'!S22 -> 4 | Q32: =CONCATENATE(CONCAT("W: ",COUNTIF('Hidden Sheet'!S19:S21, 2)), (CONCAT(" T: ", COUNTIF('Hidden Sheet'!S19:S21, 1))), CONCAT(" L: ",COUNTIF('Hidden Sheet'!S19:S21, 0))) -> W: 2 T: 0 L: 1
B34: Jacobs | J34: LaPorta
C37: =B40 -> Amador Valley B | D37: =B41 -> Clovis North | E37: =B42 -> Green Hope | F37: =B43 -> Montgomery Blair A | G37: PPG | H37: Points | K37: =J40 -> American B | L37: =J41 -> BASIS McLean | M37: =J42 -> Interlake A | N37: =J43 -> Amador Valley A | O37: PPG | P37: Points
B40: Amador Valley B | D40: 44 | E40: 16 | F40: 22 | G40: =IFERROR(ROUND(AVERAGE(C40:F40),2),) -> 27.33 | H40: ='Hidden Sheet'!D39 -> 0 | I40: =CONCATENATE(CONCAT("W: ",COUNTIF('Hidden Sheet'!D36:D38, 2)), (CONCAT(" T: ", COUNTIF('Hidden Sheet'!D36:D38, 1))), CONCAT(" L: ",COUNTIF('Hidden Sheet'!D36:D38, 0))) -> W: 0 T: 0 L: 3 | J40: American B | L40: 32 | M40: 0 | N40: 4 | O40: =IFERROR(ROUND(AVERAGE(K40:N40),2),) -> 12 | P40: ='Hidden Sheet'!P39 -> 0 | Q40: =CONCATENATE(CONCAT("W: ",COUNTIF('Hidden Sheet'!P36:P38, 2)), (CONCAT(" T: ", COUNTIF('Hidden Sheet'!P36:P38, 1))), CONCAT(" L: ",COUNTIF('Hidden Sheet'!P36:P38, 0))) -> W: 0 T: 0 L: 3
B41: Clovis North | C41: 88 | E41: 82 | F41: 92 | G41: =IFERROR(ROUND(AVERAGE(C41:F41),2),) -> 87.33 | H41: ='Hidden Sheet'!E39 -> 6 | I41: =CONCATENATE(CONCAT("W: ",COUNTIF('Hidden Sheet'!E36:E38, 2)), (CONCAT(" T: ", COUNTIF('Hidden Sheet'!E36:E38, 1))), CONCAT(" L: ",COUNTIF('Hidden Sheet'!E36:E38, 0))) -> W: 3 T: 0 L: 0 | J41: BASIS McLean | K41: 36 | M41: 60 | N41: 26 | O41: =IFERROR(ROUND(AVERAGE(K41:N41),2),) -> 40.67 | P41: ='Hidden Sheet'!Q39 -> 2 | Q41: =CONCATENATE(CONCAT("W: ",COUNTIF('Hidden Sheet'!Q36:Q38, 2)), (CONCAT(" T: ", COUNTIF('Hidden Sheet'!Q36:Q38, 1))), CONCAT(" L: ",COUNTIF('Hidden Sheet'!Q36:Q38, 0))) -> W: 1 T: 0 L: 2
B42: Green Hope | C42: 138 | D42: 58 | F42: 120 | G42: =IFERROR(ROUND(AVERAGE(C42:F42),2),) -> 105.33 | H42: ='Hidden Sheet'!F39 -> 4 | I42: =CONCATENATE(CONCAT("W: ",COUNTIF('Hidden Sheet'!F36:F38, 2)), (CONCAT(" T: ", COUNTIF('Hidden Sheet'!F36:F38, 1))), CONCAT(" L: ",COUNTIF('Hidden Sheet'!F36:F38, 0))) -> W: 2 T: 0 L: 1 | J42: Interlake A | K42: 138 | L42: 102 | N42: 74 | O42: =IFERROR(ROUND(AVERAGE(K42:N42),2),) -> 104.67 | P42: ='Hidden Sheet'!R39 -> 4 | Q42: =CONCATENATE(CONCAT("W: ",COUNTIF('Hidden Sheet'!R36:R38, 2)), (CONCAT(" T: ", COUNTIF('Hidden Sheet'!R36:R38, 1))), CONCAT(" L: ",COUNTIF('Hidden Sheet'!R36:R38, 0))) -> W: 2 T: 0 L: 1
B43: Montgomery Blair A | C43: 56 | D43: 68 | E43: 18 | G43: =IFERROR(ROUND(AVERAGE(C43:F43),2),) -> 47.33 | H43: ='Hidden Sheet'!G39 -> 2 | I43: =CONCATENATE(CONCAT("W: ",COUNTIF('Hidden Sheet'!G36:G38, 2)), (CONCAT(" T: ", COUNTIF('Hidden Sheet'!G36:G38, 1))), CONCAT(" L: ",COUNTIF('Hidden Sheet'!G36:G38, 0))) -> W: 1 T: 0 L: 2 | J43: Amador Valley A | K43: 96 | L43: 132 | M43: 78 | O43: =IFERROR(ROUND(AVERAGE(K43:N43),2),) -> 102 | P43: ='Hidden Sheet'!S39 -> 6 | Q43: =CONCATENATE(CONCAT("W: ",COUNTIF('Hidden Sheet'!S36:S38, 2)), (CONCAT(" T: ", COUNTIF('Hidden Sheet'!S36:S38, 1))), CONCAT(" L: ",COUNTIF('Hidden Sheet'!S36:S38, 0))) -> W: 3 T: 0 L: 0
B45: Reynolds | J45: St. Brown
C48: =B51 -> Buchholz A | D48: =B52 -> Clements | E48: =B53 -> Foothill B | F48: =B54 -> TJHSST A | G48: PPG | H48: Points | K48: =J51 -> Lynbrook A | L48: =J52 -> McLean A | M48: =J53 -> Stuyvesant | N48: =J54 -> Foothill A | O48: PPG | P48: Points
B51: Buchholz A | D51: 70 | E51: 110 | F51: 54 | G51: =IFERROR(ROUND(AVERAGE(C51:F51),2),) -> 78 | H51: ='Hidden Sheet'!D65 -> 2 | I51: =CONCATENATE(CONCAT("W: ",COUNTIF('Hidden Sheet'!D62:D64, 2)), (CONCAT(" T: ", COUNTIF('Hidden Sheet'!D62:D64, 1))), CONCAT(" L: ",COUNTIF('Hidden Sheet'!D62:D64, 0))) -> W: 1 T: 0 L: 2 | J51: Lynbrook A | L51: 142 | M51: 126 | N51: 118 | O51: =IFERROR(ROUND(AVERAGE(K51:N51),2),) -> 128.67 | P51: ='Hidden Sheet'!P65 -> 6 | Q51: =CONCATENATE(CONCAT("W: ",COUNTIF('Hidden Sheet'!P62:P64, 2)), (CONCAT(" T: ", COUNTIF('Hidden Sheet'!P62:P64, 1))), CONCAT(" L: ",COUNTIF('Hidden Sheet'!P62:P64, 0))) -> W: 3 T: 0 L: 0
B52: Clements | C52: 72 | E52: 134 | F52: 148 | G52: =IFERROR(ROUND(AVERAGE(C52:F52),2),) -> 118 | H52: ='Hidden Sheet'!E65 -> 6 | I52: =CONCATENATE(CONCAT("W: ",COUNTIF('Hidden Sheet'!E62:E64, 2)), (CONCAT(" T: ", COUNTIF('Hidden Sheet'!E62:E64, 1))), CONCAT(" L: ",COUNTIF('Hidden Sheet'!E62:E64, 0))) -> W: 3 T: 0 L: 0 | J52: McLean A | K52: 10 | M52: 36 | N52: 96 | O52: =IFERROR(ROUND(AVERAGE(K52:N52),2),) -> 47.33 | P52: ='Hidden Sheet'!Q65 -> 4 | Q52: =CONCATENATE(CONCAT("W: ",COUNTIF('Hidden Sheet'!Q62:Q64, 2)), (CONCAT(" T: ", COUNTIF('Hidden Sheet'!Q62:Q64, 1))), CONCAT(" L: ",COUNTIF('Hidden Sheet'!Q62:Q64, 0))) -> W: 2 T: 0 L: 1
B53: Foothill B | C53: 4 | D53: 8 | F53: 22 | G53: =IFERROR(ROUND(AVERAGE(C53:F53),2),) -> 11.33 | H53: ='Hidden Sheet'!F65 -> 0 | I53: =CONCATENATE(CONCAT("W: ",COUNTIF('Hidden Sheet'!F62:F64, 2)), (CONCAT(" T: ", COUNTIF('Hidden Sheet'!F62:F64, 1))), CONCAT(" L: ",COUNTIF('Hidden Sheet'!F62:F64, 0))) -> W: 0 T: 0 L: 3 | J53: Stuyvesant | K53: 26 | L53: 30 | N53: 42 | O53: =IFERROR(ROUND(AVERAGE(K53:N53),2),) -> 32.67 | P53: ='Hidden Sheet'!R65 -> 0 | Q53: =CONCATENATE(CONCAT("W: ",COUNTIF('Hidden Sheet'!R62:R64, 2)), (CONCAT(" T: ", COUNTIF('Hidden Sheet'!R62:R64, 1))), CONCAT(" L: ",COUNTIF('Hidden Sheet'!R62:R64, 0))) -> W: 0 T: 0 L: 3
B54: TJHSST A | C54: 64 | D54: 42 | E54: 162 | G54: =IFERROR(ROUND(AVERAGE(C54:F54),2),) -> 89.33 | H54: ='Hidden Sheet'!G65 -> 4 | I54: =CONCATENATE(CONCAT("W: ",COUNTIF('Hidden Sheet'!G62:G64, 2)), (CONCAT(" T: ", COUNTIF('Hidden Sheet'!G62:G64, 1))), CONCAT(" L: ",COUNTIF('Hidden Sheet'!G62:G64, 0))) -> W: 2 T: 0 L: 1 | J54: Foothill A | K54: 8 | L54: 32 | M54: 52 | O54: =IFERROR(ROUND(AVERAGE(K54:N54),2),) -> 30.67 | P54: ='Hidden Sheet'!S65 -> 2 | Q54: =CONCATENATE(CONCAT("W: ",COUNTIF('Hidden Sheet'!S62:S64, 2)), (CONCAT(" T: ", COUNTIF('Hidden Sheet'!S62:S64, 1))), CONCAT(" L: ",COUNTIF('Hidden Sheet'!S62:S64, 0))) -> W: 1 T: 0 L: 2

Sheet Hidden Sheet
A1: Group A | D1: ='Round Robin'!B18 -> Brooklyn Tech A | E1: ='Round Robin'!B19 -> Canyon Crest Academy | F1: ='Round Robin'!B20 -> Dulles | G1: ='Round Robin'!B21 -> Jordan | H1: =LARGE(D5:G5,3) -> 2 | I1: =IFS(AND(H1=D5,D1<>B10,D1<>B13),D1,AND(H1=E5,E1<>B10,E1<>B13),E1,AND(H1=F5,F1<>B10,F1<>B13),F1,AND(H1=G5,G1<>B10,G1<>B13),G1) -> Brooklyn Tech A | M1: Group B | P1: ='Round Robin'!J18 -> Del Norte | Q1: ='Round Robin'!J19 -> North Hollywood | R1: ='Round Robin'!J20 -> St. Mark's | S1: ='Round Robin'!J21 -> University A | T1: =LARGE(P5:S5,3) -> 2 | U1: =IFS(AND(T1=P5,P1<>N10,P1<>N13),P1,AND(T1=Q5,Q1<>N10,Q1<>N13),Q1,AND(T1=R5,R1<>N10,R1<>N13),R1,AND(T1=S5,S1<>N10,S1<>N13),S1) -> St. Mark's
A2: ='Round Robin'!D18 -> -8 | B2: ='Round Robin'!C19 -> 164 | C2: 1v2 | D2: =IF(ISBLANK(A2),,IFS(A2>B2,2,A2=B2,1,A2<B2,0)) -> 0 | E2: =IF(ISBLANK(A2),,IFS(A2>B2,0,A2=B2,1,A2<B2,2)) -> 2 | F2: =IF(ISBLANK(A3),,IFS(A3>B3,0,A3=B3,1,A3<B3,2)) -> 0 | G2: =IF(ISBLANK(A4),,IFS(A4>B4,0,A4=B4,1,A4<B4,2)) -> 2 | H2: =LARGE(D5:G5,4) -> 2 | I2: =IF(H2=H1,IFS(AND(H2=D5,D1<>B10,D1<>B13,D1<>I1),D1,AND(H2=E5,E1<>B10,E1<>B13,E1<>I1),E1,AND(H2=F5,F1<>B10,F1<>B13,F1<>I1),F1,AND(H2=G5,G1<>B10,G1<>B13,G1<>I1),G1),) -> Dulles | M2: ='Round Robin'!L18 -> 10 | N2: ='Round Robin'!K19 -> 126 | O2: 1v2 | P2: =IF(ISBLANK(M2),,IFS(M2>N2,2,M2=N2,1,M2<N2,0)) -> 0 | Q2: =IF(ISBLANK(M2),,IFS(M2>N2,0,M2=N2,1,M2<N2,2)) -> 2 | R2: =IF(ISBLANK(M3),,IFS(M3>N3,0,M3=N3,1,M3<N3,2)) -> 2 | S2: =IF(ISBLANK(M4),,IFS(M4>N4,0,M4=N4,1,M4<N4,2)) -> 2 | T2: =LARGE(P5:S5,4) -> 0 | U2: =IF(T2=T1,IFS(AND(T2=P5,P1<>N10,P1<>N13,P1<>U1),P1,AND(T2=Q5,Q1<>N10,Q1<>N13,Q1<>U1),Q1,AND(T2=R5,R1<>N10,R1<>N13,R1<>U1),R1,AND(T2=S5,S1<>N10,S1<>N13,S1<>U1),S1),)
A3: ='Round Robin'!E18 -> 50 | B3: ='Round Robin'!C20 -> 44 | C3: 1v3 | D3: =IF(ISBLANK(A3),,IFS(A3>B3,2,A3=B3,1,A3<B3,0)) -> 2 | E3: =IF(ISBLANK(A5),,IFS(A5>B5,2,A5=B5,1,A5<B5,0)) -> 2 | F3: =IF(ISBLANK(A5),,IFS(A5>B5,0,A5=B5,1,A5<B5,2)) -> 0 | G3: =IF(ISBLANK(A6),,IFS(A6>B6,0,A6=B6,1,A6<B6,2)) -> 2 | H3: =IF(H2=H1,HLOOKUP(I1,D8:G9,2,FALSE)) -> 15.33 | I3: =I1 -> Brooklyn Tech A | M3: ='Round Robin'!M18 -> 60 | N3: ='Round Robin'!K20 -> 82 | O3: 1v3 | P3: =IF(ISBLANK(M3),,IFS(M3>N3,2,M3=N3,1,M3<N3,0)) -> 0 | Q3: =IF(ISBLANK(M5),,IFS(M5>N5,2,M5=N5,1,M5<N5,0)) -> 2 | R3: =IF(ISBLANK(M5),,IFS(M5>N5,0,M5=N5,1,M5<N5,2)) -> 0 | S3: =IF(ISBLANK(M6),,IFS(M6>N6,0,M6=N6,1,M6<N6,2)) -> 0 | T3: =IF(T2=T1,HLOOKUP(U1,P8:S9,2,FALSE)) -> FALSE | U3: =U1 -> St. Mark's
A4: ='Round Robin'!F18 -> 4 | B4: ='Round Robin'!C21 -> 118 | C4: 1v4 | D4: =IF(ISBLANK(A4),,IFS(A4>B4,2,A4=B4,1,A4<B4,0)) -> 0 | E4: =IF(ISBLANK(A6),,IFS(A6>B6,2,A6=B6,1,A6<B6,0)) -> 0 | F4: =IF(ISBLANK(A7),,IFS(A7>B7,2,A7=B7,1,A7<B7,0)) -> 2 | G4: =IF(ISBLANK(A7),,IFS(A7>B7,0,A7=B7,1,A7<B7,2)) -> 0 | H4: =IF(H2=H1,HLOOKUP(I2,D8:G9,2,FALSE)) -> 52.67 | I4: =I2 -> Dulles | M4: ='Round Robin'!N18 -> 0 | N4: ='Round Robin'!K21 -> 138 | O4: 1v4 | P4: =IF(ISBLANK(M4),,IFS(M4>N4,2,M4=N4,1,M4<N4,0)) -> 0 | Q4: =IF(ISBLANK(M6),,IFS(M6>N6,2,M6=N6,1,M6<N6,0)) -> 2 | R4: =IF(ISBLANK(M7),,IFS(M7>N7,2,M7=N7,1,M7<N7,0)) -> 0 | S4: =IF(ISBLANK(M7),,IFS(M7>N7,0,M7=N7,1,M7<N7,2)) -> 2 | T4: =IF(T2=T1,HLOOKUP(U2,P8:S9,2,FALSE)) -> FALSE | U4: =U2
A5: ='Round Robin'!E19 -> 176 | B5: ='Round Robin'!D20 -> 32 | C5: 2v3 | D5: =SUM(D2:D4) -> 2 | E5: =SUM(E2:E4) -> 4 | F5: =SUM(F2:F4) -> 2 | G5: =SUM(G2:G4) -> 4 | H5: =IFS(H3=FALSE,I1,H3>H4,I3,H3<H4,I4,H3=H4,CONCATENATE("Tie", I3, I4)) -> Dulles | I5: =IFS(H3>H4,H3,H4>H3,H4,H3=H4,H4) -> 52.67 | M5: ='Round Robin'!M19 -> 150 | N5: ='Round Robin'!L20 -> 18 | O5: 2v3 | P5: =SUM(P2:P4) -> 0 | Q5: =SUM(Q2:Q4) -> 6 | R5: =SUM(R2:R4) -> 2 | S5: =SUM(S2:S4) -> 4 | T5: =IFS(T3=FALSE,U1,T3>T4,U3,T3<T4,U4,T3=T4,CONCATENATE("Tie", U3, U4)) -> St. Mark's | U5: =IFS(T3>T4,T3,T4>T3,T4,T3=T4,T4) -> FALSE
A6: ='Round Robin'!F19 -> 98 | B6: ='Round Robin'!D21 -> 114 | C6: 2v4 | F6: =IF(OR(D5="",E5="",F5="",G5="",G4="",F4="",E4="",D4="",D3="",D2="",E3="",E2="",F3="",F2="",G3="",G2=""),"",IFNA(IFS(AND(D7=E5,E1<>E7),'Round Robin'!D15,AND(D7=F5,F1<>E7),'Round Robin'!E15,AND(D7=G5,G1<>E7),'Round Robin'!F15),"")) -> Jordan | G6: =IF(OR(D5="",E5="",F5="",G5="",G4="",F4="",E4="",D4="",D3="",D2="",E3="",E2="",F3="",F2="",G3="",G2=""),"",IFNA(IFS(AND(D7=F5,F1<>E7,F1<>F7),'Round Robin'!E15,AND(D7=G5,G1<>E7,G1<>F7),'Round Robin'!F15),"")) | M6: ='Round Robin'!N19 -> 180 | N6: ='Round Robin'!L21 -> 32 | O6: 2v4 | R6: =IF(OR(P5="",Q5="",R5="",S5="",S4="",R4="",Q4="",P4="",P3="",P2="",Q3="",Q2="",R3="",R2="",S3="",S2=""),"",IFNA(IFS(AND(P7=Q5,Q1<>Q7),Q1,AND(P7=R5,R1<>Q7),R1,AND(P7=S5,S1<>Q7),S1),"")) | S6: =IF(OR(P5="",Q5="",R5="",S5="",S4="",R4="",Q4="",P4="",P3="",P2="",Q3="",Q2="",R3="",R2="",S3="",S2=""),"",IFNA(IFS(AND(P7=R5,R1<>Q7,R1<>R7),R1,AND(P7=S5,S1<>Q7,S1<>R7),S1),""))
A7: ='Round Robin'!F20 -> 82 | B7: ='Round Robin'!E21 -> 54 | C7: 3v4 | D7: =MAX(D5:G5) -> 4 | E7: =IF(OR(D5="",E5="",F5="",G5="",G4="",F4="",E4="",D4="",D3="",D2="",E3="",E2="",F3="",F2="",G3="",G2=""),"",IFS(D7=D5,'Round Robin'!C15,D7=E5,'Round Robin'!D15,D7=F5,'Round Robin'!E15,D7=G5,'Round Robin'!F15)) -> Canyon Crest Academy | F7: =IF(AND(F6<>E7),F6,"") -> Jordan | G7: =IF(AND(G6<>E7,G6<>F7),G6,"") | M7: ='Round Robin'!N20 -> 28 | N7: ='Round Robin'!M21 -> 124 | O7: 3v4 | P7: =MAX(P5:S5) -> 6 | Q7: =IF(OR(P5="",Q5="",R5="",S5="",S4="",R4="",Q4="",P4="",P3="",P2="",Q3="",Q2="",R3="",R2="",S3="",S2=""),"",IFS(P7=P5,'Round Robin'!K15,P7=Q5,'Round Robin'!L15,P7=R5,'Round Robin'!M15,P7=S5,'Round Robin'!N15)) -> North Hollywood | R7: =IF(R6<>Q7,R6,"") | S7: =IF(AND(S6<>Q7,S6<>R7),S6,"")
D8: =D1 -> Brooklyn Tech A | E8: =E1 -> Canyon Crest Academy | F8: =F1 -> Dulles | G8: =G1 -> Jordan | P8: =P1 -> Del Norte | Q8: =Q1 -> North Hollywood | R8: =R1 -> St. Mark's | S8: =S1 -> University A
A9: =HLOOKUP(E7,D8:G9,2,FALSE) -> 146 | B9: =IFERROR(HLOOKUP(F7,D8:G9,2,FALSE),"") -> 95.33 | C9: =IFERROR(HLOOKUP(G7,E8:L9,2,FALSE),"") | D9: ='Round Robin'!G18 -> 15.33 | E9: ='Round Robin'!G19 -> 146 | F9: ='Round Robin'!G20 -> 52.67 | G9: ='Round Robin'!G21 -> 95.33 | M9: =HLOOKUP(Q7,P8:S9,2,FALSE) -> 152 | N9: =IFERROR(HLOOKUP(R7,P8:S9,2,FALSE),"") | O9: =IFERROR(HLOOKUP(S7,Q8:T9,2,FALSE),"") | P9: ='Round Robin'!O18 -> 23.33 | Q9: ='Round Robin'!O19 -> 152 | R9: ='Round Robin'!O20 -> 42.67 | S9: ='Round Robin'!O21 -> 98
A10: =MAX(A9:C9) -> 146 | B10: =IFNA(HLOOKUP(A10,D9:G10,2,FALSE),"Branch #1") -> Canyon Crest Academy | D10: =D1 -> Brooklyn Tech A | E10: =E1 -> Canyon Crest Academy | F10: =F1 -> Dulles | G10: =G1 -> Jordan | M10: =MAX(M9:O9) -> 152 | N10: =IFNA(HLOOKUP(M10,P9:S10,2,FALSE),"Campbell #1") -> North Hollywood | P10: =P1 -> Del Norte | Q10: =Q1 -> North Hollywood | R10: =R1 -> St. Mark's | S10: =S1 -> University A
F11: =IF(OR(D2="",E2="",F2="",G2="",G3="",F3="",E3="",D3="",D4="",D5="",E4="",E5="",F4="",F5="",G4="",G5=""),"",IFNA(IFS(AND(D12=E5,E1<>E12),E1,AND(D12=F5,F1<>E12),F1,AND(D12=G5,G1<>E12),G1),"")) -> Canyon Crest Academy | G11: =IF(OR(D2="",E2="",F2="",G2="",G3="",F3="",E3="",D3="",D4="",D5="",E4="",E5="",F4="",F5="",G4="",G5=""),"",IFNA(IFS(AND(D12=E5,E1<>E12,E1<>F12),E1,AND(D12=F5,F1<>E12,F1<>F12),F1,AND(D12=G5,G1<>E12,G1<>F12),G1),"")) -> Canyon Crest Academy | H11: =IF(OR(E5="",F5="",G5="",H5="",H4="",G4="",F4="",E4="",E3="",E2="",F3="",F2="",G3="",G2="",H3="",H2=""),"",IFNA(IFS(E7=F5,'Round Robin'!A15,E7=G5,'Round Robin'!B15,E7=H5,'Round Robin'!C15),"")) | R11: =IF(OR(P2="",Q2="",R2="",S2="",S3="",R3="",Q3="",P3="",P4="",P5="",Q4="",Q5="",R4="",R5="",S4="",S5=""),"",IFNA(IFS(AND(P12=Q5,Q1<>Q12),Q1,AND(P12=R5,R1<>Q12),R1,AND(P12=S5,S1<>Q12),S1),"")) | S11: =IF(OR(P2="",Q2="",R2="",S2="",S3="",R3="",Q3="",P3="",P4="",P5="",Q4="",Q5="",R4="",R5="",S4="",S5=""),"",IFNA(IFS(AND(P12=Q5,Q1<>Q12,Q1<>R12),Q1,AND(P12=R5,R1<>Q12,R1<>R12),R1,AND(P12=S5,S1<>Q12,S1<>R12),S1),""))
D12: =LARGE(D5:G5,2) -> 4 | E12: =IF(OR(D5="",E5="",F5="",G5="",G4="",F4="",E4="",D4="",D3="",D2="",E3="",E2="",F3="",F2="",G3="",G2=""),"",IFS(AND(D12=D5,D1<>B10),D1,AND(D12=E5,E1<>B10),E1,AND(D12=F5,F1<>B10),F1,AND(D12=G5,G1<>B10),G1)) -> Jordan | F12: =IF(AND(F11<>E12,F11<>B10),F11,"") | G12: =IF(AND(G11<>E12,G11<>F12,G11<>B10),G11,"") | P12: =LARGE(P5:S5,2) -> 4 | Q12: =IF(OR(P5="",Q5="",R5="",S5="",S4="",R4="",Q4="",P4="",P3="",P2="",Q3="",Q2="",R3="",R2="",S3="",S2=""),"",IFS(AND(P12=P5,P1<>N10),P1,AND(P12=Q5,Q1<>N10),Q1,AND(P12=R5,R1<>N10),R1,AND(P12=S5,S1<>N10),S1)) -> University A | R12: =IF(AND(R11<>Q12,R11<>N10),R11,"") | S12: =IF(AND(S11<>Q12,S11<>R12,S11<>N10),S11,"")
A13: =MAX(E13:G13) -> 95.33 | B13: =IFNA(HLOOKUP(A13,D9:G10,2,FALSE),"Branch #2") -> Jordan | E13: =IFNA(HLOOKUP(E12,D8:G9,2,FALSE),) -> 95.33 | F13: =IFNA(HLOOKUP(F12,D8:G9,2,FALSE),) | G13: =IFNA(HLOOKUP(G12,D8:G9,2,FALSE),) | M13: =MAX(Q13:S13) -> 98 | N13: =IFNA(HLOOKUP(M13,P9:S10,2,FALSE),"Campbell #2") -> University A | Q13: =IFNA(HLOOKUP(Q12,P8:S9,2,FALSE),) -> 98 | R13: =IFNA(HLOOKUP(R12,P8:S9,2,FALSE),) | S13: =IFNA(HLOOKUP(S12,P8:S9,2,FALSE),)
A14: PPG | B14: =IF(B15<>"Branch #1",HLOOKUP(B15,D8:G9,2,FALSE),) -> 146 | C14: PPG | D14: =IF(D15<>"Branch #2",HLOOKUP(D15,D8:G9,2,FALSE),) -> 95.33 | E14: =E12 -> Jordan | F14: =F12 | G14: =G12 | M14: PPG | N14: =IF(N15<>"Campbell #1",HLOOKUP(N15,P8:S9,2,FALSE),) -> 152 | O14: PPG | P14: =IF(P15<>"Campbell #2",HLOOKUP(P15,P8:S9,2,FALSE),) -> 98 | Q14: =Q12 -> University A | R14: =R12 | S14: =S12
A15: 1st Place: | B15: =B10 -> Canyon Crest Academy | C15: 2nd Place: | D15: =B13 -> Jordan | E15: 3rd Place: | F15: =IF(D15="Cayuga #2","Cayuga #3",H5) -> Dulles | M15: 1st Place: | N15: =N10 -> North Hollywood | O15: 2nd Place: | P15: =N13 -> University A | Q15: 3rd Place: | R15: =IF(P15="Seneca #2","Seneca #3",T5) -> St. Mark's
F16: =HLOOKUP(F15,D8:G9,2,FALSE) -> 52.67 | R16: =HLOOKUP(R15,P8:S9,2,FALSE) -> 42.67
A18: Group C | D18: ='Round Robin'!B29 -> American A | E18: ='Round Robin'!B30 -> East Brunswick A | F18: ='Round Robin'!B31 -> WWPN | G18: ='Round Robin'!B32 -> University B | H18: =LARGE(D22:G22,3) -> 2 | I18: =IFS(AND(H18=D22,D18<>B27,D18<>B30),D18,AND(H18=E22,E18<>B27,E18<>B30),E18,AND(H18=F22,F18<>B27,F18<>B30),F18,AND(H18=G22,G18<>B27,G18<>B30),G18) -> American A | M18: Group D | P18: ='Round Robin'!J29 -> Cupertino | Q18: ='Round Robin'!J30 -> Enloe | R18: ='Round Robin'!J31 -> Iolani | S18: ='Round Robin'!J32 -> TJHSST B | T18: =LARGE(P22:S22,3) -> 2 | U18: =IFS(AND(T18=P22,P18<>N27,P18<>N30),P18,AND(T18=Q22,Q18<>N27,Q18<>N30),Q18,AND(T18=R22,R18<>N27,R18<>N30),R18,AND(T18=S22,S18<>N27,S18<>N30),S18) -> Enloe
A19: ='Round Robin'!D29 -> -2 | B19: ='Round Robin'!C30 -> 62 | C19: 1v2 | D19: =IF(ISBLANK(A19),,IFS(A19>B19,2,A19=B19,1,A19<B19,0)) -> 0 | E19: =IF(ISBLANK(A19),,IFS(A19>B19,0,A19=B19,1,A19<B19,2)) -> 2 | F19: =IF(ISBLANK(A20),,IFS(A20>B20,0,A20=B20,1,A20<B20,2)) -> 2 | G19: =IF(ISBLANK(A21),,IFS(A21>B21,0,A21=B21,1,A21<B21,2)) -> 0 | H19: =LARGE(D22:G22,4) -> 2 | I19: =IF(H19=H18,IFS(AND(H19=D22,D18<>B27,D18<>B30,D18<>I18),D18,AND(H19=E22,E18<>B27,E18<>B30,E18<>I18),E18,AND(H19=F22,F18<>B27,F18<>B30,F18<>I18),F18,AND(H19=G22,G18<>B27,G18<>B30,G18<>I18),G18),) -> East Brunswick A | M19: ='Round Robin'!L29 -> 20 | N19: ='Round Robin'!K30 -> 40 | O19: 1v2 | P19: =IF(ISBLANK(M19),,IFS(M19>N19,2,M19=N19,1,M19<N19,0)) -> 0 | Q19: =IF(ISBLANK(M19),,IFS(M19>N19,0,M19=N19,1,M19<N19,2)) -> 2 | R19: =IF(ISBLANK(M20),,IFS(M20>N20,0,M20=N20,1,M20<N20,2)) -> 2 | S19: =IF(ISBLANK(M21),,IFS(M21>N21,0,M21=N21,1,M21<N21,2)) -> 2 | T19: =LARGE(P22:S22,4) -> 0 | U19: =IF(T19=T18,IFS(AND(T19=P22,P18<>N27,P18<>N30,P18<>U18),P18,AND(T19=Q22,Q18<>N27,Q18<>N30,Q18<>U18),Q18,AND(T19=R22,R18<>N27,R18<>N30,R18<>U18),R18,AND(T19=S22,S18<>N27,S18<>N30,S18<>U18),S18),)
A20: ='Round Robin'!E29 -> 36 | B20: ='Round Robin'!C31 -> 166 | C20: 1v3 | D20: =IF(ISBLANK(A20),,IFS(A20>B20,2,A20=B20,1,A20<B20,0)) -> 0 | E20: =IF(ISBLANK(A22),,IFS(A22>B22,2,A22=B22,1,A22<B22,0)) -> 0 | F20: =IF(ISBLANK(A22),,IFS(A22>B22,0,A22=B22,1,A22<B22,2)) -> 2 | G20: =IF(ISBLANK(A23),,IFS(A23>B23,0,A23=B23,1,A23<B23,2)) -> 2 | H20: =IF(H19=H18,HLOOKUP(I18,D25:G26,2,FALSE)) -> 25.33 | I20: =I18 -> American A | M20: ='Round Robin'!M29 -> 4 | N20: ='Round Robin'!K31 -> 128 | O20: 1v3 | P20: =IF(ISBLANK(M20),,IFS(M20>N20,2,M20=N20,1,M20<N20,0)) -> 0 | Q20: =IF(ISBLANK(M22),,IFS(M22>N22,2,M22=N22,1,M22<N22,0)) -> 0 | R20: =IF(ISBLANK(M22),,IFS(M22>N22,0,M22=N22,1,M22<N22,2)) -> 2 | S20: =IF(ISBLANK(M23),,IFS(M23>N23,0,M23=N23,1,M23<N23,2)) -> 2 | T20: =IF(T19=T18,HLOOKUP(U18,P25:S26,2,FALSE)) -> FALSE | U20: =U18 -> Enloe
A21: ='Round Robin'!F29 -> 42 | B21: ='Round Robin'!C32 -> 30 | C21: 1v4 | D21: =IF(ISBLANK(A21),,IFS(A21>B21,2,A21=B21,1,A21<B21,0)) -> 2 | E21: =IF(ISBLANK(A23),,IFS(A23>B23,2,A23=B23,1,A23<B23,0)) -> 0 | F21: =IF(ISBLANK(A24),,IFS(A24>B24,2,A24=B24,1,A24<B24,0)) -> 2 | G21: =IF(ISBLANK(A24),,IFS(A24>B24,0,A24=B24,1,A24<B24,2)) -> 0 | H21: =IF(H19=H18,HLOOKUP(I19,D25:G26,2,FALSE)) -> 37.33 | I21: =I19 -> East Brunswick A | M21: ='Round Robin'!N29 -> 4 | N21: ='Round Robin'!K32 -> 68 | O21: 1v4 | P21: =IF(ISBLANK(M21),,IFS(M21>N21,2,M21=N21,1,M21<N21,0)) -> 0 | Q21: =IF(ISBLANK(M23),,IFS(M23>N23,2,M23=N23,1,M23<N23,0)) -> 0 | R21: =IF(ISBLANK(M24),,IFS(M24>N24,2,M24=N24,1,M24<N24,0)) -> 2 | S21: =IF(ISBLANK(M24),,IFS(M24>N24,0,M24=N24,1,M24<N24,2)) -> 0 | T21: =IF(T19=T18,HLOOKUP(U19,P25:S26,2,FALSE)) -> FALSE | U21: =U19
A22: ='Round Robin'!E30 -> 10 | B22: ='Round Robin'!D31 -> 108 | C22: 2v3 | D22: =SUM(D19:D21) -> 2 | E22: =SUM(E19:E21) -> 2 | F22: =SUM(F19:F21) -> 6 | G22: =SUM(G19:G21) -> 2 | H22: =IFS(H20=FALSE,I18,H20>H21,I20,H20<H21,I21,H20=H21,CONCATENATE("Tie", I20, I21)) -> East Brunswick A | I22: =IFS(H20>H21,H20,H21>H20,H21,H20=H21,H21) -> 37.33 | M22: ='Round Robin'!M30 -> 14 | N22: ='Round Robin'!L31 -> 154 | O22: 2v3 | P22: =SUM(P19:P21) -> 0 | Q22: =SUM(Q19:Q21) -> 2 | R22: =SUM(R19:R21) -> 6 | S22: =SUM(S19:S21) -> 4 | T22: =IFS(T20=FALSE,U18,T20>T21,U20,T20<T21,U21,T20=T21,CONCATENATE("Tie", U20, U21)) -> Enloe | U22: =IFS(T20>T21,T20,T21>T20,T21,T20=T21,T21) -> FALSE
A23: ='Round Robin'!F30 -> 40 | B23: ='Round Robin'!D32 -> 70 | C23: 2v4 | F23: =IF(OR(D22="",E22="",F22="",G22="",G21="",F21="",E21="",D21="",D20="",D19="",E20="",E19="",F20="",F19="",G20="",G19=""),"",IFNA(IFS(AND(D24=E22,E18<>E24),E18,AND(D24=F22,F18<>E24),F18,AND(D24=G22,G18<>E24),G18),"")) | G23: =IF(OR(D22="",E22="",F22="",G22="",G21="",F21="",E21="",D21="",D20="",D19="",E20="",E19="",F20="",F19="",G20="",G19=""),"",IFNA(IFS(AND(D24=F22,F18<>E24,F18<>F24),F18,AND(D24=G22,G18<>E24,G18<>F24),G18),"")) | M23: ='Round Robin'!N30 -> 8 | N23: ='Round Robin'!L32 -> 142 | O23: 2v4 | R23: =IF(OR(P22="",Q22="",R22="",S22="",S21="",R21="",Q21="",P21="",P20="",P19="",Q20="",Q19="",R20="",R19="",S20="",S19=""),"",IFNA(IFS(AND(P24=Q22,Q18<>Q24),Q18,AND(P24=R22,R18<>Q24),R18,AND(P24=S22,S18<>Q24),S18),"")) | S23: =IF(OR(P22="",Q22="",R22="",S22="",S21="",R21="",Q21="",P21="",P20="",P19="",Q20="",Q19="",R20="",R19="",S20="",S19=""),"",IFNA(IFS(AND(P24=R22,R18<>Q24,R18<>R24),R18,AND(P24=S22,S18<>Q24,S18<>R24),S18),""))
A24: ='Round Robin'!F31 -> 156 | B24: ='Round Robin'!E32 -> 18 | C24: 3v4 | D24: =MAX(D22:G22) -> 6 | E24: =IF(OR(D22="",E22="",F22="",G22="",G21="",F21="",E21="",D21="",D20="",D19="",E20="",E19="",F20="",F19="",G20="",G19=""),"",IFS(D24=D22,'Round Robin'!C26,D24=E22,'Round Robin'!D26,D24=F22,'Round Robin'!E26,D24=G22,'Round Robin'!F26)) -> WWPN | F24: =IF(F23<>E24,F23,"") | G24: =IF(AND(G23<>E24,G23<>F24),G23,"") | M24: ='Round Robin'!N31 -> 88 | N24: ='Round Robin'!M32 -> 64 | O24: 3v4 | P24: =MAX(P22:S22) -> 6 | Q24: =IF(OR(P22="",Q22="",R22="",S22="",S21="",R21="",Q21="",P21="",P20="",P19="",Q20="",Q19="",R20="",R19="",S20="",S19=""),"",IFS(P24=P22,'Round Robin'!K26,P24=Q22,'Round Robin'!L26,P24=R22,'Round Robin'!M26,P24=S22,'Round Robin'!N26)) -> Iolani | R24: =IF(R23<>Q24,R23,"") | S24: =IF(AND(S23<>Q24,S23<>R24),S23,"")
D25: =D18 -> American A | E25: =E18 -> East Brunswick A | F25: =F18 -> WWPN | G25: =G18 -> University B | P25: =P18 -> Cupertino | Q25: =Q18 -> Enloe | R25: =R18 -> Iolani | S25: =S18 -> TJHSST B
A26: =HLOOKUP(E24,D25:G26,2,FALSE) -> 143.33 | B26: =IFERROR(HLOOKUP(F24,D25:G26,2,FALSE),"") | C26: =IFERROR(HLOOKUP(G24,E25:L26,2,FALSE),"") | D26: ='Round Robin'!G29 -> 25.33 | E26: ='Round Robin'!G30 -> 37.33 | F26: ='Round Robin'!G31 -> 143.33 | G26: ='Round Robin'!G32 -> 39.33 | M26: =HLOOKUP(Q24,P25:S26,2,FALSE) -> 123.33 | N26: =IFERROR(HLOOKUP(R24,P25:S26,2,FALSE),"") | O26: =IFERROR(HLOOKUP(S24,Q25:T26,2,FALSE),"") | P26: ='Round Robin'!O29 -> 9.33 | Q26: ='Round Robin'!O30 -> 20.67 | R26: ='Round Robin'!O31 -> 123.33 | S26: ='Round Robin'!O32 -> 91.33
A27: =MAX(A26:C26) -> 143.33 | B27: =IFNA(HLOOKUP(A27,D26:G27,2,FALSE),"Goff #1") -> WWPN | D27: =D18 -> American A | E27: =E18 -> East Brunswick A | F27: =F18 -> WWPN | G27: =G18 -> University B | M27: =MAX(M26:O26) -> 123.33 | N27: =IFNA(HLOOKUP(M27,P26:S27,2,FALSE),"Hutchinson #1") -> Iolani | P27: =P18 -> Cupertino | Q27: =Q18 -> Enloe | R27: =R18 -> Iolani | S27: =S18 -> TJHSST B
F28: =IF(OR(D19="",E19="",F19="",G19="",G20="",F20="",E20="",D20="",D21="",D22="",E21="",E22="",F21="",F22="",G21="",G22=""),"",IFNA(IFS(AND(D29=E22,E18<>E29),E18,AND(D29=F22,F18<>E29),F18,AND(D29=G22,G18<>E29),G18),"")) -> East Brunswick A | G28: =IF(OR(D19="",E19="",F19="",G19="",G20="",F20="",E20="",D20="",D21="",D22="",E21="",E22="",F21="",F22="",G21="",G22=""),"",IFNA(IFS(AND(D29=E22,E18<>E29,E18<>F29),E18,AND(D29=F22,F18<>E29,F18<>F29),F18,AND(D29=G22,G18<>E29,G18<>F29),G18),"")) -> University B | R28: =IF(OR(P19="",Q19="",R19="",S19="",S20="",R20="",Q20="",P20="",P21="",P22="",Q21="",Q22="",R21="",R22="",S21="",S22=""),"",IFNA(IFS(AND(P29=Q22,Q18<>Q29),Q18,AND(P29=R22,R18<>Q29),R18,AND(P29=S22,S18<>Q29),S18),"")) | S28: =IF(OR(P19="",Q19="",R19="",S19="",S20="",R20="",Q20="",P20="",P21="",P22="",Q21="",Q22="",R21="",R22="",S21="",S22=""),"",IFNA(IFS(AND(P29=Q22,Q18<>Q29,Q18<>R29),Q18,AND(P29=R22,R18<>Q29,R18<>R29),R18,AND(P29=S22,S18<>Q29,S18<>R29),S18),""))
D29: =LARGE(D22:G22,2) -> 2 | E29: =IF(OR(D22="",E22="",F22="",G22="",G21="",F21="",E21="",D21="",D20="",D19="",E20="",E19="",F20="",F19="",G20="",G19=""),"",IFS(AND(D29=D22,D18<>B27),D18,AND(D29=E22,E18<>B27),E18,AND(D29=F22,F18<>B27),F18,AND(D29=G22,G18<>B27),G18)) -> American A | F29: =IF(AND(F28<>E29,F28<>B27),F28,"") -> East Brunswick A | G29: =IF(AND(G28<>E29,G28<>F29,G28<>B27),G28,"") -> University B | P29: =LARGE(P22:S22,2) -> 4 | Q29: =IF(OR(P22="",Q22="",R22="",S22="",S21="",R21="",Q21="",P21="",P20="",P19="",Q20="",Q19="",R20="",R19="",S20="",S19=""),"",IFS(AND(P29=P22,P18<>N27),P18,AND(P29=Q22,Q18<>N27),Q18,AND(P29=R22,R18<>N27),R18,AND(P29=S22,S18<>N27),S18)) -> TJHSST B | R29: =IF(AND(R28<>Q29,R28<>N27),R28,"") | S29: =IF(AND(S28<>Q29,S28<>R29,S28<>N27),S28,"")
A30: =MAX(E30:G30) -> 39.33 | B30: =IFNA(HLOOKUP(A30,D30:G31,2,FALSE),"Goff #2") -> University B | E30: =IFNA(HLOOKUP(E29,D25:G26,2,FALSE),) -> 25.33 | F30: =IFNA(HLOOKUP(F29,D25:G26,2,FALSE),) -> 37.33 | G30: =IFNA(HLOOKUP(G29,D25:G26,2,FALSE),) -> 39.33 | M30: =MAX(Q30:S30) -> 91.33 | N30: =IFNA(HLOOKUP(M30,P30:S31,2,FALSE),"Hutchinson #2") -> TJHSST B | Q30: =IFNA(HLOOKUP(Q29,P25:S26,2,FALSE),) -> 91.33 | R30: =IFNA(HLOOKUP(R29,P25:S26,2,FALSE),) | S30: =IFNA(HLOOKUP(S29,P25:S26,2,FALSE),)
A31: PPG | B31: =IF(B32<>"Goff #1",HLOOKUP(B32,D25:G26,2,FALSE),) -> 143.33 | C31: PPG | D31: =IF(D32<>"Goff #2",HLOOKUP(D32,D25:G26,2,FALSE),) -> 39.33 | E31: =E29 -> American A | F31: =F29 -> East Brunswick A | G31: =G29 -> University B | M31: PPG | N31: =IF(N32<>"Hutchinson #1",HLOOKUP(N32,P25:S26,2,FALSE),) -> 123.33 | O31: PPG | P31: =IF(P32<>"Hutchinson #2",HLOOKUP(P32,P25:S26,2,FALSE),) -> 91.33 | Q31: =Q29 -> TJHSST B | R31: =R29 | S31: =S29
A32: 1st Place: | B32: =B27 -> WWPN | C32: 2nd Place: | D32: =B30 -> University B | E32: 3rd Place: | F32: =IF(D32="Onondaga #2","Onondaga #3",H22) -> East Brunswick A | M32: 1st Place: | N32: =N27 -> Iolani | O32: 2nd Place: | P32: =N30 -> TJHSST B | Q32: 3rd Place: | R32: =IF(P32="Oneida #2","Oneida #3",T22) -> Enloe
F33: =HLOOKUP(F32,D25:G26,2,FALSE) -> 37.33 | R33: =HLOOKUP(R32,P25:S26,2,FALSE) -> 20.67
A35: Group E | D35: ='Round Robin'!B40 -> Amador Valley B | E35: ='Round Robin'!B41 -> Clovis North | F35: ='Round Robin'!B42 -> Green Hope | G35: ='Round Robin'!B43 -> Montgomery Blair A | H35: =LARGE(D39:G39,3) -> 2 | I35: =IFS(AND(H35=D39,D35<>B44,D35<>B47),D35,AND(H35=E39,E35<>B44,E35<>B47),E35,AND(H35=F39,F35<>B44,F35<>B47),F35,AND(H35=G39,G35<>B44,G35<>B47),G35) -> Montgomery Blair A | M35: Group F | P35: ='Round Robin'!J40 -> American B | Q35: ='Round Robin'!J41 -> BASIS McLean | R35: ='Round Robin'!J42 -> Interlake A | S35: ='Round Robin'!J43 -> Amador Valley A | T35: =LARGE(P39:S39,3) -> 2 | U35: =IFS(AND(T35=P39,P35<>N44,P35<>N47),P35,AND(T35=Q39,Q35<>N44,Q35<>N47),Q35,AND(T35=R39,R35<>N44,R35<>N47),R35,AND(T35=S39,S35<>N44,S35<>N47),S35) -> BASIS McLean
A36: ='Round Robin'!D40 -> 44 | B36: ='Round Robin'!C41 -> 88 | C36: 1v2 | D36: =IF(ISBLANK(A36),,IFS(A36>B36,2,A36=B36,1,A36<B36,0)) -> 0 | E36: =IF(ISBLANK(A36),,IFS(A36>B36,0,A36=B36,1,A36<B36,2)) -> 2 | F36: =IF(ISBLANK(A37),,IFS(A37>B37,0,A37=B37,1,A37<B37,2)) -> 2 | G36: =IF(ISBLANK(A38),,IFS(A38>B38,0,A38=B38,1,A38<B38,2)) -> 2 | H36: =LARGE(D39:G39,4) -> 0 | I36: =IF(H36=H35,IFS(AND(H36=D39,D35<>B44,D35<>B47,D35<>I35),D35,AND(H36=E39,E35<>B44,E35<>B47,E35<>I35),E35,AND(H36=F39,F35<>B44,F35<>B47,F35<>I35),F35,AND(H36=G39,G35<>B44,G35<>B47,G35<>I35),G35),) | M36: ='Round Robin'!L40 -> 32 | N36: ='Round Robin'!K41 -> 36 | O36: 1v2 | P36: =IF(ISBLANK(M36),,IFS(M36>N36,2,M36=N36,1,M36<N36,0)) -> 0 | Q36: =IF(ISBLANK(M36),,IFS(M36>N36,0,M36=N36,1,M36<N36,2)) -> 2 | R36: =IF(ISBLANK(M37),,IFS(M37>N37,0,M37=N37,1,M37<N37,2)) -> 2 | S36: =IF(ISBLANK(M38),,IFS(M38>N38,0,M38=N38,1,M38<N38,2)) -> 2 | T36: =LARGE(P39:S39,4) -> 0 | U36: =IF(T36=T35,IFS(AND(T36=P39,P35<>N44,P35<>N47,P35<>U35),P35,AND(T36=Q39,Q35<>N44,Q35<>N47,Q35<>U35),Q35,AND(T36=R39,R35<>N44,R35<>N47,R35<>U35),R35,AND(T36=S39,S35<>N44,S35<>N47,S35<>U35),S35),)
A37: ='Round Robin'!E40 -> 16 | B37: ='Round Robin'!C42 -> 138 | C37: 1v3 | D37: =IF(ISBLANK(A37),,IFS(A37>B37,2,A37=B37,1,A37<B37,0)) -> 0 | E37: =IF(ISBLANK(A39),,IFS(A39>B39,2,A39=B39,1,A39<B39,0)) -> 2 | F37: =IF(ISBLANK(A39),,IFS(A39>B39,0,A39=B39,1,A39<B39,2)) -> 0 | G37: =IF(ISBLANK(A40),,IFS(A40>B40,0,A40=B40,1,A40<B40,2)) -> 0 | H37: =IF(H36=H35,HLOOKUP(I35,D42:G43,2,FALSE)) -> FALSE | I37: =I35 -> Montgomery Blair A | M37: ='Round Robin'!M40 -> 0 | N37: ='Round Robin'!K42 -> 138 | O37: 1v3 | P37: =IF(ISBLANK(M37),,IFS(M37>N37,2,M37=N37,1,M37<N37,0)) -> 0 | Q37: =IF(ISBLANK(M39),,IFS(M39>N39,2,M39=N39,1,M39<N39,0)) -> 0 | R37: =IF(ISBLANK(M39),,IFS(M39>N39,0,M39=N39,1,M39<N39,2)) -> 2 | S37: =IF(ISBLANK(M40),,IFS(M40>N40,0,M40=N40,1,M40<N40,2)) -> 2 | T37: =IF(T36=T35,HLOOKUP(U35,P42:S43,2,FALSE)) -> FALSE | U37: =U35 -> BASIS McLean
A38: ='Round Robin'!F40 -> 22 | B38: ='Round Robin'!C43 -> 56 | C38: 1v4 | D38: =IF(ISBLANK(A38),,IFS(A38>B38,2,A38=B38,1,A38<B38,0)) -> 0 | E38: =IF(ISBLANK(A40),,IFS(A40>B40,2,A40=B40,1,A40<B40,0)) -> 2 | F38: =IF(ISBLANK(A41),,IFS(A41>B41,2,A41=B41,1,A41<B41,0)) -> 2 | G38: =IF(ISBLANK(A41),,IFS(A41>B41,0,A41=B41,1,A41<B41,2)) -> 0 | H38: =IF(H36=H35,HLOOKUP(I36,D42:G43,2,FALSE)) -> FALSE | I38: =I36 | M38: ='Round Robin'!N40 -> 4 | N38: ='Round Robin'!K43 -> 96 | O38: 1v4 | P38: =IF(ISBLANK(M38),,IFS(M38>N38,2,M38=N38,1,M38<N38,0)) -> 0 | Q38: =IF(ISBLANK(M40),,IFS(M40>N40,2,M40=N40,1,M40<N40,0)) -> 0 | R38: =IF(ISBLANK(M41),,IFS(M41>N41,2,M41=N41,1,M41<N41,0)) -> 0 | S38: =IF(ISBLANK(M41),,IFS(M41>N41,0,M41=N41,1,M41<N41,2)) -> 2 | T38: =IF(T36=T35,HLOOKUP(U36,P42:S43,2,FALSE)) -> FALSE | U38: =U36
A39: ='Round Robin'!E41 -> 82 | B39: ='Round Robin'!D42 -> 58 | C39: 2v3 | D39: =SUM(D36:D38) -> 0 | E39: =SUM(E36:E38) -> 6 | F39: =SUM(F36:F38) -> 4 | G39: =SUM(G36:G38) -> 2 | H39: =IFS(H37=FALSE,I35,H37>H38,I37,H37<H38,I38,H37=H38,CONCATENATE("Tie", I37, I38)) -> Montgomery Blair A | I39: =IFS(H37>H38,H37,H38>H37,H38,H37=H38,H38) -> FALSE | M39: ='Round Robin'!M41 -> 60 | N39: ='Round Robin'!L42 -> 102 | O39: 2v3 | P39: =SUM(P36:P38) -> 0 | Q39: =SUM(Q36:Q38) -> 2 | R39: =SUM(R36:R38) -> 4 | S39: =SUM(S36:S38) -> 6 | T39: =IFS(T37=FALSE,U35,T37>T38,U37,T37<T38,U38,T37=T38,CONCATENATE("Tie", U37, U38)) -> BASIS McLean | U39: =IFS(T37>T38,T37,T38>T37,T38,T37=T38,T38) -> FALSE
A40: ='Round Robin'!F41 -> 92 | B40: ='Round Robin'!D43 -> 68 | C40: 2v4 | F40: =IF(OR(D39="",E39="",F39="",G39="",G38="",F38="",E38="",D38="",D37="",D36="",E37="",E36="",F37="",F36="",G37="",G36=""),"",IFNA(IFS(AND(D41=E39,E35<>E41),E35,AND(D41=F39,F35<>E41),F35,AND(D41=G39,G35<>E41),G35),"")) | G40: =IF(OR(D39="",E39="",F39="",G39="",G38="",F38="",E38="",D38="",D37="",D36="",E37="",E36="",F37="",F36="",G37="",G36=""),"",IFNA(IFS(AND(D41=F39,F35<>E41,F35<>F41),F35,AND(D41=G39,G35<>E41,G35<>F41),G35),"")) | M40: ='Round Robin'!N41 -> 26 | N40: ='Round Robin'!L43 -> 132 | O40: 2v4 | R40: =IF(OR(P39="",Q39="",R39="",S39="",S38="",R38="",Q38="",P38="",P37="",P36="",Q37="",Q36="",R37="",R36="",S37="",S36=""),"",IFNA(IFS(AND(P41=Q39,Q35<>Q41),Q35,AND(P41=R39,R35<>Q41),R35,AND(P41=S39,S35<>Q41),S35),"")) | S40: =IF(OR(P39="",Q39="",R39="",S39="",S38="",R38="",Q38="",P38="",P37="",P36="",Q37="",Q36="",R37="",R36="",S37="",S36=""),"",IFNA(IFS(AND(P41=R39,R35<>Q41,R35<>R41),R35,AND(P41=S39,S35<>Q41,S35<>R41),S35),""))
A41: ='Round Robin'!F42 -> 120 | B41: ='Round Robin'!E43 -> 18 | C41: 3v4 | D41: =MAX(D39:G39) -> 6 | E41: =IF(OR(D39="",E39="",F39="",G39="",G38="",F38="",E38="",D38="",D37="",D36="",E37="",E36="",F37="",F36="",G37="",G36=""),"",IFS(D41=D39,'Round Robin'!C37,D41=E39,'Round Robin'!D37,D41=F39,'Round Robin'!E37,D41=G39,'Round Robin'!F37)) -> Clovis North | F41: =IF(F40<>E41,F40,"") | G41: =IF(AND(G40<>E41,G40<>F41),G40,"") | M41: ='Round Robin'!N42 -> 74 | N41: ='Round Robin'!M43 -> 78 | O41: 3v4 | P41: =MAX(P39:S39) -> 6 | Q41: =IF(OR(P39="",Q39="",R39="",S39="",S38="",R38="",Q38="",P38="",P37="",P36="",Q37="",Q36="",R37="",R36="",S37="",S36=""),"",IFS(P41=P39,'Round Robin'!K37,P41=Q39,'Round Robin'!L37,P41=R39,'Round Robin'!M37,P41=S39,'Round Robin'!N37)) -> Amador Valley A | R41: =IF(R40<>Q41,R40,"") | S41: =IF(AND(S40<>Q41,S40<>R41),S40,"")
D42: =D35 -> Amador Valley B | E42: =E35 -> Clovis North | F42: =F35 -> Green Hope | G42: =G35 -> Montgomery Blair A | P42: =P35 -> American B | Q42: =Q35 -> BASIS McLean | R42: =R35 -> Interlake A | S42: =S35 -> Amador Valley A
...

Sheet Sheet6
C5: Branch | E5: Campbell | G5: Goff | I5: Hutchinson
C6: Brooklyn Tech A | E6: Amador Valley A | G6: American A | I6: Cupertino
C7: Canyon Crest Academy | E7: North Hollywood | G7: East Brunswick A | I7: Enloe
C8: Dulles | E8: St. Mark's | G8: WWPN | I8: Iolani
C9: Jordan | E9: University A | G9: University B | I9: TJHSST B
C12: Jacobs | E12: LaPorta | G12: Reynolds | I12: St. Brown
C13: Amador Valley B | E13: American B | G13: Buchholz A | I13: Lynbrook A
C14: Clovis North | E14: BASIS McLean | G14: Clements | I14: McLean A
C15: Green Hope | E15: Interlake A | G15: Foothill B | I15: Stuyvesant
C16: Montgomery Blair A | E16: Poolesville | G16: TJHSST A | I16: Foothill A

Sheet Schedule
C1: HST | D1: PDT | E1: MDT | F1: CDT | G1: EDT
A2: Opening Ceremony | C2: 0.19444444 | D2: 0.31944444 | E2: 0.36111111 | F2: 0.40277778 | G2: 0.44444444
A3: Round Robin 1 | C3: 0.20833333 | D3: 0.33333333 | E3: 0.375 | F3: 0.41666667 | G3: 0.45833333
A4: Round Robin 2 | C4: 0.25 | D4: 0.375 | E4: 0.41666667 | F4: 0.45833333 | G4: 0.5
A5: Round Robin 3 | C5: 0.29166667 | D5: 0.41666667 | E5: 0.45833333 | F5: 0.5 | G5: 0.54166667
A6: Round of 16 | C6: 0.33333333 | D6: 0.45833333 | E6: 0.5 | F6: 0.54166667 | G6: 0.58333333
A7: Quarterfinals | C7: 0.375 | D7: 0.5 | E7: 0.54166667 | F7: 0.58333333 | G7: 0.625
A8: Semifinals | C8: 0.41666667 | D8: 0.54166667 | E8: 0.58333333 | F8: 0.625 | G8: 0.66666667
A9: Finals | C9: 0.45833333 | D9: 0.58333333 | E9: 0.625 | F9: 0.66666667 | G9: 0.70833333
A10: Awards Ceremony | C10: 0.5 | D10: 0.625 | E10: 0.66666667 | F10: 0.70833333 | G10: 0.75

Sheet Testing Data
B1: Group A | J1: Group B
C4: Team 1 | D4: Team 2 | E4: Team 3 | F4: Team 4 | G4: PPG | H4: Points | I4: Functioning Group | K4: Team 5 | L4: Team 6 | M4: Team 7 | N4: Team 8 | O4: PPG | P4: Points | Q4: Test data 3-way tie 1st
B7: Team 1 | D7: 46 | E7: 96 | F7: 12 | G7: 96 | H7: 0 | J7: Team 5 | L7: 28 | M7: 17 | N7: 100 | O7: 102.67 | P7: 4
B8: Team 2 | C8: 162 | E8: 24 | F8: 64 | G8: 101.33 | H8: 4 | J8: Team 6 | K8: 153 | M8: 161 | N8: 104 | O8: 101.33 | P8: 4
B9: Team 3 | C9: 4 | D9: 96 | F9: 23 | G9: 100 | H9: 4 | J9: Team 7 | K9: 123 | L9: 143 | N9: 123 | O9: 97.33 | P9: 0
B10: Team 4 | C10: 4 | D10: 8 | E10: 8 | G10: 102.67 | H10: 4 | J10: Team 8 | K10: 164 | L10: 153 | M10: 125 | O10: 100 | P10: 4
B12: Group C | J12: Group D
C15: Team 9 | D15: Team 10 | E15: Team 11 | F15: Team 12 | G15: PPG | H15: Points | K15: Team 13 | L15: Team 14 | M15: Team 15 | N15: Team 16 | O15: PPG | P15: Points
B18: Team 9 | D18: 146 | E18: 101 | F18: 164 | G18: 100.67 | H18: 6 | I18: Test data no ties | J18: Team 13 | L18: 104 | M18: 199 | N18: 104 | O18: 104 | P18: 6 | Q18: Test data 3-way tie 2nd
B19: Team 10 | C19: 0 | E19: 132 | F19: 185 | G19: 78.33 | H19: 4 | J19: Team 14 | K19: 92 | M19: 97 | N19: 200 | O19: 98.67 | P19: 2
B20: Team 11 | C20: 0 | D20: 0 | F20: 15 | G20: 88 | H20: 0 | J20: Team 15 | K20: 88 | L20: 42 | N20: 104 | O20: 100 | P20: 2
B21: Team 12 | C21: 0 | D21: 0 | E21: 2 | G21: 61.67 | H21: 2 | J21: Team 16 | K21: 68 | L21: 104 | M21: 200 | O21: 101.33 | P21: 2
B23: Group E | J23: Group F
C26: Team 17 | D26: Team 18 | E26: Team 19 | F26: Team 20 | G26: PPG | H26: Points | K26: Team 21 | L26: Team 22 | M26: Team 23 | N26: Team 24 | O26: PPG | P26: Points
B29: Team 17 | D29: 0 | E29: 0 | F29: 0 | G29: 92 | H29: 0 | I29: Test data 3-way tie 1st transposed | J29: Team 21 | L29: 200 | M29: 92 | N29: 84 | O29: 90.67 | P29: 2 | Q29: Test data 3-way tie 2nd transposed
B30: Team 18 | C30: 87 | E30: 0 | F30: 0 | G30: 97.33 | H30: 4 | J30: Team 22 | K30: 28 | M30: 44 | N30: 200 | O30: 92 | P30: 2
B31: Team 19 | C31: 86 | D31: 84 | F31: 0 | G31: 96 | H31: 4 | J31: Team 23 | K31: 42 | L31: 48 | N31: 18 | O31: 93.33 | P31: 2
B32: Team 20 | C32: 85 | D32: 83 | E32: 81 | G32: 98.67 | H32: 4 | J32: Team 24 | K32: 78 | L32: 56 | M32: 91 | O32: 96 | P32: 6
