Workbook
Name Group2: 'RR Scoresheet'!$J$6:$O$11

Sheet Field
A1: Field
A2: Code | B2: Team
A3: A1 | B3: Plainsboro Knights
A4: A2 | B4: West Windsor-Plainsboro HS South B
A5: A3 | B5: The Wilberforce School A
A6: A4 | B6: BASIS Independent McLean
A7: A5 | B7: Thomas S Wootton High School A
A8: A6 | B8: Wheaton High School B
A9: B1 | B9: Centennial High School A
A10: B2 | B10: Alexandria City High School
A11: B3 | B11: Thomas Jefferson HS for Science and Technology B
A12: B4 | B12: Beltway Blazers B
A13: B5 | B13: West Windsor-Plainsboro HS South A
... A26: D6 | B26: Poolesville High School

Sheet RR Pairings and Schedule
A1: RR Pairings and Schedule
A3: RR Pairings | H3: Schedule (Times in EST)
H5: TIME | J5: ROUND
A6: Azure
A7: ROOM | B7: RR1 | C7: RR2 | D7: RR3 | E7: RR4 | F7: RR5 | H7: 7:30 - 8:30 a.m. EST | J7: Volunteer Check-In
A8: Hodson 203 | B8: A1 — A2 | C8: A4— A5 | D8: A2 — A3 | E8: A1 — A5 | F8: A3 — A4
A9: Hodson 210 | B9: A3 — A5 | C9: A1 — A3 | D9: A5 — A6 | E9: A2 — A4 | F9: A1 — A6 | H9: 8:00 - 8:30 a.m. EST | J9: Team Check-In (Hodson 110)
A10: Hodson 211 | B10: A4 — A6 | C10: A2 — A6 | D10: A1 — A4 | E10: A3 — A6 | F10: A2 — A5
H11: 8:30 - 8:50 a.m. EST | J11: OPENING CEREMONY (Hodson 110)
A12: Blueberry
A13: ROOM | B13: RR1 | C13: RR2 | D13: RR3 | E13: RR4 | F13: RR5 | H13: 8:50 - 9:25 a.m. EST | J13: Round Robin 1
A14: Hodson 213 | B14: B1 — B2 | C14: B4— B5 | D14: B2 — B3 | E14: B1 — B5 | F14: B3 — B4
A15: Hodson 216 | B15: B3 — B5 | C15: B1 — B3 | D15: B5 — B6 | E15: B2 — B4 | F15: B1 — B6 | H15: 9:25 - 10:00 a.m. EST | J15: Round Robin 2
A16: Hodson 301 | B16: B4 — B6 | C16: B2 — B6 | D16: B1 — B4 | E16: B3 — B6 | F16: B2 — B5
H17: 10:00 - 10:35 a.m. EST | J17: Round Robin 3
A18: Cerulean
A19: ROOM | B19: RR1 | C19: RR2 | D19: RR3 | E19: RR4 | F19: RR5 | H19: 10:35 - 11:10 a.m. EST | J19: Round Robin 4
A20: Hodson 303 | B20: C1 — C2 | C20: C4— C5 | D20: C2 — C3 | E20: C1 — C5 | F20: C3 — C4
A21: Hodson 305 | B21: C3 — C5 | C21: C1 — C3 | D21: C5 — C6 | E21: C2 — C4 | F21: C1 — C6 | H21: 11:10 - 11:45 a.m. EST | J21: Round Robin 5
A22: Hodson 313 | B22: C4 — C6 | C22: C2 — C6 | D22: C1 — C4 | E22: C3 — C6 | F22: C2 — C5
H23: 11:45 - 1:00 p.m. EST | J23: LUNCH BREAK
A24: Denim
A25: ROOM | B25: RR1 | C25: RR2 | D25: RR3 | E25: RR4 | F25: RR5 | H25: 1:00 - 1:15 p.m. EST | J25: SEEDING AND AWARDS CEREMONY (Hodson 110)
A26: Hodson 311 | B26: D1 — D2 | C26: D4— D5 | D26: D2 — D3 | E26: D1 — D5 | F26: D3 — D4
A27: Hodson 315 | B27: D3 — D5 | C27: D1 — D3 | D27: D5 — D6 | E27: D2 — D4 | F27: D1 — D6 | H27: 1:15 - 1:50 p.m. EST | J27: Double Elimination 1 (top 16)
A28: Hodson 316 | B28: D4 — D6 | C28: D2 — D6 | D28: D1 — D4 | E28: D3 — D6 | F28: D2 — D5
H29: 1:50 - 2:25 p.m. EST | J29: Double Elimination 2 (top 16)
H31: 2:25 - 3:00 p.m. EST | J31: Double Elimination 3 (top 12)
H33: 3:00 - 3:35 p.m. EST | J33: Double Elimination 4 (top 8)
H35: 3:35 - 4:10 p.m. EST | J35: Double Elimination 5 (top 6)
H37: 4:10 - 4:40 p.m. EST | J37: Double Elimination 6 (top 4)
H39: 4:40 - 4:50 p.m. EST | J39: BREAK (move to Hodson 110)
H41: 4:50 - 5:25 p.m. EST | J41: Double Elimination 7 (Hodson 110)
H43: 5:25 - 5:55 p.m. EST | J43: Finals 1 (Hodson 110)
H45: 5:55 - 6:25 p.m. EST | J45: Finals 2 (Hodson 110) if necessary
H47: 6:25 - 6:40 p.m. EST | J47: CLOSING CEREMONY

Sheet RR Scoresheet
A1: RR Scoresheet
A2: RR 1: 8:50-9:25 AM RR 2: 9:25-10:00 AM RR 3: 10:00-10:35 AM RR 4: 10:35-11:10 AM RR 5: 11:10-11:45 AM
A4: Azure | I4: Blueberry
A5: =SUM(B6:G11) -> 2332 | B5: A1 | C5: A2 | D5: A3 | E5: A4 | F5: A5 | G5: A6 | I5: =SUM(J6:O11) -> 2464 | J5: B1 | K5: B2 | L5: B3 | M5: B4 | N5: B5 | O5: B6
A6: A1 Plainsboro Knights | C6: =IFERROR(__xludf.DUMMYFUNCTION("IMPORTRANGE(""1bBaxRc1NB103ARWITryXCsb62HVgfI-_YtSE-b4hJuU"", ""RR1!E25"")"),114.0) -> 114 | D6: =IFERROR(__xludf.DUMMYFUNCTION("IMPORTRANGE(""1EGAJaL0bqJkoLm1uA6Zh54FOg1VvM2YJuc3PqgsQQ_w"", ""RR2!E25"")"),174.0) -> 174 | E6: =IFERROR(__xludf.DUMMYFUNCTION("IMPORTRANGE(""1hNeAYq0ortgqvT3OlfxsodTdhYQvY130xJoCf4DjT5k"", ""RR3!E25"")"),160.0) -> 160 | F6: =IFERROR(__xludf.DUMMYFUNCTION("IMPORTRANGE(""1bBaxRc1NB103ARWITryXCsb62HVgfI-_YtSE-b4hJuU"", ""RR4!E25"")"),138.0) -> 138 | G6: =IFERROR(__xludf.DUMMYFUNCTION("IMPORTRANGE(""1EGAJaL0bqJkoLm1uA6Zh54FOg1VvM2YJuc3PqgsQQ_w"", ""RR5!E25"")"),156.0) -> 156 | I6: B1 Centennial A | K6: =IFERROR(__xludf.DUMMYFUNCTION("IMPORTRANGE(""1XlpmV0Btj1xT6oKcR4ANLUEplHWyheIPCs_M9o3tO2Q"", ""RR1!E25"")"),112.0) -> 112 | L6: =IFERROR(__xludf.DUMMYFUNCTION("IMPORTRANGE(""14Q3kZeRy11-MpTZrCBXwgONgM1L7a0GMyhOOHHOV8Qs"", ""RR2!E25"")"),96.0) -> 96 | M6: =IFERROR(__xludf.DUMMYFUNCTION("IMPORTRANGE(""1aUUfGV4_4tbeXKyEln-X6-Wzg4x2MAF27ARbdiq_9Wc"", ""RR3!E25"")"),114.0) -> 114 | N6: =IFERROR(__xludf.DUMMYFUNCTION("IMPORTRANGE(""1XlpmV0Btj1xT6oKcR4ANLUEplHWyheIPCs_M9o3tO2Q"", ""RR4!E25"")"),106.0) -> 106 | O6: =IFERROR(__xludf.DUMMYFUNCTION("IMPORTRANGE(""14Q3kZeRy11-MpTZrCBXwgONgM1L7a0GMyhOOHHOV8Qs"", ""RR5!E25"")"),80.0) -> 80
A7: A2 WWPS B | B7: =IFERROR(__xludf.DUMMYFUNCTION("IMPORTRANGE(""1bBaxRc1NB103ARWITryXCsb62HVgfI-_YtSE-b4hJuU"", ""RR1!H25"")"),124.0) -> 124 | D7: =IFERROR(__xludf.DUMMYFUNCTION("IMPORTRANGE(""1bBaxRc1NB103ARWITryXCsb62HVgfI-_YtSE-b4hJuU"", ""RR3!E25"")"),136.0) -> 136 | E7: =IFERROR(__xludf.DUMMYFUNCTION("IMPORTRANGE(""1EGAJaL0bqJkoLm1uA6Zh54FOg1VvM2YJuc3PqgsQQ_w"", ""RR4!E25"")"),174.0) -> 174 | F7: =IFERROR(__xludf.DUMMYFUNCTION("IMPORTRANGE(""1hNeAYq0ortgqvT3OlfxsodTdhYQvY130xJoCf4DjT5k"", ""RR5!E25"")"),160.0) -> 160 | G7: =IFERROR(__xludf.DUMMYFUNCTION("IMPORTRANGE(""1hNeAYq0ortgqvT3OlfxsodTdhYQvY130xJoCf4DjT5k"", ""RR2!E25"")"),150.0) -> 150 | I7: B2 Alexandria City | J7: =IFERROR(__xludf.DUMMYFUNCTION("IMPORTRANGE(""1XlpmV0Btj1xT6oKcR4ANLUEplHWyheIPCs_M9o3tO2Q"", ""RR1!H25"")"),4.0) -> 4 | L7: =IFERROR(__xludf.DUMMYFUNCTION("IMPORTRANGE(""1XlpmV0Btj1xT6oKcR4ANLUEplHWyheIPCs_M9o3tO2Q"", ""RR3!E25"")"),38.0) -> 38 | M7: =IFERROR(__xludf.DUMMYFUNCTION("IMPORTRANGE(""14Q3kZeRy11-MpTZrCBXwgONgM1L7a0GMyhOOHHOV8Qs"", ""RR4!E25"")"),12.0) -> 12 | N7: =IFERROR(__xludf.DUMMYFUNCTION("IMPORTRANGE(""1aUUfGV4_4tbeXKyEln-X6-Wzg4x2MAF27ARbdiq_9Wc"", ""RR5!E25"")"),8.0) -> 8 | O7: =IFERROR(__xludf.DUMMYFUNCTION("IMPORTRANGE(""1aUUfGV4_4tbeXKyEln-X6-Wzg4x2MAF27ARbdiq_9Wc"", ""RR2!E25"")"),12.0) -> 12
A8: A3 Wilberforce A | B8: =IFERROR(__xludf.DUMMYFUNCTION("IMPORTRANGE(""1EGAJaL0bqJkoLm1uA6Zh54FOg1VvM2YJuc3PqgsQQ_w"", ""RR2!H25"")"),44.0) -> 44 | C8: =IFERROR(__xludf.DUMMYFUNCTION("IMPORTRANGE(""1bBaxRc1NB103ARWITryXCsb62HVgfI-_YtSE-b4hJuU"", ""RR3!H25"")"),44.0) -> 44 | E8: =IFERROR(__xludf.DUMMYFUNCTION("IMPORTRANGE(""1bBaxRc1NB103ARWITryXCsb62HVgfI-_YtSE-b4hJuU"", ""RR5!E25"")"),66.0) -> 66 | F8: =IFERROR(__xludf.DUMMYFUNCTION("IMPORTRANGE(""1EGAJaL0bqJkoLm1uA6Zh54FOg1VvM2YJuc3PqgsQQ_w"", ""RR1!E25"")"),90.0) -> 90 | G8: =IFERROR(__xludf.DUMMYFUNCTION("IMPORTRANGE(""1hNeAYq0ortgqvT3OlfxsodTdhYQvY130xJoCf4DjT5k"", ""RR4!E25"")"),80.0) -> 80 | I8: B3 TJHSST B | J8: =IFERROR(__xludf.DUMMYFUNCTION("IMPORTRANGE(""14Q3kZeRy11-MpTZrCBXwgONgM1L7a0GMyhOOHHOV8Qs"", ""RR2!H25"")"),90.0) -> 90 | K8: =IFERROR(__xludf.DUMMYFUNCTION("IMPORTRANGE(""1XlpmV0Btj1xT6oKcR4ANLUEplHWyheIPCs_M9o3tO2Q"", ""RR3!H25"")"),100.0) -> 100 | M8: =IFERROR(__xludf.DUMMYFUNCTION("IMPORTRANGE(""1XlpmV0Btj1xT6oKcR4ANLUEplHWyheIPCs_M9o3tO2Q"", ""RR5!E25"")"),82.0) -> 82 | N8: =IFERROR(__xludf.DUMMYFUNCTION("IMPORTRANGE(""14Q3kZeRy11-MpTZrCBXwgONgM1L7a0GMyhOOHHOV8Qs"", ""RR1!E25"")"),82.0) -> 82 | O8: =IFERROR(__xludf.DUMMYFUNCTION("IMPORTRANGE(""1aUUfGV4_4tbeXKyEln-X6-Wzg4x2MAF27ARbdiq_9Wc"", ""RR4!E25"")"),62.0) -> 62
A9: A4 BASIS McLean | B9: =IFERROR(__xludf.DUMMYFUNCTION("IMPORTRANGE(""1hNeAYq0ortgqvT3OlfxsodTdhYQvY130xJoCf4DjT5k"", ""RR3!H25"")"),12.0) -> 12 | C9: =IFERROR(__xludf.DUMMYFUNCTION("IMPORTRANGE(""1EGAJaL0bqJkoLm1uA6Zh54FOg1VvM2YJuc3PqgsQQ_w"", ""RR4!H25"")"),8.0) -> 8 | D9: =IFERROR(__xludf.DUMMYFUNCTION("IMPORTRANGE(""1bBaxRc1NB103ARWITryXCsb62HVgfI-_YtSE-b4hJuU"", ""RR5!H25"")"),26.0) -> 26 | F9: =IFERROR(__xludf.DUMMYFUNCTION("IMPORTRANGE(""1bBaxRc1NB103ARWITryXCsb62HVgfI-_YtSE-b4hJuU"", ""RR2!E25"")"),4.0) -> 4 | G9: =IFERROR(__xludf.DUMMYFUNCTION("IMPORTRANGE(""1hNeAYq0ortgqvT3OlfxsodTdhYQvY130xJoCf4DjT5k"", ""RR1!E25"")"),18.0) -> 18 | I9: B4 Beltway Blazers B | J9: =IFERROR(__xludf.DUMMYFUNCTION("IMPORTRANGE(""1aUUfGV4_4tbeXKyEln-X6-Wzg4x2MAF27ARbdiq_9Wc"", ""RR3!H25"")"),96.0) -> 96 | K9: =IFERROR(__xludf.DUMMYFUNCTION("IMPORTRANGE(""14Q3kZeRy11-MpTZrCBXwgONgM1L7a0GMyhOOHHOV8Qs"", ""RR4!H25"")"),94.0) -> 94 | L9: =IFERROR(__xludf.DUMMYFUNCTION("IMPORTRANGE(""1XlpmV0Btj1xT6oKcR4ANLUEplHWyheIPCs_M9o3tO2Q"", ""RR5!H25"")"),92.0) -> 92 | N9: =IFERROR(__xludf.DUMMYFUNCTION("IMPORTRANGE(""1XlpmV0Btj1xT6oKcR4ANLUEplHWyheIPCs_M9o3tO2Q"", ""RR2!E25"")"),110.0) -> 110 | O9: =IFERROR(__xludf.DUMMYFUNCTION("IMPORTRANGE(""1aUUfGV4_4tbeXKyEln-X6-Wzg4x2MAF27ARbdiq_9Wc"", ""RR1!E25"")"),96.0) -> 96
A10: A5 Thomas S Wootton A | B10: =IFERROR(__xludf.DUMMYFUNCTION("IMPORTRANGE(""1bBaxRc1NB103ARWITryXCsb62HVgfI-_YtSE-b4hJuU"", ""RR4!H25"")"),52.0) -> 52 | C10: =IFERROR(__xludf.DUMMYFUNCTION("IMPORTRANGE(""1hNeAYq0ortgqvT3OlfxsodTdhYQvY130xJoCf4DjT5k"", ""RR5!H25"")"),16.0) -> 16 | D10: =IFERROR(__xludf.DUMMYFUNCTION("IMPORTRANGE(""1EGAJaL0bqJkoLm1uA6Zh54FOg1VvM2YJuc3PqgsQQ_w"", ""RR1!H25"")"),26.0) -> 26 | E10: =IFERROR(__xludf.DUMMYFUNCTION("IMPORTRANGE(""1bBaxRc1NB103ARWITryXCsb62HVgfI-_YtSE-b4hJuU"", ""RR2!H25"")"),64.0) -> 64 | G10: =IFERROR(__xludf.DUMMYFUNCTION("IMPORTRANGE(""1EGAJaL0bqJkoLm1uA6Zh54FOg1VvM2YJuc3PqgsQQ_w"", ""RR3!E25"")"),66.0) -> 66 | I10: B5 WWPS A | J10: =IFERROR(__xludf.DUMMYFUNCTION("IMPORTRANGE(""1XlpmV0Btj1xT6oKcR4ANLUEplHWyheIPCs_M9o3tO2Q"", ""RR4!H25"")"),124.0) -> 124 | K10: =IFERROR(__xludf.DUMMYFUNCTION("IMPORTRANGE(""1aUUfGV4_4tbeXKyEln-X6-Wzg4x2MAF27ARbdiq_9Wc"", ""RR5!H25"")"),186.0) -> 186 | L10: =IFERROR(__xludf.DUMMYFUNCTION("IMPORTRANGE(""14Q3kZeRy11-MpTZrCBXwgONgM1L7a0GMyhOOHHOV8Qs"", ""RR1!H25"")"),134.0) -> 134 | M10: =IFERROR(__xludf.DUMMYFUNCTION("IMPORTRANGE(""1XlpmV0Btj1xT6oKcR4ANLUEplHWyheIPCs_M9o3tO2Q"", ""RR2!H25"")"),102.0) -> 102 | O10: =IFERROR(__xludf.DUMMYFUNCTION("IMPORTRANGE(""14Q3kZeRy11-MpTZrCBXwgONgM1L7a0GMyhOOHHOV8Qs"", ""RR3!E25"")"),152.0) -> 152
A11: A6 Wheaton B | B11: =IFERROR(__xludf.DUMMYFUNCTION("IMPORTRANGE(""1EGAJaL0bqJkoLm1uA6Zh54FOg1VvM2YJuc3PqgsQQ_w"", ""RR5!H25"")"),30.0) -> 30 | C11: =IFERROR(__xludf.DUMMYFUNCTION("IMPORTRANGE(""1hNeAYq0ortgqvT3OlfxsodTdhYQvY130xJoCf4DjT5k"", ""RR2!H25"")"),28.0) -> 28 | D11: =IFERROR(__xludf.DUMMYFUNCTION("IMPORTRANGE(""1hNeAYq0ortgqvT3OlfxsodTdhYQvY130xJoCf4DjT5k"", ""RR4!H25"")"),68.0) -> 68 | E11: =IFERROR(__xludf.DUMMYFUNCTION("IMPORTRANGE(""1hNeAYq0ortgqvT3OlfxsodTdhYQvY130xJoCf4DjT5k"", ""RR1!H25"")"),62.0) -> 62 | F11: =IFERROR(__xludf.DUMMYFUNCTION("IMPORTRANGE(""1EGAJaL0bqJkoLm1uA6Zh54FOg1VvM2YJuc3PqgsQQ_w"", ""RR3!H25"")"),42.0) -> 42 | I11: B6 Wheaton A | J11: =IFERROR(__xludf.DUMMYFUNCTION("IMPORTRANGE(""14Q3kZeRy11-MpTZrCBXwgONgM1L7a0GMyhOOHHOV8Qs"", ""RR5!H25"")"),58.0) -> 58 | K11: =IFERROR(__xludf.DUMMYFUNCTION("IMPORTRANGE(""1aUUfGV4_4tbeXKyEln-X6-Wzg4x2MAF27ARbdiq_9Wc"", ""RR2!H25"")"),56.0) -> 56 | L11: =IFERROR(__xludf.DUMMYFUNCTION("IMPORTRANGE(""1aUUfGV4_4tbeXKyEln-X6-Wzg4x2MAF27ARbdiq_9Wc"", ""RR4!H25"")"),86.0) -> 86 | M11: =IFERROR(__xludf.DUMMYFUNCTION("IMPORTRANGE(""1aUUfGV4_4tbeXKyEln-X6-Wzg4x2MAF27ARbdiq_9Wc"", ""RR1!H25"")"),42.0) -> 42 | N11: =IFERROR(__xludf.DUMMYFUNCTION("IMPORTRANGE(""14Q3kZeRy11-MpTZrCBXwgONgM1L7a0GMyhOOHHOV8Qs"", ""RR3!H25"")"),38.0) -> 38
A13: Cerulean | I13: Denim
A14: =SUM(B15:G20) -> 2270 | B14: C1 | C14: C2 | D14: C3 | E14: C4 | F14: C5 | G14: C6 | I14: =SUM(J15:O20) -> 2676 | J14: D1 | K14: D2 | L14: D3 | M14: D4 | N14: D5 | O14: D6
A15: C1 Deep Run | C15: =IFERROR(__xludf.DUMMYFUNCTION("IMPORTRANGE(""1qa62mdbdWiy5RjjYdhmu0eUEb2Zcp5cejYIFG7fnrWs"", ""RR1!E25"")"),68.0) -> 68 | D15: =IFERROR(__xludf.DUMMYFUNCTION("IMPORTRANGE(""1SCVX9W3N-siFlvX2krUw1KBMk-omHCkvy-4I4moTpWM"", ""RR2!E25"")"),88.0) -> 88 | E15: =IFERROR(__xludf.DUMMYFUNCTION("IMPORTRANGE(""1Lo-UEbdVL-D3TuF5gEj-3AWGU8LSSjTDDeH9OM07xLM"", ""RR3!E25"")"),28.0) -> 28 | F15: =IFERROR(__xludf.DUMMYFUNCTION("IMPORTRANGE(""1qa62mdbdWiy5RjjYdhmu0eUEb2Zcp5cejYIFG7fnrWs"", ""RR4!E25"")"),122.0) -> 122 | G15: =IFERROR(__xludf.DUMMYFUNCTION("IMPORTRANGE(""1SCVX9W3N-siFlvX2krUw1KBMk-omHCkvy-4I4moTpWM"", ""RR5!E25"")"),48.0) -> 48 | I15: D1 Centennial B | K15: =IFERROR(__xludf.DUMMYFUNCTION("IMPORTRANGE(""1Ak43y8GCpe0VeJyOSmu5frUAg6HEnwknENOp_P2vusc"", ""RR1!E25"")"),8.0) -> 8 | L15: =IFERROR(__xludf.DUMMYFUNCTION("IMPORTRANGE(""1QZzUr_MV6N6HMhICv9mBCuii7MD3z6uCvZMLFZibU6Q"", ""RR2!E25"")"),44.0) -> 44 | M15: =IFERROR(__xludf.DUMMYFUNCTION("IMPORTRANGE(""1EzV00Mnju8SkO4Z2XZFfkboXLUXdjoqVyO6dO-P0bsc"", ""RR3!E25"")"),54.0) -> 54 | N15: =IFERROR(__xludf.DUMMYFUNCTION("IMPORTRANGE(""1Ak43y8GCpe0VeJyOSmu5frUAg6HEnwknENOp_P2vusc"", ""RR4!E25"")"),26.0) -> 26 | O15: =IFERROR(__xludf.DUMMYFUNCTION("IMPORTRANGE(""1QZzUr_MV6N6HMhICv9mBCuii7MD3z6uCvZMLFZibU6Q"", ""RR5!E25"")"),18.0) -> 18
A16: C2 Richard Montgomery | B16: =IFERROR(__xludf.DUMMYFUNCTION("IMPORTRANGE(""1qa62mdbdWiy5RjjYdhmu0eUEb2Zcp5cejYIFG7fnrWs"", ""RR1!H25"")"),124.0) -> 124 | D16: =IFERROR(__xludf.DUMMYFUNCTION("IMPORTRANGE(""1qa62mdbdWiy5RjjYdhmu0eUEb2Zcp5cejYIFG7fnrWs"", ""RR3!E25"")"),118.0) -> 118 | E16: =IFERROR(__xludf.DUMMYFUNCTION("IMPORTRANGE(""1SCVX9W3N-siFlvX2krUw1KBMk-omHCkvy-4I4moTpWM"", ""RR4!E25"")"),170.0) -> 170 | F16: =IFERROR(__xludf.DUMMYFUNCTION("IMPORTRANGE(""1Lo-UEbdVL-D3TuF5gEj-3AWGU8LSSjTDDeH9OM07xLM"", ""RR5!E25"")"),152.0) -> 152 | G16: =IFERROR(__xludf.DUMMYFUNCTION("IMPORTRANGE(""1Lo-UEbdVL-D3TuF5gEj-3AWGU8LSSjTDDeH9OM07xLM"", ""RR2!E25"")"),96.0) -> 96 | I16: D2 Beltway Blazers A | J16: =IFERROR(__xludf.DUMMYFUNCTION("IMPORTRANGE(""1Ak43y8GCpe0VeJyOSmu5frUAg6HEnwknENOp_P2vusc"", ""RR1!H25"")"),254.0) -> 254 | L16: =IFERROR(__xludf.DUMMYFUNCTION("IMPORTRANGE(""1Ak43y8GCpe0VeJyOSmu5frUAg6HEnwknENOp_P2vusc"", ""RR3!E25"")"),224.0) -> 224 | M16: =IFERROR(__xludf.DUMMYFUNCTION("IMPORTRANGE(""1QZzUr_MV6N6HMhICv9mBCuii7MD3z6uCvZMLFZibU6Q"", ""RR4!E25"")"),250.0) -> 250 | N16: =IFERROR(__xludf.DUMMYFUNCTION("IMPORTRANGE(""1EzV00Mnju8SkO4Z2XZFfkboXLUXdjoqVyO6dO-P0bsc"", ""RR5!E25"")"),222.0) -> 222 | O16: =IFERROR(__xludf.DUMMYFUNCTION("IMPORTRANGE(""1EzV00Mnju8SkO4Z2XZFfkboXLUXdjoqVyO6dO-P0bsc"", ""RR2!E25"")"),224.0) -> 224
A17: C3 John R. Lewis | B17: =IFERROR(__xludf.DUMMYFUNCTION("IMPORTRANGE(""1SCVX9W3N-siFlvX2krUw1KBMk-omHCkvy-4I4moTpWM"", ""RR2!H25"")"),24.0) -> 24 | C17: =IFERROR(__xludf.DUMMYFUNCTION("IMPORTRANGE(""1qa62mdbdWiy5RjjYdhmu0eUEb2Zcp5cejYIFG7fnrWs"", ""RR3!H25"")"),24.0) -> 24 | E17: =IFERROR(__xludf.DUMMYFUNCTION("IMPORTRANGE(""1qa62mdbdWiy5RjjYdhmu0eUEb2Zcp5cejYIFG7fnrWs"", ""RR5!E25"")"),20.0) -> 20 | F17: =IFERROR(__xludf.DUMMYFUNCTION("IMPORTRANGE(""1SCVX9W3N-siFlvX2krUw1KBMk-omHCkvy-4I4moTpWM"", ""RR1!E25"")"),24.0) -> 24 | G17: =IFERROR(__xludf.DUMMYFUNCTION("IMPORTRANGE(""1Lo-UEbdVL-D3TuF5gEj-3AWGU8LSSjTDDeH9OM07xLM"", ""RR4!E25"")"),46.0) -> 46 | I17: D3 Winston Churchill | J17: =IFERROR(__xludf.DUMMYFUNCTION("IMPORTRANGE(""1QZzUr_MV6N6HMhICv9mBCuii7MD3z6uCvZMLFZibU6Q"", ""RR2!H25"")"),88.0) -> 88 | K17: =IFERROR(__xludf.DUMMYFUNCTION("IMPORTRANGE(""1Ak43y8GCpe0VeJyOSmu5frUAg6HEnwknENOp_P2vusc"", ""RR3!H25"")"),4.0) -> 4 | M17: =IFERROR(__xludf.DUMMYFUNCTION("IMPORTRANGE(""1Ak43y8GCpe0VeJyOSmu5frUAg6HEnwknENOp_P2vusc"", ""RR5!E25"")"),58.0) -> 58 | N17: =IFERROR(__xludf.DUMMYFUNCTION("IMPORTRANGE(""1QZzUr_MV6N6HMhICv9mBCuii7MD3z6uCvZMLFZibU6Q"", ""RR1!E25"")"),46.0) -> 46 | O17: =IFERROR(__xludf.DUMMYFUNCTION("IMPORTRANGE(""1EzV00Mnju8SkO4Z2XZFfkboXLUXdjoqVyO6dO-P0bsc"", ""RR4!E25"")"),52.0) -> 52
A18: C4 Westtown A | B18: =IFERROR(__xludf.DUMMYFUNCTION("IMPORTRANGE(""1Lo-UEbdVL-D3TuF5gEj-3AWGU8LSSjTDDeH9OM07xLM"", ""RR3!H25"")"),62.0) -> 62 | C18: =IFERROR(__xludf.DUMMYFUNCTION("IMPORTRANGE(""1SCVX9W3N-siFlvX2krUw1KBMk-omHCkvy-4I4moTpWM"", ""RR4!H25"")"),26.0) -> 26 | D18: =IFERROR(__xludf.DUMMYFUNCTION("IMPORTRANGE(""1qa62mdbdWiy5RjjYdhmu0eUEb2Zcp5cejYIFG7fnrWs"", ""RR5!H25"")"),56.0) -> 56 | F18: =IFERROR(__xludf.DUMMYFUNCTION("IMPORTRANGE(""1qa62mdbdWiy5RjjYdhmu0eUEb2Zcp5cejYIFG7fnrWs"", ""RR2!E25"")"),26.0) -> 26 | G18: =IFERROR(__xludf.DUMMYFUNCTION("IMPORTRANGE(""1Lo-UEbdVL-D3TuF5gEj-3AWGU8LSSjTDDeH9OM07xLM"", ""RR1!E25"")"),48.0) -> 48 | I18: D4 Westtown B | J18: =IFERROR(__xludf.DUMMYFUNCTION("IMPORTRANGE(""1EzV00Mnju8SkO4Z2XZFfkboXLUXdjoqVyO6dO-P0bsc"", ""RR3!H25"")"),58.0) -> 58 | K18: =IFERROR(__xludf.DUMMYFUNCTION("IMPORTRANGE(""1QZzUr_MV6N6HMhICv9mBCuii7MD3z6uCvZMLFZibU6Q"", ""RR4!H25"")"),8.0) -> 8 | L18: =IFERROR(__xludf.DUMMYFUNCTION("IMPORTRANGE(""1Ak43y8GCpe0VeJyOSmu5frUAg6HEnwknENOp_P2vusc"", ""RR5!H25"")"),18.0) -> 18 | N18: =IFERROR(__xludf.DUMMYFUNCTION("IMPORTRANGE(""1Ak43y8GCpe0VeJyOSmu5frUAg6HEnwknENOp_P2vusc"", ""RR2!E25"")"),40.0) -> 40 | O18: =IFERROR(__xludf.DUMMYFUNCTION("IMPORTRANGE(""1EzV00Mnju8SkO4Z2XZFfkboXLUXdjoqVyO6dO-P0bsc"", ""RR1!E25"")"),58.0) -> 58
A19: C5 Wilberforce B | B19: =IFERROR(__xludf.DUMMYFUNCTION("IMPORTRANGE(""1qa62mdbdWiy5RjjYdhmu0eUEb2Zcp5cejYIFG7fnrWs"", ""RR4!H25"")"),22.0) -> 22 | C19: =IFERROR(__xludf.DUMMYFUNCTION("IMPORTRANGE(""1Lo-UEbdVL-D3TuF5gEj-3AWGU8LSSjTDDeH9OM07xLM"", ""RR5!H25"")"),8.0) -> 8 | D19: =IFERROR(__xludf.DUMMYFUNCTION("IMPORTRANGE(""1SCVX9W3N-siFlvX2krUw1KBMk-omHCkvy-4I4moTpWM"", ""RR1!H25"")"),22.0) -> 22 | E19: =IFERROR(__xludf.DUMMYFUNCTION("IMPORTRANGE(""1qa62mdbdWiy5RjjYdhmu0eUEb2Zcp5cejYIFG7fnrWs"", ""RR2!H25"")"),34.0) -> 34 | G19: =IFERROR(__xludf.DUMMYFUNCTION("IMPORTRANGE(""1SCVX9W3N-siFlvX2krUw1KBMk-omHCkvy-4I4moTpWM"", ""RR3!E25"")"),38.0) -> 38 | I19: D5 Centreville A | J19: =IFERROR(__xludf.DUMMYFUNCTION("IMPORTRANGE(""1Ak43y8GCpe0VeJyOSmu5frUAg6HEnwknENOp_P2vusc"", ""RR4!H25"")"),68.0) -> 68 | K19: =IFERROR(__xludf.DUMMYFUNCTION("IMPORTRANGE(""1EzV00Mnju8SkO4Z2XZFfkboXLUXdjoqVyO6dO-P0bsc"", ""RR5!H25"")"),46.0) -> 46 | L19: =IFERROR(__xludf.DUMMYFUNCTION("IMPORTRANGE(""1QZzUr_MV6N6HMhICv9mBCuii7MD3z6uCvZMLFZibU6Q"", ""RR1!H25"")"),100.0) -> 100 | M19: =IFERROR(__xludf.DUMMYFUNCTION("IMPORTRANGE(""1Ak43y8GCpe0VeJyOSmu5frUAg6HEnwknENOp_P2vusc"", ""RR2!H25"")"),68.0) -> 68 | O19: =IFERROR(__xludf.DUMMYFUNCTION("IMPORTRANGE(""1QZzUr_MV6N6HMhICv9mBCuii7MD3z6uCvZMLFZibU6Q"", ""RR3!E25"")"),40.0) -> 40
A20: C6 TJHSST A | B20: =IFERROR(__xludf.DUMMYFUNCTION("IMPORTRANGE(""1SCVX9W3N-siFlvX2krUw1KBMk-omHCkvy-4I4moTpWM"", ""RR5!H25"")"),168.0) -> 168 | C20: =IFERROR(__xludf.DUMMYFUNCTION("IMPORTRANGE(""1Lo-UEbdVL-D3TuF5gEj-3AWGU8LSSjTDDeH9OM07xLM"", ""RR2!H25"")"),126.0) -> 126 | D20: =IFERROR(__xludf.DUMMYFUNCTION("IMPORTRANGE(""1Lo-UEbdVL-D3TuF5gEj-3AWGU8LSSjTDDeH9OM07xLM"", ""RR4!H25"")"),160.0) -> 160 | E20: =IFERROR(__xludf.DUMMYFUNCTION("IMPORTRANGE(""1Lo-UEbdVL-D3TuF5gEj-3AWGU8LSSjTDDeH9OM07xLM"", ""RR1!H25"")"),136.0) -> 136 | F20: =IFERROR(__xludf.DUMMYFUNCTION("IMPORTRANGE(""1SCVX9W3N-siFlvX2krUw1KBMk-omHCkvy-4I4moTpWM"", ""RR3!H25"")"),186.0) -> 186 | I20: D6 Poolesville | J20: =IFERROR(__xludf.DUMMYFUNCTION("IMPORTRANGE(""1QZzUr_MV6N6HMhICv9mBCuii7MD3z6uCvZMLFZibU6Q"", ""RR5!H25"")"),134.0) -> 134 | K20: =IFERROR(__xludf.DUMMYFUNCTION("IMPORTRANGE(""1EzV00Mnju8SkO4Z2XZFfkboXLUXdjoqVyO6dO-P0bsc"", ""RR2!H25"")"),54.0) -> 54 | L20: =IFERROR(__xludf.DUMMYFUNCTION("IMPORTRANGE(""1EzV00Mnju8SkO4Z2XZFfkboXLUXdjoqVyO6dO-P0bsc"", ""RR4!H25"")"),106.0) -> 106 | M20: =IFERROR(__xludf.DUMMYFUNCTION("IMPORTRANGE(""1EzV00Mnju8SkO4Z2XZFfkboXLUXdjoqVyO6dO-P0bsc"", ""RR1!H25"")"),122.0) -> 122 | N20: =IFERROR(__xludf.DUMMYFUNCTION("IMPORTRANGE(""1QZzUr_MV6N6HMhICv9mBCuii7MD3z6uCvZMLFZibU6Q"", ""RR3!H25"")"),184.0) -> 184

Sheet Team Scores
A1: Team Scores
A2: Code | B2: School | C2: Total Points
A3: A1 | B3: Plainsboro Knights | C3: =sum('RR Scoresheet'!B6:G6) -> 742
A4: A2 | B4: West Windsor-Plainsboro HS South B | C4: =sum('RR Scoresheet'!B7:G7) -> 744
A5: A3 | B5: The Wilberforce School A | C5: =sum('RR Scoresheet'!B8:G8) -> 324
A6: A4 | B6: BASIS Independent McLean | C6: =sum('RR Scoresheet'!B9:G9) -> 68
A7: A5 | B7: Thomas S Wootton High School A | C7: =sum('RR Scoresheet'!B10:G10) -> 224
A8: A6 | B8: Wheaton High School B | C8: =sum('RR Scoresheet'!B11:G11) -> 230
A9: B1 | B9: Centennial High School A | C9: =sum('RR Scoresheet'!J6:O6) -> 508
A10: B2 | B10: Alexandria City High School | C10: =sum('RR Scoresheet'!J7:O7) -> 74
A11: B3 | B11: Thomas Jefferson HS for Science and Technology B | C11: =sum('RR Scoresheet'!J8:O8) -> 416
A12: B4 | B12: Beltway Blazers B | C12: =sum('RR Scoresheet'!J9:O9) -> 488
A13: B5 | B13: West Windsor-Plainsboro HS South A | C13: =sum('RR Scoresheet'!J10:O10) -> 698
A14: B6 | B14: Wheaton High School A | C14: =sum('RR Scoresheet'!J11:O11) -> 280
A15: C1 | B15: Deep Run High School | C15: =sum('RR Scoresheet'!B15:G15) -> 354
A16: C2 | B16: Richard Montgomery | C16: =sum('RR Scoresheet'!B16:G16) -> 660
A17: C3 | B17: John R. Lewis High School | C17: =sum('RR Scoresheet'!B17:G17) -> 138
A18: C4 | B18: Westtown School A | C18: =sum('RR Scoresheet'!B18:G18) -> 218
A19: C5 | B19: The Wilberforce School B | C19: =sum('RR Scoresheet'!B19:G19) -> 124
A20: C6 | B20: Thomas Jefferson HS for Science and Technology A | C20: =sum('RR Scoresheet'!B20:G20) -> 776
A21: D1 | B21: Centennial High School B | C21: =sum('RR Scoresheet'!J15:O15) -> 150
A22: D2 | B22: Beltway Blazers A | C22: =sum('RR Scoresheet'!J16:O16) -> 1174
A23: D3 | B23: Winston Churchill High School | C23: =sum('RR Scoresheet'!J17:O17) -> 248
A24: D4 | B24: Westtown School B | C24: =sum('RR Scoresheet'!J18:O18) -> 182
A25: D5 | B25: Centreville High School A | C25: =sum('RR Scoresheet'!J19:O19) -> 322
A26: D6 | B26: Poolesville High School | C26: =sum('RR Scoresheet'!J20:O20) -> 600

Sheet DE Bracket
A1: DE 1: 1:15 - 1:50 p.m. EST | C1: DE 2: 1:50 - 2:25 p.m. EST | E1: DE 3: 2:25 - 3:00 p.m. EST | G1: DE 4: 3:00 - 3:35 p.m. EST | I1: DE 5: 3:35 - 4:10 p.m. EST | K1: DE 6: 4:10 - 4:40 p.m. EST | M1: DE 7: 4:50 - 5:25 p.m. EST | O1: FINALS: 5:25 - 6:25 p.m. EST
A2: Beltway Blazers A | B2: 218
A3: Hodson 210 (W1-1) | C3: Beltway Blazers A | D3: 198
A4: Westtown A | B4: 30
C5: Hodson 210 (W2-1) | E5: BYE | G5: Beltway Blazers A | H5: 182
A6: Centennial A | B6: 66
A7: Hodson 211 (W1-2) | C7: Beltway Blazers B | D7: 28
A8: Beltway Blazers B | B8: 108
G9: Hodson 210 (W4-1) | I9: BYE | K9: Beltway Blazers A | L9: 106
A10: Plainsboro Knights | B10: 94
A11: Hodson 213 (W1-3) | C11: Plainsboro Knights | D11: 50
A12: Wheaton A | B12: 8
C13: Hodson 211 (W2-2) | E13: BYE | G13: WWPS A | H13: 22
A14: WWPS A | B14: 98
A15: Hodson 216 (W1-4) | C15: WWPS A | D15: 126
A16: Deep Run | B16: 94
K17: Hodson 210 (W6-1) | M17: BYE | O17: Beltway Blazers A | P17: 76 | Q17: 110
A18: TJHSST A | B18: 100
A19: Hodson 301 (W1-5) | C19: TJHSST A | D19: 178
A20: Thomas S Wootton A | B20: 60
C21: Hodson 213 (W2-3) | E21: BYE | G21: TJHSST A | H21: 66
A22: Poolesville | B22: 98
A23: Hodson 303 (W1-6) | C23: Poolesville | D23: 48
A24: Wilberforce A | B24: 22
G25: Hodson 213 (W4-2) | I25: BYE | K25: WWPS B | L25: 92
A26: WWPS B | B26: 134 | R26: CHAMPION:
A27: Hodson 305 (W1-7) | C27: WWPS B | D27: 104 | O27: Hodson 210 (W8-1) | R27: Beltway Blazers A 🏆
A28: Winston Churchill | B28: 68
C29: Hodson 216 (W2-4) | E29: BYE | G29: WWPS B | H29: 80 | M29: WWPS B | N29: 42
A30: Richard Montgomery | B30: 106
A31: Hodson 311 (W1-8) | C31: Richard Montgomery | D31: 66
A32: Centreville A | B32: 16
I33: WWPS A | J33: 86
E35: Richard Montgomery | F35: 108
E37: Hodson 210 (L3-1) | G37: Richard Montgomery | H37: 52 | I37: Hodson 210 (L5-1) | K37: WWPS A | L37: 38 | M37: Hodson 210 (L7-1) | O37: TJHSST A | P37: 90 | Q37: 16
C38: Westtown A | D38: 24
C39: Hodson 301 (L2-1) | E39: Centennial A | F39: 26
C40: Centennial A | D40: 62
G41: Hodson 211 (L4-1) | I41: Richard Montgomery | J41: 28
E43: Poolesville | F43: 102
...
