Workbook

Sheet Advanced DE
A1: Advanced DE
A2: DE 1: 9-9:30 PDT | E2: DE 2: 9:30-10 PDT | I2: DE 3: 10-10:30 PDT | M2: DE 4: 10:45-11:15 PDT | Q2: DE 5: 11:15-11:45 PDT | U2: DE 6: 11:45-12:15 PDT | Y2: DE 7: 12:30-1 PDT | AC2: DE 8: 1-1:30 PDT | AG2: DE 9: 1:30-2 PDT | AK2: DE 10: 2-2:30 PDT | AO2: DE 11: 2:30-3 PDT
E4: 9 | F4: =Seeding!B3 -> Rohan B | G4: 90
A5: 1 | B5: =Seeding!B19 -> Darius S | C5: 0 | F5: =IFS(C5>C6,B5,C5<C6,B6,TRUE,) -> Advai S | G5: 44
B6: =Seeding!B18 -> Advai S | C6: 72 | J6: BYE | M6: 25 | N6: =IFS(G4>G5,F4,G4<G5,F5,TRUE,) -> Rohan B | O6: 38
N7: =IFS(G8>G9,F8,G8<G9,F9,TRUE,) -> Kensuke O | O7: 82
E8: 10 | F8: =Seeding!B10 -> Kensuke O | G8: 128
A9: 2 | B9: =Seeding!B11 -> Bryce T | C9: 4 | F9: =IFS(C9>C10,B9,C9<C10,B10,TRUE,) -> Baljeet C | G9: 32
B10: =Seeding!B26 -> Baljeet C | C10: 56 | R10: BYE | U10: 37 | V10: =IFS(O6>O7,N6,O6<O7,N7,TRUE,) -> Kensuke O | W10: 42 | Z10: BYE
V11: =IFS(O14>O15,N14,O14<O15,N15,TRUE,) -> Peter B | W11: 12
E12: 11 | F12: =Seeding!B7 -> Peter B | G12: 130
A13: 3 | B13: =Seeding!B23 -> Akshay R | C13: 22 | F13: =IFS(C13>C14,B13,C13<C14,B14,TRUE,) -> Ian C | G13: 32
B14: =Seeding!B14 -> Ian C | C14: 78 | J14: BYE | M14: 26 | N14: =IFS(G12>G13,F12,G12<G13,F13,TRUE,) -> Peter B | O14: 76
N15: =IFS(G16>G17,F16,G16<G17,F17,TRUE,) -> Akhil B | O15: 46
E16: 12 | F16: =Seeding!B6 -> Camille P | G16: 6
A17: 4 | B17: =Seeding!B15 -> Akhil B | C17: 92 | F17: Akhil B | G17: 56
B18: =Seeding!B22 -> Jason Y | C18: 46 | AC18: 43 | AD18: =IFS(W10>W11,V10,W10<W11,V11,TRUE,) -> Kensuke O | AE18: 36 | AH18: BYE
AD19: =IFS(W26>W27,V26,W26<W27,V27,TRUE,) -> Ziang Z | AE19: 30
E20: 13 | F20: =Seeding!B5 -> Alex L | G20: 58
A21: 5 | B21: =Seeding!B21 -> Kevin F | C21: 66 | F21: =IFS(C21>C22,B21,C21<C22,B22,TRUE,) -> Travis D | G21: 58+T
B22: =Seeding!B16 -> Travis D | C22: 74 | J22: BYE | M22: 27 | N22: =IFS(G20>G21,F20,G20<G21,F21,TRUE,) -> Travis D | O22: 4
N23: =IFS(G24>G25,F24,G24<G25,F25,TRUE,) -> Varyan J | O23: 70
E24: 14 | F24: =Seeding!B8 -> Ishaan K | G24: 44
A25: 6 | B25: =Seeding!B13 -> Varyan J | C25: 126 | F25: =IFS(C25>C26,B25,C25<C26,B26,TRUE,) -> Varyan J | G25: 70
B26: =Seeding!B24 -> Luyao Y | C26: -8 | R26: BYE | U26: 38 | V26: =IFS(O22>O23,N22,O22<O23,N23,TRUE,) -> Varyan J | W26: 16 | Z26: BYE
V27: =IFS(O30>O31,N30,O30<O31,N31,TRUE,) -> Ziang Z | W27: 54
E28: 15 | F28: =Seeding!B9 -> Suzuko O | G28: 80
A29: 7 | B29: =Seeding!B25 -> Henry L | C29: 40 | F29: =IFS(C29>C30,B29,C29<C30,B30,TRUE,) -> Praneel A | G29: 14
B30: =Seeding!B12 -> Praneel A | C30: 96 | J30: BYE | M30: 28 | N30: =IFS(G28>G29,F28,G28<G29,F29,TRUE,) -> Suzuko O | O30: 66
N31: =IFS(G32>G33,F32,G32<G33,F33,TRUE,) -> Ziang Z | O31: 90
E32: 16 | F32: =Seeding!B4 -> Ziang Z | G32: 104 | AK32: 46 | AL32: =IFS(AE18>AE19,AD18,AE18<AE19,AD19,TRUE,) -> Kensuke O | AM32: 16 | AO32: 47 | AP32: Rohan B | AQ32: 10
A33: 8 | B33: =Seeding!B17 -> Alex Z | C33: 0 | F33: =IFS(C33>C34,B33,C33<C34,B34,TRUE,) -> Abhiraam G | G33: -36 | AL33: =IFS(AI47>AI48,AH47,AI47<AI48,AH48,TRUE,) -> Rohan B | AM33: 24 | AP33: Kensuke O | AQ33: 2
B34: =Seeding!B20 -> Abhiraam G | C34: 36
Q37: 33 | R37: =IFS(O6>O7,N7,O6<O7,N6,TRUE,) -> Rohan B | S37: 90
I38: 17 | J38: =IFS(C5>C6,B6,C5<C6,B5,TRUE,) -> Darius S | K38: 72 | R38: =IFS(O40>O41,N40,O40<O41,N41,TRUE,) -> Darius S | S38: 2
J39: =IFS(G32>G33,F33,G32<G33,F32,TRUE,) -> Abhiraam G | K39: 0 | Y39: 41 | Z39: =IFS(W26>W27,V27,W26<W27,V26,TRUE,) -> Varyan J | AA39: 8
M40: 29 | N40: =IFS(K38>K39,J38,K38<K39,J39,TRUE,) -> Darius S | O40: 18 | Z40: =IFS(W42>W43,V42,W42<W43,V43,TRUE,) -> Rohan B | AA40: 40
N41: =IFS(K42>K43,J42,K42<K43,J43,TRUE,) -> Praneel A | O41: 12
I42: 18 | J42: =IFS(C9>C10,B10,C9<C10,B9,TRUE,) -> Bryce T | K42: 26 | U42: 39 | V42: =IFS(S37>S38,R37,S37<S38,R38,TRUE,) -> Rohan B | W42: 62
J43: =IFS(G28>G29,F29,G28<G29,F28,TRUE,) -> Praneel A | K43: 94 | V43: =IFS(S47>S48,R47,S47<S48,R48,TRUE,) -> Akhil B | W43: 58
...

Sheet Novice SE
H1: Novice SE
A2: SE 1: 9-9:30 PDT | E2: SE 2: 9:30-10 PDT | I2: SE 3: 10-10:30 PDT | M2: SE 4: 10:45-11:15 PDT
A4: 1 | B4: Mihin B | C4: 0
B5: Chris W | C5: 4
E6: 9 | F6: =IFS(C4>C5,B4,C4<C5,B5,TRUE,) -> Chris W | G6: 66
F7: =IFS(C8>C9,B8,C8<C9,B9,TRUE,) -> Mila H | G7: 6
A8: 2 | B8: Mila H | C8: 4
B9: Jabez Z | C9: 0
I10: 13 | J10: =IFS(G6>G7,F6,G6<G7,F7,TRUE,) -> Chris W | K10: 18
J11: =IFS(G14>G15,F14,G14<G15,F15,TRUE,) -> Achuth V | K11: 32
A12: 3 | B12: Timothy Y | C12: 56
B13: Sarabhesh S | C13: 50
E14: 10 | F14: =IFS(C12>C13,B12,C12<C13,B13,TRUE,) -> Timothy Y | G14: 6
F15: =IFS(C16>C17,B16,C16<C17,B17,TRUE,) -> Achuth V | G15: 84
A16: 4 | B16: Achuth V | C16: 54
B17: Caroline H | C17: 0
M18: 15 | N18: =IFS(K10>K11,J10,K10<K11,J11,TRUE,) -> Achuth V | O18: 12
N19: =IFS(K26>K27,J26,K26<K27,J27,TRUE,) -> Shannon I | O19: 38
A20: 5 | B20: Dennis J | C20: 124
B21: Catherine D | C21: 22
E22: 11 | F22: =IFS(C20>C21,B20,C20<C21,B21,TRUE,) -> Dennis J | G22: 48
F23: =IFS(C24>C25,B24,C24<C25,B25,TRUE,) -> Monish S | G23: 46
A24: 6 | B24: Jack W | C24: 52
B25: Monish S | C25: 56
I26: 14 | J26: =IFS(G22>G23,F22,G22<G23,F23,TRUE,) -> Dennis J | K26: 62
J27: =IFS(G30>G31,F30,G30<G31,F31,TRUE,) -> Shannon I | K27: 62+T
A28: 7 | B28: Nathaniel O | C28: 0
B29: Sriman D | C29: 82
E30: 12 | F30: =IFS(C28>C29,B28,C28<C29,B29,TRUE,) -> Sriman D | G30: 2
F31: Shannon I | G31: 78
A32: 8 | B32: Shannon I | C32: 124
B33: Maneesh G | C33: 14

Sheet Seeding
A1: Advanced | C1: Novice
A2: Seed | B2: Name | C2: Seed | D2: Name
A3: 1 | B3: Rohan B | C3: 1 | D3: Mihin B
A4: 2 | B4: Ziang Z | C4: 2 | D4: Shannon I
A5: 3 | B5: Alex L | C5: 3 | D5: Jack W
A6: 4 | B6: Camille P | C6: 4 | D6: Achuth V
A7: 5 | B7: Peter B | C7: 5 | D7: Timothy Y
A8: 6 | B8: Ishaan K | C8: 6 | D8: Dennis J
A9: 7 | B9: Suzuko O | C9: 7 | D9: Nathaniel O
A10: 8 | B10: Kensuke O | C10: 8 | D10: Mila H
A11: 9 | B11: Bryce T | C11: 9 | D11: Jabez Z
A12: 10 | B12: Praneel A | C12: 10 | D12: Sriman D
A13: 11 | B13: Varyan J | C13: 11 | D13: Catherine D
A14: 12 | B14: Ian C | C14: 12 | D14: Sarabhesh S
... A18: 16 | B18: Advai S | C18: 16 | D18: Chris W
A19: 17 | B19: Darius S
A20: 18 | B20: Abhiraam G
A21: 19 | B21: Kevin F
A22: 20 | B22: Jason Y
A23: 21 | B23: Akshay R
A24: 22 | B24: Luyao Y
A25: 23 | B25: Henry L
A26: 24 | B26: Baljeet C

Sheet RR Results (Novice)
A1: RR Results (Novice)
A3: Albite | T3: Anorthite
A4: =SUM(P5:P12) -> 1950 | B4: RR1 | D4: RR2 | F4: RR3 | H4: RR4 | J4: RR5 | L4: RR6 | N4: RR7 | P4: Total | Q4: Pts | R4: R | T4: =SUM(AI5:AI12) -> 1698 | U4: RR1 | W4: RR2 | Y4: RR3 | AA4: RR4 | AC4: RR5 | AE4: RR6 | AG4: RR7 | AI4: Total | AJ4: Pts | AK4: R
A5: Catherine D | B5: T | C5: 28 | D5: L | E5: 10 | F5: L | G5: 28 | H5: W | I5: 36 | J5: W | K5: 62 | L5: L | M5: 26 | N5: L | O5: 28 | P5: =SUM(C5 + E5 + G5 + I5 + K5 + M5 + O5) -> 218 | Q5: =2*countif(B5:O5,"W")+countif(B5:O5,"T") -> 5 | R5: 6 | T5: Chris W | U5: L | V5: -2 | W5: L | X5: 0 | Y5: L | Z5: 24 | AA5: L | AB5: 2 | AC5: L | AD5: 40 | AE5: L | AF5: 34 | AG5: L | AH5: 22 | AI5: =SUM(V5 + X5 + Z5 + AB5 + AD5 + AF5 + AH5) -> 120 | AJ5: =2*countif(U5:AH5,"W")+countif(U5:AH5,"T") -> 0 | AK5: 8
A6: Caroline H | B6: T | C6: 28 | D6: L | E6: 18 | F6: L | G6: 8 | H6: L | I6: 8 | J6: T | K6: 34 | L6: L | M6: 18 | N6: L | O6: 22 | P6: =SUM(C6 + E6 + G6 + I6 + K6 + M6 + O6) -> 136 | Q6: =2*countif(B6:O6,"W")+countif(B6:O6,"T") -> 2 | R6: 7 | T6: Sarabhesh S | U6: W | V6: 32 | W6: L | X6: 16 | Y6: L | Z6: 6 | AA6: W | AB6: 24 | AC6: L | AD6: 14 | AE6: L | AF6: 18 | AG6: L | AH6: 32 | AI6: =SUM(V6 + X6 + Z6 + AB6 + AD6 + AF6 + AH6) -> 142 | AJ6: =2*countif(U6:AH6,"W")+countif(U6:AH6,"T") -> 4 | AK6: 6
A7: Mihin B | B7: W | C7: 66 | D7: W | E7: 68 | F7: W | G7: 78 | H7: T | I7: 48 | J7: W | K7: 60 | L7: W | M7: 86 | N7: W | O7: 56 | P7: =SUM(C7 + E7 + G7 + I7 + K7 + M7 + O7) -> 462 | Q7: =2*countif(B7:O7,"W")+countif(B7:O7,"T") -> 13 | R7: 1 | T7: Shannon I | U7: W | V7: 46 | W7: W | X7: 62 | Y7: W | Z7: 54 | AA7: W | AB7: 58 | AC7: L | AD7: 30 | AE7: W | AF7: 46 | AG7: W | AH7: 44 | AI7: =SUM(V7 + X7 + Z7 + AB7 + AD7 + AF7 + AH7) -> 340 | AJ7: =2*countif(U7:AH7,"W")+countif(U7:AH7,"T") -> 12 | AK7: 1
A8: Timothy Y | B8: W | C8: 50 | D8: W | E8: 52 | F8: W | G8: 34 | H8: W | I8: 52 | J8: L | K8: 24 | L8: L | M8: 26 | N8: L | O8: 8 | P8: =SUM(C8 + E8 + G8 + I8 + K8 + M8 + O8) -> 246 | Q8: =2*countif(B8:O8,"W")+countif(B8:O8,"T") -> 8 | R8: 3 | T8: Monish S | U8: L | V8: 6 | W8: L | X8: 12 | Y8: W | Z8: 40 | AA8: L | AB8: 8 | AC8: W | AD8: 46 | AE8: L | AF8: 8 | AG8: L | AH8: 0 | AI8: =SUM(V8 + X8 + Z8 + AB8 + AD8 + AF8 + AH8) -> 120 | AJ8: =2*countif(U8:AH8,"W")+countif(U8:AH8,"T") -> 4 | AK8: 7
A9: Mila H | B9: L | C9: 20 | D9: W | E9: 50 | F9: W | G9: 48 | H9: L | I9: 26 | J9: T | K9: 34 | L9: L | M9: -4 | N9: W | O9: 30 | P9: =SUM(C9 + E9 + G9 + I9 + K9 + M9 + O9) -> 204 | Q9: =2*countif(B9:O9,"W")+countif(B9:O9,"T") -> 7 | R9: 4 | T9: Achuth V | U9: W | V9: 20 | W9: W | X9: 44 | Y9: W | Z9: 56 | AA9: W | AB9: 18 | AC9: W | AD9: 48 | AE9: L | AF9: 42 | AG9: W | AH9: 16 | AI9: =SUM(V9 + X9 + Z9 + AB9 + AD9 + AF9 + AH9) -> 244 | AJ9: =2*countif(U9:AH9,"W")+countif(U9:AH9,"T") -> 12 | AK9: 2
A10: Maneesh G | B10: L | C10: 14 | D10: L | E10: 38 | F10: L | G10: 8 | H10: L | I10: 12 | J10: L | K10: 12 | L10: W | M10: 42 | N10: L | O10: 4 | P10: =SUM(C10 + E10 + G10 + I10 + K10 + M10 + O10) -> 130 | Q10: =2*countif(B10:O10,"W")+countif(B10:O10,"T") -> 2 | R10: 8 | T10: Dennis J | U10: W | V10: 36 | W10: L | X10: 30 | Y10: L | Z10: 32 | AA10: W | AB10: 30 | AC10: W | AD10: 44 | AE10: W | AF10: 72 | AG10: L | AH10: 26 | AI10: =SUM(V10 + X10 + Z10 + AB10 + AD10 + AF10 + AH10) -> 270 | AJ10: =2*countif(U10:AH10,"W")+countif(U10:AH10,"T") -> 8 | AK10: 3
A11: Jabez Z | B11: L | C11: 8 | D11: L | E11: 30 | F11: L | G11: 38 | H11: W | I11: 52 | J11: L | K11: 12 | L11: W | M11: 38 | N11: W | O11: 34 | P11: =SUM(C11 + E11 + G11 + I11 + K11 + M11 + O11) -> 212 | Q11: =2*countif(B11:O11,"W")+countif(B11:O11,"T") -> 6 | R11: 5 | T11: Nathaniel O | U11: L | V11: 20 | W11: W | X11: 58 | Y11: L | Z11: 18 | AA11: L | AB11: 28 | AC11: W | AD11: 50 | AE11: W | AF11: 36 | AG11: W | AH11: 42 | AI11: =SUM(V11 + X11 + Z11 + AB11 + AD11 + AF11 + AH11) -> 252 | AJ11: =2*countif(U11:AH11,"W")+countif(U11:AH11,"T") -> 8 | AK11: 4
A12: Jack W | B12: W | C12: 40 | D12: W | E12: 46 | F12: W | G12: 72 | H12: T | I12: 48 | J12: W | K12: 56 | L12: W | M12: 46 | N12: W | O12: 34 | P12: =SUM(C12 + E12 + G12 + I12 + K12 + M12 + O12) -> 342 | Q12: =2*countif(B12:O12,"W")+countif(B12:O12,"T") -> 13 | R12: 2 | T12: Sriman D | U12: L | V12: 8 | W12: W | X12: 64 | Y12: W | Z12: 48 | AA12: L | AB12: 4 | AC12: L | AD12: 24 | AE12: W | AF12: 32 | AG12: W | AH12: 30 | AI12: =SUM(V12 + X12 + Z12 + AB12 + AD12 + AF12 + AH12) -> 210 | AJ12: =2*countif(U12:AH12,"W")+countif(U12:AH12,"T") -> 8 | AK12: 5

Sheet RR Results (Adv)
A1: RR Results (Advanced)
A3: Almandine | T3: Andradite
A4: =SUM(P5:P12) -> 1664 | B4: RR1 | D4: RR2 | F4: RR3 | H4: RR4 | J4: RR5 | L4: RR6 | N4: RR7 | P4: Total | Q4: Pts | R4: R | T4: =SUM(AI5:AI12) -> 1618 | U4: RR1 | W4: RR2 | Y4: RR3 | AA4: RR4 | AC4: RR5 | AE4: RR6 | AG4: RR7 | AI4: Total | AJ4: Pts | AK4: R
A5: Peter B | B5: W | C5: 74 | D5: W | E5: 52 | F5: W | G5: 54 | H5: W | I5: 54 | J5: W | K5: 26 | L5: W | M5: 30 | N5: W | O5: 50 | P5: =SUM(C5 + E5 + G5 + I5 + K5 + M5 + O5) -> 340 | Q5: =2*countif(B5:O5,"W")+countif(B5:O5,"T") -> 14 | R5: 1 | T5: Alex Z | U5: W | V5: 46 | W5: L | X5: 16 | Y5: L | Z5: 26 | AA5: L | AB5: 42 | AC5: W | AD5: 44 | AE5: W | AF5: 14 | AG5: W | AH5: 44 | AI5: =SUM(V5 + X5 + Z5 + AB5 + AD5 + AF5 + AH5) -> 232 | AJ5: =2*countif(U5:AH5,"W")+countif(U5:AH5,"T") -> 8 | AK5: 3
A6: Jason Y | B6: L | C6: 12 | D6: W | E6: 32 | F6: L | G6: 18 | H6: W | I6: 42 | J6: L | K6: 38 | L6: W | M6: 48 | N6: W | O6: 42 | P6: =SUM(C6 + E6 + G6 + I6 + K6 + M6 + O6) -> 232 | Q6: =2*countif(B6:O6,"W")+countif(B6:O6,"T") -> 8 | R6: 4 | T6: Kevin F | U6: L | V6: 32 | W6: W | X6: 50 | Y6: L | Z6: 34 | AA6: L | AB6: 14 | AC6: W | AD6: 58 | AE6: L | AF6: 22 | AG6: W | AH6: 48 | AI6: =SUM(V6 + X6 + Z6 + AB6 + AD6 + AF6 + AH6) -> 258 | AJ6: =2*countif(U6:AH6,"W")+countif(U6:AH6,"T") -> 6 | AK6: 4
A7: Akhil B | B7: W | C7: 68 | D7: L | E7: 38 | F7: W | G7: 60 | H7: W | I7: 60 | J7: W | K7: 42 | L7: L | M7: 30 | N7: L | O7: 18 | P7: =SUM(C7 + E7 + G7 + I7 + K7 + M7 + O7) -> 316 | Q7: =2*countif(B7:O7,"W")+countif(B7:O7,"T") -> 8 | R7: 3 | T7: Kensuke O | U7: W | V7: 70 | W7: W | X7: 40 | Y7: W | Z7: 36 | AA7: W | AB7: 44 | AC7: L | AD7: 24 | AE7: W | AF7: 70 | AG7: W | AH7: 30 | AI7: =SUM(V7 + X7 + Z7 + AB7 + AD7 + AF7 + AH7) -> 314 | AJ7: =2*countif(U7:AH7,"W")+countif(U7:AH7,"T") -> 12 | AK7: 2
A8: Edwin H | B8: L | C8: 12 | D8: L | E8: 28 | F8: L | G8: 24 | H8: L | I8: 22 | J8: L | K8: 18 | L8: W | M8: 30 | N8: L | O8: 22 | P8: =SUM(C8 + E8 + G8 + I8 + K8 + M8 + O8) -> 156 | Q8: =2*countif(B8:O8,"W")+countif(B8:O8,"T") -> 2 | R8: 7 | T8: Ishaan K | U8: W | V8: 64 | W8: L | X8: 4 | Y8: W | Z8: 50 | AA8: W | AB8: 46 | AC8: W | AD8: 34 | AE8: W | AF8: 98 | AG8: W | AH8: 50 | AI8: =SUM(V8 + X8 + Z8 + AB8 + AD8 + AF8 + AH8) -> 346 | AJ8: =2*countif(U8:AH8,"W")+countif(U8:AH8,"T") -> 12 | AK8: 1
A9: Praneel A | B9: W | C9: 62 | D9: W | E9: 34 | F9: W | G9: 40 | H9: L | I9: 30 | J9: W | K9: 40 | L9: W | M9: 48 | N9: W | O9: 34 | P9: =SUM(C9 + E9 + G9 + I9 + K9 + M9 + O9) -> 288 | Q9: =2*countif(B9:O9,"W")+countif(B9:O9,"T") -> 12 | R9: 2 | T9: Birdie L | U9: W | V9: 34 | W9: L | X9: 18 | Y9: W | Z9: 42 | AA9: W | AB9: 48 | AC9: L | AD9: 10 | AE9: L | AF9: -6 | AG9: L | AH9: 2 | AI9: =SUM(V9 + X9 + Z9 + AB9 + AD9 + AF9 + AH9) -> 148 | AJ9: =2*countif(U9:AH9,"W")+countif(U9:AH9,"T") -> 6 | AK9: 5
A10: Shreehan P | B10: W | C10: 30 | D10: L | E10: 6 | F10: W | G10: 16 | H10: T | I10: 12 | J10: L | K10: 24 | L10: L | M10: 16 | N10: W | O10: 28 | P10: =SUM(C10 + E10 + G10 + I10 + K10 + M10 + O10) -> 132 | Q10: =2*countif(B10:O10,"W")+countif(B10:O10,"T") -> 7 | R10: 5 | T10: Shashank V | U10: L | V10: 14 | W10: W | X10: 20 | Y10: W | Z10: 24 | AA10: L | AB10: 20 | AC10: L | AD10: 14 | AE10: W | AF10: 34 | AG10: L | AH10: 2 | AI10: =SUM(V10 + X10 + Z10 + AB10 + AD10 + AF10 + AH10) -> 128 | AJ10: =2*countif(U10:AH10,"W")+countif(U10:AH10,"T") -> 6 | AK10: 6
A11: Shubam V | B11: L | C11: 20 | D11: W | E11: 40 | F11: L | G11: 20 | H11: T | I11: 12 | J11: T | K11: 18 | L11: L | M11: 10 | N11: L | O11: 18 | P11: =SUM(C11 + E11 + G11 + I11 + K11 + M11 + O11) -> 138 | Q11: =2*countif(B11:O11,"W")+countif(B11:O11,"T") -> 4 | R11: 6 | T11: Adam N | U11: L | V11: 10 | W11: W | X11: 8 | Y11: L | Z11: 12 | AA11: W | AB11: 30 | AC11: T | AD11: 20 | AE11: L | AF11: 12 | AG11: L | AH11: -8 | AI11: =SUM(V11 + X11 + Z11 + AB11 + AD11 + AF11 + AH11) -> 84 | AJ11: =2*countif(U11:AH11,"W")+countif(U11:AH11,"T") -> 5 | AK11: 7
A12: Azim F | B12: L | C12: 18 | D12: L | E12: 22 | F12: L | G12: 12 | H12: L | I12: 2 | J12: T | K12: 18 | L12: L | M12: 2 | N12: L | O12: -12 | P12: =SUM(C12 + E12 + G12 + I12 + K12 + M12 + O12) -> 62 | Q12: =2*countif(B12:O12,"W")+countif(B12:O12,"T") -> 1 | R12: 8 | T12: Nimit A | U12: L | V12: 28 | W12: L | X12: 20 | Y12: L | Z12: 20 | AA12: L | AB12: 24 | AC12: T | AD12: 20 | AE12: L | AF12: -6 | AG12: L | AH12: 2 | AI12: =SUM(V12 + X12 + Z12 + AB12 + AD12 + AF12 + AH12) -> 108 | AJ12: =2*countif(U12:AH12,"W")+countif(U12:AH12,"T") -> 1 | AK12: 8
A14: Pyrope | T14: Grossular
A15: =SUM(P16:P23) -> 1622 | B15: RR1 | D15: RR2 | F15: RR3 | H15: RR4 | J15: RR5 | L15: RR6 | N15: RR7 | P15: Total | Q15: Pts | R15: R | T15: =SUM(AI16:AI23) -> 1728 | U15: RR1 | W15: RR2 | Y15: RR3 | AA15: RR4 | AC15: RR5 | AE15: RR6 | AG15: RR7 | AI15: Total | AJ15: Pts | AK15: R
A16: Ziang Z | B16: W | C16: 68 | D16: W | E16: 56 | F16: T | G16: 28 | H16: W | I16: 66 | J16: W | K16: 68 | L16: W | M16: 66 | N16: W | O16: 50 | P16: =SUM(C16 + E16 + G16 + I16 + K16 + M16 + O16) -> 402 | Q16: =2*countif(B16:O16,"W")+countif(B16:O16,"T") -> 13 | R16: 1 | T16: Bryce T | U16: W | V16: 54 | W16: W | X16: 36 | Y16: W | Z16: 84 | AA16: W | AB16: 40 | AC16: W | AD16: 44 | AE16: L | AF16: 2 | AG16: L | AH16: 24 | AI16: =SUM(V16 + X16 + Z16 + AB16 + AD16 + AF16 + AH16) -> 284 | AJ16: =2*countif(U16:AH16,"W")+countif(U16:AH16,"T") -> 10 | AK16: 2
A17: Shaleen B | B17: L | C17: 20 | D17: L | E17: 12 | F17: L | G17: 20 | H17: L | I17: 24 | J17: W | K17: 36 | L17: L | M17: 10 | N17: L | O17: 28 | P17: =SUM(C17 + E17 + G17 + I17 + K17 + M17 + O17) -> 150 | Q17: =2*countif(B17:O17,"W")+countif(B17:O17,"T") -> 2 | R17: 7 | T17: Jack G | U17: L | V17: 20 | W17: L | X17: 26 | Y17: L | Z17: 4 | AA17: L | AB17: 38 | AC17: L | AD17: 12 | AE17: W | AF17: 48 | AG17: L | AH17: 20 | AI17: =SUM(V17 + X17 + Z17 + AB17 + AD17 + AF17 + AH17) -> 168 | AJ17: =2*countif(U17:AH17,"W")+countif(U17:AH17,"T") -> 2 | AK17: 7
A18: Advai S | B18: W | C18: 78 | D18: L | E18: 20 | F18: W | G18: 30 | H18: L | I18: 12 | J18: L | K18: 6 | L18: W | M18: 36 | N18: W | O18: 48 | P18: =SUM(C18 + E18 + G18 + I18 + K18 + M18 + O18) -> 230 | Q18: =2*countif(B18:O18,"W")+countif(B18:O18,"T") -> 8 | R18: 3 | T18: Shreyas E | U18: W | V18: 56 | W18: L | X18: 28 | Y18: W | Z18: 58 | AA18: W | AB18: 48 | AC18: W | AD18: 34 | AE18: L | AF18: 2 | AG18: W | AH18: 52 | AI18: =SUM(V18 + X18 + Z18 + AB18 + AD18 + AF18 + AH18) -> 278 | AJ18: =2*countif(U18:AH18,"W")+countif(U18:AH18,"T") -> 10 | AK18: 3
A19: Varyan J | B19: W | C19: 44 | D19: W | E19: 38 | F19: T | G19: 28 | H19: W | I19: 52 | J19: W | K19: 52 | L19: W | M19: 36 | N19: L | O19: 14 | P19: =SUM(C19 + E19 + G19 + I19 + K19 + M19 + O19) -> 264 | Q19: =2*countif(B19:O19,"W")+countif(B19:O19,"T") -> 11 | R19: 2 | T19: Baljeet C | U19: W | V19: 50 | W19: L | X19: 26 | Y19: L | Z19: 8 | AA19: W | AB19: 42 | AC19: L | AD19: 16 | AE19: L | AF19: 30 | AG19: L | AH19: 16 | AI19: =SUM(V19 + X19 + Z19 + AB19 + AD19 + AF19 + AH19) -> 188 | AJ19: =2*countif(U19:AH19,"W")+countif(U19:AH19,"T") -> 4 | AK19: 6
A20: Mary P | B20: L | C20: 16 | D20: W | E20: 32 | F20: W | G20: 36 | H20: L | I20: 30 | J20: L | K20: 14 | L20: L | M20: 30 | N20: W | O20: 22 | P20: =SUM(C20 + E20 + G20 + I20 + K20 + M20 + O20) -> 180 | Q20: =2*countif(B20:O20,"W")+countif(B20:O20,"T") -> 6 | R20: 5 | T20: Alex L | U20: W | V20: 66 | W20: W | X20: 58 | Y20: W | Z20: 72 | AA20: L | AB20: 8 | AC20: W | AD20: 46 | AE20: W | AF20: 42 | AG20: W | AH20: 66 | AI20: =SUM(V20 + X20 + Z20 + AB20 + AD20 + AF20 + AH20) -> 358 | AJ20: =2*countif(U20:AH20,"W")+countif(U20:AH20,"T") -> 12 | AK20: 1
A21: Daniel Y | B21: L | C21: 18 | D21: L | E21: 20 | F21: L | G21: 6 | H21: L | I21: -12 | J21: L | K21: -4 | L21: W | M21: 24 | N21: L | O21: 6 | P21: =SUM(C21 + E21 + G21 + I21 + K21 + M21 + O21) -> 58 | Q21: =2*countif(B21:O21,"W")+countif(B21:O21,"T") -> 2 | R21: 8 | T21: Sudhanva B | U21: L | V21: 16 | W21: L | X21: 4 | Y21: L | Z21: 26 | AA21: L | AB21: 18 | AC21: L | AD21: 4 | AE21: L | AF21: 14 | AG21: L | AH21: 0 | AI21: =SUM(V21 + X21 + Z21 + AB21 + AD21 + AF21 + AH21) -> 82 | AJ21: =2*countif(U21:AH21,"W")+countif(U21:AH21,"T") -> 0 | AK21: 8
A22: Arnav H | B22: L | C22: 6 | D22: L | E22: 28 | F22: L | G22: 2 | H22: W | I22: 44 | J22: W | K22: 34 | L22: L | M22: 10 | N22: W | O22: 38 | P22: =SUM(C22 + E22 + G22 + I22 + K22 + M22 + O22) -> 162 | Q22: =2*countif(B22:O22,"W")+countif(B22:O22,"T") -> 6 | R22: 6 | T22: Luyao Y | U22: L | V22: 18 | W22: W | X22: 44 | Y22: L | Z22: 12 | AA22: W | AB22: 38 | AC22: L | AD22: 12 | AE22: W | AF22: 14 | AG22: W | AH22: 26 | AI22: =SUM(V22 + X22 + Z22 + AB22 + AD22 + AF22 + AH22) -> 164 | AJ22: =2*countif(U22:AH22,"W")+countif(U22:AH22,"T") -> 8 | AK22: 5
A23: Akshay R | B23: W | C23: 38 | D23: W | E23: 44 | F23: W | G23: 20 | H23: W | I23: 50 | J23: L | K23: 26 | L23: L | M23: 10 | N23: L | O23: -12 | P23: =SUM(C23 + E23 + G23 + I23 + K23 + M23 + O23) -> 176 | Q23: =2*countif(B23:O23,"W")+countif(B23:O23,"T") -> 8 | R23: 4 | T23: Andrew F | U23: L | V23: -4 | W23: W | X23: 40 | Y23: W | Z23: 28 | AA23: L | AB23: 24 | AC23: W | AD23: 50 | AE23: W | AF23: 36 | AG23: W | AH23: 32 | AI23: =SUM(V23 + X23 + Z23 + AB23 + AD23 + AF23 + AH23) -> 206 | AJ23: =2*countif(U23:AH23,"W")+countif(U23:AH23,"T") -> 10 | AK23: 4
A25: Spessartine | T25: Uvarovite
A26: =SUM(P27:P34) -> 1830 | B26: RR1 | D26: RR2 | F26: RR3 | H26: RR4 | J26: RR5 | L26: RR6 | N26: RR7 | P26: Total | Q26: Pts | R26: R | T26: =SUM(AI27:AI34) -> 1836 | U26: RR1 | W26: RR2 | Y26: RR3 | AA26: RR4 | AC26: RR5 | AE26: RR6 | AG26: RR7 | AI26: Total | AJ26: Pts | AK26: R
A27: Aastik B | B27: L | C27: 32 | D27: L | E27: 8 | F27: L | G27: 22 | H27: L | I27: 24 | J27: W | K27: 24 | L27: L | M27: 8 | N27: L | O27: 36 | P27: =SUM(C27 + E27 + G27 + I27 + K27 + M27 + O27) -> 154 | Q27: =2*countif(B27:O27,"W")+countif(B27:O27,"T") -> 2 | R27: 7 | T27: Henry L | U27: L | V27: 20 | W27: W | X27: 46 | Y27: L | Z27: 14 | AA27: L | AB27: 24 | AC27: T | AD27: 22 | AE27: L | AF27: 16 | AG27: W | AH27: 62 | AI27: =SUM(V27 + X27 + Z27 + AB27 + AD27 + AF27 + AH27) -> 204 | AJ27: =2*countif(U27:AH27,"W")+countif(U27:AH27,"T") -> 5 | AK27: 6
A28: Camille P | B28: W | C28: 40 | D28: W | E28: 48 | F28: W | G28: 42 | H28: W | I28: 40 | J28: W | K28: 38 | L28: W | M28: 46 | N28: W | O28: 60 | P28: =SUM(C28 + E28 + G28 + I28 + K28 + M28 + O28) -> 314 | Q28: =2*countif(B28:O28,"W")+countif(B28:O28,"T") -> 14 | R28: 1 | T28: Ian C | U28: W | V28: 28 | W28: W | X28: 40 | Y28: L | Z28: 18 | AA28: L | AB28: 28 | AC28: W | AD28: 28 | AE28: T | AF28: 28 | AG28: W | AH28: 34 | AI28: =SUM(V28 + X28 + Z28 + AB28 + AD28 + AF28 + AH28) -> 204 | AJ28: =2*countif(U28:AH28,"W")+countif(U28:AH28,"T") -> 9 | AK28: 2
A29: Suzuko O | B29: W | C29: 38 | D29: W | E29: 64 | F29: L | G29: 32 | H29: W | I29: 52 | J29: W | K29: 30 | L29: W | M29: 66 | N29: W | O29: 36 | P29: =SUM(C29 + E29 + G29 + I29 + K29 + M29 + O29) -> 318 | Q29: =2*countif(B29:O29,"W")+countif(B29:O29,"T") -> 12 | R29: 2 | T29: Ryan E | U29: L | V29: 42 | W29: L | X29: 40 | Y29: W | Z29: 48 | AA29: W | AB29: 34 | AC29: L | AD29: 42 | AE29: W | AF29: 40 | AG29: W | AH29: 58 | AI29: =SUM(V29 + X29 + Z29 + AB29 + AD29 + AF29 + AH29) -> 304 | AJ29: =2*countif(U29:AH29,"W")+countif(U29:AH29,"T") -> 8 | AK29: 3
A30: Travis D | B30: W | C30: 66 | D30: W | E30: 48 | F30: W | G30: 56 | H30: L | I30: 38 | J30: L | K30: 20 | L30: L | M30: 10 | N30: W | O30: 44 | P30: =SUM(C30 + E30 + G30 + I30 + K30 + M30 + O30) -> 282 | Q30: =2*countif(B30:O30,"W")+countif(B30:O30,"T") -> 8 | R30: 3 | T30: Rohan B | U30: W | V30: 80 | W30: W | X30: 58 | Y30: W | Z30: 70 | AA30: W | AB30: 62 | AC30: W | AD30: 44 | AE30: W | AF30: 42 | AG30: W | AH30: 52 | AI30: =SUM(V30 + X30 + Z30 + AB30 + AD30 + AF30 + AH30) -> 408 | AJ30: =2*countif(U30:AH30,"W")+countif(U30:AH30,"T") -> 14 | AK30: 1
A31: Isaiah S | B31: W | C31: 54 | D31: W | E31: 46 | F31: L | G31: 36 | H31: W | I31: 46 | J31: L | K31: 36 | L31: L | M31: 16 | N31: L | O31: 24 | P31: =SUM(C31 + E31 + G31 + I31 + K31 + M31 + O31) -> 258 | Q31: =2*countif(B31:O31,"W")+countif(B31:O31,"T") -> 6 | R31: 5 | T31: Joey L | U31: W | V31: 50 | W31: W | X31: 56 | Y31: L | Z31: 26 | AA31: W | AB31: 42 | AC31: L | AD31: 0 | AE31: L | AF31: 30 | AG31: L | AH31: 24 | AI31: =SUM(V31 + X31 + Z31 + AB31 + AD31 + AF31 + AH31) -> 228 | AJ31: =2*countif(U31:AH31,"W")+countif(U31:AH31,"T") -> 6 | AK31: 5
A32: Taran J | B32: L | C32: 12 | D32: L | E32: 12 | F32: L | G32: 16 | H32: L | I32: 10 | J32: L | K32: 12 | L32: L | M32: 12 | N32: L | O32: 12 | P32: =SUM(C32 + E32 + G32 + I32 + K32 + M32 + O32) -> 86 | Q32: =2*countif(B32:O32,"W")+countif(B32:O32,"T") -> 0 | R32: 8 | T32: Gautam G | U32: L | V32: 8 | W32: L | X32: 4 | Y32: L | Z32: 28 | AA32: L | AB32: 8 | AC32: T | AD32: 22 | AE32: T | AF32: 28 | AG32: L | AH32: 0 | AI32: =SUM(V32 + X32 + Z32 + AB32 + AD32 + AF32 + AH32) -> 98 | AJ32: =2*countif(U32:AH32,"W")+countif(U32:AH32,"T") -> 2 | AK32: 8
A33: Kian D | B33: L | C33: 30 | D33: L | E33: 14 | F33: W | G33: 38 | H33: W | I33: 32 | J33: L | K33: 18 | L33: W | M33: 38 | N33: L | O33: 14 | P33: =SUM(C33 + E33 + G33 + I33 + K33 + M33 + O33) -> 184 | Q33: =2*countif(B33:O33,"W")+countif(B33:O33,"T") -> 6 | R33: 6 | T33: Darius S | U33: W | V33: 54 | W33: L | X33: 8 | Y33: W | Z33: 34 | AA33: W | AB33: 44 | AC33: L | AD33: 30 | AE33: W | AF33: 50 | AG33: L | AH33: 18 | AI33: =SUM(V33 + X33 + Z33 + AB33 + AD33 + AF33 + AH33) -> 238 | AJ33: =2*countif(U33:AH33,"W")+countif(U33:AH33,"T") -> 8 | AK33: 4
A34: Abhiraam G | B34: L | C34: 40 | D34: L | E34: 26 | F34: W | G34: 32 | H34: L | I34: 18 | J34: W | K34: 32 | L34: W | M34: 38 | N34: W | O34: 48 | P34: =SUM(C34 + E34 + G34 + I34 + K34 + M34 + O34) -> 234 | Q34: =2*countif(B34:O34,"W")+countif(B34:O34,"T") -> 8 | R34: 4 | T34: Daniel J | U34: L | V34: 22 | W34: L | X34: 16 | Y34: W | Z34: 30 | AA34: L | AB34: 30 | AC34: W | AD34: 34 | AE34: L | AF34: 10 | AG34: L | AH34: 10 | AI34: =SUM(V34 + X34 + Z34 + AB34 + AD34 + AF34 + AH34) -> 152 | AJ34: =2*countif(U34:AH34,"W")+countif(U34:AH34,"T") -> 4 | AK34: 7

Sheet RR Schedule (Novice)
A1: RR Schedule (Novice) | U1: Discord
A2: RR 1: 7/20-7/22 RR 2: 7/23-7/25 RR 3: 7/26-7/28 RR 4: 7/29-7/31 RR 5: 8/1-8/3 RR 6: 8/4-8/6 RR 7: 8/7-8/9 | U2: Name | V2: Username
U3: Catherine D | V3: eco_5
A4: Albite (7) | K4: Anorthite (8) | U4: Caroline H | V4: coconut102
B5: Catherine D | C5: Caroline H | D5: Mihin B | E5: Timothy Y | F5: Mila H | G5: Maneesh G | H5: Jabez Z | I5: Jack W | L5: Chris W | M5: Sarabhesh S | N5: Shannon I | O5: Monish S | P5: Achuth V | Q5: Dennis J | R5: Nathaniel O | S5: Sriman D | U5: Mihin B | V5: vexaddict_52655
A6: Catherine D | C6: 7/20-7/22 | D6: 7/23-7/25 | E6: 7/26-7/28 | F6: 7/29-7/31 | G6: 8/1-8/3 | H6: 8/4-8/6 | I6: 8/7-8/9 | K6: Chris W | M6: 7/20-7/22 | N6: 7/23-7/25 | O6: 7/26-7/28 | P6: 7/29-7/31 | Q6: 8/1-8/3 | R6: 8/4-8/6 | S6: 8/7-8/9 | U6: Timothy Y | V6: timmy.yu.123
A7: Caroline H | B7: 7/20-7/22 | D7: 7/26-7/28 | E7: 7/29-7/31 | F7: 8/1-8/3 | G7: 8/4-8/6 | H7: 8/7-8/9 | I7: 7/23-7/25 | K7: Sarabhesh S | L7: 7/20-7/22 | N7: 7/26-7/28 | O7: 7/29-7/31 | P7: 8/1-8/3 | Q7: 8/4-8/6 | R7: 8/7-8/9 | S7: 7/23-7/25 | U7: Mila H | V7: mila.n.pusheen
A8: Mihin B | B8: 7/23-7/25 | C8: 7/26-7/28 | E8: 8/1-8/3 | F8: 8/4-8/6 | G8: 8/7-8/9 | H8: 7/20-7/22 | I8: 7/29-7/31 | K8: Shannon I | L8: 7/23-7/25 | M8: 7/26-7/28 | O8: 8/1-8/3 | P8: 8/4-8/6 | Q8: 8/7-8/9 | R8: 7/20-7/22 | S8: 7/29-7/31 | U8: Maneesh G | V8: Voidless_psycho
A9: Timothy Y | B9: 7/26-7/28 | C9: 7/29-7/31 | D9: 8/1-8/3 | F9: 8/7-8/9 | G9: 7/20-7/22 | H9: 7/23-7/25 | I9: 8/4-8/6 | K9: Monish S | L9: 7/26-7/28 | M9: 7/29-7/31 | N9: 8/1-8/3 | P9: 8/7-8/9 | Q9: 7/20-7/22 | R9: 7/23-7/25 | S9: 8/4-8/6 | U9: Jabez Z | V9: ukraine7776
A10: Mila H | B10: 7/29-7/31 | C10: 8/1-8/3 | D10: 8/4-8/6 | E10: 8/7-8/9 | G10: 7/23-7/25 | H10: 7/26-7/28 | I10: 7/20-7/22 | K10: Achuth V | L10: 7/29-7/31 | M10: 8/1-8/3 | N10: 8/4-8/6 | O10: 8/7-8/9 | Q10: 7/23-7/25 | R10: 7/26-7/28 | S10: 7/20-7/22 | U10: Jack W | V10: COPPERCEREAL
A11: Maneesh G | B11: 8/1-8/3 | C11: 8/4-8/6 | D11: 8/7-8/9 | E11: 7/20-7/22 | F11: 7/23-7/25 | H11: 7/29-7/31 | I11: 7/26-7/28 | K11: Dennis J | L11: 8/1-8/3 | M11: 8/4-8/6 | N11: 8/7-8/9 | O11: 7/20-7/22 | P11: 7/23-7/25 | R11: 7/29-7/31 | S11: 7/26-7/28 | U11: Chris W | V11: .orca.whale.
A12: Jabez Z | B12: 8/4-8/6 | C12: 8/7-8/9 | D12: 7/20-7/22 | E12: 7/23-7/25 | F12: 7/26-7/28 | G12: 7/29-7/31 | I12: 8/1-8/3 | K12: Nathaniel O | L12: 8/4-8/6 | M12: 8/7-8/9 | N12: 7/20-7/22 | O12: 7/23-7/25 | P12: 7/26-7/28 | Q12: 7/29-7/31 | S12: 8/1-8/3 | U12: Sarabhesh S | V12: karasuno0766
A13: Jack W | B13: 8/7-8/9 | C13: 7/23-7/25 | D13: 7/29-7/31 | E13: 8/4-8/6 | F13: 7/20-7/22 | G13: 7/26-7/28 | H13: 8/1-8/3 | K13: Sriman D | L13: 8/7-8/9 | M13: 7/23-7/25 | N13: 7/29-7/31 | O13: 8/4-8/6 | P13: 7/20-7/22 | Q13: 7/26-7/28 | R13: 8/1-8/3 | U13: Shannon I | V13: shamp0
U14: Monish S | V14: KINGRel
U15: Achuth V | V15: Giannis
U16: Dennis J | V16: sellmeperson
U17: Nathaniel O | V17: alkalint
U18: Sriman D | V18: Sr¡m@η!

Sheet RR Schedule (Adv)
A1: RR Schedule (Advanced) | U1: Discord
A2: RR 1: 7/20-7/22 RR 2: 7/23-7/25 RR 3: 7/26-7/28 RR 4: 7/29-7/31 RR 5: 8/1-8/3 RR 6: 8/4-8/6 RR 7: 8/7-8/9 | U2: Name | V2: Username
U3: Peter B | V3: thecryolite
A4: Almandine (1) | K4: Andradite (2) | U4: Jason Y | V4: bdcl
B5: Peter B | C5: Jason Y | D5: Akhil B | E5: Edwin H | F5: Praneel A | G5: Shreehan P | H5: Shubam V | I5: Azim F | L5: Alex Z | M5: Kevin F | N5: Kensuke O | O5: Ishaan K | P5: Birdie L | Q5: Shashank V | R5: Adam N | S5: Nimit A | U5: Akhil B | V5: abat48
A6: Peter B | C6: 7/20-7/22 | D6: 7/23-7/25 | E6: 7/26-7/28 | F6: 7/29-7/31 | G6: 8/1-8/3 | H6: 8/4-8/6 | I6: 8/7-8/9 | K6: Alex Z | M6: 7/20-7/22 | N6: 7/23-7/25 | O6: 7/26-7/28 | P6: 7/29-7/31 | Q6: 8/1-8/3 | R6: 8/4-8/6 | S6: 8/7-8/9 | U6: Edwin H | V6: draoethar
A7: Jason Y | B7: 7/20-7/22 | D7: 7/26-7/28 | E7: 7/29-7/31 | F7: 8/1-8/3 | G7: 8/4-8/6 | H7: 8/7-8/9 | I7: 7/23-7/25 | K7: Kevin F | L7: 7/20-7/22 | N7: 7/26-7/28 | O7: 7/29-7/31 | P7: 8/1-8/3 | Q7: 8/4-8/6 | R7: 8/7-8/9 | S7: 7/23-7/25 | U7: Praneel A | V7: GRB5128
A8: Akhil B | B8: 7/23-7/25 | C8: 7/26-7/28 | E8: 8/1-8/3 | F8: 8/4-8/6 | G8: 8/7-8/9 | H8: 7/20-7/22 | I8: 7/29-7/31 | K8: Kensuke O | L8: 7/23-7/25 | M8: 7/26-7/28 | O8: 8/1-8/3 | P8: 8/4-8/6 | Q8: 8/7-8/9 | R8: 7/20-7/22 | S8: 7/29-7/31 | U8: Shreehan P | V8: TheHyades
A9: Edwin H | B9: 7/26-7/28 | C9: 7/29-7/31 | D9: 8/1-8/3 | F9: 8/7-8/9 | G9: 7/20-7/22 | H9: 7/23-7/25 | I9: 8/4-8/6 | K9: Ishaan K | L9: 7/26-7/28 | M9: 7/29-7/31 | N9: 8/1-8/3 | P9: 8/7-8/9 | Q9: 7/20-7/22 | R9: 7/23-7/25 | S9: 8/4-8/6 | U9: Shubam V | V9: The Shubaminator
A10: Praneel A | B10: 7/29-7/31 | C10: 8/1-8/3 | D10: 8/4-8/6 | E10: 8/7-8/9 | G10: 7/23-7/25 | H10: 7/26-7/28 | I10: 7/20-7/22 | K10: Birdie L | L10: 7/29-7/31 | M10: 8/1-8/3 | N10: 8/4-8/6 | O10: 8/7-8/9 | Q10: 7/23-7/25 | R10: 7/26-7/28 | S10: 7/20-7/22 | U10: Azim F | V10: memyselfandi22
A11: Shreehan P | B11: 8/1-8/3 | C11: 8/4-8/6 | D11: 8/7-8/9 | E11: 7/20-7/22 | F11: 7/23-7/25 | H11: 7/29-7/31 | I11: 7/26-7/28 | K11: Shashank V | L11: 8/1-8/3 | M11: 8/4-8/6 | N11: 8/7-8/9 | O11: 7/20-7/22 | P11: 7/23-7/25 | R11: 7/29-7/31 | S11: 7/26-7/28 | U11: Alex Z | V11: shaulaz
A12: Shubam V | B12: 8/4-8/6 | C12: 8/7-8/9 | D12: 7/20-7/22 | E12: 7/23-7/25 | F12: 7/26-7/28 | G12: 7/29-7/31 | I12: 8/1-8/3 | K12: Adam N | L12: 8/4-8/6 | M12: 8/7-8/9 | N12: 7/20-7/22 | O12: 7/23-7/25 | P12: 7/26-7/28 | Q12: 7/29-7/31 | S12: 8/1-8/3 | U12: Kevin F | V12: alpha_zom
A13: Azim F | B13: 8/7-8/9 | C13: 7/23-7/25 | D13: 7/29-7/31 | E13: 8/4-8/6 | F13: 7/20-7/22 | G13: 7/26-7/28 | H13: 8/1-8/3 | K13: Nimit A | L13: 8/7-8/9 | M13: 7/23-7/25 | N13: 7/29-7/31 | O13: 8/4-8/6 | P13: 7/20-7/22 | Q13: 7/26-7/28 | R13: 8/1-8/3 | U13: Kensuke O | V13: 3neks
U14: Ishaan K | V14: hellcat4024
A15: Pyrope (3) | K15: Grossular (4) | U15: Birdie L | V15: vorixx9850
B16: Ziang Z | C16: Shaleen B | D16: Advai S | E16: Varyan J | F16: Mary P | G16: Daniel Y | H16: Arnav H | I16: Akshay R | L16: Bryce T | M16: Jack G | N16: Shreyas E | O16: Baljeet C | P16: Alex L | Q16: Sudhanva B | R16: Luyao Y | S16: Andrew F | U16: Shashank V | V16: labrador1te
A17: Ziang Z | C17: 7/20-7/22 | D17: 7/23-7/25 | E17: 7/26-7/28 | F17: 7/29-7/31 | G17: 8/1-8/3 | H17: 8/4-8/6 | I17: 8/7-8/9 | K17: Bryce T | M17: 7/20-7/22 | N17: 7/23-7/25 | O17: 7/26-7/28 | P17: 7/29-7/31 | Q17: 8/1-8/3 | R17: 8/4-8/6 | S17: 8/7-8/9 | U17: Adam N | V17: coffeesmile1117
A18: Shaleen B | B18: 7/20-7/22 | D18: 7/26-7/28 | E18: 7/29-7/31 | F18: 8/1-8/3 | G18: 8/4-8/6 | H18: 8/7-8/9 | I18: 7/23-7/25 | K18: Jack G | L18: 7/20-7/22 | N18: 7/26-7/28 | O18: 7/29-7/31 | P18: 8/1-8/3 | Q18: 8/4-8/6 | R18: 8/7-8/9 | S18: 7/23-7/25 | U18: Nimit A | V18: nimit_agrawal_17406
A19: Advai S | B19: 7/23-7/25 | C19: 7/26-7/28 | E19: 8/1-8/3 | F19: 8/4-8/6 | G19: 8/7-8/9 | H19: 7/20-7/22 | I19: 7/29-7/31 | K19: Shreyas E | L19: 7/23-7/25 | M19: 7/26-7/28 | O19: 8/1-8/3 | P19: 8/4-8/6 | Q19: 8/7-8/9 | R19: 7/20-7/22 | S19: 7/29-7/31 | U19: Ziang Z | V19: deasert_willow
A20: Varyan J | B20: 7/26-7/28 | C20: 7/29-7/31 | D20: 8/1-8/3 | F20: 8/7-8/9 | G20: 7/20-7/22 | H20: 7/23-7/25 | I20: 8/4-8/6 | K20: Baljeet C | L20: 7/26-7/28 | M20: 7/29-7/31 | N20: 8/1-8/3 | P20: 8/7-8/9 | Q20: 7/20-7/22 | R20: 7/23-7/25 | S20: 8/4-8/6 | U20: Shaleen B | V20: groundbreaker36
A21: Mary P | B21: 7/29-7/31 | C21: 8/1-8/3 | D21: 8/4-8/6 | E21: 8/7-8/9 | G21: 7/23-7/25 | H21: 7/26-7/28 | I21: 7/20-7/22 | K21: Alex L | L21: 7/29-7/31 | M21: 8/1-8/3 | N21: 8/4-8/6 | O21: 8/7-8/9 | Q21: 7/23-7/25 | R21: 7/26-7/28 | S21: 7/20-7/22 | U21: Advai S | V21: Dwaii
A22: Daniel Y | B22: 8/1-8/3 | C22: 8/4-8/6 | D22: 8/7-8/9 | E22: 7/20-7/22 | F22: 7/23-7/25 | H22: 7/29-7/31 | I22: 7/26-7/28 | K22: Sudhanva B | L22: 8/1-8/3 | M22: 8/4-8/6 | N22: 8/7-8/9 | O22: 7/20-7/22 | P22: 7/23-7/25 | R22: 7/29-7/31 | S22: 7/26-7/28 | U22: Varyan J | V22: varnite
A23: Arnav H | B23: 8/4-8/6 | C23: 8/7-8/9 | D23: 7/20-7/22 | E23: 7/23-7/25 | F23: 7/26-7/28 | G23: 7/29-7/31 | I23: 8/1-8/3 | K23: Luyao Y | L23: 8/4-8/6 | M23: 8/7-8/9 | N23: 7/20-7/22 | O23: 7/23-7/25 | P23: 7/26-7/28 | Q23: 7/29-7/31 | S23: 8/1-8/3 | U23: Mary P | V23: mareeeena
A24: Akshay R | B24: 8/7-8/9 | C24: 7/23-7/25 | D24: 7/29-7/31 | E24: 8/4-8/6 | F24: 7/20-7/22 | G24: 7/26-7/28 | H24: 8/1-8/3 | K24: Andrew F | L24: 8/7-8/9 | M24: 7/23-7/25 | N24: 7/29-7/31 | O24: 8/4-8/6 | P24: 7/20-7/22 | Q24: 7/26-7/28 | R24: 8/1-8/3 | U24: Daniel Y | V24: caravan._.
U25: Arnav H | V25: supernova2011
A26: Spessartine (5) | K26: Uvarovite (6) | U26: Akshay R | V26: ajrspeculator_30045
B27: Aastik B | C27: Camille P | D27: Suzuko O | E27: Travis D | F27: Isaiah S | G27: Taran J | H27: Kian D | I27: Abhiraam G | L27: Henry L | M27: Ian C | N27: Ryan E | O27: Rohan B | P27: Joey L | Q27: Gautam G | R27: Darius S | S27: Daniel J | U27: Bryce T | V27: _en2k
A28: Aastik B | C28: 7/20-7/22 | D28: 7/23-7/25 | E28: 7/26-7/28 | F28: 7/29-7/31 | G28: 8/1-8/3 | H28: 8/4-8/6 | I28: 8/7-8/9 | K28: Henry L | M28: 7/20-7/22 | N28: 7/23-7/25 | O28: 7/26-7/28 | P28: 7/29-7/31 | Q28: 8/1-8/3 | R28: 8/4-8/6 | S28: 8/7-8/9 | U28: Jack G | V28: actuallyadumbperson
A29: Camille P | B29: 7/20-7/22 | D29: 7/26-7/28 | E29: 7/29-7/31 | F29: 8/1-8/3 | G29: 8/4-8/6 | H29: 8/7-8/9 | I29: 7/23-7/25 | K29: Ian C | L29: 7/20-7/22 | N29: 7/26-7/28 | O29: 7/29-7/31 | P29: 8/1-8/3 | Q29: 8/4-8/6 | R29: 8/7-8/9 | S29: 7/23-7/25 | U29: Shreyas E | V29: shreyase39
A30: Suzuko O | B30: 7/23-7/25 | C30: 7/26-7/28 | E30: 8/1-8/3 | F30: 8/4-8/6 | G30: 8/7-8/9 | H30: 7/20-7/22 | I30: 7/29-7/31 | K30: Ryan E | L30: 7/23-7/25 | M30: 7/26-7/28 | O30: 8/1-8/3 | P30: 8/4-8/6 | Q30: 8/7-8/9 | R30: 7/20-7/22 | S30: 7/29-7/31 | U30: Baljeet C | V30: baljeetoff
A31: Travis D | B31: 7/26-7/28 | C31: 7/29-7/31 | D31: 8/1-8/3 | F31: 8/7-8/9 | G31: 7/20-7/22 | H31: 7/23-7/25 | I31: 8/4-8/6 | K31: Rohan B | L31: 7/26-7/28 | M31: 7/29-7/31 | N31: 8/1-8/3 | P31: 8/7-8/9 | Q31: 7/20-7/22 | R31: 7/23-7/25 | S31: 8/4-8/6 | U31: Alex L | V31: abacus14
A32: Isaiah S | B32: 7/29-7/31 | C32: 8/1-8/3 | D32: 8/4-8/6 | E32: 8/7-8/9 | G32: 7/23-7/25 | H32: 7/26-7/28 | I32: 7/20-7/22 | K32: Joey L | L32: 7/29-7/31 | M32: 8/1-8/3 | N32: 8/4-8/6 | O32: 8/7-8/9 | Q32: 7/23-7/25 | R32: 7/26-7/28 | S32: 7/20-7/22 | U32: Sudhanva B | V32: sudbelur
A33: Taran J | B33: 8/1-8/3 | C33: 8/4-8/6 | D33: 8/7-8/9 | E33: 7/20-7/22 | F33: 7/23-7/25 | H33: 7/29-7/31 | I33: 7/26-7/28 | K33: Gautam G | L33: 8/1-8/3 | M33: 8/4-8/6 | N33: 8/7-8/9 | O33: 7/20-7/22 | P33: 7/23-7/25 | R33: 7/29-7/31 | S33: 7/26-7/28 | U33: Luyao Y | V33: optil
A34: Kian D | B34: 8/4-8/6 | C34: 8/7-8/9 | D34: 7/20-7/22 | E34: 7/23-7/25 | F34: 7/26-7/28 | G34: 7/29-7/31 | I34: 8/1-8/3 | K34: Darius S | L34: 8/4-8/6 | M34: 8/7-8/9 | N34: 7/20-7/22 | O34: 7/23-7/25 | P34: 7/26-7/28 | Q34: 7/29-7/31 | S34: 8/1-8/3 | U34: Andrew F | V34: Spahgooti
A35: Abhiraam G | B35: 8/7-8/9 | C35: 7/23-7/25 | D35: 7/29-7/31 | E35: 8/4-8/6 | F35: 7/20-7/22 | G35: 7/26-7/28 | H35: 8/1-8/3 | K35: Daniel J | L35: 8/7-8/9 | M35: 7/23-7/25 | N35: 7/29-7/31 | O35: 8/4-8/6 | P35: 7/20-7/22 | Q35: 7/26-7/28 | R35: 8/1-8/3 | U35: Aastik B | V35: thepleiadess.
U36: Camille P | V36: sio2.cgp
U37: Suzuko O | V37: so.what.if.
U38: Travis D | V38: Travis_842
U39: Isaiah S | V39: iaaiahfishy
U40: Taran J | V40: taran0737
...

Sheet SE Bracket (Alt)
B1: SE Bracket
A2: 2024 Earth and Space Scrimmage | B2: SE1: Time | F2: SE2: Time | J2: SE3: Time | N2: SE4: Time
B4: 1 | C4: Player | D4: Pts
C5: Player | D5: Pts
F6: 9 | G6: Player | H6: Pts
G7: Player | H7: Pts
B8: 2 | C8: Player | D8: Pts
C9: Player | D9: Pts
J10: 13 | K10: Player | L10: Pts
K11: Player | L11: Pts
B12: 3 | C12: Player | D12: Pts
C13: Player | D13: Pts
F14: 10 | G14: Player | H14: Pts
G15: Player | H15: Pts
B16: 4 | C16: Player | D16: Pts
C17: Player | D17: Pts
N18: 15 | O18: Player | P18: Pts
O19: Player | P19: Pts
B20: 5 | C20: Player | D20: Pts
C21: Player | D21: Pts
F22: 11 | G22: Player | H22: Pts
G23: Player | H23: Pts
B24: 6 | C24: Player | D24: Pts
C25: Player | D25: Pts
J26: 14 | K26: Player | L26: Pts
K27: Player | L27: Pts
B28: 7 | C28: Player | D28: Pts
C29: Player | D29: Pts
F30: 12 | G30: Player | H30: Pts
G31: Player | H31: Pts
B32: 8 | C32: Player | D32: Pts
C33: Player | D33: Pts

Sheet RR Crosstables (Novice)
A1: RR Crosstables (Novice)
A3: Albite | K3: Anorthite
B4: Catherine D | C4: Caroline H | D4: Mihin B | E4: Timothy Y | F4: Mila H | G4: Maneesh G | H4: Jabez Z | I4: Jack W | L4: Chris W | M4: Sarabhesh S | N4: Shannon I | O4: Monish S | P4: Achuth V | Q4: Dennis J | R4: Nathaniel O | S4: Sriman D
A5: Catherine D | B5: {=IF('RR Schedule (Novice)'!B6="","",LET(nm,'RR Results (Novice)'!$A:$A,g,'RR Results (Novice)'!$B:$O,n,MATCH('RR Schedule (Novice)'!B6,{"7/20-7/22";"7/23-7/25";"7/26-7/28";"7/29-7/31";"8/1-8/3";"8/4-8/6";"8/7-8/9"},0),me,MATCH($A5,nm,0),IF(COUNT(INDEX(g,me,2*n))=1,INDEX(g,me,2*n),"")))} | C5: {=IF('RR Schedule (Novice)'!C6="","",LET(nm,'RR Results (Novice)'!$A:$A,g,'RR Results (Novice)'!$B:$O,n,MATCH('RR Schedule (Novice)'!C6,{"7/20-7/22";"7/23-7/25";"7/26-7/28";"7/29-7/31";"8/1-8/3";"8/4-8/6";"8/7-8/9"},0),me,MATCH($A5,nm,0),IF(COUNT(INDEX(g,me,2*n))=1,INDEX(g,me,2*n),"")))} -> 28 | D5: {=IF('RR Schedule (Novice)'!D6="","",LET(nm,'RR Results (Novice)'!$A:$A,g,'RR Results (Novice)'!$B:$O,n,MATCH('RR Schedule (Novice)'!D6,{"7/20-7/22";"7/23-7/25";"7/26-7/28";"7/29-7/31";"8/1-8/3";"8/4-8/6";"8/7-8/9"},0),me,MATCH($A5,nm,0),IF(COUNT(INDEX(g,me,2*n))=1,INDEX(g,me,2*n),"")))} -> 10 | E5: {=IF('RR Schedule (Novice)'!E6="","",LET(nm,'RR Results (Novice)'!$A:$A,g,'RR Results (Novice)'!$B:$O,n,MATCH('RR Schedule (Novice)'!E6,{"7/20-7/22";"7/23-7/25";"7/26-7/28";"7/29-7/31";"8/1-8/3";"8/4-8/6";"8/7-8/9"},0),me,MATCH($A5,nm,0),IF(COUNT(INDEX(g,me,2*n))=1,INDEX(g,me,2*n),"")))} -> 28 | F5: {=IF('RR Schedule (Novice)'!F6="","",LET(nm,'RR Results (Novice)'!$A:$A,g,'RR Results (Novice)'!$B:$O,n,MATCH('RR Schedule (Novice)'!F6,{"7/20-7/22";"7/23-7/25";"7/26-7/28";"7/29-7/31";"8/1-8/3";"8/4-8/6";"8/7-8/9"},0),me,MATCH($A5,nm,0),IF(COUNT(INDEX(g,me,2*n))=1,INDEX(g,me,2*n),"")))} -> 36 | G5: {=IF('RR Schedule (Novice)'!G6="","",LET(nm,'RR Results (Novice)'!$A:$A,g,'RR Results (Novice)'!$B:$O,n,MATCH('RR Schedule (Novice)'!G6,{"7/20-7/22";"7/23-7/25";"7/26-7/28";"7/29-7/31";"8/1-8/3";"8/4-8/6";"8/7-8/9"},0),me,MATCH($A5,nm,0),IF(COUNT(INDEX(g,me,2*n))=1,INDEX(g,me,2*n),"")))} -> 62 | H5: {=IF('RR Schedule (Novice)'!H6="","",LET(nm,'RR Results (Novice)'!$A:$A,g,'RR Results (Novice)'!$B:$O,n,MATCH('RR Schedule (Novice)'!H6,{"7/20-7/22";"7/23-7/25";"7/26-7/28";"7/29-7/31";"8/1-8/3";"8/4-8/6";"8/7-8/9"},0),me,MATCH($A5,nm,0),IF(COUNT(INDEX(g,me,2*n))=1,INDEX(g,me,2*n),"")))} -> 26 | I5: {=IF('RR Schedule (Novice)'!I6="","",LET(nm,'RR Results (Novice)'!$A:$A,g,'RR Results (Novice)'!$B:$O,n,MATCH('RR Schedule (Novice)'!I6,{"7/20-7/22";"7/23-7/25";"7/26-7/28";"7/29-7/31";"8/1-8/3";"8/4-8/6";"8/7-8/9"},0),me,MATCH($A5,nm,0),IF(COUNT(INDEX(g,me,2*n))=1,INDEX(g,me,2*n),"")))} -> 28 | K5: Chris W | L5: {=IF('RR Schedule (Novice)'!L6="","",LET(nm,'RR Results (Novice)'!$T:$T,g,'RR Results (Novice)'!$U:$AH,n,MATCH('RR Schedule (Novice)'!L6,{"7/20-7/22";"7/23-7/25";"7/26-7/28";"7/29-7/31";"8/1-8/3";"8/4-8/6";"8/7-8/9"},0),me,MATCH($K5,nm,0),IF(COUNT(INDEX(g,me,2*n))=1,INDEX(g,me,2*n),"")))} | M5: {=IF('RR Schedule (Novice)'!M6="","",LET(nm,'RR Results (Novice)'!$T:$T,g,'RR Results (Novice)'!$U:$AH,n,MATCH('RR Schedule (Novice)'!M6,{"7/20-7/22";"7/23-7/25";"7/26-7/28";"7/29-7/31";"8/1-8/3";"8/4-8/6";"8/7-8/9"},0),me,MATCH($K5,nm,0),IF(COUNT(INDEX(g,me,2*n))=1,INDEX(g,me,2*n),"")))} -> -2 | N5: {=IF('RR Schedule (Novice)'!N6="","",LET(nm,'RR Results (Novice)'!$T:$T,g,'RR Results (Novice)'!$U:$AH,n,MATCH('RR Schedule (Novice)'!N6,{"7/20-7/22";"7/23-7/25";"7/26-7/28";"7/29-7/31";"8/1-8/3";"8/4-8/6";"8/7-8/9"},0),me,MATCH($K5,nm,0),IF(COUNT(INDEX(g,me,2*n))=1,INDEX(g,me,2*n),"")))} -> 0 | O5: {=IF('RR Schedule (Novice)'!O6="","",LET(nm,'RR Results (Novice)'!$T:$T,g,'RR Results (Novice)'!$U:$AH,n,MATCH('RR Schedule (Novice)'!O6,{"7/20-7/22";"7/23-7/25";"7/26-7/28";"7/29-7/31";"8/1-8/3";"8/4-8/6";"8/7-8/9"},0),me,MATCH($K5,nm,0),IF(COUNT(INDEX(g,me,2*n))=1,INDEX(g,me,2*n),"")))} -> 24 | P5: {=IF('RR Schedule (Novice)'!P6="","",LET(nm,'RR Results (Novice)'!$T:$T,g,'RR Results (Novice)'!$U:$AH,n,MATCH('RR Schedule (Novice)'!P6,{"7/20-7/22";"7/23-7/25";"7/26-7/28";"7/29-7/31";"8/1-8/3";"8/4-8/6";"8/7-8/9"},0),me,MATCH($K5,nm,0),IF(COUNT(INDEX(g,me,2*n))=1,INDEX(g,me,2*n),"")))} -> 2 | Q5: {=IF('RR Schedule (Novice)'!Q6="","",LET(nm,'RR Results (Novice)'!$T:$T,g,'RR Results (Novice)'!$U:$AH,n,MATCH('RR Schedule (Novice)'!Q6,{"7/20-7/22";"7/23-7/25";"7/26-7/28";"7/29-7/31";"8/1-8/3";"8/4-8/6";"8/7-8/9"},0),me,MATCH($K5,nm,0),IF(COUNT(INDEX(g,me,2*n))=1,INDEX(g,me,2*n),"")))} -> 40 | R5: {=IF('RR Schedule (Novice)'!R6="","",LET(nm,'RR Results (Novice)'!$T:$T,g,'RR Results (Novice)'!$U:$AH,n,MATCH('RR Schedule (Novice)'!R6,{"7/20-7/22";"7/23-7/25";"7/26-7/28";"7/29-7/31";"8/1-8/3";"8/4-8/6";"8/7-8/9"},0),me,MATCH($K5,nm,0),IF(COUNT(INDEX(g,me,2*n))=1,INDEX(g,me,2*n),"")))} -> 34 | S5: {=IF('RR Schedule (Novice)'!S6="","",LET(nm,'RR Results (Novice)'!$T:$T,g,'RR Results (Novice)'!$U:$AH,n,MATCH('RR Schedule (Novice)'!S6,{"7/20-7/22";"7/23-7/25";"7/26-7/28";"7/29-7/31";"8/1-8/3";"8/4-8/6";"8/7-8/9"},0),me,MATCH($K5,nm,0),IF(COUNT(INDEX(g,me,2*n))=1,INDEX(g,me,2*n),"")))} -> 22
A6: Caroline H | B6: {=IF('RR Schedule (Novice)'!B7="","",LET(nm,'RR Results (Novice)'!$A:$A,g,'RR Results (Novice)'!$B:$O,n,MATCH('RR Schedule (Novice)'!B7,{"7/20-7/22";"7/23-7/25";"7/26-7/28";"7/29-7/31";"8/1-8/3";"8/4-8/6";"8/7-8/9"},0),me,MATCH($A6,nm,0),IF(COUNT(INDEX(g,me,2*n))=1,INDEX(g,me,2*n),"")))} -> 28 | C6: {=IF('RR Schedule (Novice)'!C7="","",LET(nm,'RR Results (Novice)'!$A:$A,g,'RR Results (Novice)'!$B:$O,n,MATCH('RR Schedule (Novice)'!C7,{"7/20-7/22";"7/23-7/25";"7/26-7/28";"7/29-7/31";"8/1-8/3";"8/4-8/6";"8/7-8/9"},0),me,MATCH($A6,nm,0),IF(COUNT(INDEX(g,me,2*n))=1,INDEX(g,me,2*n),"")))} | D6: {=IF('RR Schedule (Novice)'!D7="","",LET(nm,'RR Results (Novice)'!$A:$A,g,'RR Results (Novice)'!$B:$O,n,MATCH('RR Schedule (Novice)'!D7,{"7/20-7/22";"7/23-7/25";"7/26-7/28";"7/29-7/31";"8/1-8/3";"8/4-8/6";"8/7-8/9"},0),me,MATCH($A6,nm,0),IF(COUNT(INDEX(g,me,2*n))=1,INDEX(g,me,2*n),"")))} -> 8 | E6: {=IF('RR Schedule (Novice)'!E7="","",LET(nm,'RR Results (Novice)'!$A:$A,g,'RR Results (Novice)'!$B:$O,n,MATCH('RR Schedule (Novice)'!E7,{"7/20-7/22";"7/23-7/25";"7/26-7/28";"7/29-7/31";"8/1-8/3";"8/4-8/6";"8/7-8/9"},0),me,MATCH($A6,nm,0),IF(COUNT(INDEX(g,me,2*n))=1,INDEX(g,me,2*n),"")))} -> 8 | F6: {=IF('RR Schedule (Novice)'!F7="","",LET(nm,'RR Results (Novice)'!$A:$A,g,'RR Results (Novice)'!$B:$O,n,MATCH('RR Schedule (Novice)'!F7,{"7/20-7/22";"7/23-7/25";"7/26-7/28";"7/29-7/31";"8/1-8/3";"8/4-8/6";"8/7-8/9"},0),me,MATCH($A6,nm,0),IF(COUNT(INDEX(g,me,2*n))=1,INDEX(g,me,2*n),"")))} -> 34 | G6: {=IF('RR Schedule (Novice)'!G7="","",LET(nm,'RR Results (Novice)'!$A:$A,g,'RR Results (Novice)'!$B:$O,n,MATCH('RR Schedule (Novice)'!G7,{"7/20-7/22";"7/23-7/25";"7/26-7/28";"7/29-7/31";"8/1-8/3";"8/4-8/6";"8/7-8/9"},0),me,MATCH($A6,nm,0),IF(COUNT(INDEX(g,me,2*n))=1,INDEX(g,me,2*n),"")))} -> 18 | H6: {=IF('RR Schedule (Novice)'!H7="","",LET(nm,'RR Results (Novice)'!$A:$A,g,'RR Results (Novice)'!$B:$O,n,MATCH('RR Schedule (Novice)'!H7,{"7/20-7/22";"7/23-7/25";"7/26-7/28";"7/29-7/31";"8/1-8/3";"8/4-8/6";"8/7-8/9"},0),me,MATCH($A6,nm,0),IF(COUNT(INDEX(g,me,2*n))=1,INDEX(g,me,2*n),"")))} -> 22 | I6: {=IF('RR Schedule (Novice)'!I7="","",LET(nm,'RR Results (Novice)'!$A:$A,g,'RR Results (Novice)'!$B:$O,n,MATCH('RR Schedule (Novice)'!I7,{"7/20-7/22";"7/23-7/25";"7/26-7/28";"7/29-7/31";"8/1-8/3";"8/4-8/6";"8/7-8/9"},0),me,MATCH($A6,nm,0),IF(COUNT(INDEX(g,me,2*n))=1,INDEX(g,me,2*n),"")))} -> 18 | K6: Sarabhesh S | L6: {=IF('RR Schedule (Novice)'!L7="","",LET(nm,'RR Results (Novice)'!$T:$T,g,'RR Results (Novice)'!$U:$AH,n,MATCH('RR Schedule (Novice)'!L7,{"7/20-7/22";"7/23-7/25";"7/26-7/28";"7/29-7/31";"8/1-8/3";"8/4-8/6";"8/7-8/9"},0),me,MATCH($K6,nm,0),IF(COUNT(INDEX(g,me,2*n))=1,INDEX(g,me,2*n),"")))} -> 32 | M6: {=IF('RR Schedule (Novice)'!M7="","",LET(nm,'RR Results (Novice)'!$T:$T,g,'RR Results (Novice)'!$U:$AH,n,MATCH('RR Schedule (Novice)'!M7,{"7/20-7/22";"7/23-7/25";"7/26-7/28";"7/29-7/31";"8/1-8/3";"8/4-8/6";"8/7-8/9"},0),me,MATCH($K6,nm,0),IF(COUNT(INDEX(g,me,2*n))=1,INDEX(g,me,2*n),"")))} | N6: {=IF('RR Schedule (Novice)'!N7="","",LET(nm,'RR Results (Novice)'!$T:$T,g,'RR Results (Novice)'!$U:$AH,n,MATCH('RR Schedule (Novice)'!N7,{"7/20-7/22";"7/23-7/25";"7/26-7/28";"7/29-7/31";"8/1-8/3";"8/4-8/6";"8/7-8/9"},0),me,MATCH($K6,nm,0),IF(COUNT(INDEX(g,me,2*n))=1,INDEX(g,me,2*n),"")))} -> 6 | O6: {=IF('RR Schedule (Novice)'!O7="","",LET(nm,'RR Results (Novice)'!$T:$T,g,'RR Results (Novice)'!$U:$AH,n,MATCH('RR Schedule (Novice)'!O7,{"7/20-7/22";"7/23-7/25";"7/26-7/28";"7/29-7/31";"8/1-8/3";"8/4-8/6";"8/7-8/9"},0),me,MATCH($K6,nm,0),IF(COUNT(INDEX(g,me,2*n))=1,INDEX(g,me,2*n),"")))} -> 24 | P6: {=IF('RR Schedule (Novice)'!P7="","",LET(nm,'RR Results (Novice)'!$T:$T,g,'RR Results (Novice)'!$U:$AH,n,MATCH('RR Schedule (Novice)'!P7,{"7/20-7/22";"7/23-7/25";"7/26-7/28";"7/29-7/31";"8/1-8/3";"8/4-8/6";"8/7-8/9"},0),me,MATCH($K6,nm,0),IF(COUNT(INDEX(g,me,2*n))=1,INDEX(g,me,2*n),"")))} -> 14 | Q6: {=IF('RR Schedule (Novice)'!Q7="","",LET(nm,'RR Results (Novice)'!$T:$T,g,'RR Results (Novice)'!$U:$AH,n,MATCH('RR Schedule (Novice)'!Q7,{"7/20-7/22";"7/23-7/25";"7/26-7/28";"7/29-7/31";"8/1-8/3";"8/4-8/6";"8/7-8/9"},0),me,MATCH($K6,nm,0),IF(COUNT(INDEX(g,me,2*n))=1,INDEX(g,me,2*n),"")))} -> 18 | R6: {=IF('RR Schedule (Novice)'!R7="","",LET(nm,'RR Results (Novice)'!$T:$T,g,'RR Results (Novice)'!$U:$AH,n,MATCH('RR Schedule (Novice)'!R7,{"7/20-7/22";"7/23-7/25";"7/26-7/28";"7/29-7/31";"8/1-8/3";"8/4-8/6";"8/7-8/9"},0),me,MATCH($K6,nm,0),IF(COUNT(INDEX(g,me,2*n))=1,INDEX(g,me,2*n),"")))} -> 32 | S6: {=IF('RR Schedule (Novice)'!S7="","",LET(nm,'RR Results (Novice)'!$T:$T,g,'RR Results (Novice)'!$U:$AH,n,MATCH('RR Schedule (Novice)'!S7,{"7/20-7/22";"7/23-7/25";"7/26-7/28";"7/29-7/31";"8/1-8/3";"8/4-8/6";"8/7-8/9"},0),me,MATCH($K6,nm,0),IF(COUNT(INDEX(g,me,2*n))=1,INDEX(g,me,2*n),"")))} -> 16
A7: Mihin B | B7: {=IF('RR Schedule (Novice)'!B8="","",LET(nm,'RR Results (Novice)'!$A:$A,g,'RR Results (Novice)'!$B:$O,n,MATCH('RR Schedule (Novice)'!B8,{"7/20-7/22";"7/23-7/25";"7/26-7/28";"7/29-7/31";"8/1-8/3";"8/4-8/6";"8/7-8/9"},0),me,MATCH($A7,nm,0),IF(COUNT(INDEX(g,me,2*n))=1,INDEX(g,me,2*n),"")))} -> 68 | C7: {=IF('RR Schedule (Novice)'!C8="","",LET(nm,'RR Results (Novice)'!$A:$A,g,'RR Results (Novice)'!$B:$O,n,MATCH('RR Schedule (Novice)'!C8,{"7/20-7/22";"7/23-7/25";"7/26-7/28";"7/29-7/31";"8/1-8/3";"8/4-8/6";"8/7-8/9"},0),me,MATCH($A7,nm,0),IF(COUNT(INDEX(g,me,2*n))=1,INDEX(g,me,2*n),"")))} -> 78 | D7: {=IF('RR Schedule (Novice)'!D8="","",LET(nm,'RR Results (Novice)'!$A:$A,g,'RR Results (Novice)'!$B:$O,n,MATCH('RR Schedule (Novice)'!D8,{"7/20-7/22";"7/23-7/25";"7/26-7/28";"7/29-7/31";"8/1-8/3";"8/4-8/6";"8/7-8/9"},0),me,MATCH($A7,nm,0),IF(COUNT(INDEX(g,me,2*n))=1,INDEX(g,me,2*n),"")))} | E7: {=IF('RR Schedule (Novice)'!E8="","",LET(nm,'RR Results (Novice)'!$A:$A,g,'RR Results (Novice)'!$B:$O,n,MATCH('RR Schedule (Novice)'!E8,{"7/20-7/22";"7/23-7/25";"7/26-7/28";"7/29-7/31";"8/1-8/3";"8/4-8/6";"8/7-8/9"},0),me,MATCH($A7,nm,0),IF(COUNT(INDEX(g,me,2*n))=1,INDEX(g,me,2*n),"")))} -> 60 | F7: {=IF('RR Schedule (Novice)'!F8="","",LET(nm,'RR Results (Novice)'!$A:$A,g,'RR Results (Novice)'!$B:$O,n,MATCH('RR Schedule (Novice)'!F8,{"7/20-7/22";"7/23-7/25";"7/26-7/28";"7/29-7/31";"8/1-8/3";"8/4-8/6";"8/7-8/9"},0),me,MATCH($A7,nm,0),IF(COUNT(INDEX(g,me,2*n))=1,INDEX(g,me,2*n),"")))} -> 86 | G7: {=IF('RR Schedule (Novice)'!G8="","",LET(nm,'RR Results (Novice)'!$A:$A,g,'RR Results (Novice)'!$B:$O,n,MATCH('RR Schedule (Novice)'!G8,{"7/20-7/22";"7/23-7/25";"7/26-7/28";"7/29-7/31";"8/1-8/3";"8/4-8/6";"8/7-8/9"},0),me,MATCH($A7,nm,0),IF(COUNT(INDEX(g,me,2*n))=1,INDEX(g,me,2*n),"")))} -> 56 | H7: {=IF('RR Schedule (Novice)'!H8="","",LET(nm,'RR Results (Novice)'!$A:$A,g,'RR Results (Novice)'!$B:$O,n,MATCH('RR Schedule (Novice)'!H8,{"7/20-7/22";"7/23-7/25";"7/26-7/28";"7/29-7/31";"8/1-8/3";"8/4-8/6";"8/7-8/9"},0),me,MATCH($A7,nm,0),IF(COUNT(INDEX(g,me,2*n))=1,INDEX(g,me,2*n),"")))} -> 66 | I7: {=IF('RR Schedule (Novice)'!I8="","",LET(nm,'RR Results (Novice)'!$A:$A,g,'RR Results (Novice)'!$B:$O,n,MATCH('RR Schedule (Novice)'!I8,{"7/20-7/22";"7/23-7/25";"7/26-7/28";"7/29-7/31";"8/1-8/3";"8/4-8/6";"8/7-8/9"},0),me,MATCH($A7,nm,0),IF(COUNT(INDEX(g,me,2*n))=1,INDEX(g,me,2*n),"")))} -> 48 | K7: Shannon I | L7: {=IF('RR Schedule (Novice)'!L8="","",LET(nm,'RR Results (Novice)'!$T:$T,g,'RR Results (Novice)'!$U:$AH,n,MATCH('RR Schedule (Novice)'!L8,{"7/20-7/22";"7/23-7/25";"7/26-7/28";"7/29-7/31";"8/1-8/3";"8/4-8/6";"8/7-8/9"},0),me,MATCH($K7,nm,0),IF(COUNT(INDEX(g,me,2*n))=1,INDEX(g,me,2*n),"")))} -> 62 | M7: {=IF('RR Schedule (Novice)'!M8="","",LET(nm,'RR Results (Novice)'!$T:$T,g,'RR Results (Novice)'!$U:$AH,n,MATCH('RR Schedule (Novice)'!M8,{"7/20-7/22";"7/23-7/25";"7/26-7/28";"7/29-7/31";"8/1-8/3";"8/4-8/6";"8/7-8/9"},0),me,MATCH($K7,nm,0),IF(COUNT(INDEX(g,me,2*n))=1,INDEX(g,me,2*n),"")))} -> 54 | N7: {=IF('RR Schedule (Novice)'!N8="","",LET(nm,'RR Results (Novice)'!$T:$T,g,'RR Results (Novice)'!$U:$AH,n,MATCH('RR Schedule (Novice)'!N8,{"7/20-7/22";"7/23-7/25";"7/26-7/28";"7/29-7/31";"8/1-8/3";"8/4-8/6";"8/7-8/9"},0),me,MATCH($K7,nm,0),IF(COUNT(INDEX(g,me,2*n))=1,INDEX(g,me,2*n),"")))} | O7: {=IF('RR Schedule (Novice)'!O8="","",LET(nm,'RR Results (Novice)'!$T:$T,g,'RR Results (Novice)'!$U:$AH,n,MATCH('RR Schedule (Novice)'!O8,{"7/20-7/22";"7/23-7/25";"7/26-7/28";"7/29-7/31";"8/1-8/3";"8/4-8/6";"8/7-8/9"},0),me,MATCH($K7,nm,0),IF(COUNT(INDEX(g,me,2*n))=1,INDEX(g,me,2*n),"")))} -> 30 | P7: {=IF('RR Schedule (Novice)'!P8="","",LET(nm,'RR Results (Novice)'!$T:$T,g,'RR Results (Novice)'!$U:$AH,n,MATCH('RR Schedule (Novice)'!P8,{"7/20-7/22";"7/23-7/25";"7/26-7/28";"7/29-7/31";"8/1-8/3";"8/4-8/6";"8/7-8/9"},0),me,MATCH($K7,nm,0),IF(COUNT(INDEX(g,me,2*n))=1,INDEX(g,me,2*n),"")))} -> 46 | Q7: {=IF('RR Schedule (Novice)'!Q8="","",LET(nm,'RR Results (Novice)'!$T:$T,g,'RR Results (Novice)'!$U:$AH,n,MATCH('RR Schedule (Novice)'!Q8,{"7/20-7/22";"7/23-7/25";"7/26-7/28";"7/29-7/31";"8/1-8/3";"8/4-8/6";"8/7-8/9"},0),me,MATCH($K7,nm,0),IF(COUNT(INDEX(g,me,2*n))=1,INDEX(g,me,2*n),"")))} -> 44 | R7: {=IF('RR Schedule (Novice)'!R8="","",LET(nm,'RR Results (Novice)'!$T:$T,g,'RR Results (Novice)'!$U:$AH,n,MATCH('RR Schedule (Novice)'!R8,{"7/20-7/22";"7/23-7/25";"7/26-7/28";"7/29-7/31";"8/1-8/3";"8/4-8/6";"8/7-8/9"},0),me,MATCH($K7,nm,0),IF(COUNT(INDEX(g,me,2*n))=1,INDEX(g,me,2*n),"")))} -> 46 | S7: {=IF('RR Schedule (Novice)'!S8="","",LET(nm,'RR Results (Novice)'!$T:$T,g,'RR Results (Novice)'!$U:$AH,n,MATCH('RR Schedule (Novice)'!S8,{"7/20-7/22";"7/23-7/25";"7/26-7/28";"7/29-7/31";"8/1-8/3";"8/4-8/6";"8/7-8/9"},0),me,MATCH($K7,nm,0),IF(COUNT(INDEX(g,me,2*n))=1,INDEX(g,me,2*n),"")))} -> 58
A8: Timothy Y | B8: {=IF('RR Schedule (Novice)'!B9="","",LET(nm,'RR Results (Novice)'!$A:$A,g,'RR Results (Novice)'!$B:$O,n,MATCH('RR Schedule (Novice)'!B9,{"7/20-7/22";"7/23-7/25";"7/26-7/28";"7/29-7/31";"8/1-8/3";"8/4-8/6";"8/7-8/9"},0),me,MATCH($A8,nm,0),IF(COUNT(INDEX(g,me,2*n))=1,INDEX(g,me,2*n),"")))} -> 34 | C8: {=IF('RR Schedule (Novice)'!C9="","",LET(nm,'RR Results (Novice)'!$A:$A,g,'RR Results (Novice)'!$B:$O,n,MATCH('RR Schedule (Novice)'!C9,{"7/20-7/22";"7/23-7/25";"7/26-7/28";"7/29-7/31";"8/1-8/3";"8/4-8/6";"8/7-8/9"},0),me,MATCH($A8,nm,0),IF(COUNT(INDEX(g,me,2*n))=1,INDEX(g,me,2*n),"")))} -> 52 | D8: {=IF('RR Schedule (Novice)'!D9="","",LET(nm,'RR Results (Novice)'!$A:$A,g,'RR Results (Novice)'!$B:$O,n,MATCH('RR Schedule (Novice)'!D9,{"7/20-7/22";"7/23-7/25";"7/26-7/28";"7/29-7/31";"8/1-8/3";"8/4-8/6";"8/7-8/9"},0),me,MATCH($A8,nm,0),IF(COUNT(INDEX(g,me,2*n))=1,INDEX(g,me,2*n),"")))} -> 24 | E8: {=IF('RR Schedule (Novice)'!E9="","",LET(nm,'RR Results (Novice)'!$A:$A,g,'RR Results (Novice)'!$B:$O,n,MATCH('RR Schedule (Novice)'!E9,{"7/20-7/22";"7/23-7/25";"7/26-7/28";"7/29-7/31";"8/1-8/3";"8/4-8/6";"8/7-8/9"},0),me,MATCH($A8,nm,0),IF(COUNT(INDEX(g,me,2*n))=1,INDEX(g,me,2*n),"")))} | F8: {=IF('RR Schedule (Novice)'!F9="","",LET(nm,'RR Results (Novice)'!$A:$A,g,'RR Results (Novice)'!$B:$O,n,MATCH('RR Schedule (Novice)'!F9,{"7/20-7/22";"7/23-7/25";"7/26-7/28";"7/29-7/31";"8/1-8/3";"8/4-8/6";"8/7-8/9"},0),me,MATCH($A8,nm,0),IF(COUNT(INDEX(g,me,2*n))=1,INDEX(g,me,2*n),"")))} -> 8 | G8: {=IF('RR Schedule (Novice)'!G9="","",LET(nm,'RR Results (Novice)'!$A:$A,g,'RR Results (Novice)'!$B:$O,n,MATCH('RR Schedule (Novice)'!G9,{"7/20-7/22";"7/23-7/25";"7/26-7/28";"7/29-7/31";"8/1-8/3";"8/4-8/6";"8/7-8/9"},0),me,MATCH($A8,nm,0),IF(COUNT(INDEX(g,me,2*n))=1,INDEX(g,me,2*n),"")))} -> 50 | H8: {=IF('RR Schedule (Novice)'!H9="","",LET(nm,'RR Results (Novice)'!$A:$A,g,'RR Results (Novice)'!$B:$O,n,MATCH('RR Schedule (Novice)'!H9,{"7/20-7/22";"7/23-7/25";"7/26-7/28";"7/29-7/31";"8/1-8/3";"8/4-8/6";"8/7-8/9"},0),me,MATCH($A8,nm,0),IF(COUNT(INDEX(g,me,2*n))=1,INDEX(g,me,2*n),"")))} -> 52 | I8: {=IF('RR Schedule (Novice)'!I9="","",LET(nm,'RR Results (Novice)'!$A:$A,g,'RR Results (Novice)'!$B:$O,n,MATCH('RR Schedule (Novice)'!I9,{"7/20-7/22";"7/23-7/25";"7/26-7/28";"7/29-7/31";"8/1-8/3";"8/4-8/6";"8/7-8/9"},0),me,MATCH($A8,nm,0),IF(COUNT(INDEX(g,me,2*n))=1,INDEX(g,me,2*n),"")))} -> 26 | K8: Monish S | L8: {=IF('RR Schedule (Novice)'!L9="","",LET(nm,'RR Results (Novice)'!$T:$T,g,'RR Results (Novice)'!$U:$AH,n,MATCH('RR Schedule (Novice)'!L9,{"7/20-7/22";"7/23-7/25";"7/26-7/28";"7/29-7/31";"8/1-8/3";"8/4-8/6";"8/7-8/9"},0),me,MATCH($K8,nm,0),IF(COUNT(INDEX(g,me,2*n))=1,INDEX(g,me,2*n),"")))} -> 40 | M8: {=IF('RR Schedule (Novice)'!M9="","",LET(nm,'RR Results (Novice)'!$T:$T,g,'RR Results (Novice)'!$U:$AH,n,MATCH('RR Schedule (Novice)'!M9,{"7/20-7/22";"7/23-7/25";"7/26-7/28";"7/29-7/31";"8/1-8/3";"8/4-8/6";"8/7-8/9"},0),me,MATCH($K8,nm,0),IF(COUNT(INDEX(g,me,2*n))=1,INDEX(g,me,2*n),"")))} -> 8 | N8: {=IF('RR Schedule (Novice)'!N9="","",LET(nm,'RR Results (Novice)'!$T:$T,g,'RR Results (Novice)'!$U:$AH,n,MATCH('RR Schedule (Novice)'!N9,{"7/20-7/22";"7/23-7/25";"7/26-7/28";"7/29-7/31";"8/1-8/3";"8/4-8/6";"8/7-8/9"},0),me,MATCH($K8,nm,0),IF(COUNT(INDEX(g,me,2*n))=1,INDEX(g,me,2*n),"")))} -> 46 | O8: {=IF('RR Schedule (Novice)'!O9="","",LET(nm,'RR Results (Novice)'!$T:$T,g,'RR Results (Novice)'!$U:$AH,n,MATCH('RR Schedule (Novice)'!O9,{"7/20-7/22";"7/23-7/25";"7/26-7/28";"7/29-7/31";"8/1-8/3";"8/4-8/6";"8/7-8/9"},0),me,MATCH($K8,nm,0),IF(COUNT(INDEX(g,me,2*n))=1,INDEX(g,me,2*n),"")))} | P8: {=IF('RR Schedule (Novice)'!P9="","",LET(nm,'RR Results (Novice)'!$T:$T,g,'RR Results (Novice)'!$U:$AH,n,MATCH('RR Schedule (Novice)'!P9,{"7/20-7/22";"7/23-7/25";"7/26-7/28";"7/29-7/31";"8/1-8/3";"8/4-8/6";"8/7-8/9"},0),me,MATCH($K8,nm,0),IF(COUNT(INDEX(g,me,2*n))=1,INDEX(g,me,2*n),"")))} -> 0 | Q8: {=IF('RR Schedule (Novice)'!Q9="","",LET(nm,'RR Results (Novice)'!$T:$T,g,'RR Results (Novice)'!$U:$AH,n,MATCH('RR Schedule (Novice)'!Q9,{"7/20-7/22";"7/23-7/25";"7/26-7/28";"7/29-7/31";"8/1-8/3";"8/4-8/6";"8/7-8/9"},0),me,MATCH($K8,nm,0),IF(COUNT(INDEX(g,me,2*n))=1,INDEX(g,me,2*n),"")))} -> 6 | R8: {=IF('RR Schedule (Novice)'!R9="","",LET(nm,'RR Results (Novice)'!$T:$T,g,'RR Results (Novice)'!$U:$AH,n,MATCH('RR Schedule (Novice)'!R9,{"7/20-7/22";"7/23-7/25";"7/26-7/28";"7/29-7/31";"8/1-8/3";"8/4-8/6";"8/7-8/9"},0),me,MATCH($K8,nm,0),IF(COUNT(INDEX(g,me,2*n))=1,INDEX(g,me,2*n),"")))} -> 12 | S8: {=IF('RR Schedule (Novice)'!S9="","",LET(nm,'RR Results (Novice)'!$T:$T,g,'RR Results (Novice)'!$U:$AH,n,MATCH('RR Schedule (Novice)'!S9,{"7/20-7/22";"7/23-7/25";"7/26-7/28";"7/29-7/31";"8/1-8/3";"8/4-8/6";"8/7-8/9"},0),me,MATCH($K8,nm,0),IF(COUNT(INDEX(g,me,2*n))=1,INDEX(g,me,2*n),"")))} -> 8
