Workbook

Sheet Games
A1: id | B1: roundNum | C1: roomId | D1: teamAId | E1: teamBId | F1: scoreA | G1: scoreB | H1: createdAt | I1: updatedAt
A2: 177 | B2: 1 | C2: 32 | D2: 11 | E2: 15 | F2: 136 | G2: 138 | H2: 2023-02-04 16:34:16.205+00 | I2: 2023-02-04 16:34:16.205+00
A3: 178 | B3: 1 | C3: 27 | D3: 18 | E3: 39 | F3: 18 | G3: 198 | H3: 2023-02-04 16:36:04.378+00 | I3: 2023-02-04 16:36:04.378+00
A4: 179 | B4: 1 | C4: 33 | D4: 25 | E4: 37 | F4: 212 | G4: 26 | H4: 2023-02-04 16:36:36.508+00 | I4: 2023-02-04 16:36:36.508+00
A5: 180 | B5: 1 | C5: 29 | D5: 12 | E5: 19 | F5: 178 | G5: 8 | H5: 2023-02-04 16:37:50.262+00 | I5: 2023-02-04 16:37:50.262+00
A6: 181 | B6: 1 | C6: 15 | D6: 29 | E6: 33 | F6: 122 | G6: 0 | H6: 2023-02-04 16:38:46.155+00 | I6: 2023-02-04 16:38:46.155+00
A7: 182 | B7: 1 | C7: 14 | D7: 7 | E7: 22 | F7: 74 | G7: 170 | H7: 2023-02-04 16:39:05.959+00 | I7: 2023-02-04 16:39:05.959+00
A8: 183 | B8: 1 | C8: 30 | D8: 38 | E8: 40 | F8: 178 | G8: 44 | H8: 2023-02-04 16:39:24.079+00 | I8: 2023-02-04 16:39:24.079+00
A9: 184 | B9: 1 | C9: 17 | D9: 2 | E9: 20 | F9: 56 | G9: 178 | H9: 2023-02-04 16:40:04.772+00 | I9: 2023-02-04 16:40:04.772+00
A10: 185 | B10: 1 | C10: 24 | D10: 23 | E10: 36 | F10: 122 | G10: 144 | H10: 2023-02-04 16:41:35.5+00 | I10: 2023-02-04 16:41:35.5+00
A11: 186 | B11: 1 | C11: 20 | D11: 4 | E11: 5 | F11: 82 | G11: 118 | H11: 2023-02-04 16:41:59.346+00 | I11: 2023-02-04 16:41:59.346+00
A12: 187 | B12: 1 | C12: 23 | D12: 1 | E12: 14 | F12: 170 | G12: 76 | H12: 2023-02-04 16:42:07.498+00 | I12: 2023-02-04 16:42:07.498+00
A13: 188 | B13: 1 | C13: 21 | D13: 24 | E13: 41 | F13: 174 | G13: 34 | H13: 2023-02-04 16:43:34.844+00 | I13: 2023-02-04 16:43:34.844+00
... A292: 467 | B292: 15 | C292: 11 | D292: 65 | E292: 84 | F292: 118 | G292: 72 | H292: 2023-02-06 06:34:34.435+00 | I292: 2023-02-06 06:34:34.435+00

Sheet Raw
A1: id | B1: gameRecordId | C1: score | D1: whoBuzzedGID | E1: teamId | F1: Team | G1: isTeamA | H1: isEmpty | I1: questionNum | J1: Cat
A2: 123001 | B2: 177 | C2: 0 | E2: 11 | F2: =vlookup(E2,Teams!$A:B,2,false) -> Fossil Ridge | G2: TRUE | H2: TRUE | I2: 1 | J2: =vlookup(I2,Cats!$A:$B,2,false) -> X
A3: 123002 | B3: 177 | C3: 14 | D3: 105742581620835495719 | E3: 15 | F3: =vlookup(E3,Teams!$A:B,2,false) -> Interlake D | G3: FALSE | H3: FALSE | I3: 1 | J3: =vlookup(I3,Cats!$A:$B,2,false) -> X
A4: 123003 | B4: 177 | C4: 0 | E4: 11 | F4: =vlookup(E4,Teams!$A:B,2,false) -> Fossil Ridge | G4: TRUE | H4: TRUE | I4: 2 | J4: =vlookup(I4,Cats!$A:$B,2,false) -> M
A5: 123004 | B5: 177 | C5: 14 | D5: 103474733858251827147 | E5: 15 | F5: =vlookup(E5,Teams!$A:B,2,false) -> Interlake D | G5: FALSE | H5: FALSE | I5: 2 | J5: =vlookup(I5,Cats!$A:$B,2,false) -> M
A6: 123005 | B6: 177 | C6: 0 | E6: 11 | F6: =vlookup(E6,Teams!$A:B,2,false) -> Fossil Ridge | G6: TRUE | H6: TRUE | I6: 3 | J6: =vlookup(I6,Cats!$A:$B,2,false) -> C
A7: 123006 | B7: 177 | C7: 14 | D7: 103474733858251827147 | E7: 15 | F7: =vlookup(E7,Teams!$A:B,2,false) -> Interlake D | G7: FALSE | H7: FALSE | I7: 3 | J7: =vlookup(I7,Cats!$A:$B,2,false) -> C
A8: 123007 | B8: 177 | C8: -4 | D8: 104156773302712156449 | E8: 11 | F8: =vlookup(E8,Teams!$A:B,2,false) -> Fossil Ridge | G8: TRUE | H8: FALSE | I8: 4 | J8: =vlookup(I8,Cats!$A:$B,2,false) -> E
A9: 123008 | B9: 177 | C9: 14 | D9: 105742581620835495719 | E9: 15 | F9: =vlookup(E9,Teams!$A:B,2,false) -> Interlake D | G9: FALSE | H9: FALSE | I9: 4 | J9: =vlookup(I9,Cats!$A:$B,2,false) -> E
A10: 123009 | B10: 177 | C10: 14 | D10: 102086610308437271448 | E10: 11 | F10: =vlookup(E10,Teams!$A:B,2,false) -> Fossil Ridge | G10: TRUE | H10: FALSE | I10: 5 | J10: =vlookup(I10,Cats!$A:$B,2,false) -> B
A11: 123010 | B11: 177 | C11: -4 | D11: 111177114471781468507 | E11: 15 | F11: =vlookup(E11,Teams!$A:B,2,false) -> Interlake D | G11: FALSE | H11: FALSE | I11: 5 | J11: =vlookup(I11,Cats!$A:$B,2,false) -> B
A12: 123011 | B12: 177 | C12: 4 | D12: 114069392661778914056 | E12: 11 | F12: =vlookup(E12,Teams!$A:B,2,false) -> Fossil Ridge | G12: TRUE | H12: FALSE | I12: 6 | J12: =vlookup(I12,Cats!$A:$B,2,false) -> P
A13: 123012 | B13: 177 | C13: -4 | D13: 110297046011568433830 | E13: 15 | F13: =vlookup(E13,Teams!$A:B,2,false) -> Interlake D | G13: FALSE | H13: FALSE | I13: 6 | J13: =vlookup(I13,Cats!$A:$B,2,false) -> P
A14: 123013 | B14: 177 | C14: 14 | D14: 102086610308437271448 | E14: 11 | F14: =vlookup(E14,Teams!$A:B,2,false) -> Fossil Ridge | G14: TRUE | H14: FALSE | I14: 7 | J14: =vlookup(I14,Cats!$A:$B,2,false) -> X
A15: 123014 | B15: 177 | C15: 0 | E15: 15 | F15: =vlookup(E15,Teams!$A:B,2,false) -> Interlake D | G15: FALSE | H15: TRUE | I15: 7 | J15: =vlookup(I15,Cats!$A:$B,2,false) -> X
A16: 123015 | B16: 177 | C16: 14 | D16: 102086610308437271448 | E16: 11 | F16: =vlookup(E16,Teams!$A:B,2,false) -> Fossil Ridge | G16: TRUE | H16: FALSE | I16: 8 | J16: =vlookup(I16,Cats!$A:$B,2,false) -> M
A17: 123016 | B17: 177 | C17: 0 | E17: 15 | F17: =vlookup(E17,Teams!$A:B,2,false) -> Interlake D | G17: FALSE | H17: TRUE | I17: 8 | J17: =vlookup(I17,Cats!$A:$B,2,false) -> M
A18: 123017 | B18: 177 | C18: 0 | E18: 11 | F18: =vlookup(E18,Teams!$A:B,2,false) -> Fossil Ridge | G18: TRUE | H18: TRUE | I18: 9 | J18: =vlookup(I18,Cats!$A:$B,2,false) -> C
A19: 123018 | B19: 177 | C19: 14 | D19: 103474733858251827147 | E19: 15 | F19: =vlookup(E19,Teams!$A:B,2,false) -> Interlake D | G19: FALSE | H19: FALSE | I19: 9 | J19: =vlookup(I19,Cats!$A:$B,2,false) -> C
A20: 123019 | B20: 177 | C20: 0 | E20: 11 | F20: =vlookup(E20,Teams!$A:B,2,false) -> Fossil Ridge | G20: TRUE | H20: TRUE | I20: 10 | J20: =vlookup(I20,Cats!$A:$B,2,false) -> E
A21: 123020 | B21: 177 | C21: 4 | D21: 105742581620835495719 | E21: 15 | F21: =vlookup(E21,Teams!$A:B,2,false) -> Interlake D | G21: FALSE | H21: FALSE | I21: 10 | J21: =vlookup(I21,Cats!$A:$B,2,false) -> E
A22: 123021 | B22: 177 | C22: 4 | D22: 104156773302712156449 | E22: 11 | F22: =vlookup(E22,Teams!$A:B,2,false) -> Fossil Ridge | G22: TRUE | H22: FALSE | I22: 11 | J22: =vlookup(I22,Cats!$A:$B,2,false) -> B
A23: 123022 | B23: 177 | C23: 0 | E23: 15 | F23: =vlookup(E23,Teams!$A:B,2,false) -> Interlake D | G23: FALSE | H23: TRUE | I23: 11 | J23: =vlookup(I23,Cats!$A:$B,2,false) -> B
A24: 123023 | B24: 177 | C24: 0 | E24: 11 | F24: =vlookup(E24,Teams!$A:B,2,false) -> Fossil Ridge | G24: TRUE | H24: TRUE | I24: 12 | J24: =vlookup(I24,Cats!$A:$B,2,false) -> P
A25: 123024 | B25: 177 | C25: 4 | D25: 103474733858251827147 | E25: 15 | F25: =vlookup(E25,Teams!$A:B,2,false) -> Interlake D | G25: FALSE | H25: FALSE | I25: 12 | J25: =vlookup(I25,Cats!$A:$B,2,false) -> P
A26: 123025 | B26: 177 | C26: 0 | E26: 11 | F26: =vlookup(E26,Teams!$A:B,2,false) -> Fossil Ridge | G26: TRUE | H26: TRUE | I26: 13 | J26: =vlookup(I26,Cats!$A:$B,2,false) -> X
A27: 123026 | B27: 177 | C27: 14 | D27: 105742581620835495719 | E27: 15 | F27: =vlookup(E27,Teams!$A:B,2,false) -> Interlake D | G27: FALSE | H27: FALSE | I27: 13 | J27: =vlookup(I27,Cats!$A:$B,2,false) -> X
A28: 123027 | B28: 177 | C28: 14 | D28: 102086610308437271448 | E28: 11 | F28: =vlookup(E28,Teams!$A:B,2,false) -> Fossil Ridge | G28: TRUE | H28: FALSE | I28: 14 | J28: =vlookup(I28,Cats!$A:$B,2,false) -> M
A29: 123028 | B29: 177 | C29: 0 | E29: 15 | F29: =vlookup(E29,Teams!$A:B,2,false) -> Interlake D | G29: FALSE | H29: TRUE | I29: 14 | J29: =vlookup(I29,Cats!$A:$B,2,false) -> M
A30: 123029 | B30: 177 | C30: 0 | D30: 102086610308437271448 | E30: 11 | F30: =vlookup(E30,Teams!$A:B,2,false) -> Fossil Ridge | G30: TRUE | H30: FALSE | I30: 15 | J30: =vlookup(I30,Cats!$A:$B,2,false) -> C
A31: 123030 | B31: 177 | C31: 0 | D31: 103474733858251827147 | E31: 15 | F31: =vlookup(E31,Teams!$A:B,2,false) -> Interlake D | G31: FALSE | H31: FALSE | I31: 15 | J31: =vlookup(I31,Cats!$A:$B,2,false) -> C
A32: 123031 | B32: 177 | C32: 0 | E32: 11 | F32: =vlookup(E32,Teams!$A:B,2,false) -> Fossil Ridge | G32: TRUE | H32: TRUE | I32: 16 | J32: =vlookup(I32,Cats!$A:$B,2,false) -> E
A33: 123032 | B33: 177 | C33: 14 | D33: 105742581620835495719 | E33: 15 | F33: =vlookup(E33,Teams!$A:B,2,false) -> Interlake D | G33: FALSE | H33: FALSE | I33: 16 | J33: =vlookup(I33,Cats!$A:$B,2,false) -> E
A34: 123033 | B34: 177 | C34: 0 | E34: 11 | F34: =vlookup(E34,Teams!$A:B,2,false) -> Fossil Ridge | G34: TRUE | H34: TRUE | I34: 17 | J34: =vlookup(I34,Cats!$A:$B,2,false) -> B
A35: 123034 | B35: 177 | C35: 14 | D35: 111177114471781468507 | E35: 15 | F35: =vlookup(E35,Teams!$A:B,2,false) -> Interlake D | G35: FALSE | H35: FALSE | I35: 17 | J35: =vlookup(I35,Cats!$A:$B,2,false) -> B
A36: 123035 | B36: 177 | C36: 14 | D36: 102086610308437271448 | E36: 11 | F36: =vlookup(E36,Teams!$A:B,2,false) -> Fossil Ridge | G36: TRUE | H36: FALSE | I36: 18 | J36: =vlookup(I36,Cats!$A:$B,2,false) -> P
A37: 123036 | B37: 177 | C37: 0 | E37: 15 | F37: =vlookup(E37,Teams!$A:B,2,false) -> Interlake D | G37: FALSE | H37: TRUE | I37: 18 | J37: =vlookup(I37,Cats!$A:$B,2,false) -> P
A38: 123037 | B38: 177 | C38: 0 | E38: 11 | F38: =vlookup(E38,Teams!$A:B,2,false) -> Fossil Ridge | G38: TRUE | H38: TRUE | I38: 19 | J38: =vlookup(I38,Cats!$A:$B,2,false) -> X
A39: 123038 | B39: 177 | C39: 14 | D39: 103474733858251827147 | E39: 15 | F39: =vlookup(E39,Teams!$A:B,2,false) -> Interlake D | G39: FALSE | H39: FALSE | I39: 19 | J39: =vlookup(I39,Cats!$A:$B,2,false) -> X
A40: 123039 | B40: 177 | C40: 14 | D40: 102086610308437271448 | E40: 11 | F40: =vlookup(E40,Teams!$A:B,2,false) -> Fossil Ridge | G40: TRUE | H40: FALSE | I40: 20 | J40: =vlookup(I40,Cats!$A:$B,2,false) -> M
...

Sheet PrelimRaw
A1: id | B1: gameRecordId | C1: Round | D1: score | E1: whoBuzzedGID | F1: teamId | G1: Team | H1: isTeamA | I1: isEmpty | J1: questionNum | K1: Cat
A2: 123001 | B2: 177 | C2: =vlookup(B2,Games!A:B,2,false) -> 1 | D2: 0 | F2: 11 | G2: =vlookup(F2,Teams!$A:B,2,false) -> Fossil Ridge | H2: TRUE | I2: TRUE | J2: 1 | K2: =vlookup(J2,Cats!$A:$B,2,false) -> X
A3: 123002 | B3: 177 | C3: =vlookup(B3,Games!A:B,2,false) -> 1 | D3: 14 | E3: 105742581620835495719 | F3: 15 | G3: =vlookup(F3,Teams!$A:B,2,false) -> Interlake D | H3: FALSE | I3: FALSE | J3: 1 | K3: =vlookup(J3,Cats!$A:$B,2,false) -> X
A4: 123003 | B4: 177 | C4: =vlookup(B4,Games!A:B,2,false) -> 1 | D4: 0 | F4: 11 | G4: =vlookup(F4,Teams!$A:B,2,false) -> Fossil Ridge | H4: TRUE | I4: TRUE | J4: 2 | K4: =vlookup(J4,Cats!$A:$B,2,false) -> M
A5: 123004 | B5: 177 | C5: =vlookup(B5,Games!A:B,2,false) -> 1 | D5: 14 | E5: 103474733858251827147 | F5: 15 | G5: =vlookup(F5,Teams!$A:B,2,false) -> Interlake D | H5: FALSE | I5: FALSE | J5: 2 | K5: =vlookup(J5,Cats!$A:$B,2,false) -> M
A6: 123005 | B6: 177 | C6: =vlookup(B6,Games!A:B,2,false) -> 1 | D6: 0 | F6: 11 | G6: =vlookup(F6,Teams!$A:B,2,false) -> Fossil Ridge | H6: TRUE | I6: TRUE | J6: 3 | K6: =vlookup(J6,Cats!$A:$B,2,false) -> C
A7: 123006 | B7: 177 | C7: =vlookup(B7,Games!A:B,2,false) -> 1 | D7: 14 | E7: 103474733858251827147 | F7: 15 | G7: =vlookup(F7,Teams!$A:B,2,false) -> Interlake D | H7: FALSE | I7: FALSE | J7: 3 | K7: =vlookup(J7,Cats!$A:$B,2,false) -> C
A8: 123007 | B8: 177 | C8: =vlookup(B8,Games!A:B,2,false) -> 1 | D8: -4 | E8: 104156773302712156449 | F8: 11 | G8: =vlookup(F8,Teams!$A:B,2,false) -> Fossil Ridge | H8: TRUE | I8: FALSE | J8: 4 | K8: =vlookup(J8,Cats!$A:$B,2,false) -> E
A9: 123008 | B9: 177 | C9: =vlookup(B9,Games!A:B,2,false) -> 1 | D9: 14 | E9: 105742581620835495719 | F9: 15 | G9: =vlookup(F9,Teams!$A:B,2,false) -> Interlake D | H9: FALSE | I9: FALSE | J9: 4 | K9: =vlookup(J9,Cats!$A:$B,2,false) -> E
A10: 123009 | B10: 177 | C10: =vlookup(B10,Games!A:B,2,false) -> 1 | D10: 14 | E10: 102086610308437271448 | F10: 11 | G10: =vlookup(F10,Teams!$A:B,2,false) -> Fossil Ridge | H10: TRUE | I10: FALSE | J10: 5 | K10: =vlookup(J10,Cats!$A:$B,2,false) -> B
A11: 123010 | B11: 177 | C11: =vlookup(B11,Games!A:B,2,false) -> 1 | D11: -4 | E11: 111177114471781468507 | F11: 15 | G11: =vlookup(F11,Teams!$A:B,2,false) -> Interlake D | H11: FALSE | I11: FALSE | J11: 5 | K11: =vlookup(J11,Cats!$A:$B,2,false) -> B
A12: 123011 | B12: 177 | C12: =vlookup(B12,Games!A:B,2,false) -> 1 | D12: 4 | E12: 114069392661778914056 | F12: 11 | G12: =vlookup(F12,Teams!$A:B,2,false) -> Fossil Ridge | H12: TRUE | I12: FALSE | J12: 6 | K12: =vlookup(J12,Cats!$A:$B,2,false) -> P
A13: 123012 | B13: 177 | C13: =vlookup(B13,Games!A:B,2,false) -> 1 | D13: -4 | E13: 110297046011568433830 | F13: 15 | G13: =vlookup(F13,Teams!$A:B,2,false) -> Interlake D | H13: FALSE | I13: FALSE | J13: 6 | K13: =vlookup(J13,Cats!$A:$B,2,false) -> P
A14: 123013 | B14: 177 | C14: =vlookup(B14,Games!A:B,2,false) -> 1 | D14: 14 | E14: 102086610308437271448 | F14: 11 | G14: =vlookup(F14,Teams!$A:B,2,false) -> Fossil Ridge | H14: TRUE | I14: FALSE | J14: 7 | K14: =vlookup(J14,Cats!$A:$B,2,false) -> X
A15: 123014 | B15: 177 | C15: =vlookup(B15,Games!A:B,2,false) -> 1 | D15: 0 | F15: 15 | G15: =vlookup(F15,Teams!$A:B,2,false) -> Interlake D | H15: FALSE | I15: TRUE | J15: 7 | K15: =vlookup(J15,Cats!$A:$B,2,false) -> X
A16: 123015 | B16: 177 | C16: =vlookup(B16,Games!A:B,2,false) -> 1 | D16: 14 | E16: 102086610308437271448 | F16: 11 | G16: =vlookup(F16,Teams!$A:B,2,false) -> Fossil Ridge | H16: TRUE | I16: FALSE | J16: 8 | K16: =vlookup(J16,Cats!$A:$B,2,false) -> M
A17: 123016 | B17: 177 | C17: =vlookup(B17,Games!A:B,2,false) -> 1 | D17: 0 | F17: 15 | G17: =vlookup(F17,Teams!$A:B,2,false) -> Interlake D | H17: FALSE | I17: TRUE | J17: 8 | K17: =vlookup(J17,Cats!$A:$B,2,false) -> M
A18: 123017 | B18: 177 | C18: =vlookup(B18,Games!A:B,2,false) -> 1 | D18: 0 | F18: 11 | G18: =vlookup(F18,Teams!$A:B,2,false) -> Fossil Ridge | H18: TRUE | I18: TRUE | J18: 9 | K18: =vlookup(J18,Cats!$A:$B,2,false) -> C
A19: 123018 | B19: 177 | C19: =vlookup(B19,Games!A:B,2,false) -> 1 | D19: 14 | E19: 103474733858251827147 | F19: 15 | G19: =vlookup(F19,Teams!$A:B,2,false) -> Interlake D | H19: FALSE | I19: FALSE | J19: 9 | K19: =vlookup(J19,Cats!$A:$B,2,false) -> C
A20: 123019 | B20: 177 | C20: =vlookup(B20,Games!A:B,2,false) -> 1 | D20: 0 | F20: 11 | G20: =vlookup(F20,Teams!$A:B,2,false) -> Fossil Ridge | H20: TRUE | I20: TRUE | J20: 10 | K20: =vlookup(J20,Cats!$A:$B,2,false) -> E
A21: 123020 | B21: 177 | C21: =vlookup(B21,Games!A:B,2,false) -> 1 | D21: 4 | E21: 105742581620835495719 | F21: 15 | G21: =vlookup(F21,Teams!$A:B,2,false) -> Interlake D | H21: FALSE | I21: FALSE | J21: 10 | K21: =vlookup(J21,Cats!$A:$B,2,false) -> E
A22: 123021 | B22: 177 | C22: =vlookup(B22,Games!A:B,2,false) -> 1 | D22: 4 | E22: 104156773302712156449 | F22: 11 | G22: =vlookup(F22,Teams!$A:B,2,false) -> Fossil Ridge | H22: TRUE | I22: FALSE | J22: 11 | K22: =vlookup(J22,Cats!$A:$B,2,false) -> B
A23: 123022 | B23: 177 | C23: =vlookup(B23,Games!A:B,2,false) -> 1 | D23: 0 | F23: 15 | G23: =vlookup(F23,Teams!$A:B,2,false) -> Interlake D | H23: FALSE | I23: TRUE | J23: 11 | K23: =vlookup(J23,Cats!$A:$B,2,false) -> B
A24: 123023 | B24: 177 | C24: =vlookup(B24,Games!A:B,2,false) -> 1 | D24: 0 | F24: 11 | G24: =vlookup(F24,Teams!$A:B,2,false) -> Fossil Ridge | H24: TRUE | I24: TRUE | J24: 12 | K24: =vlookup(J24,Cats!$A:$B,2,false) -> P
A25: 123024 | B25: 177 | C25: =vlookup(B25,Games!A:B,2,false) -> 1 | D25: 4 | E25: 103474733858251827147 | F25: 15 | G25: =vlookup(F25,Teams!$A:B,2,false) -> Interlake D | H25: FALSE | I25: FALSE | J25: 12 | K25: =vlookup(J25,Cats!$A:$B,2,false) -> P
A26: 123025 | B26: 177 | C26: =vlookup(B26,Games!A:B,2,false) -> 1 | D26: 0 | F26: 11 | G26: =vlookup(F26,Teams!$A:B,2,false) -> Fossil Ridge | H26: TRUE | I26: TRUE | J26: 13 | K26: =vlookup(J26,Cats!$A:$B,2,false) -> X
A27: 123026 | B27: 177 | C27: =vlookup(B27,Games!A:B,2,false) -> 1 | D27: 14 | E27: 105742581620835495719 | F27: 15 | G27: =vlookup(F27,Teams!$A:B,2,false) -> Interlake D | H27: FALSE | I27: FALSE | J27: 13 | K27: =vlookup(J27,Cats!$A:$B,2,false) -> X
A28: 123027 | B28: 177 | C28: =vlookup(B28,Games!A:B,2,false) -> 1 | D28: 14 | E28: 102086610308437271448 | F28: 11 | G28: =vlookup(F28,Teams!$A:B,2,false) -> Fossil Ridge | H28: TRUE | I28: FALSE | J28: 14 | K28: =vlookup(J28,Cats!$A:$B,2,false) -> M
A29: 123028 | B29: 177 | C29: =vlookup(B29,Games!A:B,2,false) -> 1 | D29: 0 | F29: 15 | G29: =vlookup(F29,Teams!$A:B,2,false) -> Interlake D | H29: FALSE | I29: TRUE | J29: 14 | K29: =vlookup(J29,Cats!$A:$B,2,false) -> M
A30: 123029 | B30: 177 | C30: =vlookup(B30,Games!A:B,2,false) -> 1 | D30: 0 | E30: 102086610308437271448 | F30: 11 | G30: =vlookup(F30,Teams!$A:B,2,false) -> Fossil Ridge | H30: TRUE | I30: FALSE | J30: 15 | K30: =vlookup(J30,Cats!$A:$B,2,false) -> C
A31: 123030 | B31: 177 | C31: =vlookup(B31,Games!A:B,2,false) -> 1 | D31: 0 | E31: 103474733858251827147 | F31: 15 | G31: =vlookup(F31,Teams!$A:B,2,false) -> Interlake D | H31: FALSE | I31: FALSE | J31: 15 | K31: =vlookup(J31,Cats!$A:$B,2,false) -> C
A32: 123031 | B32: 177 | C32: =vlookup(B32,Games!A:B,2,false) -> 1 | D32: 0 | F32: 11 | G32: =vlookup(F32,Teams!$A:B,2,false) -> Fossil Ridge | H32: TRUE | I32: TRUE | J32: 16 | K32: =vlookup(J32,Cats!$A:$B,2,false) -> E
A33: 123032 | B33: 177 | C33: =vlookup(B33,Games!A:B,2,false) -> 1 | D33: 14 | E33: 105742581620835495719 | F33: 15 | G33: =vlookup(F33,Teams!$A:B,2,false) -> Interlake D | H33: FALSE | I33: FALSE | J33: 16 | K33: =vlookup(J33,Cats!$A:$B,2,false) -> E
A34: 123033 | B34: 177 | C34: =vlookup(B34,Games!A:B,2,false) -> 1 | D34: 0 | F34: 11 | G34: =vlookup(F34,Teams!$A:B,2,false) -> Fossil Ridge | H34: TRUE | I34: TRUE | J34: 17 | K34: =vlookup(J34,Cats!$A:$B,2,false) -> B
A35: 123034 | B35: 177 | C35: =vlookup(B35,Games!A:B,2,false) -> 1 | D35: 14 | E35: 111177114471781468507 | F35: 15 | G35: =vlookup(F35,Teams!$A:B,2,false) -> Interlake D | H35: FALSE | I35: FALSE | J35: 17 | K35: =vlookup(J35,Cats!$A:$B,2,false) -> B
A36: 123035 | B36: 177 | C36: =vlookup(B36,Games!A:B,2,false) -> 1 | D36: 14 | E36: 102086610308437271448 | F36: 11 | G36: =vlookup(F36,Teams!$A:B,2,false) -> Fossil Ridge | H36: TRUE | I36: FALSE | J36: 18 | K36: =vlookup(J36,Cats!$A:$B,2,false) -> P
A37: 123036 | B37: 177 | C37: =vlookup(B37,Games!A:B,2,false) -> 1 | D37: 0 | F37: 15 | G37: =vlookup(F37,Teams!$A:B,2,false) -> Interlake D | H37: FALSE | I37: TRUE | J37: 18 | K37: =vlookup(J37,Cats!$A:$B,2,false) -> P
A38: 123037 | B38: 177 | C38: =vlookup(B38,Games!A:B,2,false) -> 1 | D38: 0 | F38: 11 | G38: =vlookup(F38,Teams!$A:B,2,false) -> Fossil Ridge | H38: TRUE | I38: TRUE | J38: 19 | K38: =vlookup(J38,Cats!$A:$B,2,false) -> X
A39: 123038 | B39: 177 | C39: =vlookup(B39,Games!A:B,2,false) -> 1 | D39: 14 | E39: 103474733858251827147 | F39: 15 | G39: =vlookup(F39,Teams!$A:B,2,false) -> Interlake D | H39: FALSE | I39: FALSE | J39: 19 | K39: =vlookup(J39,Cats!$A:$B,2,false) -> X
A40: 123039 | B40: 177 | C40: =vlookup(B40,Games!A:B,2,false) -> 1 | D40: 14 | E40: 102086610308437271448 | F40: 11 | G40: =vlookup(F40,Teams!$A:B,2,false) -> Fossil Ridge | H40: TRUE | I40: FALSE | J40: 20 | K40: =vlookup(J40,Cats!$A:$B,2,false) -> M
...

Sheet Cats
A1: 1 | B1: X
A2: 2 | B2: M
A3: 3 | B3: C
A4: 4 | B4: E
A5: 5 | B5: B
A6: 6 | B6: P
A7: 7 | B7: X
A8: 8 | B8: M
A9: 9 | B9: C
A10: 10 | B10: E
A11: 11 | B11: B
A12: 12 | B12: P
... A24: 24 | B24: P

Sheet Prelims
A1: ID | B1: Name | C1: Team | D1: GP | E1: TUH | F1: TU | G1: X | H1: Neg | I1: # Buzz | J1: % Buzz | K1: Acc | L1: Points | M1: PPG | N1: X PPG | O1: M PPG | P1: C PPG | Q1: E PPG | R1: B PPG | S1: P PPG
A2: 104421903707714227310 | B2: Anurag | C2: Centennial | D2: 4 | E2: 96 | F2: 71 | G2: 11 | H2: 1 | I2: 83 | J2: 0.86458333 | K2: 0.85542169 | L2: 280 | M2: 70 | N2: =vlookup($A2,'X-Risk'!$A:$M,13,false) -> 11 | O2: =vlookup($A2,Math!$A:$M,13,false) -> 8 | P2: =vlookup($A2,Chemistry!$A:$M,13,false) -> 16 | Q2: =vlookup($A2,EarthSpace!$A:$M,13,false) -> 12 | R2: =vlookup($A2,Biology!$A:$M,13,false) -> 12 | S2: =vlookup($A2,Physics!$A:$M,13,false) -> 11
A3: 100741934745181838949 | B3: Vishnu | C3: Lakeside A | D3: 4 | E3: 96 | F3: 51 | G3: 11 | H3: 1 | I3: 63 | J3: 0.65625 | K3: 0.80952381 | L3: 200 | M3: 50 | N3: =vlookup($A3,'X-Risk'!$A:$M,13,false) -> 7 | O3: =vlookup($A3,Math!$A:$M,13,false) -> 4 | P3: =vlookup($A3,Chemistry!$A:$M,13,false) -> 12 | Q3: =vlookup($A3,EarthSpace!$A:$M,13,false) -> 12 | R3: =vlookup($A3,Biology!$A:$M,13,false) -> 10 | S3: =vlookup($A3,Physics!$A:$M,13,false) -> 5
A4: 115421750943056030767 | B4: Kushal | C4: JP Stevens A | D4: 4 | E4: 96 | F4: 55 | G4: 6 | H4: 6 | I4: 67 | J4: 0.69791667 | K4: 0.82089552 | L4: 196 | M4: 49 | N4: =vlookup($A4,'X-Risk'!$A:$M,13,false) -> 10 | O4: =vlookup($A4,Math!$A:$M,13,false) -> 3 | P4: =vlookup($A4,Chemistry!$A:$M,13,false) -> 3 | Q4: =vlookup($A4,EarthSpace!$A:$M,13,false) -> 13 | R4: =vlookup($A4,Biology!$A:$M,13,false) -> 10 | S4: =vlookup($A4,Physics!$A:$M,13,false) -> 10
A5: 102086610308437271448 | B5: Viraj | C5: Dulles A | D5: 4 | E5: 96 | F5: 47 | G5: 8 | H5: 3 | I5: 58 | J5: 0.60416667 | K5: 0.81034483 | L5: 176 | M5: 44 | N5: =vlookup($A5,'X-Risk'!$A:$M,13,false) -> 7 | O5: =vlookup($A5,Math!$A:$M,13,false) -> 5 | P5: =vlookup($A5,Chemistry!$A:$M,13,false) -> 12 | Q5: =vlookup($A5,EarthSpace!$A:$M,13,false) -> 9 | R5: =vlookup($A5,Biology!$A:$M,13,false) -> 6 | S5: =vlookup($A5,Physics!$A:$M,13,false) -> 5
A6: 100552342580135245961 | B6: Luke | C6: duPont Manual | D6: 4 | E6: 96 | F6: 41 | G6: 5 | H6: 5 | I6: 51 | J6: 0.53125 | K6: 0.80392157 | L6: 144 | M6: 36 | N6: =vlookup($A6,'X-Risk'!$A:$M,13,false) -> 7 | O6: =vlookup($A6,Math!$A:$M,13,false) -> 6 | P6: =vlookup($A6,Chemistry!$A:$M,13,false) -> 8 | Q6: =vlookup($A6,EarthSpace!$A:$M,13,false) -> 1 | R6: =vlookup($A6,Biology!$A:$M,13,false) -> 12 | S6: =vlookup($A6,Physics!$A:$M,13,false) -> 2
A7: 110301036443128012178 | B7: Jackson | C7: Fossil Ridge | D7: 3 | E7: 72 | F7: 24 | G7: 8 | H7: 0 | I7: 32 | J7: 0.44444444 | K7: 0.75 | L7: 96 | M7: 32 | N7: =vlookup($A7,'X-Risk'!$A:$M,13,false) -> 2.6666667 | O7: =vlookup($A7,Math!$A:$M,13,false) -> 10.666667 | P7: =vlookup($A7,Chemistry!$A:$M,13,false) -> 5.3333333 | Q7: =vlookup($A7,EarthSpace!$A:$M,13,false) -> 1.3333333 | R7: =vlookup($A7,Biology!$A:$M,13,false) -> 2.6666667 | S7: =vlookup($A7,Physics!$A:$M,13,false) -> 9.3333333
A8: 115924773297427523154 | B8: Caleb | C8: Blair A | D8: 4 | E8: 96 | F8: 34 | G8: 1 | H8: 2 | I8: 37 | J8: 0.38541667 | K8: 0.91891892 | L8: 128 | M8: 32 | N8: =vlookup($A8,'X-Risk'!$A:$M,13,false) -> 7 | O8: =vlookup($A8,Math!$A:$M,13,false) -> 0 | P8: =vlookup($A8,Chemistry!$A:$M,13,false) -> 12 | Q8: =vlookup($A8,EarthSpace!$A:$M,13,false) -> 0 | R8: =vlookup($A8,Biology!$A:$M,13,false) -> 12 | S8: =vlookup($A8,Physics!$A:$M,13,false) -> 1
A9: 113094777403527549084 | B9: Vidur | C9: Lindbergh A | D9: 4 | E9: 96 | F9: 32 | G9: 16 | H9: 1 | I9: 49 | J9: 0.51041667 | K9: 0.65306122 | L9: 124 | M9: 31 | N9: =vlookup($A9,'X-Risk'!$A:$M,13,false) -> 3 | O9: =vlookup($A9,Math!$A:$M,13,false) -> 9 | P9: =vlookup($A9,Chemistry!$A:$M,13,false) -> 7 | Q9: =vlookup($A9,EarthSpace!$A:$M,13,false) -> 5 | R9: =vlookup($A9,Biology!$A:$M,13,false) -> 4 | S9: =vlookup($A9,Physics!$A:$M,13,false) -> 3
A10: 106442958599386378471 | B10: Daniel | C10: Lexington B | D10: 4 | E10: 96 | F10: 33 | G10: 3 | H10: 2 | I10: 38 | J10: 0.39583333 | K10: 0.86842105 | L10: 124 | M10: 31 | N10: =vlookup($A10,'X-Risk'!$A:$M,13,false) -> 7 | O10: =vlookup($A10,Math!$A:$M,13,false) -> 0 | P10: =vlookup($A10,Chemistry!$A:$M,13,false) -> 7 | Q10: =vlookup($A10,EarthSpace!$A:$M,13,false) -> 12 | R10: =vlookup($A10,Biology!$A:$M,13,false) -> 5 | S10: =vlookup($A10,Physics!$A:$M,13,false) -> 0
A11: 100662456472081319887 | B11: Andrey | C11: Buchholz A | D11: 5 | E11: 120 | F11: 43 | G11: 3 | H11: 5 | I11: 51 | J11: 0.425 | K11: 0.84313725 | L11: 152 | M11: 30.4 | N11: =vlookup($A11,'X-Risk'!$A:$M,13,false) -> 5.6 | O11: =vlookup($A11,Math!$A:$M,13,false) -> 1.6 | P11: =vlookup($A11,Chemistry!$A:$M,13,false) -> 0.8 | Q11: =vlookup($A11,EarthSpace!$A:$M,13,false) -> 5.6 | R11: =vlookup($A11,Biology!$A:$M,13,false) -> 12 | S11: =vlookup($A11,Physics!$A:$M,13,false) -> 4.8
A12: 100737823064401076042 | B12: Mason | C12: Westminster | D12: 4 | E12: 96 | F12: 32 | G12: 6 | H12: 2 | I12: 40 | J12: 0.41666667 | K12: 0.8 | L12: 120 | M12: 30 | N12: =vlookup($A12,'X-Risk'!$A:$M,13,false) -> 5 | O12: =vlookup($A12,Math!$A:$M,13,false) -> 0 | P12: =vlookup($A12,Chemistry!$A:$M,13,false) -> 1 | Q12: =vlookup($A12,EarthSpace!$A:$M,13,false) -> 12 | R12: =vlookup($A12,Biology!$A:$M,13,false) -> 11 | S12: =vlookup($A12,Physics!$A:$M,13,false) -> 1
A13: 114425244605279404977 | B13: Connor | C13: NoHo B | D13: 4 | E13: 96 | F13: 30 | G13: 11 | H13: 1 | I13: 42 | J13: 0.4375 | K13: 0.71428571 | L13: 116 | M13: 29 | N13: =vlookup($A13,'X-Risk'!$A:$M,13,false) -> 3 | O13: =vlookup($A13,Math!$A:$M,13,false) -> 7 | P13: =vlookup($A13,Chemistry!$A:$M,13,false) -> 5 | Q13: =vlookup($A13,EarthSpace!$A:$M,13,false) -> 8 | R13: =vlookup($A13,Biology!$A:$M,13,false) -> 2 | S13: =vlookup($A13,Physics!$A:$M,13,false) -> 4
... A458: 109902093337574294667 | B458: Akhil | C458: BRHS | D458: 4 | E458: 96 | F458: 1 | G458: 4 | H458: 2 | I458: 7 | J458: 0.072916667 | K458: 0.14285714 | L458: -4 | M458: -1 | N458: =vlookup($A458,'X-Risk'!$A:$M,13,false) -> 0 | O458: =vlookup($A458,Math!$A:$M,13,false) -> -2 | P458: =vlookup($A458,Chemistry!$A:$M,13,false) -> 0 | Q458: =vlookup($A458,EarthSpace!$A:$M,13,false) -> 0 | R458: =vlookup($A458,Biology!$A:$M,13,false) -> 1 | S458: =vlookup($A458,Physics!$A:$M,13,false) -> 0

Sheet Full
A1: ID | B1: Name | C1: Team | D1: GP | E1: TUH | F1: TU | G1: X | H1: Neg | I1: # Buzz | J1: % Buzz | K1: Acc | L1: Points | M1: PPG | N1: X PPG | O1: M PPG | P1: C PPG | Q1: E PPG | R1: B PPG | S1: P PPG
A2: 104421903707714227310 | B2: Anurag | C2: Centennial | D2: 10 | E2: 240 | F2: 144 | G2: 39 | H2: 9 | I2: 192 | J2: 0.8 | K2: 0.75 | L2: 540 | M2: 54 | N2: =vlookup($A2,'X-Risk Full'!$A:$M,13,false) -> 7.6 | O2: =vlookup($A2,'Math Full'!$A:$M,13,false) -> 5.6 | P2: =vlookup($A2,'Chemistry Full'!$A:$M,13,false) -> 15.2 | Q2: =vlookup($A2,'EarthSpace Full'!$A:$M,13,false) -> 7.6 | R2: =vlookup($A2,'Biology Full'!$A:$M,13,false) -> 8 | S2: =vlookup($A2,'Physics Full'!$A:$M,13,false) -> 10
A3: 100741934745181838949 | B3: Vishnu | C3: Lakeside A | D3: 7 | E3: 168 | F3: 77 | G3: 21 | H3: 2 | I3: 100 | J3: 0.5952381 | K3: 0.77 | L3: 300 | M3: 42.857143 | N3: =vlookup($A3,'X-Risk Full'!$A:$M,13,false) -> 5.1428571 | O3: =vlookup($A3,'Math Full'!$A:$M,13,false) -> 5.1428571 | P3: =vlookup($A3,'Chemistry Full'!$A:$M,13,false) -> 9.7142857 | Q3: =vlookup($A3,'EarthSpace Full'!$A:$M,13,false) -> 11.428571 | R3: =vlookup($A3,'Biology Full'!$A:$M,13,false) -> 6.8571429 | S3: =vlookup($A3,'Physics Full'!$A:$M,13,false) -> 4.5714286
A4: 115421750943056030767 | B4: Kushal | C4: JP Stevens A | D4: 8 | E4: 192 | F4: 80 | G4: 22 | H4: 13 | I4: 115 | J4: 0.59895833 | K4: 0.69565217 | L4: 268 | M4: 33.5 | N4: =vlookup($A4,'X-Risk Full'!$A:$M,13,false) -> 6.5 | O4: =vlookup($A4,'Math Full'!$A:$M,13,false) -> 1.5 | P4: =vlookup($A4,'Chemistry Full'!$A:$M,13,false) -> 2 | Q4: =vlookup($A4,'EarthSpace Full'!$A:$M,13,false) -> 8.5 | R4: =vlookup($A4,'Biology Full'!$A:$M,13,false) -> 7 | S4: =vlookup($A4,'Physics Full'!$A:$M,13,false) -> 8
A5: 102086610308437271448 | B5: Jackson | C5: Fossil Ridge | D5: 3 | E5: 72 | F5: 24 | G5: 8 | H5: 0 | I5: 32 | J5: 0.44444444 | K5: 0.75 | L5: 96 | M5: 32 | N5: =vlookup($A5,'X-Risk Full'!$A:$M,13,false) -> 2.6666667 | O5: =vlookup($A5,'Math Full'!$A:$M,13,false) -> 10.666667 | P5: =vlookup($A5,'Chemistry Full'!$A:$M,13,false) -> 5.3333333 | Q5: =vlookup($A5,'EarthSpace Full'!$A:$M,13,false) -> 1.3333333 | R5: =vlookup($A5,'Biology Full'!$A:$M,13,false) -> 2.6666667 | S5: =vlookup($A5,'Physics Full'!$A:$M,13,false) -> 9.3333333
A6: 100552342580135245961 | B6: Connor | C6: NoHo B | D6: 4 | E6: 96 | F6: 30 | G6: 11 | H6: 1 | I6: 42 | J6: 0.4375 | K6: 0.71428571 | L6: 116 | M6: 29 | N6: =vlookup($A6,'X-Risk Full'!$A:$M,13,false) -> 3 | O6: =vlookup($A6,'Math Full'!$A:$M,13,false) -> 7 | P6: =vlookup($A6,'Chemistry Full'!$A:$M,13,false) -> 5 | Q6: =vlookup($A6,'EarthSpace Full'!$A:$M,13,false) -> 8 | R6: =vlookup($A6,'Biology Full'!$A:$M,13,false) -> 2 | S6: =vlookup($A6,'Physics Full'!$A:$M,13,false) -> 4
A7: 110301036443128012178 | B7: Luke | C7: duPont Manual | D7: 6 | E7: 144 | F7: 50 | G7: 8 | H7: 7 | I7: 65 | J7: 0.45138889 | K7: 0.76923077 | L7: 172 | M7: 28.666667 | N7: =vlookup($A7,'X-Risk Full'!$A:$M,13,false) -> 6 | O7: =vlookup($A7,'Math Full'!$A:$M,13,false) -> 4.6666667 | P7: =vlookup($A7,'Chemistry Full'!$A:$M,13,false) -> 8 | Q7: =vlookup($A7,'EarthSpace Full'!$A:$M,13,false) -> 1.3333333 | R7: =vlookup($A7,'Biology Full'!$A:$M,13,false) -> 7.3333333 | S7: =vlookup($A7,'Physics Full'!$A:$M,13,false) -> 1.3333333
A8: 115924773297427523154 | B8: Archi | C8: Tupelo | D8: 5 | E8: 120 | F8: 36 | G8: 24 | H8: 1 | I8: 61 | J8: 0.50833333 | K8: 0.59016393 | L8: 140 | M8: 28 | N8: =vlookup($A8,'X-Risk Full'!$A:$M,13,false) -> 5.6 | O8: =vlookup($A8,'Math Full'!$A:$M,13,false) -> 5.6 | P8: =vlookup($A8,'Chemistry Full'!$A:$M,13,false) -> 6.4 | Q8: =vlookup($A8,'EarthSpace Full'!$A:$M,13,false) -> 1.6 | R8: =vlookup($A8,'Biology Full'!$A:$M,13,false) -> 6.4 | S8: =vlookup($A8,'Physics Full'!$A:$M,13,false) -> 2.4
A9: 113094777403527549084 | B9: Caleb | C9: Blair A | D9: 9 | E9: 216 | F9: 71 | G9: 6 | H9: 8 | I9: 85 | J9: 0.39351852 | K9: 0.83529412 | L9: 252 | M9: 28 | N9: =vlookup($A9,'X-Risk Full'!$A:$M,13,false) -> 5.7777778 | O9: =vlookup($A9,'Math Full'!$A:$M,13,false) -> 0 | P9: =vlookup($A9,'Chemistry Full'!$A:$M,13,false) -> 10.666667 | Q9: =vlookup($A9,'EarthSpace Full'!$A:$M,13,false) -> 1.3333333 | R9: =vlookup($A9,'Biology Full'!$A:$M,13,false) -> 8.8888889 | S9: =vlookup($A9,'Physics Full'!$A:$M,13,false) -> 1.3333333
A10: 106442958599386378471 | B10: Vidur | C10: Lindbergh A | D10: 5 | E10: 120 | F10: 35 | G10: 23 | H10: 2 | I10: 60 | J10: 0.5 | K10: 0.58333333 | L10: 132 | M10: 26.4 | N10: =vlookup($A10,'X-Risk Full'!$A:$M,13,false) -> 2.4 | O10: =vlookup($A10,'Math Full'!$A:$M,13,false) -> 7.2 | P10: =vlookup($A10,'Chemistry Full'!$A:$M,13,false) -> 5.6 | Q10: =vlookup($A10,'EarthSpace Full'!$A:$M,13,false) -> 5.6 | R10: =vlookup($A10,'Biology Full'!$A:$M,13,false) -> 3.2 | S10: =vlookup($A10,'Physics Full'!$A:$M,13,false) -> 2.4
A11: 100662456472081319887 | B11: Daniel | C11: Lexington B | D11: 7 | E11: 168 | F11: 50 | G11: 12 | H11: 4 | I11: 66 | J11: 0.39285714 | K11: 0.75757576 | L11: 184 | M11: 26.285714 | N11: =vlookup($A11,'X-Risk Full'!$A:$M,13,false) -> 7.4285714 | O11: =vlookup($A11,'Math Full'!$A:$M,13,false) -> 0 | P11: =vlookup($A11,'Chemistry Full'!$A:$M,13,false) -> 5.7142857 | Q11: =vlookup($A11,'EarthSpace Full'!$A:$M,13,false) -> 9.7142857 | R11: =vlookup($A11,'Biology Full'!$A:$M,13,false) -> 3.4285714 | S11: =vlookup($A11,'Physics Full'!$A:$M,13,false) -> 0
A12: 100737823064401076042 | B12: Sharvaa | C12: AHS Broward A | D12: 6 | E12: 144 | F12: 39 | G12: 23 | H12: 0 | I12: 62 | J12: 0.43055556 | K12: 0.62903226 | L12: 156 | M12: 26 | N12: =vlookup($A12,'X-Risk Full'!$A:$M,13,false) -> 2.6666667 | O12: =vlookup($A12,'Math Full'!$A:$M,13,false) -> 6 | P12: =vlookup($A12,'Chemistry Full'!$A:$M,13,false) -> 11.333333 | Q12: =vlookup($A12,'EarthSpace Full'!$A:$M,13,false) -> 1.3333333 | R12: =vlookup($A12,'Biology Full'!$A:$M,13,false) -> 0.66666667 | S12: =vlookup($A12,'Physics Full'!$A:$M,13,false) -> 4
A13: 114425244605279404977 | B13: Vinay | C13: Edison B | D13: 5 | E13: 120 | F13: 32 | G13: 20 | H13: 0 | I13: 52 | J13: 0.43333333 | K13: 0.61538462 | L13: 128 | M13: 25.6 | N13: =vlookup($A13,'X-Risk Full'!$A:$M,13,false) -> 5.6 | O13: =vlookup($A13,'Math Full'!$A:$M,13,false) -> 3.2 | P13: =vlookup($A13,'Chemistry Full'!$A:$M,13,false) -> 1.6 | Q13: =vlookup($A13,'EarthSpace Full'!$A:$M,13,false) -> 4 | R13: =vlookup($A13,'Biology Full'!$A:$M,13,false) -> 6.4 | S13: =vlookup($A13,'Physics Full'!$A:$M,13,false) -> 4.8
... A458: 109902093337574294667 | B458: Akhil | C458: BRHS | D458: 4 | E458: 96 | F458: 1 | G458: 4 | H458: 2 | I458: 7 | J458: 0.072916667 | K458: 0.14285714 | L458: -4 | M458: -1 | N458: =vlookup($A458,'X-Risk Full'!$A:$M,13,false) -> 0 | O458: =vlookup($A458,'Math Full'!$A:$M,13,false) -> -2 | P458: =vlookup($A458,'Chemistry Full'!$A:$M,13,false) -> 0 | Q458: =vlookup($A458,'EarthSpace Full'!$A:$M,13,false) -> 0 | R458: =vlookup($A458,'Biology Full'!$A:$M,13,false) -> 1 | S458: =vlookup($A458,'Physics Full'!$A:$M,13,false) -> 0

Sheet Team Prelims
A1: id | B1: Team | C1: GP | D1: TUH | E1: TU | F1: X | G1: Neg | H1: # Buzz | I1: % Buzz | J1: Acc | K1: Points | L1: PPG | M1: Bonus | N1: % Bonus | O1: BAPPG
A2: 1 | B2: Enloe A | C2: 4 | D2: 96 | E2: 73 | F2: 10 | G2: 8 | H2: 91 | I2: 0.94791667 | J2: 0.8021978 | K2: 260 | L2: 65 | M2: 68 | N2: 0.93150685 | O2: 235
A3: 2 | B3: Blair A | C3: 4 | D3: 96 | E3: 70 | F3: 8 | G3: 10 | H3: 88 | I3: 0.91666667 | J3: 0.79545455 | K3: 240 | L3: 60 | M3: 65 | N3: 0.92857143 | O3: 222.5
A4: 3 | B4: Centennial | C4: 4 | D4: 96 | E4: 74 | F4: 12 | G4: 2 | H4: 88 | I4: 0.91666667 | J4: 0.84090909 | K4: 288 | L4: 72 | M4: 60 | N4: 0.81081081 | O4: 222
A5: 4 | B5: Westminster | C5: 4 | D5: 96 | E5: 73 | F5: 12 | G5: 5 | H5: 90 | I5: 0.9375 | J5: 0.81111111 | K5: 272 | L5: 68 | M5: 61 | N5: 0.83561644 | O5: 220.5
A6: 5 | B6: Buchholz A | C6: 5 | D6: 120 | E6: 91 | F6: 10 | G6: 8 | H6: 109 | I6: 0.90833333 | J6: 0.83486239 | K6: 332 | L6: 66.4 | M6: 76 | N6: 0.83516484 | O6: 218.4
A7: 6 | B7: Lexington A | C7: 4 | D7: 96 | E7: 70 | F7: 12 | G7: 5 | H7: 87 | I7: 0.90625 | J7: 0.8045977 | K7: 260 | L7: 65 | M7: 58 | N7: 0.82857143 | O7: 210
A8: 7 | B8: NoHo A | C8: 4 | D8: 96 | E8: 67 | F8: 15 | G8: 1 | H8: 83 | I8: 0.86458333 | J8: 0.80722892 | K8: 264 | L8: 66 | M8: 54 | N8: 0.80597015 | O8: 201
A9: 8 | B9: MSJ A | C9: 4 | D9: 96 | E9: 65 | F9: 13 | G9: 13 | H9: 91 | I9: 0.94791667 | J9: 0.71428571 | K9: 208 | L9: 52 | M9: 56 | N9: 0.86153846 | O9: 192
A10: 9 | B10: Wayzata A | C10: 4 | D10: 96 | E10: 63 | F10: 14 | G10: 2 | H10: 79 | I10: 0.82291667 | J10: 0.79746835 | K10: 244 | L10: 61 | M10: 51 | N10: 0.80952381 | O10: 188.5
A11: 11 | B11: Green Hope A | C11: 4 | D11: 96 | E11: 68 | F11: 17 | G11: 1 | H11: 86 | I11: 0.89583333 | J11: 0.79069767 | K11: 268 | L11: 67 | M11: 48 | N11: 0.70588235 | O11: 187
A12: 12 | B12: JP Stevens A | C12: 4 | D12: 96 | E12: 66 | F12: 15 | G12: 6 | H12: 87 | I12: 0.90625 | J12: 0.75862069 | K12: 240 | L12: 60 | M12: 50 | N12: 0.75757576 | O12: 185
A13: 14 | B13: Tesla STEM A | C13: 4 | D13: 96 | E13: 58 | F13: 12 | G13: 4 | H13: 74 | I13: 0.77083333 | J13: 0.78378378 | K13: 216 | L13: 54 | M13: 52 | N13: 0.89655172 | O13: 184
... A112: 133 | B112: Rock Bridge B | C112: 4 | D112: 96 | E112: 5 | F112: 21 | G112: 0 | H112: 26 | I112: 0.27083333 | J112: 0.19230769 | K112: 20 | L112: 5 | M112: 1 | N112: 0.2 | O112: 7.5

Sheet Team Full
A1: id | B1: Team | C1: GP | D1: TUH | E1: TU | F1: X | G1: Neg | H1: # Buzz | I1: % Buzz | J1: Acc | K1: Points | L1: PPG | M1: Bonus | N1: % Bonus | O1: BAPPG
A2: 1 | B2: Buchholz A | C2: 9 | D2: 216 | E2: 139 | F2: 25 | G2: 22 | H2: 186 | I2: 0.86111111 | J2: 0.74731183 | K2: 468 | L2: 52 | M2: 109 | N2: 0.78417266 | O2: 173.11111
A3: 2 | B3: MSJ A | C3: 7 | D3: 168 | E3: 101 | F3: 27 | G3: 20 | H3: 148 | I3: 0.88095238 | J3: 0.68243243 | K3: 324 | L3: 46.285714 | M3: 86 | N3: 0.85148515 | O3: 169.14286
A4: 3 | B4: Enloe A | C4: 8 | D4: 192 | E4: 114 | F4: 30 | G4: 16 | H4: 160 | I4: 0.83333333 | J4: 0.7125 | K4: 392 | L4: 49 | M4: 96 | N4: 0.84210526 | O4: 169
A5: 4 | B5: NoHo A | C5: 8 | D5: 192 | E5: 114 | F5: 26 | G5: 9 | H5: 149 | I5: 0.77604167 | J5: 0.76510067 | K5: 420 | L5: 52.5 | M5: 93 | N5: 0.81578947 | O5: 168.75
A6: 5 | B6: Blair A | C6: 9 | D6: 216 | E6: 129 | F6: 33 | G6: 24 | H6: 186 | I6: 0.86111111 | J6: 0.69354839 | K6: 420 | L6: 46.666667 | M6: 107 | N6: 0.82945736 | O6: 165.55556
A7: 6 | B7: Centennial | C7: 10 | D7: 240 | E7: 150 | F7: 44 | G7: 10 | H7: 204 | I7: 0.85 | J7: 0.73529412 | K7: 560 | L7: 56 | M7: 102 | N7: 0.68 | O7: 158
A8: 7 | B8: Westminster | C8: 9 | D8: 216 | E8: 129 | F8: 34 | G8: 18 | H8: 181 | I8: 0.83796296 | J8: 0.71270718 | K8: 444 | L8: 49.333333 | M8: 94 | N8: 0.72868217 | O8: 153.77778
A9: 8 | B9: Wayzata A | C9: 7 | D9: 168 | E9: 94 | F9: 32 | G9: 9 | H9: 135 | I9: 0.80357143 | J9: 0.6962963 | K9: 340 | L9: 48.571429 | M9: 73 | N9: 0.77659574 | O9: 152.85714
A10: 9 | B10: Interlake D | C10: 6 | D10: 144 | E10: 79 | F10: 22 | G10: 10 | H10: 111 | I10: 0.77083333 | J10: 0.71171171 | K10: 276 | L10: 46 | M10: 61 | N10: 0.7721519 | O10: 147.66667
A11: 11 | B11: Enloe B | C11: 7 | D11: 168 | E11: 91 | F11: 31 | G11: 6 | H11: 128 | I11: 0.76190476 | J11: 0.7109375 | K11: 340 | L11: 48.571429 | M11: 68 | N11: 0.74725275 | O11: 145.71429
A12: 12 | B12: Dulles A | C12: 10 | D12: 240 | E12: 131 | F12: 38 | G12: 17 | H12: 186 | I12: 0.775 | J12: 0.70430108 | K12: 456 | L12: 45.6 | M12: 96 | N12: 0.73282443 | O12: 141.6
A13: 14 | B13: Lexington A | C13: 12 | D13: 288 | E13: 158 | F13: 34 | G13: 19 | H13: 211 | I13: 0.73263889 | J13: 0.74881517 | K13: 556 | L13: 46.333333 | M13: 114 | N13: 0.72151899 | O13: 141.33333
... A112: 133 | B112: Tesla STEM B | C112: 3 | D112: 72 | E112: 3 | F112: 7 | G112: 0 | H112: 10 | I112: 0.13888889 | J112: 0.3 | K112: 12 | L112: 4 | M112: 1 | N112: 0.33333333 | O112: 7.3333333

Sheet Team Prelim Cats
A1: Team | B1: GP | C1: X TU | D1: X X | E1: X Neg | F1: X PPG | G1: X Bonus | H1: X % Bonus | I1: X BAPPG | J1: M TU | K1: M X | L1: X Neg | M1: M PPG | N1: X Bonus | O1: M % Bonus | P1: M BAPPG | T1: C PPG | V1: C % Bonus | W1: C BAPPG | AA1: E PPG | AC1: E % Bonus | AD1: E BAPPG | AH1: B PPG | AJ1: B % Bonus | AK1: B BAPPG | AO1: P PPG | AQ1: P % Bonus | AR1: P BAPPG
A2: Enloe A | B2: 4 | C2: =sumifs('X-Risk'!$F$1:$F1000,'X-Risk'!$C$1:$C1000,$A2) -> 10 | D2: =sumifs('X-Risk'!$G$1:$G1000,'X-Risk'!$C$1:$C1000,$A2) -> 2 | E2: =sumifs('X-Risk'!$H$1:$H1000,'X-Risk'!$C$1:$C1000,$A2) -> 2 | F2: =(4*C2-4*E2)/$B2 -> 8 | G2: =countifs(PrelimRaw!$D$1:$D1000,14,PrelimRaw!$G$1:$G1000,$A2,PrelimRaw!$K$1:$K1000,"X") -> 10 | H2: =G2/C2 -> 1 | I2: =(C2*4-E2*4+G2*10)/$B2 -> 33 | J2: =sumifs(Math!$F$1:$F1000,Math!$C$1:$C1000,$A2) -> 12 | K2: =sumifs(Math!$G$1:$G1000,Math!$C$1:$C1000,$A2) -> 2 | L2: =sumifs(Math!$H$1:$H1000,Math!$C$1:$C1000,$A2) -> 2 | M2: =(4*J2-4*L2)/$B2 -> 10 | N2: =countifs(PrelimRaw!$D$1:$D1000,14,PrelimRaw!$G$1:$G1000,$A2,PrelimRaw!$K$1:$K1000,"M") -> 11 | O2: =N2/J2 -> 0.91666667 | P2: =(J2*4-L2*4+N2*10)/$B2 -> 37.5 | Q2: =sumifs(Chemistry!$F$1:$F1000,Chemistry!$C$1:$C1000,$A2) -> 14 | R2: =sumifs(Chemistry!$G$1:$G1000,Chemistry!$C$1:$C1000,$A2) -> 1 | S2: =sumifs(Chemistry!$H$1:$H1000,Chemistry!$C$1:$C1000,$A2) -> 1 | T2: =(4*Q2-4*S2)/$B2 -> 13 | U2: =countifs(PrelimRaw!$D$1:$D1000,14,PrelimRaw!$G$1:$G1000,$A2,PrelimRaw!$K$1:$K1000,"C") -> 13 | V2: =U2/Q2 -> 0.92857143 | W2: =(Q2*4-S2*4+U2*10)/$B2 -> 45.5 | X2: =sumifs(EarthSpace!$F$1:$F1000,EarthSpace!$C$1:$C1000,$A2) -> 13 | Y2: =sumifs(EarthSpace!$G$1:$G1000,EarthSpace!$C$1:$C1000,$A2) -> 0 | Z2: =sumifs(EarthSpace!$H$1:$H1000,EarthSpace!$C$1:$C1000,$A2) -> 1 | AA2: =(4*X2-4*Z2)/$B2 -> 12 | AB2: =countifs(PrelimRaw!$D$1:$D1000,14,PrelimRaw!$G$1:$G1000,$A2,PrelimRaw!$K$1:$K1000,"E") -> 13 | AC2: =AB2/X2 -> 1 | AD2: =(X2*4-Z2*4+AB2*10)/$B2 -> 44.5 | AE2: =sumifs(Biology!$F$1:$F1000,Biology!$C$1:$C1000,$A2) -> 14 | AF2: =sumifs(Biology!$G$1:$G1000,Biology!$C$1:$C1000,$A2) -> 1 | AG2: =sumifs(Biology!$H$1:$H1000,Biology!$C$1:$C1000,$A2) -> 0 | AH2: =(4*AE2-4*AG2)/$B2 -> 14 | AI2: =countifs(PrelimRaw!$D$1:$D1000,14,PrelimRaw!$G$1:$G1000,$A2,PrelimRaw!$K$1:$K1000,"B") -> 12 | AJ2: =AI2/AE2 -> 0.85714286 | AK2: =(AE2*4-AG2*4+AI2*10)/$B2 -> 44 | AL2: =sumifs(Physics!$F$1:$F1000,Physics!$C$1:$C1000,$A2) -> 10 | AM2: =sumifs(Physics!$G$1:$G1000,Physics!$C$1:$C1000,$A2) -> 4 | AN2: =sumifs(Physics!$H$1:$H1000,Physics!$C$1:$C1000,$A2) -> 2 | AO2: =(4*AL2-4*AN2)/$B2 -> 8 | AP2: =countifs(PrelimRaw!$D$1:$D1000,14,PrelimRaw!$G$1:$G1000,$A2,PrelimRaw!$K$1:$K1000,"P") -> 8 | AQ2: =AP2/AL2 -> 0.8 | AR2: =(AL2*4-AN2*4+AP2*10)/$B2 -> 28
A3: Blair A | B3: 4 | C3: =sumifs('X-Risk'!$F$1:$F1000,'X-Risk'!$C$1:$C1000,$A3) -> 13 | D3: =sumifs('X-Risk'!$G$1:$G1000,'X-Risk'!$C$1:$C1000,$A3) -> 0 | E3: =sumifs('X-Risk'!$H$1:$H1000,'X-Risk'!$C$1:$C1000,$A3) -> 2 | F3: =(4*C3-4*E3)/$B3 -> 11 | G3: =countifs(PrelimRaw!$D$1:$D1000,14,PrelimRaw!$G$1:$G1000,$A3,PrelimRaw!$K$1:$K1000,"X") -> 11 | H3: =G3/C3 -> 0.84615385 | I3: =(C3*4-E3*4+G3*10)/$B3 -> 38.5 | J3: =sumifs(Math!$F$1:$F1000,Math!$C$1:$C1000,$A3) -> 9 | K3: =sumifs(Math!$G$1:$G1000,Math!$C$1:$C1000,$A3) -> 4 | L3: =sumifs(Math!$H$1:$H1000,Math!$C$1:$C1000,$A3) -> 2 | M3: =(4*J3-4*L3)/$B3 -> 7 | N3: =countifs(PrelimRaw!$D$1:$D1000,14,PrelimRaw!$G$1:$G1000,$A3,PrelimRaw!$K$1:$K1000,"M") -> 9 | O3: =N3/J3 -> 1 | P3: =(J3*4-L3*4+N3*10)/$B3 -> 29.5 | Q3: =sumifs(Chemistry!$F$1:$F1000,Chemistry!$C$1:$C1000,$A3) -> 14 | R3: =sumifs(Chemistry!$G$1:$G1000,Chemistry!$C$1:$C1000,$A3) -> 0 | S3: =sumifs(Chemistry!$H$1:$H1000,Chemistry!$C$1:$C1000,$A3) -> 1 | T3: =(4*Q3-4*S3)/$B3 -> 13 | U3: =countifs(PrelimRaw!$D$1:$D1000,14,PrelimRaw!$G$1:$G1000,$A3,PrelimRaw!$K$1:$K1000,"C") -> 15 | V3: 1 | W3: =(Q3*4-S3*4+U3*10)/$B3 -> 50.5 | X3: =sumifs(EarthSpace!$F$1:$F1000,EarthSpace!$C$1:$C1000,$A3) -> 9 | Y3: =sumifs(EarthSpace!$G$1:$G1000,EarthSpace!$C$1:$C1000,$A3) -> 2 | Z3: =sumifs(EarthSpace!$H$1:$H1000,EarthSpace!$C$1:$C1000,$A3) -> 3 | AA3: =(4*X3-4*Z3)/$B3 -> 6 | AB3: =countifs(PrelimRaw!$D$1:$D1000,14,PrelimRaw!$G$1:$G1000,$A3,PrelimRaw!$K$1:$K1000,"E") -> 9 | AC3: =AB3/X3 -> 1 | AD3: =(X3*4-Z3*4+AB3*10)/$B3 -> 28.5 | AE3: =sumifs(Biology!$F$1:$F1000,Biology!$C$1:$C1000,$A3) -> 14 | AF3: =sumifs(Biology!$G$1:$G1000,Biology!$C$1:$C1000,$A3) -> 0 | AG3: =sumifs(Biology!$H$1:$H1000,Biology!$C$1:$C1000,$A3) -> 1 | AH3: =(4*AE3-4*AG3)/$B3 -> 13 | AI3: =countifs(PrelimRaw!$D$1:$D1000,14,PrelimRaw!$G$1:$G1000,$A3,PrelimRaw!$K$1:$K1000,"B") -> 13 | AJ3: =AI3/AE3 -> 0.92857143 | AK3: =(AE3*4-AG3*4+AI3*10)/$B3 -> 45.5 | AL3: =sumifs(Physics!$F$1:$F1000,Physics!$C$1:$C1000,$A3) -> 11 | AM3: =sumifs(Physics!$G$1:$G1000,Physics!$C$1:$C1000,$A3) -> 2 | AN3: =sumifs(Physics!$H$1:$H1000,Physics!$C$1:$C1000,$A3) -> 1 | AO3: =(4*AL3-4*AN3)/$B3 -> 10 | AP3: =countifs(PrelimRaw!$D$1:$D1000,14,PrelimRaw!$G$1:$G1000,$A3,PrelimRaw!$K$1:$K1000,"P") -> 8 | AQ3: =AP3/AL3 -> 0.72727273 | AR3: =(AL3*4-AN3*4+AP3*10)/$B3 -> 30
A4: Centennial | B4: 4 | C4: =sumifs('X-Risk'!$F$1:$F1000,'X-Risk'!$C$1:$C1000,$A4) -> 12 | D4: =sumifs('X-Risk'!$G$1:$G1000,'X-Risk'!$C$1:$C1000,$A4) -> 2 | E4: =sumifs('X-Risk'!$H$1:$H1000,'X-Risk'!$C$1:$C1000,$A4) -> 0 | F4: =(4*C4-4*E4)/$B4 -> 12 | G4: =countifs(PrelimRaw!$D$1:$D1000,14,PrelimRaw!$G$1:$G1000,$A4,PrelimRaw!$K$1:$K1000,"X") -> 9 | H4: =G4/C4 -> 0.75 | I4: =(C4*4-E4*4+G4*10)/$B4 -> 34.5 | J4: =sumifs(Math!$F$1:$F1000,Math!$C$1:$C1000,$A4) -> 9 | K4: =sumifs(Math!$G$1:$G1000,Math!$C$1:$C1000,$A4) -> 3 | L4: =sumifs(Math!$H$1:$H1000,Math!$C$1:$C1000,$A4) -> 1 | M4: =(4*J4-4*L4)/$B4 -> 8 | N4: =countifs(PrelimRaw!$D$1:$D1000,14,PrelimRaw!$G$1:$G1000,$A4,PrelimRaw!$K$1:$K1000,"M") -> 7 | O4: =N4/J4 -> 0.77777778 | P4: =(J4*4-L4*4+N4*10)/$B4 -> 25.5 | Q4: =sumifs(Chemistry!$F$1:$F1000,Chemistry!$C$1:$C1000,$A4) -> 16 | R4: =sumifs(Chemistry!$G$1:$G1000,Chemistry!$C$1:$C1000,$A4) -> 0 | S4: =sumifs(Chemistry!$H$1:$H1000,Chemistry!$C$1:$C1000,$A4) -> 0 | T4: =(4*Q4-4*S4)/$B4 -> 16 | U4: =countifs(PrelimRaw!$D$1:$D1000,14,PrelimRaw!$G$1:$G1000,$A4,PrelimRaw!$K$1:$K1000,"C") -> 15 | V4: =U4/Q4 -> 0.9375 | W4: =(Q4*4-S4*4+U4*10)/$B4 -> 53.5 | X4: =sumifs(EarthSpace!$F$1:$F1000,EarthSpace!$C$1:$C1000,$A4) -> 12 | Y4: =sumifs(EarthSpace!$G$1:$G1000,EarthSpace!$C$1:$C1000,$A4) -> 3 | Z4: =sumifs(EarthSpace!$H$1:$H1000,EarthSpace!$C$1:$C1000,$A4) -> 0 | AA4: =(4*X4-4*Z4)/$B4 -> 12 | AB4: =countifs(PrelimRaw!$D$1:$D1000,14,PrelimRaw!$G$1:$G1000,$A4,PrelimRaw!$K$1:$K1000,"E") -> 8 | AC4: =AB4/X4 -> 0.66666667 | AD4: =(X4*4-Z4*4+AB4*10)/$B4 -> 32 | AE4: =sumifs(Biology!$F$1:$F1000,Biology!$C$1:$C1000,$A4) -> 14 | AF4: =sumifs(Biology!$G$1:$G1000,Biology!$C$1:$C1000,$A4) -> 1 | AG4: =sumifs(Biology!$H$1:$H1000,Biology!$C$1:$C1000,$A4) -> 1 | AH4: =(4*AE4-4*AG4)/$B4 -> 13 | AI4: =countifs(PrelimRaw!$D$1:$D1000,14,PrelimRaw!$G$1:$G1000,$A4,PrelimRaw!$K$1:$K1000,"B") -> 12 | AJ4: =AI4/AE4 -> 0.85714286 | AK4: =(AE4*4-AG4*4+AI4*10)/$B4 -> 43 | AL4: =sumifs(Physics!$F$1:$F1000,Physics!$C$1:$C1000,$A4) -> 11 | AM4: =sumifs(Physics!$G$1:$G1000,Physics!$C$1:$C1000,$A4) -> 3 | AN4: =sumifs(Physics!$H$1:$H1000,Physics!$C$1:$C1000,$A4) -> 0 | AO4: =(4*AL4-4*AN4)/$B4 -> 11 | AP4: =countifs(PrelimRaw!$D$1:$D1000,14,PrelimRaw!$G$1:$G1000,$A4,PrelimRaw!$K$1:$K1000,"P") -> 9 | AQ4: =AP4/AL4 -> 0.81818182 | AR4: =(AL4*4-AN4*4+AP4*10)/$B4 -> 33.5
A5: Westminster | B5: 4 | C5: =sumifs('X-Risk'!$F$1:$F1000,'X-Risk'!$C$1:$C1000,$A5) -> 9 | D5: =sumifs('X-Risk'!$G$1:$G1000,'X-Risk'!$C$1:$C1000,$A5) -> 3 | E5: =sumifs('X-Risk'!$H$1:$H1000,'X-Risk'!$C$1:$C1000,$A5) -> 2 | F5: =(4*C5-4*E5)/$B5 -> 7 | G5: =countifs(PrelimRaw!$D$1:$D1000,14,PrelimRaw!$G$1:$G1000,$A5,PrelimRaw!$K$1:$K1000,"X") -> 7 | H5: =G5/C5 -> 0.77777778 | I5: =(C5*4-E5*4+G5*10)/$B5 -> 24.5 | J5: =sumifs(Math!$F$1:$F1000,Math!$C$1:$C1000,$A5) -> 12 | K5: =sumifs(Math!$G$1:$G1000,Math!$C$1:$C1000,$A5) -> 1 | L5: =sumifs(Math!$H$1:$H1000,Math!$C$1:$C1000,$A5) -> 0 | M5: =(4*J5-4*L5)/$B5 -> 12 | N5: =countifs(PrelimRaw!$D$1:$D1000,14,PrelimRaw!$G$1:$G1000,$A5,PrelimRaw!$K$1:$K1000,"M") -> 9 | O5: =N5/J5 -> 0.75 | P5: =(J5*4-L5*4+N5*10)/$B5 -> 34.5 | Q5: =sumifs(Chemistry!$F$1:$F1000,Chemistry!$C$1:$C1000,$A5) -> 15 | R5: =sumifs(Chemistry!$G$1:$G1000,Chemistry!$C$1:$C1000,$A5) -> 0 | S5: =sumifs(Chemistry!$H$1:$H1000,Chemistry!$C$1:$C1000,$A5) -> 1 | T5: =(4*Q5-4*S5)/$B5 -> 14 | U5: =countifs(PrelimRaw!$D$1:$D1000,14,PrelimRaw!$G$1:$G1000,$A5,PrelimRaw!$K$1:$K1000,"C") -> 11 | V5: =U5/Q5 -> 0.73333333 | W5: =(Q5*4-S5*4+U5*10)/$B5 -> 41.5 | X5: =sumifs(EarthSpace!$F$1:$F1000,EarthSpace!$C$1:$C1000,$A5) -> 12 | Y5: =sumifs(EarthSpace!$G$1:$G1000,EarthSpace!$C$1:$C1000,$A5) -> 4 | Z5: =sumifs(EarthSpace!$H$1:$H1000,EarthSpace!$C$1:$C1000,$A5) -> 0 | AA5: =(4*X5-4*Z5)/$B5 -> 12 | AB5: =countifs(PrelimRaw!$D$1:$D1000,14,PrelimRaw!$G$1:$G1000,$A5,PrelimRaw!$K$1:$K1000,"E") -> 11 | AC5: =AB5/X5 -> 0.91666667 | AD5: =(X5*4-Z5*4+AB5*10)/$B5 -> 39.5 | AE5: =sumifs(Biology!$F$1:$F1000,Biology!$C$1:$C1000,$A5) -> 14 | AF5: =sumifs(Biology!$G$1:$G1000,Biology!$C$1:$C1000,$A5) -> 0 | AG5: =sumifs(Biology!$H$1:$H1000,Biology!$C$1:$C1000,$A5) -> 1 | AH5: =(4*AE5-4*AG5)/$B5 -> 13 | AI5: =countifs(PrelimRaw!$D$1:$D1000,14,PrelimRaw!$G$1:$G1000,$A5,PrelimRaw!$K$1:$K1000,"B") -> 14 | AJ5: =AI5/AE5 -> 1 | AK5: =(AE5*4-AG5*4+AI5*10)/$B5 -> 48 | AL5: =sumifs(Physics!$F$1:$F1000,Physics!$C$1:$C1000,$A5) -> 11 | AM5: =sumifs(Physics!$G$1:$G1000,Physics!$C$1:$C1000,$A5) -> 4 | AN5: =sumifs(Physics!$H$1:$H1000,Physics!$C$1:$C1000,$A5) -> 1 | AO5: =(4*AL5-4*AN5)/$B5 -> 10 | AP5: =countifs(PrelimRaw!$D$1:$D1000,14,PrelimRaw!$G$1:$G1000,$A5,PrelimRaw!$K$1:$K1000,"P") -> 9 | AQ5: =AP5/AL5 -> 0.81818182 | AR5: =(AL5*4-AN5*4+AP5*10)/$B5 -> 32.5
A6: Buchholz A | B6: 5 | C6: =sumifs('X-Risk'!$F$1:$F1000,'X-Risk'!$C$1:$C1000,$A6) -> 15 | D6: =sumifs('X-Risk'!$G$1:$G1000,'X-Risk'!$C$1:$C1000,$A6) -> 2 | E6: =sumifs('X-Risk'!$H$1:$H1000,'X-Risk'!$C$1:$C1000,$A6) -> 1 | F6: =(4*C6-4*E6)/$B6 -> 11.2 | G6: =countifs(PrelimRaw!$D$1:$D1000,14,PrelimRaw!$G$1:$G1000,$A6,PrelimRaw!$K$1:$K1000,"X") -> 11 | H6: =G6/C6 -> 0.73333333 | I6: =(C6*4-E6*4+G6*10)/$B6 -> 33.2 | J6: =sumifs(Math!$F$1:$F1000,Math!$C$1:$C1000,$A6) -> 16 | K6: =sumifs(Math!$G$1:$G1000,Math!$C$1:$C1000,$A6) -> 3 | L6: =sumifs(Math!$H$1:$H1000,Math!$C$1:$C1000,$A6) -> 1 | M6: =(4*J6-4*L6)/$B6 -> 12 | N6: =countifs(PrelimRaw!$D$1:$D1000,14,PrelimRaw!$G$1:$G1000,$A6,PrelimRaw!$K$1:$K1000,"M") -> 13 | O6: =N6/J6 -> 0.8125 | P6: =(J6*4-L6*4+N6*10)/$B6 -> 38 | Q6: =sumifs(Chemistry!$F$1:$F1000,Chemistry!$C$1:$C1000,$A6) -> 14 | R6: =sumifs(Chemistry!$G$1:$G1000,Chemistry!$C$1:$C1000,$A6) -> 1 | S6: =sumifs(Chemistry!$H$1:$H1000,Chemistry!$C$1:$C1000,$A6) -> 1 | T6: =(4*Q6-4*S6)/$B6 -> 10.4 | U6: =countifs(PrelimRaw!$D$1:$D1000,14,PrelimRaw!$G$1:$G1000,$A6,PrelimRaw!$K$1:$K1000,"C") -> 12 | V6: =U6/Q6 -> 0.85714286 | W6: =(Q6*4-S6*4+U6*10)/$B6 -> 34.4 | X6: =sumifs(EarthSpace!$F$1:$F1000,EarthSpace!$C$1:$C1000,$A6) -> 15 | Y6: =sumifs(EarthSpace!$G$1:$G1000,EarthSpace!$C$1:$C1000,$A6) -> 2 | Z6: =sumifs(EarthSpace!$H$1:$H1000,EarthSpace!$C$1:$C1000,$A6) -> 2 | AA6: =(4*X6-4*Z6)/$B6 -> 10.4 | AB6: =countifs(PrelimRaw!$D$1:$D1000,14,PrelimRaw!$G$1:$G1000,$A6,PrelimRaw!$K$1:$K1000,"E") -> 13 | AC6: =AB6/X6 -> 0.86666667 | AD6: =(X6*4-Z6*4+AB6*10)/$B6 -> 36.4 | AE6: =sumifs(Biology!$F$1:$F1000,Biology!$C$1:$C1000,$A6) -> 18 | AF6: =sumifs(Biology!$G$1:$G1000,Biology!$C$1:$C1000,$A6) -> 0 | AG6: =sumifs(Biology!$H$1:$H1000,Biology!$C$1:$C1000,$A6) -> 0 | AH6: =(4*AE6-4*AG6)/$B6 -> 14.4 | AI6: =countifs(PrelimRaw!$D$1:$D1000,14,PrelimRaw!$G$1:$G1000,$A6,PrelimRaw!$K$1:$K1000,"B") -> 17 | AJ6: =AI6/AE6 -> 0.94444444 | AK6: =(AE6*4-AG6*4+AI6*10)/$B6 -> 48.4 | AL6: =sumifs(Physics!$F$1:$F1000,Physics!$C$1:$C1000,$A6) -> 13 | AM6: =sumifs(Physics!$G$1:$G1000,Physics!$C$1:$C1000,$A6) -> 2 | AN6: =sumifs(Physics!$H$1:$H1000,Physics!$C$1:$C1000,$A6) -> 3 | AO6: =(4*AL6-4*AN6)/$B6 -> 8 | AP6: =countifs(PrelimRaw!$D$1:$D1000,14,PrelimRaw!$G$1:$G1000,$A6,PrelimRaw!$K$1:$K1000,"P") -> 10 | AQ6: =AP6/AL6 -> 0.76923077 | AR6: =(AL6*4-AN6*4+AP6*10)/$B6 -> 28
A7: Lexington A | B7: 4 | C7: =sumifs('X-Risk'!$F$1:$F1000,'X-Risk'!$C$1:$C1000,$A7) -> 11 | D7: =sumifs('X-Risk'!$G$1:$G1000,'X-Risk'!$C$1:$C1000,$A7) -> 0 | E7: =sumifs('X-Risk'!$H$1:$H1000,'X-Risk'!$C$1:$C1000,$A7) -> 3 | F7: =(4*C7-4*E7)/$B7 -> 8 | G7: =countifs(PrelimRaw!$D$1:$D1000,14,PrelimRaw!$G$1:$G1000,$A7,PrelimRaw!$K$1:$K1000,"X") -> 9 | H7: =G7/C7 -> 0.81818182 | I7: =(C7*4-E7*4+G7*10)/$B7 -> 30.5 | J7: =sumifs(Math!$F$1:$F1000,Math!$C$1:$C1000,$A7) -> 13 | K7: =sumifs(Math!$G$1:$G1000,Math!$C$1:$C1000,$A7) -> 1 | L7: =sumifs(Math!$H$1:$H1000,Math!$C$1:$C1000,$A7) -> 1 | M7: =(4*J7-4*L7)/$B7 -> 12 | N7: =countifs(PrelimRaw!$D$1:$D1000,14,PrelimRaw!$G$1:$G1000,$A7,PrelimRaw!$K$1:$K1000,"M") -> 10 | O7: =N7/J7 -> 0.76923077 | P7: =(J7*4-L7*4+N7*10)/$B7 -> 37 | Q7: =sumifs(Chemistry!$F$1:$F1000,Chemistry!$C$1:$C1000,$A7) -> 10 | R7: =sumifs(Chemistry!$G$1:$G1000,Chemistry!$C$1:$C1000,$A7) -> 2 | S7: =sumifs(Chemistry!$H$1:$H1000,Chemistry!$C$1:$C1000,$A7) -> 1 | T7: =(4*Q7-4*S7)/$B7 -> 9 | U7: =countifs(PrelimRaw!$D$1:$D1000,14,PrelimRaw!$G$1:$G1000,$A7,PrelimRaw!$K$1:$K1000,"C") -> 9 | V7: =U7/Q7 -> 0.9 | W7: =(Q7*4-S7*4+U7*10)/$B7 -> 31.5 | X7: =sumifs(EarthSpace!$F$1:$F1000,EarthSpace!$C$1:$C1000,$A7) -> 14 | Y7: =sumifs(EarthSpace!$G$1:$G1000,EarthSpace!$C$1:$C1000,$A7) -> 2 | Z7: =sumifs(EarthSpace!$H$1:$H1000,EarthSpace!$C$1:$C1000,$A7) -> 0 | AA7: =(4*X7-4*Z7)/$B7 -> 14 | AB7: =countifs(PrelimRaw!$D$1:$D1000,14,PrelimRaw!$G$1:$G1000,$A7,PrelimRaw!$K$1:$K1000,"E") -> 12 | AC7: =AB7/X7 -> 0.85714286 | AD7: =(X7*4-Z7*4+AB7*10)/$B7 -> 44 | AE7: =sumifs(Biology!$F$1:$F1000,Biology!$C$1:$C1000,$A7) -> 11 | AF7: =sumifs(Biology!$G$1:$G1000,Biology!$C$1:$C1000,$A7) -> 3 | AG7: =sumifs(Biology!$H$1:$H1000,Biology!$C$1:$C1000,$A7) -> 0 | AH7: =(4*AE7-4*AG7)/$B7 -> 11 | AI7: =countifs(PrelimRaw!$D$1:$D1000,14,PrelimRaw!$G$1:$G1000,$A7,PrelimRaw!$K$1:$K1000,"B") -> 10 | AJ7: =AI7/AE7 -> 0.90909091 | AK7: =(AE7*4-AG7*4+AI7*10)/$B7 -> 36 | AL7: =sumifs(Physics!$F$1:$F1000,Physics!$C$1:$C1000,$A7) -> 11 | AM7: =sumifs(Physics!$G$1:$G1000,Physics!$C$1:$C1000,$A7) -> 4 | AN7: =sumifs(Physics!$H$1:$H1000,Physics!$C$1:$C1000,$A7) -> 0 | AO7: =(4*AL7-4*AN7)/$B7 -> 11 | AP7: =countifs(PrelimRaw!$D$1:$D1000,14,PrelimRaw!$G$1:$G1000,$A7,PrelimRaw!$K$1:$K1000,"P") -> 8 | AQ7: =AP7/AL7 -> 0.72727273 | AR7: =(AL7*4-AN7*4+AP7*10)/$B7 -> 31
A8: NoHo A | B8: 4 | C8: =sumifs('X-Risk'!$F$1:$F1000,'X-Risk'!$C$1:$C1000,$A8) -> 11 | D8: =sumifs('X-Risk'!$G$1:$G1000,'X-Risk'!$C$1:$C1000,$A8) -> 3 | E8: =sumifs('X-Risk'!$H$1:$H1000,'X-Risk'!$C$1:$C1000,$A8) -> 0 | F8: =(4*C8-4*E8)/$B8 -> 11 | G8: =countifs(PrelimRaw!$D$1:$D1000,14,PrelimRaw!$G$1:$G1000,$A8,PrelimRaw!$K$1:$K1000,"X") -> 10 | H8: =G8/C8 -> 0.90909091 | I8: =(C8*4-E8*4+G8*10)/$B8 -> 36 | J8: =sumifs(Math!$F$1:$F1000,Math!$C$1:$C1000,$A8) -> 9 | K8: =sumifs(Math!$G$1:$G1000,Math!$C$1:$C1000,$A8) -> 3 | L8: =sumifs(Math!$H$1:$H1000,Math!$C$1:$C1000,$A8) -> 0 | M8: =(4*J8-4*L8)/$B8 -> 9 | N8: =countifs(PrelimRaw!$D$1:$D1000,14,PrelimRaw!$G$1:$G1000,$A8,PrelimRaw!$K$1:$K1000,"M") -> 6 | O8: =N8/J8 -> 0.66666667 | P8: =(J8*4-L8*4+N8*10)/$B8 -> 24 | Q8: =sumifs(Chemistry!$F$1:$F1000,Chemistry!$C$1:$C1000,$A8) -> 11 | R8: =sumifs(Chemistry!$G$1:$G1000,Chemistry!$C$1:$C1000,$A8) -> 3 | S8: =sumifs(Chemistry!$H$1:$H1000,Chemistry!$C$1:$C1000,$A8) -> 0 | T8: =(4*Q8-4*S8)/$B8 -> 11 | U8: =countifs(PrelimRaw!$D$1:$D1000,14,PrelimRaw!$G$1:$G1000,$A8,PrelimRaw!$K$1:$K1000,"C") -> 7 | V8: =U8/Q8 -> 0.63636364 | W8: =(Q8*4-S8*4+U8*10)/$B8 -> 28.5 | X8: =sumifs(EarthSpace!$F$1:$F1000,EarthSpace!$C$1:$C1000,$A8) -> 12 | Y8: =sumifs(EarthSpace!$G$1:$G1000,EarthSpace!$C$1:$C1000,$A8) -> 1 | Z8: =sumifs(EarthSpace!$H$1:$H1000,EarthSpace!$C$1:$C1000,$A8) -> 1 | AA8: =(4*X8-4*Z8)/$B8 -> 11 | AB8: =countifs(PrelimRaw!$D$1:$D1000,14,PrelimRaw!$G$1:$G1000,$A8,PrelimRaw!$K$1:$K1000,"E") -> 12 | AC8: =AB8/X8 -> 1 | AD8: =(X8*4-Z8*4+AB8*10)/$B8 -> 41 | AE8: =sumifs(Biology!$F$1:$F1000,Biology!$C$1:$C1000,$A8) -> 14 | AF8: =sumifs(Biology!$G$1:$G1000,Biology!$C$1:$C1000,$A8) -> 1 | AG8: =sumifs(Biology!$H$1:$H1000,Biology!$C$1:$C1000,$A8) -> 0 | AH8: =(4*AE8-4*AG8)/$B8 -> 14 | AI8: =countifs(PrelimRaw!$D$1:$D1000,14,PrelimRaw!$G$1:$G1000,$A8,PrelimRaw!$K$1:$K1000,"B") -> 13 | AJ8: =AI8/AE8 -> 0.92857143 | AK8: =(AE8*4-AG8*4+AI8*10)/$B8 -> 46.5 | AL8: =sumifs(Physics!$F$1:$F1000,Physics!$C$1:$C1000,$A8) -> 10 | AM8: =sumifs(Physics!$G$1:$G1000,Physics!$C$1:$C1000,$A8) -> 4 | AN8: =sumifs(Physics!$H$1:$H1000,Physics!$C$1:$C1000,$A8) -> 0 | AO8: =(4*AL8-4*AN8)/$B8 -> 10 | AP8: =countifs(PrelimRaw!$D$1:$D1000,14,PrelimRaw!$G$1:$G1000,$A8,PrelimRaw!$K$1:$K1000,"P") -> 6 | AQ8: =AP8/AL8 -> 0.6 | AR8: =(AL8*4-AN8*4+AP8*10)/$B8 -> 25
A9: MSJ A | B9: 4 | C9: =sumifs('X-Risk'!$F$1:$F1000,'X-Risk'!$C$1:$C1000,$A9) -> 8 | D9: =sumifs('X-Risk'!$G$1:$G1000,'X-Risk'!$C$1:$C1000,$A9) -> 3 | E9: =sumifs('X-Risk'!$H$1:$H1000,'X-Risk'!$C$1:$C1000,$A9) -> 5 | F9: =(4*C9-4*E9)/$B9 -> 3 | G9: =countifs(PrelimRaw!$D$1:$D1000,14,PrelimRaw!$G$1:$G1000,$A9,PrelimRaw!$K$1:$K1000,"X") -> 7 | H9: =G9/C9 -> 0.875 | I9: =(C9*4-E9*4+G9*10)/$B9 -> 20.5 | J9: =sumifs(Math!$F$1:$F1000,Math!$C$1:$C1000,$A9) -> 11 | K9: =sumifs(Math!$G$1:$G1000,Math!$C$1:$C1000,$A9) -> 2 | L9: =sumifs(Math!$H$1:$H1000,Math!$C$1:$C1000,$A9) -> 2 | M9: =(4*J9-4*L9)/$B9 -> 9 | N9: =countifs(PrelimRaw!$D$1:$D1000,14,PrelimRaw!$G$1:$G1000,$A9,PrelimRaw!$K$1:$K1000,"M") -> 8 | O9: =N9/J9 -> 0.72727273 | P9: =(J9*4-L9*4+N9*10)/$B9 -> 29 | Q9: =sumifs(Chemistry!$F$1:$F1000,Chemistry!$C$1:$C1000,$A9) -> 12 | R9: =sumifs(Chemistry!$G$1:$G1000,Chemistry!$C$1:$C1000,$A9) -> 2 | S9: =sumifs(Chemistry!$H$1:$H1000,Chemistry!$C$1:$C1000,$A9) -> 0 | T9: =(4*Q9-4*S9)/$B9 -> 12 | U9: =countifs(PrelimRaw!$D$1:$D1000,14,PrelimRaw!$G$1:$G1000,$A9,PrelimRaw!$K$1:$K1000,"C") -> 11 | V9: =U9/Q9 -> 0.91666667 | W9: =(Q9*4-S9*4+U9*10)/$B9 -> 39.5 | X9: =sumifs(EarthSpace!$F$1:$F1000,EarthSpace!$C$1:$C1000,$A9) -> 13 | Y9: =sumifs(EarthSpace!$G$1:$G1000,EarthSpace!$C$1:$C1000,$A9) -> 1 | Z9: =sumifs(EarthSpace!$H$1:$H1000,EarthSpace!$C$1:$C1000,$A9) -> 1 | AA9: =(4*X9-4*Z9)/$B9 -> 12 | AB9: =countifs(PrelimRaw!$D$1:$D1000,14,PrelimRaw!$G$1:$G1000,$A9,PrelimRaw!$K$1:$K1000,"E") -> 11 | AC9: =AB9/X9 -> 0.84615385 | AD9: =(X9*4-Z9*4+AB9*10)/$B9 -> 39.5 | AE9: =sumifs(Biology!$F$1:$F1000,Biology!$C$1:$C1000,$A9) -> 11 | AF9: =sumifs(Biology!$G$1:$G1000,Biology!$C$1:$C1000,$A9) -> 2 | AG9: =sumifs(Biology!$H$1:$H1000,Biology!$C$1:$C1000,$A9) -> 3 | AH9: =(4*AE9-4*AG9)/$B9 -> 8 | AI9: =countifs(PrelimRaw!$D$1:$D1000,14,PrelimRaw!$G$1:$G1000,$A9,PrelimRaw!$K$1:$K1000,"B") -> 10 | AJ9: =AI9/AE9 -> 0.90909091 | AK9: =(AE9*4-AG9*4+AI9*10)/$B9 -> 33 | AL9: =sumifs(Physics!$F$1:$F1000,Physics!$C$1:$C1000,$A9) -> 10 | AM9: =sumifs(Physics!$G$1:$G1000,Physics!$C$1:$C1000,$A9) -> 3 | AN9: =sumifs(Physics!$H$1:$H1000,Physics!$C$1:$C1000,$A9) -> 2 | AO9: =(4*AL9-4*AN9)/$B9 -> 8 | AP9: =countifs(PrelimRaw!$D$1:$D1000,14,PrelimRaw!$G$1:$G1000,$A9,PrelimRaw!$K$1:$K1000,"P") -> 9 | AQ9: =AP9/AL9 -> 0.9 | AR9: =(AL9*4-AN9*4+AP9*10)/$B9 -> 30.5
A10: Wayzata A | B10: 4 | C10: =sumifs('X-Risk'!$F$1:$F1000,'X-Risk'!$C$1:$C1000,$A10) -> 8 | D10: =sumifs('X-Risk'!$G$1:$G1000,'X-Risk'!$C$1:$C1000,$A10) -> 3 | E10: =sumifs('X-Risk'!$H$1:$H1000,'X-Risk'!$C$1:$C1000,$A10) -> 2 | F10: =(4*C10-4*E10)/$B10 -> 6 | G10: =countifs(PrelimRaw!$D$1:$D1000,14,PrelimRaw!$G$1:$G1000,$A10,PrelimRaw!$K$1:$K1000,"X") -> 7 | H10: =G10/C10 -> 0.875 | I10: =(C10*4-E10*4+G10*10)/$B10 -> 23.5 | J10: =sumifs(Math!$F$1:$F1000,Math!$C$1:$C1000,$A10) -> 11 | K10: =sumifs(Math!$G$1:$G1000,Math!$C$1:$C1000,$A10) -> 3 | L10: =sumifs(Math!$H$1:$H1000,Math!$C$1:$C1000,$A10) -> 0 | M10: =(4*J10-4*L10)/$B10 -> 11 | N10: =countifs(PrelimRaw!$D$1:$D1000,14,PrelimRaw!$G$1:$G1000,$A10,PrelimRaw!$K$1:$K1000,"M") -> 8 | O10: =N10/J10 -> 0.72727273 | P10: =(J10*4-L10*4+N10*10)/$B10 -> 31 | Q10: =sumifs(Chemistry!$F$1:$F1000,Chemistry!$C$1:$C1000,$A10) -> 11 | R10: =sumifs(Chemistry!$G$1:$G1000,Chemistry!$C$1:$C1000,$A10) -> 2 | S10: =sumifs(Chemistry!$H$1:$H1000,Chemistry!$C$1:$C1000,$A10) -> 0 | T10: =(4*Q10-4*S10)/$B10 -> 11 | U10: =countifs(PrelimRaw!$D$1:$D1000,14,PrelimRaw!$G$1:$G1000,$A10,PrelimRaw!$K$1:$K1000,"C") -> 9 | V10: =U10/Q10 -> 0.81818182 | W10: =(Q10*4-S10*4+U10*10)/$B10 -> 33.5 | X10: =sumifs(EarthSpace!$F$1:$F1000,EarthSpace!$C$1:$C1000,$A10) -> 9 | Y10: =sumifs(EarthSpace!$G$1:$G1000,EarthSpace!$C$1:$C1000,$A10) -> 3 | Z10: =sumifs(EarthSpace!$H$1:$H1000,EarthSpace!$C$1:$C1000,$A10) -> 0 | AA10: =(4*X10-4*Z10)/$B10 -> 9 | AB10: =countifs(PrelimRaw!$D$1:$D1000,14,PrelimRaw!$G$1:$G1000,$A10,PrelimRaw!$K$1:$K1000,"E") -> 6 | AC10: =AB10/X10 -> 0.66666667 | AD10: =(X10*4-Z10*4+AB10*10)/$B10 -> 24 | AE10: =sumifs(Biology!$F$1:$F1000,Biology!$C$1:$C1000,$A10) -> 12 | AF10: =sumifs(Biology!$G$1:$G1000,Biology!$C$1:$C1000,$A10) -> 0 | AG10: =sumifs(Biology!$H$1:$H1000,Biology!$C$1:$C1000,$A10) -> 0 | AH10: =(4*AE10-4*AG10)/$B10 -> 12 | AI10: =countifs(PrelimRaw!$D$1:$D1000,14,PrelimRaw!$G$1:$G1000,$A10,PrelimRaw!$K$1:$K1000,"B") -> 11 | AJ10: =AI10/AE10 -> 0.91666667 | AK10: =(AE10*4-AG10*4+AI10*10)/$B10 -> 39.5 | AL10: =sumifs(Physics!$F$1:$F1000,Physics!$C$1:$C1000,$A10) -> 12 | AM10: =sumifs(Physics!$G$1:$G1000,Physics!$C$1:$C1000,$A10) -> 3 | AN10: =sumifs(Physics!$H$1:$H1000,Physics!$C$1:$C1000,$A10) -> 0 | AO10: =(4*AL10-4*AN10)/$B10 -> 12 | AP10: =countifs(PrelimRaw!$D$1:$D1000,14,PrelimRaw!$G$1:$G1000,$A10,PrelimRaw!$K$1:$K1000,"P") -> 10 | AQ10: =AP10/AL10 -> 0.83333333 | AR10: =(AL10*4-AN10*4+AP10*10)/$B10 -> 37
