Workbook

Sheet Round Robin Scores
A1: Antares | C1: =B2 -> Diamond Bar | E1: =B3 -> Troy | G1: =B4 -> South Pasadena | I1: =B5 -> OCSA | K1: =B6 -> Portola | M1: =B6 -> Portola | O1: Points
A2: A1 | B2: Diamond Bar | E2: 88 | F2: =if(E2>C3,"W",if(E2<C3,"L",if(isblank(E2),"","T"))) -> L | G2: 76 | H2: =if(G2>C4,"W",if(G2<C4,"L",if(isblank(G2),"","T"))) -> L | I2: 38 | J2: L | K2: 56 | L2: L | N2: =if(M2>C6,"W",if(M2<C6,"L",if(isblank(M2),"","T"))) -> L | O2: =(2*COUNTIF(C2:N2, "W"))+COUNTIF(C2:N2, "T") -> 0
A3: A2 | B3: Troy | C3: 134 | D3: =if(E2<C3,"W",if(E2>C3,"L",if(isblank(C3),"","T"))) -> W | G3: 214 | H3: =if(G3>E4,"W",if(G3<E4,"L",if(isblank(G3),"","T"))) -> W | I3: 202 | J3: W | K3: 152 | L3: =if(K3>E5,"W",if(K3<E5,"L",if(isblank(K3),"","T"))) -> W | N3: =if(M3>E6,"W",if(M3<E6,"L",if(isblank(M3),"","T"))) -> L | O3: =(2*COUNTIF(C3:N3, "W"))+COUNTIF(C3:N3, "T") -> 8
A4: A3 | B4: South Pasadena | C4: 100 | D4: =if(G2<C4,"W",if(G2>C4,"L",if(isblank(C4),"","T"))) -> W | E4: 32 | F4: =if(G3<E4,"W",if(G3>E4,"L",if(isblank(E4),"","T"))) -> L | I4: 16 | J4: L | K4: 88 | L4: L | N4: =if(M4>G6,"W",if(M4<G6,"L",if(isblank(M4),"","T"))) -> L | O4: =(2*COUNTIF(C4:N4, "W"))+COUNTIF(C4:N4, "T") -> 2
A5: A4 | B5: OCSA | C5: 100 | D5: W | E5: 18 | F5: L | G5: 184 | H5: =if(K4<G5,"W",if(K4>G5,"L",if(isblank(G5),"","T"))) -> W | K5: 82 | L5: L | N5: =if(M5>K6,"W",if(M5<K6,"L",if(isblank(M5),"","T"))) | O5: =(2*COUNTIF(C5:N5, "W"))+COUNTIF(C5:N5, "T") -> 4
A6: A5 | B6: Portola | C6: 72 | D6: =if(M2<C6,"W",if(M2>C6,"L",if(isblank(C6),"","T"))) -> W | E6: 82 | F6: L | G6: 114 | H6: =if(M4<G6,"W",if(M4>G6,"L",if(isblank(G6),"","T"))) -> W | I6: 94 | J6: W | L6: =if(M5<K6,"W",if(M5>K6,"L",if(isblank(K6),"","T"))) | O6: =(2*COUNTIF(C6:N6, "W"))+COUNTIF(C6:N6, "T") -> 6
A8: Bellatrix | C8: =B9 -> Palm Desert | E8: =B10 -> Santa Monica | G8: =B11 -> San Marino | I8: =B12 -> Palos Verdes | K8: =B13 -> Northwood | O8: Points
A9: B1 | B9: Palm Desert | E9: 30 | F9: =if(E9>C10,"W",if(E9<C10,"L",if(isblank(E9),"","T"))) -> L | G9: 46 | H9: =if(G9>C11,"W",if(G9<C11,"L",if(isblank(G9),"","T"))) -> L | I9: 48 | J9: L | K9: 44 | L9: L | N9: =if(M9>C13,"W",if(M9<C13,"L",if(isblank(M9),"","T"))) -> L | O9: =(2*COUNTIF(C9:N9, "W"))+COUNTIF(C9:N9, "T") -> 0
A10: B2 | B10: Santa Monica | C10: 164 | D10: =if(E9<C10,"W",if(E9>C10,"L",if(isblank(C10),"","T"))) -> W | G10: 156 | H10: =if(G10>E11,"W",if(G10<E11,"L",if(isblank(G10),"","T"))) -> W | I10: 102 | J10: W | K10: 146 | L10: =if(K10>E12,"W",if(K10<E12,"L",if(isblank(K10),"","T"))) -> W | N10: =if(M10>E13,"W",if(M10<E13,"L",if(isblank(M10),"","T"))) -> L | O10: =(2*COUNTIF(C10:N10, "W"))+COUNTIF(C10:N10, "T") -> 8
A11: B3 | B11: San Marino | C11: 182 | D11: =if(G9<C11,"W",if(G9>C11,"L",if(isblank(C11),"","T"))) -> W | E11: 114 | F11: =if(G10<E11,"W",if(G10>E11,"L",if(isblank(E11),"","T"))) -> L | I11: 106 | J11: W | K11: 152 | L11: W | N11: =if(M11>G13,"W",if(M11<G13,"L",if(isblank(M11),"","T"))) -> L | O11: =(2*COUNTIF(C11:N11, "W"))+COUNTIF(C11:N11, "T") -> 6
A12: B4 | B12: Palos Verdes | C12: 90 | D12: W | E12: 100 | F12: L | G12: 82 | H12: L | K12: 68 | L12: W | N12: =if(M12>K13,"W",if(M12<K13,"L",if(isblank(M12),"","T"))) | O12: =(2*COUNTIF(C12:N12, "W"))+COUNTIF(C12:N12, "T") -> 4
A13: B5 | B13: Northwood | C13: 122 | D13: =if(M9<C13,"W",if(M9>C13,"L",if(isblank(C13),"","T"))) -> W | E13: 46 | F13: L | G13: 42 | H13: L | I13: 64 | J13: L | L13: =if(M12<K13,"W",if(M12>K13,"L",if(isblank(K13),"","T"))) | O13: =(2*COUNTIF(C13:N13, "W"))+COUNTIF(C13:N13, "T") -> 2
A15: Copernicus | C15: =B16 -> La Canada | E15: =B17 -> Aquinas | G15: =B18 -> Arcadia 1 | I15: =B19 -> Walnut | K15: =B20 -> Beckman | M15: =B21 -> University | O15: Points
A16: C1 | B16: La Canada | E16: 62 | F16: =if(E16>C17,"W",if(E16<C17,"L",if(isblank(E16),"","T"))) -> L | G16: 80 | H16: =if(G16>C18,"W",if(G16<C18,"L",if(isblank(G16),"","T"))) -> L | I16: 64 | J16: L | K16: 60 | L16: L | M16: 34 | N16: =if(M16>C21,"W",if(M16<C21,"L",if(isblank(M16),"","T"))) -> L | O16: 0
A17: C2 | B17: Aquinas | C17: 68 | D17: =if(E16<C17,"W",if(E16>C17,"L",if(isblank(C17),"","T"))) -> W | G17: 28 | H17: =if(G17>E18,"W",if(G17<E18,"L",if(isblank(G17),"","T"))) -> L | I17: 44 | J17: L | K17: 36 | L17: L | M17: 24 | N17: =if(M17>E21,"W",if(M17<E21,"L",if(isblank(M17),"","T"))) -> L | O17: 2
A18: C3 | B18: Arcadia 1 | C18: 122 | D18: =if(G16<C18,"W",if(G16>C18,"L",if(isblank(C18),"","T"))) -> W | E18: 170 | F18: =if(G17<E18,"W",if(G17>E18,"L",if(isblank(E18),"","T"))) -> W | I18: 146 | J18: W | K18: 86 | L18: =if(K18>G20,"W",if(K18<G20,"L",if(isblank(K18),"","T"))) -> L | M18: 86 | N18: =if(M18>G21,"W",if(M18<G21,"L",if(isblank(M18),"","T"))) -> L | O18: 6
A19: C4 | B19: Walnut | C19: 76 | D19: W | E19: 142 | F19: W | G19: 76 | H19: L | K19: 60 | L19: L | M19: 66 | N19: L | O19: 4
A20: C5 | B20: Beckman | C20: 112 | D20: W | E20: 118 | F20: =if(K17<E20,"W",if(K17>E20,"L",if(isblank(E20),"","T"))) -> W | G20: 132 | H20: =if(K18<G20,"W",if(K18>G20,"L",if(isblank(G20),"","T"))) -> W | I20: 136 | J20: W | M20: 94 | N20: =if(M20>K21,"W",if(M20<K21,"L",if(isblank(M20),"","T"))) -> L | O20: 8
A21: C6 | B21: University | C21: 270 | D21: =if(M16<C21,"W",if(M16>C21,"L",if(isblank(C21),"","T"))) -> W | E21: 230 | F21: =if(M17<E21,"W",if(M17>E21,"L",if(isblank(E21),"","T"))) -> W | G21: 164 | H21: =if(M18<G21,"W",if(M18>G21,"L",if(isblank(G21),"","T"))) -> W | I21: 212 | J21: W | K21: 164 | L21: =if(M20<K21,"W",if(M20>K21,"L",if(isblank(K21),"","T"))) -> W | O21: 10
A23: Diadem | C23: =B24 -> Temple City | E23: =B25 -> Whitney | G23: =B26 -> Arcadia 2 | I23: =B27 -> Simi Valley | K23: =B28 -> Marshall | M23: =B29 -> St. Margaret's | O23: Points
A24: D1 | B24: Temple City | E24: 94 | F24: =if(E24>C25,"W",if(E24<C25,"L",if(isblank(E24),"","T"))) -> L | G24: 108 | H24: =if(G24>C26,"W",if(G24<C26,"L",if(isblank(G24),"","T"))) -> W | I24: 66 | J24: W | K24: 164 | L24: =if(K24>C28,"W",if(K24<C28,"L",if(isblank(K24),"","T"))) -> W | M24: 102 | N24: =if(M24>C29,"W",if(M24<C29,"L",if(isblank(M24),"","T"))) -> W | O24: 8
A25: D2 | B25: Whitney | C25: 148 | D25: =if(E24<C25,"W",if(E24>C25,"L",if(isblank(C25),"","T"))) -> W | G25: 128 | H25: =if(G25>E26,"W",if(G25<E26,"L",if(isblank(G25),"","T"))) -> W | I25: 168 | J25: W | K25: 152 | L25: =if(K25>E28,"W",if(K25<E28,"L",if(isblank(K25),"","T"))) -> W | M25: 134 | N25: =if(M25>E29,"W",if(M25<E29,"L",if(isblank(M25),"","T"))) -> W | O25: 10
A26: D3 | B26: Arcadia 2 | C26: 66 | D26: =if(G24<C26,"W",if(G24>C26,"L",if(isblank(C26),"","T"))) -> L | E26: 72 | F26: =if(G25<E26,"W",if(G25>E26,"L",if(isblank(E26),"","T"))) -> L | I26: 140 | J26: W | K26: 68 | L26: =if(K26>G28,"W",if(K26<G28,"L",if(isblank(K26),"","T"))) -> L | M26: 62 | N26: =if(M26>G29,"W",if(M26<G29,"L",if(isblank(M26),"","T"))) -> L | O26: 2
A27: D4 | B27: Simi Valley | C27: 44 | D27: L | E27: 22 | F27: L | G27: 12 | H27: L | K27: 20 | L27: L | M27: 36 | N27: L | O27: 0
A28: D5 | B28: Marshall | C28: 64 | D28: =if(K24<C28,"W",if(K24>C28,"L",if(isblank(C28),"","T"))) -> L | E28: 54 | F28: =if(K25<E28,"W",if(K25>E28,"L",if(isblank(E28),"","T"))) -> L | G28: 72 | H28: =if(K26<G28,"W",if(K26>G28,"L",if(isblank(G28),"","T"))) -> W | I28: 98 | J28: W | M28: 40 | N28: =if(M28>K29,"W",if(M28<K29,"L",if(isblank(M28),"","T"))) -> L | O28: 4
A29: D6 | B29: St. Margaret's | C29: 64 | D29: =if(M24<C29,"W",if(M24>C29,"L",if(isblank(C29),"","T"))) -> L | E29: 58 | F29: =if(M25<E29,"W",if(M25>E29,"L",if(isblank(E29),"","T"))) -> L | G29: 108 | H29: =if(M26<G29,"W",if(M26>G29,"L",if(isblank(G29),"","T"))) -> W | I29: 144 | J29: W | K29: 104 | L29: =if(M28<K29,"W",if(M28>K29,"L",if(isblank(K29),"","T"))) -> W | O29: 6

Sheet Round Robin Schedule
B1: Antares | E1: Bellatrix | H1: Copernicus | K1: Diadem
B2: Team 1 | C2: Team 2 | D2: Room | E2: Team 1 | F2: Team 2 | G2: Room | H2: Team 1 | I2: Team 2 | J2: Room | K2: Team 1 | L2: Team 2 | M2: Room
A3: Round 1 9:00-9:30 | B3: =vlookup(B19,'Round Robin Scores'!$A$1:$B999,2,false) -> Diamond Bar | C3: =vlookup(C19,'Round Robin Scores'!$A$1:$B999,2,false) -> Troy | D3: Kaplan A30 | E3: =vlookup(E19,'Round Robin Scores'!$A$1:$B999,2,false) -> Palm Desert | F3: =vlookup(F19,'Round Robin Scores'!$A$1:$B999,2,false) -> Santa Monica | G3: Kaplan A60 | H3: =vlookup(H19,'Round Robin Scores'!$A$1:$B999,2,false) -> La Canada | I3: =vlookup(I19,'Round Robin Scores'!$A$1:$B999,2,false) -> Aquinas | J3: Math Sci 5128 | K3: =vlookup(K19,'Round Robin Scores'!$A$1:$B999,2,false) -> Temple City | L3: =vlookup(L19,'Round Robin Scores'!$A$1:$B999,2,false) -> Whitney | M3: Dodd 167
B4: =vlookup(B20,'Round Robin Scores'!$A$1:$B999,2,false) -> South Pasadena | C4: BYE | E4: =vlookup(E20,'Round Robin Scores'!$A$1:$B999,2,false) -> San Marino | F4: BYE | H4: =vlookup(H20,'Round Robin Scores'!$A$1:$B999,2,false) -> Arcadia 1 | I4: University | J4: Math Sci 5118 | K4: =vlookup(K20,'Round Robin Scores'!$A$1:$B999,2,false) -> Arcadia 2 | L4: St. Margaret's | M4: Math Sci 5138
B5: =vlookup(B21,'Round Robin Scores'!$A$1:$B999,2,false) -> OCSA | C5: =vlookup(C21,'Round Robin Scores'!$A$1:$B999,2,false) -> Portola | D5: Kaplan A56 | E5: =vlookup(E21,'Round Robin Scores'!$A$1:$B999,2,false) -> Palos Verdes | F5: =vlookup(F21,'Round Robin Scores'!$A$1:$B999,2,false) -> Northwood | G5: Math Sci 5147 | H5: =vlookup(H21,'Round Robin Scores'!$A$1:$B999,2,false) -> Walnut | I5: =vlookup(I21,'Round Robin Scores'!$A$1:$B999,2,false) -> Beckman | J5: Math Sci 5127 | K5: =vlookup(K21,'Round Robin Scores'!$A$1:$B999,2,false) -> Simi Valley | L5: =vlookup(L21,'Round Robin Scores'!$A$1:$B999,2,false) -> Marshall | M5: Math Sci 5137
A6: Round 2 9:35-10:05 | B6: =vlookup(B22,'Round Robin Scores'!$A$1:$B999,2,false) -> Diamond Bar | C6: BYE | E6: =vlookup(E22,'Round Robin Scores'!$A$1:$B999,2,false) -> Palm Desert | F6: BYE | H6: =vlookup(H22,'Round Robin Scores'!$A$1:$B999,2,false) -> La Canada | I6: University | J6: Math Sci 5127 | K6: =vlookup(K22,'Round Robin Scores'!$A$1:$B999,2,false) -> Temple City | L6: St. Margaret's | M6: Math Sci 5128
B7: =vlookup(B23,'Round Robin Scores'!$A$1:$B999,2,false) -> Troy | C7: =vlookup(C23,'Round Robin Scores'!$A$1:$B999,2,false) -> Portola | D7: Kaplan A60 | E7: =vlookup(E23,'Round Robin Scores'!$A$1:$B999,2,false) -> Santa Monica | F7: =vlookup(F23,'Round Robin Scores'!$A$1:$B999,2,false) -> Northwood | G7: Kaplan A30 | H7: =vlookup(H23,'Round Robin Scores'!$A$1:$B999,2,false) -> Aquinas | I7: =vlookup(I23,'Round Robin Scores'!$A$1:$B999,2,false) -> Beckman | J7: Math Sci 5118 | K7: =vlookup(K23,'Round Robin Scores'!$A$1:$B999,2,false) -> Whitney | L7: =vlookup(L23,'Round Robin Scores'!$A$1:$B999,2,false) -> Marshall | M7: Math Sci 5137
B8: =vlookup(B24,'Round Robin Scores'!$A$1:$B999,2,false) -> South Pasadena | C8: =vlookup(C24,'Round Robin Scores'!$A$1:$B999,2,false) -> OCSA | D8: Math Sci 5147 | E8: =vlookup(E24,'Round Robin Scores'!$A$1:$B999,2,false) -> San Marino | F8: =vlookup(F24,'Round Robin Scores'!$A$1:$B999,2,false) -> Palos Verdes | G8: Kaplan A56 | H8: =vlookup(H24,'Round Robin Scores'!$A$1:$B999,2,false) -> Arcadia 1 | I8: =vlookup(I24,'Round Robin Scores'!$A$1:$B999,2,false) -> Walnut | J8: Math Sci 5138 | K8: =vlookup(K24,'Round Robin Scores'!$A$1:$B999,2,false) -> Arcadia 2 | L8: =vlookup(L24,'Round Robin Scores'!$A$1:$B999,2,false) -> Simi Valley | M8: Dodd 167
A9: Round 3 10:15-10:45 | B9: =vlookup(B25,'Round Robin Scores'!$A$1:$B999,2,false) -> Diamond Bar | C9: =vlookup(C25,'Round Robin Scores'!$A$1:$B999,2,false) -> Portola | D9: Kaplan A56 | E9: =vlookup(E25,'Round Robin Scores'!$A$1:$B999,2,false) -> Palm Desert | F9: =vlookup(F25,'Round Robin Scores'!$A$1:$B999,2,false) -> Northwood | G9: Math Sci 5147 | H9: =vlookup(H25,'Round Robin Scores'!$A$1:$B999,2,false) -> La Canada | I9: =vlookup(I25,'Round Robin Scores'!$A$1:$B999,2,false) -> Beckman | J9: Math Sci 5118 | K9: =vlookup(K25,'Round Robin Scores'!$A$1:$B999,2,false) -> Temple City | L9: =vlookup(L25,'Round Robin Scores'!$A$1:$B999,2,false) -> Marshall | M9: Dodd 167
B10: =vlookup(B26,'Round Robin Scores'!$A$1:$B999,2,false) -> Troy | C10: =vlookup(C26,'Round Robin Scores'!$A$1:$B999,2,false) -> South Pasadena | D10: Kaplan A30 | E10: =vlookup(E26,'Round Robin Scores'!$A$1:$B999,2,false) -> Santa Monica | F10: =vlookup(F26,'Round Robin Scores'!$A$1:$B999,2,false) -> San Marino | G10: Kaplan A60 | H10: =vlookup(H26,'Round Robin Scores'!$A$1:$B999,2,false) -> Aquinas | I10: =vlookup(I26,'Round Robin Scores'!$A$1:$B999,2,false) -> Arcadia 1 | J10: Math Sci 5127 | K10: =vlookup(K26,'Round Robin Scores'!$A$1:$B999,2,false) -> Whitney | L10: =vlookup(L26,'Round Robin Scores'!$A$1:$B999,2,false) -> Arcadia 2 | M10: Math Sci 5128
B11: =vlookup(B27,'Round Robin Scores'!$A$1:$B999,2,false) -> OCSA | C11: BYE | E11: =vlookup(E27,'Round Robin Scores'!$A$1:$B999,2,false) -> Palos Verdes | F11: BYE | H11: =vlookup(H27,'Round Robin Scores'!$A$1:$B999,2,false) -> Walnut | I11: University | J11: Math Sci 5138 | K11: =vlookup(K27,'Round Robin Scores'!$A$1:$B999,2,false) -> Simi Valley | L11: St. Margaret's | M11: Math Sci 5137
A12: Round 4 10:50-11:20 | B12: =vlookup(B28,'Round Robin Scores'!$A$1:$B999,2,false) -> Diamond Bar | C12: =vlookup(C28,'Round Robin Scores'!$A$1:$B999,2,false) -> OCSA | D12: Math Sci 5147 | E12: =vlookup(E28,'Round Robin Scores'!$A$1:$B999,2,false) -> Palm Desert | F12: =vlookup(F28,'Round Robin Scores'!$A$1:$B999,2,false) -> Palos Verdes | G12: Kaplan A56 | H12: =vlookup(H28,'Round Robin Scores'!$A$1:$B999,2,false) -> La Canada | I12: =vlookup(I28,'Round Robin Scores'!$A$1:$B999,2,false) -> Walnut | J12: Math Sci 5128 | K12: =vlookup(K28,'Round Robin Scores'!$A$1:$B999,2,false) -> Temple City | L12: =vlookup(L28,'Round Robin Scores'!$A$1:$B999,2,false) -> Simi Valley | M12: Math Sci 5137
B13: =vlookup(B29,'Round Robin Scores'!$A$1:$B999,2,false) -> South Pasadena | C13: =vlookup(C29,'Round Robin Scores'!$A$1:$B999,2,false) -> Portola | D13: Kaplan A60 | E13: =vlookup(E29,'Round Robin Scores'!$A$1:$B999,2,false) -> San Marino | F13: =vlookup(F29,'Round Robin Scores'!$A$1:$B999,2,false) -> Northwood | G13: Kaplan A30 | H13: =vlookup(H29,'Round Robin Scores'!$A$1:$B999,2,false) -> Arcadia 1 | I13: =vlookup(I29,'Round Robin Scores'!$A$1:$B999,2,false) -> Beckman | J13: Math Sci 5138 | K13: =vlookup(K29,'Round Robin Scores'!$A$1:$B999,2,false) -> Arcadia 2 | L13: =vlookup(L29,'Round Robin Scores'!$A$1:$B999,2,false) -> Marshall | M13: Dodd 167
B14: =vlookup(B30,'Round Robin Scores'!$A$1:$B999,2,false) -> Troy | C14: BYE | E14: =vlookup(E30,'Round Robin Scores'!$A$1:$B999,2,false) -> Santa Monica | F14: BYE | H14: =vlookup(H30,'Round Robin Scores'!$A$1:$B999,2,false) -> Aquinas | I14: University | J14: Math Sci 5127 | K14: =vlookup(K30,'Round Robin Scores'!$A$1:$B999,2,false) -> Whitney | L14: St. Margaret's | M14: Math Sci 5118
A15: Round 5 11:25-11:55 | B15: =vlookup(B31,'Round Robin Scores'!$A$1:$B999,2,false) -> Diamond Bar | C15: =vlookup(C31,'Round Robin Scores'!$A$1:$B999,2,false) -> South Pasadena | D15: Kaplan A30 | E15: =vlookup(E31,'Round Robin Scores'!$A$1:$B999,2,false) -> Palm Desert | F15: =vlookup(F31,'Round Robin Scores'!$A$1:$B999,2,false) -> San Marino | G15: Kaplan A60 | H15: =vlookup(H31,'Round Robin Scores'!$A$1:$B999,2,false) -> La Canada | I15: =vlookup(I31,'Round Robin Scores'!$A$1:$B999,2,false) -> Arcadia 1 | J15: Math Sci 5138 | K15: =vlookup(K31,'Round Robin Scores'!$A$1:$B999,2,false) -> Temple City | L15: =vlookup(L31,'Round Robin Scores'!$A$1:$B999,2,false) -> Arcadia 2 | M15: Math Sci 5118
B16: =vlookup(B32,'Round Robin Scores'!$A$1:$B999,2,false) -> Troy | C16: =vlookup(C32,'Round Robin Scores'!$A$1:$B999,2,false) -> OCSA | D16: Kaplan A56 | E16: =vlookup(E32,'Round Robin Scores'!$A$1:$B999,2,false) -> Santa Monica | F16: =vlookup(F32,'Round Robin Scores'!$A$1:$B999,2,false) -> Palos Verdes | G16: Math Sci 5147 | H16: =vlookup(H32,'Round Robin Scores'!$A$1:$B999,2,false) -> Aquinas | I16: =vlookup(I32,'Round Robin Scores'!$A$1:$B999,2,false) -> Walnut | J16: Math Sci 5128 | K16: =vlookup(K32,'Round Robin Scores'!$A$1:$B999,2,false) -> Whitney | L16: =vlookup(L32,'Round Robin Scores'!$A$1:$B999,2,false) -> Simi Valley | M16: Dodd 167
B17: =vlookup(B33,'Round Robin Scores'!$A$1:$B999,2,false) -> Portola | C17: BYE | E17: =vlookup(E33,'Round Robin Scores'!$A$1:$B999,2,false) -> Northwood | F17: BYE | H17: =vlookup(H33,'Round Robin Scores'!$A$1:$B999,2,false) -> Beckman | I17: University | J17: Math Sci 5137 | K17: =vlookup(K33,'Round Robin Scores'!$A$1:$B999,2,false) -> Marshall | L17: St. Margaret's | M17: Math Sci 5127
B19: A1 | C19: A2 | E19: B1 | F19: B2 | H19: C1 | I19: C2 | K19: D1 | L19: D2 | N19: E1 | O19: E2 | Q19: F1 | R19: F2
B20: A3 | C20: A6 | E20: B3 | F20: B6 | H20: C3 | I20: C6 | K20: D3 | L20: D6 | N20: E3 | O20: E6 | Q20: F3 | R20: F6
B21: A4 | C21: A5 | E21: B4 | F21: B5 | H21: C4 | I21: C5 | K21: D4 | L21: D5 | N21: E4 | O21: E5 | Q21: F4 | R21: F5
B22: A1 | C22: A6 | E22: B1 | F22: B6 | H22: C1 | I22: C6 | K22: D1 | L22: D6 | N22: E1 | O22: E6 | Q22: F1 | R22: F6
B23: A2 | C23: A5 | E23: B2 | F23: B5 | H23: C2 | I23: C5 | K23: D2 | L23: D5 | N23: E2 | O23: E5 | Q23: F2 | R23: F5
B24: A3 | C24: A4 | E24: B3 | F24: B4 | H24: C3 | I24: C4 | K24: D3 | L24: D4 | N24: E3 | O24: E4 | Q24: F3 | R24: F4
B25: A1 | C25: A5 | E25: B1 | F25: B5 | H25: C1 | I25: C5 | K25: D1 | L25: D5 | N25: E1 | O25: E5 | Q25: F1 | R25: F5
B26: A2 | C26: A3 | E26: B2 | F26: B3 | H26: C2 | I26: C3 | K26: D2 | L26: D3 | N26: E2 | O26: E3 | Q26: F2 | R26: F3
B27: A4 | C27: A6 | E27: B4 | F27: B6 | H27: C4 | I27: C6 | K27: D4 | L27: D6 | N27: E4 | O27: E6 | Q27: F4 | R27: F6
B28: A1 | C28: A4 | E28: B1 | F28: B4 | H28: C1 | I28: C4 | K28: D1 | L28: D4 | N28: E1 | O28: E4 | Q28: F1 | R28: F4
B29: A3 | C29: A5 | E29: B3 | F29: B5 | H29: C3 | I29: C5 | K29: D3 | L29: D5 | N29: E3 | O29: E5 | Q29: F3 | R29: F5
B30: A2 | C30: A6 | E30: B2 | F30: B6 | H30: C2 | I30: C6 | K30: D2 | L30: D6 | N30: E2 | O30: E6 | Q30: F2 | R30: F6
... B33: A5 | C33: A6 | E33: B5 | F33: B6 | H33: C5 | I33: C6 | K33: D5 | L33: D6 | N33: E5 | O33: E6 | Q33: F5 | R33: F6

Sheet Double Elimination
A1: Round 1 | C1: Round 2 | G1: Round 3 | I1: Round 4 | K1: Round 5 | M1: Finals
A2: 2:30-3:00 PM | C2: 3:05-3:35 PM | G2: 3:40-4:10 PM | I2: 4:15-4:45 PM | K2: 5:00-5:30 PM | M2: 5:35-6:30 PM
A4: University | B4: 210
A5: Kaplan A30 | D5: =iferror(vlookup(concat(C5,C9),Raw!$K$1:$L990,2,false),iferror(vlookup(concat(C5,C9),Raw!$M$1:$N990,2,false),"")) | E5: University | F5: 172
A6: Portola | B6: 64
E7: Kaplan A30 | I7: University | J7: 134
A8: San Marino | B8: 96
A9: Kaplan A56 | E9: San Marino | F9: 112
A10: Santa Monica | B10: 44
I11: Dodd 167 | L11: =iferror(vlookup(concat(K11,K22),Raw!$K$1:$L990,2,false),iferror(vlookup(concat(K11,K22),Raw!$M$1:$N990,2,false),""))
A12: Whitney | B12: 78
A13: Kaplan A60 | D13: =iferror(vlookup(concat(C13,C17),Raw!$K$1:$L990,2,false),iferror(vlookup(concat(C13,C17),Raw!$M$1:$N990,2,false),"")) | E13: Whitney | F13: 122
A14: Beckman | B14: 72
E15: Dodd 167 | I15: Whitney | J15: 126
A16: Temple City | B16: 54
A17: Dodd 167 | E17: Troy | F17: 92
A18: Troy | B18: 152
M19: University | N19: 150
M20: Haines A18
L22: =iferror(vlookup(concat(K22,K11),Raw!$K$1:$L990,2,false),iferror(vlookup(concat(K22,K11),Raw!$M$1:$N990,2,false),""))
G25: Troy | H25: 156 | K25: Whitney | L25: 54
K26: Haines A18
E27: Santa Monica | F27: 84 | G27: Kaplan A30
I28: Troy | J28: 138
E30: Kaplan A56 | G30: Santa Monica | H30: 76
M31: Troy | N31: 114
E33: Portola | F33: 78
I34: Kaplan A56
G37: San Marino | H37: 68 | K37: Troy | L37: 162
E39: Temple City | F39: 56 | G39: Kaplan A56
I40: Beckman | J40: 50
E42: Kaplan A60 | G42: Beckman | H42: 88
E45: Beckman | F45: 76

Sheet Raw
B1: =IFERROR(__xludf.DUMMYFUNCTION("importrange(""https://docs.google.com/spreadsheets/d/1sfb2iVS50i8Mp2l-Nup_CN4oz6K0oTcRctM-cGqGISI/edit?gid=133829336#gid=133829336"",""Scores!A2:E15"")"),"RR1") -> RR1 | C1: =IFERROR(__xludf.DUMMYFUNCTION("""COMPUTED_VALUE"""),"Canyon Crest A") -> Canyon Crest A | D1: =IFERROR(__xludf.DUMMYFUNCTION("""COMPUTED_VALUE"""),154.0) -> 154 | E1: =IFERROR(__xludf.DUMMYFUNCTION("""COMPUTED_VALUE"""),"North Hollywood B") -> North Hollywood B | F1: =IFERROR(__xludf.DUMMYFUNCTION("""COMPUTED_VALUE"""),62.0) -> 62 | G1: =IFERROR(__xludf.DUMMYFUNCTION("if(regexmatch($B1,""RR""),concat(C1,E1),"""")"),"Canyon Crest ANorth Hollywood B") -> Canyon Crest ANorth Hollywood B | H1: =IFERROR(__xludf.DUMMYFUNCTION("if(regexmatch($B1,""RR""),D1,"""")"),154.0) -> 154 | I1: =IFERROR(__xludf.DUMMYFUNCTION("if(regexmatch($B1,""RR""),concat(E1,C1),"""")"),"North Hollywood BCanyon Crest A") -> North Hollywood BCanyon Crest A | J1: =IFERROR(__xludf.DUMMYFUNCTION("if(regexmatch($B1,""RR""),F1,"""")"),62.0) -> 62 | K1: =IFERROR(__xludf.DUMMYFUNCTION("if(regexmatch($B1,""DE""),concat(C1,E1),"""")"),"") | L1: =IFERROR(__xludf.DUMMYFUNCTION("if(regexmatch($B1,""DE""),D1,"""")"),"") | M1: =IFERROR(__xludf.DUMMYFUNCTION("if(regexmatch($B1,""DE""),concat(E1,C1),"""")"),"") | N1: =IFERROR(__xludf.DUMMYFUNCTION("if(regexmatch($B1,""DE""),F1,"""")"),"")
B2: =IFERROR(__xludf.DUMMYFUNCTION("""COMPUTED_VALUE"""),"RR2") -> RR2 | C2: =IFERROR(__xludf.DUMMYFUNCTION("""COMPUTED_VALUE"""),"Sci Acad A") -> Sci Acad A | D2: =IFERROR(__xludf.DUMMYFUNCTION("""COMPUTED_VALUE"""),154.0) -> 154 | E2: =IFERROR(__xludf.DUMMYFUNCTION("""COMPUTED_VALUE"""),"Arcadia B") -> Arcadia B | F2: =IFERROR(__xludf.DUMMYFUNCTION("""COMPUTED_VALUE"""),44.0) -> 44 | G2: =IFERROR(__xludf.DUMMYFUNCTION("if(regexmatch($B2,""RR""),concat(C2,E2),"""")"),"Sci Acad AArcadia B") -> Sci Acad AArcadia B | H2: =IFERROR(__xludf.DUMMYFUNCTION("if(regexmatch($B2,""RR""),D2,"""")"),154.0) -> 154 | I2: =IFERROR(__xludf.DUMMYFUNCTION("if(regexmatch($B2,""RR""),concat(E2,C2),"""")"),"Arcadia BSci Acad A") -> Arcadia BSci Acad A | J2: =IFERROR(__xludf.DUMMYFUNCTION("if(regexmatch($B2,""RR""),F2,"""")"),44.0) -> 44 | K2: =IFERROR(__xludf.DUMMYFUNCTION("if(regexmatch($B2,""DE""),concat(C2,E2),"""")"),"") | L2: =IFERROR(__xludf.DUMMYFUNCTION("if(regexmatch($B2,""DE""),D2,"""")"),"") | M2: =IFERROR(__xludf.DUMMYFUNCTION("if(regexmatch($B2,""DE""),concat(E2,C2),"""")"),"") | N2: =IFERROR(__xludf.DUMMYFUNCTION("if(regexmatch($B2,""DE""),F2,"""")"),"")
B3: =IFERROR(__xludf.DUMMYFUNCTION("""COMPUTED_VALUE"""),"RR3") -> RR3 | C3: =IFERROR(__xludf.DUMMYFUNCTION("""COMPUTED_VALUE"""),"Sci Acad A") -> Sci Acad A | D3: =IFERROR(__xludf.DUMMYFUNCTION("""COMPUTED_VALUE"""),138.0) -> 138 | E3: =IFERROR(__xludf.DUMMYFUNCTION("""COMPUTED_VALUE"""),"Venice A") -> Venice A | F3: =IFERROR(__xludf.DUMMYFUNCTION("""COMPUTED_VALUE"""),100.0) -> 100 | G3: =IFERROR(__xludf.DUMMYFUNCTION("if(regexmatch($B3,""RR""),concat(C3,E3),"""")"),"Sci Acad AVenice A") -> Sci Acad AVenice A | H3: =IFERROR(__xludf.DUMMYFUNCTION("if(regexmatch($B3,""RR""),D3,"""")"),138.0) -> 138 | I3: =IFERROR(__xludf.DUMMYFUNCTION("if(regexmatch($B3,""RR""),concat(E3,C3),"""")"),"Venice ASci Acad A") -> Venice ASci Acad A | J3: =IFERROR(__xludf.DUMMYFUNCTION("if(regexmatch($B3,""RR""),F3,"""")"),100.0) -> 100 | K3: =IFERROR(__xludf.DUMMYFUNCTION("if(regexmatch($B3,""DE""),concat(C3,E3),"""")"),"") | L3: =IFERROR(__xludf.DUMMYFUNCTION("if(regexmatch($B3,""DE""),D3,"""")"),"") | M3: =IFERROR(__xludf.DUMMYFUNCTION("if(regexmatch($B3,""DE""),concat(E3,C3),"""")"),"") | N3: =IFERROR(__xludf.DUMMYFUNCTION("if(regexmatch($B3,""DE""),F3,"""")"),"")
B4: =IFERROR(__xludf.DUMMYFUNCTION("""COMPUTED_VALUE"""),"RR4") -> RR4 | C4: =IFERROR(__xludf.DUMMYFUNCTION("""COMPUTED_VALUE"""),"Sci Acad B") -> Sci Acad B | D4: =IFERROR(__xludf.DUMMYFUNCTION("""COMPUTED_VALUE"""),132.0) -> 132 | E4: =IFERROR(__xludf.DUMMYFUNCTION("""COMPUTED_VALUE"""),"Beckman A") -> Beckman A | F4: =IFERROR(__xludf.DUMMYFUNCTION("""COMPUTED_VALUE"""),68.0) -> 68 | G4: =IFERROR(__xludf.DUMMYFUNCTION("if(regexmatch($B4,""RR""),concat(C4,E4),"""")"),"Sci Acad BBeckman A") -> Sci Acad BBeckman A | H4: =IFERROR(__xludf.DUMMYFUNCTION("if(regexmatch($B4,""RR""),D4,"""")"),132.0) -> 132 | I4: =IFERROR(__xludf.DUMMYFUNCTION("if(regexmatch($B4,""RR""),concat(E4,C4),"""")"),"Beckman ASci Acad B") -> Beckman ASci Acad B | J4: =IFERROR(__xludf.DUMMYFUNCTION("if(regexmatch($B4,""RR""),F4,"""")"),68.0) -> 68 | K4: =IFERROR(__xludf.DUMMYFUNCTION("if(regexmatch($B4,""DE""),concat(C4,E4),"""")"),"") | L4: =IFERROR(__xludf.DUMMYFUNCTION("if(regexmatch($B4,""DE""),D4,"""")"),"") | M4: =IFERROR(__xludf.DUMMYFUNCTION("if(regexmatch($B4,""DE""),concat(E4,C4),"""")"),"") | N4: =IFERROR(__xludf.DUMMYFUNCTION("if(regexmatch($B4,""DE""),F4,"""")"),"")
B5: =IFERROR(__xludf.DUMMYFUNCTION("""COMPUTED_VALUE"""),"RR5") -> RR5 | C5: =IFERROR(__xludf.DUMMYFUNCTION("""COMPUTED_VALUE"""),"Canyon Crest B") -> Canyon Crest B | D5: =IFERROR(__xludf.DUMMYFUNCTION("""COMPUTED_VALUE"""),92.0) -> 92 | E5: =IFERROR(__xludf.DUMMYFUNCTION("""COMPUTED_VALUE"""),"Beckman A") -> Beckman A | F5: =IFERROR(__xludf.DUMMYFUNCTION("""COMPUTED_VALUE"""),68.0) -> 68 | G5: =IFERROR(__xludf.DUMMYFUNCTION("if(regexmatch($B5,""RR""),concat(C5,E5),"""")"),"Canyon Crest BBeckman A") -> Canyon Crest BBeckman A | H5: =IFERROR(__xludf.DUMMYFUNCTION("if(regexmatch($B5,""RR""),D5,"""")"),92.0) -> 92 | I5: =IFERROR(__xludf.DUMMYFUNCTION("if(regexmatch($B5,""RR""),concat(E5,C5),"""")"),"Beckman ACanyon Crest B") -> Beckman ACanyon Crest B | J5: =IFERROR(__xludf.DUMMYFUNCTION("if(regexmatch($B5,""RR""),F5,"""")"),68.0) -> 68 | K5: =IFERROR(__xludf.DUMMYFUNCTION("if(regexmatch($B5,""DE""),concat(C5,E5),"""")"),"") | L5: =IFERROR(__xludf.DUMMYFUNCTION("if(regexmatch($B5,""DE""),D5,"""")"),"") | M5: =IFERROR(__xludf.DUMMYFUNCTION("if(regexmatch($B5,""DE""),concat(E5,C5),"""")"),"") | N5: =IFERROR(__xludf.DUMMYFUNCTION("if(regexmatch($B5,""DE""),F5,"""")"),"")
B6: =IFERROR(__xludf.DUMMYFUNCTION("""COMPUTED_VALUE"""),"DE1") -> DE1 | C6: =IFERROR(__xludf.DUMMYFUNCTION("""COMPUTED_VALUE"""),"Granada Hills A") -> Granada Hills A | D6: =IFERROR(__xludf.DUMMYFUNCTION("""COMPUTED_VALUE"""),18.0) -> 18 | E6: =IFERROR(__xludf.DUMMYFUNCTION("""COMPUTED_VALUE"""),"North Hollywood A") -> North Hollywood A | F6: =IFERROR(__xludf.DUMMYFUNCTION("""COMPUTED_VALUE"""),138.0) -> 138 | G6: =IFERROR(__xludf.DUMMYFUNCTION("if(regexmatch($B6,""RR""),concat(C6,E6),"""")"),"") | H6: =IFERROR(__xludf.DUMMYFUNCTION("if(regexmatch($B6,""RR""),D6,"""")"),"") | I6: =IFERROR(__xludf.DUMMYFUNCTION("if(regexmatch($B6,""RR""),concat(E6,C6),"""")"),"") | J6: =IFERROR(__xludf.DUMMYFUNCTION("if(regexmatch($B6,""RR""),F6,"""")"),"") | K6: =IFERROR(__xludf.DUMMYFUNCTION("if(regexmatch($B6,""DE""),concat(C6,E6),"""")"),"Granada Hills ANorth Hollywood A") -> Granada Hills ANorth Hollywood A | L6: =IFERROR(__xludf.DUMMYFUNCTION("if(regexmatch($B6,""DE""),D6,"""")"),18.0) -> 18 | M6: =IFERROR(__xludf.DUMMYFUNCTION("if(regexmatch($B6,""DE""),concat(E6,C6),"""")"),"North Hollywood AGranada Hills A") -> North Hollywood AGranada Hills A | N6: =IFERROR(__xludf.DUMMYFUNCTION("if(regexmatch($B6,""DE""),F6,"""")"),138.0) -> 138
B7: =IFERROR(__xludf.DUMMYFUNCTION("""COMPUTED_VALUE"""),"DE2") -> DE2 | C7: =IFERROR(__xludf.DUMMYFUNCTION("""COMPUTED_VALUE"""),"Canyon Crest B") -> Canyon Crest B | D7: =IFERROR(__xludf.DUMMYFUNCTION("""COMPUTED_VALUE"""),66.0) -> 66 | E7: =IFERROR(__xludf.DUMMYFUNCTION("""COMPUTED_VALUE"""),"OCSA") -> OCSA | F7: =IFERROR(__xludf.DUMMYFUNCTION("""COMPUTED_VALUE"""),118.0) -> 118 | G7: =IFERROR(__xludf.DUMMYFUNCTION("if(regexmatch($B7,""RR""),concat(C7,E7),"""")"),"") | H7: =IFERROR(__xludf.DUMMYFUNCTION("if(regexmatch($B7,""RR""),D7,"""")"),"") | I7: =IFERROR(__xludf.DUMMYFUNCTION("if(regexmatch($B7,""RR""),concat(E7,C7),"""")"),"") | J7: =IFERROR(__xludf.DUMMYFUNCTION("if(regexmatch($B7,""RR""),F7,"""")"),"") | K7: =IFERROR(__xludf.DUMMYFUNCTION("if(regexmatch($B7,""DE""),concat(C7,E7),"""")"),"Canyon Crest BOCSA") -> Canyon Crest BOCSA | L7: =IFERROR(__xludf.DUMMYFUNCTION("if(regexmatch($B7,""DE""),D7,"""")"),66.0) -> 66 | M7: =IFERROR(__xludf.DUMMYFUNCTION("if(regexmatch($B7,""DE""),concat(E7,C7),"""")"),"OCSACanyon Crest B") -> OCSACanyon Crest B | N7: =IFERROR(__xludf.DUMMYFUNCTION("if(regexmatch($B7,""DE""),F7,"""")"),118.0) -> 118
B8: =IFERROR(__xludf.DUMMYFUNCTION("""COMPUTED_VALUE"""),"DE3") -> DE3 | C8: =IFERROR(__xludf.DUMMYFUNCTION("""COMPUTED_VALUE"""),"Venice A") -> Venice A | D8: =IFERROR(__xludf.DUMMYFUNCTION("""COMPUTED_VALUE"""),86.0) -> 86 | E8: =IFERROR(__xludf.DUMMYFUNCTION("""COMPUTED_VALUE"""),"University") -> University | F8: =IFERROR(__xludf.DUMMYFUNCTION("""COMPUTED_VALUE"""),54.0) -> 54 | G8: =IFERROR(__xludf.DUMMYFUNCTION("if(regexmatch($B8,""RR""),concat(C8,E8),"""")"),"") | H8: =IFERROR(__xludf.DUMMYFUNCTION("if(regexmatch($B8,""RR""),D8,"""")"),"") | I8: =IFERROR(__xludf.DUMMYFUNCTION("if(regexmatch($B8,""RR""),concat(E8,C8),"""")"),"") | J8: =IFERROR(__xludf.DUMMYFUNCTION("if(regexmatch($B8,""RR""),F8,"""")"),"") | K8: =IFERROR(__xludf.DUMMYFUNCTION("if(regexmatch($B8,""DE""),concat(C8,E8),"""")"),"Venice AUniversity") -> Venice AUniversity | L8: =IFERROR(__xludf.DUMMYFUNCTION("if(regexmatch($B8,""DE""),D8,"""")"),86.0) -> 86 | M8: =IFERROR(__xludf.DUMMYFUNCTION("if(regexmatch($B8,""DE""),concat(E8,C8),"""")"),"UniversityVenice A") -> UniversityVenice A | N8: =IFERROR(__xludf.DUMMYFUNCTION("if(regexmatch($B8,""DE""),F8,"""")"),54.0) -> 54
B9: =IFERROR(__xludf.DUMMYFUNCTION("""COMPUTED_VALUE"""),"DE4") -> DE4 | C9: =IFERROR(__xludf.DUMMYFUNCTION("""COMPUTED_VALUE"""),"[Select Team Name]") -> [Select Team Name] | D9: =IFERROR(__xludf.DUMMYFUNCTION("""COMPUTED_VALUE"""),0.0) -> 0 | E9: =IFERROR(__xludf.DUMMYFUNCTION("""COMPUTED_VALUE"""),"[Select Team Name]") -> [Select Team Name] | F9: =IFERROR(__xludf.DUMMYFUNCTION("""COMPUTED_VALUE"""),0.0) -> 0 | G9: =IFERROR(__xludf.DUMMYFUNCTION("if(regexmatch($B9,""RR""),concat(C9,E9),"""")"),"") | H9: =IFERROR(__xludf.DUMMYFUNCTION("if(regexmatch($B9,""RR""),D9,"""")"),"") | I9: =IFERROR(__xludf.DUMMYFUNCTION("if(regexmatch($B9,""RR""),concat(E9,C9),"""")"),"") | J9: =IFERROR(__xludf.DUMMYFUNCTION("if(regexmatch($B9,""RR""),F9,"""")"),"") | K9: =IFERROR(__xludf.DUMMYFUNCTION("if(regexmatch($B9,""DE""),concat(C9,E9),"""")"),"[Select Team Name][Select Team Name]") -> [Select Team Name][Select Team Name] | L9: =IFERROR(__xludf.DUMMYFUNCTION("if(regexmatch($B9,""DE""),D9,"""")"),0.0) -> 0 | M9: =IFERROR(__xludf.DUMMYFUNCTION("if(regexmatch($B9,""DE""),concat(E9,C9),"""")"),"[Select Team Name][Select Team Name]") -> [Select Team Name][Select Team Name] | N9: =IFERROR(__xludf.DUMMYFUNCTION("if(regexmatch($B9,""DE""),F9,"""")"),0.0) -> 0
B10: =IFERROR(__xludf.DUMMYFUNCTION("""COMPUTED_VALUE"""),"DE5") -> DE5 | C10: =IFERROR(__xludf.DUMMYFUNCTION("""COMPUTED_VALUE"""),"[Select Team Name]") -> [Select Team Name] | D10: =IFERROR(__xludf.DUMMYFUNCTION("""COMPUTED_VALUE"""),0.0) -> 0 | E10: =IFERROR(__xludf.DUMMYFUNCTION("""COMPUTED_VALUE"""),"[Select Team Name]") -> [Select Team Name] | F10: =IFERROR(__xludf.DUMMYFUNCTION("""COMPUTED_VALUE"""),0.0) -> 0 | G10: =IFERROR(__xludf.DUMMYFUNCTION("if(regexmatch($B10,""RR""),concat(C10,E10),"""")"),"") | H10: =IFERROR(__xludf.DUMMYFUNCTION("if(regexmatch($B10,""RR""),D10,"""")"),"") | I10: =IFERROR(__xludf.DUMMYFUNCTION("if(regexmatch($B10,""RR""),concat(E10,C10),"""")"),"") | J10: =IFERROR(__xludf.DUMMYFUNCTION("if(regexmatch($B10,""RR""),F10,"""")"),"") | K10: =IFERROR(__xludf.DUMMYFUNCTION("if(regexmatch($B10,""DE""),concat(C10,E10),"""")"),"[Select Team Name][Select Team Name]") -> [Select Team Name][Select Team Name] | L10: =IFERROR(__xludf.DUMMYFUNCTION("if(regexmatch($B10,""DE""),D10,"""")"),0.0) -> 0 | M10: =IFERROR(__xludf.DUMMYFUNCTION("if(regexmatch($B10,""DE""),concat(E10,C10),"""")"),"[Select Team Name][Select Team Name]") -> [Select Team Name][Select Team Name] | N10: =IFERROR(__xludf.DUMMYFUNCTION("if(regexmatch($B10,""DE""),F10,"""")"),0.0) -> 0
B11: =IFERROR(__xludf.DUMMYFUNCTION("""COMPUTED_VALUE"""),"DE6") -> DE6 | C11: =IFERROR(__xludf.DUMMYFUNCTION("""COMPUTED_VALUE"""),"[Select Team Name]") -> [Select Team Name] | D11: =IFERROR(__xludf.DUMMYFUNCTION("""COMPUTED_VALUE"""),0.0) -> 0 | E11: =IFERROR(__xludf.DUMMYFUNCTION("""COMPUTED_VALUE"""),"[Select Team Name]") -> [Select Team Name] | F11: =IFERROR(__xludf.DUMMYFUNCTION("""COMPUTED_VALUE"""),0.0) -> 0 | G11: =IFERROR(__xludf.DUMMYFUNCTION("if(regexmatch($B11,""RR""),concat(C11,E11),"""")"),"") | H11: =IFERROR(__xludf.DUMMYFUNCTION("if(regexmatch($B11,""RR""),D11,"""")"),"") | I11: =IFERROR(__xludf.DUMMYFUNCTION("if(regexmatch($B11,""RR""),concat(E11,C11),"""")"),"") | J11: =IFERROR(__xludf.DUMMYFUNCTION("if(regexmatch($B11,""RR""),F11,"""")"),"") | K11: =IFERROR(__xludf.DUMMYFUNCTION("if(regexmatch($B11,""DE""),concat(C11,E11),"""")"),"[Select Team Name][Select Team Name]") -> [Select Team Name][Select Team Name] | L11: =IFERROR(__xludf.DUMMYFUNCTION("if(regexmatch($B11,""DE""),D11,"""")"),0.0) -> 0 | M11: =IFERROR(__xludf.DUMMYFUNCTION("if(regexmatch($B11,""DE""),concat(E11,C11),"""")"),"[Select Team Name][Select Team Name]") -> [Select Team Name][Select Team Name] | N11: =IFERROR(__xludf.DUMMYFUNCTION("if(regexmatch($B11,""DE""),F11,"""")"),0.0) -> 0
B12: =IFERROR(__xludf.DUMMYFUNCTION("""COMPUTED_VALUE"""),"DE7") -> DE7 | C12: =IFERROR(__xludf.DUMMYFUNCTION("""COMPUTED_VALUE"""),"[Select Team Name]") -> [Select Team Name] | D12: =IFERROR(__xludf.DUMMYFUNCTION("""COMPUTED_VALUE"""),0.0) -> 0 | E12: =IFERROR(__xludf.DUMMYFUNCTION("""COMPUTED_VALUE"""),"[Select Team Name]") -> [Select Team Name] | F12: =IFERROR(__xludf.DUMMYFUNCTION("""COMPUTED_VALUE"""),0.0) -> 0 | G12: =IFERROR(__xludf.DUMMYFUNCTION("if(regexmatch($B12,""RR""),concat(C12,E12),"""")"),"") | H12: =IFERROR(__xludf.DUMMYFUNCTION("if(regexmatch($B12,""RR""),D12,"""")"),"") | I12: =IFERROR(__xludf.DUMMYFUNCTION("if(regexmatch($B12,""RR""),concat(E12,C12),"""")"),"") | J12: =IFERROR(__xludf.DUMMYFUNCTION("if(regexmatch($B12,""RR""),F12,"""")"),"") | K12: =IFERROR(__xludf.DUMMYFUNCTION("if(regexmatch($B12,""DE""),concat(C12,E12),"""")"),"[Select Team Name][Select Team Name]") -> [Select Team Name][Select Team Name] | L12: =IFERROR(__xludf.DUMMYFUNCTION("if(regexmatch($B12,""DE""),D12,"""")"),0.0) -> 0 | M12: =IFERROR(__xludf.DUMMYFUNCTION("if(regexmatch($B12,""DE""),concat(E12,C12),"""")"),"[Select Team Name][Select Team Name]") -> [Select Team Name][Select Team Name] | N12: =IFERROR(__xludf.DUMMYFUNCTION("if(regexmatch($B12,""DE""),F12,"""")"),0.0) -> 0
B13: =IFERROR(__xludf.DUMMYFUNCTION("""COMPUTED_VALUE"""),"DE8") -> DE8 | C13: =IFERROR(__xludf.DUMMYFUNCTION("""COMPUTED_VALUE"""),"[Select Team Name]") -> [Select Team Name] | D13: =IFERROR(__xludf.DUMMYFUNCTION("""COMPUTED_VALUE"""),0.0) -> 0 | E13: =IFERROR(__xludf.DUMMYFUNCTION("""COMPUTED_VALUE"""),"[Select Team Name]") -> [Select Team Name] | F13: =IFERROR(__xludf.DUMMYFUNCTION("""COMPUTED_VALUE"""),0.0) -> 0 | G13: =IFERROR(__xludf.DUMMYFUNCTION("if(regexmatch($B13,""RR""),concat(C13,E13),"""")"),"") | H13: =IFERROR(__xludf.DUMMYFUNCTION("if(regexmatch($B13,""RR""),D13,"""")"),"") | I13: =IFERROR(__xludf.DUMMYFUNCTION("if(regexmatch($B13,""RR""),concat(E13,C13),"""")"),"") | J13: =IFERROR(__xludf.DUMMYFUNCTION("if(regexmatch($B13,""RR""),F13,"""")"),"") | K13: =IFERROR(__xludf.DUMMYFUNCTION("if(regexmatch($B13,""DE""),concat(C13,E13),"""")"),"[Select Team Name][Select Team Name]") -> [Select Team Name][Select Team Name] | L13: =IFERROR(__xludf.DUMMYFUNCTION("if(regexmatch($B13,""DE""),D13,"""")"),0.0) -> 0 | M13: =IFERROR(__xludf.DUMMYFUNCTION("if(regexmatch($B13,""DE""),concat(E13,C13),"""")"),"[Select Team Name][Select Team Name]") -> [Select Team Name][Select Team Name] | N13: =IFERROR(__xludf.DUMMYFUNCTION("if(regexmatch($B13,""DE""),F13,"""")"),0.0) -> 0
B14: =IFERROR(__xludf.DUMMYFUNCTION("""COMPUTED_VALUE"""),"DE9") -> DE9 | C14: =IFERROR(__xludf.DUMMYFUNCTION("""COMPUTED_VALUE"""),"[Select Team Name]") -> [Select Team Name] | D14: =IFERROR(__xludf.DUMMYFUNCTION("""COMPUTED_VALUE"""),0.0) -> 0 | E14: =IFERROR(__xludf.DUMMYFUNCTION("""COMPUTED_VALUE"""),"[Select Team Name]") -> [Select Team Name] | F14: =IFERROR(__xludf.DUMMYFUNCTION("""COMPUTED_VALUE"""),0.0) -> 0 | G14: =IFERROR(__xludf.DUMMYFUNCTION("if(regexmatch($B14,""RR""),concat(C14,E14),"""")"),"") | H14: =IFERROR(__xludf.DUMMYFUNCTION("if(regexmatch($B14,""RR""),D14,"""")"),"") | I14: =IFERROR(__xludf.DUMMYFUNCTION("if(regexmatch($B14,""RR""),concat(E14,C14),"""")"),"") | J14: =IFERROR(__xludf.DUMMYFUNCTION("if(regexmatch($B14,""RR""),F14,"""")"),"") | K14: =IFERROR(__xludf.DUMMYFUNCTION("if(regexmatch($B14,""DE""),concat(C14,E14),"""")"),"[Select Team Name][Select Team Name]") -> [Select Team Name][Select Team Name] | L14: =IFERROR(__xludf.DUMMYFUNCTION("if(regexmatch($B14,""DE""),D14,"""")"),0.0) -> 0 | M14: =IFERROR(__xludf.DUMMYFUNCTION("if(regexmatch($B14,""DE""),concat(E14,C14),"""")"),"[Select Team Name][Select Team Name]") -> [Select Team Name][Select Team Name] | N14: =IFERROR(__xludf.DUMMYFUNCTION("if(regexmatch($B14,""DE""),F14,"""")"),0.0) -> 0
B15: =IFERROR(__xludf.DUMMYFUNCTION("importrange(""https://docs.google.com/spreadsheets/d/1PrHA2qOcRnj3qQiPlEjCIGgdoTa2xExIam1kz3NVJno/edit?gid=0#gid=0"",""Scores!A2:E15"")"),"RR1") -> RR1 | C15: =IFERROR(__xludf.DUMMYFUNCTION("""COMPUTED_VALUE"""),"Granada Hills A") -> Granada Hills A | D15: =IFERROR(__xludf.DUMMYFUNCTION("""COMPUTED_VALUE"""),72.0) -> 72 | E15: =IFERROR(__xludf.DUMMYFUNCTION("""COMPUTED_VALUE"""),"Oak Avenue") -> Oak Avenue | F15: =IFERROR(__xludf.DUMMYFUNCTION("""COMPUTED_VALUE"""),68.0) -> 68 | G15: =IFERROR(__xludf.DUMMYFUNCTION("if(regexmatch($B15,""RR""),concat(C15,E15),"""")"),"Granada Hills AOak Avenue") -> Granada Hills AOak Avenue | H15: =IFERROR(__xludf.DUMMYFUNCTION("if(regexmatch($B15,""RR""),D15,"""")"),72.0) -> 72 | I15: =IFERROR(__xludf.DUMMYFUNCTION("if(regexmatch($B15,""RR""),concat(E15,C15),"""")"),"Oak AvenueGranada Hills A") -> Oak AvenueGranada Hills A | J15: =IFERROR(__xludf.DUMMYFUNCTION("if(regexmatch($B15,""RR""),F15,"""")"),68.0) -> 68 | K15: =IFERROR(__xludf.DUMMYFUNCTION("if(regexmatch($B15,""DE""),concat(C15,E15),"""")"),"") | L15: =IFERROR(__xludf.DUMMYFUNCTION("if(regexmatch($B15,""DE""),D15,"""")"),"") | M15: =IFERROR(__xludf.DUMMYFUNCTION("if(regexmatch($B15,""DE""),concat(E15,C15),"""")"),"") | N15: =IFERROR(__xludf.DUMMYFUNCTION("if(regexmatch($B15,""DE""),F15,"""")"),"")
B16: =IFERROR(__xludf.DUMMYFUNCTION("""COMPUTED_VALUE"""),"RR2") -> RR2 | C16: =IFERROR(__xludf.DUMMYFUNCTION("""COMPUTED_VALUE"""),"North Hollywood B") -> North Hollywood B | D16: =IFERROR(__xludf.DUMMYFUNCTION("""COMPUTED_VALUE"""),54.0) -> 54 | E16: =IFERROR(__xludf.DUMMYFUNCTION("""COMPUTED_VALUE"""),"Oak Avenue") -> Oak Avenue | F16: =IFERROR(__xludf.DUMMYFUNCTION("""COMPUTED_VALUE"""),86.0) -> 86 | G16: =IFERROR(__xludf.DUMMYFUNCTION("if(regexmatch($B16,""RR""),concat(C16,E16),"""")"),"North Hollywood BOak Avenue") -> North Hollywood BOak Avenue | H16: =IFERROR(__xludf.DUMMYFUNCTION("if(regexmatch($B16,""RR""),D16,"""")"),54.0) -> 54 | I16: =IFERROR(__xludf.DUMMYFUNCTION("if(regexmatch($B16,""RR""),concat(E16,C16),"""")"),"Oak AvenueNorth Hollywood B") -> Oak AvenueNorth Hollywood B | J16: =IFERROR(__xludf.DUMMYFUNCTION("if(regexmatch($B16,""RR""),F16,"""")"),86.0) -> 86 | K16: =IFERROR(__xludf.DUMMYFUNCTION("if(regexmatch($B16,""DE""),concat(C16,E16),"""")"),"") | L16: =IFERROR(__xludf.DUMMYFUNCTION("if(regexmatch($B16,""DE""),D16,"""")"),"") | M16: =IFERROR(__xludf.DUMMYFUNCTION("if(regexmatch($B16,""DE""),concat(E16,C16),"""")"),"") | N16: =IFERROR(__xludf.DUMMYFUNCTION("if(regexmatch($B16,""DE""),F16,"""")"),"")
B17: =IFERROR(__xludf.DUMMYFUNCTION("""COMPUTED_VALUE"""),"RR3") -> RR3 | C17: =IFERROR(__xludf.DUMMYFUNCTION("""COMPUTED_VALUE"""),"Arcadia B") -> Arcadia B | D17: =IFERROR(__xludf.DUMMYFUNCTION("""COMPUTED_VALUE"""),104.0) -> 104 | E17: =IFERROR(__xludf.DUMMYFUNCTION("""COMPUTED_VALUE"""),"University") -> University | F17: =IFERROR(__xludf.DUMMYFUNCTION("""COMPUTED_VALUE"""),114.0) -> 114 | G17: =IFERROR(__xludf.DUMMYFUNCTION("if(regexmatch($B17,""RR""),concat(C17,E17),"""")"),"Arcadia BUniversity") -> Arcadia BUniversity | H17: =IFERROR(__xludf.DUMMYFUNCTION("if(regexmatch($B17,""RR""),D17,"""")"),104.0) -> 104 | I17: =IFERROR(__xludf.DUMMYFUNCTION("if(regexmatch($B17,""RR""),concat(E17,C17),"""")"),"UniversityArcadia B") -> UniversityArcadia B | J17: =IFERROR(__xludf.DUMMYFUNCTION("if(regexmatch($B17,""RR""),F17,"""")"),114.0) -> 114 | K17: =IFERROR(__xludf.DUMMYFUNCTION("if(regexmatch($B17,""DE""),concat(C17,E17),"""")"),"") | L17: =IFERROR(__xludf.DUMMYFUNCTION("if(regexmatch($B17,""DE""),D17,"""")"),"") | M17: =IFERROR(__xludf.DUMMYFUNCTION("if(regexmatch($B17,""DE""),concat(E17,C17),"""")"),"") | N17: =IFERROR(__xludf.DUMMYFUNCTION("if(regexmatch($B17,""DE""),F17,"""")"),"")
B18: =IFERROR(__xludf.DUMMYFUNCTION("""COMPUTED_VALUE"""),"RR4") -> RR4 | C18: =IFERROR(__xludf.DUMMYFUNCTION("""COMPUTED_VALUE"""),"Westview") -> Westview | D18: =IFERROR(__xludf.DUMMYFUNCTION("""COMPUTED_VALUE"""),48.0) -> 48 | E18: =IFERROR(__xludf.DUMMYFUNCTION("""COMPUTED_VALUE"""),"Canyon Crest B") -> Canyon Crest B | F18: =IFERROR(__xludf.DUMMYFUNCTION("""COMPUTED_VALUE"""),76.0) -> 76 | G18: =IFERROR(__xludf.DUMMYFUNCTION("if(regexmatch($B18,""RR""),concat(C18,E18),"""")"),"WestviewCanyon Crest B") -> WestviewCanyon Crest B | H18: =IFERROR(__xludf.DUMMYFUNCTION("if(regexmatch($B18,""RR""),D18,"""")"),48.0) -> 48 | I18: =IFERROR(__xludf.DUMMYFUNCTION("if(regexmatch($B18,""RR""),concat(E18,C18),"""")"),"Canyon Crest BWestview") -> Canyon Crest BWestview | J18: =IFERROR(__xludf.DUMMYFUNCTION("if(regexmatch($B18,""RR""),F18,"""")"),76.0) -> 76 | K18: =IFERROR(__xludf.DUMMYFUNCTION("if(regexmatch($B18,""DE""),concat(C18,E18),"""")"),"") | L18: =IFERROR(__xludf.DUMMYFUNCTION("if(regexmatch($B18,""DE""),D18,"""")"),"") | M18: =IFERROR(__xludf.DUMMYFUNCTION("if(regexmatch($B18,""DE""),concat(E18,C18),"""")"),"") | N18: =IFERROR(__xludf.DUMMYFUNCTION("if(regexmatch($B18,""DE""),F18,"""")"),"")
B19: =IFERROR(__xludf.DUMMYFUNCTION("""COMPUTED_VALUE"""),"RR5") -> RR5 | C19: =IFERROR(__xludf.DUMMYFUNCTION("""COMPUTED_VALUE"""),"Canyon Crest A") -> Canyon Crest A | D19: =IFERROR(__xludf.DUMMYFUNCTION("""COMPUTED_VALUE"""),170.0) -> 170 | E19: =IFERROR(__xludf.DUMMYFUNCTION("""COMPUTED_VALUE"""),"Beckman B") -> Beckman B | F19: =IFERROR(__xludf.DUMMYFUNCTION("""COMPUTED_VALUE"""),34.0) -> 34 | G19: =IFERROR(__xludf.DUMMYFUNCTION("if(regexmatch($B19,""RR""),concat(C19,E19),"""")"),"Canyon Crest ABeckman B") -> Canyon Crest ABeckman B | H19: =IFERROR(__xludf.DUMMYFUNCTION("if(regexmatch($B19,""RR""),D19,"""")"),170.0) -> 170 | I19: =IFERROR(__xludf.DUMMYFUNCTION("if(regexmatch($B19,""RR""),concat(E19,C19),"""")"),"Beckman BCanyon Crest A") -> Beckman BCanyon Crest A | J19: =IFERROR(__xludf.DUMMYFUNCTION("if(regexmatch($B19,""RR""),F19,"""")"),34.0) -> 34 | K19: =IFERROR(__xludf.DUMMYFUNCTION("if(regexmatch($B19,""DE""),concat(C19,E19),"""")"),"") | L19: =IFERROR(__xludf.DUMMYFUNCTION("if(regexmatch($B19,""DE""),D19,"""")"),"") | M19: =IFERROR(__xludf.DUMMYFUNCTION("if(regexmatch($B19,""DE""),concat(E19,C19),"""")"),"") | N19: =IFERROR(__xludf.DUMMYFUNCTION("if(regexmatch($B19,""DE""),F19,"""")"),"")
B20: =IFERROR(__xludf.DUMMYFUNCTION("""COMPUTED_VALUE"""),"DE1") -> DE1 | C20: =IFERROR(__xludf.DUMMYFUNCTION("""COMPUTED_VALUE"""),"[Select Team Name]") -> [Select Team Name] | D20: =IFERROR(__xludf.DUMMYFUNCTION("""COMPUTED_VALUE"""),0.0) -> 0 | E20: =IFERROR(__xludf.DUMMYFUNCTION("""COMPUTED_VALUE"""),"[Select Team Name]") -> [Select Team Name] | F20: =IFERROR(__xludf.DUMMYFUNCTION("""COMPUTED_VALUE"""),0.0) -> 0 | G20: =IFERROR(__xludf.DUMMYFUNCTION("if(regexmatch($B20,""RR""),concat(C20,E20),"""")"),"") | H20: =IFERROR(__xludf.DUMMYFUNCTION("if(regexmatch($B20,""RR""),D20,"""")"),"") | I20: =IFERROR(__xludf.DUMMYFUNCTION("if(regexmatch($B20,""RR""),concat(E20,C20),"""")"),"") | J20: =IFERROR(__xludf.DUMMYFUNCTION("if(regexmatch($B20,""RR""),F20,"""")"),"") | K20: =IFERROR(__xludf.DUMMYFUNCTION("if(regexmatch($B20,""DE""),concat(C20,E20),"""")"),"[Select Team Name][Select Team Name]") -> [Select Team Name][Select Team Name] | L20: =IFERROR(__xludf.DUMMYFUNCTION("if(regexmatch($B20,""DE""),D20,"""")"),0.0) -> 0 | M20: =IFERROR(__xludf.DUMMYFUNCTION("if(regexmatch($B20,""DE""),concat(E20,C20),"""")"),"[Select Team Name][Select Team Name]") -> [Select Team Name][Select Team Name] | N20: =IFERROR(__xludf.DUMMYFUNCTION("if(regexmatch($B20,""DE""),F20,"""")"),0.0) -> 0
B21: =IFERROR(__xludf.DUMMYFUNCTION("""COMPUTED_VALUE"""),"DE2") -> DE2 | C21: =IFERROR(__xludf.DUMMYFUNCTION("""COMPUTED_VALUE"""),"[Select Team Name]") -> [Select Team Name] | D21: =IFERROR(__xludf.DUMMYFUNCTION("""COMPUTED_VALUE"""),0.0) -> 0 | E21: =IFERROR(__xludf.DUMMYFUNCTION("""COMPUTED_VALUE"""),"[Select Team Name]") -> [Select Team Name] | F21: =IFERROR(__xludf.DUMMYFUNCTION("""COMPUTED_VALUE"""),0.0) -> 0 | G21: =IFERROR(__xludf.DUMMYFUNCTION("if(regexmatch($B21,""RR""),concat(C21,E21),"""")"),"") | H21: =IFERROR(__xludf.DUMMYFUNCTION("if(regexmatch($B21,""RR""),D21,"""")"),"") | I21: =IFERROR(__xludf.DUMMYFUNCTION("if(regexmatch($B21,""RR""),concat(E21,C21),"""")"),"") | J21: =IFERROR(__xludf.DUMMYFUNCTION("if(regexmatch($B21,""RR""),F21,"""")"),"") | K21: =IFERROR(__xludf.DUMMYFUNCTION("if(regexmatch($B21,""DE""),concat(C21,E21),"""")"),"[Select Team Name][Select Team Name]") -> [Select Team Name][Select Team Name] | L21: =IFERROR(__xludf.DUMMYFUNCTION("if(regexmatch($B21,""DE""),D21,"""")"),0.0) -> 0 | M21: =IFERROR(__xludf.DUMMYFUNCTION("if(regexmatch($B21,""DE""),concat(E21,C21),"""")"),"[Select Team Name][Select Team Name]") -> [Select Team Name][Select Team Name] | N21: =IFERROR(__xludf.DUMMYFUNCTION("if(regexmatch($B21,""DE""),F21,"""")"),0.0) -> 0
B22: =IFERROR(__xludf.DUMMYFUNCTION("""COMPUTED_VALUE"""),"DE3") -> DE3 | C22: =IFERROR(__xludf.DUMMYFUNCTION("""COMPUTED_VALUE"""),"[Select Team Name]") -> [Select Team Name] | D22: =IFERROR(__xludf.DUMMYFUNCTION("""COMPUTED_VALUE"""),0.0) -> 0 | E22: =IFERROR(__xludf.DUMMYFUNCTION("""COMPUTED_VALUE"""),"[Select Team Name]") -> [Select Team Name] | F22: =IFERROR(__xludf.DUMMYFUNCTION("""COMPUTED_VALUE"""),0.0) -> 0 | G22: =IFERROR(__xludf.DUMMYFUNCTION("if(regexmatch($B22,""RR""),concat(C22,E22),"""")"),"") | H22: =IFERROR(__xludf.DUMMYFUNCTION("if(regexmatch($B22,""RR""),D22,"""")"),"") | I22: =IFERROR(__xludf.DUMMYFUNCTION("if(regexmatch($B22,""RR""),concat(E22,C22),"""")"),"") | J22: =IFERROR(__xludf.DUMMYFUNCTION("if(regexmatch($B22,""RR""),F22,"""")"),"") | K22: =IFERROR(__xludf.DUMMYFUNCTION("if(regexmatch($B22,""DE""),concat(C22,E22),"""")"),"[Select Team Name][Select Team Name]") -> [Select Team Name][Select Team Name] | L22: =IFERROR(__xludf.DUMMYFUNCTION("if(regexmatch($B22,""DE""),D22,"""")"),0.0) -> 0 | M22: =IFERROR(__xludf.DUMMYFUNCTION("if(regexmatch($B22,""DE""),concat(E22,C22),"""")"),"[Select Team Name][Select Team Name]") -> [Select Team Name][Select Team Name] | N22: =IFERROR(__xludf.DUMMYFUNCTION("if(regexmatch($B22,""DE""),F22,"""")"),0.0) -> 0
B23: =IFERROR(__xludf.DUMMYFUNCTION("""COMPUTED_VALUE"""),"DE4") -> DE4 | C23: =IFERROR(__xludf.DUMMYFUNCTION("""COMPUTED_VALUE"""),"[Select Team Name]") -> [Select Team Name] | D23: =IFERROR(__xludf.DUMMYFUNCTION("""COMPUTED_VALUE"""),0.0) -> 0 | E23: =IFERROR(__xludf.DUMMYFUNCTION("""COMPUTED_VALUE"""),"[Select Team Name]") -> [Select Team Name] | F23: =IFERROR(__xludf.DUMMYFUNCTION("""COMPUTED_VALUE"""),0.0) -> 0 | G23: =IFERROR(__xludf.DUMMYFUNCTION("if(regexmatch($B23,""RR""),concat(C23,E23),"""")"),"") | H23: =IFERROR(__xludf.DUMMYFUNCTION("if(regexmatch($B23,""RR""),D23,"""")"),"") | I23: =IFERROR(__xludf.DUMMYFUNCTION("if(regexmatch($B23,""RR""),concat(E23,C23),"""")"),"") | J23: =IFERROR(__xludf.DUMMYFUNCTION("if(regexmatch($B23,""RR""),F23,"""")"),"") | K23: =IFERROR(__xludf.DUMMYFUNCTION("if(regexmatch($B23,""DE""),concat(C23,E23),"""")"),"[Select Team Name][Select Team Name]") -> [Select Team Name][Select Team Name] | L23: =IFERROR(__xludf.DUMMYFUNCTION("if(regexmatch($B23,""DE""),D23,"""")"),0.0) -> 0 | M23: =IFERROR(__xludf.DUMMYFUNCTION("if(regexmatch($B23,""DE""),concat(E23,C23),"""")"),"[Select Team Name][Select Team Name]") -> [Select Team Name][Select Team Name] | N23: =IFERROR(__xludf.DUMMYFUNCTION("if(regexmatch($B23,""DE""),F23,"""")"),0.0) -> 0
B24: =IFERROR(__xludf.DUMMYFUNCTION("""COMPUTED_VALUE"""),"DE5") -> DE5 | C24: =IFERROR(__xludf.DUMMYFUNCTION("""COMPUTED_VALUE"""),"[Select Team Name]") -> [Select Team Name] | D24: =IFERROR(__xludf.DUMMYFUNCTION("""COMPUTED_VALUE"""),0.0) -> 0 | E24: =IFERROR(__xludf.DUMMYFUNCTION("""COMPUTED_VALUE"""),"[Select Team Name]") -> [Select Team Name] | F24: =IFERROR(__xludf.DUMMYFUNCTION("""COMPUTED_VALUE"""),0.0) -> 0 | G24: =IFERROR(__xludf.DUMMYFUNCTION("if(regexmatch($B24,""RR""),concat(C24,E24),"""")"),"") | H24: =IFERROR(__xludf.DUMMYFUNCTION("if(regexmatch($B24,""RR""),D24,"""")"),"") | I24: =IFERROR(__xludf.DUMMYFUNCTION("if(regexmatch($B24,""RR""),concat(E24,C24),"""")"),"") | J24: =IFERROR(__xludf.DUMMYFUNCTION("if(regexmatch($B24,""RR""),F24,"""")"),"") | K24: =IFERROR(__xludf.DUMMYFUNCTION("if(regexmatch($B24,""DE""),concat(C24,E24),"""")"),"[Select Team Name][Select Team Name]") -> [Select Team Name][Select Team Name] | L24: =IFERROR(__xludf.DUMMYFUNCTION("if(regexmatch($B24,""DE""),D24,"""")"),0.0) -> 0 | M24: =IFERROR(__xludf.DUMMYFUNCTION("if(regexmatch($B24,""DE""),concat(E24,C24),"""")"),"[Select Team Name][Select Team Name]") -> [Select Team Name][Select Team Name] | N24: =IFERROR(__xludf.DUMMYFUNCTION("if(regexmatch($B24,""DE""),F24,"""")"),0.0) -> 0
B25: =IFERROR(__xludf.DUMMYFUNCTION("""COMPUTED_VALUE"""),"DE6") -> DE6 | C25: =IFERROR(__xludf.DUMMYFUNCTION("""COMPUTED_VALUE"""),"[Select Team Name]") -> [Select Team Name] | D25: =IFERROR(__xludf.DUMMYFUNCTION("""COMPUTED_VALUE"""),0.0) -> 0 | E25: =IFERROR(__xludf.DUMMYFUNCTION("""COMPUTED_VALUE"""),"[Select Team Name]") -> [Select Team Name] | F25: =IFERROR(__xludf.DUMMYFUNCTION("""COMPUTED_VALUE"""),0.0) -> 0 | G25: =IFERROR(__xludf.DUMMYFUNCTION("if(regexmatch($B25,""RR""),concat(C25,E25),"""")"),"") | H25: =IFERROR(__xludf.DUMMYFUNCTION("if(regexmatch($B25,""RR""),D25,"""")"),"") | I25: =IFERROR(__xludf.DUMMYFUNCTION("if(regexmatch($B25,""RR""),concat(E25,C25),"""")"),"") | J25: =IFERROR(__xludf.DUMMYFUNCTION("if(regexmatch($B25,""RR""),F25,"""")"),"") | K25: =IFERROR(__xludf.DUMMYFUNCTION("if(regexmatch($B25,""DE""),concat(C25,E25),"""")"),"[Select Team Name][Select Team Name]") -> [Select Team Name][Select Team Name] | L25: =IFERROR(__xludf.DUMMYFUNCTION("if(regexmatch($B25,""DE""),D25,"""")"),0.0) -> 0 | M25: =IFERROR(__xludf.DUMMYFUNCTION("if(regexmatch($B25,""DE""),concat(E25,C25),"""")"),"[Select Team Name][Select Team Name]") -> [Select Team Name][Select Team Name] | N25: =IFERROR(__xludf.DUMMYFUNCTION("if(regexmatch($B25,""DE""),F25,"""")"),0.0) -> 0
B26: =IFERROR(__xludf.DUMMYFUNCTION("""COMPUTED_VALUE"""),"DE7") -> DE7 | C26: =IFERROR(__xludf.DUMMYFUNCTION("""COMPUTED_VALUE"""),"[Select Team Name]") -> [Select Team Name] | D26: =IFERROR(__xludf.DUMMYFUNCTION("""COMPUTED_VALUE"""),0.0) -> 0 | E26: =IFERROR(__xludf.DUMMYFUNCTION("""COMPUTED_VALUE"""),"[Select Team Name]") -> [Select Team Name] | F26: =IFERROR(__xludf.DUMMYFUNCTION("""COMPUTED_VALUE"""),0.0) -> 0 | G26: =IFERROR(__xludf.DUMMYFUNCTION("if(regexmatch($B26,""RR""),concat(C26,E26),"""")"),"") | H26: =IFERROR(__xludf.DUMMYFUNCTION("if(regexmatch($B26,""RR""),D26,"""")"),"") | I26: =IFERROR(__xludf.DUMMYFUNCTION("if(regexmatch($B26,""RR""),concat(E26,C26),"""")"),"") | J26: =IFERROR(__xludf.DUMMYFUNCTION("if(regexmatch($B26,""RR""),F26,"""")"),"") | K26: =IFERROR(__xludf.DUMMYFUNCTION("if(regexmatch($B26,""DE""),concat(C26,E26),"""")"),"[Select Team Name][Select Team Name]") -> [Select Team Name][Select Team Name] | L26: =IFERROR(__xludf.DUMMYFUNCTION("if(regexmatch($B26,""DE""),D26,"""")"),0.0) -> 0 | M26: =IFERROR(__xludf.DUMMYFUNCTION("if(regexmatch($B26,""DE""),concat(E26,C26),"""")"),"[Select Team Name][Select Team Name]") -> [Select Team Name][Select Team Name] | N26: =IFERROR(__xludf.DUMMYFUNCTION("if(regexmatch($B26,""DE""),F26,"""")"),0.0) -> 0
B27: =IFERROR(__xludf.DUMMYFUNCTION("""COMPUTED_VALUE"""),"DE8") -> DE8 | C27: =IFERROR(__xludf.DUMMYFUNCTION("""COMPUTED_VALUE"""),"[Select Team Name]") -> [Select Team Name] | D27: =IFERROR(__xludf.DUMMYFUNCTION("""COMPUTED_VALUE"""),0.0) -> 0 | E27: =IFERROR(__xludf.DUMMYFUNCTION("""COMPUTED_VALUE"""),"[Select Team Name]") -> [Select Team Name] | F27: =IFERROR(__xludf.DUMMYFUNCTION("""COMPUTED_VALUE"""),0.0) -> 0 | G27: =IFERROR(__xludf.DUMMYFUNCTION("if(regexmatch($B27,""RR""),concat(C27,E27),"""")"),"") | H27: =IFERROR(__xludf.DUMMYFUNCTION("if(regexmatch($B27,""RR""),D27,"""")"),"") | I27: =IFERROR(__xludf.DUMMYFUNCTION("if(regexmatch($B27,""RR""),concat(E27,C27),"""")"),"") | J27: =IFERROR(__xludf.DUMMYFUNCTION("if(regexmatch($B27,""RR""),F27,"""")"),"") | K27: =IFERROR(__xludf.DUMMYFUNCTION("if(regexmatch($B27,""DE""),concat(C27,E27),"""")"),"[Select Team Name][Select Team Name]") -> [Select Team Name][Select Team Name] | L27: =IFERROR(__xludf.DUMMYFUNCTION("if(regexmatch($B27,""DE""),D27,"""")"),0.0) -> 0 | M27: =IFERROR(__xludf.DUMMYFUNCTION("if(regexmatch($B27,""DE""),concat(E27,C27),"""")"),"[Select Team Name][Select Team Name]") -> [Select Team Name][Select Team Name] | N27: =IFERROR(__xludf.DUMMYFUNCTION("if(regexmatch($B27,""DE""),F27,"""")"),0.0) -> 0
B28: =IFERROR(__xludf.DUMMYFUNCTION("""COMPUTED_VALUE"""),"DE9") -> DE9 | C28: =IFERROR(__xludf.DUMMYFUNCTION("""COMPUTED_VALUE"""),"[Select Team Name]") -> [Select Team Name] | D28: =IFERROR(__xludf.DUMMYFUNCTION("""COMPUTED_VALUE"""),0.0) -> 0 | E28: =IFERROR(__xludf.DUMMYFUNCTION("""COMPUTED_VALUE"""),"[Select Team Name]") -> [Select Team Name] | F28: =IFERROR(__xludf.DUMMYFUNCTION("""COMPUTED_VALUE"""),0.0) -> 0 | G28: =IFERROR(__xludf.DUMMYFUNCTION("if(regexmatch($B28,""RR""),concat(C28,E28),"""")"),"") | H28: =IFERROR(__xludf.DUMMYFUNCTION("if(regexmatch($B28,""RR""),D28,"""")"),"") | I28: =IFERROR(__xludf.DUMMYFUNCTION("if(regexmatch($B28,""RR""),concat(E28,C28),"""")"),"") | J28: =IFERROR(__xludf.DUMMYFUNCTION("if(regexmatch($B28,""RR""),F28,"""")"),"") | K28: =IFERROR(__xludf.DUMMYFUNCTION("if(regexmatch($B28,""DE""),concat(C28,E28),"""")"),"[Select Team Name][Select Team Name]") -> [Select Team Name][Select Team Name] | L28: =IFERROR(__xludf.DUMMYFUNCTION("if(regexmatch($B28,""DE""),D28,"""")"),0.0) -> 0 | M28: =IFERROR(__xludf.DUMMYFUNCTION("if(regexmatch($B28,""DE""),concat(E28,C28),"""")"),"[Select Team Name][Select Team Name]") -> [Select Team Name][Select Team Name] | N28: =IFERROR(__xludf.DUMMYFUNCTION("if(regexmatch($B28,""DE""),F28,"""")"),0.0) -> 0
B29: =IFERROR(__xludf.DUMMYFUNCTION("importrange(""https://docs.google.com/spreadsheets/d/1v3Plj3RjU3BJi7RhvJ9zd-0BmodIVTY64rszllWMLxo/edit?gid=0#gid=0"",""Scores!A2:E15"")"),"RR1") -> RR1 | C29: =IFERROR(__xludf.DUMMYFUNCTION("""COMPUTED_VALUE"""),"Westview") -> Westview | D29: =IFERROR(__xludf.DUMMYFUNCTION("""COMPUTED_VALUE"""),60.0) -> 60 | E29: =IFERROR(__xludf.DUMMYFUNCTION("""COMPUTED_VALUE"""),"Sci Acad B") -> Sci Acad B | F29: =IFERROR(__xludf.DUMMYFUNCTION("""COMPUTED_VALUE"""),86.0) -> 86 | G29: =IFERROR(__xludf.DUMMYFUNCTION("if(regexmatch($B29,""RR""),concat(C29,E29),"""")"),"WestviewSci Acad B") -> WestviewSci Acad B | H29: =IFERROR(__xludf.DUMMYFUNCTION("if(regexmatch($B29,""RR""),D29,"""")"),60.0) -> 60 | I29: =IFERROR(__xludf.DUMMYFUNCTION("if(regexmatch($B29,""RR""),concat(E29,C29),"""")"),"Sci Acad BWestview") -> Sci Acad BWestview | J29: =IFERROR(__xludf.DUMMYFUNCTION("if(regexmatch($B29,""RR""),F29,"""")"),86.0) -> 86 | K29: =IFERROR(__xludf.DUMMYFUNCTION("if(regexmatch($B29,""DE""),concat(C29,E29),"""")"),"") | L29: =IFERROR(__xludf.DUMMYFUNCTION("if(regexmatch($B29,""DE""),D29,"""")"),"") | M29: =IFERROR(__xludf.DUMMYFUNCTION("if(regexmatch($B29,""DE""),concat(E29,C29),"""")"),"") | N29: =IFERROR(__xludf.DUMMYFUNCTION("if(regexmatch($B29,""DE""),F29,"""")"),"")
B30: =IFERROR(__xludf.DUMMYFUNCTION("""COMPUTED_VALUE"""),"RR2") -> RR2 | C30: =IFERROR(__xludf.DUMMYFUNCTION("""COMPUTED_VALUE"""),"Temple City A") -> Temple City A | D30: =IFERROR(__xludf.DUMMYFUNCTION("""COMPUTED_VALUE"""),68.0) -> 68 | E30: =IFERROR(__xludf.DUMMYFUNCTION("""COMPUTED_VALUE"""),"Venice A") -> Venice A | F30: =IFERROR(__xludf.DUMMYFUNCTION("""COMPUTED_VALUE"""),156.0) -> 156 | G30: =IFERROR(__xludf.DUMMYFUNCTION("if(regexmatch($B30,""RR""),concat(C30,E30),"""")"),"Temple City AVenice A") -> Temple City AVenice A | H30: =IFERROR(__xludf.DUMMYFUNCTION("if(regexmatch($B30,""RR""),D30,"""")"),68.0) -> 68 | I30: =IFERROR(__xludf.DUMMYFUNCTION("if(regexmatch($B30,""RR""),concat(E30,C30),"""")"),"Venice ATemple City A") -> Venice ATemple City A | J30: =IFERROR(__xludf.DUMMYFUNCTION("if(regexmatch($B30,""RR""),F30,"""")"),156.0) -> 156 | K30: =IFERROR(__xludf.DUMMYFUNCTION("if(regexmatch($B30,""DE""),concat(C30,E30),"""")"),"") | L30: =IFERROR(__xludf.DUMMYFUNCTION("if(regexmatch($B30,""DE""),D30,"""")"),"") | M30: =IFERROR(__xludf.DUMMYFUNCTION("if(regexmatch($B30,""DE""),concat(E30,C30),"""")"),"") | N30: =IFERROR(__xludf.DUMMYFUNCTION("if(regexmatch($B30,""DE""),F30,"""")"),"")
B31: =IFERROR(__xludf.DUMMYFUNCTION("""COMPUTED_VALUE"""),"RR3") -> RR3 | C31: =IFERROR(__xludf.DUMMYFUNCTION("""COMPUTED_VALUE"""),"Beckman B") -> Beckman B | D31: =IFERROR(__xludf.DUMMYFUNCTION("""COMPUTED_VALUE"""),44.0) -> 44 | E31: =IFERROR(__xludf.DUMMYFUNCTION("""COMPUTED_VALUE"""),"North Hollywood B") -> North Hollywood B | F31: =IFERROR(__xludf.DUMMYFUNCTION("""COMPUTED_VALUE"""),102.0) -> 102 | G31: =IFERROR(__xludf.DUMMYFUNCTION("if(regexmatch($B31,""RR""),concat(C31,E31),"""")"),"Beckman BNorth Hollywood B") -> Beckman BNorth Hollywood B | H31: =IFERROR(__xludf.DUMMYFUNCTION("if(regexmatch($B31,""RR""),D31,"""")"),44.0) -> 44 | I31: =IFERROR(__xludf.DUMMYFUNCTION("if(regexmatch($B31,""RR""),concat(E31,C31),"""")"),"North Hollywood BBeckman B") -> North Hollywood BBeckman B | J31: =IFERROR(__xludf.DUMMYFUNCTION("if(regexmatch($B31,""RR""),F31,"""")"),102.0) -> 102 | K31: =IFERROR(__xludf.DUMMYFUNCTION("if(regexmatch($B31,""DE""),concat(C31,E31),"""")"),"") | L31: =IFERROR(__xludf.DUMMYFUNCTION("if(regexmatch($B31,""DE""),D31,"""")"),"") | M31: =IFERROR(__xludf.DUMMYFUNCTION("if(regexmatch($B31,""DE""),concat(E31,C31),"""")"),"") | N31: =IFERROR(__xludf.DUMMYFUNCTION("if(regexmatch($B31,""DE""),F31,"""")"),"")
B32: =IFERROR(__xludf.DUMMYFUNCTION("""COMPUTED_VALUE"""),"RR4") -> RR4 | C32: =IFERROR(__xludf.DUMMYFUNCTION("""COMPUTED_VALUE"""),"OCSA") -> OCSA | D32: =IFERROR(__xludf.DUMMYFUNCTION("""COMPUTED_VALUE"""),44.0) -> 44 | E32: =IFERROR(__xludf.DUMMYFUNCTION("""COMPUTED_VALUE"""),"North Hollywood A") -> North Hollywood A | F32: =IFERROR(__xludf.DUMMYFUNCTION("""COMPUTED_VALUE"""),176.0) -> 176 | G32: =IFERROR(__xludf.DUMMYFUNCTION("if(regexmatch($B32,""RR""),concat(C32,E32),"""")"),"OCSANorth Hollywood A") -> OCSANorth Hollywood A | H32: =IFERROR(__xludf.DUMMYFUNCTION("if(regexmatch($B32,""RR""),D32,"""")"),44.0) -> 44 | I32: =IFERROR(__xludf.DUMMYFUNCTION("if(regexmatch($B32,""RR""),concat(E32,C32),"""")"),"North Hollywood AOCSA") -> North Hollywood AOCSA | J32: =IFERROR(__xludf.DUMMYFUNCTION("if(regexmatch($B32,""RR""),F32,"""")"),176.0) -> 176 | K32: =IFERROR(__xludf.DUMMYFUNCTION("if(regexmatch($B32,""DE""),concat(C32,E32),"""")"),"") | L32: =IFERROR(__xludf.DUMMYFUNCTION("if(regexmatch($B32,""DE""),D32,"""")"),"") | M32: =IFERROR(__xludf.DUMMYFUNCTION("if(regexmatch($B32,""DE""),concat(E32,C32),"""")"),"") | N32: =IFERROR(__xludf.DUMMYFUNCTION("if(regexmatch($B32,""DE""),F32,"""")"),"")
