Workbook

Sheet Round Robin
B4: Amino Division | M4: Bijection Division
D6: North Hollywood | E6: Dulles B | F6: Crestview Middle | G6: Buchholz A | H6: Lexington 2 | I6: Niskayuna A | J6: PPG | K6: Points | O6: MSJ C | P6: South Hollywood | Q6: Westminster | R6: Shen | S6: Dulles A | T6: CCA 1 | U6: PPG | V6: Points | X6: Schedule (EDT)
Y8: Start - End | Z8: Room 1 | AA8: Room 2 | AB8: Room 3
X9: RR1 | Y9: 10:00 - 10:40 | Z9: 1 vs 2 | AA9: 3 vs 4 | AB9: 5 vs 6
X10: RR2 | Y10: 10:40 - 11:20 | Z10: 1 vs 3 | AA10: 2 vs 5 | AB10: 4 vs 6
X11: RR3 | Y11: 11:20 - 12:00 | Z11: 1 vs 4 | AA11: 3 vs 5 | AB11: 2 vs 6
B12: 1 | C12: North Hollywood | E12: 178 | F12: 122 | G12: 168 | H12: 106 | I12: 124 | J12: =SUM(D12:I12)/IF(COUNTA(D12:I12)=0,1,COUNTA(D12:I12)) -> 139.6 | K12: =SUMPRODUCT(IF(D12:I12>'Round Robin Transpose'!D12:I12,2,IF(D12:I12='Round Robin Transpose'!D12:I12,1,0)))-6+COUNTA(D12:I12) -> 10 | M12: 1 | N12: MSJ C | P12: 34 | Q12: 36 | R12: 30 | S12: 32 | T12: 40 | U12: =SUM(O12:T12)/IF(COUNTA(O12:T12)=0,1,COUNTA(O12:T12)) -> 34.4 | V12: =SUMPRODUCT(IF(O12:T12>'Round Robin Transpose'!O12:T12,2,IF(O12:T12='Round Robin Transpose'!O12:T12,1,0)))-6+COUNTA(O12:T12) -> 1 | X12: RR4 | Y12: 12:00 - 12:40 | Z12: 1 vs 5 | AA12: 2 vs 4 | AB12: 3 vs 6
B13: 2 | C13: Dulles B | D13: 12 | F13: 18 | G13: 8 | H13: 42 | I13: 28 | J13: =SUM(D13:I13)/IF(COUNTA(D13:I13)=0,1,COUNTA(D13:I13)) -> 21.6 | K13: =SUMPRODUCT(IF(D13:I13>'Round Robin Transpose'!D13:I13,2,IF(D13:I13='Round Robin Transpose'!D13:I13,1,0)))-6+COUNTA(D13:I13) -> 2 | M13: 2 | N13: South Hollywood | O13: 44 | Q13: 52 | R13: 74 | S13: 48 | T13: 122 | U13: =SUM(O13:T13)/IF(COUNTA(O13:T13)=0,1,COUNTA(O13:T13)) -> 68 | V13: =SUMPRODUCT(IF(O13:T13>'Round Robin Transpose'!O13:T13,2,IF(O13:T13='Round Robin Transpose'!O13:T13,1,0)))-6+COUNTA(O13:T13) -> 6 | X13: RR5 | Y13: 12:40 - 1:20 | Z13: 2 vs 3 | AA13: 4 vs 5 | AB13: 1 vs 6
B14: 3 | C14: Crestview Middle | D14: 8 | E14: 44 | G14: 32 | H14: 44 | I14: 54 | J14: =SUM(D14:I14)/IF(COUNTA(D14:I14)=0,1,COUNTA(D14:I14)) -> 36.4 | K14: =SUMPRODUCT(IF(D14:I14>'Round Robin Transpose'!D14:I14,2,IF(D14:I14='Round Robin Transpose'!D14:I14,1,0)))-6+COUNTA(D14:I14) -> 4 | M14: 3 | N14: Westminster | O14: 110 | P14: 68 | R14: 142 | S14: 94 | T14: 106 | U14: =SUM(O14:T14)/IF(COUNTA(O14:T14)=0,1,COUNTA(O14:T14)) -> 104 | V14: =SUMPRODUCT(IF(O14:T14>'Round Robin Transpose'!O14:T14,2,IF(O14:T14='Round Robin Transpose'!O14:T14,1,0)))-6+COUNTA(O14:T14) -> 8
B15: 4 | C15: Buchholz A | D15: 88 | E15: 154 | F15: 130 | H15: 106 | I15: 92 | J15: =SUM(D15:I15)/IF(COUNTA(D15:I15)=0,1,COUNTA(D15:I15)) -> 114 | K15: =SUMPRODUCT(IF(D15:I15>'Round Robin Transpose'!D15:I15,2,IF(D15:I15='Round Robin Transpose'!D15:I15,1,0)))-6+COUNTA(D15:I15) -> 8 | M15: 4 | N15: Shen | O15: 88 | P15: 54 | Q15: 22 | S15: 54 | T15: 72 | U15: =SUM(O15:T15)/IF(COUNTA(O15:T15)=0,1,COUNTA(O15:T15)) -> 58 | V15: =SUMPRODUCT(IF(O15:T15>'Round Robin Transpose'!O15:T15,2,IF(O15:T15='Round Robin Transpose'!O15:T15,1,0)))-6+COUNTA(O15:T15) -> 2
B16: 5 | C16: Lexington 2 | D16: 22 | E16: 22 | F16: 46 | G16: -4 | I16: 76 | J16: =SUM(D16:I16)/IF(COUNTA(D16:I16)=0,1,COUNTA(D16:I16)) -> 32.4 | K16: =SUMPRODUCT(IF(D16:I16>'Round Robin Transpose'!D16:I16,2,IF(D16:I16='Round Robin Transpose'!D16:I16,1,0)))-6+COUNTA(D16:I16) -> 4 | M16: 5 | N16: Dulles A | O16: 68 | P16: 100 | Q16: 108 | R16: 88 | T16: 192 | U16: =SUM(O16:T16)/IF(COUNTA(O16:T16)=0,1,COUNTA(O16:T16)) -> 111.2 | V16: =SUMPRODUCT(IF(O16:T16>'Round Robin Transpose'!O16:T16,2,IF(O16:T16='Round Robin Transpose'!O16:T16,1,0)))-6+COUNTA(O16:T16) -> 10
B17: 6 | C17: Niskayuna A | D17: 0 | E17: 72 | F17: 38 | G17: 12 | H17: 24 | J17: =SUM(D17:I17)/IF(COUNTA(D17:I17)=0,1,COUNTA(D17:I17)) -> 29.2 | K17: =SUMPRODUCT(IF(D17:I17>'Round Robin Transpose'!D17:I17,2,IF(D17:I17='Round Robin Transpose'!D17:I17,1,0)))-6+COUNTA(D17:I17) -> 2 | M17: 6 | N17: CCA 1 | O17: 40 | P17: 46 | Q17: 26 | R17: 76 | S17: 22 | U17: =SUM(O17:T17)/IF(COUNTA(O17:T17)=0,1,COUNTA(O17:T17)) -> 42 | V17: =SUMPRODUCT(IF(O17:T17>'Round Robin Transpose'!O17:T17,2,IF(O17:T17='Round Robin Transpose'!O17:T17,1,0)))-6+COUNTA(O17:T17) -> 3
B20: Cesium Division | M20: Dielectric Division
D22: Hwite Bread A | E22: Sodium Hypobromite | F22: Foothill | G22: MSJ B | H22: Iolani B | I22: BYE | J22: PPG | K22: Points | O22: Niskayuna B | P22: Knights | Q22: MSJ A | R22: Hwite Bread B | S22: Amador Valley 1 | T22: BYE | U22: PPG | V22: Points | X22: Schedule (EDT)
Y24: Start - End | Z24: Room 1 | AA24: Room 2
X25: RR1 | Y25: 10:00 - 10:40 | Z25: 1 vs 2 | AA25: 3 vs 4
X26: RR2 | Y26: 10:40 - 11:20 | Z26: 1 vs 3 | AA26: 2 vs 5
X27: RR3 | Y27: 11:20 - 12:00 | Z27: 1 vs 4 | AA27: 3 vs 5
B28: 1 | C28: Hwite Bread A | E28: 136 | F28: 98 | G28: 190 | H28: 110 | J28: =SUM(D28:I28)/IF(COUNTA(D28:I28)=0,1,COUNTA(D28:I28)) -> 133.5 | K28: =SUMPRODUCT(IF(D28:I28>'Round Robin Transpose'!D28:I28,2,0))+SUMPRODUCT(IF(D28:I28='Round Robin Transpose'!D28:I28,1,0))-6+COUNTA(D28:I28) -> 8 | M28: 1 | N28: Niskayuna B | P28: 32 | Q28: 30 | R28: 70 | S28: 20 | U28: =SUM(O28:T28)/IF(COUNTA(O28:T28)=0,1,COUNTA(O28:T28)) -> 38 | V28: =SUMPRODUCT(IF(O28:T28>'Round Robin Transpose'!O28:T28,2,IF(O28:T28='Round Robin Transpose'!O28:T28,1,0)))-6+COUNTA(O28:T28) -> 0 | X28: RR4 | Y28: 12:00 - 12:40 | Z28: 1 vs 5 | AA28: 2 vs 4
B29: 2 | C29: Sodium Hypobromite | D29: 24 | F29: 58 | G29: 80 | H29: 112 | J29: =SUM(D29:I29)/IF(COUNTA(D29:I29)=0,1,COUNTA(D29:I29)) -> 68.5 | K29: =SUMPRODUCT(IF(D29:I29>'Round Robin Transpose'!D29:I29,2,IF(D29:I29='Round Robin Transpose'!D29:I29,1,0)))-6+COUNTA(D29:I29) -> 6 | M29: 2 | N29: Knights | O29: 72 | Q29: 74 | R29: 86 | S29: 92 | U29: =SUM(O29:T29)/IF(COUNTA(O29:T29)=0,1,COUNTA(O29:T29)) -> 81 | V29: =SUMPRODUCT(IF(O29:T29>'Round Robin Transpose'!O29:T29,2,IF(O29:T29='Round Robin Transpose'!O29:T29,1,0)))-6+COUNTA(O29:T29) -> 6 | X29: RR5 | Y29: 12:40 - 1:20 | Z29: 2 vs 3 | AA29: 4 vs 5
B30: 3 | C30: Foothill | D30: 74 | E30: 40 | G30: 92 | H30: 118 | J30: =SUM(D30:I30)/IF(COUNTA(D30:I30)=0,1,COUNTA(D30:I30)) -> 81 | K30: =SUMPRODUCT(IF(D30:I30>'Round Robin Transpose'!D30:I30,2,IF(D30:I30='Round Robin Transpose'!D30:I30,1,0)))-6+COUNTA(D30:I30) -> 4 | M30: 3 | N30: MSJ A | O30: 60 | P30: 98 | R30: 102 | S30: 124 | U30: =SUM(O30:T30)/IF(COUNTA(O30:T30)=0,1,COUNTA(O30:T30)) -> 96 | V30: =SUMPRODUCT(IF(O30:T30>'Round Robin Transpose'!O30:T30,2,IF(O30:T30='Round Robin Transpose'!O30:T30,1,0)))-6+COUNTA(O30:T30) -> 8
B31: 4 | C31: MSJ B | D31: 0 | E31: 22 | F31: 60 | H31: 74 | J31: =SUM(D31:I31)/IF(COUNTA(D31:I31)=0,1,COUNTA(D31:I31)) -> 39 | K31: =SUMPRODUCT(IF(D31:I31>'Round Robin Transpose'!D31:I31,2,IF(D31:I31='Round Robin Transpose'!D31:I31,1,0)))-6+COUNTA(D31:I31) -> 2 | M31: 4 | N31: Hwite Bread B | O31: 80 | P31: 72 | Q31: 56 | S31: 28 | U31: =SUM(O31:T31)/IF(COUNTA(O31:T31)=0,1,COUNTA(O31:T31)) -> 59 | V31: =SUMPRODUCT(IF(O31:T31>'Round Robin Transpose'!O31:T31,2,IF(O31:T31='Round Robin Transpose'!O31:T31,1,0)))-6+COUNTA(O31:T31) -> 2
B32: 5 | C32: Iolani B | D32: 4 | E32: 26 | F32: 22 | G32: 4 | J32: =SUM(D32:I32)/IF(COUNTA(D32:I32)=0,1,COUNTA(D32:I32)) -> 14 | K32: =SUMPRODUCT(IF(D32:I32>'Round Robin Transpose'!D32:I32,2,IF(D32:I32='Round Robin Transpose'!D32:I32,1,0)))-6+COUNTA(D32:I32) -> 0 | M32: 5 | N32: Amador Valley 1 | O32: 34 | P32: 38 | Q32: 40 | R32: 60 | U32: =SUM(O32:T32)/IF(COUNTA(O32:T32)=0,1,COUNTA(O32:T32)) -> 43 | V32: =SUMPRODUCT(IF(O32:T32>'Round Robin Transpose'!O32:T32,2,IF(O32:T32='Round Robin Transpose'!O32:T32,1,0)))-6+COUNTA(O32:T32) -> 4
B33: 6 | C33: BYE | M33: 6 | N33: BYE
B36: Electron Division | M36: Fluorite Division
D38: Pullman A | E38: CCA 2 | F38: Lexington 1 | G38: University | H38: Iolani A | I38: BYE | J38: PPG | K38: Points | O38: Lakeside | P38: Centennial | Q38: SSM-GH | R38: Amador Valley 2 | S38: Saratoga | T38: BYE | U38: PPG | V38: Points | X38: Schedule (EDT)
Y40: Start - End | Z40: Room 1 | AA40: Room 2
X41: RR1 | Y41: 10:00 - 10:40 | Z41: 1 vs 2 | AA41: 3 vs 4
X42: RR2 | Y42: 10:40 - 11:20 | Z42: 1 vs 3 | AA42: 2 vs 5
X43: RR3 | Y43: 11:20 - 12:00 | Z43: 1 vs 4 | AA43: 3 vs 5
B44: 1 | C44: Pullman A | E44: 62 | F44: 12 | G44: 10 | H44: 64 | J44: =SUM(D44:I44)/IF(COUNTA(D44:I44)=0,1,COUNTA(D44:I44)) -> 37 | K44: =SUMPRODUCT(IF(D44:I44>'Round Robin Transpose'!D44:I44,2,IF(D44:I44='Round Robin Transpose'!D44:I44,1,0)))-6+COUNTA(D44:I44) -> 4 | M44: 1 | N44: Lakeside | P44: 68 | Q44: 52 | R44: 106 | S44: 50 | U44: =SUM(O44:T44)/IF(COUNTA(O44:T44)=0,1,COUNTA(O44:T44)) -> 69 | V44: =SUMPRODUCT(IF(O44:T44>'Round Robin Transpose'!O44:T44,2,IF(O44:T44='Round Robin Transpose'!O44:T44,1,0)))-6+COUNTA(O44:T44) -> 2 | X44: RR4 | Y44: 12:00 - 12:40 | Z44: 1 vs 5 | AA44: 2 vs 4
B45: 2 | C45: CCA 2 | D45: 12 | F45: 34 | G45: 22 | H45: 24 | J45: =SUM(D45:I45)/IF(COUNTA(D45:I45)=0,1,COUNTA(D45:I45)) -> 23 | K45: =SUMPRODUCT(IF(D45:I45>'Round Robin Transpose'!D45:I45,2,IF(D45:I45='Round Robin Transpose'!D45:I45,1,0)))-6+COUNTA(D45:I45) -> 0 | M45: 2 | N45: Centennial | O45: 162 | Q45: 106 | R45: 132 | S45: 106 | U45: =SUM(O45:T45)/IF(COUNTA(O45:T45)=0,1,COUNTA(O45:T45)) -> 126.5 | V45: =SUMPRODUCT(IF(O45:T45>'Round Robin Transpose'!O45:T45,2,IF(O45:T45='Round Robin Transpose'!O45:T45,1,0)))-6+COUNTA(O45:T45) -> 8 | X45: RR5 | Y45: 12:40 - 1:20 | Z45: 2 vs 3 | AA45: 4 vs 5
B46: 3 | C46: Lexington 1 | D46: 72 | E46: 54 | G46: 14 | H46: 102 | J46: =SUM(D46:I46)/IF(COUNTA(D46:I46)=0,1,COUNTA(D46:I46)) -> 60.5 | K46: =SUMPRODUCT(IF(D46:I46>'Round Robin Transpose'!D46:I46,2,IF(D46:I46='Round Robin Transpose'!D46:I46,1,0)))-6+COUNTA(D46:I46) -> 6 | M46: 3 | N46: SSM-GH | O46: 62 | P46: 76 | R46: 132 | S46: 60 | U46: =SUM(O46:T46)/IF(COUNTA(O46:T46)=0,1,COUNTA(O46:T46)) -> 82.5 | V46: =SUMPRODUCT(IF(O46:T46>'Round Robin Transpose'!O46:T46,2,IF(O46:T46='Round Robin Transpose'!O46:T46,1,0)))-6+COUNTA(O46:T46) -> 6
B47: 4 | C47: University | D47: 208 | E47: 110 | F47: 150 | H47: 156 | J47: =SUM(D47:I47)/IF(COUNTA(D47:I47)=0,1,COUNTA(D47:I47)) -> 156 | K47: =SUMPRODUCT(IF(D47:I47>'Round Robin Transpose'!D47:I47,2,IF(D47:I47='Round Robin Transpose'!D47:I47,1,0)))-6+COUNTA(D47:I47) -> 8 | M47: 4 | N47: Amador Valley 2 | O47: 28 | P47: 8 | Q47: 16 | S47: 26 | U47: =SUM(O47:T47)/IF(COUNTA(O47:T47)=0,1,COUNTA(O47:T47)) -> 19.5 | V47: =SUMPRODUCT(IF(O47:T47>'Round Robin Transpose'!O47:T47,2,IF(O47:T47='Round Robin Transpose'!O47:T47,1,0)))-6+COUNTA(O47:T47) -> 0
B48: 5 | C48: Iolani A | D48: 26 | E48: 82 | F48: 44 | G48: 50.6 | J48: =SUM(D48:I48)/IF(COUNTA(D48:I48)=0,1,COUNTA(D48:I48)) -> 50.65 | K48: =SUMPRODUCT(IF(D48:I48>'Round Robin Transpose'!D48:I48,2,IF(D48:I48='Round Robin Transpose'!D48:I48,1,0)))-6+COUNTA(D48:I48) -> 2 | M48: 5 | N48: Saratoga | O48: 104 | P48: 74 | Q48: 58 | R48: 94 | U48: =SUM(O48:T48)/IF(COUNTA(O48:T48)=0,1,COUNTA(O48:T48)) -> 82.5 | V48: =SUMPRODUCT(IF(O48:T48>'Round Robin Transpose'!O48:T48,2,IF(O48:T48='Round Robin Transpose'!O48:T48,1,0)))-6+COUNTA(O48:T48) -> 4
B49: 6 | C49: BYE | M49: 6 | N49: BYE

Sheet Round Robin Transpose
B4: Amino Division | M4: Bijection Division
D6: North Hollywood | E6: Dulles B | F6: Crestview Middle | G6: Buchholz A | H6: Lexington 2 | I6: Niskayuna A | J6: PPG | K6: Points | O6: MSJ C | P6: South Hollywood | Q6: Westminster | R6: Shen | S6: Dulles A | T6: CCA 1 | V6: Schedule
V8: RR1 | W8: 1 vs 2 | X8: 3 vs 4 | Y8: 5 vs 6
V9: RR2 | W9: 1 vs 3 | X9: 2 vs 5 | Y9: 4 vs 6
V10: RR3 | W10: 1 vs 4 | X10: 2 vs 6 | Y10: 3 vs 5
V11: RR4 | W11: 1 vs 5 | X11: 2 vs 4 | Y11: 3 vs 6
B12: 1 | C12: North Hollywood | D12: {=TRANSPOSE('Round Robin'!D12:I17)} | E12: 12 | F12: 8 | G12: 88 | H12: 22 | I12: 0 | M12: 1 | N12: MSJ C | O12: {=TRANSPOSE('Round Robin'!O12:T17)} | P12: 44 | Q12: 110 | R12: 88 | S12: 68 | T12: 40 | V12: RR5 | W12: 1 vs 6 | X12: 2 vs 3 | Y12: 4 vs 5
B13: 2 | C13: Dulles B | D13: 178 | F13: 44 | G13: 154 | H13: 22 | I13: 72 | M13: 2 | N13: South Hollywood | O13: 34 | Q13: 68 | R13: 54 | S13: 100 | T13: 46
B14: 3 | C14: Crestview Middle | D14: 122 | E14: 18 | G14: 130 | H14: 46 | I14: 38 | M14: 3 | N14: Westminster | O14: 36 | P14: 52 | R14: 22 | S14: 108 | T14: 26
B15: 4 | C15: Buchholz A | D15: 168 | E15: 8 | F15: 32 | H15: -4 | I15: 12 | M15: 4 | N15: Shen | O15: 30 | P15: 74 | Q15: 142 | S15: 88 | T15: 76
B16: 5 | C16: Lexington 2 | D16: 106 | E16: 42 | F16: 44 | G16: 106 | I16: 24 | M16: 5 | N16: Dulles A | O16: 32 | P16: 48 | Q16: 94 | R16: 54 | T16: 22
B17: 6 | C17: Niskayuna A | D17: 124 | E17: 28 | F17: 54 | G17: 92 | H17: 76 | M17: 6 | N17: Sodium Hypobromite | O17: 40 | P17: 122 | Q17: 106 | R17: 72 | S17: 192
B20: Cesium Division | M20: Dielectric Division
D22: Hwite Bread A | E22: Sodium Hypobromite | F22: Foothill | G22: MSJ B | H22: Iolani B | I22: BYE | O22: Niskayuna A | P22: Knights | Q22: MSJ A | R22: Hwite Bread B | S22: Amador Valley 1 | T22: BYE | V22: Schedule
V24: RR1 | W24: 1 vs 2 | X24: 3 vs 4 | Y24: 5 vs 6
V25: RR2 | W25: 1 vs 3 | X25: 2 vs 5 | Y25: 4 vs 6
V26: RR3 | W26: 1 vs 4 | X26: 2 vs 6 | Y26: 3 vs 5
V27: RR4 | W27: 1 vs 5 | X27: 2 vs 4 | Y27: 3 vs 6
B28: 1 | C28: Hwite Bread A | D28: {=TRANSPOSE('Round Robin'!D28:I33)} | E28: 24 | F28: 74 | G28: 0 | H28: 4 | M28: 1 | N28: Niskayuna B | O28: {=TRANSPOSE('Round Robin'!O28:T33)} | P28: 72 | Q28: 60 | R28: 80 | S28: 34 | V28: RR5 | W28: 1 vs 6 | X28: 2 vs 3 | Y28: 4 vs 5
B29: 2 | C29: CCA 1 | D29: 136 | F29: 40 | G29: 22 | H29: 26 | M29: 2 | N29: Knights | O29: 32 | Q29: 98 | R29: 72 | S29: 38
B30: 3 | C30: Foothill | D30: 98 | E30: 58 | G30: 60 | H30: 22 | M30: 3 | N30: MSJ A | O30: 30 | P30: 74 | R30: 56 | S30: 40
B31: 4 | C31: MSJ B | D31: 190 | E31: 80 | F31: 92 | H31: 4 | M31: 4 | N31: Hwite Bread B | O31: 70 | P31: 86 | Q31: 102 | S31: 60
B32: 5 | C32: Iolani B | D32: 110 | E32: 112 | F32: 118 | G32: 74 | M32: 5 | N32: Amador Valley 1 | O32: 20 | P32: 92 | Q32: 124 | R32: 28
B33: 6 | C33: BYE | M33: 6 | N33: BYE
B36: Electron Division | M36: Fluorite Division
D38: Pullman A | E38: CCA 2 | F38: Lexington 1 | G38: University | H38: Iolani A | I38: BYE | O38: Lakeside | P38: Centennial | Q38: SSM-GH | R38: Amador Valley 2 | S38: Saratoga | T38: BYE | V38: Schedule
V40: RR1 | W40: 1 vs 2 | X40: 3 vs 4 | Y40: 5 vs 6
V41: RR2 | W41: 1 vs 3 | X41: 2 vs 5 | Y41: 4 vs 6
V42: RR3 | W42: 1 vs 4 | X42: 2 vs 6 | Y42: 3 vs 5
V43: RR4 | W43: 1 vs 5 | X43: 2 vs 4 | Y43: 3 vs 6
B44: 1 | C44: Pullman A | D44: {=TRANSPOSE('Round Robin'!D44:I49)} | E44: 12 | F44: 72 | G44: 208 | H44: 26 | M44: 1 | N44: Lakeside | O44: {=TRANSPOSE('Round Robin'!O44:T49)} | P44: 162 | Q44: 62 | R44: 28 | S44: 104 | V44: RR5 | W44: 1 vs 6 | X44: 2 vs 3 | Y44: 4 vs 5
B45: 2 | C45: CCA 2 | D45: 62 | F45: 54 | G45: 110 | H45: 82 | M45: 2 | N45: Centennial | O45: 68 | Q45: 76 | R45: 8 | S45: 74
B46: 3 | C46: Lexington 1 | D46: 12 | E46: 34 | G46: 150 | H46: 44 | M46: 3 | N46: SSM-GH | O46: 52 | P46: 106 | R46: 16 | S46: 58
B47: 4 | C47: University | D47: 10 | E47: 22 | F47: 14 | H47: 50.6 | M47: 4 | N47: Amador Valley 2 | O47: 106 | P47: 132 | Q47: 132 | S47: 94
B48: 5 | C48: Iolani A | D48: 64 | E48: 24 | F48: 102 | G48: 156 | M48: 5 | N48: Saratoga | O48: 50 | P48: 106 | Q48: 60 | R48: 26
B49: 6 | C49: BYE | M49: 6 | N49: BYE

Sheet Double Elimination
B3: 1st Amino | C3: North Hollywood | D3: 94
D5: A1 | E5: North Hollywood
B6: 3rd w/ 1st PPG | C6: Saratoga | D6: 54
G8: North Hollywood | I8: 124
B9: 2nd Cesium | C9: Sodium Hypobromite | D9: 88 | F9: A1
D11: B1 | E11: Sodium hypobromite
B12: 2nd Dielectric | C12: Knights | D12: 82
J14: A1 | M14: North Hollywood | N14: 26
B15: 1st Bijection | C15: Dulles A | D15: 76
D17: C1 | E17: Dulles A | F17: 72
B18: 3rd w/ 2nd PPG | C18: Foothill | D18: 42
G20: University | I20: 24
B21: 1st Electron | C21: University | D21: 112 | F21: B1
D23: D1 | E23: University | F23: 96
B24: 2nd Fluorite | C24: SSM-GH | D24: 18
N26: A1 | Q26: North Hollywood | R26: 34
B27: 1st Cesium | C27: Hwite Bread A | D27: 72
D29: E1 | E29: Hwite Bread A | F29: 74
B30: 3rd w/ 3rd PPG | C30: South Hollywood | D30: 60
F32: C1 | G32: Hwite Bread A | J32: 58
B33: 2nd Amino | C33: Buchholz A | D33: 86
D35: F1 | E35: Buchholz A | F35: 32
B36: 2nd Bijection | C36: Westminster | D36: 60
J38: C1 | M38: Hwite Bread A | N38: 18
B39: 1st Dielectric | C39: MSJ A | D39: 82
R40: A1 | T40: North Hollywood
D41: A2 | E41: MSJ A | F41: 42
B42: 3rd w/ 4th PPG | C42: Amador Valley A | D42: 40
F44: D1 | G44: Centennial | J44: 30
B45: 1st Fluorite | C45: Centennial | D45: 104
D47: B2 | E47: Centennial | F47: 102
B48: 2nd Electron | C48: Lexington 1 | D48: 42 | O48: Hwite Bread A | P48: 78
K51: University | L51: 66
G52: MSJ A | H52: 42
D53: Loser of A1 | E53: Saratoga | F53: 20
H54: E1 | I54: Knights | J54: 54 | L54: C1 | M54: University | N54: 54 | P54: A1 | Q54: Hwite Bread A | R54: 14
F55: E1 | G55: Knights | H55: 76 | J55: TB: 4
D56: Loser of B1 | E56: Knights | F56: 70
J57: F1 | K57: Buchholz | L57: 36
G58: Buchholz A | H58: 118
...
