Workbook

Sheet CT Championship Scores (Public)
B1: *use the tabs at the bottom to navigate between scores and bracket. Refresh constantly to remain up to date :)
A2: filename | C2: CT Double Elimination Round 1 | G2: CT Double Elimination Round 2 | K2: CT Double Elimination Round 3 | O2: CT Double Elimination Round 4 | S2: CT Double Elimination Round 5 | W2: CT Double Elimination Round 6 | AA2: CT Championship Semi Final Round 7 | AE2: CT Championship Round 8 (FINAL MATCH) | AI2: CT Championship Round 9 (needed)
A3: https://docs.google.com/spreadsheets/d/1riy79QbgAMQ7be_qPmaYXSmTEkKw3sqeqtB8mEkpKVE/edit?gid=618646761#gid=618646761 | C3: ='CT Bracket'!C3 -> 0.59375 | G3: ='CT Bracket'!E3 -> 0.625 | K3: 0.65625 | O3: 0.67708333 | S3: 0.69791667 | W3: 0.71875 | AA3: 0.75 | AE3: 0.77777778 | AI3: 0.80902778
B4: Seed | C4: Teams | D4: Score | E4: CC Verification | F4: Points | G4: Teams | H4: Score | I4: CC Verification | J4: Points | K4: Teams | L4: Score | M4: CC Verification | N4: Points | O4: Teams | P4: Score | Q4: CC Verification | R4: Points | S4: Teams | T4: Score | U4: CC Verification | V4: Points | W4: Teams | X4: Score | Y4: CC Verification | Z4: Points | AA4: Teams | AB4: Score | AC4: CC Verification | AD4: Points | AE4: Teams | AF4: Score | AG4: CC Verification | AH4: Points | AI4: Teams | AJ4: Score | AK4: CC Verification | AL4: Points | AM4: Score | AN4: CC Verification | AO4: Points
A5: 3 | B5: 1 | C5: =IFERROR(__xludf.DUMMYFUNCTION("if(importrange($A$3,""CT RR Calculations (Private)!$AB$10"")=""Not Ready"",concatenate(B5,"" Seed Team""),concatenate(B5,"" "", importrange($A$3,CONCATENATE(""CT RR Calculations (Private)!"",""W"",A5))))"),"1 Farmington HS - Team 1") -> 1 Farmington HS - Team 1 | D5: 174 | E5: TRUE | F5: =IF(E5=True, IF(D5>D6,2,IF(D5=D6,1,0)),0) -> 2 | G5: ='CT Bracket'!E6 -> 1 Farmington HS - Team 1 | H5: 108 | I5: TRUE | J5: =IF(I5=True, IF(H5>H6,2,IF(H5=H6,1,0)),0) -> 2 | K5: ='CT Bracket'!G6 -> 1 Farmington HS - Team 1 | M5: TRUE | N5: =IF(M5=True, IF(L5>L6,2,IF(L5=L6,1,0)),0) -> 1 | O5: ='CT Bracket'!I8 -> 1 Farmington HS - Team 1 | P5: 90 | Q5: TRUE | R5: =IF(Q5=True, IF(P5>P6,2,IF(P5=P6,1,0)),0) -> 0 | S5: ='CT Bracket'!M12 -> 4 Greenwich HS - Team 1 | U5: TRUE | V5: =IF(U5=True, IF(T5>T6,2,IF(T5=T6,1,0)),0) -> 1 | W5: ='CT Bracket'!M12 -> 4 Greenwich HS - Team 1 | X5: 70 | Y5: TRUE | Z5: =IFS(X5="",0,(X5-X6)>0,X5+100,(X5-X6)=0,X5+50,(X5-X6)<0,X5) -> 170 | AA5: BYE | AC5: FALSE | AD5: =IF(AC5=True, IF(AB5>AB6,2,IF(AB5=AB6,1,0)),0) -> 0 | AE5: ='CT Bracket'!Q20 -> 4 Greenwich HS - Team 1 | AF5: 72 | AG5: TRUE | AH5: =IF(AG5=True, IF(AF5>AF6,2,IF(AF5=AF6,1,0)),0) -> 0 | AI5: ='CT Bracket'!Q20 -> 4 Greenwich HS - Team 1 | AJ5: 118 | AK5: TRUE | AL5: =IF(AK5=True, IF(AJ5>AJ6,2,IF(AJ5=AJ6,1,0)),0) -> 2 | AN5: FALSE | AO5: =IFS(AM5="",0,(AM5-AM6)>0,AM5+100,(AM5-AM6)=0,AM5+50,(AM5-AM6)<0,AM5) -> 0
A6: =B6+2 -> 18 | B6: 16 | C6: =IFERROR(__xludf.DUMMYFUNCTION("if(importrange($A$3,""CT RR Calculations (Private)!$AB$10"")=""Not Ready"",concatenate(B6,"" Seed Team""),concatenate(B6,"" "", importrange($A$3,CONCATENATE(""CT RR Calculations (Private)!"",""W"",A6))))"),"16 New Canaan HS - Team 3") -> 16 New Canaan HS - Team 3 | D6: 28 | E6: TRUE | F6: =IF(E6=True, IF(D6>D5,2,IF(D6=D5,1,0)),0) -> 0 | G6: ='CT Bracket'!E10 -> 9 Amity Regional HS | H6: 42 | I6: TRUE | J6: =IF(I6=True, IF(H6>H5,2,IF(H6=H5,1,0)),0) -> 0 | K6: ='CT Bracket'!G8 -> BYE | M6: FALSE | N6: =IF(M6=True, IF(L6>L5,2,IF(L6=L5,1,0)),0) -> 0 | O6: ='CT Bracket'!I16 -> 4 Greenwich HS - Team 1 | P6: 94 | Q6: TRUE | R6: =IF(Q6=True, IF(P6>P5,2,IF(P6=P5,1,0)),0) -> 2 | S6: ='CT Bracket'!K12 -> BYE | U6: FALSE | V6: =IF(U6=True, IF(T6>T5,2,IF(T6=T5,1,0)),0) -> 0 | W6: ='CT Bracket'!M28 -> 2 Waterford HS - Team 1 | X6: 58 | Y6: TRUE | Z6: =IFS(X6="",0,(X6-X5)>0,X6+100,(X6-X5)=0,X6+50,(X6-X5)<0,X6) -> 58 | AA6: BYE | AC6: FALSE | AD6: =IF(AC6=True, IF(AB6>AB5,2,IF(AB6=AB5,1,0)),0) -> 0 | AE6: ='CT Bracket'!Q39 -> 1 Farmington HS - Team 1 | AF6: 88 | AG6: TRUE | AH6: =IF(AG6=True, IF(AF6>AF5,2,IF(AF6=AF5,1,0)),0) -> 2 | AI6: =AE6 -> 1 Farmington HS - Team 1 | AJ6: 90 | AK6: TRUE | AL6: =IF(AK6=True, IF(AJ6>AJ5,2,IF(AJ6=AJ5,1,0)),0) -> 0 | AN6: FALSE | AO6: =IFS(AM6="",0,(AM6-AM5)>0,AM6+100,(AM6-AM5)=0,AM6+50,(AM6-AM5)<0,AM6) -> 0
A7: =B7+2 -> 10 | B7: 8 | C7: =IFERROR(__xludf.DUMMYFUNCTION("if(importrange($A$3,""CT RR Calculations (Private)!$AB$10"")=""Not Ready"",concatenate(B7,"" Seed Team""),concatenate(B7,"" "", importrange($A$3,CONCATENATE(""CT RR Calculations (Private)!"",""W"",A7))))"),"8 Rocky Hill HS - Team 1") -> 8 Rocky Hill HS - Team 1 | D7: 66 | E7: TRUE | F7: =IF(E7=True, IF(D7>D8,2,IF(D7=D8,1,0)),0) -> 0 | G7: ='CT Bracket'!E14 -> 5 Southington HS - Team 1 | H7: 26 | I7: TRUE | J7: =IF(I7=True, IF(H7>H8,2,IF(H7=H8,1,0)),0) -> 0 | K7: ='CT Bracket'!G14 -> 4 Greenwich HS - Team 1 | M7: TRUE | N7: =IF(M7=True, IF(L7>L8,2,IF(L7=L8,1,0)),0) -> 1 | O7: ='CT Bracket'!I24 -> 3 EO Smith HS - Team 1 | P7: 80 | Q7: TRUE | R7: =IF(Q7=True, IF(P7>P8,2,IF(P7=P8,1,0)),0) -> 0 | S7: ='CT Bracket'!M28 -> 2 Waterford HS - Team 1 | U7: TRUE | V7: =IF(U7=True, IF(T7>T8,2,IF(T7=T8,1,0)),0) -> 1 | Y7: =IFS(W7="",0,(W7-W8)>0,W7+100,(W7-W8)=0,W7+50,(W7-W8)<0,W7) -> 0 | Z7: =IFS(X7="",0,(X7-X8)>0,X7+100,(X7-X8)=0,X7+50,(X7-X8)<0,X7) -> 0 | AC7: =IFS(AA7="",0,(AA7-AA8)>0,AA7+100,(AA7-AA8)=0,AA7+50,(AA7-AA8)<0,AA7) -> 0 | AD7: =IFS(AB7="",0,(AB7-AB8)>0,AB7+100,(AB7-AB8)=0,AB7+50,(AB7-AB8)<0,AB7) -> 0 | AG7: =IFS(AE7="",0,(AE7-AE8)>0,AE7+100,(AE7-AE8)=0,AE7+50,(AE7-AE8)<0,AE7) -> 0 | AH7: =IFS(AF7="",0,(AF7-AF8)>0,AF7+100,(AF7-AF8)=0,AF7+50,(AF7-AF8)<0,AF7) -> 0 | AK7: =IFS(AI7="",0,(AI7-AI8)>0,AI7+100,(AI7-AI8)=0,AI7+50,(AI7-AI8)<0,AI7) -> 0 | AL7: =IFS(AJ7="",0,(AJ7-AJ8)>0,AJ7+100,(AJ7-AJ8)=0,AJ7+50,(AJ7-AJ8)<0,AJ7) -> 0 | AN7: =IFS(AL7="",0,(AL7-AL8)>0,AL7+100,(AL7-AL8)=0,AL7+50,(AL7-AL8)<0,AL7) -> 50 | AO7: =IFS(AM7="",0,(AM7-AM8)>0,AM7+100,(AM7-AM8)=0,AM7+50,(AM7-AM8)<0,AM7) -> 0
A8: =B8+2 -> 11 | B8: 9 | C8: =IFERROR(__xludf.DUMMYFUNCTION("if(importrange($A$3,""CT RR Calculations (Private)!$AB$10"")=""Not Ready"",concatenate(B8,"" Seed Team""),concatenate(B8,"" "", importrange($A$3,CONCATENATE(""CT RR Calculations (Private)!"",""W"",A8))))"),"9 Amity Regional HS") -> 9 Amity Regional HS | D8: 78 | E8: TRUE | F8: =IF(E8=True, IF(D8>D7,2,IF(D8=D7,1,0)),0) -> 2 | G8: ='CT Bracket'!E18 -> 4 Greenwich HS - Team 1 | H8: 140 | I8: TRUE | J8: =IF(I8=True, IF(H8>H7,2,IF(H8=H7,1,0)),0) -> 2 | K8: ='CT Bracket'!G16 -> BYE | M8: FALSE | N8: =IF(M8=True, IF(L8>L7,2,IF(L8=L7,1,0)),0) -> 0 | O8: ='CT Bracket'!I32 -> 2 Waterford HS - Team 1 | P8: 84 | Q8: TRUE | R8: =IF(Q8=True, IF(P8>P7,2,IF(P8=P7,1,0)),0) -> 2 | S8: ='CT Bracket'!K28 -> BYE | U8: FALSE | V8: =IF(U8=True, IF(T8>T7,2,IF(T8=T7,1,0)),0) -> 0 | Y8: =IFS(W8="",0,(W8-W7)>0,W8+100,(W8-W7)=0,W8+50,(W8-W7)<0,W8) -> 0 | Z8: =IFS(X8="",0,(X8-X7)>0,X8+100,(X8-X7)=0,X8+50,(X8-X7)<0,X8) -> 0 | AC8: =IFS(AA8="",0,(AA8-AA7)>0,AA8+100,(AA8-AA7)=0,AA8+50,(AA8-AA7)<0,AA8) -> 0 | AD8: =IFS(AB8="",0,(AB8-AB7)>0,AB8+100,(AB8-AB7)=0,AB8+50,(AB8-AB7)<0,AB8) -> 0 | AG8: =IFS(AE8="",0,(AE8-AE7)>0,AE8+100,(AE8-AE7)=0,AE8+50,(AE8-AE7)<0,AE8) -> 0 | AH8: =IFS(AF8="",0,(AF8-AF7)>0,AF8+100,(AF8-AF7)=0,AF8+50,(AF8-AF7)<0,AF8) -> 0 | AK8: =IFS(AI8="",0,(AI8-AI7)>0,AI8+100,(AI8-AI7)=0,AI8+50,(AI8-AI7)<0,AI8) -> 0 | AL8: =IFS(AJ8="",0,(AJ8-AJ7)>0,AJ8+100,(AJ8-AJ7)=0,AJ8+50,(AJ8-AJ7)<0,AJ8) -> 0 | AN8: =IFS(AL8="",0,(AL8-AL7)>0,AL8+100,(AL8-AL7)=0,AL8+50,(AL8-AL7)<0,AL8) -> 50 | AO8: =IFS(AM8="",0,(AM8-AM7)>0,AM8+100,(AM8-AM7)=0,AM8+50,(AM8-AM7)<0,AM8) -> 0
A9: =B9+2 -> 7 | B9: 5 | C9: =IFERROR(__xludf.DUMMYFUNCTION("if(importrange($A$3,""CT RR Calculations (Private)!$AB$10"")=""Not Ready"",concatenate(B9,"" Seed Team""),concatenate(B9,"" "", importrange($A$3,CONCATENATE(""CT RR Calculations (Private)!"",""W"",A9))))"),"5 Southington HS - Team 1") -> 5 Southington HS - Team 1 | D9: 56 | E9: TRUE | F9: =IF(E9=True, IF(D9>D10,2,IF(D9=D10,1,0)),0) -> 2 | G9: ='CT Bracket'!E22 -> 3 EO Smith HS - Team 1 | H9: 80 | I9: TRUE | J9: =IF(I9=True, IF(H9>H10,2,IF(H9=H10,1,0)),0) -> 2 | K9: ='CT Bracket'!G22 -> 3 EO Smith HS - Team 1 | M9: TRUE | N9: =IF(M9=True, IF(L9>L10,2,IF(L9=L10,1,0)),0) -> 1 | Q9: =IFS(O9="",0,(O9-O10)>0,O9+100,(O9-O10)=0,O9+50,(O9-O10)<0,O9) -> 0 | R9: =IFS(P9="",0,(P9-P10)>0,P9+100,(P9-P10)=0,P9+50,(P9-P10)<0,P9) -> 0 | U9: =IFS(S9="",0,(S9-S10)>0,S9+100,(S9-S10)=0,S9+50,(S9-S10)<0,S9) -> 0 | V9: =IFS(T9="",0,(T9-T10)>0,T9+100,(T9-T10)=0,T9+50,(T9-T10)<0,T9) -> 0 | Y9: =IFS(W9="",0,(W9-W10)>0,W9+100,(W9-W10)=0,W9+50,(W9-W10)<0,W9) -> 0 | Z9: =IFS(X9="",0,(X9-X10)>0,X9+100,(X9-X10)=0,X9+50,(X9-X10)<0,X9) -> 0 | AC9: =IFS(AA9="",0,(AA9-AA10)>0,AA9+100,(AA9-AA10)=0,AA9+50,(AA9-AA10)<0,AA9) -> 0 | AD9: =IFS(AB9="",0,(AB9-AB10)>0,AB9+100,(AB9-AB10)=0,AB9+50,(AB9-AB10)<0,AB9) -> 0 | AG9: =IFS(AE9="",0,(AE9-AE10)>0,AE9+100,(AE9-AE10)=0,AE9+50,(AE9-AE10)<0,AE9) -> 0 | AH9: =IFS(AF9="",0,(AF9-AF10)>0,AF9+100,(AF9-AF10)=0,AF9+50,(AF9-AF10)<0,AF9) -> 0 | AK9: =IFS(AI9="",0,(AI9-AI10)>0,AI9+100,(AI9-AI10)=0,AI9+50,(AI9-AI10)<0,AI9) -> 0 | AL9: =IFS(AJ9="",0,(AJ9-AJ10)>0,AJ9+100,(AJ9-AJ10)=0,AJ9+50,(AJ9-AJ10)<0,AJ9) -> 0 | AN9: =IFS(AL9="",0,(AL9-AL10)>0,AL9+100,(AL9-AL10)=0,AL9+50,(AL9-AL10)<0,AL9) -> 50 | AO9: =IFS(AM9="",0,(AM9-AM10)>0,AM9+100,(AM9-AM10)=0,AM9+50,(AM9-AM10)<0,AM9) -> 0
A10: =B10+2 -> 14 | B10: 12 | C10: =IFERROR(__xludf.DUMMYFUNCTION("if(importrange($A$3,""CT RR Calculations (Private)!$AB$10"")=""Not Ready"",concatenate(B10,"" Seed Team""),concatenate(B10,"" "", importrange($A$3,CONCATENATE(""CT RR Calculations (Private)!"",""W"",A10))))"),"12 Univ HS Sci & Eng") -> 12 Univ HS Sci & Eng | D10: 32 | E10: TRUE | F10: =IF(E10=True, IF(D10>D9,2,IF(D10=D9,1,0)),0) -> 0 | G10: ='CT Bracket'!E26 -> 6 Farmington HS - Team 2 | H10: 42 | I10: TRUE | J10: =IF(I10=True, IF(H10>H9,2,IF(H10=H9,1,0)),0) -> 0 | K10: ='CT Bracket'!G24 -> BYE | M10: FALSE | N10: =IF(M10=True, IF(L10>L9,2,IF(L10=L9,1,0)),0) -> 0 | Q10: =IFS(O10="",0,(O10-O9)>0,O10+100,(O10-O9)=0,O10+50,(O10-O9)<0,O10) -> 0 | R10: =IFS(P10="",0,(P10-P9)>0,P10+100,(P10-P9)=0,P10+50,(P10-P9)<0,P10) -> 0 | U10: =IFS(S10="",0,(S10-S9)>0,S10+100,(S10-S9)=0,S10+50,(S10-S9)<0,S10) -> 0 | V10: =IFS(T10="",0,(T10-T9)>0,T10+100,(T10-T9)=0,T10+50,(T10-T9)<0,T10) -> 0 | Y10: =IFS(W10="",0,(W10-W9)>0,W10+100,(W10-W9)=0,W10+50,(W10-W9)<0,W10) -> 0 | Z10: =IFS(X10="",0,(X10-X9)>0,X10+100,(X10-X9)=0,X10+50,(X10-X9)<0,X10) -> 0 | AC10: =IFS(AA10="",0,(AA10-AA9)>0,AA10+100,(AA10-AA9)=0,AA10+50,(AA10-AA9)<0,AA10) -> 0 | AD10: =IFS(AB10="",0,(AB10-AB9)>0,AB10+100,(AB10-AB9)=0,AB10+50,(AB10-AB9)<0,AB10) -> 0 | AG10: =IFS(AE10="",0,(AE10-AE9)>0,AE10+100,(AE10-AE9)=0,AE10+50,(AE10-AE9)<0,AE10) -> 0 | AH10: =IFS(AF10="",0,(AF10-AF9)>0,AF10+100,(AF10-AF9)=0,AF10+50,(AF10-AF9)<0,AF10) -> 0 | AK10: =IFS(AI10="",0,(AI10-AI9)>0,AI10+100,(AI10-AI9)=0,AI10+50,(AI10-AI9)<0,AI10) -> 0 | AL10: =IFS(AJ10="",0,(AJ10-AJ9)>0,AJ10+100,(AJ10-AJ9)=0,AJ10+50,(AJ10-AJ9)<0,AJ10) -> 0 | AN10: =IFS(AL10="",0,(AL10-AL9)>0,AL10+100,(AL10-AL9)=0,AL10+50,(AL10-AL9)<0,AL10) -> 50 | AO10: =IFS(AM10="",0,(AM10-AM9)>0,AM10+100,(AM10-AM9)=0,AM10+50,(AM10-AM9)<0,AM10) -> 0
A11: =B11+2 -> 15 | B11: 13 | C11: =IFERROR(__xludf.DUMMYFUNCTION("if(importrange($A$3,""CT RR Calculations (Private)!$AB$10"")=""Not Ready"",concatenate(B11,"" Seed Team""),concatenate(B11,"" "", importrange($A$3,CONCATENATE(""CT RR Calculations (Private)!"",""W"",A11))))"),"13 Fairfield Warde HS - Team 1") -> 13 Fairfield Warde HS - Team 1 | D11: 48 | E11: TRUE | F11: =IF(E11=True, IF(D11>D12,2,IF(D11=D12,1,0)),0) -> 0 | G11: ='CT Bracket'!E30 -> 7 Loomis Chaffee - Team 1 | H11: 68 | I11: TRUE | J11: =IF(I11=True, IF(H11>H12,2,IF(H11=H12,1,0)),0) -> 0 | K11: ='CT Bracket'!G30 -> 2 Waterford HS - Team 1 | M11: TRUE | N11: =IF(M11=True, IF(L11>L12,2,IF(L11=L12,1,0)),0) -> 1 | Q11: =IFS(O11="",0,(O11-O12)>0,O11+100,(O11-O12)=0,O11+50,(O11-O12)<0,O11) -> 0 | R11: =IFS(P11="",0,(P11-P12)>0,P11+100,(P11-P12)=0,P11+50,(P11-P12)<0,P11) -> 0 | U11: =IFS(S11="",0,(S11-S12)>0,S11+100,(S11-S12)=0,S11+50,(S11-S12)<0,S11) -> 0 | V11: =IFS(T11="",0,(T11-T12)>0,T11+100,(T11-T12)=0,T11+50,(T11-T12)<0,T11) -> 0 | Y11: =IFS(W11="",0,(W11-W12)>0,W11+100,(W11-W12)=0,W11+50,(W11-W12)<0,W11) -> 0 | Z11: =IFS(X11="",0,(X11-X12)>0,X11+100,(X11-X12)=0,X11+50,(X11-X12)<0,X11) -> 0 | AC11: =IFS(AA11="",0,(AA11-AA12)>0,AA11+100,(AA11-AA12)=0,AA11+50,(AA11-AA12)<0,AA11) -> 0 | AD11: =IFS(AB11="",0,(AB11-AB12)>0,AB11+100,(AB11-AB12)=0,AB11+50,(AB11-AB12)<0,AB11) -> 0 | AG11: =IFS(AE11="",0,(AE11-AE12)>0,AE11+100,(AE11-AE12)=0,AE11+50,(AE11-AE12)<0,AE11) -> 0 | AH11: =IFS(AF11="",0,(AF11-AF12)>0,AF11+100,(AF11-AF12)=0,AF11+50,(AF11-AF12)<0,AF11) -> 0 | AK11: =IFS(AI11="",0,(AI11-AI12)>0,AI11+100,(AI11-AI12)=0,AI11+50,(AI11-AI12)<0,AI11) -> 0 | AL11: =IFS(AJ11="",0,(AJ11-AJ12)>0,AJ11+100,(AJ11-AJ12)=0,AJ11+50,(AJ11-AJ12)<0,AJ11) -> 0 | AN11: =IFS(AL11="",0,(AL11-AL12)>0,AL11+100,(AL11-AL12)=0,AL11+50,(AL11-AL12)<0,AL11) -> 50 | AO11: =IFS(AM11="",0,(AM11-AM12)>0,AM11+100,(AM11-AM12)=0,AM11+50,(AM11-AM12)<0,AM11) -> 0
A12: =B12+2 -> 6 | B12: 4 | C12: =IFERROR(__xludf.DUMMYFUNCTION("if(importrange($A$3,""CT RR Calculations (Private)!$AB$10"")=""Not Ready"",concatenate(B12,"" Seed Team""),concatenate(B12,"" "", importrange($A$3,CONCATENATE(""CT RR Calculations (Private)!"",""W"",A12))))"),"4 Greenwich HS - Team 1") -> 4 Greenwich HS - Team 1 | D12: 104 | E12: TRUE | F12: =IF(E12=True, IF(D12>D11,2,IF(D12=D11,1,0)),0) -> 2 | G12: ='CT Bracket'!E34 -> 2 Waterford HS - Team 1 | H12: 94 | I12: TRUE | J12: =IF(I12=True, IF(H12>H11,2,IF(H12=H11,1,0)),0) -> 2 | K12: ='CT Bracket'!G32 -> BYE | M12: FALSE | N12: =IF(M12=True, IF(L12>L11,2,IF(L12=L11,1,0)),0) -> 0 | Q12: =IFS(O12="",0,(O12-O11)>0,O12+100,(O12-O11)=0,O12+50,(O12-O11)<0,O12) -> 0 | R12: =IFS(P12="",0,(P12-P11)>0,P12+100,(P12-P11)=0,P12+50,(P12-P11)<0,P12) -> 0 | U12: =IFS(S12="",0,(S12-S11)>0,S12+100,(S12-S11)=0,S12+50,(S12-S11)<0,S12) -> 0 | V12: =IFS(T12="",0,(T12-T11)>0,T12+100,(T12-T11)=0,T12+50,(T12-T11)<0,T12) -> 0 | Y12: =IFS(W12="",0,(W12-W11)>0,W12+100,(W12-W11)=0,W12+50,(W12-W11)<0,W12) -> 0 | Z12: =IFS(X12="",0,(X12-X11)>0,X12+100,(X12-X11)=0,X12+50,(X12-X11)<0,X12) -> 0 | AC12: =IFS(AA12="",0,(AA12-AA11)>0,AA12+100,(AA12-AA11)=0,AA12+50,(AA12-AA11)<0,AA12) -> 0 | AD12: =IFS(AB12="",0,(AB12-AB11)>0,AB12+100,(AB12-AB11)=0,AB12+50,(AB12-AB11)<0,AB12) -> 0 | AG12: =IFS(AE12="",0,(AE12-AE11)>0,AE12+100,(AE12-AE11)=0,AE12+50,(AE12-AE11)<0,AE12) -> 0 | AH12: =IFS(AF12="",0,(AF12-AF11)>0,AF12+100,(AF12-AF11)=0,AF12+50,(AF12-AF11)<0,AF12) -> 0 | AK12: =IFS(AI12="",0,(AI12-AI11)>0,AI12+100,(AI12-AI11)=0,AI12+50,(AI12-AI11)<0,AI12) -> 0 | AL12: =IFS(AJ12="",0,(AJ12-AJ11)>0,AJ12+100,(AJ12-AJ11)=0,AJ12+50,(AJ12-AJ11)<0,AJ12) -> 0 | AN12: =IFS(AL12="",0,(AL12-AL11)>0,AL12+100,(AL12-AL11)=0,AL12+50,(AL12-AL11)<0,AL12) -> 50 | AO12: =IFS(AM12="",0,(AM12-AM11)>0,AM12+100,(AM12-AM11)=0,AM12+50,(AM12-AM11)<0,AM12) -> 0
A13: =B13+2 -> 5 | B13: 3 | C13: =IFERROR(__xludf.DUMMYFUNCTION("if(importrange($A$3,""CT RR Calculations (Private)!$AB$10"")=""Not Ready"",concatenate(B13,"" Seed Team""),concatenate(B13,"" "", importrange($A$3,CONCATENATE(""CT RR Calculations (Private)!"",""W"",A13))))"),"3 EO Smith HS - Team 1") -> 3 EO Smith HS - Team 1 | D13: 146 | E13: TRUE | F13: =IF(E13=True, IF(D13>D14,2,IF(D13=D14,1,0)),0) -> 2 | G13: ='CT Bracket'!E38 -> 16 New Canaan HS - Team 3 | H13: 26 | I13: TRUE | J13: =IF(I13=True, IF(H13>H14,2,IF(H13=H14,1,0)),0) -> 0 | K13: ='CT Bracket'!G37 -> 9 Amity Regional HS | L13: 62 | M13: TRUE | N13: =IF(M13=True, IF(L13>L14,2,IF(L13=L14,1,0)),0) -> 2 | O13: ='CT Bracket'!I38 -> 9 Amity Regional HS | P13: 18 | Q13: TRUE | R13: =IF(Q13=True, IF(P13>P14,2,IF(P13=P14,1,0)),0) -> 0 | S13: ='CT Bracket'!K36 -> 1 Farmington HS - Team 1 | T13: 138 | U13: TRUE | V13: =IF(U13=True, IF(T13>T14,2,IF(T13=T14,1,0)),0) -> 2 | W13: ='CT Bracket'!M38 -> 1 Farmington HS - Team 1 | X13: 90 | Y13: TRUE | Z13: =IFS(X13="",0,(X13-X14)>0,X13+100,(X13-X14)=0,X13+50,(X13-X14)<0,X13) -> 190 | AA13: ='CT Bracket'!O36 -> 2 Waterford HS - Team 1 | AB13: 58 | AC13: TRUE | AD13: =IF(AC13=True, IF(AB13>AB14,2,IF(AB13=AB14,1,0)),0) -> 0 | AG13: =IFS(AE13="",0,(AE13-AE14)>0,AE13+100,(AE13-AE14)=0,AE13+50,(AE13-AE14)<0,AE13) -> 0 | AH13: =IFS(AF13="",0,(AF13-AF14)>0,AF13+100,(AF13-AF14)=0,AF13+50,(AF13-AF14)<0,AF13) -> 0 | AK13: =IFS(AI13="",0,(AI13-AI14)>0,AI13+100,(AI13-AI14)=0,AI13+50,(AI13-AI14)<0,AI13) -> 0 | AL13: =IFS(AJ13="",0,(AJ13-AJ14)>0,AJ13+100,(AJ13-AJ14)=0,AJ13+50,(AJ13-AJ14)<0,AJ13) -> 0 | AN13: FALSE | AO13: =IFS(AM13="",0,(AM13-AM14)>0,AM13+100,(AM13-AM14)=0,AM13+50,(AM13-AM14)<0,AM13) -> 0
A14: =B14+2 -> 16 | B14: 14 | C14: =IFERROR(__xludf.DUMMYFUNCTION("if(importrange($A$3,""CT RR Calculations (Private)!$AB$10"")=""Not Ready"",concatenate(B14,"" Seed Team""),concatenate(B14,"" "", importrange($A$3,CONCATENATE(""CT RR Calculations (Private)!"",""W"",A14))))"),"14 South Windsor HS - Team 2") -> 14 South Windsor HS - Team 2 | D14: 28 | E14: TRUE | F14: =IF(E14=True, IF(D14>D13,2,IF(D14=D13,1,0)),0) -> 0 | G14: ='CT Bracket'!E40 -> 8 Rocky Hill HS - Team 1 | H14: 80 | I14: TRUE | J14: =IF(I14=True, IF(H14>H13,2,IF(H14=H13,1,0)),0) -> 2 | K14: ='CT Bracket'!G39 -> 8 Rocky Hill HS - Team 1 | L14: 52 | M14: TRUE | N14: =IF(M14=True, IF(L14>L13,2,IF(L14=L13,1,0)),0) -> 0 | O14: ='CT Bracket'!I42 -> 5 Southington HS - Team 1 | P14: 104 | Q14: TRUE | R14: =IF(Q14=True, IF(P14>P13,2,IF(P14=P13,1,0)),0) -> 2 | S14: ='CT Bracket'!K40 -> 5 Southington HS - Team 1 | T14: 18 | U14: TRUE | V14: =IF(U14=True, IF(T14>T13,2,IF(T14=T13,1,0)),0) -> 0 | W14: ='CT Bracket'!M46 -> 3 EO Smith HS - Team 1 | X14: 48 | Y14: TRUE | Z14: =IFS(X14="",0,(X14-X13)>0,X14+100,(X14-X13)=0,X14+50,(X14-X13)<0,X14) -> 48 | AA14: ='CT Bracket'!O42 -> 1 Farmington HS - Team 1 | AB14: 114 | AC14: TRUE | AD14: =IF(AC14=True, IF(AB14>AB13,2,IF(AB14=AB13,1,0)),0) -> 2 | AG14: =IFS(AE14="",0,(AE14-AE13)>0,AE14+100,(AE14-AE13)=0,AE14+50,(AE14-AE13)<0,AE14) -> 0 | AH14: =IFS(AF14="",0,(AF14-AF13)>0,AF14+100,(AF14-AF13)=0,AF14+50,(AF14-AF13)<0,AF14) -> 0 | AK14: =IFS(AI14="",0,(AI14-AI13)>0,AI14+100,(AI14-AI13)=0,AI14+50,(AI14-AI13)<0,AI14) -> 0 | AL14: =IFS(AJ14="",0,(AJ14-AJ13)>0,AJ14+100,(AJ14-AJ13)=0,AJ14+50,(AJ14-AJ13)<0,AJ14) -> 0 | AN14: FALSE | AO14: =IFS(AM14="",0,(AM14-AM13)>0,AM14+100,(AM14-AM13)=0,AM14+50,(AM14-AM13)<0,AM14) -> 0
A15: =B15+2 -> 8 | B15: 6 | C15: =IFERROR(__xludf.DUMMYFUNCTION("if(importrange($A$3,""CT RR Calculations (Private)!$AB$10"")=""Not Ready"",concatenate(B15,"" Seed Team""),concatenate(B15,"" "", importrange($A$3,CONCATENATE(""CT RR Calculations (Private)!"",""W"",A15))))"),"6 Farmington HS - Team 2") -> 6 Farmington HS - Team 2 | D15: 64 | E15: TRUE | F15: =IF(E15=True, IF(D15>D16,2,IF(D15=D16,1,0)),0) -> 2 | G15: ='CT Bracket'!E42 -> 12 Univ HS Sci & Eng | H15: 72 | I15: TRUE | J15: =IF(I15=True, IF(H15>H16,2,IF(H15=H16,1,0)),0) -> 2 | K15: ='CT Bracket'!G41 -> 5 Southington HS - Team 1 | L15: 76 | M15: TRUE | N15: =IF(M15=True, IF(L15>L16,2,IF(L15=L16,1,0)),0) -> 2 | O15: ='CT Bracket'!I46 -> 6 Farmington HS - Team 2 | P15: 52 | Q15: TRUE | R15: =IF(Q15=True, IF(P15>P16,2,IF(P15=P16,1,0)),0) -> 0 | S15: ='CT Bracket'!K44 -> 3 EO Smith HS - Team 1 | T15: 80 | U15: TRUE | V15: =IF(U15=True, IF(T15>T16,2,IF(T15=T16,1,0)),0) -> 2 | Y15: =IFS(W15="",0,(W15-W16)>0,W15+100,(W15-W16)=0,W15+50,(W15-W16)<0,W15) -> 0 | Z15: =IFS(X15="",0,(X15-X16)>0,X15+100,(X15-X16)=0,X15+50,(X15-X16)<0,X15) -> 0 | AC15: =IFS(AA15="",0,(AA15-AA16)>0,AA15+100,(AA15-AA16)=0,AA15+50,(AA15-AA16)<0,AA15) -> 0 | AD15: =IFS(AB15="",0,(AB15-AB16)>0,AB15+100,(AB15-AB16)=0,AB15+50,(AB15-AB16)<0,AB15) -> 0 | AG15: =IFS(AE15="",0,(AE15-AE16)>0,AE15+100,(AE15-AE16)=0,AE15+50,(AE15-AE16)<0,AE15) -> 0 | AH15: =IFS(AF15="",0,(AF15-AF16)>0,AF15+100,(AF15-AF16)=0,AF15+50,(AF15-AF16)<0,AF15) -> 0 | AK15: =IFS(AI15="",0,(AI15-AI16)>0,AI15+100,(AI15-AI16)=0,AI15+50,(AI15-AI16)<0,AI15) -> 0 | AL15: =IFS(AJ15="",0,(AJ15-AJ16)>0,AJ15+100,(AJ15-AJ16)=0,AJ15+50,(AJ15-AJ16)<0,AJ15) -> 0 | AN15: =IFS(AL15="",0,(AL15-AL16)>0,AL15+100,(AL15-AL16)=0,AL15+50,(AL15-AL16)<0,AL15) -> 50 | AO15: =IFS(AM15="",0,(AM15-AM16)>0,AM15+100,(AM15-AM16)=0,AM15+50,(AM15-AM16)<0,AM15) -> 0
A16: =B16+2 -> 13 | B16: 11 | C16: =IFERROR(__xludf.DUMMYFUNCTION("if(importrange($A$3,""CT RR Calculations (Private)!$AB$10"")=""Not Ready"",concatenate(B16,"" Seed Team""),concatenate(B16,"" "", importrange($A$3,CONCATENATE(""CT RR Calculations (Private)!"",""W"",A16))))"),"11 New Canaan HS - Team 1") -> 11 New Canaan HS - Team 1 | D16: 56 | E16: TRUE | F16: =IF(E16=True, IF(D16>D15,2,IF(D16=D15,1,0)),0) -> 0 | G16: ='CT Bracket'!E44 -> 13 Fairfield Warde HS - Team 1 | H16: 30 | I16: TRUE | J16: =IF(I16=True, IF(H16>H15,2,IF(H16=H15,1,0)),0) -> 0 | K16: ='CT Bracket'!G43 -> 12 Univ HS Sci & Eng | L16: 52 | M16: TRUE | N16: =IF(M16=True, IF(L16>L15,2,IF(L16=L15,1,0)),0) -> 0 | O16: ='CT Bracket'!I50 -> 7 Loomis Chaffee - Team 1 | P16: 64 | Q16: TRUE | R16: =IF(Q16=True, IF(P16>P15,2,IF(P16=P15,1,0)),0) -> 2 | S16: ='CT Bracket'!K48 -> 7 Loomis Chaffee - Team 1 | T16: 42 | U16: TRUE | V16: =IF(U16=True, IF(T16>T15,2,IF(T16=T15,1,0)),0) -> 0 | Y16: =IFS(W16="",0,(W16-W15)>0,W16+100,(W16-W15)=0,W16+50,(W16-W15)<0,W16) -> 0 | Z16: =IFS(X16="",0,(X16-X15)>0,X16+100,(X16-X15)=0,X16+50,(X16-X15)<0,X16) -> 0 | AC16: =IFS(AA16="",0,(AA16-AA15)>0,AA16+100,(AA16-AA15)=0,AA16+50,(AA16-AA15)<0,AA16) -> 0 | AD16: =IFS(AB16="",0,(AB16-AB15)>0,AB16+100,(AB16-AB15)=0,AB16+50,(AB16-AB15)<0,AB16) -> 0 | AG16: =IFS(AE16="",0,(AE16-AE15)>0,AE16+100,(AE16-AE15)=0,AE16+50,(AE16-AE15)<0,AE16) -> 0 | AH16: =IFS(AF16="",0,(AF16-AF15)>0,AF16+100,(AF16-AF15)=0,AF16+50,(AF16-AF15)<0,AF16) -> 0 | AK16: =IFS(AI16="",0,(AI16-AI15)>0,AI16+100,(AI16-AI15)=0,AI16+50,(AI16-AI15)<0,AI16) -> 0 | AL16: =IFS(AJ16="",0,(AJ16-AJ15)>0,AJ16+100,(AJ16-AJ15)=0,AJ16+50,(AJ16-AJ15)<0,AJ16) -> 0 | AN16: =IFS(AL16="",0,(AL16-AL15)>0,AL16+100,(AL16-AL15)=0,AL16+50,(AL16-AL15)<0,AL16) -> 50 | AO16: =IFS(AM16="",0,(AM16-AM15)>0,AM16+100,(AM16-AM15)=0,AM16+50,(AM16-AM15)<0,AM16) -> 0
A17: =B17+2 -> 9 | B17: 7 | C17: =IFERROR(__xludf.DUMMYFUNCTION("if(importrange($A$3,""CT RR Calculations (Private)!$AB$10"")=""Not Ready"",concatenate(B17,"" Seed Team""),concatenate(B17,"" "", importrange($A$3,CONCATENATE(""CT RR Calculations (Private)!"",""W"",A17))))"),"7 Loomis Chaffee - Team 1") -> 7 Loomis Chaffee - Team 1 | D17: 116 | E17: TRUE | F17: =IF(E17=True, IF(D17>D18,2,IF(D17=D18,1,0)),0) -> 2 | G17: ='CT Bracket'!E46 -> 14 South Windsor HS - Team 2 | H17: 68 | I17: TRUE | J17: =IF(I17=True, IF(H17>H18,2,IF(H17=H18,1,0)),0) -> 2 | K17: ='CT Bracket'!G45 -> 6 Farmington HS - Team 2 | L17: 96 | M17: TRUE | N17: =IF(M17=True, IF(L17>L18,2,IF(L17=L18,1,0)),0) -> 2 | Q17: =IFS(O17="",0,(O17-O18)>0,O17+100,(O17-O18)=0,O17+50,(O17-O18)<0,O17) -> 0 | R17: =IFS(P17="",0,(P17-P18)>0,P17+100,(P17-P18)=0,P17+50,(P17-P18)<0,P17) -> 0 | U17: =IFS(S17="",0,(S17-S18)>0,S17+100,(S17-S18)=0,S17+50,(S17-S18)<0,S17) -> 0 | V17: =IFS(T17="",0,(T17-T18)>0,T17+100,(T17-T18)=0,T17+50,(T17-T18)<0,T17) -> 0 | Y17: =IFS(W17="",0,(W17-W18)>0,W17+100,(W17-W18)=0,W17+50,(W17-W18)<0,W17) -> 0 | Z17: =IFS(X17="",0,(X17-X18)>0,X17+100,(X17-X18)=0,X17+50,(X17-X18)<0,X17) -> 0 | AC17: =IFS(AA17="",0,(AA17-AA18)>0,AA17+100,(AA17-AA18)=0,AA17+50,(AA17-AA18)<0,AA17) -> 0 | AD17: =IFS(AB17="",0,(AB17-AB18)>0,AB17+100,(AB17-AB18)=0,AB17+50,(AB17-AB18)<0,AB17) -> 0 | AG17: =IFS(AE17="",0,(AE17-AE18)>0,AE17+100,(AE17-AE18)=0,AE17+50,(AE17-AE18)<0,AE17) -> 0 | AH17: =IFS(AF17="",0,(AF17-AF18)>0,AF17+100,(AF17-AF18)=0,AF17+50,(AF17-AF18)<0,AF17) -> 0 | AK17: =IFS(AI17="",0,(AI17-AI18)>0,AI17+100,(AI17-AI18)=0,AI17+50,(AI17-AI18)<0,AI17) -> 0 | AL17: =IFS(AJ17="",0,(AJ17-AJ18)>0,AJ17+100,(AJ17-AJ18)=0,AJ17+50,(AJ17-AJ18)<0,AJ17) -> 0 | AN17: =IFS(AL17="",0,(AL17-AL18)>0,AL17+100,(AL17-AL18)=0,AL17+50,(AL17-AL18)<0,AL17) -> 50 | AO17: =IFS(AM17="",0,(AM17-AM18)>0,AM17+100,(AM17-AM18)=0,AM17+50,(AM17-AM18)<0,AM17) -> 0
A18: =B18+2 -> 12 | B18: 10 | C18: =IFERROR(__xludf.DUMMYFUNCTION("if(importrange($A$3,""CT RR Calculations (Private)!$AB$10"")=""Not Ready"",concatenate(B18,"" Seed Team""),concatenate(B18,"" "", importrange($A$3,CONCATENATE(""CT RR Calculations (Private)!"",""W"",A18))))"),"10 Greenwich HS - Team 2") -> 10 Greenwich HS - Team 2 | D18: 26 | E18: TRUE | F18: =IF(E18=True, IF(D18>D17,2,IF(D18=D17,1,0)),0) -> 0 | G18: ='CT Bracket'!E48 -> 11 New Canaan HS - Team 1 | H18: 16 | I18: TRUE | J18: =IF(I18=True, IF(H18>H17,2,IF(H18=H17,1,0)),0) -> 0 | K18: ='CT Bracket'!G47 -> 14 South Windsor HS - Team 2 | L18: 20 | M18: TRUE | N18: =IF(M18=True, IF(L18>L17,2,IF(L18=L17,1,0)),0) -> 0 | Q18: =IFS(O18="",0,(O18-O17)>0,O18+100,(O18-O17)=0,O18+50,(O18-O17)<0,O18) -> 0 | R18: =IFS(P18="",0,(P18-P17)>0,P18+100,(P18-P17)=0,P18+50,(P18-P17)<0,P18) -> 0 | U18: =IFS(S18="",0,(S18-S17)>0,S18+100,(S18-S17)=0,S18+50,(S18-S17)<0,S18) -> 0 | V18: =IFS(T18="",0,(T18-T17)>0,T18+100,(T18-T17)=0,T18+50,(T18-T17)<0,T18) -> 0 | Y18: =IFS(W18="",0,(W18-W17)>0,W18+100,(W18-W17)=0,W18+50,(W18-W17)<0,W18) -> 0 | Z18: =IFS(X18="",0,(X18-X17)>0,X18+100,(X18-X17)=0,X18+50,(X18-X17)<0,X18) -> 0 | AC18: =IFS(AA18="",0,(AA18-AA17)>0,AA18+100,(AA18-AA17)=0,AA18+50,(AA18-AA17)<0,AA18) -> 0 | AD18: =IFS(AB18="",0,(AB18-AB17)>0,AB18+100,(AB18-AB17)=0,AB18+50,(AB18-AB17)<0,AB18) -> 0 | AG18: =IFS(AE18="",0,(AE18-AE17)>0,AE18+100,(AE18-AE17)=0,AE18+50,(AE18-AE17)<0,AE18) -> 0 | AH18: =IFS(AF18="",0,(AF18-AF17)>0,AF18+100,(AF18-AF17)=0,AF18+50,(AF18-AF17)<0,AF18) -> 0 | AK18: =IFS(AI18="",0,(AI18-AI17)>0,AI18+100,(AI18-AI17)=0,AI18+50,(AI18-AI17)<0,AI18) -> 0 | AL18: =IFS(AJ18="",0,(AJ18-AJ17)>0,AJ18+100,(AJ18-AJ17)=0,AJ18+50,(AJ18-AJ17)<0,AJ18) -> 0 | AN18: =IFS(AL18="",0,(AL18-AL17)>0,AL18+100,(AL18-AL17)=0,AL18+50,(AL18-AL17)<0,AL18) -> 50 | AO18: =IFS(AM18="",0,(AM18-AM17)>0,AM18+100,(AM18-AM17)=0,AM18+50,(AM18-AM17)<0,AM18) -> 0
A19: =B19+2 -> 17 | B19: 15 | C19: =IFERROR(__xludf.DUMMYFUNCTION("if(importrange($A$3,""CT RR Calculations (Private)!$AB$10"")=""Not Ready"",concatenate(B19,"" Seed Team""),concatenate(B19,"" "", importrange($A$3,CONCATENATE(""CT RR Calculations (Private)!"",""W"",A19))))"),"15 EO Smith HS - Team 2") -> 15 EO Smith HS - Team 2 | D19: 8 | E19: TRUE | F19: =IF(E19=True, IF(D19>D20,2,IF(D19=D20,1,0)),0) -> 0 | G19: ='CT Bracket'!E50 -> 10 Greenwich HS - Team 2 | H19: 30 | I19: TRUE | J19: =IF(I19=True, IF(H19>H20,2,IF(H19=H20,1,0)),0) -> 0 | K19: ='CT Bracket'!G49 -> 7 Loomis Chaffee - Team 1 | L19: 120 | M19: TRUE | N19: =IF(M19=True, IF(L19>L20,2,IF(L19=L20,1,0)),0) -> 2 | Q19: =IFS(O19="",0,(O19-O20)>0,O19+100,(O19-O20)=0,O19+50,(O19-O20)<0,O19) -> 0 | R19: =IFS(P19="",0,(P19-P20)>0,P19+100,(P19-P20)=0,P19+50,(P19-P20)<0,P19) -> 0 | U19: =IFS(S19="",0,(S19-S20)>0,S19+100,(S19-S20)=0,S19+50,(S19-S20)<0,S19) -> 0 | V19: =IFS(T19="",0,(T19-T20)>0,T19+100,(T19-T20)=0,T19+50,(T19-T20)<0,T19) -> 0 | Y19: =IFS(W19="",0,(W19-W20)>0,W19+100,(W19-W20)=0,W19+50,(W19-W20)<0,W19) -> 0 | Z19: =IFS(X19="",0,(X19-X20)>0,X19+100,(X19-X20)=0,X19+50,(X19-X20)<0,X19) -> 0 | AC19: =IFS(AA19="",0,(AA19-AA20)>0,AA19+100,(AA19-AA20)=0,AA19+50,(AA19-AA20)<0,AA19) -> 0 | AD19: =IFS(AB19="",0,(AB19-AB20)>0,AB19+100,(AB19-AB20)=0,AB19+50,(AB19-AB20)<0,AB19) -> 0 | AG19: =IFS(AE19="",0,(AE19-AE20)>0,AE19+100,(AE19-AE20)=0,AE19+50,(AE19-AE20)<0,AE19) -> 0 | AH19: =IFS(AF19="",0,(AF19-AF20)>0,AF19+100,(AF19-AF20)=0,AF19+50,(AF19-AF20)<0,AF19) -> 0 | AK19: =IFS(AI19="",0,(AI19-AI20)>0,AI19+100,(AI19-AI20)=0,AI19+50,(AI19-AI20)<0,AI19) -> 0 | AL19: =IFS(AJ19="",0,(AJ19-AJ20)>0,AJ19+100,(AJ19-AJ20)=0,AJ19+50,(AJ19-AJ20)<0,AJ19) -> 0 | AN19: =IFS(AL19="",0,(AL19-AL20)>0,AL19+100,(AL19-AL20)=0,AL19+50,(AL19-AL20)<0,AL19) -> 50 | AO19: =IFS(AM19="",0,(AM19-AM20)>0,AM19+100,(AM19-AM20)=0,AM19+50,(AM19-AM20)<0,AM19) -> 0
A20: =B20+2 -> 4 | B20: 2 | C20: =IFERROR(__xludf.DUMMYFUNCTION("if(importrange($A$3,""CT RR Calculations (Private)!$AB$10"")=""Not Ready"",concatenate(B20,"" Seed Team""),concatenate(B20,"" "", importrange($A$3,CONCATENATE(""CT RR Calculations (Private)!"",""W"",A20))))"),"2 Waterford HS - Team 1") -> 2 Waterford HS - Team 1 | D20: 164 | E20: TRUE | F20: =IF(E20=True, IF(D20>D19,2,IF(D20=D19,1,0)),0) -> 2 | G20: ='CT Bracket'!E52 -> 15 EO Smith HS - Team 2 | H20: 88 | I20: TRUE | J20: =IF(I20=True, IF(H20>H19,2,IF(H20=H19,1,0)),0) -> 2 | K20: ='CT Bracket'!G51 -> 15 EO Smith HS - Team 2 | L20: 18 | M20: TRUE | N20: =IF(M20=True, IF(L20>L19,2,IF(L20=L19,1,0)),0) -> 0 | Q20: =IFS(O20="",0,(O20-O19)>0,O20+100,(O20-O19)=0,O20+50,(O20-O19)<0,O20) -> 0 | R20: =IFS(P20="",0,(P20-P19)>0,P20+100,(P20-P19)=0,P20+50,(P20-P19)<0,P20) -> 0 | U20: =IFS(S20="",0,(S20-S19)>0,S20+100,(S20-S19)=0,S20+50,(S20-S19)<0,S20) -> 0 | V20: =IFS(T20="",0,(T20-T19)>0,T20+100,(T20-T19)=0,T20+50,(T20-T19)<0,T20) -> 0 | Y20: =IFS(W20="",0,(W20-W19)>0,W20+100,(W20-W19)=0,W20+50,(W20-W19)<0,W20) -> 0 | Z20: =IFS(X20="",0,(X20-X19)>0,X20+100,(X20-X19)=0,X20+50,(X20-X19)<0,X20) -> 0 | AC20: =IFS(AA20="",0,(AA20-AA19)>0,AA20+100,(AA20-AA19)=0,AA20+50,(AA20-AA19)<0,AA20) -> 0 | AD20: =IFS(AB20="",0,(AB20-AB19)>0,AB20+100,(AB20-AB19)=0,AB20+50,(AB20-AB19)<0,AB20) -> 0 | AG20: =IFS(AE20="",0,(AE20-AE19)>0,AE20+100,(AE20-AE19)=0,AE20+50,(AE20-AE19)<0,AE20) -> 0 | AH20: =IFS(AF20="",0,(AF20-AF19)>0,AF20+100,(AF20-AF19)=0,AF20+50,(AF20-AF19)<0,AF20) -> 0 | AK20: =IFS(AI20="",0,(AI20-AI19)>0,AI20+100,(AI20-AI19)=0,AI20+50,(AI20-AI19)<0,AI20) -> 0 | AL20: =IFS(AJ20="",0,(AJ20-AJ19)>0,AJ20+100,(AJ20-AJ19)=0,AJ20+50,(AJ20-AJ19)<0,AJ20) -> 0 | AN20: =IFS(AL20="",0,(AL20-AL19)>0,AL20+100,(AL20-AL19)=0,AL20+50,(AL20-AL19)<0,AL20) -> 50 | AO20: =IFS(AM20="",0,(AM20-AM19)>0,AM20+100,(AM20-AM19)=0,AM20+50,(AM20-AM19)<0,AM20) -> 0

Sheet CT Bracket
C1: 6 | E1: 7 | G1: 8 | I1: 9 | K1: 10 | M1: 11 | O1: 12 | Q1: 13 | S1: 14
C2: Championship Round 1 | E2: Championship Round 2 | G2: Championship Round 3 | I2: Championship Round 4 | K2: Championship Round 5 | M2: Championship Round 6 | O2: Championship Round 7 (Semi-Final) | Q2: Championship Round 8 (Final) | S2: Championship Round 9 (if needed)
C3: 0.59375 | E3: 0.625 | G3: 0.64583333 | I3: ='CT Championship Scores (Public)'!O3 -> 0.67708333 | K3: ='CT Championship Scores (Public)'!S3 -> 0.69791667 | M3: ='CT Championship Scores (Public)'!W3 -> 0.71875 | O3: ='CT Championship Scores (Public)'!AA3 -> 0.75 | Q3: ='CT Championship Scores (Public)'!AE3 -> 0.77777778 | S3: 0.80902778
C5: ='CT Championship Scores (Public)'!C5 -> 1 Farmington HS - Team 1
A6: 1 → | B6: SHH 101 | E6: =if(and('CT Championship Scores (Public)'!$E$5=true,'CT Championship Scores (Public)'!$E$6=true),if('CT Championship Scores (Public)'!$F$5>'CT Championship Scores (Public)'!$F$6,'CT Championship Scores (Public)'!$C$5,'CT Championship Scores (Public)'!$C$6),"Winner Seed 1 v 16") -> 1 Farmington HS - Team 1 | G6: =if(and('CT Championship Scores (Public)'!$I$5=true,'CT Championship Scores (Public)'!$I$6=true),if('CT Championship Scores (Public)'!$J$5>'CT Championship Scores (Public)'!$J$6,'CT Championship Scores (Public)'!$G$5,'CT Championship Scores (Public)'!$G$6),concatenate("Winner ",E8," Round 2")) -> 1 Farmington HS - Team 1
C7: ='CT Championship Scores (Public)'!C6 -> 16 New Canaan HS - Team 3
E8: =B6 -> SHH 101 | G8: BYE | I8: =G6 -> 1 Farmington HS - Team 1
C9: ='CT Championship Scores (Public)'!C7 -> 8 Rocky Hill HS - Team 1
A10: 2→ | B10: SHH 109 | E10: =if(and('CT Championship Scores (Public)'!$E$7=true,'CT Championship Scores (Public)'!$E$8=true),if('CT Championship Scores (Public)'!$F$7>'CT Championship Scores (Public)'!$F$8,'CT Championship Scores (Public)'!$C$7,'CT Championship Scores (Public)'!$C$8),"Winner Seed 8 v 9") -> 9 Amity Regional HS
C11: ='CT Championship Scores (Public)'!C8 -> 9 Amity Regional HS
I12: =E8 -> SHH 101 | K12: BYE | M12: =if(and('CT Championship Scores (Public)'!$Q$5=true,'CT Championship Scores (Public)'!$Q$6=true),if('CT Championship Scores (Public)'!$R$5>'CT Championship Scores (Public)'!$R$6,'CT Championship Scores (Public)'!$O$5,'CT Championship Scores (Public)'!$O$6),concatenate("Winner ",I12," Round 4")) -> 4 Greenwich HS - Team 1
C13: ='CT Championship Scores (Public)'!C9 -> 5 Southington HS - Team 1
A14: 3 → | B14: SHH 108 | E14: =if(and('CT Championship Scores (Public)'!$E$9=true,'CT Championship Scores (Public)'!$E$10=true),if('CT Championship Scores (Public)'!$F$9>'CT Championship Scores (Public)'!$F$10,'CT Championship Scores (Public)'!$C$9,'CT Championship Scores (Public)'!$C$10),"Winner Seed 5 v 12") -> 5 Southington HS - Team 1 | G14: =if(and('CT Championship Scores (Public)'!$I$7=true,'CT Championship Scores (Public)'!$I$8=true),if('CT Championship Scores (Public)'!$J$7>'CT Championship Scores (Public)'!$J$8,'CT Championship Scores (Public)'!$G$7,'CT Championship Scores (Public)'!$G$8),concatenate("Winner ",E16," Round 2")) -> 4 Greenwich HS - Team 1
C15: ='CT Championship Scores (Public)'!C10 -> 12 Univ HS Sci & Eng
E16: =B14 -> SHH 108 | G16: BYE | I16: =G14 -> 4 Greenwich HS - Team 1
C17: ='CT Championship Scores (Public)'!C11 -> 13 Fairfield Warde HS - Team 1
A18: 4→ | B18: SHH 107 | E18: =if(and('CT Championship Scores (Public)'!$E$11=true,'CT Championship Scores (Public)'!$E$12=true),if('CT Championship Scores (Public)'!$F$11>'CT Championship Scores (Public)'!$F$12,'CT Championship Scores (Public)'!$C$11,'CT Championship Scores (Public)'!$C$12),"Winner Seed 13 v 4") -> 4 Greenwich HS - Team 1
C19: ='CT Championship Scores (Public)'!C12 -> 4 Greenwich HS - Team 1
M20: =I12 -> SHH 101 | O20: BYE | Q20: =if(and('CT Championship Scores (Public)'!$Y$5=true,'CT Championship Scores (Public)'!$Y$6=true),if('CT Championship Scores (Public)'!$Z$5>'CT Championship Scores (Public)'!$Z$6,'CT Championship Scores (Public)'!$W$5,'CT Championship Scores (Public)'!$W$6),concatenate("Winner ",M20," Round 6")) -> 4 Greenwich HS - Team 1
C21: ='CT Championship Scores (Public)'!C13 -> 3 EO Smith HS - Team 1
A22: 6 → | B22: SHH 106 | E22: =if(and('CT Championship Scores (Public)'!$E$13=true,'CT Championship Scores (Public)'!$E$14=true),if('CT Championship Scores (Public)'!$F$13>'CT Championship Scores (Public)'!$F$14,'CT Championship Scores (Public)'!$C$13,'CT Championship Scores (Public)'!$C$14),"Winner Seed 3 v 14") -> 3 EO Smith HS - Team 1 | G22: =if(and('CT Championship Scores (Public)'!$I$9=true,'CT Championship Scores (Public)'!$I$10=true),if('CT Championship Scores (Public)'!$J$9>'CT Championship Scores (Public)'!$J$10,'CT Championship Scores (Public)'!$G$9,'CT Championship Scores (Public)'!$G$10),concatenate("Winner ",E24," Round 2")) -> 3 EO Smith HS - Team 1
C23: ='CT Championship Scores (Public)'!C14 -> 14 South Windsor HS - Team 2
E24: =B22 -> SHH 106 | G24: BYE | I24: =G22 -> 3 EO Smith HS - Team 1
C25: ='CT Championship Scores (Public)'!C15 -> 6 Farmington HS - Team 2
A26: 5→ | B26: SHH 105 | E26: =if(and('CT Championship Scores (Public)'!$E$15=true,'CT Championship Scores (Public)'!$E$16=true),if('CT Championship Scores (Public)'!$F$15>'CT Championship Scores (Public)'!$F$16,'CT Championship Scores (Public)'!$C$15,'CT Championship Scores (Public)'!$C$16),"Winner Seed 6 v 11") -> 6 Farmington HS - Team 2
C27: ='CT Championship Scores (Public)'!C16 -> 11 New Canaan HS - Team 1
I28: =E32 -> SHH 104 | K28: BYE | M28: =if(and('CT Championship Scores (Public)'!$Q$7=true,'CT Championship Scores (Public)'!$Q$8=true),if('CT Championship Scores (Public)'!$R$7>'CT Championship Scores (Public)'!$R$8,'CT Championship Scores (Public)'!$O$7,'CT Championship Scores (Public)'!$O$8),concatenate("Winner ",I28," Round 4")) -> 2 Waterford HS - Team 1
C29: ='CT Championship Scores (Public)'!C17 -> 7 Loomis Chaffee - Team 1
A30: 7 → | B30: SHH 104 | E30: =if(and('CT Championship Scores (Public)'!$E$17=true,'CT Championship Scores (Public)'!$E$18=true),if('CT Championship Scores (Public)'!$F$17>'CT Championship Scores (Public)'!$F$18,'CT Championship Scores (Public)'!$C$17,'CT Championship Scores (Public)'!$C$18),"Winner Seed 7 v 10") -> 7 Loomis Chaffee - Team 1 | G30: =if(and('CT Championship Scores (Public)'!$I$11=true,'CT Championship Scores (Public)'!$I$12=true),if('CT Championship Scores (Public)'!$J$11>'CT Championship Scores (Public)'!$J$12,'CT Championship Scores (Public)'!$G$11,'CT Championship Scores (Public)'!$G$12),concatenate("Winner ",E32," Round 2")) -> 2 Waterford HS - Team 1 | Q30: =M20 -> SHH 101 | S30: =if(and('CT Championship Scores (Public)'!$AG$5=true,'CT Championship Scores (Public)'!$AG$6=true),if('CT Championship Scores (Public)'!$AH$5>'CT Championship Scores (Public)'!$AH$6,'CT Championship Scores (Public)'!$AE$5,'CT Championship Scores (Public)'!$AE$6),concatenate("Winner ",Q30," Round 8")) -> 1 Farmington HS - Team 1
C31: ='CT Championship Scores (Public)'!C18 -> 10 Greenwich HS - Team 2 | T31: Champion
E32: =B30 -> SHH 104 | G32: BYE | I32: =G30 -> 2 Waterford HS - Team 1
C33: ='CT Championship Scores (Public)'!C19 -> 15 EO Smith HS - Team 2 | S33: =R30
A34: 8→ | B34: SHH 110 | E34: =if(and('CT Championship Scores (Public)'!$E$19=true,'CT Championship Scores (Public)'!$E$20=true),if('CT Championship Scores (Public)'!$F$19>'CT Championship Scores (Public)'!$F$20,'CT Championship Scores (Public)'!$C$19,'CT Championship Scores (Public)'!$C$20),"Winner Seed 15 v 2") -> 2 Waterford HS - Team 1
C35: ='CT Championship Scores (Public)'!C20 -> 2 Waterford HS - Team 1
K36: =if(and('CT Championship Scores (Public)'!$Q$5=true,'CT Championship Scores (Public)'!$Q$6=true),if('CT Championship Scores (Public)'!$R$5>'CT Championship Scores (Public)'!$R$6,'CT Championship Scores (Public)'!$O$6,'CT Championship Scores (Public)'!$O$5),concatenate("Loser ",I12," Round 4")) -> 1 Farmington HS - Team 1 | O36: =if(and('CT Championship Scores (Public)'!$Y$5=true,'CT Championship Scores (Public)'!$Y$6=true),if('CT Championship Scores (Public)'!$Z$5>'CT Championship Scores (Public)'!$Z$6,'CT Championship Scores (Public)'!$W$6,'CT Championship Scores (Public)'!$W$5),concatenate("Loser ",M20," Round 6")) -> 2 Waterford HS - Team 1 | S36: Rematch if both teams have 1 loss
G37: =if(and('CT Championship Scores (Public)'!$I$5=true,'CT Championship Scores (Public)'!$I$6=true),if('CT Championship Scores (Public)'!$J$5>'CT Championship Scores (Public)'!$J$6,'CT Championship Scores (Public)'!$G$6,'CT Championship Scores (Public)'!$G$5),concatenate("Loser ",E8," Round 2")) -> 9 Amity Regional HS
D38: L1 | E38: =if(and('CT Championship Scores (Public)'!$E$5=true,'CT Championship Scores (Public)'!$E$6=true),if('CT Championship Scores (Public)'!$F$5>'CT Championship Scores (Public)'!$F$6,'CT Championship Scores (Public)'!$C$6,'CT Championship Scores (Public)'!$C$5),"Loser Seed 1 v 16") -> 16 New Canaan HS - Team 3 | G38: =E39 -> SHH 111 | I38: =if(and('CT Championship Scores (Public)'!$M$13=true,'CT Championship Scores (Public)'!$M$14=true),if('CT Championship Scores (Public)'!$N$13>'CT Championship Scores (Public)'!$N$14,'CT Championship Scores (Public)'!$K$13,'CT Championship Scores (Public)'!$K$14),concatenate("Winner ",G38," Round 3")) -> 9 Amity Regional HS | K38: SHH 109 | M38: =if(and('CT Championship Scores (Public)'!$U$13=true,'CT Championship Scores (Public)'!$U$14=true),if('CT Championship Scores (Public)'!$V$13>'CT Championship Scores (Public)'!$V$14,'CT Championship Scores (Public)'!$S$13,'CT Championship Scores (Public)'!$S$14),concatenate("Winner ",K38," Round 5")) -> 1 Farmington HS - Team 1
E39: SHH 111 | G39: =if(and('CT Championship Scores (Public)'!$I$13=true,'CT Championship Scores (Public)'!$I$14=true),if('CT Championship Scores (Public)'!$J$13>'CT Championship Scores (Public)'!$J$14,'CT Championship Scores (Public)'!$G$13,'CT Championship Scores (Public)'!$G$14),concatenate("Winner ",E39," Round 2")) -> 8 Rocky Hill HS - Team 1 | O39: =M42 -> SHH 109 | Q39: =if(and('CT Championship Scores (Public)'!$AC$13=true,'CT Championship Scores (Public)'!$AC$14=true),if('CT Championship Scores (Public)'!$AD$13>'CT Championship Scores (Public)'!$AD$14,'CT Championship Scores (Public)'!$AA$13,'CT Championship Scores (Public)'!$AA$14),concatenate("Winner ",O39," Round 7")) -> 1 Farmington HS - Team 1
D40: L2 | E40: =if(and('CT Championship Scores (Public)'!$E$7=true,'CT Championship Scores (Public)'!$E$8=true),if('CT Championship Scores (Public)'!$F$7>'CT Championship Scores (Public)'!$F$8,'CT Championship Scores (Public)'!$C$8,'CT Championship Scores (Public)'!$C$7),"Loser Seed 8 v 9") -> 8 Rocky Hill HS - Team 1 | I40: =G42 -> SHH 109 | K40: =if(and('CT Championship Scores (Public)'!$Q$13=true,'CT Championship Scores (Public)'!$Q$14=true),if('CT Championship Scores (Public)'!$R$13>'CT Championship Scores (Public)'!$R$14,'CT Championship Scores (Public)'!$O$13,'CT Championship Scores (Public)'!$O$14),concatenate("Winner ",I40," Round 4")) -> 5 Southington HS - Team 1
G41: =if(and('CT Championship Scores (Public)'!$I$7=true,'CT Championship Scores (Public)'!$I$8=true),if('CT Championship Scores (Public)'!$J$7>'CT Championship Scores (Public)'!$J$8,'CT Championship Scores (Public)'!$G$8,'CT Championship Scores (Public)'!$G$7),concatenate("Loser ",E16," Round 2")) -> 5 Southington HS - Team 1
...
