Workbook

Sheet SW1
C1: game 1
B2: school
A3: 1 | B3: Amity Regional - Team 1 | C3: 12
A4: 2 | B4: Bacon Academy - Team 1 | C4: 20
A5: 3 | B5: Bacon Academy - Team 2
A6: 4 | B6: Cheshire HS - Team 1
A7: 5 | B7: Cheshire HS - Team 2
A8: 6 | B8: CT IB Acad
A9: 7 | B9: EO Smith HS - Team 1
A10: 8 | B10: EO Smith HS - Team 2
A11: 9 | B11: East Lyme HS - Team 1
A12: 10 | B12: East Lyme HS - Team 2
A13: 11 | B13: Fairfield Ludlowe HS
A14: 12 | B14: Fairfield Warde HS
A15: 13 | B15: Farmington HS - Team 1
A16: 14 | B16: Farmington HS - Team 2
... A44: 42 | B44: Waterford HS - Team 2

Sheet SW2
C1: game 1 | E1: T/F | F1: Winning Score | G1: Team
B2: school
B3: Academy of Aerospace and Engineering | C3: 12 | E3: =IF('SW1'!C3=C3,"TRUE") -> TRUE
B4: Advanced Math and Science Academy Charter School | C4: 20 | E4: =IF('SW1'!C4=C4,"TRUE") -> TRUE | F4: =MAX(C3:C4) -> 20
B5: Amity Regional HS
B6: Bacon Academy
B7: Bedford High
B8: Boston Latin
B9: Boston University Academy
B10: Cheshire HS
B11: Cheshire HS
B12: Choate Rosemary Hall
B13: Conard HS
B14: Cranston HS East
B15: Deerfield Academy
B16: E. O. Smith HS
... B51: Wayland HS

Sheet NE Regional CHAMPIONSHIP Bracke
B1: NE Regional (NORTH) CHAMPIONSHIP Bracket
B3: Round 6 | C3: Round 7 | D3: Round 8 | E3: Round 9 | F3: Round 10 | G3: Round 11 | H3: Round 12 | I3: Round 13 | J3: Round 14
B4: 0.58333333 | C4: =B4+"00:30" -> 0.60416667 | D4: =C4+"00:30" -> 0.625 | E4: =D4+"00:30" -> 0.64583333 | F4: =E4+"00:30" -> 0.66666667 | G4: =F4+"00:30" -> 0.6875 | H4: =G4+"00:30" -> 0.70833333 | I4: =H4+"00:30" -> 0.72916667 | J4: =I4+"00:30" -> 0.75
B8: MCHU 305
C10: MCHU 101 | D10: BYE
B12: MCHU 306
E14: MCHU 110 | F14: BYE
B16: MCHU 205
C18: MCHU 111 | D18: BYE
B20: MCHU 206
G22: MCHU 101 | H22: BYE
B24: MCHU 111
C26: MCHU 110 | D26: BYE
B28: MCHU 109
E30: MCHU 111 | F30: BYE
I31: MCHU 101
B32: MCHU 110
C34: MCHU 109 | D34: BYE
B36: MCHU 101
D41: MCHU 110 | F41: MCHU 101 | H41: MCHU 101
C42: MCHU 305
E43: MCHU 109
D45: MCHU 101 | G45: MCHU 111
C46: MCHU 306
D49: MCHU 111 | F49: MCHU 111
C50: MCHU 205
E51: MCHU 101
D53: MCHU 109
C54: MCHU 206

Sheet CT Region ROUND ROBIN Scores (P
B1: CT Regional ROUND ROBIN Scores
A3: Room | B3: Round 1 | F3: Round 2 | J3: Round 3 | N3: Round 4 | R3: Round 5
B4: 0.40972222 | F4: 0.4375 | J4: 0.46041667 | N4: 0.48958333 | R4: 0.51388889 | Y4: Points are awarded for wins (2 pts) or ties (1 pt). Scores are the sum of correct responses & pentalties earned within matches
B5: Division 1 (Temple Grandin)
Y6: Points and Scores by Team | AH6: Scores by Division
B7: Teams | C7: Score | D7: CC Verification | E7: Points | F7: Teams | G7: Score | H7: CC Verification | I7: Points | J7: Teams | K7: Score | L7: CC Verification | M7: Points | N7: Teams | O7: Score | P7: CC Verification | Q7: Points | R7: Teams | S7: Score | T7: CC Verification | U7: Points | W7: Seed # | X7: Team | Y7: Team (Alphabetical) | Z7: Division | AA7: Total Points | AB7: Total Score | AC7: =X7 -> Team | AE7: Rank | AF7: Points w/ DB | AG7: Team | AH7: Division | AI7: Total Points | AJ7: Total Scores
A8: SHH 101 | B8: =X8 -> Farmington HS - Team 1 | C8: 260 | D8: TRUE | E8: =IF(D8=True, IF(C8>C9,2,IF(C8=C9,1,0)),0) -> 2 | F8: =B10 -> Southington HS - Team 1 | G8: 84 | H8: TRUE | I8: =IF(H8=True, IF(G8>G9,2,IF(G8=G9,1,0)),0) -> 2 | J8: =F12 -> Farmington HS - Team 1 | K8: 218 | L8: TRUE | M8: =IF(L8=True, IF(K8>K9,2,IF(K8=K9,1,0)),0) -> 2 | N8: =J13 -> Ethel Walker School | O8: 8 | P8: TRUE | Q8: =IF(P8=True, IF(O8>O9,2,IF(O8=O9,1,0)),0) -> 0 | R8: =N12 -> Loomis Chaffee - Team 2 | S8: 114 | T8: TRUE | U8: =IF(T8=True, IF(S8>S9,2,IF(S8=S9,1,0)),0) -> 2 | W8: 1 | X8: Farmington HS - Team 1 | Y8: {=sort(X8:X55)} -> Amity Regional HS | Z8: =IF(MATCH(Y8,R:R,0)<14,$B$5,IF(MATCH(Y8,R:R,0)<23,$B$14,IF(MATCH(Y8,R:R,0)<32,$B$23,IF(MATCH(Y8,R:R,0)<41,$B$32,IF(MATCH(Y8,R:R,0)<50,$B$41,IF(MATCH(Y8,R:R,0)<59,$B$50,IF(MATCH(Y8,R:R,0)<68,$B$59,$B$68))))))) -> Division 3 (Silas Adekunle) | AA8: =SUM(VLOOKUP(Y8,B:E,4,FALSE),VLOOKUP(Y8,F:I,4,FALSE),VLOOKUP(Y8,J:M,4,FALSE),VLOOKUP(Y8,N:Q,4,FALSE),VLOOKUP(Y8,R:U,4,FALSE)) -> 8 | AB8: =SUM(VLOOKUP(Y8,$B:$E,2,FALSE),VLOOKUP(Y8,$F:$I,2,FALSE),VLOOKUP(Y8,$J:$M,2,FALSE),VLOOKUP(Y8,$N:$Q,2,FALSE),VLOOKUP(Y8,$R:$U,2,FALSE)) -> 438 | AC8: =X9 -> Waterford HS - Team 1 | AE8: 1 | AF8: 1489.5698 | AH8: =B5 -> Division 1 (Temple Grandin) | AI8: =SUM(E8:E13,I8:I13,M8:M13,Q8:Q13,U8:U13) -> 30 | AJ8: =SUM(C$8:C$13,G$8:G$13,K$8:K$13,O$8:O$13,S$8:S$13) -> 2466
B9: =X23 -> Ethel Walker School | C9: 8 | D9: TRUE | E9: =IF(D9=True, IF(C9>C8,2,IF(C9=C8,1,0)),0) -> 0 | F9: =B13 -> CT IB Acad - Team 2 | G9: 34 | H9: TRUE | I9: =IF(H9=True, IF(G9>G8,2,IF(G9=G8,1,0)),0) -> 0 | J9: =F10 -> Loomis Chaffee - Team 2 | K9: 40 | L9: TRUE | M9: =IF(L9=True, IF(K9>K8,2,IF(K9=K8,1,0)),0) -> 0 | N9: =J11 -> Fairfield Ludlowe HS | O9: 66 | P9: TRUE | Q9: =IF(P9=True, IF(O9>O8,2,IF(O9=O8,1,0)),0) -> 2 | R9: =N9 -> Fairfield Ludlowe HS | S9: 40 | T9: TRUE | U9: =IF(T9=True, IF(S9>S8,2,IF(S9=S8,1,0)),0) -> 0 | W9: =W8+1 -> 2 | X9: Waterford HS - Team 1 | Y9: Bacon Academy | Z9: =IF(MATCH(Y9,R:R,0)<14,$B$5,IF(MATCH(Y9,R:R,0)<23,$B$14,IF(MATCH(Y9,R:R,0)<32,$B$23,IF(MATCH(Y9,R:R,0)<41,$B$32,IF(MATCH(Y9,R:R,0)<50,$B$41,IF(MATCH(Y9,R:R,0)<59,$B$50,IF(MATCH(Y9,R:R,0)<68,$B$59,$B$68))))))) -> Division 2 (Marian Croak) | AA9: =SUM(VLOOKUP(Y9,B:E,4,FALSE),VLOOKUP(Y9,F:I,4,FALSE),VLOOKUP(Y9,J:M,4,FALSE),VLOOKUP(Y9,N:Q,4,FALSE),VLOOKUP(Y9,R:U,4,FALSE)) -> 2 | AB9: =SUM(VLOOKUP(Y9,$B:$E,2,FALSE),VLOOKUP(Y9,$F:$I,2,FALSE),VLOOKUP(Y9,$J:$M,2,FALSE),VLOOKUP(Y9,$N:$Q,2,FALSE),VLOOKUP(Y9,$R:$U,2,FALSE)) -> 152 | AC9: =X10 -> EO Smith HS - Team 1 | AE9: =AE8+1 -> 2 | AF9: 1487.3284 | AH9: =B14 -> Division 2 (Marian Croak) | AI9: =SUM(E$17:E$22,I$17:I$22,M$17:M$22,Q$17:Q$22,U$17:U$22) -> 30 | AJ9: =SUM(C$17:C$22,G$17:G$22,K$17:K$22,O$17:O$22,S$17:S$22) -> 1812
A10: SHH 104 | B10: =X24 -> Southington HS - Team 1 | C10: 166 | D10: TRUE | E10: =IF(D10=True, IF(C10>C11,2,IF(C10=C11,1,0)),0) -> 2 | F10: =B12 -> Loomis Chaffee - Team 2 | G10: 80 | H10: TRUE | I10: =IF(H10=True, IF(G10>G11,2,IF(G10=G11,1,0)),0) -> 2 | J10: =F9 -> CT IB Acad - Team 2 | K10: 74 | L10: TRUE | M10: =IF(L10=True, IF(K10>K11,2,IF(K10=K11,1,0)),0) -> 2 | N10: =J8 -> Farmington HS - Team 1 | O10: 176 | P10: TRUE | Q10: =IF(P10=True, IF(O10>O11,2,IF(O10=O11,1,0)),0) -> 2 | R10: =N10 -> Farmington HS - Team 1 | S10: 198 | T10: TRUE | U10: =IF(T10=True, IF(S10>S11,2,IF(S10=S11,1,0)),0) -> 2 | W10: =W9+1 -> 3 | X10: EO Smith HS - Team 1 | Y10: Choate Rosemary Hall | Z10: =IF(MATCH(Y10,R:R,0)<14,$B$5,IF(MATCH(Y10,R:R,0)<23,$B$14,IF(MATCH(Y10,R:R,0)<32,$B$23,IF(MATCH(Y10,R:R,0)<41,$B$32,IF(MATCH(Y10,R:R,0)<50,$B$41,IF(MATCH(Y10,R:R,0)<59,$B$50,IF(MATCH(Y10,R:R,0)<68,$B$59,$B$68))))))) -> Division 7 (Irene Uchida) | AA10: =SUM(VLOOKUP(Y10,B:E,4,FALSE),VLOOKUP(Y10,F:I,4,FALSE),VLOOKUP(Y10,J:M,4,FALSE),VLOOKUP(Y10,N:Q,4,FALSE),VLOOKUP(Y10,R:U,4,FALSE)) -> 6 | AB10: =SUM(VLOOKUP(Y10,$B:$E,2,FALSE),VLOOKUP(Y10,$F:$I,2,FALSE),VLOOKUP(Y10,$J:$M,2,FALSE),VLOOKUP(Y10,$N:$Q,2,FALSE),VLOOKUP(Y10,$R:$U,2,FALSE)) -> 294 | AC10: =X11 -> Greenwich HS - Team 1 | AE10: =AE9+1 -> 3 | AF10: 1117.2772 | AH10: =B23 -> Division 3 (Silas Adekunle) | AI10: =SUM(E$26:E$31,I$26:I$31,M$26:M$31,Q$26:Q$31,U$26:U$31) -> 30 | AJ10: =SUM(C$26:C$31,G$26:G$31,K$26:K$31,O$26:O$31,S$26:S$31) -> 2024
B11: =X39 -> Fairfield Ludlowe HS | C11: 40 | D11: TRUE | E11: =IF(D11=True, IF(C11>C10,2,IF(C11=C10,1,0)),0) -> 0 | F11: =B9 -> Ethel Walker School | G11: 16 | H11: TRUE | I11: =IF(H11=True, IF(G11>G10,2,IF(G11=G10,1,0)),0) -> 0 | J11: =F13 -> Fairfield Ludlowe HS | K11: 20 | L11: TRUE | M11: =IF(L11=True, IF(K11>K10,2,IF(K11=K10,1,0)),0) -> 0 | N11: =J10 -> CT IB Acad - Team 2 | O11: 16 | P11: TRUE | Q11: =IF(P11=True, IF(O11>O10,2,IF(O11=O10,1,0)),0) -> 0 | R11: =N13 -> Southington HS - Team 1 | S11: 62 | T11: TRUE | U11: =IF(T11=True, IF(S11>S10,2,IF(S11=S10,1,0)),0) -> 0 | W11: =W10+1 -> 4 | X11: Greenwich HS - Team 1 | Y11: Conard HS - Team 1 | Z11: =IF(MATCH(Y11,R:R,0)<14,$B$5,IF(MATCH(Y11,R:R,0)<23,$B$14,IF(MATCH(Y11,R:R,0)<32,$B$23,IF(MATCH(Y11,R:R,0)<41,$B$32,IF(MATCH(Y11,R:R,0)<50,$B$41,IF(MATCH(Y11,R:R,0)<59,$B$50,IF(MATCH(Y11,R:R,0)<68,$B$59,$B$68))))))) -> Division 4 (Ellen Ochoa) | AA11: =SUM(VLOOKUP(Y11,B:E,4,FALSE),VLOOKUP(Y11,F:I,4,FALSE),VLOOKUP(Y11,J:M,4,FALSE),VLOOKUP(Y11,N:Q,4,FALSE),VLOOKUP(Y11,R:U,4,FALSE)) -> 6 | AB11: =SUM(VLOOKUP(Y11,$B:$E,2,FALSE),VLOOKUP(Y11,$F:$I,2,FALSE),VLOOKUP(Y11,$J:$M,2,FALSE),VLOOKUP(Y11,$N:$Q,2,FALSE),VLOOKUP(Y11,$R:$U,2,FALSE)) -> 290 | AC11: =X12 -> East Lyme HS - Team 1 | AE11: =AE10+1 -> 4 | AF11: 1097.2772 | AH11: =B32 -> Division 4 (Ellen Ochoa) | AI11: =SUM(E35:E40,I35:I40,M35:M40,Q35:Q40,U35:U40) -> 30 | AJ11: =SUM(C$35:C$40,G$35:G$40,K$35:K$40,O$35:O$40,S$35:S$40) -> 1916
A12: SHH 105 | B12: =X40 -> Loomis Chaffee - Team 2 | C12: 70 | D12: TRUE | E12: =IF(D12=True, IF(C12>C13,2,IF(C12=C13,1,0)),0) -> 2 | F12: =B8 -> Farmington HS - Team 1 | G12: 178 | H12: TRUE | I12: =IF(H12=True, IF(G12>G13,2,IF(G12=G13,1,0)),0) -> 2 | J12: =F8 -> Southington HS - Team 1 | K12: 158 | L12: TRUE | M12: =IF(L12=True, IF(K12>K13,2,IF(K12=K13,1,0)),0) -> 2 | N12: =J9 -> Loomis Chaffee - Team 2 | O12: 30 | P12: TRUE | Q12: =IF(P12=True, IF(O12>O13,2,IF(O12=O13,1,0)),0) -> 0 | R12: =N11 -> CT IB Acad - Team 2 | S12: 48 | T12: TRUE | U12: =IF(T12=True, IF(S12>S13,2,IF(S12=S13,1,0)),0) -> 2 | W12: =W11+1 -> 5 | X12: East Lyme HS - Team 1 | Y12: Conard HS - Team 2 | Z12: =IF(MATCH(Y12,R:R,0)<14,$B$5,IF(MATCH(Y12,R:R,0)<23,$B$14,IF(MATCH(Y12,R:R,0)<32,$B$23,IF(MATCH(Y12,R:R,0)<41,$B$32,IF(MATCH(Y12,R:R,0)<50,$B$41,IF(MATCH(Y12,R:R,0)<59,$B$50,IF(MATCH(Y12,R:R,0)<68,$B$59,$B$68))))))) -> Division 2 (Marian Croak) | AA12: =SUM(VLOOKUP(Y12,B:E,4,FALSE),VLOOKUP(Y12,F:I,4,FALSE),VLOOKUP(Y12,J:M,4,FALSE),VLOOKUP(Y12,N:Q,4,FALSE),VLOOKUP(Y12,R:U,4,FALSE)) -> 6 | AB12: =SUM(VLOOKUP(Y12,$B:$E,2,FALSE),VLOOKUP(Y12,$F:$I,2,FALSE),VLOOKUP(Y12,$J:$M,2,FALSE),VLOOKUP(Y12,$N:$Q,2,FALSE),VLOOKUP(Y12,$R:$U,2,FALSE)) -> 220 | AC12: =X13 -> Rocky Hill HS - Team 1 | AE12: =AE11+1 -> 5 | AF12: 1095.3284 | AH12: =B41 -> Division 5 (Ursula Burns) | AI12: =SUM(E44:E49,I44:I49,M44:M49,Q44:Q49,U44:U49) -> 30 | AJ12: =SUM(C$44:C$49,G$44:G$49,K$44:K$49,O$44:O$49,S$44:S$49) -> 1842
B13: =X55 -> CT IB Acad - Team 2 | C13: 54 | D13: TRUE | E13: =IF(D13=True, IF(C13>C12,2,IF(C13=C12,1,0)),0) -> 0 | F13: =B11 -> Fairfield Ludlowe HS | G13: 34 | H13: TRUE | I13: =IF(H13=True, IF(G13>G12,2,IF(G13=G12,1,0)),0) -> 0 | J13: =F11 -> Ethel Walker School | K13: 12 | L13: TRUE | M13: =IF(L13=True, IF(K13>K12,2,IF(K13=K12,1,0)),0) -> 0 | N13: =J12 -> Southington HS - Team 1 | O13: 136 | P13: TRUE | Q13: =IF(P13=True, IF(O13>O12,2,IF(O13=O12,1,0)),0) -> 2 | R13: =N8 -> Ethel Walker School | S13: 26 | T13: TRUE | U13: =IF(T13=True, IF(S13>S12,2,IF(S13=S12,1,0)),0) -> 0 | W13: =W12+1 -> 6 | X13: Rocky Hill HS - Team 1 | Y13: CT IB Acad - Team 1 | Z13: =IF(MATCH(Y13,R:R,0)<14,$B$5,IF(MATCH(Y13,R:R,0)<23,$B$14,IF(MATCH(Y13,R:R,0)<32,$B$23,IF(MATCH(Y13,R:R,0)<41,$B$32,IF(MATCH(Y13,R:R,0)<50,$B$41,IF(MATCH(Y13,R:R,0)<59,$B$50,IF(MATCH(Y13,R:R,0)<68,$B$59,$B$68))))))) -> Division 3 (Silas Adekunle) | AA13: =SUM(VLOOKUP(Y13,B:E,4,FALSE),VLOOKUP(Y13,F:I,4,FALSE),VLOOKUP(Y13,J:M,4,FALSE),VLOOKUP(Y13,N:Q,4,FALSE),VLOOKUP(Y13,R:U,4,FALSE)) -> 0 | AB13: =SUM(VLOOKUP(Y13,$B:$E,2,FALSE),VLOOKUP(Y13,$F:$I,2,FALSE),VLOOKUP(Y13,$J:$M,2,FALSE),VLOOKUP(Y13,$N:$Q,2,FALSE),VLOOKUP(Y13,$R:$U,2,FALSE)) -> 72 | AC13: =X14 -> Choate Rosemary Hall | AE13: =AE12+1 -> 6 | AF13: 1069.1174 | AH13: =B50 -> Division 6 (Guillermo Camarena) | AI13: =SUM(E53:E58,I53:I58,M53:M58,Q53:Q58,U53:U58) -> 30 | AJ13: =SUM(C$53:C$58,G$53:G$58,K$53:K$58,O$53:O$58,S$53:S$58) -> 1982
B14: Division 2 (Marian Croak) | W14: =W13+1 -> 7 | X14: Choate Rosemary Hall | Y14: CT IB Acad - Team 2 | Z14: =IF(MATCH(Y14,R:R,0)<14,$B$5,IF(MATCH(Y14,R:R,0)<23,$B$14,IF(MATCH(Y14,R:R,0)<32,$B$23,IF(MATCH(Y14,R:R,0)<41,$B$32,IF(MATCH(Y14,R:R,0)<50,$B$41,IF(MATCH(Y14,R:R,0)<59,$B$50,IF(MATCH(Y14,R:R,0)<68,$B$59,$B$68))))))) -> Division 1 (Temple Grandin) | AA14: =SUM(VLOOKUP(Y14,B:E,4,FALSE),VLOOKUP(Y14,F:I,4,FALSE),VLOOKUP(Y14,J:M,4,FALSE),VLOOKUP(Y14,N:Q,4,FALSE),VLOOKUP(Y14,R:U,4,FALSE)) -> 4 | AB14: =SUM(VLOOKUP(Y14,$B:$E,2,FALSE),VLOOKUP(Y14,$F:$I,2,FALSE),VLOOKUP(Y14,$J:$M,2,FALSE),VLOOKUP(Y14,$N:$Q,2,FALSE),VLOOKUP(Y14,$R:$U,2,FALSE)) -> 226 | AC14: =X15 -> Open Spot - 1 | AE14: =AE13+1 -> 7 | AF14: 1065.1174 | AH14: =B59 -> Division 7 (Irene Uchida) | AI14: =SUM(E62:E67,I62:I67,M62:M67,Q62:Q67,U62:U67) -> 30 | AJ14: =SUM(C$62:C$67,G$62:G$67,K$62:K$67,O$62:O$67,S$62:S$67) -> 1586
W15: =W14+1 -> 8 | X15: Open Spot - 1 | Y15: CT IB Acad - Team 3 | Z15: =IF(MATCH(Y15,R:R,0)<14,$B$5,IF(MATCH(Y15,R:R,0)<23,$B$14,IF(MATCH(Y15,R:R,0)<32,$B$23,IF(MATCH(Y15,R:R,0)<41,$B$32,IF(MATCH(Y15,R:R,0)<50,$B$41,IF(MATCH(Y15,R:R,0)<59,$B$50,IF(MATCH(Y15,R:R,0)<68,$B$59,$B$68))))))) -> Division 4 (Ellen Ochoa) | AA15: =SUM(VLOOKUP(Y15,B:E,4,FALSE),VLOOKUP(Y15,F:I,4,FALSE),VLOOKUP(Y15,J:M,4,FALSE),VLOOKUP(Y15,N:Q,4,FALSE),VLOOKUP(Y15,R:U,4,FALSE)) -> 0 | AB15: =SUM(VLOOKUP(Y15,$B:$E,2,FALSE),VLOOKUP(Y15,$F:$I,2,FALSE),VLOOKUP(Y15,$J:$M,2,FALSE),VLOOKUP(Y15,$N:$Q,2,FALSE),VLOOKUP(Y15,$R:$U,2,FALSE)) -> 146 | AC15: =X16 -> Open Spot - 2 | AE15: =AE14+1 -> 8 | AF15: 1016.9804 | AH15: =B68 -> Division 8 (Bernardo Houssay) - Canceled Division - Sorry! | AI15: =SUM(E71:E76,I71:I76,M71:M76,Q71:Q76,U71:U76) -> 1 | AJ15: =SUM(C$71:C$76,G$71:G$76,K$71:K$76,O$71:O$76,S$71:S$76) -> 0
B16: Teams | C16: Score | D16: CC Verification | E16: Points | F16: Teams | G16: Score | H16: CC Verification | I16: Points | J16: Teams | K16: Score | L16: CC Verification | M16: Points | N16: Teams | O16: Score | P16: CC Verification | Q16: Points | R16: Teams | S16: Score | T16: CC Verification | U16: Points | W16: =W15+1 -> 9 | X16: Open Spot - 2 | Y16: East Lyme HS - Team 1 | Z16: =IF(MATCH(Y16,R:R,0)<14,$B$5,IF(MATCH(Y16,R:R,0)<23,$B$14,IF(MATCH(Y16,R:R,0)<32,$B$23,IF(MATCH(Y16,R:R,0)<41,$B$32,IF(MATCH(Y16,R:R,0)<50,$B$41,IF(MATCH(Y16,R:R,0)<59,$B$50,IF(MATCH(Y16,R:R,0)<68,$B$59,$B$68))))))) -> Division 5 (Ursula Burns) | AA16: =SUM(VLOOKUP(Y16,B:E,4,FALSE),VLOOKUP(Y16,F:I,4,FALSE),VLOOKUP(Y16,J:M,4,FALSE),VLOOKUP(Y16,N:Q,4,FALSE),VLOOKUP(Y16,R:U,4,FALSE)) -> 4 | AB16: =SUM(VLOOKUP(Y16,$B:$E,2,FALSE),VLOOKUP(Y16,$F:$I,2,FALSE),VLOOKUP(Y16,$J:$M,2,FALSE),VLOOKUP(Y16,$N:$Q,2,FALSE),VLOOKUP(Y16,$R:$U,2,FALSE)) -> 422 | AC16: =X17 -> New Canaan HS - Team 3 | AE16: =AE15+1 -> 9 | AF16: 1009.1174
A17: SHH 106 | B17: =X9 -> Waterford HS - Team 1 | C17: 216 | D17: TRUE | E17: =IF(D17=True, IF(C17>C18,2,IF(C17=C18,1,0)),0) -> 2 | F17: =B19 -> Bacon Academy | G17: 4 | H17: TRUE | I17: =IF(H17=True, IF(G17>G18,2,IF(G17=G18,1,0)),0) -> 0 | J17: =F21 -> Waterford HS - Team 1 | K17: 130 | L17: TRUE | M17: =IF(L17=True, IF(K17>K18,2,IF(K17=K18,1,0)),0) -> 2 | N17: =J22 -> Conard HS - Team 2 | O17: 60 | P17: TRUE | Q17: =IF(P17=True, IF(O17>O18,2,IF(O17=O18,1,0)),0) -> 2 | R17: =N21 -> South Windsor HS - Team 2 | S17: 86 | T17: TRUE | U17: =IF(T17=True, IF(S17>S18,2,IF(S17=S18,1,0)),0) -> 2 | W17: =W16+1 -> 10 | X17: New Canaan HS - Team 3 | Y17: East Lyme HS - Team 2 | Z17: =IF(MATCH(Y17,R:R,0)<14,$B$5,IF(MATCH(Y17,R:R,0)<23,$B$14,IF(MATCH(Y17,R:R,0)<32,$B$23,IF(MATCH(Y17,R:R,0)<41,$B$32,IF(MATCH(Y17,R:R,0)<50,$B$41,IF(MATCH(Y17,R:R,0)<59,$B$50,IF(MATCH(Y17,R:R,0)<68,$B$59,$B$68))))))) -> Division 3 (Silas Adekunle) | AA17: =SUM(VLOOKUP(Y17,B:E,4,FALSE),VLOOKUP(Y17,F:I,4,FALSE),VLOOKUP(Y17,J:M,4,FALSE),VLOOKUP(Y17,N:Q,4,FALSE),VLOOKUP(Y17,R:U,4,FALSE)) -> 4 | AB17: =SUM(VLOOKUP(Y17,$B:$E,2,FALSE),VLOOKUP(Y17,$F:$I,2,FALSE),VLOOKUP(Y17,$J:$M,2,FALSE),VLOOKUP(Y17,$N:$Q,2,FALSE),VLOOKUP(Y17,$R:$U,2,FALSE)) -> 294 | AC17: =X18 -> New Canaan HS - Team 1 | AE17: =AE16+1 -> 10 | AF17: 878.9804
B18: =X22 -> Conard HS - Team 2 | C18: 12 | D18: TRUE | E18: =IF(D18=True, IF(C18>C17,2,IF(C18=C17,1,0)),0) -> 0 | F18: =B22 -> Southington HS - Team 2 | G18: 56 | H18: TRUE | I18: =IF(H18=True, IF(G18>G17,2,IF(G18=G17,1,0)),0) -> 2 | J18: =F19 -> South Windsor HS - Team 2 | K18: 58 | L18: TRUE | M18: =IF(L18=True, IF(K18>K17,2,IF(K18=K17,1,0)),0) -> 0 | N18: =J20 -> Greenwich HS - Team 3 | O18: 20 | P18: TRUE | Q18: =IF(P18=True, IF(O18>O17,2,IF(O18=O17,1,0)),0) -> 0 | R18: =N18 -> Greenwich HS - Team 3 | S18: 64 | T18: TRUE | U18: =IF(T18=True, IF(S18>S17,2,IF(S18=S17,1,0)),0) -> 0 | W18: =W17+1 -> 11 | X18: New Canaan HS - Team 1 | Y18: Enfield HS - Team 1 | Z18: =IF(MATCH(Y18,R:R,0)<14,$B$5,IF(MATCH(Y18,R:R,0)<23,$B$14,IF(MATCH(Y18,R:R,0)<32,$B$23,IF(MATCH(Y18,R:R,0)<41,$B$32,IF(MATCH(Y18,R:R,0)<50,$B$41,IF(MATCH(Y18,R:R,0)<59,$B$50,IF(MATCH(Y18,R:R,0)<68,$B$59,$B$68))))))) -> Division 3 (Silas Adekunle) | AA18: =SUM(VLOOKUP(Y18,B:E,4,FALSE),VLOOKUP(Y18,F:I,4,FALSE),VLOOKUP(Y18,J:M,4,FALSE),VLOOKUP(Y18,N:Q,4,FALSE),VLOOKUP(Y18,R:U,4,FALSE)) -> 2 | AB18: =SUM(VLOOKUP(Y18,$B:$E,2,FALSE),VLOOKUP(Y18,$F:$I,2,FALSE),VLOOKUP(Y18,$J:$M,2,FALSE),VLOOKUP(Y18,$N:$Q,2,FALSE),VLOOKUP(Y18,$R:$U,2,FALSE)) -> 142 | AC18: =X19 -> Loomis Chaffee - Team 1 | AE18: =AE17+1 -> 11 | AF18: 695.3284
A19: SHH 235 | B19: =X25 -> Bacon Academy | C19: 48 | D19: TRUE | E19: =IF(D19=True, IF(C19>C20,2,IF(C19=C20,1,0)),0) -> 2 | F19: =B21 -> South Windsor HS - Team 2 | G19: 60 | H19: TRUE | I19: =IF(H19=True, IF(G19>G20,2,IF(G19=G20,1,0)),0) -> 2 | J19: =F18 -> Southington HS - Team 2 | K19: 42 | L19: TRUE | M19: =IF(L19=True, IF(K19>K20,2,IF(K19=K20,1,0)),0) -> 2 | N19: =J17 -> Waterford HS - Team 1 | O19: 142 | P19: TRUE | Q19: =IF(P19=True, IF(O19>O20,2,IF(O19=O20,1,0)),0) -> 2 | R19: =N19 -> Waterford HS - Team 1 | S19: 152 | T19: TRUE | U19: =IF(T19=True, IF(S19>S20,2,IF(S19=S20,1,0)),0) -> 2 | W19: =W18+1 -> 12 | X19: Loomis Chaffee - Team 1 | Y19: Enfield HS - Team 2 | Z19: =IF(MATCH(Y19,R:R,0)<14,$B$5,IF(MATCH(Y19,R:R,0)<23,$B$14,IF(MATCH(Y19,R:R,0)<32,$B$23,IF(MATCH(Y19,R:R,0)<41,$B$32,IF(MATCH(Y19,R:R,0)<50,$B$41,IF(MATCH(Y19,R:R,0)<59,$B$50,IF(MATCH(Y19,R:R,0)<68,$B$59,$B$68))))))) -> Division 6 (Guillermo Camarena) | AA19: =SUM(VLOOKUP(Y19,B:E,4,FALSE),VLOOKUP(Y19,F:I,4,FALSE),VLOOKUP(Y19,J:M,4,FALSE),VLOOKUP(Y19,N:Q,4,FALSE),VLOOKUP(Y19,R:U,4,FALSE)) -> 2 | AB19: =SUM(VLOOKUP(Y19,$B:$E,2,FALSE),VLOOKUP(Y19,$F:$I,2,FALSE),VLOOKUP(Y19,$J:$M,2,FALSE),VLOOKUP(Y19,$N:$Q,2,FALSE),VLOOKUP(Y19,$R:$U,2,FALSE)) -> 158 | AC19: =X20 -> Conard HS - Team 1 | AE19: =AE18+1 -> 12 | AF19: 693.1174
B20: =X38 -> Greenwich HS - Team 3 | C20: 36 | D20: TRUE | E20: =IF(D20=True, IF(C20>C19,2,IF(C20=C19,1,0)),0) -> 0 | F20: =B18 -> Conard HS - Team 2 | G20: 22 | H20: TRUE | I20: =IF(H20=True, IF(G20>G19,2,IF(G20=G19,1,0)),0) -> 0 | J20: =F22 -> Greenwich HS - Team 3 | K20: 34 | L20: TRUE | M20: =IF(L20=True, IF(K20>K19,2,IF(K20=K19,1,0)),0) -> 0 | N20: =J19 -> Southington HS - Team 2 | O20: 16 | P20: TRUE | Q20: =IF(P20=True, IF(O20>O19,2,IF(O20=O19,1,0)),0) -> 0 | R20: =N22 -> Bacon Academy | S20: 38 | T20: TRUE | U20: =IF(T20=True, IF(S20>S19,2,IF(S20=S19,1,0)),0) -> 0 | W20: =W19+1 -> 13 | X20: Conard HS - Team 1 | Y20: Enfield HS - Team 3 | Z20: =IF(MATCH(Y20,R:R,0)<14,$B$5,IF(MATCH(Y20,R:R,0)<23,$B$14,IF(MATCH(Y20,R:R,0)<32,$B$23,IF(MATCH(Y20,R:R,0)<41,$B$32,IF(MATCH(Y20,R:R,0)<50,$B$41,IF(MATCH(Y20,R:R,0)<59,$B$50,IF(MATCH(Y20,R:R,0)<68,$B$59,$B$68))))))) -> Division 7 (Irene Uchida) | AA20: =SUM(VLOOKUP(Y20,B:E,4,FALSE),VLOOKUP(Y20,F:I,4,FALSE),VLOOKUP(Y20,J:M,4,FALSE),VLOOKUP(Y20,N:Q,4,FALSE),VLOOKUP(Y20,R:U,4,FALSE)) -> 2 | AB20: =SUM(VLOOKUP(Y20,$B:$E,2,FALSE),VLOOKUP(Y20,$F:$I,2,FALSE),VLOOKUP(Y20,$J:$M,2,FALSE),VLOOKUP(Y20,$N:$Q,2,FALSE),VLOOKUP(Y20,$R:$U,2,FALSE)) -> 156 | AC20: =X21 -> CT IB Acad - Team 1 | AE20: =AE19+1 -> 13 | AF20: 665.5698
A21: SHH 107 | B21: =X41 -> South Windsor HS - Team 2 | C21: 92 | D21: TRUE | E21: =IF(D21=True, IF(C21>C22,2,IF(C21=C22,1,0)),0) -> 2 | F21: =B17 -> Waterford HS - Team 1 | G21: 122 | H21: TRUE | I21: =IF(H21=True, IF(G21>G22,2,IF(G21=G22,1,0)),0) -> 2 | J21: =F17 -> Bacon Academy | K21: 38 | L21: TRUE | M21: =IF(L21=True, IF(K21>K22,2,IF(K21=K22,1,0)),0) -> 0 | N21: =J18 -> South Windsor HS - Team 2 | O21: 50 | P21: TRUE | Q21: =IF(P21=True, IF(O21>O22,2,IF(O21=O22,1,0)),0) -> 2 | R21: =N20 -> Southington HS - Team 2 | S21: 26 | T21: TRUE | U21: =IF(T21=True, IF(S21>S22,2,IF(S21=S22,1,0)),0) -> 0 | W21: =W20+1 -> 14 | X21: CT IB Acad - Team 1 | Y21: EO Smith HS - Team 1 | Z21: =IF(MATCH(Y21,R:R,0)<14,$B$5,IF(MATCH(Y21,R:R,0)<23,$B$14,IF(MATCH(Y21,R:R,0)<32,$B$23,IF(MATCH(Y21,R:R,0)<41,$B$32,IF(MATCH(Y21,R:R,0)<50,$B$41,IF(MATCH(Y21,R:R,0)<59,$B$50,IF(MATCH(Y21,R:R,0)<68,$B$59,$B$68))))))) -> Division 3 (Silas Adekunle) | AA21: =SUM(VLOOKUP(Y21,B:E,4,FALSE),VLOOKUP(Y21,F:I,4,FALSE),VLOOKUP(Y21,J:M,4,FALSE),VLOOKUP(Y21,N:Q,4,FALSE),VLOOKUP(Y21,R:U,4,FALSE)) -> 10 | AB21: =SUM(VLOOKUP(Y21,$B:$E,2,FALSE),VLOOKUP(Y21,$F:$I,2,FALSE),VLOOKUP(Y21,$J:$M,2,FALSE),VLOOKUP(Y21,$N:$Q,2,FALSE),VLOOKUP(Y21,$R:$U,2,FALSE)) -> 750 | AC21: =X22 -> Conard HS - Team 2 | AE21: =AE20+1 -> 14 | AF21: 662.9804
B22: =X54 -> Southington HS - Team 2 | C22: 22 | D22: TRUE | E22: =IF(D22=True, IF(C22>C21,2,IF(C22=C21,1,0)),0) -> 0 | F22: =B20 -> Greenwich HS - Team 3 | G22: 16 | H22: TRUE | I22: =IF(H22=True, IF(G22>G21,2,IF(G22=G21,1,0)),0) -> 0 | J22: =F20 -> Conard HS - Team 2 | K22: 56 | L22: TRUE | M22: =IF(L22=True, IF(K22>K21,2,IF(K22=K21,1,0)),0) -> 2 | N22: =J21 -> Bacon Academy | O22: 24 | P22: TRUE | Q22: =IF(P22=True, IF(O22>O21,2,IF(O22=O21,1,0)),0) -> 0 | R22: =N17 -> Conard HS - Team 2 | S22: 70 | T22: TRUE | U22: =IF(T22=True, IF(S22>S21,2,IF(S22=S21,1,0)),0) -> 2 | W22: =W21+1 -> 15 | X22: Conard HS - Team 2 | Y22: EO Smith HS - Team 2 | Z22: =IF(MATCH(Y22,R:R,0)<14,$B$5,IF(MATCH(Y22,R:R,0)<23,$B$14,IF(MATCH(Y22,R:R,0)<32,$B$23,IF(MATCH(Y22,R:R,0)<41,$B$32,IF(MATCH(Y22,R:R,0)<50,$B$41,IF(MATCH(Y22,R:R,0)<59,$B$50,IF(MATCH(Y22,R:R,0)<68,$B$59,$B$68))))))) -> Division 5 (Ursula Burns) | AA22: =SUM(VLOOKUP(Y22,B:E,4,FALSE),VLOOKUP(Y22,F:I,4,FALSE),VLOOKUP(Y22,J:M,4,FALSE),VLOOKUP(Y22,N:Q,4,FALSE),VLOOKUP(Y22,R:U,4,FALSE)) -> 6 | AB22: =SUM(VLOOKUP(Y22,$B:$E,2,FALSE),VLOOKUP(Y22,$F:$I,2,FALSE),VLOOKUP(Y22,$J:$M,2,FALSE),VLOOKUP(Y22,$N:$Q,2,FALSE),VLOOKUP(Y22,$R:$U,2,FALSE)) -> 298 | AC22: =X23 -> Ethel Walker School | AE22: =AE21+1 -> 15 | AF22: 617.2772
B23: Division 3 (Silas Adekunle) | W23: =W22+1 -> 16 | X23: Ethel Walker School | Y23: Ethel Walker School | Z23: =IF(MATCH(Y23,R:R,0)<14,$B$5,IF(MATCH(Y23,R:R,0)<23,$B$14,IF(MATCH(Y23,R:R,0)<32,$B$23,IF(MATCH(Y23,R:R,0)<41,$B$32,IF(MATCH(Y23,R:R,0)<50,$B$41,IF(MATCH(Y23,R:R,0)<59,$B$50,IF(MATCH(Y23,R:R,0)<68,$B$59,$B$68))))))) -> Division 1 (Temple Grandin) | AA23: =SUM(VLOOKUP(Y23,B:E,4,FALSE),VLOOKUP(Y23,F:I,4,FALSE),VLOOKUP(Y23,J:M,4,FALSE),VLOOKUP(Y23,N:Q,4,FALSE),VLOOKUP(Y23,R:U,4,FALSE)) -> 0 | AB23: =SUM(VLOOKUP(Y23,$B:$E,2,FALSE),VLOOKUP(Y23,$F:$I,2,FALSE),VLOOKUP(Y23,$J:$M,2,FALSE),VLOOKUP(Y23,$N:$Q,2,FALSE),VLOOKUP(Y23,$R:$U,2,FALSE)) -> 70 | AC23: =X24 -> Southington HS - Team 1 | AE23: =AE22+1 -> 16 | AF23: 609.5698
W24: =W23+1 -> 17 | X24: Southington HS - Team 1 | Y24: Fairfield Ludlowe HS | Z24: =IF(MATCH(Y24,R:R,0)<14,$B$5,IF(MATCH(Y24,R:R,0)<23,$B$14,IF(MATCH(Y24,R:R,0)<32,$B$23,IF(MATCH(Y24,R:R,0)<41,$B$32,IF(MATCH(Y24,R:R,0)<50,$B$41,IF(MATCH(Y24,R:R,0)<59,$B$50,IF(MATCH(Y24,R:R,0)<68,$B$59,$B$68))))))) -> Division 1 (Temple Grandin) | AA24: =SUM(VLOOKUP(Y24,B:E,4,FALSE),VLOOKUP(Y24,F:I,4,FALSE),VLOOKUP(Y24,J:M,4,FALSE),VLOOKUP(Y24,N:Q,4,FALSE),VLOOKUP(Y24,R:U,4,FALSE)) -> 2 | AB24: =SUM(VLOOKUP(Y24,$B:$E,2,FALSE),VLOOKUP(Y24,$F:$I,2,FALSE),VLOOKUP(Y24,$J:$M,2,FALSE),VLOOKUP(Y24,$N:$Q,2,FALSE),VLOOKUP(Y24,$R:$U,2,FALSE)) -> 200 | AC24: =X25 -> Bacon Academy | AE24: =AE23+1 -> 17 | AF24: 575.5698
B25: Teams | C25: Score | D25: CC Verification | E25: Points | F25: Teams | G25: Score | H25: CC Verification | I25: Points | J25: Teams | K25: Score | L25: CC Verification | M25: Points | N25: Teams | O25: Score | P25: CC Verification | Q25: Points | R25: Teams | S25: Score | T25: CC Verification | U25: Points | W25: =W24+1 -> 18 | X25: Bacon Academy | Y25: Fairfield Warde HS - Team 1 | Z25: =IF(MATCH(Y25,R:R,0)<14,$B$5,IF(MATCH(Y25,R:R,0)<23,$B$14,IF(MATCH(Y25,R:R,0)<32,$B$23,IF(MATCH(Y25,R:R,0)<41,$B$32,IF(MATCH(Y25,R:R,0)<50,$B$41,IF(MATCH(Y25,R:R,0)<59,$B$50,IF(MATCH(Y25,R:R,0)<68,$B$59,$B$68))))))) -> Division 4 (Ellen Ochoa) | AA25: =SUM(VLOOKUP(Y25,B:E,4,FALSE),VLOOKUP(Y25,F:I,4,FALSE),VLOOKUP(Y25,J:M,4,FALSE),VLOOKUP(Y25,N:Q,4,FALSE),VLOOKUP(Y25,R:U,4,FALSE)) -> 8 | AB25: =SUM(VLOOKUP(Y25,$B:$E,2,FALSE),VLOOKUP(Y25,$F:$I,2,FALSE),VLOOKUP(Y25,$J:$M,2,FALSE),VLOOKUP(Y25,$N:$Q,2,FALSE),VLOOKUP(Y25,$R:$U,2,FALSE)) -> 370 | AC25: =X26 -> Amity Regional HS | AE25: =AE24+1 -> 18 | AF25: 551.3284
A26: SHH 108 | B26: =X10 -> EO Smith HS - Team 1 | C26: 164 | D26: TRUE | E26: =IF(D26=True, IF(C26>C27,2,IF(C26=C27,1,0)),0) -> 2 | F26: =B28 -> Amity Regional HS | G26: 88 | H26: TRUE | I26: =IF(H26=True, IF(G26>G27,2,IF(G26=G27,1,0)),0) -> 2 | J26: =F30 -> EO Smith HS - Team 1 | K26: 186 | L26: TRUE | M26: =IF(L26=True, IF(K26>K27,2,IF(K26=K27,1,0)),0) -> 2 | N26: =J31 -> CT IB Acad - Team 1 | O26: 20 | P26: TRUE | Q26: =IF(P26=True, IF(O26>O27,2,IF(O26=O27,1,0)),0) -> 0 | R26: =N30 -> Rocky Hill HS - Team 2 | S26: 102 | T26: TRUE | U26: =IF(T26=True, IF(S26>S27,2,IF(S26=S27,1,0)),0) -> 2 | W26: =W25+1 -> 19 | X26: Amity Regional HS | Y26: Fairfield Warde HS - Team 2 | Z26: =IF(MATCH(Y26,R:R,0)<14,$B$5,IF(MATCH(Y26,R:R,0)<23,$B$14,IF(MATCH(Y26,R:R,0)<32,$B$23,IF(MATCH(Y26,R:R,0)<41,$B$32,IF(MATCH(Y26,R:R,0)<50,$B$41,IF(MATCH(Y26,R:R,0)<59,$B$50,IF(MATCH(Y26,R:R,0)<68,$B$59,$B$68))))))) -> Division 6 (Guillermo Camarena) | AA26: =SUM(VLOOKUP(Y26,B:E,4,FALSE),VLOOKUP(Y26,F:I,4,FALSE),VLOOKUP(Y26,J:M,4,FALSE),VLOOKUP(Y26,N:Q,4,FALSE),VLOOKUP(Y26,R:U,4,FALSE)) -> 0 | AB26: =SUM(VLOOKUP(Y26,$B:$E,2,FALSE),VLOOKUP(Y26,$F:$I,2,FALSE),VLOOKUP(Y26,$J:$M,2,FALSE),VLOOKUP(Y26,$N:$Q,2,FALSE),VLOOKUP(Y26,$R:$U,2,FALSE)) -> 146 | AC26: =X27 -> New Canaan HS - Team 2 | AE26: =AE25+1 -> 19 | AF26: 551.2772
B27: =X21 -> CT IB Acad - Team 1 | C27: 8 | D27: TRUE | E27: =IF(D27=True, IF(C27>C26,2,IF(C27=C26,1,0)),0) -> 0 | F27: =B31 -> East Lyme HS - Team 2 | G27: 36 | H27: TRUE | I27: =IF(H27=True, IF(G27>G26,2,IF(G27=G26,1,0)),0) -> 0 | J27: =F28 -> Rocky Hill HS - Team 2 | K27: 40 | L27: TRUE | M27: =IF(L27=True, IF(K27>K26,2,IF(K27=K26,1,0)),0) -> 0 | N27: =J29 -> Enfield HS - Team 1 | O27: 42 | P27: TRUE | Q27: =IF(P27=True, IF(O27>O26,2,IF(O27=O26,1,0)),0) -> 2 | R27: =N27 -> Enfield HS - Team 1 | S27: 32 | T27: TRUE | U27: =IF(T27=True, IF(S27>S26,2,IF(S27=S26,1,0)),0) -> 0 | W27: =W26+1 -> 20 | X27: New Canaan HS - Team 2 | Y27: Farmington HS - Team 1 | Z27: =IF(MATCH(Y27,R:R,0)<14,$B$5,IF(MATCH(Y27,R:R,0)<23,$B$14,IF(MATCH(Y27,R:R,0)<32,$B$23,IF(MATCH(Y27,R:R,0)<41,$B$32,IF(MATCH(Y27,R:R,0)<50,$B$41,IF(MATCH(Y27,R:R,0)<59,$B$50,IF(MATCH(Y27,R:R,0)<68,$B$59,$B$68))))))) -> Division 1 (Temple Grandin) | AA27: =SUM(VLOOKUP(Y27,B:E,4,FALSE),VLOOKUP(Y27,F:I,4,FALSE),VLOOKUP(Y27,J:M,4,FALSE),VLOOKUP(Y27,N:Q,4,FALSE),VLOOKUP(Y27,R:U,4,FALSE)) -> 10 | AB27: =SUM(VLOOKUP(Y27,$B:$E,2,FALSE),VLOOKUP(Y27,$F:$I,2,FALSE),VLOOKUP(Y27,$J:$M,2,FALSE),VLOOKUP(Y27,$N:$Q,2,FALSE),VLOOKUP(Y27,$R:$U,2,FALSE)) -> 1030 | AC27: =X28 -> Waterford HS - Team 2 | AE27: =AE26+1 -> 20 | AF27: 547.2772
A28: SHH 109 | B28: =X26 -> Amity Regional HS | C28: 128 | D28: TRUE | E28: =IF(D28=True, IF(C28>C29,2,IF(C28=C29,1,0)),0) -> 2 | F28: =B30 -> Rocky Hill HS - Team 2 | G28: 72 | H28: TRUE | I28: =IF(H28=True, IF(G28>G29,2,IF(G28=G29,1,0)),0) -> 2 | J28: =F27 -> East Lyme HS - Team 2 | K28: 98 | L28: TRUE | M28: =IF(L28=True, IF(K28>K29,2,IF(K28=K29,1,0)),0) -> 2 | N28: =J26 -> EO Smith HS - Team 1 | O28: 92 | P28: TRUE | Q28: =IF(P28=True, IF(O28>O29,2,IF(O28=O29,1,0)),0) -> 2 | R28: =N28 -> EO Smith HS - Team 1 | S28: 156 | T28: TRUE | U28: =IF(T28=True, IF(S28>S29,2,IF(S28=S29,1,0)),0) -> 2 | W28: =W27+1 -> 21 | X28: Waterford HS - Team 2 | Y28: Farmington HS - Team 2 | Z28: =IF(MATCH(Y28,R:R,0)<14,$B$5,IF(MATCH(Y28,R:R,0)<23,$B$14,IF(MATCH(Y28,R:R,0)<32,$B$23,IF(MATCH(Y28,R:R,0)<41,$B$32,IF(MATCH(Y28,R:R,0)<50,$B$41,IF(MATCH(Y28,R:R,0)<59,$B$50,IF(MATCH(Y28,R:R,0)<68,$B$59,$B$68))))))) -> Division 6 (Guillermo Camarena) | AA28: =SUM(VLOOKUP(Y28,B:E,4,FALSE),VLOOKUP(Y28,F:I,4,FALSE),VLOOKUP(Y28,J:M,4,FALSE),VLOOKUP(Y28,N:Q,4,FALSE),VLOOKUP(Y28,R:U,4,FALSE)) -> 8 | AB28: =SUM(VLOOKUP(Y28,$B:$E,2,FALSE),VLOOKUP(Y28,$F:$I,2,FALSE),VLOOKUP(Y28,$J:$M,2,FALSE),VLOOKUP(Y28,$N:$Q,2,FALSE),VLOOKUP(Y28,$R:$U,2,FALSE)) -> 508 | AC28: =X29 -> Farmington HS - Team 2 | AE28: =AE27+1 -> 21 | AF28: 506.9804
B29: =X37 -> Enfield HS - Team 1 | C29: 22 | D29: TRUE | E29: =IF(D29=True, IF(C29>C28,2,IF(C29=C28,1,0)),0) -> 0 | F29: =B27 -> CT IB Acad - Team 1 | G29: 4 | H29: TRUE | I29: =IF(H29=True, IF(G29>G28,2,IF(G29=G28,1,0)),0) -> 0 | J29: =F31 -> Enfield HS - Team 1 | K29: 20 | L29: TRUE | M29: =IF(L29=True, IF(K29>K28,2,IF(K29=K28,1,0)),0) -> 0 | N29: =J28 -> East Lyme HS - Team 2 | O29: 42 | P29: TRUE | Q29: =IF(P29=True, IF(O29>O28,2,IF(O29=O28,1,0)),0) -> 0 | R29: =N31 -> Amity Regional HS | S29: 92 | T29: TRUE | U29: =IF(T29=True, IF(S29>S28,2,IF(S29=S28,1,0)),0) -> 0 | W29: =W28+1 -> 22 | X29: Farmington HS - Team 2 | Y29: Greenwich HS - Team 1 | Z29: =IF(MATCH(Y29,R:R,0)<14,$B$5,IF(MATCH(Y29,R:R,0)<23,$B$14,IF(MATCH(Y29,R:R,0)<32,$B$23,IF(MATCH(Y29,R:R,0)<41,$B$32,IF(MATCH(Y29,R:R,0)<50,$B$41,IF(MATCH(Y29,R:R,0)<59,$B$50,IF(MATCH(Y29,R:R,0)<68,$B$59,$B$68))))))) -> Division 4 (Ellen Ochoa) | AA29: =SUM(VLOOKUP(Y29,B:E,4,FALSE),VLOOKUP(Y29,F:I,4,FALSE),VLOOKUP(Y29,J:M,4,FALSE),VLOOKUP(Y29,N:Q,4,FALSE),VLOOKUP(Y29,R:U,4,FALSE)) -> 10 | AB29: =SUM(VLOOKUP(Y29,$B:$E,2,FALSE),VLOOKUP(Y29,$F:$I,2,FALSE),VLOOKUP(Y29,$J:$M,2,FALSE),VLOOKUP(Y29,$N:$Q,2,FALSE),VLOOKUP(Y29,$R:$U,2,FALSE)) -> 650 | AC29: =X30 -> Greenwich HS - Team 2 | AE29: =AE28+1 -> 22 | AF29: 487.5698
A30: SHH 110 | B30: =X42 -> Rocky Hill HS - Team 2 | C30: 68 | D30: TRUE | E30: =IF(D30=True, IF(C30>C31,2,IF(C30=C31,1,0)),0) -> 2 | F30: =B26 -> EO Smith HS - Team 1 | G30: 152 | H30: TRUE | I30: =IF(H30=True, IF(G30>G31,2,IF(G30=G31,1,0)),0) -> 2 | J30: =F26 -> Amity Regional HS | K30: 76 | L30: TRUE | M30: =IF(L30=True, IF(K30>K31,2,IF(K30=K31,1,0)),0) -> 2 | N30: =J27 -> Rocky Hill HS - Team 2 | O30: 46 | P30: TRUE | Q30: =IF(P30=True, IF(O30>O31,2,IF(O30=O31,1,0)),0) -> 0 | R30: =N29 -> East Lyme HS - Team 2 | S30: 74 | T30: TRUE | U30: =IF(T30=True, IF(S30>S31,2,IF(S30=S31,1,0)),0) -> 2 | W30: =W29+1 -> 23 | X30: Greenwich HS - Team 2 | Y30: Greenwich HS - Team 2 | Z30: =IF(MATCH(Y30,R:R,0)<14,$B$5,IF(MATCH(Y30,R:R,0)<23,$B$14,IF(MATCH(Y30,R:R,0)<32,$B$23,IF(MATCH(Y30,R:R,0)<41,$B$32,IF(MATCH(Y30,R:R,0)<50,$B$41,IF(MATCH(Y30,R:R,0)<59,$B$50,IF(MATCH(Y30,R:R,0)<68,$B$59,$B$68))))))) -> Division 7 (Irene Uchida) | AA30: =SUM(VLOOKUP(Y30,B:E,4,FALSE),VLOOKUP(Y30,F:I,4,FALSE),VLOOKUP(Y30,J:M,4,FALSE),VLOOKUP(Y30,N:Q,4,FALSE),VLOOKUP(Y30,R:U,4,FALSE)) -> 10 | AB30: =SUM(VLOOKUP(Y30,$B:$E,2,FALSE),VLOOKUP(Y30,$F:$I,2,FALSE),VLOOKUP(Y30,$J:$M,2,FALSE),VLOOKUP(Y30,$N:$Q,2,FALSE),VLOOKUP(Y30,$R:$U,2,FALSE)) -> 420 | AC30: =X31 -> Open Spot - 3 | AE30: =AE29+1 -> 23 | AF30: 469.1174
B31: =X53 -> East Lyme HS - Team 2 | C31: 44 | D31: TRUE | E31: =IF(D31=True, IF(C31>C30,2,IF(C31=C30,1,0)),0) -> 0 | F31: =B29 -> Enfield HS - Team 1 | G31: 26 | H31: TRUE | I31: =IF(H31=True, IF(G31>G30,2,IF(G31=G30,1,0)),0) -> 0 | J31: =F29 -> CT IB Acad - Team 1 | K31: 28 | L31: TRUE | M31: =IF(L31=True, IF(K31>K30,2,IF(K31=K30,1,0)),0) -> 0 | N31: =J30 -> Amity Regional HS | O31: 54 | P31: TRUE | Q31: =IF(P31=True, IF(O31>O30,2,IF(O31=O30,1,0)),0) -> 2 | R31: =N26 -> CT IB Acad - Team 1 | S31: 12 | T31: TRUE | U31: =IF(T31=True, IF(S31>S30,2,IF(S31=S30,1,0)),0) -> 0 | W31: =W30+1 -> 24 | X31: Open Spot - 3 | Y31: Greenwich HS - Team 3 | Z31: =IF(MATCH(Y31,R:R,0)<14,$B$5,IF(MATCH(Y31,R:R,0)<23,$B$14,IF(MATCH(Y31,R:R,0)<32,$B$23,IF(MATCH(Y31,R:R,0)<41,$B$32,IF(MATCH(Y31,R:R,0)<50,$B$41,IF(MATCH(Y31,R:R,0)<59,$B$50,IF(MATCH(Y31,R:R,0)<68,$B$59,$B$68))))))) -> Division 2 (Marian Croak) | AA31: =SUM(VLOOKUP(Y31,B:E,4,FALSE),VLOOKUP(Y31,F:I,4,FALSE),VLOOKUP(Y31,J:M,4,FALSE),VLOOKUP(Y31,N:Q,4,FALSE),VLOOKUP(Y31,R:U,4,FALSE)) -> 0 | AB31: =SUM(VLOOKUP(Y31,$B:$E,2,FALSE),VLOOKUP(Y31,$F:$I,2,FALSE),VLOOKUP(Y31,$J:$M,2,FALSE),VLOOKUP(Y31,$N:$Q,2,FALSE),VLOOKUP(Y31,$R:$U,2,FALSE)) -> 170 | AC31: =#REF! -> #REF! | AE31: =AE30+1 -> 24 | AF31: 409.2772
B32: Division 4 (Ellen Ochoa) | W32: =W31+1 -> 25 | X32: Open Spot - 4 | Y32: Greenwich HS - Team 4 | Z32: =IF(MATCH(Y32,R:R,0)<14,$B$5,IF(MATCH(Y32,R:R,0)<23,$B$14,IF(MATCH(Y32,R:R,0)<32,$B$23,IF(MATCH(Y32,R:R,0)<41,$B$32,IF(MATCH(Y32,R:R,0)<50,$B$41,IF(MATCH(Y32,R:R,0)<59,$B$50,IF(MATCH(Y32,R:R,0)<68,$B$59,$B$68))))))) -> Division 8 (Bernardo Houssay) - Canceled Division - Sorry! | AA32: =SUM(VLOOKUP(Y32,B:E,4,FALSE),VLOOKUP(Y32,F:I,4,FALSE),VLOOKUP(Y32,J:M,4,FALSE),VLOOKUP(Y32,N:Q,4,FALSE),VLOOKUP(Y32,R:U,4,FALSE)) -> 0 | AB32: =SUM(VLOOKUP(Y32,$B:$E,2,FALSE),VLOOKUP(Y32,$F:$I,2,FALSE),VLOOKUP(Y32,$J:$M,2,FALSE),VLOOKUP(Y32,$N:$Q,2,FALSE),VLOOKUP(Y32,$R:$U,2,FALSE)) -> 0 | AC32: =X33 -> Enfield HS - Team 3 | AE32: =AE31+1 -> 25 | AF32: 384.9804 | AG32: =VLOOKUP(AF32,$AC$8:$AC$37,2,FALSE) -> #REF!
W33: =W32+1 -> 26 | X33: Enfield HS - Team 3 | Y33: Joel Barlow HS | Z33: =IF(MATCH(Y33,R:R,0)<14,$B$5,IF(MATCH(Y33,R:R,0)<23,$B$14,IF(MATCH(Y33,R:R,0)<32,$B$23,IF(MATCH(Y33,R:R,0)<41,$B$32,IF(MATCH(Y33,R:R,0)<50,$B$41,IF(MATCH(Y33,R:R,0)<59,$B$50,IF(MATCH(Y33,R:R,0)<68,$B$59,$B$68))))))) -> Division 4 (Ellen Ochoa) | AA33: =SUM(VLOOKUP(Y33,B:E,4,FALSE),VLOOKUP(Y33,F:I,4,FALSE),VLOOKUP(Y33,J:M,4,FALSE),VLOOKUP(Y33,N:Q,4,FALSE),VLOOKUP(Y33,R:U,4,FALSE)) -> 4 | AB33: =SUM(VLOOKUP(Y33,$B:$E,2,FALSE),VLOOKUP(Y33,$F:$I,2,FALSE),VLOOKUP(Y33,$J:$M,2,FALSE),VLOOKUP(Y33,$N:$Q,2,FALSE),VLOOKUP(Y33,$R:$U,2,FALSE)) -> 248 | AC33: =X34 -> Enfield HS - Team 2 | AE33: =AE32+1 -> 26 | AF33: 383.3284 | AG33: =VLOOKUP(AF33,$AC$8:$AC$37,2,FALSE) -> #REF!
B34: Teams | C34: Score | D34: CC Verification | E34: Points | F34: Teams | G34: Score | H34: CC Verification | I34: Points | J34: Teams | K34: Score | L34: CC Verification | M34: Points | N34: Teams | O34: Score | P34: CC Verification | Q34: Points | R34: Teams | S34: Score | T34: CC Verification | U34: Points | W34: =W33+1 -> 27 | X34: Enfield HS - Team 2 | Y34: Loomis Chaffee - Team 1 | Z34: =IF(MATCH(Y34,R:R,0)<14,$B$5,IF(MATCH(Y34,R:R,0)<23,$B$14,IF(MATCH(Y34,R:R,0)<32,$B$23,IF(MATCH(Y34,R:R,0)<41,$B$32,IF(MATCH(Y34,R:R,0)<50,$B$41,IF(MATCH(Y34,R:R,0)<59,$B$50,IF(MATCH(Y34,R:R,0)<68,$B$59,$B$68))))))) -> Division 5 (Ursula Burns) | AA34: =SUM(VLOOKUP(Y34,B:E,4,FALSE),VLOOKUP(Y34,F:I,4,FALSE),VLOOKUP(Y34,J:M,4,FALSE),VLOOKUP(Y34,N:Q,4,FALSE),VLOOKUP(Y34,R:U,4,FALSE)) -> 8 | AB34: =SUM(VLOOKUP(Y34,$B:$E,2,FALSE),VLOOKUP(Y34,$F:$I,2,FALSE),VLOOKUP(Y34,$J:$M,2,FALSE),VLOOKUP(Y34,$N:$Q,2,FALSE),VLOOKUP(Y34,$R:$U,2,FALSE)) -> 468 | AC34: =X35 -> Univ HS Sci & Eng | AE34: =AE33+1 -> 27 | AF34: 343.3284 | AG34: =VLOOKUP(AF34,$AC$8:$AC$37,2,FALSE) -> #REF!
A35: SHH 111 | B35: =X11 -> Greenwich HS - Team 1 | C35: 86 | D35: TRUE | E35: =IF(D35=True, IF(C35>C36,2,IF(C35=C36,1,0)),0) -> 2 | F35: =B37 -> New Canaan HS - Team 2 | G35: 34 | H35: TRUE | I35: =IF(H35=True, IF(G35>G36,2,IF(G35=G36,1,0)),0) -> 0 | J35: =F39 -> Greenwich HS - Team 1 | K35: 136 | L35: TRUE | M35: =IF(L35=True, IF(K35>K36,2,IF(K35=K36,1,0)),0) -> 2 | N35: =J40 -> Conard HS - Team 1 | O35: 24 | P35: TRUE | Q35: =IF(P35=True, IF(O35>O36,2,IF(O35=O36,1,0)),0) -> 0 | R35: =N39 -> CT IB Acad - Team 3 | S35: 40 | T35: TRUE | U35: =IF(T35=True, IF(S35>S36,2,IF(S35=S36,1,0)),0) -> 0 | W35: =W34+1 -> 28 | X35: Univ HS Sci & Eng | Y35: Loomis Chaffee - Team 2 | Z35: =IF(MATCH(Y35,R:R,0)<14,$B$5,IF(MATCH(Y35,R:R,0)<23,$B$14,IF(MATCH(Y35,R:R,0)<32,$B$23,IF(MATCH(Y35,R:R,0)<41,$B$32,IF(MATCH(Y35,R:R,0)<50,$B$41,IF(MATCH(Y35,R:R,0)<59,$B$50,IF(MATCH(Y35,R:R,0)<68,$B$59,$B$68))))))) -> Division 1 (Temple Grandin) | AA35: =SUM(VLOOKUP(Y35,B:E,4,FALSE),VLOOKUP(Y35,F:I,4,FALSE),VLOOKUP(Y35,J:M,4,FALSE),VLOOKUP(Y35,N:Q,4,FALSE),VLOOKUP(Y35,R:U,4,FALSE)) -> 6 | AB35: =SUM(VLOOKUP(Y35,$B:$E,2,FALSE),VLOOKUP(Y35,$F:$I,2,FALSE),VLOOKUP(Y35,$J:$M,2,FALSE),VLOOKUP(Y35,$N:$Q,2,FALSE),VLOOKUP(Y35,$R:$U,2,FALSE)) -> 334 | AC35: =X36 -> Fairfield Warde HS - Team 1 | AE35: =AE34+1 -> 28 | AF35: 338.9804 | AG35: =VLOOKUP(AF35,$AC$8:$AC$37,2,FALSE) -> #REF!
B36: =X20 -> Conard HS - Team 1 | C36: 68 | D36: TRUE | E36: =IF(D36=True, IF(C36>C35,2,IF(C36=C35,1,0)),0) -> 0 | F36: =B40 -> Joel Barlow HS | G36: 62 | H36: TRUE | I36: =IF(H36=True, IF(G36>G35,2,IF(G36=G35,1,0)),0) -> 2 | J36: =F37 -> CT IB Acad - Team 3 | K36: 26 | L36: TRUE | M36: =IF(L36=True, IF(K36>K35,2,IF(K36=K35,1,0)),0) -> 0 | N36: =J38 -> Fairfield Warde HS - Team 1 | O36: 66 | P36: TRUE | Q36: =IF(P36=True, IF(O36>O35,2,IF(O36=O35,1,0)),0) -> 2 | R36: =N36 -> Fairfield Warde HS - Team 1 | S36: 100 | T36: TRUE | U36: =IF(T36=True, IF(S36>S35,2,IF(S36=S35,1,0)),0) -> 2 | W36: =W35+1 -> 29 | X36: Fairfield Warde HS - Team 1 | Y36: New Canaan HS - Team 1 | Z36: =IF(MATCH(Y36,R:R,0)<14,$B$5,IF(MATCH(Y36,R:R,0)<23,$B$14,IF(MATCH(Y36,R:R,0)<32,$B$23,IF(MATCH(Y36,R:R,0)<41,$B$32,IF(MATCH(Y36,R:R,0)<50,$B$41,IF(MATCH(Y36,R:R,0)<59,$B$50,IF(MATCH(Y36,R:R,0)<68,$B$59,$B$68))))))) -> Division 6 (Guillermo Camarena) | AA36: =SUM(VLOOKUP(Y36,B:E,4,FALSE),VLOOKUP(Y36,F:I,4,FALSE),VLOOKUP(Y36,J:M,4,FALSE),VLOOKUP(Y36,N:Q,4,FALSE),VLOOKUP(Y36,R:U,4,FALSE)) -> 8 | AB36: =SUM(VLOOKUP(Y36,$B:$E,2,FALSE),VLOOKUP(Y36,$F:$I,2,FALSE),VLOOKUP(Y36,$J:$M,2,FALSE),VLOOKUP(Y36,$N:$Q,2,FALSE),VLOOKUP(Y36,$R:$U,2,FALSE)) -> 406 | AC36: =X37 -> Enfield HS - Team 1 | AE36: =AE35+1 -> 29 | AF36: 239.1174 | AG36: =VLOOKUP(AF36,$AC$8:$AC$37,2,FALSE) -> #REF!
A37: SHH 112 | B37: =X27 -> New Canaan HS - Team 2 | C37: 44 | D37: TRUE | E37: =IF(D37=True, IF(C37>C38,2,IF(C37=C38,1,0)),0) -> 0 | F37: =B39 -> CT IB Acad - Team 3 | G37: 12 | H37: TRUE | I37: =IF(H37=True, IF(G37>G38,2,IF(G37=G38,1,0)),0) -> 0 | J37: =F36 -> Joel Barlow HS | K37: 32 | L37: TRUE | M37: =IF(L37=True, IF(K37>K38,2,IF(K37=K38,1,0)),0) -> 0 | N37: =J35 -> Greenwich HS - Team 1 | O37: 118 | P37: TRUE | Q37: =IF(P37=True, IF(O37>O38,2,IF(O37=O38,1,0)),0) -> 2 | R37: =N37 -> Greenwich HS - Team 1 | S37: 178 | T37: TRUE | U37: =IF(T37=True, IF(S37>S38,2,IF(S37=S38,1,0)),0) -> 2 | W37: =W36+1 -> 30 | X37: Enfield HS - Team 1 | Y37: New Canaan HS - Team 2 | Z37: =IF(MATCH(Y37,R:R,0)<14,$B$5,IF(MATCH(Y37,R:R,0)<23,$B$14,IF(MATCH(Y37,R:R,0)<32,$B$23,IF(MATCH(Y37,R:R,0)<41,$B$32,IF(MATCH(Y37,R:R,0)<50,$B$41,IF(MATCH(Y37,R:R,0)<59,$B$50,IF(MATCH(Y37,R:R,0)<68,$B$59,$B$68))))))) -> Division 4 (Ellen Ochoa) | AA37: =SUM(VLOOKUP(Y37,B:E,4,FALSE),VLOOKUP(Y37,F:I,4,FALSE),VLOOKUP(Y37,J:M,4,FALSE),VLOOKUP(Y37,N:Q,4,FALSE),VLOOKUP(Y37,R:U,4,FALSE)) -> 2 | AB37: =SUM(VLOOKUP(Y37,$B:$E,2,FALSE),VLOOKUP(Y37,$F:$I,2,FALSE),VLOOKUP(Y37,$J:$M,2,FALSE),VLOOKUP(Y37,$N:$Q,2,FALSE),VLOOKUP(Y37,$R:$U,2,FALSE)) -> 212 | AC37: =X38 -> Greenwich HS - Team 3 | AE37: =AE36+1 -> 30 | AF37: 221.5698 | AG37: =VLOOKUP(AF37,$AC$8:$AC$37,2,FALSE) -> #REF!
B38: =X36 -> Fairfield Warde HS - Team 1 | C38: 72 | D38: TRUE | E38: =IF(D38=True, IF(C38>C37,2,IF(C38=C37,1,0)),0) -> 2 | F38: =B36 -> Conard HS - Team 1 | G38: 64 | H38: TRUE | I38: =IF(H38=True, IF(G38>G37,2,IF(G38=G37,1,0)),0) -> 2 | J38: =F40 -> Fairfield Warde HS - Team 1 | K38: 86 | L38: TRUE | M38: =IF(L38=True, IF(K38>K37,2,IF(K38=K37,1,0)),0) -> 2 | N38: =J37 -> Joel Barlow HS | O38: 34 | P38: TRUE | Q38: =IF(P38=True, IF(O38>O37,2,IF(O38=O37,1,0)),0) -> 0 | R38: =N40 -> New Canaan HS - Team 2 | S38: 32 | T38: TRUE | U38: =IF(T38=True, IF(S38>S37,2,IF(S38=S37,1,0)),0) -> 0 | W38: =W37+1 -> 31 | X38: Greenwich HS - Team 3 | Y38: New Canaan HS - Team 3 | Z38: =IF(MATCH(Y38,R:R,0)<14,$B$5,IF(MATCH(Y38,R:R,0)<23,$B$14,IF(MATCH(Y38,R:R,0)<32,$B$23,IF(MATCH(Y38,R:R,0)<41,$B$32,IF(MATCH(Y38,R:R,0)<50,$B$41,IF(MATCH(Y38,R:R,0)<59,$B$50,IF(MATCH(Y38,R:R,0)<68,$B$59,$B$68))))))) -> Division 7 (Irene Uchida) | AA38: =SUM(VLOOKUP(Y38,B:E,4,FALSE),VLOOKUP(Y38,F:I,4,FALSE),VLOOKUP(Y38,J:M,4,FALSE),VLOOKUP(Y38,N:Q,4,FALSE),VLOOKUP(Y38,R:U,4,FALSE)) -> 6 | AB38: =SUM(VLOOKUP(Y38,$B:$E,2,FALSE),VLOOKUP(Y38,$F:$I,2,FALSE),VLOOKUP(Y38,$J:$M,2,FALSE),VLOOKUP(Y38,$N:$Q,2,FALSE),VLOOKUP(Y38,$R:$U,2,FALSE)) -> 264
A39: SHH 117 | B39: =X43 -> CT IB Acad - Team 3 | C39: 48 | D39: TRUE | E39: =IF(D39=True, IF(C39>C40,2,IF(C39=C40,1,0)),0) -> 0 | F39: =B35 -> Greenwich HS - Team 1 | G39: 132 | H39: TRUE | I39: =IF(H39=True, IF(G39>G40,2,IF(G39=G40,1,0)),0) -> 2 | J39: =F35 -> New Canaan HS - Team 2 | K39: 52 | L39: TRUE | M39: =IF(L39=True, IF(K39>K40,2,IF(K39=K40,1,0)),0) -> 0 | N39: =J36 -> CT IB Acad - Team 3 | O39: 20 | P39: TRUE | Q39: =IF(P39=True, IF(O39>O40,2,IF(O39=O40,1,0)),0) -> 0 | R39: =N38 -> Joel Barlow HS | S39: 58 | T39: TRUE | U39: =IF(T39=True, IF(S39>S40,2,IF(S39=S40,1,0)),0) -> 0 | W39: =W38+1 -> 32 | X39: Fairfield Ludlowe HS | Y39: Newtown HS | Z39: =IF(MATCH(Y39,R:R,0)<14,$B$5,IF(MATCH(Y39,R:R,0)<23,$B$14,IF(MATCH(Y39,R:R,0)<32,$B$23,IF(MATCH(Y39,R:R,0)<41,$B$32,IF(MATCH(Y39,R:R,0)<50,$B$41,IF(MATCH(Y39,R:R,0)<59,$B$50,IF(MATCH(Y39,R:R,0)<68,$B$59,$B$68))))))) -> Division 6 (Guillermo Camarena) | AA39: =SUM(VLOOKUP(Y39,B:E,4,FALSE),VLOOKUP(Y39,F:I,4,FALSE),VLOOKUP(Y39,J:M,4,FALSE),VLOOKUP(Y39,N:Q,4,FALSE),VLOOKUP(Y39,R:U,4,FALSE)) -> 6 | AB39: =SUM(VLOOKUP(Y39,$B:$E,2,FALSE),VLOOKUP(Y39,$F:$I,2,FALSE),VLOOKUP(Y39,$J:$M,2,FALSE),VLOOKUP(Y39,$N:$Q,2,FALSE),VLOOKUP(Y39,$R:$U,2,FALSE)) -> 306
B40: =X52 -> Joel Barlow HS | C40: 62 | D40: TRUE | E40: =IF(D40=True, IF(C40>C39,2,IF(C40=C39,1,0)),0) -> 2 | F40: =B38 -> Fairfield Warde HS - Team 1 | G40: 46 | H40: TRUE | I40: =IF(H40=True, IF(G40>G39,2,IF(G40=G39,1,0)),0) -> 0 | J40: =F38 -> Conard HS - Team 1 | K40: 72 | L40: TRUE | M40: =IF(L40=True, IF(K40>K39,2,IF(K40=K39,1,0)),0) -> 2 | N40: =J39 -> New Canaan HS - Team 2 | O40: 50 | P40: TRUE | Q40: =IF(P40=True, IF(O40>O39,2,IF(O40=O39,1,0)),0) -> 2 | R40: =N35 -> Conard HS - Team 1 | S40: 62 | T40: TRUE | U40: =IF(T40=True, IF(S40>S39,2,IF(S40=S39,1,0)),0) -> 2 | W40: =W39+1 -> 33 | X40: Loomis Chaffee - Team 2 | Y40: Open Spot - 1 | Z40: =IF(MATCH(Y40,R:R,0)<14,$B$5,IF(MATCH(Y40,R:R,0)<23,$B$14,IF(MATCH(Y40,R:R,0)<32,$B$23,IF(MATCH(Y40,R:R,0)<41,$B$32,IF(MATCH(Y40,R:R,0)<50,$B$41,IF(MATCH(Y40,R:R,0)<59,$B$50,IF(MATCH(Y40,R:R,0)<68,$B$59,$B$68))))))) -> Division 8 (Bernardo Houssay) - Canceled Division - Sorry! | AA40: =SUM(VLOOKUP(Y40,B:E,4,FALSE),VLOOKUP(Y40,F:I,4,FALSE),VLOOKUP(Y40,J:M,4,FALSE),VLOOKUP(Y40,N:Q,4,FALSE),VLOOKUP(Y40,R:U,4,FALSE)) -> 0 | AB40: =SUM(VLOOKUP(Y40,$B:$E,2,FALSE),VLOOKUP(Y40,$F:$I,2,FALSE),VLOOKUP(Y40,$J:$M,2,FALSE),VLOOKUP(Y40,$N:$Q,2,FALSE),VLOOKUP(Y40,$R:$U,2,FALSE)) -> 0
B41: Division 5 (Ursula Burns) | W41: =W40+1 -> 34 | X41: South Windsor HS - Team 2 | Y41: Open Spot - 2 | Z41: =IF(MATCH(Y41,R:R,0)<14,$B$5,IF(MATCH(Y41,R:R,0)<23,$B$14,IF(MATCH(Y41,R:R,0)<32,$B$23,IF(MATCH(Y41,R:R,0)<41,$B$32,IF(MATCH(Y41,R:R,0)<50,$B$41,IF(MATCH(Y41,R:R,0)<59,$B$50,IF(MATCH(Y41,R:R,0)<68,$B$59,$B$68))))))) -> Division 8 (Bernardo Houssay) - Canceled Division - Sorry! | AA41: =SUM(VLOOKUP(Y41,B:E,4,FALSE),VLOOKUP(Y41,F:I,4,FALSE),VLOOKUP(Y41,J:M,4,FALSE),VLOOKUP(Y41,N:Q,4,FALSE),VLOOKUP(Y41,R:U,4,FALSE)) -> 0 | AB41: =SUM(VLOOKUP(Y41,$B:$E,2,FALSE),VLOOKUP(Y41,$F:$I,2,FALSE),VLOOKUP(Y41,$J:$M,2,FALSE),VLOOKUP(Y41,$N:$Q,2,FALSE),VLOOKUP(Y41,$R:$U,2,FALSE)) -> 0
...

Sheet CT RR Calculations (Private)
A1: Formula Copied Scores from Main Sheet | F1: Sorted By Division | K1: Divisional Sort | P1: Top 2 Teams in Division (check head to head) | V1: Top 16 Teams Seeded by Score | AB1: Test Mode | AC1: Blank | AD1: =if('CT RR Calculations (Private)'!$AC$1="Test Scores On",randbetween(1,75),)
A2: ='CT Region ROUND ROBIN Scores (P'!Y7 -> Team (Alphabetical) | B2: ='CT Region ROUND ROBIN Scores (P'!Z7 -> Division | C2: ='CT Region ROUND ROBIN Scores (P'!AA7 -> Total Points | D2: ='CT Region ROUND ROBIN Scores (P'!AB7 -> Total Score | F2: Team | G2: Division | H2: Total Points | I2: Total Score | K2: Team | L2: Division | M2: Total Points | N2: Total Score | P2: Div. Seed | Q2: Team | R2: Division | S2: Total Points | T2: Total Score | V2: Seed | W2: Team | X2: Division | Y2: Total Points | Z2: Total Score
A3: ='CT Region ROUND ROBIN Scores (P'!Y8 -> Amity Regional HS | B3: ='CT Region ROUND ROBIN Scores (P'!Z8 -> Division 3 (Silas Adekunle) | C3: ='CT Region ROUND ROBIN Scores (P'!AA8 -> 8 | D3: ='CT Region ROUND ROBIN Scores (P'!AB8 -> 438 | F3: {=sort(A3:D50,2,true)} -> CT IB Acad - Team 2 | G3: Division 1 (Temple Grandin) | H3: 4 | I3: 226 | K3: {=sort(F3:I8,3,False,4,False)} -> Farmington HS - Team 1 | L3: Division 1 (Temple Grandin) | M3: 10 | N3: 1030 | P3: 1 | Q3: Farmington HS - Team 1 | R3: Division 1 (Temple Grandin) | S3: 8 | T3: 832 | V3: 1 | W3: {=sort(Q3:T18,4,false)} -> Farmington HS - Team 1 | X3: Division 1 (Temple Grandin) | Y3: 8 | Z3: 832 | AB3: Round Robin Signal
A4: ='CT Region ROUND ROBIN Scores (P'!Y9 -> Bacon Academy | B4: ='CT Region ROUND ROBIN Scores (P'!Z9 -> Division 2 (Marian Croak) | C4: ='CT Region ROUND ROBIN Scores (P'!AA9 -> 2 | D4: ='CT Region ROUND ROBIN Scores (P'!AB9 -> 152 | F4: Ethel Walker School | G4: Division 1 (Temple Grandin) | H4: 0 | I4: 70 | K4: Southington HS - Team 1 | L4: Division 1 (Temple Grandin) | M4: 8 | N4: 606 | P4: 2 | Q4: Southington HS - Team 1 | R4: Division 1 (Temple Grandin) | S4: 8 | T4: 544 | V4: 2 | W4: Waterford HS - Team 1 | X4: Division 2 (Marian Croak) | Y4: 10 | Z4: 762 | AB4: Not Ready
A5: ='CT Region ROUND ROBIN Scores (P'!Y10 -> Choate Rosemary Hall | B5: ='CT Region ROUND ROBIN Scores (P'!Z10 -> Division 7 (Irene Uchida) | C5: ='CT Region ROUND ROBIN Scores (P'!AA10 -> 6 | D5: ='CT Region ROUND ROBIN Scores (P'!AB10 -> 294 | F5: Fairfield Ludlowe HS | G5: Division 1 (Temple Grandin) | H5: 2 | I5: 200 | K5: Loomis Chaffee - Team 2 | L5: Division 1 (Temple Grandin) | M5: 6 | N5: 334 | P5: 1 | Q5: Waterford HS - Team 1 | R5: Division 2 (Marian Croak) | S5: 10 | T5: 762 | V5: 3 | W5: EO Smith HS - Team 1 | X5: Division 3 (Silas Adekunle) | Y5: 10 | Z5: 750
A6: ='CT Region ROUND ROBIN Scores (P'!Y11 -> Conard HS - Team 1 | B6: ='CT Region ROUND ROBIN Scores (P'!Z11 -> Division 4 (Ellen Ochoa) | C6: ='CT Region ROUND ROBIN Scores (P'!AA11 -> 6 | D6: ='CT Region ROUND ROBIN Scores (P'!AB11 -> 290 | F6: Farmington HS - Team 1 | G6: Division 1 (Temple Grandin) | H6: 10 | I6: 1030 | K6: CT IB Acad - Team 2 | L6: Division 1 (Temple Grandin) | M6: 4 | N6: 226 | P6: 2 | Q6: South Windsor HS - Team 2 | R6: Division 2 (Marian Croak) | S6: 8 | T6: 346 | V6: 4 | W6: Greenwich HS - Team 1 | X6: Division 4 (Ellen Ochoa) | Y6: 10 | Z6: 650 | AB6: Tiebreaker Game Signal
A7: ='CT Region ROUND ROBIN Scores (P'!Y12 -> Conard HS - Team 2 | B7: ='CT Region ROUND ROBIN Scores (P'!Z12 -> Division 2 (Marian Croak) | C7: ='CT Region ROUND ROBIN Scores (P'!AA12 -> 6 | D7: ='CT Region ROUND ROBIN Scores (P'!AB12 -> 220 | F7: Loomis Chaffee - Team 2 | G7: Division 1 (Temple Grandin) | H7: 6 | I7: 334 | K7: Fairfield Ludlowe HS | L7: Division 1 (Temple Grandin) | M7: 2 | N7: 200 | P7: 1 | Q7: EO Smith HS - Team 1 | R7: Division 3 (Silas Adekunle) | S7: 10 | T7: 750 | V7: 5 | W7: Southington HS - Team 1 | X7: Division 1 (Temple Grandin) | Y7: 8 | Z7: 544 | AB7: Ready
A8: ='CT Region ROUND ROBIN Scores (P'!Y13 -> CT IB Acad - Team 1 | B8: ='CT Region ROUND ROBIN Scores (P'!Z13 -> Division 3 (Silas Adekunle) | C8: ='CT Region ROUND ROBIN Scores (P'!AA13 -> 0 | D8: ='CT Region ROUND ROBIN Scores (P'!AB13 -> 72 | F8: Southington HS - Team 1 | G8: Division 1 (Temple Grandin) | H8: 8 | I8: 606 | K8: Ethel Walker School | L8: Division 1 (Temple Grandin) | M8: 0 | N8: 70 | P8: 2 | Q8: Amity Regional HS | R8: Division 3 (Silas Adekunle) | S8: 8 | T8: 438 | V8: 6 | W8: Farmington HS - Team 2 | X8: Division 6 (Guillermo Camarena) | Y8: 8 | Z8: 508
A9: ='CT Region ROUND ROBIN Scores (P'!Y14 -> CT IB Acad - Team 2 | B9: ='CT Region ROUND ROBIN Scores (P'!Z14 -> Division 1 (Temple Grandin) | C9: ='CT Region ROUND ROBIN Scores (P'!AA14 -> 4 | D9: ='CT Region ROUND ROBIN Scores (P'!AB14 -> 226 | F9: Bacon Academy | G9: Division 2 (Marian Croak) | H9: 2 | I9: 152 | K9: {=sort(F9:I14,3,False,4,False)} -> Waterford HS - Team 1 | L9: Division 2 (Marian Croak) | M9: 10 | N9: 762 | P9: 1 | Q9: Greenwich HS - Team 1 | R9: Division 4 (Ellen Ochoa) | S9: 10 | T9: 650 | V9: 7 | W9: Loomis Chaffee - Team 1 | X9: Division 5 (Ursula Burns) | Y9: 8 | Z9: 468 | AB9: Championship Game Signal
A10: ='CT Region ROUND ROBIN Scores (P'!Y15 -> CT IB Acad - Team 3 | B10: ='CT Region ROUND ROBIN Scores (P'!Z15 -> Division 4 (Ellen Ochoa) | C10: ='CT Region ROUND ROBIN Scores (P'!AA15 -> 0 | D10: ='CT Region ROUND ROBIN Scores (P'!AB15 -> 146 | F10: Conard HS - Team 2 | G10: Division 2 (Marian Croak) | H10: 6 | I10: 220 | K10: South Windsor HS - Team 2 | L10: Division 2 (Marian Croak) | M10: 8 | N10: 346 | P10: 2 | Q10: Fairfield Warde HS - Team 1 | R10: Division 4 (Ellen Ochoa) | S10: 8 | T10: 370 | V10: 8 | W10: Rocky Hill HS - Team 1 | X10: Division 6 (Guillermo Camarena) | Y10: 6 | Z10: 458 | AB10: Ready
A11: ='CT Region ROUND ROBIN Scores (P'!Y16 -> East Lyme HS - Team 1 | B11: ='CT Region ROUND ROBIN Scores (P'!Z16 -> Division 5 (Ursula Burns) | C11: ='CT Region ROUND ROBIN Scores (P'!AA16 -> 4 | D11: ='CT Region ROUND ROBIN Scores (P'!AB16 -> 422 | F11: Greenwich HS - Team 3 | G11: Division 2 (Marian Croak) | H11: 0 | I11: 170 | K11: Conard HS - Team 2 | L11: Division 2 (Marian Croak) | M11: 6 | N11: 220 | P11: 1 | Q11: Univ HS Sci & Eng | R11: Division 5 (Ursula Burns) | S11: 10 | T11: 372 | V11: 9 | W11: Amity Regional HS | X11: Division 3 (Silas Adekunle) | Y11: 8 | Z11: 438
A12: ='CT Region ROUND ROBIN Scores (P'!Y17 -> East Lyme HS - Team 2 | B12: ='CT Region ROUND ROBIN Scores (P'!Z17 -> Division 3 (Silas Adekunle) | C12: ='CT Region ROUND ROBIN Scores (P'!AA17 -> 4 | D12: ='CT Region ROUND ROBIN Scores (P'!AB17 -> 294 | F12: South Windsor HS - Team 2 | G12: Division 2 (Marian Croak) | H12: 8 | I12: 346 | K12: Southington HS - Team 2 | L12: Division 2 (Marian Croak) | M12: 4 | N12: 162 | P12: 2 | Q12: Loomis Chaffee - Team 1 | R12: Division 5 (Ursula Burns) | S12: 8 | T12: 468 | V12: 10 | W12: Greenwich HS - Team 2 | X12: Division 7 (Irene Uchida) | Y12: 10 | Z12: 420 | AB12: House Tournament Game Signal
A13: ='CT Region ROUND ROBIN Scores (P'!Y18 -> Enfield HS - Team 1 | B13: ='CT Region ROUND ROBIN Scores (P'!Z18 -> Division 3 (Silas Adekunle) | C13: ='CT Region ROUND ROBIN Scores (P'!AA18 -> 2 | D13: ='CT Region ROUND ROBIN Scores (P'!AB18 -> 142 | F13: Southington HS - Team 2 | G13: Division 2 (Marian Croak) | H13: 4 | I13: 162 | K13: Bacon Academy | L13: Division 2 (Marian Croak) | M13: 2 | N13: 152 | P13: 1 | Q13: Farmington HS - Team 2 | R13: Division 6 (Guillermo Camarena) | S13: 8 | T13: 508 | V13: 11 | W13: New Canaan HS - Team 1 | X13: Division 6 (Guillermo Camarena) | Y13: 8 | Z13: 406 | AB13: Not Ready
A14: ='CT Region ROUND ROBIN Scores (P'!Y19 -> Enfield HS - Team 2 | B14: ='CT Region ROUND ROBIN Scores (P'!Z19 -> Division 6 (Guillermo Camarena) | C14: ='CT Region ROUND ROBIN Scores (P'!AA19 -> 2 | D14: ='CT Region ROUND ROBIN Scores (P'!AB19 -> 158 | F14: Waterford HS - Team 1 | G14: Division 2 (Marian Croak) | H14: 10 | I14: 762 | K14: Greenwich HS - Team 3 | L14: Division 2 (Marian Croak) | M14: 0 | N14: 170 | P14: 2 | Q14: New Canaan HS - Team 1 | R14: Division 6 (Guillermo Camarena) | S14: 8 | T14: 406 | V14: 12 | W14: Univ HS Sci & Eng | X14: Division 5 (Ursula Burns) | Y14: 10 | Z14: 372
A15: ='CT Region ROUND ROBIN Scores (P'!Y20 -> Enfield HS - Team 3 | B15: ='CT Region ROUND ROBIN Scores (P'!Z20 -> Division 7 (Irene Uchida) | C15: ='CT Region ROUND ROBIN Scores (P'!AA20 -> 2 | D15: ='CT Region ROUND ROBIN Scores (P'!AB20 -> 156 | F15: Amity Regional HS | G15: Division 3 (Silas Adekunle) | H15: 8 | I15: 438 | K15: {=sort(F15:I20,3,False,4,False)} -> EO Smith HS - Team 1 | L15: Division 3 (Silas Adekunle) | M15: 10 | N15: 750 | P15: 1 | Q15: Greenwich HS - Team 2 | R15: Division 7 (Irene Uchida) | S15: 10 | T15: 420 | V15: 13 | W15: Fairfield Warde HS - Team 1 | X15: Division 4 (Ellen Ochoa) | Y15: 8 | Z15: 370
A16: ='CT Region ROUND ROBIN Scores (P'!Y21 -> EO Smith HS - Team 1 | B16: ='CT Region ROUND ROBIN Scores (P'!Z21 -> Division 3 (Silas Adekunle) | C16: ='CT Region ROUND ROBIN Scores (P'!AA21 -> 10 | D16: ='CT Region ROUND ROBIN Scores (P'!AB21 -> 750 | F16: CT IB Acad - Team 1 | G16: Division 3 (Silas Adekunle) | H16: 0 | I16: 72 | K16: Amity Regional HS | L16: Division 3 (Silas Adekunle) | M16: 8 | N16: 438 | P16: 2 | Q16: New Canaan HS - Team 3 | R16: Division 7 (Irene Uchida) | S16: 6 | T16: 264 | V16: 14 | W16: South Windsor HS - Team 2 | X16: Division 2 (Marian Croak) | Y16: 8 | Z16: 346
A17: ='CT Region ROUND ROBIN Scores (P'!Y22 -> EO Smith HS - Team 2 | B17: ='CT Region ROUND ROBIN Scores (P'!Z22 -> Division 5 (Ursula Burns) | C17: ='CT Region ROUND ROBIN Scores (P'!AA22 -> 6 | D17: ='CT Region ROUND ROBIN Scores (P'!AB22 -> 298 | F17: East Lyme HS - Team 2 | G17: Division 3 (Silas Adekunle) | H17: 4 | I17: 294 | K17: Rocky Hill HS - Team 2 | L17: Division 3 (Silas Adekunle) | M17: 6 | N17: 328 | P17: 1 | Q17: Rocky Hill HS - Team 1 | R17: Division 6 (Guillermo Camarena) | S17: 6 | T17: 458 | V17: 15 | W17: EO Smith HS - Team 2 | X17: Division 5 (Ursula Burns) | Y17: 6 | Z17: 298
A18: ='CT Region ROUND ROBIN Scores (P'!Y23 -> Ethel Walker School | B18: ='CT Region ROUND ROBIN Scores (P'!Z23 -> Division 1 (Temple Grandin) | C18: ='CT Region ROUND ROBIN Scores (P'!AA23 -> 0 | D18: ='CT Region ROUND ROBIN Scores (P'!AB23 -> 70 | F18: Enfield HS - Team 1 | G18: Division 3 (Silas Adekunle) | H18: 2 | I18: 142 | K18: East Lyme HS - Team 2 | L18: Division 3 (Silas Adekunle) | M18: 4 | N18: 294 | P18: 2 | Q18: EO Smith HS - Team 2 | R18: Division 5 (Ursula Burns) | S18: 6 | T18: 298 | V18: 16 | W18: New Canaan HS - Team 3 | X18: Division 7 (Irene Uchida) | Y18: 6 | Z18: 264
A19: ='CT Region ROUND ROBIN Scores (P'!Y24 -> Fairfield Ludlowe HS | B19: ='CT Region ROUND ROBIN Scores (P'!Z24 -> Division 1 (Temple Grandin) | C19: ='CT Region ROUND ROBIN Scores (P'!AA24 -> 2 | D19: ='CT Region ROUND ROBIN Scores (P'!AB24 -> 200 | F19: EO Smith HS - Team 1 | G19: Division 3 (Silas Adekunle) | H19: 10 | I19: 750 | K19: Enfield HS - Team 1 | L19: Division 3 (Silas Adekunle) | M19: 2 | N19: 142 | V19: Tiebreaker rounds needed if more than two teams below
A20: ='CT Region ROUND ROBIN Scores (P'!Y25 -> Fairfield Warde HS - Team 1 | B20: ='CT Region ROUND ROBIN Scores (P'!Z25 -> Division 4 (Ellen Ochoa) | C20: ='CT Region ROUND ROBIN Scores (P'!AA25 -> 8 | D20: ='CT Region ROUND ROBIN Scores (P'!AB25 -> 370 | F20: Rocky Hill HS - Team 2 | G20: Division 3 (Silas Adekunle) | H20: 6 | I20: 328 | K20: CT IB Acad - Team 1 | L20: Division 3 (Silas Adekunle) | M20: 0 | N20: 72 | V20: Tiebreaker teams (manually input after checking head to head scores if needed)
A21: ='CT Region ROUND ROBIN Scores (P'!Y26 -> Fairfield Warde HS - Team 2 | B21: ='CT Region ROUND ROBIN Scores (P'!Z26 -> Division 6 (Guillermo Camarena) | C21: ='CT Region ROUND ROBIN Scores (P'!AA26 -> 0 | D21: ='CT Region ROUND ROBIN Scores (P'!AB26 -> 146 | F21: Conard HS - Team 1 | G21: Division 4 (Ellen Ochoa) | H21: 6 | I21: 290 | K21: {=sort(F21:I26,3,False,4,False)} -> Greenwich HS - Team 1 | L21: Division 4 (Ellen Ochoa) | M21: 10 | N21: 650 | P21: Remaining teams sorted by division (check head to head changes) | W21: Loomis Chaffee - Team 2 | X21: Division 1 (Temple Grandin) | Y21: 6 | Z21: 334
A22: ='CT Region ROUND ROBIN Scores (P'!Y27 -> Farmington HS - Team 1 | B22: ='CT Region ROUND ROBIN Scores (P'!Z27 -> Division 1 (Temple Grandin) | C22: ='CT Region ROUND ROBIN Scores (P'!AA27 -> 10 | D22: ='CT Region ROUND ROBIN Scores (P'!AB27 -> 1030 | F22: CT IB Acad - Team 3 | G22: Division 4 (Ellen Ochoa) | H22: 0 | I22: 146 | K22: Fairfield Warde HS - Team 1 | L22: Division 4 (Ellen Ochoa) | M22: 8 | N22: 370 | Q22: {=sort(K5:N8,3,false)} -> Loomis Chaffee - Team 2 | R22: Division 1 (Temple Grandin) | S22: 6 | T22: 334 | W22: Conard HS - Team 2 | X22: Division 2 (Marian Croak) | Y22: 6 | Z22: 220
A23: ='CT Region ROUND ROBIN Scores (P'!Y28 -> Farmington HS - Team 2 | B23: ='CT Region ROUND ROBIN Scores (P'!Z28 -> Division 6 (Guillermo Camarena) | C23: ='CT Region ROUND ROBIN Scores (P'!AA28 -> 8 | D23: ='CT Region ROUND ROBIN Scores (P'!AB28 -> 508 | F23: Fairfield Warde HS - Team 1 | G23: Division 4 (Ellen Ochoa) | H23: 8 | I23: 370 | K23: Conard HS - Team 1 | L23: Division 4 (Ellen Ochoa) | M23: 6 | N23: 290 | Q23: CT IB Acad - Team 2 | R23: Division 1 (Temple Grandin) | S23: 4 | T23: 226 | W23: Conard HS - Team 1 | X23: Division 4 (Ellen Ochoa) | Y23: 6 | Z23: 290
A24: ='CT Region ROUND ROBIN Scores (P'!Y29 -> Greenwich HS - Team 1 | B24: ='CT Region ROUND ROBIN Scores (P'!Z29 -> Division 4 (Ellen Ochoa) | C24: ='CT Region ROUND ROBIN Scores (P'!AA29 -> 10 | D24: ='CT Region ROUND ROBIN Scores (P'!AB29 -> 650 | F24: Greenwich HS - Team 1 | G24: Division 4 (Ellen Ochoa) | H24: 10 | I24: 650 | K24: Joel Barlow HS | L24: Division 4 (Ellen Ochoa) | M24: 4 | N24: 248 | Q24: Fairfield Ludlowe HS | R24: Division 1 (Temple Grandin) | S24: 2 | T24: 200 | W24: EO Smith HS - Team 2 | X24: Division 5 (Ursula Burns) | Y24: 6 | Z24: 298
A25: ='CT Region ROUND ROBIN Scores (P'!Y30 -> Greenwich HS - Team 2 | B25: ='CT Region ROUND ROBIN Scores (P'!Z30 -> Division 7 (Irene Uchida) | C25: ='CT Region ROUND ROBIN Scores (P'!AA30 -> 10 | D25: ='CT Region ROUND ROBIN Scores (P'!AB30 -> 420 | F25: Joel Barlow HS | G25: Division 4 (Ellen Ochoa) | H25: 4 | I25: 248 | K25: New Canaan HS - Team 2 | L25: Division 4 (Ellen Ochoa) | M25: 2 | N25: 212 | Q25: Ethel Walker School | R25: Division 1 (Temple Grandin) | S25: 0 | T25: 70 | W25: Rocky Hill HS - Team 1 | X25: Division 6 (Guillermo Camarena) | Y25: 6 | Z25: 458
A26: ='CT Region ROUND ROBIN Scores (P'!Y31 -> Greenwich HS - Team 3 | B26: ='CT Region ROUND ROBIN Scores (P'!Z31 -> Division 2 (Marian Croak) | C26: ='CT Region ROUND ROBIN Scores (P'!AA31 -> 0 | D26: ='CT Region ROUND ROBIN Scores (P'!AB31 -> 170 | F26: New Canaan HS - Team 2 | G26: Division 4 (Ellen Ochoa) | H26: 2 | I26: 212 | K26: CT IB Acad - Team 3 | L26: Division 4 (Ellen Ochoa) | M26: 0 | N26: 146 | Q26: {=sort(K11:N14,3,false)} -> Conard HS - Team 2 | R26: Division 2 (Marian Croak) | S26: 6 | T26: 220 | W26: Newtown HS | X26: Division 6 (Guillermo Camarena) | Y26: 6 | Z26: 306
A27: ='CT Region ROUND ROBIN Scores (P'!Y32 -> Greenwich HS - Team 4 | B27: ='CT Region ROUND ROBIN Scores (P'!Z32 -> Division 8 (Bernardo Houssay) - Canceled Division - Sorry! | C27: ='CT Region ROUND ROBIN Scores (P'!AA32 -> 0 | D27: ='CT Region ROUND ROBIN Scores (P'!AB32 -> 0 | F27: East Lyme HS - Team 1 | G27: Division 5 (Ursula Burns) | H27: 4 | I27: 422 | K27: {=sort(F27:I32,3,False,4,False)} -> Univ HS Sci & Eng | L27: Division 5 (Ursula Burns) | M27: 10 | N27: 372 | Q27: Southington HS - Team 2 | R27: Division 2 (Marian Croak) | S27: 4 | T27: 162 | W27: Choate Rosemary Hall | X27: Division 7 (Irene Uchida) | Y27: 6 | Z27: 294
