Workbook

Sheet Round Robin Groups
A1: w | E1: Category Statistics
B2: Teams | C2: Payment Status
B3: MSJ A | C3: TRUE
B4: MSJ B | C4: TRUE | E4: Round Robin Groups
B5: Iolani A | C5: TRUE
B6: Iolani B | C6: TRUE
B7: Collierville | C7: TRUE
B8: ASFA | C8: TRUE | E8: Group A | F8: Group B | G8: Group C | H8: Group D | I8: Group E | J8: Group F
B9: Palo Alto | C9: TRUE | D9: 1 | E9: Mission San Jose A | F9: Enloe | G9: Evergreen | H9: Commonwealth School | I9: Misson San Jose B | J9: Lakeside
B10: Centreville A | C10: TRUE | D10: 2 | E10: BYE | F10: Iolani A | G10: Basis Chandler A | H10: Whitney Young | I10: School of Biology | J10: Iolani B
B11: North Hollywood | C11: TRUE | D11: 3 | E11: Princeton | F11: Winston Churchill | G11: Montgomery Blair A | H11: Montgomery Blair B | I11: Brooklyn Tech A | J11: Wayzata
B12: Temple City | C12: TRUE | D12: 4 | E12: Basis Silicon Valley | F12: North Hollywood | G12: Plano West | H12: Canyon Crest A | I12: Saratoga | J12: Palo Alto
B13: Brooklyn Tech A | C13: TRUE | D13: 5 | E13: Collierville | F13: Temple City | G13: Canyon Crest B | H13: James Clemens | I13: WWPS A | J13: East Brunswick
B14: Brooklyn Tech B | C14: TRUE | D14: 6 | E14: Centreville A | F14: Brooklyn Tech B | G14: BYE | H14: BYE | I14: ASFA | J14: BYE
B15: School of Biology | C15: TRUE
B16: WWPS A | C16: TRUE
B17: Princeton | C17: TRUE
B18: East Brunswick | C18: TRUE
B19: Blair A | C19: TRUE
B20: Blair B | C20: TRUE
B21: Lakeside | C21: TRUE
B22: Plano West | C22: TRUE
B23: Basis Chandler A | C23: TRUE
B24: CCA A | C24: TRUE
B25: CCA B | C25: TRUE
B26: Evergreen | C26: TRUE
... B34: Enloe | C34: TRUE

Sheet Schedule + Room Assignments
B2: Room | C2: RR 1 | D2: RR 2 | E2: RR 3 | F2: RR 4 | G2: RR 5 | I2: Event | J2: Time (EST)
B3: Room 1 | C3: A1 BYE | D3: A4— A5 | E3: A1 — A4 | F3: A1 — A5 | G3: A3 — A4 | I3: Opening Meeting | J3: 10:55 a.m. - 11:10 a.m.
B4: Room 2 | C4: A3 — A5 | D4: A1 — A3 | E4: A5 — A6 | F4: A3 — A6 | G4: A1 — A6 | I4: RR 1 | J4: 11:10 a.m. - 11:55 a.m.
B5: Room 3 | C5: A4 — A6 | D5: A6 BYE | E5: A3 BYE | F5: A4 BYE | G5: A5 BYE | I5: RR 2 | J5: 11:55 a.m. - 12:30 p.m.
B6: Room 4 | C6: B1 — B2 | D6: B4— B5 | E6: B2 — B3 | F6: B1 — B5 | G6: B3 — B4 | I6: RR 3 | J6: 12:30 p.m. - 1:05 p.m.
B7: Room 5 | C7: B3 — B5 | D7: B1 — B3 | E7: B5 — B6 | F7: B2 — B4 | G7: B1 — B6 | I7: RR 4 | J7: 1:05 p.m. - 1:40 p.m.
B8: Room 6 | C8: B4 — B6 | D8: B2 — B6 | E8: B1 — B4 | F8: B3 — B6 | G8: B2 — B5 | I8: RR 5 | J8: 1:40 p.m. - 2:15 p.m.
B9: Room 7 | C9: C1 — C2 | D9: C4— C5 | E9: C2 — C3 | F9: C1 — C5 | G9: C3 — C4 | I9: Lunch | J9: 2:45 p.m. - 3:30p.m.
B10: Room 8 | C10: C3 — C5 | D10: C1 — C3 | E10: C1 — C4 | F10: C2 — C4 | G10: C2 — C5 | I10: DE 1 | J10: 3:30 p.m. - 4:00 p.m.
B11: Room 9 | C11: C4 BYE | D11: C2 BYE | E11: C5 BYE | F11: C3 BYE | G11: C1 BYE | I11: DE 2 | J11: 4:00 p.m. - 4:30 p.m.
B12: Room 10 | C12: D1 — D2 | D12: D4— D5 | E12: D2 — D3 | F12: D1 — D5 | G12: D3 — D4 | I12: DE 3 | J12: 4:30 p.m. - 5:00 p.m.
B13: Room 11 | C13: D3 — D5 | D13: D1 — D3 | E13: D1 — D4 | F13: D2 — D4 | G13: D2 — D5 | I13: DE Break | J13: 5:00 p.m. - 5:15 p.m.
... B20: Room 18 | C20: F4 BYE | D20: F2 BYE | E20: F5 BYE | F20: F3 BYE | G20: F1 BYE | I20: DE 9 | J20: 8:00 p.m. - 8:30 p.m.
I21: Closing Ceremony | J21: 8:30 p.m. - 8:45 p.m.

Sheet RR Scores
B2: Group A
B3: =sum(C4:H9)*3/2 -> 2763 | C3: {=TRANSPOSE(B4:B9)} -> Mission San Jose A | D3: BYE | E3: Princeton | F3: Basis Silicon Valley | G3: Collierville | H3: Centreville A | I3: Wins | J3: Ties | K3: Losses | L3: Points | M3: PPG | N3: RR Score * 5/4
B4: Mission San Jose A | E4: 184 | F4: 166 | G4: 146 | H4: 134 | I4: =COUNTIF(K68:P68, 1) -> 4 | J4: 0 | K4: =COUNTIF(K68:P68, 0) -> 0 | L4: =I4+0.5*J4 -> 4 | M4: =AVERAGE(C4:H4) -> 157.5 | N4: =(L4*500+M4*2*B3/(IF(AVERAGE($B$3, $B$12, $B$21, $B$30, $B$39, $B$48)=0, 1, AVERAGE($B$3, $B$12, $B$21, $B$30, $B$39, $B$48))))*5/4 -> 2896.1275
B5: BYE | N5: 0
B6: Princeton | C6: 94 | F6: 34 | G6: 160 | H6: 98 | I6: =COUNTIF(K70:P70, 1) -> 2 | J6: 0 | K6: =COUNTIF(K70:P70, 0) -> 2 | L6: =I6+0.5*J6 -> 2 | M6: =AVERAGE(C6:H6) -> 96.5 | N6: =(L6*500+M6*2*B3/(IF(AVERAGE($B$3, $B$12, $B$21, $B$30, $B$39, $B$48)=0, 1, AVERAGE($B$3, $B$12, $B$21, $B$30, $B$39, $B$48))))*5/4 -> 1492.7067
B7: Basis Silicon Valley | C7: 38 | E7: 176 | G7: 124 | H7: 140 | I7: =COUNTIF(K71:P71, 1) -> 3 | J7: 0 | K7: =COUNTIF(K71:P71, 0) -> 1 | L7: =I7+0.5*J7 -> 3 | M7: =AVERAGE(C7:H7) -> 119.5 | N7: =(L7*500+M7*2*B3/(IF(AVERAGE($B$3, $B$12, $B$21, $B$30, $B$39, $B$48)=0, 1, AVERAGE($B$3, $B$12, $B$21, $B$30, $B$39, $B$48))))*5/4 -> 2175.5539
B8: Collierville | C8: 6 | E8: 12 | F8: 32 | H8: 34 | I8: =COUNTIF(K72:P72, 1) -> 0 | J8: 0 | K8: =COUNTIF(K72:P72, 0) -> 4 | L8: =I8+0.5*J8 -> 0 | M8: =AVERAGE(C8:H8) -> 21 | N8: =(L8*500+M8*2*B3/(IF(AVERAGE($B$3, $B$12, $B$21, $B$30, $B$39, $B$48)=0, 1, AVERAGE($B$3, $B$12, $B$21, $B$30, $B$39, $B$48))))*5/4 -> 52.817004
B9: Centreville A | C9: 46 | E9: 92 | F9: 22 | G9: 104 | I9: =COUNTIF(K73:P73, 1) -> 1 | J9: 0 | K9: =COUNTIF(K73:P73, 0) -> 3 | L9: =I9+0.5*J9 -> 1 | M9: =AVERAGE(C9:H9) -> 66 | N9: =(L9*500+M9*2*B3/(IF(AVERAGE($B$3, $B$12, $B$21, $B$30, $B$39, $B$48)=0, 1, AVERAGE($B$3, $B$12, $B$21, $B$30, $B$39, $B$48))))*5/4 -> 790.9963
B11: Group B
B12: =sum(C13:H18) -> 2876 | C12: {=TRANSPOSE(B13:B18)} -> Enloe | D12: Iolani A | E12: Winston Churchill | F12: North Hollywood | G12: Temple City | H12: Brooklyn Tech B | I12: Wins | J12: Ties | K12: Losses | L12: Points | M12: PPG | N12: RR Score
B13: Enloe | D13: 60 | E13: 200 | F13: 64 | G13: 162 | H13: 158 | I13: =COUNTIF(K77:P77, 1) -> 3 | J13: =COUNTIF(K77:P77, 0.5) -> 0 | K13: =COUNTIF(K77:P77, 0) -> 2 | L13: =I13+0.5*J13 -> 3 | M13: =AVERAGE(C13:H13) -> 128.8 | N13: =L13*500+M13*2*B12/(IF(AVERAGE($B$3, $B$12, $B$21, $B$30, $B$39, $B$48)=0, 1, AVERAGE($B$3, $B$12, $B$21, $B$30, $B$39, $B$48))) -> 1769.7543
B14: Iolani A | C14: 146 | E14: 172 | F14: 100 | G14: 176 | H14: 148 | I14: =COUNTIF(K78:P78, 1) -> 4 | J14: =COUNTIF(K78:P78, 0.5) -> 0 | K14: =COUNTIF(K78:P78, 0) -> 1 | L14: =I14+0.5*J14 -> 4 | M14: =AVERAGE(C14:H14) -> 148.4 | N14: =L14*500+M14*2*B12/(IF(AVERAGE($B$3, $B$12, $B$21, $B$30, $B$39, $B$48)=0, 1, AVERAGE($B$3, $B$12, $B$21, $B$30, $B$39, $B$48))) -> 2310.8038
B15: Winston Churchill | C15: 18 | D15: 54 | F15: 8 | G15: 36 | H15: 48 | I15: =COUNTIF(K79:P79, 1) -> 1 | J15: =COUNTIF(K79:P79, 0.5) -> 0 | K15: =COUNTIF(K79:P79, 0) -> 4 | L15: =I15+0.5*J15 -> 1 | M15: =AVERAGE(C15:H15) -> 32.8 | N15: =L15*500+M15*2*B12/(IF(AVERAGE($B$3, $B$12, $B$21, $B$30, $B$39, $B$48)=0, 1, AVERAGE($B$3, $B$12, $B$21, $B$30, $B$39, $B$48))) -> 568.69518
B16: North Hollywood | C16: 118 | D16: 124 | E16: 194 | G16: 192 | H16: 200 | I16: =COUNTIF(K80:P80, 1) -> 5 | J16: =COUNTIF(K80:P80, 0.5) -> 0 | K16: =COUNTIF(K80:P80, 0) -> 0 | L16: =I16+0.5*J16 -> 5 | M16: =AVERAGE(C16:H16) -> 165.6 | N16: =L16*500+M16*2*B12/(IF(AVERAGE($B$3, $B$12, $B$21, $B$30, $B$39, $B$48)=0, 1, AVERAGE($B$3, $B$12, $B$21, $B$30, $B$39, $B$48))) -> 2846.8269
B17: Temple City | C17: 42 | D17: 62 | E17: 140 | F17: 48 | H17: 82 | I17: =COUNTIF(K81:P81, 1) -> 2 | J17: =COUNTIF(K81:P81, 0.5) -> 0 | K17: =COUNTIF(K81:P81, 0) -> 3 | L17: =I17+0.5*J17 -> 2 | M17: =AVERAGE(C17:H17) -> 74.8 | N17: =L17*500+M17*2*B12/(IF(AVERAGE($B$3, $B$12, $B$21, $B$30, $B$39, $B$48)=0, 1, AVERAGE($B$3, $B$12, $B$21, $B$30, $B$39, $B$48))) -> 1156.6585
B18: Brooklyn Tech B | C18: 8 | D18: 40 | E18: 18 | F18: 18 | G18: 40 | I18: =COUNTIF(K82:P82, 1) -> 0 | J18: =COUNTIF(K82:P82, 0.5) -> 0 | K18: =COUNTIF(K82:P82, 0) -> 5 | L18: =I18+0.5*J18 -> 0 | M18: =AVERAGE(C18:H18) -> 24.8 | N18: =L18*500+M18*2*B12/(IF(AVERAGE($B$3, $B$12, $B$21, $B$30, $B$39, $B$48)=0, 1, AVERAGE($B$3, $B$12, $B$21, $B$30, $B$39, $B$48))) -> 51.940262
B20: Group C
B21: =sum(C22:H27)*3/2 -> 2859 | C21: {=TRANSPOSE(B22:B27)} -> Evergreen | D21: BASIS Chandler A | E21: Montgomery Blair A | F21: Plano West | G21: Canyon Crest B | H21: BYE | I21: Wins | J21: Ties | K21: Losses | L21: Points | M21: PPG | N21: RR Score * 5/4
B22: Evergreen | D22: 62 | E22: 54 | F22: 88 | G22: 88 | H22: 0 | I22: =COUNTIF(K86:P86, 1) -> 1 | J22: =COUNTIF(K86:P86, 0.5) -> 0 | K22: =COUNTIF(K86:P86, 0) -> 3 | L22: =I22+0.5*J22 -> 1 | M22: =AVERAGE(C22:H22) -> 58.4 | N22: =(L22*500+M22*2*B21/(IF(AVERAGE($B$3, $B$12, $B$21, $B$30, $B$39, $B$48)=0, 1, AVERAGE($B$3, $B$12, $B$21, $B$30, $B$39, $B$48))))*5/4 -> 776.98495
B23: BASIS Chandler A | C23: 76 | E23: 30 | F23: 80 | G23: 120 | H23: 0 | I23: =COUNTIF(K87:P87, 1) -> 3 | J23: =COUNTIF(K87:P87, 0.5) -> 0 | K23: =COUNTIF(K87:P87, 0) -> 1 | L23: =I23+0.5*J23 -> 3 | M23: =AVERAGE(C23:H23) -> 61.2 | N23: =(L23*500+M23*2*B21/(IF(AVERAGE($B$3, $B$12, $B$21, $B$30, $B$39, $B$48)=0, 1, AVERAGE($B$3, $B$12, $B$21, $B$30, $B$39, $B$48))))*5/4 -> 2034.2719
B24: Montgomery Blair A | C24: 178 | D24: 236 | F24: 264 | G24: 238 | H24: 0 | I24: =COUNTIF(K88:P88, 1) -> 4 | J24: =COUNTIF(K88:P88, 0.5) -> 0 | K24: =COUNTIF(K88:P88, 0) -> 0 | L24: =I24+0.5*J24 -> 4 | M24: =AVERAGE(C24:H24) -> 183.2 | N24: =(L24*500+M24*2*B21/(IF(AVERAGE($B$3, $B$12, $B$21, $B$30, $B$39, $B$48)=0, 1, AVERAGE($B$3, $B$12, $B$21, $B$30, $B$39, $B$48))))*5/4 -> 2976.7747
B25: Plano West | C25: 96 | D25: 30 | E25: 6 | G25: 86 | H25: 0 | I25: =COUNTIF(K89:P89, 1) -> 2 | J25: =COUNTIF(K89:P89, 0.5) -> 0 | K25: =COUNTIF(K89:P89, 0) -> 2 | L25: =I25+0.5*J25 -> 2 | M25: =AVERAGE(C25:H25) -> 43.6 | N25: =(L25*500+M25*2*B21/(IF(AVERAGE($B$3, $B$12, $B$21, $B$30, $B$39, $B$48)=0, 1, AVERAGE($B$3, $B$12, $B$21, $B$30, $B$39, $B$48))))*5/4 -> 1363.4682
B26: Canyon Crest B | C26: 32 | D26: 26 | E26: 32 | F26: 84 | H26: 0 | I26: =COUNTIF(K90:P90, 1) -> 0 | J26: =COUNTIF(K90:P90, 0.5) -> 0 | K26: =COUNTIF(K90:P90, 0) -> 4 | L26: =I26+0.5*J26 -> 0 | M26: =AVERAGE(C26:H26) -> 34.8 | N26: =(L26*500+M26*2*B21/(IF(AVERAGE($B$3, $B$12, $B$21, $B$30, $B$39, $B$48)=0, 1, AVERAGE($B$3, $B$12, $B$21, $B$30, $B$39, $B$48))))*5/4 -> 90.566374
B27: BYE | C27: 0 | D27: 0 | E27: 0 | F27: 0 | G27: 0 | I27: =COUNTIF(K91:P91, 1) -> 0 | J27: =COUNTIF(K91:P91, 0.5) -> 0 | K27: =COUNTIF(K91:P91, 0) -> 0 | L27: =I27+0.5*J27 -> 0 | N27: =L27*500+M27*2*B21/(IF(AVERAGE($B$3, $B$12, $B$21, $B$30, $B$39, $B$48)=0, 1, AVERAGE($B$3, $B$12, $B$21, $B$30, $B$39, $B$48))) -> 0
B29: Group D
B30: =sum(C31:H36)*3/2 -> 2814 | C30: {=TRANSPOSE(B31:B36)} -> Commonwealth School | D30: Whitney Young | E30: Montgomery Blair B | F30: Canyon Crest A | G30: James Clemens | H30: BYE | I30: Wins | J30: Ties | K30: Losses | L30: Points | M30: PPG | N30: RR Score * 5/4
B31: Commonwealth School | D31: 44 | E31: 40 | F31: 12 | G31: 38 | I31: =COUNTIF(K95:P95, 1) -> 0 | J31: =COUNTIF(K95:P95, 0.5) -> 0 | K31: =COUNTIF(K95:P95, 0) -> 4 | L31: =I31+0.5*J31 -> 0 | M31: =AVERAGE(C31:H31) -> 33.5 | N31: =(L31*500+M31*2*B30/(IF(AVERAGE($B$3, $B$12, $B$21, $B$30, $B$39, $B$48)=0, 1, AVERAGE($B$3, $B$12, $B$21, $B$30, $B$39, $B$48))))*5/4 -> 85.810905
B32: Whitney Young | C32: 112 | E32: 48 | F32: 68 | G32: 36 | I32: =COUNTIF(K96:P96, 1) -> 1 | J32: =COUNTIF(K96:P96, 0.5) -> 0 | K32: =COUNTIF(K96:P96, 0) -> 3 | L32: =I32+0.5*J32 -> 1 | M32: =AVERAGE(C32:H32) -> 66 | N32: =(L32*500+M32*2*B30/(IF(AVERAGE($B$3, $B$12, $B$21, $B$30, $B$39, $B$48)=0, 1, AVERAGE($B$3, $B$12, $B$21, $B$30, $B$39, $B$48))))*5/4 -> 794.06029
B33: Montgomery Blair B | C33: 132 | D33: 184 | F33: 86 | G33: 90 | I33: =COUNTIF(K97:P97, 1) -> 2 | J33: =COUNTIF(K97:P97, 0.5) -> 0 | K33: =COUNTIF(K97:P97, 0) -> 2 | L33: =I33+0.5*J33 -> 2 | M33: =AVERAGE(C33:H33) -> 123 | N33: =(L33*500+M33*2*B30/(IF(AVERAGE($B$3, $B$12, $B$21, $B$30, $B$39, $B$48)=0, 1, AVERAGE($B$3, $B$12, $B$21, $B$30, $B$39, $B$48))))*5/4 -> 1565.0669
B34: Canyon Crest A | C34: 148 | D34: 98 | E34: 110 | G34: 62 | I34: =COUNTIF(K98:P98, 1) -> 3 | J34: =COUNTIF(K98:P98, 0.5) -> 0 | K34: =COUNTIF(K98:P98, 0) -> 1 | L34: =I34+0.5*J34 -> 3 | M34: =AVERAGE(C34:H34) -> 104.5 | N34: =(L34*500+M34*2*B30/(IF(AVERAGE($B$3, $B$12, $B$21, $B$30, $B$39, $B$48)=0, 1, AVERAGE($B$3, $B$12, $B$21, $B$30, $B$39, $B$48))))*5/4 -> 2142.6788
B35: James Clemens | C35: 150 | D35: 168 | E35: 116 | F35: 134 | I35: =COUNTIF(K99:P99, 1) -> 4 | J35: =COUNTIF(K99:P99, 0.5) -> 0 | K35: =COUNTIF(K99:P99, 0) -> 0 | L35: =I35+0.5*J35 -> 4 | M35: =AVERAGE(C35:H35) -> 142 | N35: =(L35*500+M35*2*B30/(IF(AVERAGE($B$3, $B$12, $B$21, $B$30, $B$39, $B$48)=0, 1, AVERAGE($B$3, $B$12, $B$21, $B$30, $B$39, $B$48))))*5/4 -> 2863.7358
B36: BYE
B38: Group E
B39: =sum(C40:H45) -> 2716.5 | C39: {=TRANSPOSE(B40:B45)} -> Mission San Jose B | D39: School of Biology | E39: Brooklyn Tech A | F39: Saratoga | G39: WWPS A | H39: ASFA | I39: Wins | J39: Ties | K39: Losses | L39: Points | M39: PPG | N39: RR Score
B40: Mission San Jose B | D40: 54 | E40: 84 | F40: 60 | G40: 74 | H40: -2 | I40: 3 | J40: 0 | K40: 2 | L40: =I40+0.5*J40 -> 3 | M40: =AVERAGE(C40:H40) -> 54 | N40: =L40*500+M40*2*B39/(IF(AVERAGE($B$3, $B$12, $B$21, $B$30, $B$39, $B$48)=0, 1, AVERAGE($B$3, $B$12, $B$21, $B$30, $B$39, $B$48))) -> 1606.8236
B41: School of Biology | C41: 130.5 | E41: 152 | F41: 118 | G41: 168 | H41: 84 | I41: 3 | J41: 0 | K41: 2 | L41: =I41+0.5*J41 -> 3 | M41: =AVERAGE(C41:H41) -> 130.5 | N41: =L41*500+M41*2*B39/(IF(AVERAGE($B$3, $B$12, $B$21, $B$30, $B$39, $B$48)=0, 1, AVERAGE($B$3, $B$12, $B$21, $B$30, $B$39, $B$48))) -> 1758.1569
B42: Brooklyn Tech A | C42: 76 | D42: 60 | F42: 64 | G42: 28 | H42: 100 | I42: 1 | J42: 0 | K42: 4 | L42: =I42+0.5*J42 -> 1 | M42: =AVERAGE(C42:H42) -> 65.6 | N42: =L42*500+M42*2*B39/(IF(AVERAGE($B$3, $B$12, $B$21, $B$30, $B$39, $B$48)=0, 1, AVERAGE($B$3, $B$12, $B$21, $B$30, $B$39, $B$48))) -> 629.77084
B43: Saratoga | C43: 118 | D43: 54 | E43: 114 | G43: 148 | H43: 52 | I43: 3 | J43: 0 | K43: 2 | L43: =I43+0.5*J43 -> 3 | M43: =AVERAGE(C43:H43) -> 97.2 | N43: =L43*500+M43*2*B39/(IF(AVERAGE($B$3, $B$12, $B$21, $B$30, $B$39, $B$48)=0, 1, AVERAGE($B$3, $B$12, $B$21, $B$30, $B$39, $B$48))) -> 1692.2824
B44: WWPS A | C44: 66 | D44: 98 | E44: 146 | F44: 60 | H44: 110 | I44: 2 | J44: 0 | K44: 3 | L44: =I44+0.5*J44 -> 2 | M44: =AVERAGE(C44:H44) -> 96 | N44: =L44*500+M44*2*B39/(IF(AVERAGE($B$3, $B$12, $B$21, $B$30, $B$39, $B$48)=0, 1, AVERAGE($B$3, $B$12, $B$21, $B$30, $B$39, $B$48))) -> 1189.9085
B45: ASFA | C45: 128 | D45: 134 | E45: 38 | F45: 100 | G45: 100 | I45: 3 | J45: 0 | K45: 2 | L45: =I45+0.5*J45 -> 3 | M45: =AVERAGE(C45:H45) -> 100 | N45: =L45*500+M45*2*B39/(IF(AVERAGE($B$3, $B$12, $B$21, $B$30, $B$39, $B$48)=0, 1, AVERAGE($B$3, $B$12, $B$21, $B$30, $B$39, $B$48))) -> 1697.8214
...

Sheet DE Seeding
B2: Team | C2: RR Score | E2: Team | F2: RR Score | G2: DE Seed
B3: ='RR Scores'!B4 -> Mission San Jose A | C3: ='RR Scores'!N4 -> 2896.1275 | E3: {=SORT(B3:C38, 2, FALSE)} -> Montgomery Blair A | F3: 2976.7747 | G3: 1
B4: ='RR Scores'!B5 -> BYE | C4: ='RR Scores'!N5 -> 0 | E4: Mission San Jose A | F4: 2896.1275 | G4: =1+G3 -> 2
B5: ='RR Scores'!B6 -> Princeton | C5: ='RR Scores'!N6 -> 1492.7067 | E5: James Clemens | F5: 2863.7358 | G5: =1+G4 -> 3
B6: ='RR Scores'!B7 -> Basis Silicon Valley | C6: ='RR Scores'!N7 -> 2175.5539 | E6: North Hollywood | F6: 2846.8269 | G6: =1+G5 -> 4
B7: ='RR Scores'!B8 -> Collierville | C7: ='RR Scores'!N8 -> 52.817004 | E7: Lakeside | F7: 2844.9343 | G7: =1+G6 -> 5
B8: ='RR Scores'!B9 -> Centreville A | C8: ='RR Scores'!N9 -> 790.9963 | E8: Iolani A | F8: 2310.8038 | G8: =1+G7 -> 6
B9: ='RR Scores'!B13 -> Enloe | C9: ='RR Scores'!N13 -> 1769.7543 | E9: Basis Silicon Valley | F9: 2175.5539 | G9: =1+G8 -> 7
B10: ='RR Scores'!B14 -> Iolani A | C10: ='RR Scores'!N14 -> 2310.8038 | E10: Canyon Crest A | F10: 2142.6788 | G10: =1+G9 -> 8
B11: ='RR Scores'!B15 -> Winston Churchill | C11: ='RR Scores'!N15 -> 568.69518 | E11: Palo Alto | F11: 2111.3989 | G11: =1+G10 -> 9
B12: ='RR Scores'!B16 -> North Hollywood | C12: ='RR Scores'!N16 -> 2846.8269 | E12: BASIS Chandler A | F12: 2034.2719 | G12: =1+G11 -> 10
B13: ='RR Scores'!B17 -> Temple City | C13: ='RR Scores'!N17 -> 1156.6585 | E13: Enloe | F13: 1769.7543 | G13: =1+G12 -> 11
B14: ='RR Scores'!B18 -> Brooklyn Tech B | C14: ='RR Scores'!N18 -> 51.940262 | E14: School of Biology | F14: 1758.1569 | G14: =1+G13 -> 12
B15: ='RR Scores'!B22 -> Evergreen | C15: ='RR Scores'!N22 -> 776.98495 | E15: ASFA | F15: 1697.8214 | G15: =1+G14 -> 13
B16: ='RR Scores'!B23 -> BASIS Chandler A | C16: ='RR Scores'!N23 -> 2034.2719 | E16: Saratoga | F16: 1692.2824 | G16: =1+G15 -> 14
B17: ='RR Scores'!B24 -> Montgomery Blair A | C17: ='RR Scores'!N24 -> 2976.7747 | E17: Mission San Jose B | F17: 1606.8236 | G17: =1+G16 -> 15
B18: ='RR Scores'!B25 -> Plano West | C18: ='RR Scores'!N25 -> 1363.4682 | E18: Montgomery Blair B | F18: 1565.0669 | G18: =1+G17 -> 16
B19: ='RR Scores'!B26 -> Canyon Crest B | C19: ='RR Scores'!N26 -> 90.566374 | E19: Princeton | F19: 1492.7067
B20: ='RR Scores'!B27 -> BYE | C20: ='RR Scores'!N27 -> 0 | E20: Wayzata | F20: 1459.6368
B21: ='RR Scores'!B31 -> Commonwealth School | C21: ='RR Scores'!N31 -> 85.810905 | E21: Plano West | F21: 1363.4682
B22: ='RR Scores'!B32 -> Whitney Young | C22: ='RR Scores'!N32 -> 794.06029 | E22: WWPS A | F22: 1189.9085
B23: ='RR Scores'!B33 -> Montgomery Blair B | C23: ='RR Scores'!N33 -> 1565.0669 | E23: Temple City | F23: 1156.6585
B24: ='RR Scores'!B34 -> Canyon Crest A | C24: ='RR Scores'!N34 -> 2142.6788 | E24: Whitney Young | F24: 794.06029
B25: ='RR Scores'!B35 -> James Clemens | C25: ='RR Scores'!N35 -> 2863.7358 | E25: Centreville A | F25: 790.9963
B26: ='RR Scores'!B36 -> BYE | C26: ='RR Scores'!N36 | E26: Evergreen | F26: 776.98495
B27: ='RR Scores'!B40 -> Mission San Jose B | C27: ='RR Scores'!N40 -> 1606.8236 | E27: Iolani B | F27: 702.31286
B28: ='RR Scores'!B41 -> School of Biology | C28: ='RR Scores'!N41 -> 1758.1569 | E28: Brooklyn Tech A | F28: 629.77084
B29: ='RR Scores'!B42 -> Brooklyn Tech A | C29: ='RR Scores'!N42 -> 629.77084 | E29: Winston Churchill | F29: 568.69518
B30: ='RR Scores'!B43 -> Saratoga | C30: ='RR Scores'!N43 -> 1692.2824 | E30: Canyon Crest B | F30: 90.566374
B31: ='RR Scores'!B44 -> WWPS A | C31: ='RR Scores'!N44 -> 1189.9085 | E31: Commonwealth School | F31: 85.810905
B32: ='RR Scores'!B45 -> ASFA | C32: ='RR Scores'!N45 -> 1697.8214 | E32: Collierville | F32: 52.817004
B33: ='RR Scores'!B49 -> Lakeside | C33: ='RR Scores'!N49 -> 2844.9343 | E33: Brooklyn Tech B | F33: 51.940262
B34: ='RR Scores'!B50 -> Iolani B | C34: ='RR Scores'!N50 -> 702.31286 | E34: East Brunswick | F34: 42.373396
B35: ='RR Scores'!B51 -> Wayzata | C35: ='RR Scores'!N51 -> 1459.6368 | E35: BYE | F35: 0
B36: ='RR Scores'!B52 -> Palo Alto | C36: ='RR Scores'!N52 -> 2111.3989 | E36: BYE | F36: 0
B37: ='RR Scores'!B53 -> East Brunswick | C37: ='RR Scores'!N53 -> 42.373396 | E37: BYE
B38: ='RR Scores'!B54 -> BYE | C38: ='RR Scores'!N54 | E38: BYE

Sheet DE Bracket
A1: DE 1 | C1: DE 2 | E1: DE 3 | G1: DE 4 | I1: DE 5 | K1: DE 6 | M1: DE 7 | O1: DE 8, 9
A3: Montgomery Blair A | B3: 176 | R3: Results
A4: G1 - Room DE A | C4: Montgomery Blair A | D4: 124 | R4: Montgomery Blair A | S4: 1st
A5: Montgomery Blair B | B5: 40 | R5: Lakeside | S5: 2nd
C6: G9 - Room DE A | E6: BYE | G6: Montgomery Blair A | H6: 152 | R6: Mission San Jose A | S6: 3rd
A7: Canyon Crest A | B7: 60 | R7: Basis Silicon Valley | S7: 4th
A8: G2 - Room DE B | C8: Palo Alto | D8: 48
A9: Palo Alto | B9: 68
G10: G21 - Room DE A | I10: BYE | K10: Montgomery Blair A | L10: 106
A11: North Hollywood | B11: 68
A12: G3 - Room DE C | C12: North Hollywood | D12: 80
A13: ASFA | B13: 16
C14: G10 - Room DE B | E14: BYE | G14: Lakeside | H14: 24
A15: Lakeside | B15: 108
A16: G4 - Room DE D | C16: Lakeside | D16: 84
A17: School of Biology | B17: 62 | G17: E
K18: G27 - Finals Stage 1 | M18: BYE | O18: Montgomery Blair A | P18: 102
A19: Iolani A | B19: 104
A20: G5 - Room DE E | C20: Iolani A | D20: 94
A21: Enloe | B21: 44
C22: G11 - Room DE C | E22: BYE | G22: Basis Silicon Valley | H22: 18
A23: Basis Silicon Valley | B23: 56
A24: G6 - Room DE F | C24: Basis Silicon Valley | D24: 104
A25: Basis Chandler A | B25: 46
G26: G22 - Room DE B | I26: BYE | K26: Mission San Jose A | L26: 30
A27: James Clemens | B27: 62
A28: G7 - Room DE G | C28: Saratoga | D28: 70
A29: Saratoga | B29: 70 | O29: G30,31 - Finals Stage 1 | R29: Montgomery Blair A
C30: G12 - Room DE D | E30: BYE | G30: Mission San Jose A | H30: 50 | M30: Mission San Jose A | N30: 64 | R30: champion
A31: Mission San Jose A | B31: 126
A32: G8 - Room DE H | C32: Mission San Jose A | D32: 122
A33: Mission San Jose B | B33: 16
I34: Lakeside | J34: 64
E36: Saratoga | F36: 44
E38: G17 - Room DE E | G38: Canyon Crest A | H38: 54 | I38: G25 - Finals Stage 1 | K38: Lakeside | L38: 94 | M38: G29 - Finals Stage 1 | O38: Lakeside | P38: 42
C39: Montgomery Blair B | D39: 88
C40: G13 - Room DE E | E40: Canyon Crest A | F40: 68
C41: Canyon Crest A | D41: 90
G42: G23 - Room DE C | I42: School of Biology | J42: 62
E44: Iolani A | F44: 70
...
