Workbook

Sheet Catstat Hub
A1: RR | E1: DE
A4: Round Robin Team Overall | C4: Round Robin Individual Overall | E4: Double Elimination Team Overall | G4: Double Elimination Individual Overall
A6: Round Robin Team Biology | C6: Round Robin Individual Biology | E6: Double Elimination Team Biology | G6: Double Elimination Individual Biology
A7: Round Robin Team Chemistry | C7: Round Robin Individual Chemistry | E7: Double Elimination Team Chemistry | G7: Double Elimination Individual Chemistry
A8: Round Robin Team Physics | C8: Round Robin Individual Physics | E8: Double Elimination Team Physics | G8: Double Elimination Individual Physics
A9: Round Robin Team Math | C9: Round Robin Individual Math | E9: Double Elimination Team Math | G9: Double Elimination Individual Math
A10: Round Robin Team ESS | C10: Round Robin Individual ESS | E10: Double Elimination Team ESS | G10: Double Elimination Individual ESS
A11: Round Robin Team Energy | C11: Round Robin Individual Energy | E11: Double Elimination Team Energy | G11: Double Elimination Individual Energy
B15: use the hyperlink on the top left of each of these sheets to come back to the hub

Sheet Playoff Seeding
B1: Team Rank | C1: Team Name | D1: League Points | E1: Raw Points | G1: Round Scores (in no particular order)
B2: 10 | C2: WWPS 1 | D2: 8 | E2: =sum(G2:M2) -> #REF! | G2: ='Playoff Scoring'!D11 -> #REF! | H2: ='Playoff Scoring'!E11 -> #REF! | I2: ='Playoff Scoring'!F11 -> #REF! | J2: ='Playoff Scoring'!H11 -> #REF! | K2: ='Playoff Scoring'!I11 -> #REF!
B3: 15 | C3: Palo Alto | D3: 6 | E3: =sum(G3:M3) -> #REF! | G3: ='Playoff Scoring'!D9 -> #REF! | H3: ='Playoff Scoring'!F9 -> #REF! | I3: ='Playoff Scoring'!G9 -> #REF! | J3: ='Playoff Scoring'!H9 -> #REF! | K3: ='Playoff Scoring'!I9 -> #REF!
B4: 18 | C4: Saratoga | D4: 6 | E4: =sum(G4:M4) -> #REF! | G4: ='Playoff Scoring'!D12 -> #REF! | H4: ='Playoff Scoring'!E12 -> #REF! | I4: ='Playoff Scoring'!F12 -> #REF! | J4: ='Playoff Scoring'!G12 -> #REF! | K4: ='Playoff Scoring'!I12 -> #REF!
B5: 21 | C5: CCA 2 | D5: 6 | E5: =sum(G5:M5) -> #REF! | G5: ='Playoff Scoring'!D13 -> #REF! | H5: ='Playoff Scoring'!E13 -> #REF! | I5: ='Playoff Scoring'!F13 -> #REF! | J5: ='Playoff Scoring'!G13 -> #REF! | K5: ='Playoff Scoring'!H13 -> #REF!
B6: 30 | C6: Clovis North | D6: 4 | E6: =sum(G6:M6) -> #REF! | G6: ='Playoff Scoring'!$E8 -> #REF! | H6: ='Playoff Scoring'!F8 -> #REF! | I6: ='Playoff Scoring'!G8 -> #REF! | J6: ='Playoff Scoring'!H8 -> #REF! | K6: ='Playoff Scoring'!I8 -> #REF!
B7: 44 | C7: Tokay | D7: 0 | E7: =sum(G7:M7) -> #REF! | G7: ='Playoff Scoring'!D10 -> #REF! | H7: ='Playoff Scoring'!E10 -> #REF! | I7: ='Playoff Scoring'!G10 -> #REF! | J7: ='Playoff Scoring'!H10 -> #REF! | K7: ='Playoff Scoring'!I10 -> #REF!
B8: 3 | C8: Middleton 1 | D8: 10 | E8: =sum(G8:M8) -> #REF! | G8: ='Playoff Scoring'!L10 -> #REF! | H8: ='Playoff Scoring'!M10 -> #REF! | I8: ='Playoff Scoring'!O10 -> #REF! | J8: ='Playoff Scoring'!P10 -> #REF! | K8: ='Playoff Scoring'!Q10 -> #REF!
B9: 11 | C9: TJHSST 1 | D9: 8 | E9: =sum(G9:M9) -> #REF! | G9: ='Playoff Scoring'!L12 -> #REF! | H9: ='Playoff Scoring'!M12 -> #REF! | I9: ='Playoff Scoring'!N12 -> #REF! | J9: ='Playoff Scoring'!O12 -> #REF! | K9: ='Playoff Scoring'!Q12 -> #REF!
B10: 22 | C10: ASFA | D10: 6 | E10: =sum(G10:M10) -> #REF! | G10: ='Playoff Scoring'!L9 -> #REF! | H10: ='Playoff Scoring'!N9 -> #REF! | I10: ='Playoff Scoring'!O9 -> #REF! | J10: ='Playoff Scoring'!P9 -> #REF! | K10: ='Playoff Scoring'!Q9 -> #REF!
B11: 34 | C11: California | D11: 4 | E11: =sum(G11:M11) -> #REF! | G11: ='Playoff Scoring'!M8 -> #REF! | H11: ='Playoff Scoring'!N8 -> #REF! | I11: ='Playoff Scoring'!O8 -> #REF! | J11: ='Playoff Scoring'!P8 -> #REF! | K11: ='Playoff Scoring'!Q8 -> #REF!
B12: 37 | C12: Collierville 1 | D12: 2 | E12: =sum(G12:M12) -> #REF! | G12: ='Playoff Scoring'!L11 -> #REF! | H12: ='Playoff Scoring'!M11 -> #REF! | I12: ='Playoff Scoring'!N11 -> #REF! | J12: ='Playoff Scoring'!P11 -> #REF! | K12: ='Playoff Scoring'!Q11 -> #REF!
B13: 46 | C13: Madison West 2 | D13: 0 | E13: =sum(G13:M13) -> #REF! | G13: ='Playoff Scoring'!L13 -> #REF! | H13: ='Playoff Scoring'!M13 -> #REF! | I13: ='Playoff Scoring'!N13 -> #REF! | J13: ='Playoff Scoring'!O13 -> #REF! | K13: ='Playoff Scoring'!P13 -> #REF!
B14: 1 | C14: Montgomery Blair 1 | D14: 10 | E14: =sum(G14:M14) -> #REF! | G14: ='Playoff Scoring'!D22 -> #REF! | H14: ='Playoff Scoring'!E22 -> #REF! | I14: ='Playoff Scoring'!F22 -> #REF! | J14: ='Playoff Scoring'!G22 -> #REF! | K14: ='Playoff Scoring'!H22 -> #REF!
B15: 19 | C15: Arcadia | D15: 6 | E15: =sum(G15:M15) -> #REF! | G15: ='Playoff Scoring'!D20 -> #REF! | H15: ='Playoff Scoring'!E20 -> #REF! | I15: ='Playoff Scoring'!F20 -> #REF! | J15: ='Playoff Scoring'!H20 -> #REF! | K15: ='Playoff Scoring'!I20 -> #REF!
B16: 23 | C16: 'Iolani | D16: 6 | E16: =sum(G16:M16) -> #REF! | G16: ='Playoff Scoring'!$E17 -> #REF! | H16: ='Playoff Scoring'!F17 -> #REF! | I16: ='Playoff Scoring'!G17 -> #REF! | J16: ='Playoff Scoring'!H17 -> #REF! | K16: ='Playoff Scoring'!I17 -> #REF!
B17: 24 | C17: Temple City | D17: 6 | E17: =sum(G17:M17) -> #REF! | G17: ='Playoff Scoring'!D21 -> #REF! | H17: ='Playoff Scoring'!E21 -> #REF! | I17: ='Playoff Scoring'!F21 -> #REF! | J17: ='Playoff Scoring'!G21 -> #REF! | K17: ='Playoff Scoring'!I21 -> #REF!
B18: 39 | C18: Amador Valley | D18: 2 | E18: =sum(G18:M18) -> #REF! | G18: ='Playoff Scoring'!D19 -> #REF! | H18: ='Playoff Scoring'!E19 -> #REF! | I18: ='Playoff Scoring'!G19 -> #REF! | J18: ='Playoff Scoring'!H19 -> #REF! | K18: ='Playoff Scoring'!I19 -> #REF!
B19: 48 | C19: Oak Avenue 2 | D19: 0 | E19: =sum(G19:M19) -> #REF! | G19: ='Playoff Scoring'!D18 -> #REF! | H19: ='Playoff Scoring'!F18 -> #REF! | I19: ='Playoff Scoring'!G18 -> #REF! | J19: ='Playoff Scoring'!H18 -> #REF! | K19: ='Playoff Scoring'!I18 -> #REF!
B20: 6 | C20: Lynbrook 1 | D20: 10 | E20: =sum(G20:M20) -> #REF! | G20: ='Playoff Scoring'!L18 -> #REF! | H20: ='Playoff Scoring'!N18 -> #REF! | I20: ='Playoff Scoring'!O18 -> #REF! | J20: ='Playoff Scoring'!P18 -> #REF! | K20: ='Playoff Scoring'!Q18 -> #REF!
B21: 12 | C21: Foothill | D21: 8 | E21: =sum(G21:M21) -> #REF! | G21: ='Playoff Scoring'!L22 -> #REF! | H21: ='Playoff Scoring'!M22 -> #REF! | I21: ='Playoff Scoring'!N22 -> #REF! | J21: ='Playoff Scoring'!O22 -> #REF! | K21: ='Playoff Scoring'!P22 -> #REF!
B22: 25 | C22: Whitney Young | D22: 6 | E22: =sum(G22:M22) -> #REF! | G22: ='Playoff Scoring'!L20 -> #REF! | H22: ='Playoff Scoring'!M20 -> #REF! | I22: ='Playoff Scoring'!N20 -> #REF! | J22: ='Playoff Scoring'!P20 -> #REF! | K22: ='Playoff Scoring'!Q20 -> #REF!
B23: 31 | C23: Centennial | D23: 4 | E23: =sum(G23:M23) -> #REF! | G23: ='Playoff Scoring'!L21 -> #REF! | H23: ='Playoff Scoring'!M21 -> #REF! | I23: ='Playoff Scoring'!N21 -> #REF! | J23: ='Playoff Scoring'!O21 -> #REF! | K23: ='Playoff Scoring'!Q21 -> #REF!
B24: 38 | C24: Middleton 2 | D24: 2 | E24: =sum(G24:M24) -> #REF! | G24: ='Playoff Scoring'!M17 -> #REF! | H24: ='Playoff Scoring'!N17 -> #REF! | I24: ='Playoff Scoring'!O17 -> #REF! | J24: ='Playoff Scoring'!P17 -> #REF! | K24: ='Playoff Scoring'!Q17 -> #REF!
B25: 47 | C25: Collierville 2 | D25: 0 | E25: =sum(G25:M25) -> #REF! | G25: ='Playoff Scoring'!L19 -> #REF! | H25: ='Playoff Scoring'!M19 -> #REF! | I25: ='Playoff Scoring'!O19 -> #REF! | J25: ='Playoff Scoring'!P19 -> #REF! | K25: ='Playoff Scoring'!Q19 -> #REF!
B26: 7 | C26: MSJ 1 | D26: 8 | E26: =sum(G26:M26) -> #REF! | G26: ='Playoff Scoring'!D29 -> #REF! | H26: ='Playoff Scoring'!E29 -> #REF! | I26: ='Playoff Scoring'!F29 -> #REF! | J26: ='Playoff Scoring'!H29 -> #REF! | K26: ='Playoff Scoring'!I29 -> #REF!
B27: 14 | C27: Lynbrook 2 | D27: 8 | E27: =sum(G27:M27) -> #REF! | G27: ='Playoff Scoring'!D27 -> #REF! | H27: ='Playoff Scoring'!F27 -> #REF! | I27: ='Playoff Scoring'!G27 -> #REF! | J27: ='Playoff Scoring'!H27 -> #REF! | K27: ='Playoff Scoring'!I27 -> #REF!
B28: 20 | C28: Princeton Unified | D28: 6 | E28: =sum(G28:M28) -> #REF! | G28: ='Playoff Scoring'!D30 -> #REF! | H28: ='Playoff Scoring'!E30 -> #REF! | I28: ='Playoff Scoring'!F30 -> #REF! | J28: ='Playoff Scoring'!G30 -> #REF! | K28: ='Playoff Scoring'!I30 -> #REF!
B29: 27 | C29: Frazer 1 | D29: 4 | E29: =sum(G29:M29) -> #REF! | G29: ='Playoff Scoring'!D28 -> #REF! | H29: ='Playoff Scoring'!E28 -> #REF! | I29: ='Playoff Scoring'!G28 -> #REF! | J29: ='Playoff Scoring'!H28 -> #REF! | K29: ='Playoff Scoring'!I28 -> #REF!
B30: 32 | C30: Montgomery Blair 2 | D30: 4 | E30: =sum(G30:M30) -> #REF! | G30: ='Playoff Scoring'!D31 -> #REF! | H30: ='Playoff Scoring'!E31 -> #REF! | I30: ='Playoff Scoring'!F31 -> #REF! | J30: ='Playoff Scoring'!G31 -> #REF! | K30: ='Playoff Scoring'!H31 -> #REF!
B31: 42 | C31: Stuyvesant | D31: 0 | E31: =sum(G31:M31) -> #REF! | G31: ='Playoff Scoring'!$E26 -> #REF! | H31: ='Playoff Scoring'!F26 -> #REF! | I31: ='Playoff Scoring'!G26 -> #REF! | J31: ='Playoff Scoring'!H26 -> #REF! | K31: ='Playoff Scoring'!I26 -> #REF!
B32: 4 | C32: Wayzata | D32: 10 | E32: =sum(G32:M32) -> #REF! | G32: ='Playoff Scoring'!L28 -> #REF! | H32: ='Playoff Scoring'!M28 -> #REF! | I32: ='Playoff Scoring'!O28 -> #REF! | J32: ='Playoff Scoring'!P28 -> #REF! | K32: ='Playoff Scoring'!Q28 -> #REF!
B33: 9 | C33: CCA 1 | D33: 8 | E33: =sum(G33:M33) -> #REF! | G33: ='Playoff Scoring'!M26 -> #REF! | H33: ='Playoff Scoring'!N26 -> #REF! | I33: ='Playoff Scoring'!O26 -> #REF! | J33: ='Playoff Scoring'!P26 -> #REF! | K33: ='Playoff Scoring'!Q26 -> #REF!
B34: 28 | C34: Granada Hills | D34: 4 | E34: =sum(G34:M34) -> #REF! | G34: ='Playoff Scoring'!L31 -> #REF! | H34: ='Playoff Scoring'!M31 -> #REF! | I34: ='Playoff Scoring'!N31 -> #REF! | J34: ='Playoff Scoring'!O31 -> #REF! | K34: ='Playoff Scoring'!P31 -> #REF!
B35: 29 | C35: Harvard Westlake | D35: 4 | E35: =sum(G35:M35) -> #REF! | G35: ='Playoff Scoring'!L29 -> #REF! | H35: ='Playoff Scoring'!M29 -> #REF! | I35: ='Playoff Scoring'!N29 -> #REF! | J35: ='Playoff Scoring'!P29 -> #REF! | K35: ='Playoff Scoring'!Q29 -> #REF!
B36: 35 | C36: Frazer 2 | D36: 2 | E36: =sum(G36:M36) -> #REF! | G36: ='Playoff Scoring'!L27 -> #REF! | H36: ='Playoff Scoring'!N27 -> #REF! | I36: ='Playoff Scoring'!O27 -> #REF! | J36: ='Playoff Scoring'!P27 -> #REF! | K36: ='Playoff Scoring'!Q27 -> #REF!
B37: 40 | C37: Hunter College | D37: 2 | E37: =sum(G37:M37) -> #REF! | G37: ='Playoff Scoring'!L30 -> #REF! | H37: ='Playoff Scoring'!M30 -> #REF! | I37: ='Playoff Scoring'!N30 -> #REF! | J37: ='Playoff Scoring'!O30 -> #REF! | K37: ='Playoff Scoring'!Q30 -> #REF!
B38: 2 | C38: Clements | D38: 10 | E38: =sum(G38:M38) -> #REF! | G38: =#REF! -> #REF! | H38: =#REF! -> #REF! | I38: =#REF! -> #REF! | J38: =#REF! -> #REF! | K38: =#REF! -> #REF!
B39: 13 | C39: MSJ 2 | D39: 8 | E39: =sum(G39:M39) -> #REF! | G39: =#REF! -> #REF! | H39: =#REF! -> #REF! | I39: =#REF! -> #REF! | J39: =#REF! -> #REF! | K39: =#REF! -> #REF!
B40: 17 | C40: WWPN | D40: 6 | E40: =sum(G40:M40) -> #REF! | G40: =#REF! -> #REF! | H40: =#REF! -> #REF! | I40: =#REF! -> #REF! | J40: =#REF! -> #REF! | K40: =#REF! -> #REF!
...

Sheet Double Elimination Bracket
B1: DE1 | E1: DE2 | G1: DE3 | J1: DE4 | L1: DE5 | N1: DE6 | P1: FINALS BO3
B2: 12:40-13:15 PT | E2: 13:15-13:50 PT | G2: 13:50-14:25 PT | J2: 14:45-15:15 PT | L2: 15:15-15:45 PT | N2: 15:45-16:15 PT | P2: 16:15-17:15 PT | S2: 1st: | T2: Montgomery Blair 1
S3: 2nd: | T3: MSJ 1
A4: 1 | B4: Montgomery Blair 1 | C4: 98 | S4: 3rd: | T4: TJHSST 2
A5: AlbatrosInterlake | G5: Lexington | H5: 10 | S5: 4th: | T5: Lexington
A6: 8 | B6: Lexington | C6: 110 | S6: 5-6th: | T6: Clements, Middleton 1
G7: AlbatrosInterlake | L7: TJHSST 2 | M7: 40
A8: 4 | B8: Wayzata | C8: 46
A9: AlbatrosWinston Churchill | G9: TJHSST 2 | H9: 44
A10: 5 | B10: TJHSST 2 | C10: 100
L11: Cornelia Street | P11: MSJ 1 | Q11: 6 | R11: -8
A12: 2 | B12: Clements | C12: 48 | U12: Mods | V12: 52.81
A13: BottlWayzata | G13: MSJ 1 | H13: 102
A14: 7 | B14: MSJ 1 | C14: 122 | W14: Anurag S
G15: AlbatrosWinston Churchill | L15: MSJ 1 | M15: 104
A16: 3 | B16: Middleton 1 | C16: 128 | P16: Cornelia Street | T16: Montgomery Blair 1 | V16: 31
A17: BottlDulles | G17: Middleton 1 | H17: 24 | M17: LEvergreen | N17: TJHSST 2 | O17: 26
A18: 6 | B18: Lynbrook 1 | C18: 62
I19: LMission San Jose A | J19: Lexington | K19: 96
D20: LIolani A | E20: Lynbrook 1 | F20: 98
A21: 9 | B21: CCA 1 | C21: 78 | E21: BottlWayzata | G21: Lynbrook 1 | H21: 60 | J21: Cornelia Street | L21: Lexington | M21: 54 | N21: Cornelia Street | P21: Montgomery Blair 1 | Q21: 18 | R21: 22
A22: ChampagnWayzata | E22: Ward Melville | F22: 34
A23: 16 | B23: Ward Melville | C23: 102 | G23: ChampagnWayzata | J23: Clements | K23: 62
D24: LEnloe | E24: Clements | F24: 74
A25: 12 | B25: Foothill | C25: 18 | E25: BottlDulles | G25: Clements | H25: 68 | L25: Scott Street | N25: Montgomery Blair 1 | O25: 98
A26: ChampagnDulles | E26: MSJ 2 | F26: 28
A27: 13 | B27: MSJ 2 | C27: 50 | I27: LA-2 | J27: Middleton 1 | K27: 66
D28: LA-2 | E28: Wayzata | F28: 52
A29: 10 | B29: WWPS 1 | C29: 60 | E29: ChampagnWayzata | G29: Palo Alto | H29: 26 | J29: Scott Street | L29: Montgomery Blair 1 | M29: 94
A30: Daylight-1 | E30: Palo Alto | F30: 136
A31: 15 | B31: Palo Alto | C31: 86 | G31: ChampagnDulles | J31: Montgomery Blair 1 | K31: 96
D32: LMission San Jose A | E32: Montgomery Blair 1 | F32: 150
A33: 11 | B33: TJHSST 1 | C33: 50 | E33: ChampagnDulles | G33: Montgomery Blair 1 | H33: 90
A34: Daylight-2 | E34: Lynbrook 2 | F34: 10
A35: 14 | B35: Lynbrook 2 | C35: 80

Sheet Round Robin Individual Overall
A1: Catstats Hub | B1: gamesPlayed | C1: tuh | D1: buzzes | E1: ppg | F1: PP4TUH | G1: npg | H1: Total Negs | I1: accuracy
A2: rohan g [School of Biology] | B2: 4 | C2: 92 | D2: 68 | E2: 38 | F2: =E2*B2*23/C2 -> 38 | G2: 2.75 | H2: =G2*B2 -> 11 | I2: 0.721
A3: kaiwen y [Enloe] | B3: 5 | C3: 114 | D3: 41 | E3: 28.8 | F3: =E3*B3*23/C3 -> 29.052632 | G3: 0 | H3: =G3*B3 -> 0 | I3: 0.878
A4: lucas q [Basis Silicon Valley] | B4: 4 | C4: 92 | D4: 47 | E4: 28 | F4: =E4*B4*23/C4 -> 28 | G4: 0.75 | H4: =G4*B4 -> 3 | I4: 0.66
A5: vishnu m [Lakeside] | B5: 3 | C5: 69 | D5: 27 | E5: 28 | F5: =E5*B5*23/C5 -> 28 | G5: 0.33 | H5: =G5*B5 -> 0.99 | I5: 0.815
A6: skyler m [Saratoga] | B6: 1 | C6: 23 | D6: 10 | E6: 28 | F6: =E6*B6*23/C6 -> 28 | G6: 1 | H6: =G6*B6 -> 1 | I6: 0.8
A7: suzuko o [North Hollywood] | B7: 5 | C7: 115 | D7: 48 | E7: 27.2 | F7: =E7*B7*23/C7 -> 27.2 | G7: 1 | H7: =G7*B7 -> 5 | I7: 0.813
A8: yunyi l [Blair A] | B8: 4 | C8: 92 | D8: 26 | E8: 26 | F8: =E8*B8*23/C8 -> 26 | G8: 0 | H8: =G8*B8 -> 0 | I8: 1
A9: daniel l [Iolani A] | B9: 5 | C9: 115 | D9: 47 | E9: 25.6 | F9: =E9*B9*23/C9 -> 25.6 | G9: 1.2 | H9: =G9*B9 -> 6 | I9: 0.809
A10: forrest c [Palo Alto] | B10: 4 | C10: 92 | D10: 59 | E10: 25 | F10: =E10*B10*23/C10 -> 25 | G10: 3.5 | H10: =G10*B10 -> 14 | I10: 0.661
A11: neyan s [James Clemens] | B11: 4 | C11: 92 | D11: 38 | E11: 23 | F11: =E11*B11*23/C11 -> 23 | G11: 1.5 | H11: =G11*B11 -> 6 | I11: 0.763
A12: daniel y [Iolani B] | B12: 3 | C12: 69 | D12: 44 | E12: 21.33 | F12: =E12*B12*23/C12 -> 21.33 | G12: 1.33 | H12: =G12*B12 -> 3.99 | I12: 0.455
A13: akhil b [ASFA] | B13: 5 | C13: 115 | D13: 47 | E13: 20.8 | F13: =E13*B13*23/C13 -> 20.8 | G13: 1.2 | H13: =G13*B13 -> 6 | I13: 0.681
... A126: lucas k [Blair B] | B126: 1 | C126: 23 | D126: 1 | E126: -4 | F126: =E126*B126*23/C126 -> -4 | G126: 1 | H126: =G126*B126 -> 1 | I126: 0

Sheet Round Robin Individual Biology
A1: Catstats Hub | B1: gamesPlayed | C1: tuh | D1: buzzes | E1: ppg | F1: PP4TUH | G1: npg | H1: Total Negs | I1: accuracy
A2: theenash s [Mission San Jose A] | B2: 4 | C2: 16 | D2: 16 | E2: 12 | F2: =E2*B2*4/C2 -> 12 | G2: 0.5 | H2: =G2*B2 -> 2 | I2: 0.875
A3: larry z [Basis Silicon Valley] | B3: 4 | C3: 16 | D3: 12 | E3: 10 | F3: =E3*B3*4/C3 -> 10 | G3: 0.25 | H3: =G3*B3 -> 1 | I3: 0.917
A4: kian d [Blair A] | B4: 4 | C4: 16 | D4: 10 | E4: 10 | F4: =E4*B4*4/C4 -> 10 | G4: 0 | H4: =G4*B4 -> 0 | I4: 1
A5: suzuko o [North Hollywood] | B5: 5 | C5: 20 | D5: 16 | E5: 9.6 | F5: =E5*B5*4/C5 -> 9.6 | G5: 0.2 | H5: =G5*B5 -> 1 | I5: 0.813
A6: adi p [Princeton] | B6: 3 | C6: 12 | D6: 8 | E6: 8 | F6: =E6*B6*4/C6 -> 8 | G6: 0 | H6: =G6*B6 -> 0 | I6: 0.75
A7: sean y [Canyon Crest A] | B7: 4 | C7: 16 | D7: 10 | E7: 8 | F7: =E7*B7*4/C7 -> 8 | G7: 0.25 | H7: =G7*B7 -> 1 | I7: 0.9
A8: vishnu m [Lakeside] | B8: 3 | C8: 12 | D8: 7 | E8: 8 | F8: =E8*B8*4/C8 -> 8 | G8: 0 | H8: =G8*B8 -> 0 | I8: 0.857
A9: meghna s [Blair B] | B9: 4 | C9: 16 | D9: 10 | E9: 7 | F9: =E9*B9*4/C9 -> 7 | G9: 0.25 | H9: =G9*B9 -> 1 | I9: 0.8
A10: arjun d [WWPS] | B10: 5 | C10: 20 | D10: 11 | E10: 6.4 | F10: =E10*B10*4/C10 -> 6.4 | G10: 0 | H10: =G10*B10 -> 0 | I10: 0.727
A11: warren w [Wayzata] | B11: 4 | C11: 16 | D11: 14 | E11: 6 | F11: =E11*B11*4/C11 -> 6 | G11: 0.5 | H11: =G11*B11 -> 2 | I11: 0.571
A12: nihar b [Basis Chandler] | B12: 4 | C12: 16 | D12: 10 | E12: 6 | F12: =E12*B12*4/C12 -> 6 | G12: 0.25 | H12: =G12*B12 -> 1 | I12: 0.7
A13: akhil b [ASFA] | B13: 5 | C13: 20 | D13: 7 | E13: 5.6 | F13: =E13*B13*4/C13 -> 5.6 | G13: 0 | H13: =G13*B13 -> 0 | I13: 1
... A126: kate w [Collierville] | B126: 3 | C126: 12 | D126: 2 | E126: -2.67 | F126: =E126*B126*4/C126 -> -2.67 | G126: 0.67 | H126: =G126*B126 -> 2.01 | I126: 0
A140: Catstats Hub
A141: arjun g [Centreville A]
A142: pritham s [Centreville A]
A143: lucas q [Basis Silicon Valley]
A144: aaron c [Basis Silicon Valley]
A145: larry z [Basis Silicon Valley]
A146: skyler b [ASFA]
A147: akhil b [ASFA]
A148: albert c [ASFA]
A149: advik s [ASFA]
A150: alex g [Saratoga]
A151: warren c [Saratoga]
... A960: skyler m [Saratoga]

Sheet Round Robin Individual Chemistr
A1: Catstats Hub | B1: gamesPlayed | C1: tuh | D1: buzzes | E1: ppg | F1: PP4TUH | G1: npg | H1: Total Negs | I1: accuracy
A2: daniel l [Iolani A] | B2: 5 | C2: 20 | D2: 13 | E2: 10.4 | F2: =E2*B2*4/C2 -> 10.4 | G2: 0 | H2: =G2*B2 -> 0 | I2: 1
A3: connor z [North Hollywood] | B3: 4 | C3: 16 | D3: 16 | E3: 10 | F3: =E3*B3*4/C3 -> 10 | G3: 0.75 | H3: =G3*B3 -> 3 | I3: 0.813
A4: forrest c [Palo Alto] | B4: 4 | C4: 17 | D4: 14 | E4: 10 | F4: =E4*B4*4/C4 -> 9.4117647 | G4: 0.5 | H4: =G4*B4 -> 2 | I4: 0.857
A5: akhil b [ASFA] | B5: 5 | C5: 20 | D5: 12 | E5: 8 | F5: =E5*B5*4/C5 -> 8 | G5: 0 | H5: =G5*B5 -> 0 | I5: 0.833
A6: yunyi l [Blair A] | B6: 4 | C6: 16 | D6: 8 | E6: 8 | F6: =E6*B6*4/C6 -> 8 | G6: 0 | H6: =G6*B6 -> 0 | I6: 1
A7: neyan s [James Clemens] | B7: 4 | C7: 16 | D7: 14 | E7: 8 | F7: =E7*B7*4/C7 -> 8 | G7: 0.75 | H7: =G7*B7 -> 3 | I7: 0.786
A8: rohan g [School of Biology] | B8: 4 | C8: 16 | D8: 11 | E8: 8 | F8: =E8*B8*4/C8 -> 8 | G8: 0.25 | H8: =G8*B8 -> 1 | I8: 0.818
A9: theenash s [Mission San Jose A] | B9: 4 | C9: 16 | D9: 11 | E9: 8 | F9: =E9*B9*4/C9 -> 8 | G9: 0.25 | H9: =G9*B9 -> 1 | I9: 0.818
A10: lucas q [Basis Silicon Valley] | B10: 4 | C10: 16 | D10: 11 | E10: 7 | F10: =E10*B10*4/C10 -> 7 | G10: 0 | H10: =G10*B10 -> 0 | I10: 0.636
A11: pritham s [Centreville A] | B11: 4 | C11: 16 | D11: 9 | E11: 6 | F11: =E11*B11*4/C11 -> 6 | G11: 0 | H11: =G11*B11 -> 0 | I11: 0.667
A12: sophie c [Wayzata] | B12: 4 | C12: 16 | D12: 7 | E12: 6 | F12: =E12*B12*4/C12 -> 6 | G12: 0 | H12: =G12*B12 -> 0 | I12: 0.857
A13: owen m [Canyon Crest B] | B13: 4 | C13: 16 | D13: 8 | E13: 6 | F13: =E13*B13*4/C13 -> 6 | G13: 0.25 | H13: =G13*B13 -> 1 | I13: 0.875
... A126: roshan a [Mission San Jose A] | B126: 4 | C126: 16 | D126: 5 | E126: -1 | F126: =E126*B126*4/C126 -> -1 | G126: 0.75 | H126: =G126*B126 -> 3 | I126: 0.4
A140: Catstats Hub
A141: arjun g [Centreville A]
A142: pritham s [Centreville A]
A143: lucas q [Basis Silicon Valley]
A144: aaron c [Basis Silicon Valley]
A145: larry z [Basis Silicon Valley]
A146: skyler b [ASFA]
A147: akhil b [ASFA]
A148: albert c [ASFA]
A149: advik s [ASFA]
A150: alex g [Saratoga]
A151: warren c [Saratoga]
... A960: skyler m [Saratoga]

Sheet Round Robin Individual Energy
A1: Catstats Hub | B1: gamesPlayed | C1: tuh | D1: buzzes | E1: ppg | F1: PP3TUH | G1: npg | H1: Total Negs | I1: accuracy
A2: skyler m [Saratoga] | B2: 1 | C2: 3 | D2: 2 | E2: 8 | F2: =E2*B2*3/C2 -> 8 | G2: 0 | H2: =G2*B2 -> 0 | I2: 1
A3: lucas q [Basis Silicon Valley] | B3: 4 | C3: 12 | D3: 8 | E3: 7 | F3: =E3*B3*3/C3 -> 7 | G3: 0 | H3: =G3*B3 -> 0 | I3: 0.875
A4: kaiwen y [Enloe] | B4: 5 | C4: 14 | D4: 8 | E4: 6.4 | F4: =E4*B4*3/C4 -> 6.8571429 | G4: 0 | H4: =G4*B4 -> 0 | I4: 1
A5: saahil d [Evergreen] | B5: 4 | C5: 12 | D5: 7 | E5: 6 | F5: =E5*B5*3/C5 -> 6 | G5: 0 | H5: =G5*B5 -> 0 | I5: 0.857
A6: neyan s [James Clemens] | B6: 4 | C6: 12 | D6: 6 | E6: 6 | F6: =E6*B6*3/C6 -> 6 | G6: 0 | H6: =G6*B6 -> 0 | I6: 1
A7: vybhav v [Commonwealth] | B7: 4 | C7: 13 | D7: 5 | E7: 5 | F7: =E7*B7*3/C7 -> 4.6153846 | G7: 0 | H7: =G7*B7 -> 0 | I7: 1
A8: warren w [Wayzata] | B8: 4 | C8: 12 | D8: 4 | E8: 4 | F8: =E8*B8*3/C8 -> 4 | G8: 0 | H8: =G8*B8 -> 0 | I8: 1
A9: adi p [Princeton] | B9: 3 | C9: 9 | D9: 3 | E9: 4 | F9: =E9*B9*3/C9 -> 4 | G9: 0 | H9: =G9*B9 -> 0 | I9: 1
A10: rohan g [School of Biology] | B10: 4 | C10: 12 | D10: 10 | E10: 4 | F10: =E10*B10*3/C10 -> 4 | G10: 0.5 | H10: =G10*B10 -> 2 | I10: 0.6
A11: vishnu m [Lakeside] | B11: 3 | C11: 9 | D11: 3 | E11: 4 | F11: =E11*B11*3/C11 -> 4 | G11: 0 | H11: =G11*B11 -> 0 | I11: 1
A12: evelyn w [Winston Churchill] | B12: 2 | C12: 6 | D12: 2 | E12: 4 | F12: =E12*B12*3/C12 -> 4 | G12: 0 | H12: =G12*B12 -> 0 | I12: 1
A13: meghna s [Blair B] | B13: 4 | C13: 13 | D13: 4 | E13: 4 | F13: =E13*B13*3/C13 -> 3.6923077 | G13: 0 | H13: =G13*B13 -> 0 | I13: 1
... A126: lucas k [Blair B] | B126: 1 | C126: 4 | D126: 1 | E126: -4 | F126: =E126*B126*3/C126 -> -3 | G126: 1 | H126: =G126*B126 -> 1 | I126: 0
A140: Catstats Hub
A141: arjun g [Centreville A]
A142: pritham s [Centreville A]
A143: lucas q [Basis Silicon Valley]
A144: aaron c [Basis Silicon Valley]
A145: larry z [Basis Silicon Valley]
A146: skyler b [ASFA]
A147: akhil b [ASFA]
A148: albert c [ASFA]
A149: advik s [ASFA]
A150: alex g [Saratoga]
A151: warren c [Saratoga]
... A960: skyler m [Saratoga]

Sheet Round Robin Individual ESS
A1: Catstats Hub | B1: gamesPlayed | C1: tuh | D1: buzzes | E1: ppg | F1: PP4TUH | G1: npg | H1: Total Negs | I1: accuracy
A2: akhil b [ASFA] | B2: 5 | C2: 20 | D2: 16 | E2: 8 | F2: =E2*B2*4/C2 -> 8 | G2: 0.2 | H2: =G2*B2 -> 1 | I2: 0.688
A3: varyan j [Basis Chandler] | B3: 4 | C3: 16 | D3: 11 | E3: 8 | F3: =E3*B3*4/C3 -> 8 | G3: 0 | H3: =G3*B3 -> 0 | I3: 0.727
A4: adeeb m [Brooklyn Tech A] | B4: 5 | C4: 20 | D4: 14 | E4: 8 | F4: =E4*B4*4/C4 -> 8 | G4: 0 | H4: =G4*B4 -> 0 | I4: 0.714
A5: praneel a [James Clemens] | B5: 4 | C5: 16 | D5: 10 | E5: 8 | F5: =E5*B5*4/C5 -> 8 | G5: 0 | H5: =G5*B5 -> 0 | I5: 0.8
A6: advai s [Mission San Jose B] | B6: 4 | C6: 16 | D6: 14 | E6: 8 | F6: =E6*B6*4/C6 -> 8 | G6: 0.5 | H6: =G6*B6 -> 2 | I6: 0.714
A7: flora j [Canyon Crest A] | B7: 4 | C7: 16 | D7: 12 | E7: 8 | F7: =E7*B7*4/C7 -> 8 | G7: 0.25 | H7: =G7*B7 -> 1 | I7: 0.75
A8: madhuram s [Enloe] | B8: 1 | C8: 4 | D8: 2 | E8: 8 | F8: =E8*B8*4/C8 -> 8 | G8: 0 | H8: =G8*B8 -> 0 | I8: 1
A9: rohan g [School of Biology] | B9: 4 | C9: 16 | D9: 8 | E9: 8 | F9: =E9*B9*4/C9 -> 8 | G9: 0 | H9: =G9*B9 -> 0 | I9: 1
A10: ryan e [Iolani A] | B10: 5 | C10: 20 | D10: 14 | E10: 6.4 | F10: =E10*B10*4/C10 -> 6.4 | G10: 0.2 | H10: =G10*B10 -> 1 | I10: 0.643
A11: luyao y [Wayzata] | B11: 4 | C11: 16 | D11: 12 | E11: 6 | F11: =E11*B11*4/C11 -> 6 | G11: 0.5 | H11: =G11*B11 -> 2 | I11: 0.667
A12: angelina l [Enloe] | B12: 4 | C12: 16 | D12: 6 | E12: 6 | F12: =E12*B12*4/C12 -> 6 | G12: 0 | H12: =G12*B12 -> 0 | I12: 1
A13: evan z [Blair A] | B13: 4 | C13: 16 | D13: 8 | E13: 6 | F13: =E13*B13*4/C13 -> 6 | G13: 0 | H13: =G13*B13 -> 0 | I13: 0.75
... A126: skyler m [Saratoga] | B126: 1 | C126: 4 | D126: 1 | E126: -4 | F126: =E126*B126*4/C126 -> -4 | G126: 1 | H126: =G126*B126 -> 1 | I126: 0
A140: Catstats Hub
A141: arjun g [Centreville A]
A142: pritham s [Centreville A]
A143: lucas q [Basis Silicon Valley]
A144: aaron c [Basis Silicon Valley]
A145: larry z [Basis Silicon Valley]
A146: skyler b [ASFA]
A147: akhil b [ASFA]
A148: albert c [ASFA]
A149: advik s [ASFA]
A150: alex g [Saratoga]
A151: warren c [Saratoga]
... A960: skyler m [Saratoga]

Sheet Round Robin Individual Math
A1: Catstats Hub | B1: gamesPlayed | C1: tuh | D1: buzzes | E1: ppg | F1: PP4TUH | G1: npg | H1: Total Negs | I1: accuracy
A2: skyler m [Saratoga] | B2: 1 | C2: 5 | D2: 4 | E2: 16 | F2: =E2*B2*4/C2 -> 12.8 | G2: 0 | H2: =G2*B2 -> 0 | I2: 1
A3: evan z [Blair A] | B3: 4 | C3: 16 | D3: 11 | E3: 11 | F3: =E3*B3*4/C3 -> 11 | G3: 0 | H3: =G3*B3 -> 0 | I3: 1
A4: rohan g [School of Biology] | B4: 4 | C4: 16 | D4: 15 | E4: 10 | F4: =E4*B4*4/C4 -> 10 | G4: 0.5 | H4: =G4*B4 -> 2 | I4: 0.8
A5: roshan a [Mission San Jose A] | B5: 4 | C5: 15 | D5: 12 | E5: 8 | F5: =E5*B5*4/C5 -> 8.5333333 | G5: 0.25 | H5: =G5*B5 -> 1 | I5: 0.75
A6: angelo l [Whitney Young] | B6: 1 | C6: 4 | D6: 2 | E6: 8 | F6: =E6*B6*4/C6 -> 8 | G6: 0 | H6: =G6*B6 -> 0 | I6: 1
A7: lucas q [Basis Silicon Valley] | B7: 4 | C7: 16 | D7: 13 | E7: 7 | F7: =E7*B7*4/C7 -> 7 | G7: 0.25 | H7: =G7*B7 -> 1 | I7: 0.615
A8: daniel y [Iolani B] | B8: 3 | C8: 12 | D8: 9 | E8: 6.67 | F8: =E8*B8*4/C8 -> 6.67 | G8: 0.33 | H8: =G8*B8 -> 0.99 | I8: 0.667
A9: neyan s [James Clemens] | B9: 4 | C9: 16 | D9: 11 | E9: 6 | F9: =E9*B9*4/C9 -> 6 | G9: 0.5 | H9: =G9*B9 -> 2 | I9: 0.727
A10: jayson z [Plano West] | B10: 3 | C10: 12 | D10: 6 | E10: 5.33 | F10: =E10*B10*4/C10 -> 5.33 | G10: 0.33 | H10: =G10*B10 -> 0.99 | I10: 0.833
A11: vishnu m [Lakeside] | B11: 3 | C11: 12 | D11: 6 | E11: 5.33 | F11: =E11*B11*4/C11 -> 5.33 | G11: 0.33 | H11: =G11*B11 -> 0.99 | I11: 0.833
A12: kaiwen y [Enloe] | B12: 5 | C12: 19 | D12: 7 | E12: 4.8 | F12: =E12*B12*4/C12 -> 5.0526316 | G12: 0 | H12: =G12*B12 -> 0 | I12: 0.857
A13: kevin y [Enloe] | B13: 4 | C13: 15 | D13: 5 | E13: 4 | F13: =E13*B13*4/C13 -> 4.2666667 | G13: 0 | H13: =G13*B13 -> 0 | I13: 0.8
... A126: aryan d [Canyon Crest B] | B126: 2 | C126: 8 | D126: 1 | E126: -2 | F126: =E126*B126*4/C126 -> -2 | G126: 0.5 | H126: =G126*B126 -> 1 | I126: 0
A140: Catstats Hub
A141: arjun g [Centreville A]
A142: pritham s [Centreville A]
A143: lucas q [Basis Silicon Valley]
A144: aaron c [Basis Silicon Valley]
A145: larry z [Basis Silicon Valley]
A146: skyler b [ASFA]
A147: akhil b [ASFA]
A148: albert c [ASFA]
A149: advik s [ASFA]
A150: alex g [Saratoga]
A151: warren c [Saratoga]
... A960: skyler m [Saratoga]

Sheet Round Robin Individual Physics
A1: Catstats Hub | B1: gamesPlayed | C1: tuh | D1: buzzes | E1: ppg | F1: PP4TUH | G1: npg | H1: Total Negs | I1: accuracy
A2: yunyi l [Blair A] | B2: 4 | C2: 16 | D2: 12 | E2: 12 | F2: =E2*B2*4/C2 -> 12 | G2: 0 | H2: =G2*B2 -> 0 | I2: 1
A3: kaiwen y [Enloe] | B3: 5 | C3: 21 | D3: 11 | E3: 8.8 | F3: =E3*B3*4/C3 -> 8.3809524 | G3: 0 | H3: =G3*B3 -> 0 | I3: 1
A4: forrest c [Palo Alto] | B4: 4 | C4: 16 | D4: 13 | E4: 8 | F4: =E4*B4*4/C4 -> 8 | G4: 0.5 | H4: =G4*B4 -> 2 | I4: 0.769
A5: daniel l [Iolani A] | B5: 5 | C5: 20 | D5: 13 | E5: 7.2 | F5: =E5*B5*4/C5 -> 7.2 | G5: 0.4 | H5: =G5*B5 -> 2 | I5: 0.846
A6: pritham s [Centreville A] | B6: 4 | C6: 16 | D6: 8 | E6: 6 | F6: =E6*B6*4/C6 -> 6 | G6: 0 | H6: =G6*B6 -> 0 | I6: 0.75
A7: lucas q [Basis Silicon Valley] | B7: 4 | C7: 16 | D7: 11 | E7: 6 | F7: =E7*B7*4/C7 -> 6 | G7: 0.5 | H7: =G7*B7 -> 2 | I7: 0.727
A8: josh s [Princeton] | B8: 4 | C8: 16 | D8: 9 | E8: 6 | F8: =E8*B8*4/C8 -> 6 | G8: 0.25 | H8: =G8*B8 -> 1 | I8: 0.778
A9: skyler m [Saratoga] | B9: 1 | C9: 3 | D9: 2 | E9: 4 | F9: =E9*B9*4/C9 -> 5.3333333 | G9: 0 | H9: =G9*B9 -> 0 | I9: 0.5
A10: aarush m [East Brunswick] | B10: 4 | C10: 16 | D10: 11 | E10: 5 | F10: =E10*B10*4/C10 -> 5 | G10: 0 | H10: =G10*B10 -> 0 | I10: 0.455
A11: praneel a [James Clemens] | B11: 4 | C11: 16 | D11: 7 | E11: 5 | F11: =E11*B11*4/C11 -> 5 | G11: 0.25 | H11: =G11*B11 -> 1 | I11: 0.857
A12: chris w [Blair B] | B12: 4 | C12: 16 | D12: 7 | E12: 5 | F12: =E12*B12*4/C12 -> 5 | G12: 0.25 | H12: =G12*B12 -> 1 | I12: 0.857
A13: austin x [Canyon Crest A] | B13: 4 | C13: 16 | D13: 7 | E13: 5 | F13: =E13*B13*4/C13 -> 5 | G13: 0 | H13: =G13*B13 -> 0 | I13: 0.714
... A126: akhil b [ASFA] | B126: 5 | C126: 20 | D126: 8 | E126: -2.4 | F126: =E126*B126*4/C126 -> -2.4 | G126: 0.8 | H126: =G126*B126 -> 4 | I126: 0.125
A140: Catstats Hub
A141: arjun g [Centreville A]
A142: pritham s [Centreville A]
A143: lucas q [Basis Silicon Valley]
A144: aaron c [Basis Silicon Valley]
A145: larry z [Basis Silicon Valley]
A146: skyler b [ASFA]
A147: akhil b [ASFA]
A148: albert c [ASFA]
A149: advik s [ASFA]
A150: alex g [Saratoga]
A151: warren c [Saratoga]
... A960: skyler m [Saratoga]

Sheet Double Elimination Overall Indi
A1: Catstats Hub | B1: gamesPlayed | C1: tuh | D1: buzzes | E1: ppg | F1: PP4TUH | G1: npg | H1: Total Negs | I1: accuracy
A2: kaiwen y [Enloe] | B2: 3 | C2: 68 | D2: 33 | E2: 30.67 | F2: =E2*B2*20/C2 -> 27.061765 | G2: 0.67 | H2: =G2*B2 -> 2.01 | I2: 0.758
A3: rohan g [School of Biology] | B3: 5 | C3: 115 | D3: 88 | E3: 24.8 | F3: =E3*B3*20/C3 -> 21.565217 | G3: 3.4 | H3: =G3*B3 -> 17 | I3: 0.545
A4: yunyi l [Blair A] | B4: 5 | C4: 115 | D4: 44 | E4: 22.4 | F4: =E4*B4*20/C4 -> 19.478261 | G4: 0.6 | H4: =G4*B4 -> 3 | I4: 0.705
A5: lucas q [Basis Silicon Valley] | B5: 5 | C5: 116 | D5: 57 | E5: 22.4 | F5: =E5*B5*20/C5 -> 19.310345 | G5: 0.6 | H5: =G5*B5 -> 3 | I5: 0.544
A6: suzuko o [North Hollywood] | B6: 4 | C6: 92 | D6: 38 | E6: 16 | F6: =E6*B6*20/C6 -> 13.913043 | G6: 1.25 | H6: =G6*B6 -> 5 | I6: 0.553
A7: daniel l [Iolani A] | B7: 3 | C7: 70 | D7: 24 | E7: 14.67 | F7: =E7*B7*20/C7 -> 12.574286 | G7: 1 | H7: =G7*B7 -> 3 | I7: 0.583
A8: chris w [Blair B] | B8: 2 | C8: 46 | D8: 10 | E8: 14 | F8: =E8*B8*20/C8 -> 12.173913 | G8: 0 | H8: =G8*B8 -> 0 | I8: 0.7
A9: praneel a [James Clemens] | B9: 5 | C9: 115 | D9: 26 | E9: 12.8 | F9: =E9*B9*20/C9 -> 11.130435 | G9: 0.2 | H9: =G9*B9 -> 1 | I9: 0.654
A10: evan z [Blair A] | B10: 5 | C10: 115 | D10: 28 | E10: 12.8 | F10: =E10*B10*20/C10 -> 11.130435 | G10: 0 | H10: =G10*B10 -> 0 | I10: 0.571
A11: flora j [Canyon Crest A] | B11: 4 | C11: 92 | D11: 18 | E11: 12 | F11: =E11*B11*20/C11 -> 10.434783 | G11: 0 | H11: =G11*B11 -> 0 | I11: 0.667
A12: vishnu m [Lakeside] | B12: 7 | C12: 162 | D12: 37 | E12: 11.43 | F12: =E12*B12*20/C12 -> 9.8777778 | G12: 0.43 | H12: =G12*B12 -> 3.01 | I12: 0.622
A13: sean y [Canyon Crest A] | B13: 4 | C13: 92 | D13: 27 | E13: 11 | F13: =E13*B13*20/C13 -> 9.5652174 | G13: 1.25 | H13: =G13*B13 -> 5 | I13: 0.593
... A57: charles h [North Hollywood] | B57: 1 | C57: 22 | D57: 1 | E57: -4 | F57: =E57*B57*20/C57 -> -3.6363636 | G57: 1 | H57: =G57*B57 -> 1 | I57: 0

Sheet Double Elimination Individual B
A1: Catstats Hub | B1: gamesPlayed | C1: tuh | D1: buzzes | E1: ppg | F1: PP4TUH | G1: npg | H1: Total Negs | I1: accuracy
A2: nihar b [Basis Chandler] | B2: 2 | C2: 8 | D2: 7 | E2: 8 | F2: =E2*B2*4/C2 -> 8 | G2: 0.5 | H2: =G2*B2 -> 1 | I2: 0.714
A3: larry z [Basis Silicon Valley] | B3: 5 | C3: 20 | D3: 12 | E3: 6.4 | F3: =E3*B3*4/C3 -> 6.4 | G3: 0.2 | H3: =G3*B3 -> 1 | I3: 0.75
A4: sean y [Canyon Crest A] | B4: 4 | C4: 16 | D4: 13 | E4: 6 | F4: =E4*B4*4/C4 -> 6 | G4: 0.5 | H4: =G4*B4 -> 2 | I4: 0.615
A5: rohan g [School of Biology] | B5: 5 | C5: 20 | D5: 14 | E5: 5.6 | F5: =E5*B5*4/C5 -> 5.6 | G5: 0.2 | H5: =G5*B5 -> 1 | I5: 0.571
A6: suzuko o [North Hollywood] | B6: 4 | C6: 16 | D6: 12 | E6: 5 | F6: =E6*B6*4/C6 -> 5 | G6: 0.5 | H6: =G6*B6 -> 2 | I6: 0.583
A7: theenash s [Mission San Jose A] | B7: 5 | C7: 20 | D7: 17 | E7: 4.8 | F7: =E7*B7*4/C7 -> 4.8 | G7: 1 | H7: =G7*B7 -> 5 | I7: 0.647
A8: katherine w [Blair A] | B8: 5 | C8: 20 | D8: 6 | E8: 4.8 | F8: =E8*B8*4/C8 -> 4.8 | G8: 0 | H8: =G8*B8 -> 0 | I8: 1
A9: kian d [Blair A] | B9: 5 | C9: 20 | D9: 10 | E9: 4 | F9: =E9*B9*4/C9 -> 4 | G9: 0.2 | H9: =G9*B9 -> 1 | I9: 0.6
A10: emma l [Lakeside] | B10: 2 | C10: 8 | D10: 4 | E10: 4 | F10: =E10*B10*4/C10 -> 4 | G10: 0 | H10: =G10*B10 -> 0 | I10: 0.5
A11: min s [Iolani A] | B11: 1 | C11: 4 | D11: 1 | E11: 4 | F11: =E11*B11*4/C11 -> 4 | G11: 0 | H11: =G11*B11 -> 0 | I11: 1
A12: rasia y [Palo Alto] | B12: 3 | C12: 13 | D12: 5 | E12: 2.67 | F12: =E12*B12*4/C12 -> 2.4646154 | G12: 0 | H12: =G12*B12 -> 0 | I12: 0.4
A13: yunyi l [Blair A] | B13: 5 | C13: 20 | D13: 3 | E13: 2.4 | F13: =E13*B13*4/C13 -> 2.4 | G13: 0 | H13: =G13*B13 -> 0 | I13: 1
... A57: michelle l [Basis Silicon Valley] | B57: 1 | C57: 4 | D57: 1 | E57: -4 | F57: =E57*B57*4/C57 -> -4 | G57: 1 | H57: =G57*B57 -> 1 | I57: 0

Sheet Double Elimination Individual C
A1: Catstats Hub | B1: gamesPlayed | C1: tuh | D1: buzzes | E1: ppg | F1: PP4TUH | G1: npg | H1: Total Negs | I1: accuracy
A2: yunyi l [Blair A] | B2: 5 | C2: 20 | D2: 14 | E2: 10.4 | F2: =E2*B2*4/C2 -> 10.4 | G2: 0 | H2: =G2*B2 -> 0 | I2: 0.929
A3: william w [Lakeside] | B3: 5 | C3: 21 | D3: 14 | E3: 8.8 | F3: =E3*B3*4/C3 -> 8.3809524 | G3: 0 | H3: =G3*B3 -> 0 | I3: 0.786
A4: neyan s [James Clemens] | B4: 5 | C4: 21 | D4: 18 | E4: 7.2 | F4: =E4*B4*4/C4 -> 6.8571429 | G4: 0.6 | H4: =G4*B4 -> 3 | I4: 0.667
A5: daniel l [Iolani A] | B5: 3 | C5: 12 | D5: 8 | E5: 6.67 | F5: =E5*B5*4/C5 -> 6.67 | G5: 0.33 | H5: =G5*B5 -> 0.99 | I5: 0.75
A6: advai s [Mission San Jose B] | B6: 2 | C6: 8 | D6: 3 | E6: 6 | F6: =E6*B6*4/C6 -> 6 | G6: 0 | H6: =G6*B6 -> 0 | I6: 1
A7: kaiwen y [Enloe] | B7: 3 | C7: 12 | D7: 7 | E7: 5.33 | F7: =E7*B7*4/C7 -> 5.33 | G7: 0.33 | H7: =G7*B7 -> 0.99 | I7: 0.714
A8: lucas q [Basis Silicon Valley] | B8: 5 | C8: 20 | D8: 12 | E8: 4.8 | F8: =E8*B8*4/C8 -> 4.8 | G8: 0 | H8: =G8*B8 -> 0 | I8: 0.5
A9: sam e [Blair B] | B9: 1 | C9: 4 | D9: 1 | E9: 4 | F9: =E9*B9*4/C9 -> 4 | G9: 0 | H9: =G9*B9 -> 0 | I9: 1
A10: min s [Iolani A] | B10: 1 | C10: 4 | D10: 1 | E10: 4 | F10: =E10*B10*4/C10 -> 4 | G10: 0 | H10: =G10*B10 -> 0 | I10: 1
A11: kevin p [Palo Alto] | B11: 2 | C11: 9 | D11: 2 | E11: 4 | F11: =E11*B11*4/C11 -> 3.5555556 | G11: 0 | H11: =G11*B11 -> 0 | I11: 1
A12: rohan g [School of Biology] | B12: 5 | C12: 21 | D12: 17 | E12: 3.2 | F12: =E12*B12*4/C12 -> 3.047619 | G12: 1 | H12: =G12*B12 -> 5 | I12: 0.529
A13: connor z [North Hollywood] | B13: 4 | C13: 16 | D13: 10 | E13: 3 | F13: =E13*B13*4/C13 -> 3 | G13: 0.75 | H13: =G13*B13 -> 3 | I13: 0.6
... A57: sean y [Canyon Crest A] | B57: 4 | C57: 16 | D57: 7 | E57: -1 | F57: =E57*B57*4/C57 -> -1 | G57: 0.75 | H57: =G57*B57 -> 3 | I57: 0.286

Sheet Double Elimination Individual E
A1: Catstats Hub | B1: gamesPlayed | C1: tuh | D1: buzzes | E1: ppg | F1: PP3TUH | G1: npg | H1: Total Negs | I1: accuracy
A2: kaiwen y [Enloe] | B2: 3 | C2: 9 | D2: 7 | E2: 5.33 | F2: =E2*B2*3/C2 -> 5.33 | G2: 0.33 | H2: =G2*B2 -> 0.99 | I2: 0.714
A3: akhil b [ASFA] | B3: 2 | C3: 6 | D3: 3 | E3: 4 | F3: =E3*B3*3/C3 -> 4 | G3: 0 | H3: =G3*B3 -> 0 | I3: 0.667
A4: sam e [Blair B] | B4: 1 | C4: 3 | D4: 2 | E4: 4 | F4: =E4*B4*3/C4 -> 4 | G4: 0 | H4: =G4*B4 -> 0 | I4: 0.5
A5: rohan g [School of Biology] | B5: 5 | C5: 15 | D5: 13 | E5: 3.2 | F5: =E5*B5*3/C5 -> 3.2 | G5: 0.4 | H5: =G5*B5 -> 2 | I5: 0.462
A6: lucas q [Basis Silicon Valley] | B6: 5 | C6: 15 | D6: 8 | E6: 3.2 | F6: =E6*B6*3/C6 -> 3.2 | G6: 0.2 | H6: =G6*B6 -> 1 | I6: 0.625
A7: sean y [Canyon Crest A] | B7: 4 | C7: 12 | D7: 4 | E7: 3 | F7: =E7*B7*3/C7 -> 3 | G7: 0 | H7: =G7*B7 -> 0 | I7: 0.75
A8: flora j [Canyon Crest A] | B8: 4 | C8: 12 | D8: 3 | E8: 3 | F8: =E8*B8*3/C8 -> 3 | G8: 0 | H8: =G8*B8 -> 0 | I8: 1
A9: yunyi l [Blair A] | B9: 5 | C9: 15 | D9: 5 | E9: 2.4 | F9: =E9*B9*3/C9 -> 2.4 | G9: 0 | H9: =G9*B9 -> 0 | I9: 0.6
A10: evan z [Blair A] | B10: 5 | C10: 15 | D10: 5 | E10: 2.4 | F10: =E10*B10*3/C10 -> 2.4 | G10: 0 | H10: =G10*B10 -> 0 | I10: 0.6
A11: vishnu m [Lakeside] | B11: 7 | C11: 22 | D11: 5 | E11: 2.29 | F11: =E11*B11*3/C11 -> 2.1859091 | G11: 0 | H11: =G11*B11 -> 0 | I11: 0.8
A12: kevin f [Blair B] | B12: 2 | C12: 6 | D12: 1 | E12: 2 | F12: =E12*B12*3/C12 -> 2 | G12: 0 | H12: =G12*B12 -> 0 | I12: 1
A13: varyan j [Basis Chandler] | B13: 2 | C13: 6 | D13: 1 | E13: 2 | F13: =E13*B13*3/C13 -> 2 | G13: 0 | H13: =G13*B13 -> 0 | I13: 1
... A57: advai s [Mission San Jose B] | B57: 2 | C57: 6 | D57: 1 | E57: -2 | F57: =E57*B57*3/C57 -> -2 | G57: 0.5 | H57: =G57*B57 -> 1 | I57: 0

Sheet Sheet33
A1: Catstats Hub | B1: gamesPlayed | C1: tuh | D1: buzzes | E1: ppg | F1: PP4TUH | G1: npg | H1: Total Negs | I1: accuracy
A2: suzuko o [North Hollywood] | B2: 4 | C2: 16 | D2: 12 | E2: 9 | F2: =E2*B2*4/C2 -> 9 | G2: 0.25 | H2: =G2*B2 -> 1 | I2: 0.833
A3: flora j [Canyon Crest A] | B3: 4 | C3: 16 | D3: 11 | E3: 7 | F3: =E3*B3*4/C3 -> 7 | G3: 0 | H3: =G3*B3 -> 0 | I3: 0.636
A4: kaiwen y [Enloe] | B4: 3 | C4: 12 | D4: 5 | E4: 6.67 | F4: =E4*B4*4/C4 -> 6.67 | G4: 0 | H4: =G4*B4 -> 0 | I4: 1
A5: angelina l [Enloe] | B5: 2 | C5: 8 | D5: 3 | E5: 6 | F5: =E5*B5*4/C5 -> 6 | G5: 0 | H5: =G5*B5 -> 0 | I5: 1
A6: ryan e [Iolani A] | B6: 3 | C6: 12 | D6: 8 | E6: 5.33 | F6: =E6*B6*4/C6 -> 5.33 | G6: 0.33 | H6: =G6*B6 -> 0.99 | I6: 0.625
A7: rohan g [School of Biology] | B7: 5 | C7: 19 | D7: 13 | E7: 4.8 | F7: =E7*B7*4/C7 -> 5.0526316 | G7: 0.2 | H7: =G7*B7 -> 1 | I7: 0.538
A8: lucas q [Basis Silicon Valley] | B8: 5 | C8: 20 | D8: 9 | E8: 4.8 | F8: =E8*B8*4/C8 -> 4.8 | G8: 0 | H8: =G8*B8 -> 0 | I8: 0.667
A9: roshan a [Mission San Jose A] | B9: 5 | C9: 20 | D9: 17 | E9: 4 | F9: =E9*B9*4/C9 -> 4 | G9: 0.8 | H9: =G9*B9 -> 4 | I9: 0.529
A10: lucas k [Blair B] | B10: 1 | C10: 4 | D10: 2 | E10: 4 | F10: =E10*B10*4/C10 -> 4 | G10: 0 | H10: =G10*B10 -> 0 | I10: 0.5
A11: aaron c [Basis Silicon Valley] | B11: 3 | C11: 12 | D11: 7 | E11: 4 | F11: =E11*B11*4/C11 -> 4 | G11: 0 | H11: =G11*B11 -> 0 | I11: 0.429
A12: praneel a [James Clemens] | B12: 5 | C12: 18 | D12: 7 | E12: 3.2 | F12: =E12*B12*4/C12 -> 3.5555556 | G12: 0 | H12: =G12*B12 -> 0 | I12: 0.571
A13: vishnu m [Lakeside] | B13: 7 | C13: 27 | D13: 10 | E13: 2.86 | F13: =E13*B13*4/C13 -> 2.9659259 | G13: 0 | H13: =G13*B13 -> 0 | I13: 0.5
... A57: advai s [Mission San Jose B] | B57: 2 | C57: 8 | D57: 7 | E57: -6 | F57: =E57*B57*4/C57 -> -6 | G57: 2.5 | H57: =G57*B57 -> 5 | I57: 0.286

Sheet Double Elimination Individual M
A1: Catstats Hub | B1: gamesPlayed | C1: tuh | D1: buzzes | E1: ppg | F1: PP4TUH | G1: npg | H1: Total Negs | I1: accuracy
A2: chris w [Blair B] | B2: 2 | C2: 8 | D2: 5 | E2: 8 | F2: =E2*B2*4/C2 -> 8 | G2: 0 | H2: =G2*B2 -> 0 | I2: 0.8
A3: skyler m [Saratoga] | B3: 3 | C3: 12 | D3: 10 | E3: 6.67 | F3: =E3*B3*4/C3 -> 6.67 | G3: 0.33 | H3: =G3*B3 -> 0.99 | I3: 0.6
A4: evan z [Blair A] | B4: 5 | C4: 20 | D4: 14 | E4: 6.4 | F4: =E4*B4*4/C4 -> 6.4 | G4: 0 | H4: =G4*B4 -> 0 | I4: 0.571
A5: kevin y [Enloe] | B5: 2 | C5: 8 | D5: 3 | E5: 4 | F5: =E5*B5*4/C5 -> 4 | G5: 0 | H5: =G5*B5 -> 0 | I5: 0.667
A6: rutvik a [Mission San Jose A] | B6: 1 | C6: 4 | D6: 1 | E6: 4 | F6: =E6*B6*4/C6 -> 4 | G6: 0 | H6: =G6*B6 -> 0 | I6: 1
A7: kshitij t [Mission San Jose B] | B7: 2 | C7: 8 | D7: 4 | E7: 4 | F7: =E7*B7*4/C7 -> 4 | G7: 0.5 | H7: =G7*B7 -> 1 | I7: 0.75
A8: rohan g [School of Biology] | B8: 5 | C8: 20 | D8: 16 | E8: 4 | F8: =E8*B8*4/C8 -> 4 | G8: 0.8 | H8: =G8*B8 -> 4 | I8: 0.563
A9: rohan d [Lakeside] | B9: 6 | C9: 24 | D9: 8 | E9: 4 | F9: =E9*B9*4/C9 -> 4 | G9: 0 | H9: =G9*B9 -> 0 | I9: 0.75
A10: lucas q [Basis Silicon Valley] | B10: 5 | C10: 21 | D10: 15 | E10: 4 | F10: =E10*B10*4/C10 -> 3.8095238 | G10: 0.2 | H10: =G10*B10 -> 1 | I10: 0.4
A11: vishnu m [Lakeside] | B11: 7 | C11: 28 | D11: 9 | E11: 3.43 | F11: =E11*B11*4/C11 -> 3.43 | G11: 0.14 | H11: =G11*B11 -> 0.98 | I11: 0.778
A12: kaiwen y [Enloe] | B12: 3 | C12: 11 | D12: 3 | E12: 2.67 | F12: =E12*B12*4/C12 -> 2.9127273 | G12: 0 | H12: =G12*B12 -> 0 | I12: 0.667
A13: sola m [Iolani A] | B13: 3 | C13: 13 | D13: 4 | E13: 2.67 | F13: =E13*B13*4/C13 -> 2.4646154 | G13: 0.33 | H13: =G13*B13 -> 0.99 | I13: 0.75
... A57: connor z [North Hollywood] | B57: 4 | C57: 15 | D57: 3 | E57: -1 | F57: =E57*B57*4/C57 -> -1.0666667 | G57: 0.25 | H57: =G57*B57 -> 1 | I57: 0

Sheet Double Elimination Individual P
A1: Catstats Hub | B1: gamesPlayed | C1: tuh | D1: buzzes | E1: ppg | F1: PP4TUH | G1: npg | H1: Total Negs | I1: accuracy
A2: kaiwen y [Enloe] | B2: 3 | C2: 12 | D2: 8 | E2: 9.33 | F2: =E2*B2*4/C2 -> 9.33 | G2: 0 | H2: =G2*B2 -> 0 | I2: 0.875
A3: praneel a [James Clemens] | B3: 5 | C3: 20 | D3: 13 | E3: 6.4 | F3: =E3*B3*4/C3 -> 6.4 | G3: 0.2 | H3: =G3*B3 -> 1 | I3: 0.692
A4: chris w [Blair B] | B4: 2 | C4: 8 | D4: 4 | E4: 6 | F4: =E4*B4*4/C4 -> 6 | G4: 0 | H4: =G4*B4 -> 0 | I4: 0.75
A5: yunyi l [Blair A] | B5: 5 | C5: 20 | D5: 16 | E5: 5.6 | F5: =E5*B5*4/C5 -> 5.6 | G5: 0.6 | H5: =G5*B5 -> 3 | I5: 0.625
A6: lucas q [Basis Silicon Valley] | B6: 5 | C6: 20 | D6: 12 | E6: 5.6 | F6: =E6*B6*4/C6 -> 5.6 | G6: 0.2 | H6: =G6*B6 -> 1 | I6: 0.667
A7: daniel l [Iolani A] | B7: 3 | C7: 12 | D7: 5 | E7: 4 | F7: =E7*B7*4/C7 -> 4 | G7: 0.33 | H7: =G7*B7 -> 0.99 | I7: 0.8
A8: rohan g [School of Biology] | B8: 5 | C8: 20 | D8: 15 | E8: 4 | F8: =E8*B8*4/C8 -> 4 | G8: 0.8 | H8: =G8*B8 -> 4 | I8: 0.6
A9: sean y [Canyon Crest A] | B9: 4 | C9: 16 | D9: 3 | E9: 3 | F9: =E9*B9*4/C9 -> 3 | G9: 0 | H9: =G9*B9 -> 0 | I9: 1
A10: austin x [Canyon Crest A] | B10: 4 | C10: 16 | D10: 7 | E10: 3 | F10: =E10*B10*4/C10 -> 3 | G10: 0 | H10: =G10*B10 -> 0 | I10: 0.429
A11: skyler m [Saratoga] | B11: 3 | C11: 12 | D11: 5 | E11: 2.67 | F11: =E11*B11*4/C11 -> 2.67 | G11: 0 | H11: =G11*B11 -> 0 | I11: 0.4
A12: daniel w [Lakeside] | B12: 7 | C12: 28 | D12: 8 | E12: 2.29 | F12: =E12*B12*4/C12 -> 2.29 | G12: 0.14 | H12: =G12*B12 -> 0.98 | I12: 0.625
A13: kevin y [Enloe] | B13: 2 | C13: 8 | D13: 1 | E13: 2 | F13: =E13*B13*4/C13 -> 2 | G13: 0 | H13: =G13*B13 -> 0 | I13: 1
... A57: charles h [North Hollywood] | B57: 1 | C57: 4 | D57: 1 | E57: -4 | F57: =E57*B57*4/C57 -> -4 | G57: 1 | H57: =G57*B57 -> 1 | I57: 0

Sheet Round Robin Team Overall
A1: Catstats Hub | B1: gamesPlayed | C1: tuh | D1: buzzes | E1: ppg | F1: Total Points | G1: npg | H1: Total Negs | I1: bpg | J1: Total Bonuses | K1: accuracy
A2: Blair A | B2: 4 | C2: 92 | D2: 83 | E2: 229 | F2: =E2*B2 -> 916 | G2: 1.5 | H2: =G2*B2 -> 6 | I2: 16 | J2: =I2*B2 -> 64 | K2: 0.904
A3: North Hollywood | B3: 5 | C3: 115 | D3: 105 | E3: 165.6 | F3: =E3*B3 -> 828 | G3: 3.4 | H3: =G3*B3 -> 17 | I3: 11.6 | J3: =I3*B3 -> 58 | K3: 0.752
A4: Iolani A | B4: 5 | C4: 115 | D4: 88 | E4: 148.4 | F4: =E4*B4 -> 742 | G4: 2 | H4: =G4*B4 -> 10 | I4: 10.2 | J4: =I4*B4 -> 51 | K4: 0.773
A5: Enloe | B5: 5 | C5: 114 | D5: 77 | E5: 128.8 | F5: =E5*B5 -> 644 | G5: 0.4 | H5: =G5*B5 -> 2 | I5: 8 | J5: =I5*B5 -> 40 | K5: 0.818
A6: Mission San Jose A | B6: 4 | C6: 92 | D6: 87 | E6: 157.5 | F6: =E6*B6 -> 630 | G6: 5 | H6: =G6*B6 -> 20 | I6: 11.75 | J6: =I6*B6 -> 47 | K6: 0.69
A7: James Clemens | B7: 4 | C7: 92 | D7: 79 | E7: 142 | F7: =E7*B7 -> 568 | G7: 2.75 | H7: =G7*B7 -> 11 | I7: 9.5 | J7: =I7*B7 -> 38 | K7: 0.734
A8: School of Biology | B8: 4 | C8: 92 | D8: 68 | E8: 130.5 | F8: =E8*B8 -> 522 | G8: 2.75 | H8: =G8*B8 -> 11 | I8: 9.25 | J8: =I8*B8 -> 37 | K8: 0.721
A9: ASFA | B9: 5 | C9: 115 | D9: 89 | E9: 100 | F9: =E9*B9 -> 500 | G9: 2.8 | H9: =G9*B9 -> 14 | I9: 6.4 | J9: =I9*B9 -> 32 | K9: 0.663
A10: Blair B | B10: 4 | C10: 92 | D10: 64 | E10: 121.5 | F10: =E10*B10 -> 486 | G10: 2.25 | H10: =G10*B10 -> 9 | I10: 8.25 | J10: =I10*B10 -> 33 | K10: 0.75
A11: WWPS | B11: 5 | C11: 116 | D11: 77 | E11: 96.8 | F11: =E11*B11 -> 484 | G11: 2.8 | H11: =G11*B11 -> 14 | I11: 6.8 | J11: =I11*B11 -> 34 | K11: 0.649
A12: Saratoga | B12: 5 | C12: 116 | D12: 74 | E12: 96.4 | F12: =E12*B12 -> 482 | G12: 1.8 | H12: =G12*B12 -> 9 | I12: 6.2 | J12: =I12*B12 -> 31 | K12: 0.703
A13: Basis Silicon Valley | B13: 4 | C13: 92 | D13: 68 | E13: 119.5 | F13: =E13*B13 -> 478 | G13: 1.25 | H13: =G13*B13 -> 5 | I13: 7.75 | J13: =I13*B13 -> 31 | K13: 0.691
... A33: East Brunswick | B33: 4 | C33: 92 | D33: 41 | E33: 19 | F33: =E33*B33 -> 76 | G33: 0.25 | H33: =G33*B33 -> 1 | I33: 0.5 | J33: =I33*B33 -> 2 | K33: 0.366

Sheet Round Robin Team Biology
A1: Catstats Hub | B1: gamesPlayed | C1: tuh | D1: buzzes | E1: ppg | F1: Total Points | G1: npg | H1: Total Negs | I1: bpg | J1: Total Bonuses | K1: accuracy
A2: Blair A | B2: 4 | C2: 16 | D2: 15 | E2: 50 | F2: =E2*B2 -> 200 | G2: 0 | H2: =G2*B2 -> 0 | I2: 3.5 | J2: =I2*B2 -> 14 | K2: 1
A3: North Hollywood | B3: 5 | C3: 20 | D3: 20 | E3: 35.6 | F3: =E3*B3 -> 178 | G3: 0.6 | H3: =G3*B3 -> 3 | I3: 2.6 | J3: =I3*B3 -> 13 | K3: 0.75
A4: Mission San Jose A | B4: 4 | C4: 16 | D4: 16 | E4: 44.5 | F4: =E4*B4 -> 178 | G4: 0.5 | H4: =G4*B4 -> 2 | I4: 3.25 | J4: =I4*B4 -> 13 | K4: 0.875
A5: Canyon Crest A | B5: 4 | C5: 16 | D5: 12 | E5: 35 | F5: =E5*B5 -> 140 | G5: 0.25 | H5: =G5*B5 -> 1 | I5: 2.5 | J5: =I5*B5 -> 10 | K5: 0.917
A6: WWPS | B6: 5 | C6: 20 | D6: 15 | E6: 24.4 | F6: =E6*B6 -> 122 | G6: 0.4 | H6: =G6*B6 -> 2 | I6: 1.8 | J6: =I6*B6 -> 9 | K6: 0.667
A7: ASFA | B7: 5 | C7: 20 | D7: 15 | E7: 22.4 | F7: =E7*B7 -> 112 | G7: 0 | H7: =G7*B7 -> 0 | I7: 1.2 | J7: =I7*B7 -> 6 | K7: 0.867
A8: Basis Silicon Valley | B8: 4 | C8: 16 | D8: 13 | E8: 27.5 | F8: =E8*B8 -> 110 | G8: 0.25 | H8: =G8*B8 -> 1 | I8: 1.75 | J8: =I8*B8 -> 7 | K8: 0.846
A9: Enloe | B9: 5 | C9: 20 | D9: 14 | E9: 19.2 | F9: =E9*B9 -> 96 | G9: 0.2 | H9: =G9*B9 -> 1 | I9: 1.2 | J9: =I9*B9 -> 6 | K9: 0.714
A10: Wayzata | B10: 4 | C10: 16 | D10: 15 | E10: 22 | F10: =E10*B10 -> 88 | G10: 0.5 | H10: =G10*B10 -> 2 | I10: 1.5 | J10: =I10*B10 -> 6 | K10: 0.6
A11: Blair B | B11: 4 | C11: 16 | D11: 10 | E11: 22 | F11: =E11*B11 -> 88 | G11: 0.25 | H11: =G11*B11 -> 1 | I11: 1.5 | J11: =I11*B11 -> 6 | K11: 0.8
A12: Lakeside | B12: 3 | C12: 12 | D12: 9 | E12: 28 | F12: =E12*B12 -> 84 | G12: 0 | H12: =G12*B12 -> 0 | I12: 2 | J12: =I11*B11 -> 6 | K12: 0.667
A13: Plano West | B13: 4 | C13: 16 | D13: 12 | E13: 19.5 | F13: =E13*B13 -> 78 | G13: 0.5 | H13: =G13*B13 -> 2 | I13: 1.25 | J13: =I13*B13 -> 5 | K13: 0.75
A14: Iolani A | B14: 5 | C14: 20 | D14: 11 | E14: 15.2 | F14: =E14*B14 -> 76 | G14: 0 | H14: =G14*B14 -> 0 | I14: 0.8 | J14: =I14*B14 -> 4 | K14: 0.818
A15: Saratoga | B15: 5 | C15: 20 | D15: 13 | E15: 14.8 | F15: =E15*B15 -> 74 | G15: 0.2 | H15: =G15*B15 -> 1 | I15: 1 | J15: =I15*B15 -> 5 | K15: 0.538
A16: Basis Chandler | B16: 4 | C16: 16 | D16: 10 | E16: 18.5 | F16: =E16*B16 -> 74 | G16: 0.25 | H16: =G16*B16 -> 1 | I16: 1.25 | J16: =I16*B16 -> 5 | K16: 0.7
A17: Princeton | B17: 4 | C17: 16 | D17: 11 | E17: 18.5 | F17: =E17*B17 -> 74 | G17: 0.25 | H17: =G17*B17 -> 1 | I17: 1.25 | J17: =I17*B17 -> 5 | K17: 0.636
A18: Brooklyn Tech A | B18: 5 | C18: 20 | D18: 12 | E18: 13.6 | F18: =E18*B18 -> 68 | G18: 0.2 | H18: =G18*B18 -> 1 | I18: 0.8 | J18: =I18*B18 -> 4 | K18: 0.667
A19: Winston Churchill | B19: 5 | C19: 20 | D19: 11 | E19: 13.6 | F19: =E19*B19 -> 68 | G19: 0.2 | H19: =G19*B19 -> 1 | I19: 0.8 | J19: =I19*B19 -> 4 | K19: 0.727
A20: School of Biology | B20: 4 | C20: 16 | D20: 10 | E20: 15.5 | F20: =E20*B20 -> 62 | G20: 0.5 | H20: =G20*B20 -> 2 | I20: 1.25 | J20: =I20*B20 -> 5 | K20: 0.5
A21: Whitney Young | B21: 4 | C21: 16 | D21: 9 | E21: 15 | F21: =E21*B21 -> 60 | G21: 0.25 | H21: =G21*B21 -> 1 | I21: 1 | J21: =I21*B21 -> 4 | K21: 0.667
A22: James Clemens | B22: 4 | C22: 16 | D22: 13 | E22: 14.5 | F22: =E22*B22 -> 58 | G22: 0.5 | H22: =G22*B22 -> 2 | I22: 0.75 | J22: =I22*B22 -> 3 | K22: 0.692
A23: Centreville A | B23: 4 | C23: 16 | D23: 5 | E23: 14 | F23: =E23*B23 -> 56 | G23: 0 | H23: =G23*B23 -> 0 | I23: 1 | J23: =I23*B23 -> 4 | K23: 0.8
A24: Palo Alto | B24: 4 | C24: 16 | D24: 10 | E24: 13 | F24: =E24*B24 -> 52 | G24: 0.5 | H24: =G24*B24 -> 2 | I24: 1 | J24: =I24*B24 -> 4 | K24: 0.5
... A28: Brooklyn Tech B | B28: 5 | C28: 20 | D28: 9 | E28: 5.2 | F28: =E28*B28 -> 26 | G28: 0.2 | H28: =G28*B28 -> 1 | I28: 0.2 | J28: =I28*B28 -> 1 | K28: 0.556
A29: Iolani B | B29: 3 | C29: 12 | D29: 9 | E29: 6 | F29: =E29*B29 -> 18 | G29: 0.33 | H29: =G29*B29 -> 0.99 | I29: 0.33 | J29: =I28*B28 -> 1 | K29: 0.333
A30: Commonwealth | B30: 4 | C30: 16 | D30: 5 | E30: 2 | F30: =E30*B30 -> 8 | G30: 0 | H30: =G30*B30 -> 0 | I30: 0 | J30: =I30*B30 -> 0 | K30: 0.4
A31: Collierville | B31: 4 | C31: 16 | D31: 5 | E31: 0.5 | F31: =E31*B31 -> 2 | G31: 0.75 | H31: =G31*B31 -> 3 | I31: 0.25 | J31: =I31*B31 -> 1 | K31: 0.2
A32: East Brunswick | B32: 4 | C32: 16 | D32: 7 | E32: 0 | F32: =E32*B32 -> 0 | G32: 0 | H32: =G32*B32 -> 0 | I32: 0 | J32: =I32*B32 -> 0 | K32: 0
A33: Canyon Crest B | B33: 4 | C33: 16 | D33: 3 | E33: 0 | F33: =E33*B33 -> 0 | G33: 0 | H33: =G33*B33 -> 0 | I33: 0 | J33: =I33*B33 -> 0 | K33: 0

Sheet Round Robin Team Chemistry
A1: Catstats Hub | B1: gamesPlayed | C1: tuh | D1: buzzes | E1: ppg | F1: Total Points | G1: npg | H1: Total Negs | I1: bpg | J1: Total Bonuses | K1: accuracy
A2: North Hollywood | B2: 5 | C2: 20 | D2: 20 | E2: 38.4 | F2: =E2*B2 -> 192 | G2: 0.6 | H2: =G2*B2 -> 3 | I2: 2.8 | J2: =I2*B2 -> 14 | K2: 0.8
A3: Blair A | B3: 4 | C3: 16 | D3: 16 | E3: 40 | F3: =E3*B3 -> 160 | G3: 0.75 | H3: =G3*B3 -> 3 | I3: 3 | J3: =I3*B3 -> 12 | K3: 0.813
A4: Iolani A | B4: 5 | C4: 20 | D4: 14 | E4: 31.2 | F4: =E4*B4 -> 156 | G4: 0 | H4: =G4*B4 -> 0 | I4: 2 | J4: =I4*B4 -> 10 | K4: 1
A5: Saratoga | B5: 5 | C5: 20 | D5: 15 | E5: 26.8 | F5: =E5*B5 -> 134 | G5: 0.2 | H5: =G5*B5 -> 1 | I5: 1.8 | J5: =I5*B5 -> 9 | K5: 0.8
A6: Temple City | B6: 5 | C6: 20 | D6: 17 | E6: 26.4 | F6: =E6*B6 -> 132 | G6: 0.8 | H6: =G6*B6 -> 4 | I6: 2 | J6: =I6*B6 -> 10 | K6: 0.706
A7: James Clemens | B7: 4 | C7: 16 | D7: 15 | E7: 31.5 | F7: =E7*B7 -> 126 | G7: 0.75 | H7: =G7*B7 -> 3 | I7: 2.25 | J7: =I7*B7 -> 9 | K7: 0.8
A8: Palo Alto | B8: 4 | C8: 17 | D8: 14 | E8: 30 | F8: =E8*B8 -> 120 | G8: 0.5 | H8: =G8*B8 -> 2 | I8: 2 | J8: =I8*B8 -> 8 | K8: 0.857
A9: Mission San Jose A | B9: 4 | C9: 16 | D9: 16 | E9: 27 | F9: =E9*B9 -> 108 | G9: 1 | H9: =G9*B9 -> 4 | I9: 2 | J9: =I9*B9 -> 8 | K9: 0.688
A10: Lakeside | B10: 3 | C10: 13 | D10: 11 | E10: 34.67 | F10: =E10*B10 -> 104.01 | G10: 0.67 | H10: =G10*B10 -> 2.01 | I10: 2.67 | J10: =I10*B10 -> 8.01 | K10: 0.727
A11: WWPS | B11: 5 | C11: 20 | D11: 12 | E11: 20.4 | F11: =E11*B11 -> 102 | G11: 0.2 | H11: =G11*B11 -> 1 | I11: 1.4 | J11: =I11*B11 -> 7 | K11: 0.75
A12: Blair B | B12: 4 | C12: 16 | D12: 12 | E12: 25.5 | F12: =E12*B12 -> 102 | G12: 0.5 | H12: =G12*B12 -> 2 | I12: 1.75 | J12: =I12*B12 -> 7 | K12: 0.833
A13: ASFA | B13: 5 | C13: 20 | D13: 16 | E13: 19.6 | F13: =E13*B13 -> 98 | G13: 0 | H13: =G13*B13 -> 0 | I13: 1 | J13: =I13*B13 -> 5 | K13: 0.75
... A33: Winston Churchill | B33: 5 | C33: 20 | D33: 6 | E33: 0.8 | F33: =E33*B33 -> 4 | G33: 0 | H33: =G33*B33 -> 0 | I33: 0 | J33: =I33*B33 -> 0 | K33: 0.167

Sheet Round Robin Team Energy
A1: Catstats Hub | B1: gamesPlayed | C1: tuh | D1: buzzes | E1: ppg | F1: Total Points | G1: npg | H1: Total Negs | I1: bpg | J1: Total Bonuses | K1: accuracy
A2: Iolani A | B2: 5 | C2: 15 | D2: 12 | E2: 24 | F2: =E2*B2 -> 120 | G2: 0 | H2: =G2*B2 -> 0 | I2: 1.6 | J2: =I2*B2 -> 8 | K2: 0.833
A3: Enloe | B3: 5 | C3: 14 | D3: 10 | E3: 22 | F3: =E3*B3 -> 110 | G3: 0 | H3: =G3*B3 -> 0 | I3: 1.4 | J3: =I3*B3 -> 7 | K3: 1
A4: Saratoga | B4: 5 | C4: 16 | D4: 14 | E4: 19.6 | F4: =E4*B4 -> 98 | G4: 0.6 | H4: =G4*B4 -> 3 | I4: 1.4 | J4: =I4*B4 -> 7 | K4: 0.714
A5: Wayzata | B5: 4 | C5: 12 | D5: 9 | E5: 24 | F5: =E5*B5 -> 96 | G5: 0 | H5: =G5*B5 -> 0 | I5: 1.5 | J5: =I5*B5 -> 6 | K5: 1
A6: Evergreen | B6: 4 | C6: 12 | D6: 11 | E6: 23 | F6: =E6*B6 -> 92 | G6: 0.25 | H6: =G6*B6 -> 1 | I6: 1.5 | J6: =I6*B6 -> 6 | K6: 0.818
A7: ASFA | B7: 5 | C7: 15 | D7: 11 | E7: 16.8 | F7: =E7*B7 -> 84 | G7: 0.4 | H7: =G7*B7 -> 2 | I7: 1.2 | J7: =I7*B7 -> 6 | K7: 0.727
A8: James Clemens | B8: 4 | C8: 12 | D8: 10 | E8: 21 | F8: =E8*B8 -> 84 | G8: 0.25 | H8: =G8*B8 -> 1 | I8: 1.5 | J8: =I8*B8 -> 6 | K8: 0.7
A9: Basis Silicon Valley | B9: 4 | C9: 12 | D9: 9 | E9: 20.5 | F9: =E9*B9 -> 82 | G9: 0 | H9: =G9*B9 -> 0 | I9: 1.25 | J9: =I9*B9 -> 5 | K9: 0.889
A10: Blair A | B10: 4 | C10: 12 | D10: 11 | E10: 20 | F10: =E10*B10 -> 80 | G10: 0.75 | H10: =G10*B10 -> 3 | I10: 1.5 | J10: =I10*B10 -> 6 | K10: 0.727
A11: School of Biology | B11: 4 | C11: 12 | D11: 10 | E11: 19 | F11: =E11*B11 -> 76 | G11: 0.5 | H11: =G11*B11 -> 2 | I11: 1.5 | J11: =I11*B11 -> 6 | K11: 0.6
A12: North Hollywood | B12: 5 | C12: 15 | D12: 13 | E12: 14.8 | F12: =E12*B12 -> 74 | G12: 0.6 | H12: =G12*B12 -> 3 | I12: 1 | J12: =I12*B12 -> 5 | K12: 0.692
A13: Princeton | B13: 4 | C13: 12 | D13: 7 | E13: 17 | F13: =E13*B13 -> 68 | G13: 0 | H13: =G13*B13 -> 0 | I13: 1 | J13: =I13*B13 -> 4 | K13: 1
... A33: Iolani B | B33: 3 | C33: 9 | D33: 4 | E33: 0 | F33: =E33*B33 -> 0 | G33: 0.33 | H33: =G33*B33 -> 0.99 | I33: 0 | J33: =I33*B33 -> 0 | K33: 0.25

Sheet Round Robin Team ESS
A1: Catstats Hub | B1: gamesPlayed | C1: tuh | D1: buzzes | E1: ppg | F1: Total Points | G1: npg | H1: Total Negs | I1: bpg | J1: Total Bonuses | K1: accuracy
A2: North Hollywood | B2: 5 | C2: 20 | D2: 19 | E2: 28.8 | F2: =E2*B2 -> 144 | G2: 0.6 | H2: =G2*B2 -> 3 | I2: 2 | J2: =I2*B2 -> 10 | K2: 0.737
A3: Enloe | B3: 5 | C3: 20 | D3: 15 | E3: 28.4 | F3: =E3*B3 -> 142 | G3: 0 | H3: =G3*B3 -> 0 | I3: 1.8 | J3: =I3*B3 -> 9 | K3: 0.867
A4: Blair A | B4: 4 | C4: 16 | D4: 13 | E4: 33.5 | F4: =E4*B4 -> 134 | G4: 0 | H4: =G4*B4 -> 0 | I4: 2.25 | J4: =I4*B4 -> 9 | K4: 0.846
A5: Mission San Jose A | B5: 4 | C5: 17 | D5: 16 | E5: 32 | F5: =E5*B5 -> 128 | G5: 1 | H5: =G5*B5 -> 4 | I5: 2.5 | J5: =I5*B5 -> 10 | K5: 0.688
A6: James Clemens | B6: 4 | C6: 16 | D6: 14 | E6: 31.5 | F6: =E6*B6 -> 126 | G6: 0.25 | H6: =G6*B6 -> 1 | I6: 2.25 | J6: =I6*B6 -> 9 | K6: 0.714
A7: Iolani A | B7: 5 | C7: 20 | D7: 16 | E7: 22.4 | F7: =E7*B7 -> 112 | G7: 0.4 | H7: =G7*B7 -> 2 | I7: 1.6 | J7: =I7*B7 -> 8 | K7: 0.625
A8: Mission San Jose B | B8: 4 | C8: 16 | D8: 14 | E8: 28 | F8: =E8*B8 -> 112 | G8: 0.5 | H8: =G8*B8 -> 2 | I8: 2 | J8: =I8*B8 -> 8 | K8: 0.714
A9: Wayzata | B9: 4 | C9: 16 | D9: 13 | E9: 27 | F9: =E9*B9 -> 108 | G9: 0.5 | H9: =G9*B9 -> 2 | I9: 2 | J9: =I9*B9 -> 8 | K9: 0.692
A10: ASFA | B10: 5 | C10: 20 | D10: 17 | E10: 21.2 | F10: =E10*B10 -> 106 | G10: 0.4 | H10: =G10*B10 -> 2 | I10: 1.4 | J10: =I10*B10 -> 7 | K10: 0.647
A11: Canyon Crest A | B11: 4 | C11: 16 | D11: 13 | E11: 22 | F11: =E11*B11 -> 88 | G11: 0.5 | H11: =G11*B11 -> 2 | I11: 1.5 | J11: =I11*B11 -> 6 | K11: 0.692
A12: Brooklyn Tech A | B12: 5 | C12: 20 | D12: 14 | E12: 16 | F12: =E12*B12 -> 80 | G12: 0 | H12: =G12*B12 -> 0 | I12: 0.8 | J12: =I12*B12 -> 4 | K12: 0.714
A13: Basis Chandler | B13: 4 | C13: 16 | D13: 11 | E13: 18 | F13: =E13*B13 -> 72 | G13: 0 | H13: =G13*B13 -> 0 | I13: 1 | J13: =I13*B13 -> 4 | K13: 0.727
... A33: East Brunswick | B33: 4 | C33: 16 | D33: 5 | E33: 1 | F33: =E33*B33 -> 4 | G33: 0 | H33: =G33*B33 -> 0 | I33: 0 | J33: =I33*B33 -> 0 | K33: 0.2

Sheet Round Robin Team Math
A1: Catstats Hub | B1: gamesPlayed | C1: tuh | D1: buzzes | E1: ppg | F1: Total Points | G1: npg | H1: Total Negs | I1: bpg | J1: Total Bonuses | K1: accuracy
A2: Blair A | B2: 4 | C2: 16 | D2: 14 | E2: 36.5 | F2: =E2*B2 -> 146 | G2: 0 | H2: =G2*B2 -> 0 | I2: 2.25 | J2: =I2*B2 -> 9 | K2: 1
A3: School of Biology | B3: 4 | C3: 16 | D3: 15 | E3: 35 | F3: =E3*B3 -> 140 | G3: 0.5 | H3: =G3*B3 -> 2 | I3: 2.5 | J3: =I3*B3 -> 10 | K3: 0.8
A4: Iolani A | B4: 5 | C4: 20 | D4: 18 | E4: 26.4 | F4: =E4*B4 -> 132 | G4: 0.8 | H4: =G4*B4 -> 4 | I4: 2 | J4: =I4*B4 -> 10 | K4: 0.667
A5: Blair B | B5: 4 | C5: 16 | D5: 14 | E5: 30.5 | F5: =E5*B5 -> 122 | G5: 0.5 | H5: =G5*B5 -> 2 | I5: 2.25 | J5: =I5*B5 -> 9 | K5: 0.714
A6: Saratoga | B6: 5 | C6: 21 | D6: 14 | E6: 20.8 | F6: =E6*B6 -> 104 | G6: 0.2 | H6: =G6*B6 -> 1 | I6: 1.2 | J6: =I6*B6 -> 6 | K6: 0.857
A7: WWPS | B7: 5 | C7: 20 | D7: 18 | E7: 20 | F7: =E7*B7 -> 100 | G7: 1.2 | H7: =G7*B7 -> 6 | I7: 1.6 | J7: =I7*B7 -> 8 | K7: 0.611
A8: North Hollywood | B8: 5 | C8: 20 | D8: 18 | E8: 19.2 | F8: =E8*B8 -> 96 | G8: 0.6 | H8: =G8*B8 -> 3 | I8: 1.2 | J8: =I8*B8 -> 6 | K8: 0.667
A9: Mission San Jose A | B9: 4 | C9: 15 | D9: 15 | E9: 22.5 | F9: =E9*B9 -> 90 | G9: 0.25 | H9: =G9*B9 -> 1 | I9: 1.25 | J9: =I9*B9 -> 5 | K9: 0.733
A10: Enloe | B10: 5 | C10: 19 | D10: 13 | E10: 16.8 | F10: =E10*B10 -> 84 | G10: 0 | H10: =G10*B10 -> 0 | I10: 0.8 | J10: =I10*B10 -> 4 | K10: 0.846
A11: Lakeside | B11: 3 | C11: 12 | D11: 11 | E11: 27.33 | F11: =E11*B11 -> 81.99 | G11: 0.33 | H11: =G11*B11 -> 0.99 | I11: 1.67 | J11: =I11*B11 -> 5.01 | K11: 0.818
A12: Basis Silicon Valley | B12: 4 | C12: 16 | D12: 13 | E12: 19.5 | F12: =E12*B12 -> 78 | G12: 0.25 | H12: =G12*B12 -> 1 | I12: 1.25 | J12: =I12*B12 -> 5 | K12: 0.615
A13: James Clemens | B13: 4 | C13: 16 | D13: 13 | E13: 15.5 | F13: =E13*B13 -> 62 | G13: 0.5 | H13: =G13*B13 -> 2 | I13: 0.75 | J13: =I13*B13 -> 3 | K13: 0.769
... A33: Basis Chandler | B33: 4 | C33: 16 | D33: 7 | E33: 1 | F33: =E33*B33 -> 4 | G33: 0.75 | H33: =G33*B33 -> 3 | I33: 0 | J33: =I33*B33 -> 0 | K33: 0.571

Sheet Round Robin Team Physics
A1: Catstats Hub | B1: gamesPlayed | C1: tuh | D1: buzzes | E1: ppg | F1: Total Points | G1: npg | H1: Total Negs | I1: bpg | J1: Total Bonuses | K1: accuracy
A2: Blair A | B2: 4 | C2: 16 | D2: 14 | E2: 49 | F2: =E2*B2 -> 196 | G2: 0 | H2: =G2*B2 -> 0 | I2: 3.5 | J2: =I2*B2 -> 14 | K2: 1
A3: Enloe | B3: 5 | C3: 21 | D3: 16 | E3: 31.6 | F3: =E3*B3 -> 158 | G3: 0.2 | H3: =G3*B3 -> 1 | I3: 2.2 | J3: =I3*B3 -> 11 | K3: 0.813
A4: Iolani A | B4: 5 | C4: 20 | D4: 17 | E4: 29.2 | F4: =E4*B4 -> 146 | G4: 0.8 | H4: =G4*B4 -> 4 | I4: 2.2 | J4: =I4*B4 -> 11 | K4: 0.765
A5: North Hollywood | B5: 5 | C5: 20 | D5: 15 | E5: 28.8 | F5: =E5*B5 -> 144 | G5: 0.4 | H5: =G5*B5 -> 2 | I5: 2 | J5: =I5*B5 -> 10 | K5: 0.867
A6: Palo Alto | B6: 4 | C6: 16 | D6: 14 | E6: 31.5 | F6: =E6*B6 -> 126 | G6: 0.5 | H6: =G6*B6 -> 2 | I6: 2.25 | J6: =I6*B6 -> 9 | K6: 0.786
A7: James Clemens | B7: 4 | C7: 16 | D7: 14 | E7: 28 | F7: =E7*B7 -> 112 | G7: 0.5 | H7: =G7*B7 -> 2 | I7: 2 | J7: =I7*B7 -> 8 | K7: 0.714
A8: Basis Silicon Valley | B8: 4 | C8: 16 | D8: 11 | E8: 26 | F8: =E8*B8 -> 104 | G8: 0.5 | H8: =G8*B8 -> 2 | I8: 2 | J8: =I8*B8 -> 8 | K8: 0.727
A9: Blair B | B9: 4 | C9: 16 | D9: 10 | E9: 23.5 | F9: =E9*B9 -> 94 | G9: 0.5 | H9: =G9*B9 -> 2 | I9: 1.75 | J9: =I9*B9 -> 7 | K9: 0.8
A10: Canyon Crest A | B10: 4 | C10: 16 | D10: 12 | E10: 23 | F10: =E10*B10 -> 92 | G10: 0.25 | H10: =G10*B10 -> 1 | I10: 1.5 | J10: =I10*B10 -> 6 | K10: 0.75
A11: Mission San Jose A | B11: 4 | C11: 16 | D11: 14 | E11: 21.5 | F11: =E11*B11 -> 86 | G11: 1 | H11: =G11*B11 -> 4 | I11: 1.75 | J11: =I11*B11 -> 7 | K11: 0.571
A12: Princeton | B12: 4 | C12: 16 | D12: 13 | E12: 21 | F12: =E12*B12 -> 84 | G12: 0.75 | H12: =G12*B12 -> 3 | I12: 1.5 | J12: =I12*B12 -> 6 | K12: 0.692
A13: Brooklyn Tech A | B13: 5 | C13: 19 | D13: 14 | E13: 16 | F13: =E13*B13 -> 80 | G13: 0.6 | H13: =G13*B13 -> 3 | I13: 1.2 | J13: =I13*B13 -> 6 | K13: 0.571
... A33: Iolani B | B33: 3 | C33: 12 | D33: 8 | E33: 2.67 | F33: =E33*B33 -> 8.01 | G33: 0.33 | H33: =G33*B33 -> 0.99 | I33: 0 | J33: =I33*B33 -> 0 | K33: 0.375

Sheet Double Elimination Team Overall
A1: Catstats Hub | B1: gamesPlayed | C1: tuh | D1: buzzes | E1: ppg | F1: Total Points | G1: npg | H1: Total Negs | I1: bpg | J1: Total Bonuses | K1: accuracy
A2: Blair A | B2: 5 | C2: 115 | D2: 98 | E2: 132 | F2: =E2*B2 -> 660 | G2: 1 | H2: =G2*B2 -> 5 | I2: 8.4 | J2: =I2*B2 -> 42 | K2: 0.663
A3: Lakeside | B3: 7 | C3: 162 | D3: 103 | E3: 69.43 | F3: =E3*B3 -> 486.01 | G3: 1.43 | H3: =G3*B3 -> 10.01 | I3: 4.14 | J3: =I3*B3 -> 28.98 | K3: 0.573
A4: School of Biology | B4: 5 | C4: 115 | D4: 88 | E4: 82.8 | F4: =E4*B4 -> 414 | G4: 3.4 | H4: =G4*B4 -> 17 | I4: 5.8 | J4: =I4*B4 -> 29 | K4: 0.545
A5: Mission San Jose A | B5: 5 | C5: 115 | D5: 94 | E5: 78.4 | F5: =E5*B5 -> 392 | G5: 5.8 | H5: =G5*B5 -> 29 | I5: 6.4 | J5: =I5*B5 -> 32 | K5: 0.5
A6: Basis Silicon Valley | B6: 5 | C6: 116 | D6: 81 | E6: 64.4 | F6: =E6*B6 -> 322 | G6: 1.2 | H6: =G6*B6 -> 6 | I6: 3.4 | J6: =I6*B6 -> 17 | K6: 0.543
A7: James Clemens | B7: 5 | C7: 115 | D7: 93 | E7: 60.8 | F7: =E7*B7 -> 304 | G7: 2 | H7: =G7*B7 -> 10 | I7: 3.6 | J7: =I7*B7 -> 18 | K7: 0.441
A8: Canyon Crest A | B8: 4 | C8: 92 | D8: 63 | E8: 68 | F8: =E8*B8 -> 272 | G8: 1.75 | H8: =G8*B8 -> 7 | I8: 4 | J8: =I8*B8 -> 16 | K8: 0.556
