Workbook

Sheet Field
B2: Teams | C2: Paid?
B3: Mira North | C3: TRUE
B4: Iolani | C4: FALSE
B5: Blair Clemens | C5: TRUE
B6: Galen A | C6: FALSE
B7: VMATHS | C7: TRUE
B8: ASFA | C8: FALSE | D8: (extension)
B9: School of Geology | C9: FALSE
B10: North Hollywood A | C10: TRUE
B11: North Hollywood B | C11: TRUE
B12: Niskayuna | C12: TRUE
B13: Morgantown | C13: TRUE
B14: Lexington | C14: FALSE | D14: (extension)
B15: Palo Alto | C15: TRUE
B16: Chicken Jockies | C16: TRUE
B17: Chibbles | C17: TRUE
B18: Hunter | C18: TRUE
B19: Interlake | C19: TRUE
B20: Edwin's Victims | C20: TRUE
B21: JP Stevens A | C21: TRUE
B22: JP Stevens B | C22: TRUE
B23: LE SSERAFIM | C23: TRUE
B24: North Allegheny | C24: TRUE
B25: Seven Lakes A | C25: TRUE
B26: Seven Lakes B | C26: TRUE

Sheet RR Groups
A1: code | B1: Bohr | E1: Round Robin Groups
A2: b1 | B2: VMATHS
A3: b2 | B3: North Allegheny
A4: b3 | B4: Morgantown | F4: Bohr | G4: Curie | H4: Euler | I4: Feynman
A5: b4 | B5: Galen A | E5: 1 | F5: VMATHS | G5: Interlake | H5: JP Stevens A | I5: North Hollywood B
A6: b5 | B6: School of Geology | E6: 2 | F6: North Allegheny | G6: ASFA | H6: Chibbles | I6: Chicken Jockies
A7: b6 | B7: Seven Lakes B | E7: 3 | F7: Morgantown | G7: Niskayuna | H7: Hunter | I7: LE SSERAFIM
E8: 4 | F8: Galen A | G8: North Hollywood A | H8: Mira North | I8: Seven Lakes A
A9: code | B9: Curie | E9: 5 | F9: School of Geology | G9: JP Stevens B | H9: Lexington A | I9: Palo Alto
A10: c1 | B10: Interlake | E10: 6 | F10: Seven Lakes B | G10: Iolani | H10: Edwin's Victims | I10: Blair Clemens
A11: c2 | B11: ASFA
A12: c3 | B12: Niskayuna
A13: c4 | B13: North Hollywood A
A14: c5 | B14: JP Stevens B
A15: c6 | B15: Iolani
A17: code | B17: Euler
A18: e1 | B18: JP Stevens A
A19: e2 | B19: Chibbles
A20: e3 | B20: Hunter
A21: e4 | B21: Mira North
A22: e5 | B22: Lexington A
A23: e6 | B23: Edwin's Victims
... A31: f6 | B31: Blair Clemens
V81: roshanannamalaiisgoat

Sheet Schedule + Room Assignments
B2: Room | C2: RR 1 | D2: RR 2 | E2: RR 3 | F2: RR 4 | G2: RR 5 | I2: Time (PDT) | J2: Event
B3: Bohr 1 | C3: B1–B6 | D3: B2–B3 | E3: B5–B3 | F3: B4–B2 | G3: B3–B6 | I3: 7:45 - 8:00 AM | J3: Opening Ceremony
B4: Bohr 2 | C4: B2–B5 | D4: B6–B4 | E4: B1–B4 | F4: B5–B6 | G4: B1–B2 | I4: 8:00 - 8:30 AM | J4: Round Robin 1
B5: Bohr 3 | C5: B3–B4 | D5: B1–B5 | E5: B6–B2 | F5: B1–B3 | G5: B4–B5 | I5: 8:35-9:05 AM | J5: Round Robin 2
B6: Curie 1 | C6: C1–C6 | D6: C2–C3 | E6: C5–C3 | F6: C4–C2 | G6: C3–C6 | I6: 9:10- 9:40 AM | J6: Round Robin 3
B7: Curie 2 | C7: C2–C5 | D7: C6–C4 | E7: C1–C4 | F7: C5–C6 | G7: C1–C2 | I7: 9:45-10:15 AM | J7: Round Robin 4
B8: Curie 3 | C8: C3–C4 | D8: C1–C5 | E8: C6–C2 | F8: C1–C3 | G8: C4–C5 | I8: 10:20-10:50 AM | J8: Round Robin 5
B9: Euler 1 | C9: E1–E6 | D9: E2–E3 | E9: E5–E3 | F9: E4–E2 | G9: E3–E6 | I9: 10:55 - 11:55 AM | J9: Lunch Break
B10: Euler 2 | C10: E2–E5 | D10: E6–E4 | E10: E1–E4 | F10: E5–E6 | G10: E1–E2 | I10: 12:00 - 12:30 PM | J10: Double Elimination 1
B11: Euler 3 | C11: E3–E4 | D11: E1–E5 | E11: E6–E2 | F11: E1–E3 | G11: E4–E5 | I11: 12:35 - 1:05 PM | J11: Double Elimination 2
B12: Feynman 1 | C12: F1–F6 | D12: F2–F3 | E12: F5–F3 | F12: F4–F2 | G12: F3–F6 | I12: 1:10 - 1:40 PM | J12: Double Elimination 3
B13: Feynman 2 | C13: F2–F5 | D13: F6–F4 | E13: F1–F4 | F13: F5–F6 | G13: F1–F2 | I13: 1:45 - 2:15 PM | J13: Double Elimination 4
B14: Feynman 3 | C14: F3–F4 | D14: F1–F5 | E14: F6–F2 | F14: F1–F3 | G14: F4–F5 | I14: 2:20 - 2:50 PM | J14: Double Elimination 5
I15: 2:55 - 3:25 PM | J15: Double Elimination 6
I16: 3:30 - 4:00 PM | J16: Double Elimination 7
I17: 4:05- 4:35 PM | J17: Double Elimination 8
I18: 4:40-5:00 PM | J18: Closing Ceremony

Sheet RR Scores
B2: Bohr
B3: =AVERAGE(M4:M9) -> 101.73333 | C3: VMATHS | D3: North Allegheny | E3: Morgantown | F3: Galen A | G3: School of Geology | H3: Seven Lakes B | I3: Wins | J3: Ties | K3: Losses | L3: Points | M3: PPG | N3: RR Score
B4: VMATHS | D4: 158 | E4: 78 | F4: 102 | G4: 142 | H4: 164 | I4: =COUNTIF(K68:Q68,1) -> 4 | J4: =COUNTIF(K68:Q68,0.5) -> 0 | K4: =COUNTIF(K68:Q68,0) -> 1 | L4: =I4+0.5*J4 -> 4 | M4: =AVERAGE(C4:H4) -> 128.8 | N4: =(L4*500+M4*2*B3/(IF(AVERAGE($B$3, $B$12, $B$21, $B$30, $B$39)=0, 1, AVERAGE($B$3, $B$12, $B$21, $B$30, $B$39)))) -> 2266.2361
B5: North Allegheny | C5: 88 | E5: 166 | F5: 18 | G5: 70 | H5: 200 | I5: =COUNTIF(K69:Q69,1) -> 2 | J5: =COUNTIF(K69:Q69,0.5) -> 0 | K5: =COUNTIF(K69:Q69,0) -> 3 | L5: =I5+0.5*J5 -> 2 | M5: =AVERAGE(C5:H5) -> 108.4 | N5: =(L5*500+M5*2*B3/(IF(AVERAGE($B$3, $B$12, $B$21, $B$30, $B$39)=0, 1, AVERAGE($B$3, $B$12, $B$21, $B$30, $B$39)))) -> 1224.0683
B6: Morgantown | C6: 38 | D6: 66 | F6: 24 | G6: 46 | H6: 22 | I6: =COUNTIF(K70:Q70,1) -> 1 | J6: =COUNTIF(K70:Q70,0.5) -> 0 | K6: =COUNTIF(K70:Q70,0) -> 4 | L6: =I6+0.5*J6 -> 1 | M6: =AVERAGE(C6:H6) -> 39.2 | N6: =(L6*500+M6*2*B3/(IF(AVERAGE($B$3, $B$12, $B$21, $B$30, $B$39)=0, 1, AVERAGE($B$3, $B$12, $B$21, $B$30, $B$39)))) -> 581.02838
B7: Galen A | C7: 116 | D7: 130 | E7: 202 | G7: 110 | H7: 226 | I7: =COUNTIF(K71:Q71,1) -> 5 | J7: =COUNTIF(K71:Q71,0.5) -> 0 | K7: =COUNTIF(K71:Q71,0) -> 0 | L7: =I7+0.5*J7 -> 5 | M7: =AVERAGE(C7:H7) -> 156.8 | N7: =(L7*500+M7*2*B3/(IF(AVERAGE($B$3, $B$12, $B$21, $B$30, $B$39)=0, 1, AVERAGE($B$3, $B$12, $B$21, $B$30, $B$39)))) -> 2824.1135
B8: School of Geology | C8: 100 | D8: 214 | E8: 162 | F8: 46 | H8: 170 | I8: =COUNTIF(K72:Q72,1) -> 3 | J8: =COUNTIF(K72:Q72,0.5) -> 0 | K8: =COUNTIF(K72:Q72,0) -> 2 | L8: =I8+0.5*J8 -> 3 | M8: =AVERAGE(C8:H8) -> 138.4 | N8: =(L8*500+M8*2*B3/(IF(AVERAGE($B$3, $B$12, $B$21, $B$30, $B$39)=0, 1, AVERAGE($B$3, $B$12, $B$21, $B$30, $B$39)))) -> 1786.0798
B9: Seven Lakes B | C9: 42 | D9: 60 | E9: 46 | F9: 18 | G9: 28 | I9: =COUNTIF(K73:Q73,1) -> 0 | J9: =COUNTIF(K73:Q73,0.5) -> 0 | K9: =COUNTIF(K73:Q73,0) -> 5 | L9: =I9+0.5*J9 -> 0 | M9: =AVERAGE(C9:H9) -> 38.8 | N9: =(L9*500+M9*2*B3/(IF(AVERAGE($B$3, $B$12, $B$21, $B$30, $B$39)=0, 1, AVERAGE($B$3, $B$12, $B$21, $B$30, $B$39)))) -> 80.201558
B11: Curie
B12: =AVERAGE(M13:M18) -> 96.533333 | C12: Interlake | D12: ASFA | E12: Niskayuna | F12: North Hollywood A | G12: JP Stevens B | H12: Iolani | I12: Wins | J12: Ties | K12: Losses | L12: Points | M12: PPG | N12: RR Score
B13: Interlake | D13: 34 | E13: 102 | F13: 52 | G13: 162 | H13: 94 | I13: =COUNTIF(K77:Q77,1) -> 2 | J13: =COUNTIF(K77:Q77,0.5) -> 0 | K13: =COUNTIF(K77:Q77,0) -> 3 | L13: =I13+0.5*J13 -> 2 | M13: =AVERAGE(C13:H13) -> 88.8 | N13: =L13*500+M13*2*B12/(IF(AVERAGE($B$3, $B$12, $B$21, $B$30, $B$39)=0, 1, AVERAGE($B$3, $B$12, $B$21, $B$30, $B$39))) -> 1174.1719
B14: ASFA | C14: 154 | E14: 202 | F14: 94 | G14: 204 | H14: 172 | I14: =COUNTIF(K78:Q78,1) -> 5 | J14: =COUNTIF(K78:Q78,0.5) -> 0 | K14: =COUNTIF(K78:Q78,0) -> 0 | L14: =I14+0.5*J14 -> 5 | M14: =AVERAGE(C14:H14) -> 165.2 | N14: =L14*500+M14*2*B12/(IF(AVERAGE($B$3, $B$12, $B$21, $B$30, $B$39)=0, 1, AVERAGE($B$3, $B$12, $B$21, $B$30, $B$39))) -> 2824.0225
B15: Niskayuna | C15: 40 | D15: 70 | F15: 72 | G15: 116 | H15: 56 | I15: 1 | J15: =COUNTIF(K79:Q79,0.5) -> 0 | K15: 4 | L15: =I15+0.5*J15 -> 1 | M15: =AVERAGE(C15:H15) -> 70.8 | N15: =L15*500+M15*2*B12/(IF(AVERAGE($B$3, $B$12, $B$21, $B$30, $B$39)=0, 1, AVERAGE($B$3, $B$12, $B$21, $B$30, $B$39))) -> 638.86678
B16: North Hollywood A | C16: 162 | D16: 88 | E16: 168 | G16: 84 | H16: 144 | I16: =COUNTIF(K80:Q80,1) -> 4 | J16: =COUNTIF(K80:Q80,0.5) -> 0 | K16: =COUNTIF(K80:Q80,0) -> 1 | L16: =I16+0.5*J16 -> 4 | M16: =AVERAGE(C16:H16) -> 129.2 | N16: =L16*500+M16*2*B12/(IF(AVERAGE($B$3, $B$12, $B$21, $B$30, $B$39)=0, 1, AVERAGE($B$3, $B$12, $B$21, $B$30, $B$39))) -> 2253.4123
B17: JP Stevens B | C17: 56 | D17: 8 | E17: 42 | F17: 8 | H17: 32 | I17: =COUNTIF(K81:Q81,1) -> 0 | J17: =COUNTIF(K81:Q81,0.5) -> 0 | K17: =COUNTIF(K81:Q81,0) -> 5 | L17: =I17+0.5*J17 -> 0 | M17: =AVERAGE(C17:H17) -> 29.2 | N17: =L17*500+M17*2*B12/(IF(AVERAGE($B$3, $B$12, $B$21, $B$30, $B$39)=0, 1, AVERAGE($B$3, $B$12, $B$21, $B$30, $B$39))) -> 57.27274
B18: Iolani | C18: 166 | D18: 10 | E18: 88 | F18: 70 | G18: 146 | I18: 3 | J18: =COUNTIF(K82:Q82,0.5) -> 0 | K18: 2 | L18: =I18+0.5*J18 -> 3 | M18: =AVERAGE(C18:H18) -> 96 | N18: =L18*500+M18*2*B12/(IF(AVERAGE($B$3, $B$12, $B$21, $B$30, $B$39)=0, 1, AVERAGE($B$3, $B$12, $B$21, $B$30, $B$39))) -> 1688.2939
B20: Euler
B21: =AVERAGE(M22:M27) -> 98.2 | C21: JP Stevens A | D21: Chibbles | E21: Hunter | F21: Mira North | G21: Lexington A | H21: Edwin's Victims | I21: Wins | J21: Ties | K21: Losses | L21: Points | M21: PPG | N21: RR Score
B22: JP Stevens A | D22: 4 | E22: 18 | F22: 36 | G22: 66 | H22: 28 | I22: =COUNTIF(K86:Q86,1) -> 0 | J22: =COUNTIF(K86:Q86,0.5) -> 0 | K22: =COUNTIF(K86:Q86,0) -> 5 | L22: =I22+0.5*J22 -> 0 | M22: =AVERAGE(C22:H22) -> 30.4 | N22: =(L22*500+M22*2*B21/(IF(AVERAGE($B$3, $B$12, $B$21, $B$30, $B$39)=0, 1, AVERAGE($B$3, $B$12, $B$21, $B$30, $B$39)))) -> 60.655875
B23: Chibbles | C23: 176 | E23: 200 | F23: 74 | G23: 150 | H23: 122 | I23: =COUNTIF(K87:Q87,1) -> 4 | J23: =COUNTIF(K87:Q87,0.5) -> 0 | K23: =COUNTIF(K87:Q87,0) -> 1 | L23: =I23+0.5*J23 -> 4 | M23: =AVERAGE(C23:H23) -> 144.4 | N23: =(L23*500+M23*2*B21/(IF(AVERAGE($B$3, $B$12, $B$21, $B$30, $B$39)=0, 1, AVERAGE($B$3, $B$12, $B$21, $B$30, $B$39)))) -> 2288.1154
B24: Hunter | C24: 106 | D24: 24 | F24: 72 | G24: 98 | H24: 42 | I24: =COUNTIF(K88:Q88,1) -> 2 | J24: =COUNTIF(K88:Q88,0.5) -> 0 | K24: =COUNTIF(K88:Q88,0) -> 3 | L24: =I24+0.5*J24 -> 2 | M24: =AVERAGE(C24:H24) -> 68.4 | N24: =(L24*500+M24*2*B21/(IF(AVERAGE($B$3, $B$12, $B$21, $B$30, $B$39)=0, 1, AVERAGE($B$3, $B$12, $B$21, $B$30, $B$39)))) -> 1136.4757
B25: Mira North | C25: 174 | D25: 76 | E25: 182 | G25: 64 | H25: 92 | I25: =COUNTIF(K89:Q89,1) -> 4 | J25: =COUNTIF(K89:Q89,0.5) -> 0 | K25: =COUNTIF(K89:Q89,0) -> 1 | L25: =I25+0.5*J25 -> 4 | M25: =AVERAGE(C25:H25) -> 117.6 | N25: =(L25*500+M25*2*B21/(IF(AVERAGE($B$3, $B$12, $B$21, $B$30, $B$39)=0, 1, AVERAGE($B$3, $B$12, $B$21, $B$30, $B$39)))) -> 2234.6425
B26: Lexington A | C26: 170 | D26: 86 | E26: 90 | F26: 42 | H26: 108 | I26: =COUNTIF(K90:Q90,1) -> 2 | J26: =COUNTIF(K90:Q90,0.5) -> 0 | K26: =COUNTIF(K90:Q90,0) -> 3 | L26: =I26+0.5*J26 -> 2 | M26: =AVERAGE(C26:H26) -> 99.2 | N26: =(L26*500+M26*2*B21/(IF(AVERAGE($B$3, $B$12, $B$21, $B$30, $B$39)=0, 1, AVERAGE($B$3, $B$12, $B$21, $B$30, $B$39)))) -> 1197.9297
B27: Edwin's Victims | C27: 212 | D27: 106 | E27: 140 | F27: 152 | G27: 36 | I27: =COUNTIF(K91:Q91,1) -> 3 | J27: =COUNTIF(K91:Q91,0.5) -> 0 | K27: =COUNTIF(K91:Q91,0) -> 2 | L27: =I27+0.5*J27 -> 3 | M27: =AVERAGE(C27:H27) -> 129.2 | N27: =(L27*500+M27*2*B21/(IF(AVERAGE($B$3, $B$12, $B$21, $B$30, $B$39)=0, 1, AVERAGE($B$3, $B$12, $B$21, $B$30, $B$39)))) -> 1757.7875
B29: Feynman
B30: =AVERAGE(M31:M36) -> 97.266667 | C30: North Hollywood B | D30: Chicken Jockies | E30: LE SSERAFIM | F30: Seven Lakes A | G30: Palo Alto | H30: Blair Clemens | I30: Wins | J30: Ties | K30: Losses | L30: Points | M30: PPG | N30: RR Score
B31: North Hollywood B | D31: 128 | E31: 102 | F31: 144 | G31: 234 | H31: 126 | I31: =COUNTIF(L95:Q95,1) -> 4 | J31: =COUNTIF(K95:Q95,0.5) -> 0 | K31: =COUNTIF(K95:Q95,0) -> 1 | L31: =I31+0.5*J31 -> 4 | M31: =AVERAGE(C31:H31) -> 146.8 | N31: =(L31*500+M31*2*B30/(IF(AVERAGE($B$3, $B$12, $B$21, $B$30, $B$39)=0, 1, AVERAGE($B$3, $B$12, $B$21, $B$30, $B$39)))) -> 2290.1201
B32: Chicken Jockies | C32: 28 | E32: 72 | F32: 52 | G32: 86 | H32: 46 | I32: =COUNTIF(K96:Q96,1) -> 0 | J32: =COUNTIF(K96:Q96,0.5) -> 0 | K32: =COUNTIF(K96:Q96,0) -> 5 | L32: =I32+0.5*J32 -> 0 | M32: =AVERAGE(C32:H32) -> 56.8 | N32: =(L32*500+M32*2*B30/(IF(AVERAGE($B$3, $B$12, $B$21, $B$30, $B$39)=0, 1, AVERAGE($B$3, $B$12, $B$21, $B$30, $B$39)))) -> 112.25357
B33: LE SSERAFIM | C33: 54 | D33: 76 | F33: 54 | G33: 42 | H33: 6 | I33: =COUNTIF(K97:Q97,1) -> 1 | J33: =COUNTIF(K97:Q97,0.5) -> 0 | K33: =COUNTIF(K97:Q97,0) -> 4 | L33: =I33+0.5*J33 -> 1 | M33: =AVERAGE(C33:H33) -> 46.4 | N33: =(L33*500+M33*2*B30/(IF(AVERAGE($B$3, $B$12, $B$21, $B$30, $B$39)=0, 1, AVERAGE($B$3, $B$12, $B$21, $B$30, $B$39)))) -> 591.7001
B34: Seven Lakes A | C34: 54 | D34: 142 | E34: 142 | G34: 90 | H34: 60 | I34: =COUNTIF(K98:Q98,1) -> 2 | J34: =COUNTIF(K98:Q98,0.5) -> 0 | K34: =COUNTIF(K98:Q98,0) -> 3 | L34: =I34+0.5*J34 -> 2 | M34: =AVERAGE(C34:H34) -> 97.6 | N34: =(L34*500+M34*2*B30/(IF(AVERAGE($B$3, $B$12, $B$21, $B$30, $B$39)=0, 1, AVERAGE($B$3, $B$12, $B$21, $B$30, $B$39)))) -> 1192.8864
B35: Palo Alto | C35: 48 | D35: 102 | E35: 100 | F35: 120 | H35: 40 | I35: =COUNTIF(K99:Q99,1) -> 3 | J35: =COUNTIF(K99:Q99,0.5) -> 0 | K35: =COUNTIF(K99:Q99,0) -> 2 | L35: =I35+0.5*J35 -> 3 | M35: =AVERAGE(C35:H35) -> 82 | N35: =(L35*500+M35*2*B30/(IF(AVERAGE($B$3, $B$12, $B$21, $B$30, $B$39)=0, 1, AVERAGE($B$3, $B$12, $B$21, $B$30, $B$39)))) -> 1662.0562
B36: Blair Clemens | C36: 144 | D36: 168 | E36: 144 | F36: 204 | G36: 110 | I36: =COUNTIF(K100:Q100,1) -> 5 | J36: =COUNTIF(K100:Q100,0.5) -> 0 | K36: =COUNTIF(K100:Q100,0) -> 0 | L36: =I36+0.5*J36 -> 5 | M36: =AVERAGE(C36:H36) -> 154 | N36: =(L36*500+M36*2*B30/(IF(AVERAGE($B$3, $B$12, $B$21, $B$30, $B$39)=0, 1, AVERAGE($B$3, $B$12, $B$21, $B$30, $B$39)))) -> 2804.3495
C67: =B3 -> 101.73333 | D67: {=TRANSPOSE(C68:C73)} -> VMATHS | E67: North Allegheny | F67: Morgantown | G67: Galen A | H67: School of Geology | I67: Seven Lakes B | L67: {=transpose(K68:K73)} -> VMATHS | M67: North Allegheny | N67: Morgantown | O67: Galen A | P67: School of Geology | Q67: Seven Lakes B
C68: =B4 -> VMATHS | D68: =C4 | E68: =D4 -> 158 | F68: =E4 -> 78 | G68: =F4 -> 102 | H68: =G4 -> 142 | I68: =H4 -> 164 | K68: =C68 -> VMATHS | M68: =IF(E68>D69, 1, IF(E68=D69, 0.5, 0)) -> 1 | N68: =IF(F68>D70, 1, IF(F68=D70, 0.5, 0)) -> 1 | O68: =IF(G68>D71, 1, IF(G68=D71, 0.5, 0)) -> 0 | P68: =IF(H68>D72, 1, IF(H68=D72, 0.5, 0)) -> 1 | Q68: =IF(I68>D73, 1, IF(I68=D73, 0.5, 0)) -> 1
C69: =B5 -> North Allegheny | D69: =C5 -> 88 | E69: =D5 | F69: =E5 -> 166 | G69: =F5 -> 18 | H69: =G5 -> 70 | I69: =H5 -> 200 | K69: =C69 -> North Allegheny | L69: =1-M68 -> 0 | N69: =IF(F69>E70, 1, IF(F69=E70, 0.5, 0)) -> 1 | O69: =IF(G69>E71, 1, IF(G69=E71, 0.5, 0)) -> 0 | P69: =IF(H69>E72, 1, IF(H69=E72, 0.5, 0)) -> 0 | Q69: =IF(I69>E73, 1, IF(I69=E73, 0.5, 0)) -> 1
C70: =B6 -> Morgantown | D70: =C6 -> 38 | E70: =D6 -> 66 | F70: =E6 | G70: =F6 -> 24 | H70: =G6 -> 46 | I70: =H6 -> 22 | K70: =C70 -> Morgantown | L70: =1-N68 -> 0 | M70: =1-N69 -> 0 | O70: =IF(G70>F71, 1, IF(G70=F71, 0.5, 0)) -> 0 | P70: =IF(H70>F72, 1, IF(H70=F72, 0.5, 0)) -> 0 | Q70: =IF(I70>F74, 1, IF(I70=F74, 0.5, 0)) -> 1
C71: =B7 -> Galen A | D71: =C7 -> 116 | E71: =D7 -> 130 | F71: =E7 -> 202 | G71: =F7 | H71: =G7 -> 110 | I71: =H7 -> 226 | K71: =C71 -> Galen A | L71: =1-O68 -> 1 | M71: =1-O69 -> 1 | N71: =1-O70 -> 1 | P71: =IF(H71>G72, 1, IF(H71=G72, 0.5, 0)) -> 1 | Q71: =IF(I71>G73, 1, IF(I71=G73, 0.5, 0)) -> 1
C72: =B8 -> School of Geology | D72: =C8 -> 100 | E72: =D8 -> 214 | F72: =E8 -> 162 | G72: =F8 -> 46 | H72: =G8 | I72: =H8 -> 170 | K72: =C72 -> School of Geology | L72: =1-P68 -> 0 | M72: =1-P69 -> 1 | N72: =1-P70 -> 1 | O72: =1-P71 -> 0 | Q72: =IF(I72>H73, 1, IF(I72=H73, 0.5, 0)) -> 1
C73: =B9 -> Seven Lakes B | D73: =C9 -> 42 | E73: =D9 -> 60 | F73: =E9 -> 46 | G73: =F9 -> 18 | H73: =G9 -> 28 | I73: =H9 | K73: =C73 -> Seven Lakes B | L73: =1-Q68 -> 0 | M73: =1-Q69 -> 0 | N73: =1-Q70 -> 0 | O73: =1-Q71 -> 0 | P73: =1-Q72 -> 0
D76: {=TRANSPOSE(C77:C82)} -> Interlake | E76: ASFA | F76: Niskayuna | G76: North Hollywood A | H76: JP Stevens B | I76: Iolani | L76: {=transpose(K77:K82)} -> Interlake | M76: ASFA | N76: Niskayuna | O76: North Hollywood A | P76: JP Stevens B | Q76: Iolani
...

Sheet DE Seeding
B2: Team | C2: RR Score | E2: Team | F2: RR Score | G2: DE Seed
B3: ='RR Scores'!B4 -> VMATHS | C3: ='RR Scores'!N4 -> 2266.2361 | E3: {=SORT(B3:C38, 2, FALSE)} -> #REF! | F3: #REF! | G3: 1
B4: ='RR Scores'!B5 -> North Allegheny | C4: ='RR Scores'!N5 -> 1224.0683 | E4: #REF! | F4: #REF! | G4: =1+G3 -> 2
B5: ='RR Scores'!B6 -> Morgantown | C5: ='RR Scores'!N6 -> 581.02838 | E5: #REF! | F5: #REF! | G5: =1+G4 -> 3
B6: ='RR Scores'!B7 -> Galen A | C6: ='RR Scores'!N7 -> 2824.1135 | E6: #REF! | F6: #REF! | G6: =1+G5 -> 4
B7: ='RR Scores'!B8 -> School of Geology | C7: ='RR Scores'!N8 -> 1786.0798 | E7: #REF! | F7: #REF! | G7: =1+G6 -> 5
B8: ='RR Scores'!B9 -> Seven Lakes B | C8: ='RR Scores'!N9 -> 80.201558 | E8: #REF! | F8: #REF! | G8: =1+G7 -> 6
B9: ='RR Scores'!B13 -> Interlake | C9: ='RR Scores'!N13 -> 1174.1719 | E9: Galen A | F9: 2824.1135 | G9: 1
B10: ='RR Scores'!B14 -> ASFA | C10: ='RR Scores'!N14 -> 2824.0225 | E10: ASFA | F10: 2824.0225 | G10: 2
B11: ='RR Scores'!B15 -> Niskayuna | C11: ='RR Scores'!N15 -> 638.86678 | E11: Blair Clemens | F11: 2804.3495 | G11: =1+G10 -> 3
B12: ='RR Scores'!B16 -> North Hollywood A | C12: ='RR Scores'!N16 -> 2253.4123 | E12: North Hollywood B | F12: 2290.1201 | G12: =1+G11 -> 4
B13: ='RR Scores'!B17 -> JP Stevens B | C13: ='RR Scores'!N17 -> 57.27274 | E13: Chibbles | F13: 2288.1154 | G13: =1+G12 -> 5
B14: ='RR Scores'!B18 -> Iolani | C14: ='RR Scores'!N18 -> 1688.2939 | E14: VMATHS | F14: 2266.2361 | G14: =1+G13 -> 6
B15: ='RR Scores'!B22 -> JP Stevens A | C15: ='RR Scores'!N22 -> 60.655875 | E15: North Hollywood A | F15: 2253.4123 | G15: =1+G14 -> 7
B16: ='RR Scores'!B23 -> Chibbles | C16: ='RR Scores'!N23 -> 2288.1154 | E16: Mira North | F16: 2234.6425 | G16: =1+G15 -> 8
B17: ='RR Scores'!B24 -> Hunter | C17: ='RR Scores'!N24 -> 1136.4757 | E17: School of Geology | F17: 1786.0798 | G17: =1+G16 -> 9
B18: ='RR Scores'!B25 -> Mira North | C18: ='RR Scores'!N25 -> 2234.6425 | E18: Edwin's Victims | F18: 1757.7875 | G18: =1+G17 -> 10
B19: ='RR Scores'!B26 -> Lexington A | C19: ='RR Scores'!N26 -> 1197.9297 | E19: Iolani | F19: 1688.2939 | G19: 11
B20: ='RR Scores'!B27 -> Edwin's Victims | C20: ='RR Scores'!N27 -> 1757.7875 | E20: Palo Alto | F20: 1662.0562 | G20: 12
B21: ='RR Scores'!B31 -> North Hollywood B | C21: ='RR Scores'!N31 -> 2290.1201 | E21: North Allegheny | F21: 1224.0683 | G21: 13
B22: ='RR Scores'!B32 -> Chicken Jockies | C22: ='RR Scores'!N32 -> 112.25357 | E22: Lexington A | F22: 1197.9297 | G22: 14
B23: ='RR Scores'!B33 -> LE SSERAFIM | C23: ='RR Scores'!N33 -> 591.7001 | E23: Seven Lakes A | F23: 1192.8864 | G23: 15
B24: ='RR Scores'!B34 -> Seven Lakes A | C24: ='RR Scores'!N34 -> 1192.8864 | E24: Interlake | F24: 1174.1719 | G24: 16
B25: ='RR Scores'!B35 -> Palo Alto | C25: ='RR Scores'!N35 -> 1662.0562 | E25: Hunter | F25: 1136.4757
B26: ='RR Scores'!B36 -> Blair Clemens | C26: ='RR Scores'!N36 -> 2804.3495 | E26: Niskayuna | F26: 638.86678
B27: ='RR Scores'!B40 | C27: ='RR Scores'!N40 | E27: LE SSERAFIM | F27: 591.7001
B28: ='RR Scores'!B41 | C28: ='RR Scores'!N41 | E28: Morgantown | F28: 581.02838
B29: ='RR Scores'!B42 | C29: ='RR Scores'!N42 | E29: Chicken Jockies | F29: 112.25357
B30: ='RR Scores'!B43 | C30: ='RR Scores'!N43 | E30: Seven Lakes B | F30: 80.201558
B31: ='RR Scores'!B44 | C31: ='RR Scores'!N44 | E31: JP Stevens A | F31: 60.655875
B32: ='RR Scores'!B45 | C32: ='RR Scores'!N45 | E32: JP Stevens B | F32: 57.27274
B33: =#REF! -> #REF! | C33: =#REF! -> #REF!
B34: =#REF! -> #REF! | C34: =#REF! -> #REF!
B35: =#REF! -> #REF! | C35: =#REF! -> #REF!
B36: =#REF! -> #REF! | C36: =#REF! -> #REF!
B37: =#REF! -> #REF! | C37: =#REF! -> #REF!
B38: =#REF! -> #REF! | C38: =#REF! -> #REF!

Sheet DE Bracket
A1: 12:00-12:30 | C1: 12:30-1:00 | E1: 1:00-1:30 | G1: 1:30-2:00 | I1: 2:00-2:30 | K1: 2:30-3:00 | M1: 3:00-3:30 | O1: 3:30-4:00 | R1: 4:00-4:30
A2: TIMES IN PST | C2: Bracket from ISCBT 2: ICSBT2 Tournament Hub
A4: Galen A 1 | E4: Galen A | F4: 32
A5: Room 1 | C5: Galen A | E5: ROOM 1 | I5: School of Geology
A6: Interlake 16 | E6: School of Geology | F6: 138
I7: ROOM 1 | M7: SOG
A8: Mira North 8 | B8: 38 | E8: Noho B | F8: 24
A9: DE Room 2 | C9: School of Geology | E9: ROOM 2 | I9: Chibbles
A10: School of Geology 9 | B10: 144 | E10: Chibbles | F10: 96
M11: STAGE 1 | O11: SOG | R11: SOG
A12: North Hollywood B 4 | E12: Seven Lakes A | F12: 56
A13: DE Room 3 | C13: Noho B | E13: ROOM 3 | I13: Noho A
A14: North Allegheny 13 | E14: Noho A | F14: 130
I15: ROOM 2 | M15: Noho A
A16: Chibbles 5 | B16: 120 | E16: Blair Clemens 3 | F16: 32 | Q16: STAGE 1
A17: DE Room 4 | C17: Chibbles | E17: ROOM 4 | I17: VMATHS
A18: Palo Alto 12 | B18: 40 | E18: VMATHS | F18: 104 | O18: Noho A | R18: Winners!
R19: SOG
A20: ASFA 2 | B20: 90
A21: DE Room 5 | C21: Seven Lakes A
A22: Seven Lakes A 15 | B22: 110 | K22: VMATHS
A24: North Hollywood A 7 | G24: Blair Clemens | H24: 108
A25: DE Room 6 | C25: North Hollywood A 7
A26: Edwin's Victims 10 | G26: ROOM 1 | I26: Blair Clemens | K26: ROOM 1 | M26: Seven Lakes A | N26: 50 | R26: Iolani
E27: Interlake | F27: 16
A28: Blair Clemens 3 | B28: 90 | E28: ROOM 5 | G28: Mira North | H28: 14 | O28: STAGE 1
A29: DE Room 7 | C29: Blair Clemens 3 | E29: Mira North | F29: 120
A30: Lexington A 14 | B30: 28 | I30: ROOM 3 | K30: Seven Lakes A
A32: VMATHS 6 | B32: 122 | G32: Seven Lakes A | H32: 100
A33: DE Room 8 | C33: VMaths
A34: Iolani 11 | B34: 90 | G34: ROOM 2 | I34: Seven Lakes A | M34: STAGE 2 | O34: Iolani
E35: North Allegheny | F35: 60
E36: ROOM 6 | G36: Palo Alto | H36: 26
E37: Palo Alto | F37: 82
K38: Chibbles | L38: 40
G40: Noho B
G42: ROOM 3 | I42: Edwin's Victims | K42: ROOM 2 | M42: Iolani | N42: 74
E43: ASFA | F43: 78
E44: ROOM 7 | G44: Edwin's Victims
E45: Edwin's Victims | F45: 148
...
