Workbook

Sheet All
A1: Bethlehem | B1: Bethlehem | C1: Bethlehem | D1: Bethlehem | E1: Bethlehem | F1: BHBL B | G1: BHBL B | H1: BHBL B | I1: BHBL B | J1: BHBL B | K1: Niskayuna A | L1: Niskayuna A | M1: Niskayuna A | N1: Niskayuna A | O1: Niskayuna A | P1: Shen C | Q1: Shen C | R1: Shen C | S1: Shen C | T1: Shen C | U1: BHBL A | V1: BHBL A | W1: BHBL A | X1: BHBL A | Y1: BHBL A | Z1: Niskayuna B | AA1: Niskayuna B | AB1: Niskayuna B | AC1: Niskayuna B | AD1: Niskayuna B | AE1: CBA | AF1: CBA | AG1: CBA | AH1: CBA | AI1: CBA | AJ1: Shen B | AK1: Shen B | AL1: Shen B | AM1: Shen B | AN1: Shen B | AO1: Morris Hills | AP1: Morris Hills | AQ1: Morris Hills | AR1: Morris Hills | AS1: Morris Hills | AT1: WWPN | AU1: WWPN | AV1: WWPN | AW1: WWPN | AX1: WWPN
A2: Kevin | B2: Ian | F2: Nicole | G2: Wyatt | H2: Liam | I2: Lily | J2: Matt | K2: Mihir | L2: Tarun | M2: Arjun | N2: Faiz | O2: Daniel | P2: Joseph | Q2: Jamis | R2: Ankur | S2: Karl | T2: Matthew | U2: Myles | V2: Chad | W2: Jack | X2: Madeline | Z2: Iris | AA2: Alex | AB2: Aarush | AC2: Cheuk | AD2: James | AE2: Kagame | AF2: Asif | AG2: Colin | AH2: Hubert | AI2: Ethan | AJ2: Aivin | AK2: Jo | AL2: Jacob | AM2: Kevin | AN2: Aakaash | AO2: Aditya | AP2: Brendan | AQ2: Eashan | AT2: Shreyash | AU2: Rithik | AV2: Arjun | AW2: Aldric
A3: TRUE | B3: TRUE | C3: FALSE | D3: FALSE | E3: FALSE | F3: TRUE | G3: TRUE | H3: TRUE | I3: TRUE | J3: TRUE | K3: TRUE | L3: FALSE | M3: TRUE | N3: TRUE | O3: TRUE | P3: TRUE | Q3: TRUE | R3: TRUE | S3: TRUE | T3: FALSE | U3: TRUE | V3: TRUE | W3: TRUE | X3: TRUE | Y3: FALSE | Z3: TRUE | AA3: TRUE | AB3: TRUE | AC3: TRUE | AD3: FALSE | AE3: TRUE | AF3: TRUE | AG3: TRUE | AH3: TRUE | AI3: TRUE | AJ3: TRUE | AK3: TRUE | AL3: TRUE | AM3: TRUE | AN3: TRUE | AO3: FALSE | AP3: FALSE | AQ3: FALSE | AR3: FALSE | AS3: FALSE | AT3: FALSE | AU3: FALSE | AV3: FALSE | AW3: FALSE | AX3: FALSE
A4: 4 | C4: 0 | D4: 0 | E4: 0 | K4: 0 | L4: 0 | S4: 0 | T4: 0 | W4: 4 | Y4: 0 | AA4: -4 | AD4: 0
B5: 4 | C5: 0 | D5: 0 | E5: 0 | L5: 0 | M5: 4 | T5: 0 | Y5: 0 | AC5: 4 | AD5: 0 | AG5: 4
C6: 0 | D6: 0 | E6: 0 | L6: 0 | N6: 4 | T6: 0 | Y6: 0 | AB6: 0 | AD6: 0
C7: 0 | D7: 0 | E7: 0 | L7: 0 | P7: 4 | T7: 0 | Y7: 0 | AA7: 4 | AD7: 0 | AF7: 0 | AK7: 4
A8: 4 | C8: 0 | D8: 0 | E8: 0 | K8: 0 | L8: 0 | R8: 0 | T8: 0 | X8: 0 | Y8: 0 | AB8: 0 | AD8: 0 | AJ8: 4
C9: 0 | D9: 0 | E9: 0 | I9: 4 | L9: 0 | P9: 4 | T9: 0 | W9: 0 | Y9: 0 | AB9: 0 | AD9: 0 | AJ9: 4
C10: 0 | D10: 0 | E10: 0 | L10: 0 | S10: 4 | T10: 0 | Y10: 0 | Z10: 4 | AD10: 0 | AM10: 4
C11: 0 | D11: 0 | E11: 0 | G11: 4 | K11: 0 | L11: 0 | R11: 0 | T11: 0 | Y11: 0 | AD11: 0 | AE11: 4 | AJ11: 0
A12: 4 | C12: 0 | D12: 0 | E12: 0 | L12: 0 | N12: 4 | T12: 0 | Y12: 0 | Z12: 4 | AD12: 0 | AI12: 4 | AJ12: 0
C13: 0 | D13: 0 | E13: 0 | L13: 0 | P13: 4 | T13: 0 | Y13: 0 | AB13: 4 | AD13: 0 | AH13: 0 | AJ13: 0
C14: 0 | D14: 0 | E14: 0 | H14: 4 | K14: 0 | L14: 0 | R14: 0 | T14: 0 | V14: 0 | Y14: 0 | Z14: 4 | AD14: 0 | AF14: 0 | AN14: 4
C15: 0 | D15: 0 | E15: 0 | L15: 0 | Q15: 4 | T15: 0 | W15: 0 | Y15: 0 | AB15: 4 | AD15: 0 | AI15: 4
A16: TRUE | B16: TRUE | C16: FALSE | D16: FALSE | E16: FALSE | F16: TRUE | G16: TRUE | H16: TRUE | I16: TRUE | J16: TRUE | K16: TRUE | L16: FALSE | M16: TRUE | N16: TRUE | O16: TRUE | P16: TRUE | Q16: TRUE | R16: TRUE | S16: TRUE | T16: FALSE | U16: TRUE | V16: TRUE | W16: TRUE | X16: TRUE | Y16: FALSE | Z16: TRUE | AA16: TRUE | AB16: TRUE | AC16: TRUE | AD16: FALSE | AE16: TRUE | AF16: TRUE | AG16: TRUE | AH16: TRUE | AI16: TRUE | AJ16: TRUE | AK16: TRUE | AL16: TRUE | AM16: TRUE | AN16: TRUE | AO16: FALSE | AP16: FALSE | AQ16: FALSE | AR16: FALSE | AS16: FALSE | AT16: FALSE | AU16: FALSE | AV16: FALSE | AW16: FALSE | AX16: FALSE
C17: 0 | D17: 0 | E17: 0 | H17: 4 | L17: 0 | S17: 4 | T17: 0 | Y17: 0 | AC17: 4 | AD17: 0 | AN17: 4
C18: 0 | D18: 0 | E18: 0 | H18: 4 | L18: 0 | M18: 4 | T18: 0 | V18: 4 | Y18: 0 | AD18: 0 | AE18: 0 | AK18: 0
B19: 4 | C19: 0 | D19: 0 | E19: 0 | L19: 0 | N19: 4 | T19: 0 | V19: 0 | Y19: 0 | Z19: 4 | AD19: 0 | AH19: 0 | AJ19: 0
C20: 0 | D20: 0 | E20: 0 | K20: 0 | L20: 0 | P20: 0 | T20: 0 | Y20: 0 | AA20: 4 | AD20: 0 | AK20: 0
B21: 4 | C21: 0 | D21: 0 | E21: 0 | L21: 0 | M21: 4 | T21: 0 | Y21: 0 | AB21: 4 | AD21: 0 | AM21: 4
C22: 0 | D22: 0 | E22: 0 | H22: 4 | L22: 0 | R22: 4 | T22: 0 | V22: 4 | Y22: 0 | AD22: 0 | AH22: 4
C23: 0 | D23: 0 | E23: 0 | L23: 0 | T23: 0 | V23: 0 | Y23: 0 | AB23: 0 | AD23: 0 | AG23: 0 | AJ23: 0
C24: 0 | D24: 0 | E24: 0 | H24: 4 | L24: 0 | R24: 4 | T24: 0 | Y24: 0 | AC24: 4 | AD24: 0 | AJ24: 4
B25: 4 | C25: 0 | D25: 0 | E25: 0 | H25: -4 | L25: 0 | N25: 4 | T25: 0 | V25: -4 | Y25: 0 | AC25: 4 | AD25: 0 | AJ25: 4
C26: 0 | D26: 0 | E26: 0 | L26: 0 | M26: 4 | T26: 0 | Y26: 0 | AA26: 4 | AD26: 0 | AJ26: 4
C27: 0 | D27: 0 | E27: 0 | L27: 0 | O27: 4 | T27: 0 | Y27: 0 | AB27: 0 | AD27: 0 | AK27: 4
B28: 4 | C28: 0 | D28: 0 | E28: 0 | L28: 0 | P28: 4 | T28: 0 | Y28: 0 | AC28: 4 | AD28: 0 | AL28: 4
A31: Morris Hills | B31: Morris Hills | C31: Morris Hills | D31: Morris Hills | E31: Morris Hills | F31: Niskayuna A | G31: Niskayuna A | H31: Niskayuna A | I31: Niskayuna A | J31: Niskayuna A | K31: BHBL B | L31: BHBL B | M31: BHBL B | N31: BHBL B | O31: BHBL B | P31: Shen C | Q31: Shen C | R31: Shen C | S31: Shen C | T31: Shen C | U31: WWPN | V31: WWPN | W31: WWPN | X31: WWPN | Y31: WWPN | Z31: Shen B | AA31: Shen B | AB31: Shen B | AC31: Shen B | AD31: Shen B | AE31: CBA | AF31: CBA | AG31: CBA | AH31: CBA | AI31: CBA | AJ31: Niskayuna B | AK31: Niskayuna B | AL31: Niskayuna B | AM31: Niskayuna B | AN31: Niskayuna B | AO31: Bethlehem | AP31: Bethlehem | AQ31: Bethlehem | AR31: Bethlehem | AS31: Bethlehem | AT31: BHBL A | AU31: BHBL A | AV31: BHBL A | AW31: BHBL A | AX31: BHBL A
A32: Aditya | B32: Brendan | C32: Eashan | F32: Mihir | G32: Tarun | H32: Arjun | I32: Faiz | J32: Daniel | K32: Nicole | L32: Wyatt | M32: Liam | N32: Lily | O32: Matt | P32: Joseph | Q32: Jamis | R32: Ankur | S32: Karl | T32: Matthew | U32: Shreyash | V32: Rithik | W32: Arjun | X32: Aldric | Z32: Aivin | AA32: Jo | AB32: Jacob | AC32: Kevin | AD32: Aakaash | AE32: Kagame | AF32: Asif | AG32: Colin | AH32: Hubert | AI32: Ethan | AJ32: Iris | AK32: Alex | AL32: Aarush | AM32: Cheuk | AN32: James | AO32: Kevin | AP32: Ian | AT32: Myles | AU32: Chad | AV32: Jack | AW32: Madeline
A33: TRUE | B33: TRUE | C33: TRUE | D33: FALSE | E33: FALSE | F33: TRUE | G33: FALSE | H33: TRUE | I33: TRUE | J33: TRUE | K33: TRUE | L33: TRUE | M33: TRUE | N33: TRUE | O33: TRUE | P33: TRUE | Q33: TRUE | R33: TRUE | S33: TRUE | T33: TRUE | U33: TRUE | V33: TRUE | W33: TRUE | X33: TRUE | Y33: FALSE | Z33: TRUE | AA33: TRUE | AB33: TRUE | AC33: TRUE | AD33: TRUE | AE33: TRUE | AF33: TRUE | AG33: TRUE | AH33: TRUE | AI33: TRUE | AJ33: TRUE | AK33: TRUE | AL33: TRUE | AM33: TRUE | AN33: FALSE | AO33: FALSE | AP33: FALSE | AQ33: FALSE | AR33: FALSE | AS33: FALSE | AT33: FALSE | AU33: FALSE | AV33: FALSE | AW33: FALSE | AX33: FALSE
A34: 4 | D34: 0 | E34: 0 | G34: 0 | Q34: 4 | X34: 4 | Y34: 0 | AE34: 0 | AK34: 4 | AN34: 0
D35: 0 | E35: 0 | G35: 0 | H35: 4 | R35: 4 | V35: 4 | Y35: 0 | AL35: 4 | AN35: 0
B36: 4 | D36: 0 | E36: 0 | G36: 0 | M36: 4 | Y36: 0 | AG36: 4 | AN36: 0
D37: 0 | E37: 0 | G37: 0 | J37: 4 | Q37: 4 | U37: 4 | Y37: 0 | AK37: 4 | AN37: 0
D38: 0 | E38: 0 | G38: 0 | H38: 4 | X38: 4 | Y38: 0 | AJ38: 4 | AN38: 0
D39: 0 | E39: 0 | G39: 0 | I39: 4 | K39: 4 | X39: 4 | Y39: 0 | AI39: 0 | AM39: 4 | AN39: 0
D40: 0 | E40: 0 | G40: 0 | J40: 4 | X40: 4 | Y40: 0 | AK40: 4 | AN40: 0
D41: 0 | E41: 0 | G41: 0 | L41: 4 | V41: 4 | Y41: 0 | AN41: 0
D42: 0 | E42: 0 | G42: 0 | M42: 4 | Y42: 0 | Z42: 4 | AN42: 0
...

Sheet Sorted
B1: Shen B | C1: Niskayuna B | D1: Morris Hills | E1: Shen B | F1: WWPN | G1: Niskayuna B | H1: Shen C | I1: Niskayuna A | J1: WWPN | K1: CBA | L1: Morris Hills | M1: BHBL A | N1: Niskayuna B | O1: CBA | P1: Niskayuna A | Q1: Morris Hills | R1: CBA | S1: Niskayuna A | T1: CBA | U1: Bethlehem | V1: Niskayuna B | W1: BHBL A | X1: Shen B | Y1: Niskayuna B | Z1: Shen C | AA1: Shen B | AB1: Shen C | AC1: CBA | AD1: Shen C | AE1: Bethlehem | AF1: Shen B | AG1: BHBL B | AH1: BHBL B | AI1: BHBL A | AJ1: BHBL B | AK1: Shen C | AL1: Niskayuna A | AM1: BHBL A | AN1: BHBL B | AO1: WWPN | AP1: WWPN | AQ1: Niskayuna A | AR1: BHBL B | AS1: Bethlehem | AT1: Bethlehem | AU1: Bethlehem | AV1: BHBL A | AW1: Morris Hills | AX1: Morris Hills | AY1: WWPN
B2: Aakaash | C2: Aarush | D2: Aditya | E2: Aivin | F2: Aldric | G2: Alex | H2: Ankur | I2: Arjun | J2: Arjun | K2: Asif | L2: Brendan | M2: Chad | N2: Cheuk | O2: Colin | P2: Daniel | Q2: Eashan | R2: Ethan | S2: Faiz | T2: Hubert | U2: Ian | V2: Iris | W2: Jack | X2: Jacob | Y2: James | Z2: Jamis | AA2: Jo | AB2: Joseph | AC2: Kagame | AD2: Karl | AE2: Kevin | AF2: Kevin | AG2: Liam | AH2: Lily | AI2: Madeline | AJ2: Matt | AK2: Matthew | AL2: Mihir | AM2: Myles | AN2: Nicole | AO2: Rithik | AP2: Shreyash | AQ2: Tarun | AR2: Wyatt
B3: TRUE | C3: TRUE | D3: FALSE | E3: TRUE | F3: FALSE | G3: TRUE | H3: TRUE | I3: TRUE | J3: FALSE | K3: TRUE | L3: FALSE | M3: TRUE | N3: TRUE | O3: TRUE | P3: TRUE | Q3: FALSE | R3: TRUE | S3: TRUE | T3: TRUE | U3: TRUE | V3: TRUE | W3: TRUE | X3: TRUE | Y3: FALSE | Z3: TRUE | AA3: TRUE | AB3: TRUE | AC3: TRUE | AD3: TRUE | AE3: TRUE | AF3: TRUE | AG3: TRUE | AH3: TRUE | AI3: TRUE | AJ3: TRUE | AK3: FALSE | AL3: TRUE | AM3: TRUE | AN3: TRUE | AO3: FALSE | AP3: FALSE | AQ3: FALSE | AR3: TRUE | AS3: FALSE | AT3: FALSE | AU3: FALSE | AV3: FALSE | AW3: FALSE | AX3: FALSE | AY3: FALSE
A4: X | G4: -4 | W4: 4 | Y4: 0 | AD4: 0 | AE4: 4 | AK4: 0 | AL4: 0 | AQ4: 0 | AS4: 0 | AT4: 0 | AU4: 0 | AV4: 0
A5: M | I5: 4 | N5: 4 | O5: 4 | U5: 4 | Y5: 0 | AK5: 0 | AQ5: 0 | AS5: 0 | AT5: 0 | AU5: 0 | AV5: 0
A6: C | C6: 0 | S6: 4 | Y6: 0 | AK6: 0 | AQ6: 0 | AS6: 0 | AT6: 0 | AU6: 0 | AV6: 0
A7: E | G7: 4 | K7: 0 | Y7: 0 | AA7: 4 | AB7: 4 | AK7: 0 | AQ7: 0 | AS7: 0 | AT7: 0 | AU7: 0 | AV7: 0
A8: B | C8: 0 | E8: 4 | H8: 0 | Y8: 0 | AE8: 4 | AI8: 0 | AK8: 0 | AL8: 0 | AQ8: 0 | AS8: 0 | AT8: 0 | AU8: 0 | AV8: 0
A9: P | C9: 0 | E9: 4 | W9: 0 | Y9: 0 | AB9: 4 | AH9: 4 | AK9: 0 | AQ9: 0 | AS9: 0 | AT9: 0 | AU9: 0 | AV9: 0
A10: X | V10: 4 | Y10: 0 | AD10: 4 | AF10: 4 | AK10: 0 | AQ10: 0 | AS10: 0 | AT10: 0 | AU10: 0 | AV10: 0
A11: M | E11: 0 | H11: 0 | Y11: 0 | AC11: 4 | AK11: 0 | AL11: 0 | AQ11: 0 | AR11: 4 | AS11: 0 | AT11: 0 | AU11: 0 | AV11: 0
A12: C | E12: 0 | R12: 4 | S12: 4 | V12: 4 | Y12: 0 | AE12: 4 | AK12: 0 | AQ12: 0 | AS12: 0 | AT12: 0 | AU12: 0 | AV12: 0
A13: E | C13: 4 | E13: 0 | T13: 0 | Y13: 0 | AB13: 4 | AK13: 0 | AQ13: 0 | AS13: 0 | AT13: 0 | AU13: 0 | AV13: 0
A14: B | B14: 4 | H14: 0 | K14: 0 | M14: 0 | V14: 4 | Y14: 0 | AG14: 4 | AK14: 0 | AL14: 0 | AQ14: 0 | AS14: 0 | AT14: 0 | AU14: 0 | AV14: 0
A15: P | C15: 4 | R15: 4 | W15: 0 | Y15: 0 | Z15: 4 | AK15: 0 | AQ15: 0 | AS15: 0 | AT15: 0 | AU15: 0 | AV15: 0
B16: TRUE | C16: TRUE | D16: FALSE | E16: TRUE | F16: FALSE | G16: TRUE | H16: TRUE | I16: TRUE | J16: FALSE | K16: TRUE | L16: FALSE | M16: TRUE | N16: TRUE | O16: TRUE | P16: TRUE | Q16: FALSE | R16: TRUE | S16: TRUE | T16: TRUE | U16: TRUE | V16: TRUE | W16: TRUE | X16: TRUE | Y16: FALSE | Z16: TRUE | AA16: TRUE | AB16: TRUE | AC16: TRUE | AD16: TRUE | AE16: TRUE | AF16: TRUE | AG16: TRUE | AH16: TRUE | AI16: TRUE | AJ16: TRUE | AK16: FALSE | AL16: TRUE | AM16: TRUE | AN16: TRUE | AO16: FALSE | AP16: FALSE | AQ16: FALSE | AR16: TRUE | AS16: FALSE | AT16: FALSE | AU16: FALSE | AV16: FALSE | AW16: FALSE | AX16: FALSE | AY16: FALSE
A17: X | B17: 4 | N17: 4 | Y17: 0 | AD17: 4 | AG17: 4 | AK17: 0 | AQ17: 0 | AS17: 0 | AT17: 0 | AU17: 0 | AV17: 0
A18: M | I18: 4 | M18: 4 | Y18: 0 | AA18: 0 | AC18: 0 | AG18: 4 | AK18: 0 | AQ18: 0 | AS18: 0 | AT18: 0 | AU18: 0 | AV18: 0
A19: C | E19: 0 | M19: 0 | S19: 4 | T19: 0 | U19: 4 | V19: 4 | Y19: 0 | AK19: 0 | AQ19: 0 | AS19: 0 | AT19: 0 | AU19: 0 | AV19: 0
A20: E | G20: 4 | Y20: 0 | AA20: 0 | AB20: 0 | AK20: 0 | AL20: 0 | AQ20: 0 | AS20: 0 | AT20: 0 | AU20: 0 | AV20: 0
A21: B | C21: 4 | I21: 4 | U21: 4 | Y21: 0 | AF21: 4 | AK21: 0 | AQ21: 0 | AS21: 0 | AT21: 0 | AU21: 0 | AV21: 0
A22: P | H22: 4 | M22: 4 | T22: 4 | Y22: 0 | AG22: 4 | AK22: 0 | AQ22: 0 | AS22: 0 | AT22: 0 | AU22: 0 | AV22: 0
A23: X | C23: 0 | E23: 0 | M23: 0 | O23: 0 | Y23: 0 | AK23: 0 | AQ23: 0 | AS23: 0 | AT23: 0 | AU23: 0 | AV23: 0
A24: M | E24: 4 | H24: 4 | N24: 4 | Y24: 0 | AG24: 4 | AK24: 0 | AQ24: 0 | AS24: 0 | AT24: 0 | AU24: 0 | AV24: 0
A25: C | E25: 4 | M25: -4 | N25: 4 | S25: 4 | U25: 4 | Y25: 0 | AG25: -4 | AK25: 0 | AQ25: 0 | AS25: 0 | AT25: 0 | AU25: 0 | AV25: 0
A26: E | E26: 4 | G26: 4 | I26: 4 | Y26: 0 | AK26: 0 | AQ26: 0 | AS26: 0 | AT26: 0 | AU26: 0 | AV26: 0
A27: B | C27: 0 | P27: 4 | Y27: 0 | AA27: 4 | AK27: 0 | AQ27: 0 | AS27: 0 | AT27: 0 | AU27: 0 | AV27: 0
A28: P | N28: 4 | U28: 4 | X28: 4 | Y28: 0 | AB28: 4 | AK28: 0 | AQ28: 0 | AS28: 0 | AT28: 0 | AU28: 0 | AV28: 0
B31: Shen B | C31: Niskayuna B | D31: Morris Hills | E31: Shen B | F31: WWPN | G31: Niskayuna B | H31: Shen C | I31: Niskayuna A | J31: WWPN | K31: CBA | L31: Morris Hills | M31: BHBL A | N31: Niskayuna B | O31: CBA | P31: Niskayuna A | Q31: Morris Hills | R31: CBA | S31: Niskayuna A | T31: CBA | U31: Bethlehem | V31: Niskayuna B | W31: BHBL A | X31: Shen B | Y31: Niskayuna B | Z31: Shen C | AA31: Shen B | AB31: Shen C | AC31: CBA | AD31: Shen C | AE31: Bethlehem | AF31: Shen B | AG31: BHBL B | AH31: BHBL B | AI31: BHBL A | AJ31: BHBL B | AK31: Shen C | AL31: Niskayuna A | AM31: BHBL A | AN31: BHBL B | AO31: WWPN | AP31: WWPN | AQ31: Niskayuna A | AR31: BHBL B | AS31: Morris Hills | AT31: Morris Hills | AU31: WWPN | AV31: Bethlehem | AW31: Bethlehem | AX31: Bethlehem | AY31: BHBL A
B32: Aakaash | C32: Aarush | D32: Aditya | E32: Aivin | F32: Aldric | G32: Alex | H32: Ankur | I32: Arjun | J32: Arjun | K32: Asif | L32: Brendan | M32: Chad | N32: Cheuk | O32: Colin | P32: Daniel | Q32: Eashan | R32: Ethan | S32: Faiz | T32: Hubert | U32: Ian | V32: Iris | W32: Jack | X32: Jacob | Y32: James | Z32: Jamis | AA32: Jo | AB32: Joseph | AC32: Kagame | AD32: Karl | AE32: Kevin | AF32: Kevin | AG32: Liam | AH32: Lily | AI32: Madeline | AJ32: Matt | AK32: Matthew | AL32: Mihir | AM32: Myles | AN32: Nicole | AO32: Rithik | AP32: Shreyash | AQ32: Tarun | AR32: Wyatt
B33: TRUE | C33: TRUE | D33: TRUE | E33: TRUE | F33: TRUE | G33: TRUE | H33: TRUE | I33: TRUE | J33: TRUE | K33: TRUE | L33: TRUE | M33: FALSE | N33: TRUE | O33: TRUE | P33: TRUE | Q33: TRUE | R33: TRUE | S33: TRUE | T33: TRUE | U33: FALSE | V33: TRUE | W33: FALSE | X33: TRUE | Y33: FALSE | Z33: TRUE | AA33: TRUE | AB33: TRUE | AC33: TRUE | AD33: TRUE | AE33: FALSE | AF33: TRUE | AG33: TRUE | AH33: TRUE | AI33: FALSE | AJ33: TRUE | AK33: TRUE | AL33: TRUE | AM33: FALSE | AN33: TRUE | AO33: TRUE | AP33: TRUE | AQ33: FALSE | AR33: TRUE | AS33: FALSE | AT33: FALSE | AU33: FALSE | AV33: FALSE | AW33: FALSE | AX33: FALSE | AY33: FALSE
A34: X | D34: 4 | F34: 4 | G34: 4 | Y34: 0 | Z34: 4 | AC34: 0 | AQ34: 0 | AS34: 0 | AT34: 0 | AU34: 0
A35: M | C35: 4 | H35: 4 | I35: 4 | Y35: 0 | AO35: 4 | AQ35: 0 | AS35: 0 | AT35: 0 | AU35: 0
A36: C | L36: 4 | O36: 4 | Y36: 0 | AG36: 4 | AQ36: 0 | AS36: 0 | AT36: 0 | AU36: 0
A37: E | G37: 4 | P37: 4 | Y37: 0 | Z37: 4 | AP37: 4 | AQ37: 0 | AS37: 0 | AT37: 0 | AU37: 0
A38: B | F38: 4 | I38: 4 | V38: 4 | Y38: 0 | AQ38: 0 | AS38: 0 | AT38: 0 | AU38: 0
A39: P | F39: 4 | N39: 4 | R39: 0 | S39: 4 | Y39: 0 | AN39: 4 | AQ39: 0 | AS39: 0 | AT39: 0 | AU39: 0
A40: X | F40: 4 | G40: 4 | P40: 4 | Y40: 0 | AQ40: 0 | AS40: 0 | AT40: 0 | AU40: 0
A41: M | Y41: 0 | AO41: 4 | AQ41: 0 | AR41: 4 | AS41: 0 | AT41: 0 | AU41: 0
A42: C | E42: 4 | Y42: 0 | AG42: 4 | AQ42: 0 | AS42: 0 | AT42: 0 | AU42: 0
...

Sheet Full
A1: Bethlehem | B1: Bethlehem | C1: BHBL B | D1: BHBL B | E1: Niskayuna A | F1: Niskayuna A | G1: Shen C | H1: Shen C | I1: BHBL A | J1: BHBL A | K1: Niskayuna B | L1: Niskayuna B | M1: CBA | N1: CBA | O1: Shen B | P1: Shen B | Q1: Morris Hills | R1: Morris Hills | S1: WWPN | T1: WWPN
A2: Bonus | B2: Score | C2: Bonus | D2: Score | E2: Bonus | F2: Score | G2: Bonus | H2: Score | I2: Bonus | J2: Score | K2: Bonus | L2: Score | M2: Bonus | N2: Score | O2: Bonus | P2: Score | Q2: Bonus | R2: Score | S2: Bonus | T2: Score
A4: 0 | B4: 4 | D4: 0 | F4: 0 | H4: 0 | I4: 0 | J4: 8 | L4: 0 | N4: 0 | P4: 0
A5: 0 | B5: 8 | D5: 0 | E5: 10 | F5: 14 | H5: 0 | J5: 8 | K5: 10 | L5: 14 | M5: 0 | N5: 4 | P5: 0
B6: 8 | D6: 0 | E6: 10 | F6: 28 | H6: 0 | J6: 8 | L6: 14 | N6: 4 | P6: 0
B7: 8 | D7: 0 | F7: 28 | G7: 10 | H7: 14 | J7: 8 | K7: 10 | L7: 28 | N7: 4 | O7: 10 | P7: 14
A8: 10 | B8: 22 | D8: 0 | F8: 28 | H8: 14 | J8: 8 | L8: 28 | N8: 4 | O8: 10 | P8: 28
B9: 22 | C9: 10 | D9: 14 | F9: 28 | G9: 0 | H9: 18 | J9: 8 | L9: 28 | N9: 4 | O9: 0 | P9: 32
B10: 22 | D10: 14 | F10: 28 | G10: 10 | H10: 32 | J10: 8 | K10: 10 | L10: 42 | N10: 4 | O10: 10 | P10: 46
B11: 22 | C11: 0 | D11: 18 | F11: 28 | H11: 32 | J11: 8 | L11: 42 | M11: 0 | N11: 8 | P11: 46
A12: 10 | B12: 36 | D12: 18 | E12: 10 | F12: 42 | H12: 32 | J12: 8 | K12: 10 | L12: 56 | M12: 0 | N12: 12 | P12: 46
B13: 36 | D13: 18 | F13: 42 | G13: 0 | H13: 36 | J13: 8 | K13: 0 | L13: 60 | N13: 12 | P13: 46
B14: 36 | C14: 10 | D14: 32 | F14: 42 | H14: 36 | J14: 8 | K14: 10 | L14: 74 | N14: 12 | O14: 0 | P14: 50
B15: 36 | D15: 32 | F15: 42 | G15: 0 | H15: 40 | J15: 8 | K15: 10 | L15: 88 | M15: 10 | N15: 26 | P15: 50
B17: 36 | C17: 10 | D17: 46 | F17: 42 | G17: 10 | H17: 54 | J17: 8 | K17: 0 | L17: 92 | N17: 26 | O17: 0 | P17: 54
B18: 36 | C18: 10 | D18: 60 | E18: 10 | F18: 56 | H18: 54 | I18: 0 | J18: 12 | L18: 92 | N18: 26 | P18: 54
A19: 0 | B19: 40 | D19: 60 | E19: 0 | F19: 60 | H19: 54 | J19: 12 | K19: 0 | L19: 96 | N19: 26 | P19: 54
B20: 40 | D20: 60 | F20: 60 | H20: 54 | J20: 12 | K20: 0 | L20: 100 | N20: 26 | P20: 54
A21: 10 | B21: 54 | D21: 60 | E21: 10 | F21: 74 | H21: 54 | J21: 12 | K21: 0 | L21: 104 | N21: 26 | O21: 10 | P21: 68
B22: 54 | C22: 0 | D22: 64 | F22: 74 | G22: 0 | H22: 58 | I22: 0 | J22: 16 | L22: 104 | M22: 0 | N22: 30 | P22: 68
B23: 54 | D23: 64 | F23: 74 | H23: 58 | J23: 16 | L23: 104 | N23: 30 | P23: 68
B24: 54 | C24: 10 | D24: 78 | F24: 74 | G24: 10 | H24: 72 | J24: 16 | K24: 10 | L24: 118 | N24: 30 | O24: 0 | P24: 72
A25: 10 | B25: 72 | D25: 78 | E25: 10 | F25: 88 | H25: 72 | J25: 16 | K25: 10 | L25: 136 | N25: 30 | O25: 10 | P25: 86
B26: 72 | D26: 78 | E26: 0 | F26: 92 | H26: 72 | J26: 16 | K26: 0 | L26: 140 | N26: 30 | O26: 0 | P26: 90
B27: 72 | D27: 78 | E27: 0 | F27: 96 | H27: 72 | J27: 16 | L27: 140 | N27: 30 | O27: 0 | P27: 94
A28: 0 | B28: 76 | D28: 78 | F28: 96 | G28: 0 | H28: 76 | J28: 16 | K28: 0 | L28: 144 | N28: 30 | O28: 0 | P28: 98
A31: Morris Hills | B31: Morris Hills | C31: Niskayuna A | D31: Niskayuna A | E31: BHBL B | F31: BHBL B | G31: Shen C | H31: Shen C | I31: WWPN | J31: WWPN | K31: Shen B | L31: Shen B | M31: CBA | N31: CBA | O31: Niskayuna B | P31: Niskayuna B | Q31: Bethlehem | R31: Bethlehem | S31: BHBL A | T31: BHBL A
A32: Bonus | B32: Score | C32: Bonus | D32: Score | E32: Bonus | F32: Score | G32: Bonus | H32: Score | I32: Bonus | J32: Score | K32: Bonus | L32: Score | M32: Bonus | N32: Score | O32: Bonus | P32: Score | Q32: Bonus | R32: Score | S32: Bonus | T32: Score
A34: 10 | B34: 14 | D34: 0 | F34: 0 | G34: 10 | H34: 14 | I34: 10 | J34: 14 | L34: 0 | N34: 0 | O34: 10 | P34: 14
B35: 14 | C35: 10 | D35: 14 | F35: 0 | G35: 0 | H35: 18 | I35: 10 | J35: 28 | L35: 0 | N35: 0 | O35: 0 | P35: 18
A36: 10 | B36: 28 | D36: 14 | E36: 0 | F36: 4 | H36: 18 | J36: 28 | L36: 0 | M36: 10 | N36: 14 | P36: 18
B37: 28 | C37: 10 | D37: 28 | F37: 4 | G37: 10 | H37: 32 | I37: 10 | J37: 42 | L37: 0 | N37: 14 | O37: 10 | P37: 32
B38: 28 | C38: 10 | D38: 42 | F38: 4 | H38: 32 | I38: 10 | J38: 56 | L38: 0 | N38: 14 | O38: 10 | P38: 46
B39: 28 | C39: 0 | D39: 46 | E39: 0 | F39: 8 | H39: 32 | I39: 0 | J39: 60 | L39: 0 | N39: 14 | O39: 0 | P39: 50
B40: 28 | C40: 10 | D40: 60 | F40: 8 | H40: 32 | I40: 10 | J40: 74 | L40: 0 | N40: 14 | O40: 10 | P40: 64
B41: 28 | D41: 60 | E41: 0 | F41: 12 | H41: 32 | I41: 10 | J41: 88 | L41: 0 | N41: 14 | P41: 64
B42: 28 | D42: 60 | E42: 0 | F42: 16 | H42: 32 | J42: 88 | K42: 0 | L42: 4 | N42: 14 | P42: 64
B43: 28 | C43: 0 | D43: 64 | F43: 16 | H43: 32 | J43: 88 | K43: 0 | L43: 8 | N43: 14 | O43: 10 | P43: 78
B44: 28 | D44: 64 | F44: 16 | H44: 32 | J44: 88 | L44: 8 | N44: 14 | P44: 78
B45: 28 | D45: 64 | F45: 16 | H45: 32 | J45: 88 | K45: 0 | L45: 12 | N45: 14 | P45: 78
...

Sheet Sorted Team
B1: {=transpose(sort(transpose(Full!A1:T30),1,true))} -> Bethlehem | C1: Bethlehem | D1: BHBL A | E1: BHBL A | F1: BHBL B | G1: BHBL B | H1: CBA | I1: CBA | J1: Morris Hills | K1: Morris Hills | L1: Niskayuna A | M1: Niskayuna A | N1: Niskayuna B | O1: Niskayuna B | P1: Shen B | Q1: Shen B | R1: Shen C | S1: Shen C | T1: WWPN | U1: WWPN
B2: Bonus | C2: Score | D2: Bonus | E2: Score | F2: Bonus | G2: Score | H2: Bonus | I2: Score | J2: Bonus | K2: Score | L2: Bonus | M2: Score | N2: Bonus | O2: Score | P2: Bonus | Q2: Score | R2: Bonus | S2: Score | T2: Bonus | U2: Score
A4: X | B4: 0 | C4: 4 | D4: 0 | E4: 8 | G4: 0 | I4: 0 | M4: 0 | O4: 0 | Q4: 0 | S4: 0
A5: M | B5: 0 | C5: 8 | E5: 8 | G5: 0 | H5: 0 | I5: 4 | L5: 10 | M5: 14 | N5: 10 | O5: 14 | Q5: 0 | S5: 0
A6: C | C6: 8 | E6: 8 | G6: 0 | I6: 4 | L6: 10 | M6: 28 | O6: 14 | Q6: 0 | S6: 0
A7: E | C7: 8 | E7: 8 | G7: 0 | I7: 4 | M7: 28 | N7: 10 | O7: 28 | P7: 10 | Q7: 14 | R7: 10 | S7: 14
A8: B | B8: 10 | C8: 22 | E8: 8 | G8: 0 | I8: 4 | M8: 28 | O8: 28 | P8: 10 | Q8: 28 | S8: 14
A9: P | C9: 22 | E9: 8 | F9: 10 | G9: 14 | I9: 4 | M9: 28 | O9: 28 | P9: 0 | Q9: 32 | R9: 0 | S9: 18
A10: X | C10: 22 | E10: 8 | G10: 14 | I10: 4 | M10: 28 | N10: 10 | O10: 42 | P10: 10 | Q10: 46 | R10: 10 | S10: 32
A11: M | C11: 22 | E11: 8 | F11: 0 | G11: 18 | H11: 0 | I11: 8 | M11: 28 | O11: 42 | Q11: 46 | S11: 32
A12: C | B12: 10 | C12: 36 | E12: 8 | G12: 18 | H12: 0 | I12: 12 | L12: 10 | M12: 42 | N12: 10 | O12: 56 | Q12: 46 | S12: 32
A13: E | C13: 36 | E13: 8 | G13: 18 | I13: 12 | M13: 42 | N13: 0 | O13: 60 | Q13: 46 | R13: 0 | S13: 36
A14: B | C14: 36 | E14: 8 | F14: 10 | G14: 32 | I14: 12 | M14: 42 | N14: 10 | O14: 74 | P14: 0 | Q14: 50 | S14: 36
A15: P | C15: 36 | E15: 8 | G15: 32 | H15: 10 | I15: 26 | M15: 42 | N15: 10 | O15: 88 | Q15: 50 | R15: 0 | S15: 40
A17: X | C17: 36 | E17: 8 | F17: 10 | G17: 46 | I17: 26 | M17: 42 | N17: 0 | O17: 92 | P17: 0 | Q17: 54 | R17: 10 | S17: 54
A18: M | C18: 36 | D18: 0 | E18: 12 | F18: 10 | G18: 60 | I18: 26 | L18: 10 | M18: 56 | O18: 92 | Q18: 54 | S18: 54
A19: C | B19: 0 | C19: 40 | E19: 12 | G19: 60 | I19: 26 | L19: 0 | M19: 60 | N19: 0 | O19: 96 | Q19: 54 | S19: 54
A20: E | C20: 40 | E20: 12 | G20: 60 | I20: 26 | M20: 60 | N20: 0 | O20: 100 | Q20: 54 | S20: 54
A21: B | B21: 10 | C21: 54 | E21: 12 | G21: 60 | I21: 26 | L21: 10 | M21: 74 | N21: 0 | O21: 104 | P21: 10 | Q21: 68 | S21: 54
A22: P | C22: 54 | D22: 0 | E22: 16 | F22: 0 | G22: 64 | H22: 0 | I22: 30 | M22: 74 | O22: 104 | Q22: 68 | R22: 0 | S22: 58
A23: X | C23: 54 | E23: 16 | G23: 64 | I23: 30 | M23: 74 | O23: 104 | Q23: 68 | S23: 58
A24: M | C24: 54 | E24: 16 | F24: 10 | G24: 78 | I24: 30 | M24: 74 | N24: 10 | O24: 118 | P24: 0 | Q24: 72 | R24: 10 | S24: 72
A25: C | B25: 10 | C25: 72 | E25: 16 | G25: 78 | I25: 30 | L25: 10 | M25: 88 | N25: 10 | O25: 136 | P25: 10 | Q25: 86 | S25: 72
A26: E | C26: 72 | E26: 16 | G26: 78 | I26: 30 | L26: 0 | M26: 92 | N26: 0 | O26: 140 | P26: 0 | Q26: 90 | S26: 72
A27: B | C27: 72 | E27: 16 | G27: 78 | I27: 30 | L27: 0 | M27: 96 | O27: 140 | P27: 0 | Q27: 94 | S27: 72
A28: P | B28: 0 | C28: 76 | E28: 16 | G28: 78 | I28: 30 | M28: 96 | N28: 0 | O28: 144 | P28: 0 | Q28: 98 | R28: 0 | S28: 76
B31: {=transpose(sort(transpose(Full!A31:T60),1,true))} -> Bethlehem | C31: Bethlehem | D31: BHBL A | E31: BHBL A | F31: BHBL B | G31: BHBL B | H31: CBA | I31: CBA | J31: Morris Hills | K31: Morris Hills | L31: Niskayuna A | M31: Niskayuna A | N31: Niskayuna B | O31: Niskayuna B | P31: Shen B | Q31: Shen B | R31: Shen C | S31: Shen C | T31: WWPN | U31: WWPN
B32: Bonus | C32: Score | D32: Bonus | E32: Score | F32: Bonus | G32: Score | H32: Bonus | I32: Score | J32: Bonus | K32: Score | L32: Bonus | M32: Score | N32: Bonus | O32: Score | P32: Bonus | Q32: Score | R32: Bonus | S32: Score | T32: Bonus | U32: Score
A34: X | G34: 0 | I34: 0 | J34: 10 | K34: 14 | M34: 0 | N34: 10 | O34: 14 | Q34: 0 | R34: 10 | S34: 14 | T34: 10 | U34: 14
A35: M | G35: 0 | I35: 0 | K35: 14 | L35: 10 | M35: 14 | N35: 0 | O35: 18 | Q35: 0 | R35: 0 | S35: 18 | T35: 10 | U35: 28
A36: C | F36: 0 | G36: 4 | H36: 10 | I36: 14 | J36: 10 | K36: 28 | M36: 14 | O36: 18 | Q36: 0 | S36: 18 | U36: 28
A37: E | G37: 4 | I37: 14 | K37: 28 | L37: 10 | M37: 28 | N37: 10 | O37: 32 | Q37: 0 | R37: 10 | S37: 32 | T37: 10 | U37: 42
A38: B | G38: 4 | I38: 14 | K38: 28 | L38: 10 | M38: 42 | N38: 10 | O38: 46 | Q38: 0 | S38: 32 | T38: 10 | U38: 56
A39: P | F39: 0 | G39: 8 | I39: 14 | K39: 28 | L39: 0 | M39: 46 | N39: 0 | O39: 50 | Q39: 0 | S39: 32 | T39: 0 | U39: 60
A40: X | G40: 8 | I40: 14 | K40: 28 | L40: 10 | M40: 60 | N40: 10 | O40: 64 | Q40: 0 | S40: 32 | T40: 10 | U40: 74
A41: M | F41: 0 | G41: 12 | I41: 14 | K41: 28 | M41: 60 | O41: 64 | Q41: 0 | S41: 32 | T41: 10 | U41: 88
A42: C | F42: 0 | G42: 16 | I42: 14 | K42: 28 | M42: 60 | O42: 64 | P42: 0 | Q42: 4 | S42: 32 | U42: 88
A43: E | G43: 16 | I43: 14 | K43: 28 | L43: 0 | M43: 64 | N43: 10 | O43: 78 | P43: 0 | Q43: 8 | S43: 32 | U43: 88
A44: B | G44: 16 | I44: 14 | K44: 28 | M44: 64 | O44: 78 | Q44: 8 | S44: 32 | U44: 88
A45: P | G45: 16 | I45: 14 | K45: 28 | M45: 64 | O45: 78 | P45: 0 | Q45: 12 | S45: 32 | U45: 88
...

Sheet Stats
A1: Overall | B1: Team | C1: GP | D1: TUH | E1: TU | F1: Neg | G1: TU/Neg | H1: Points | I1: PPG | J1: X TU | K1: X Neg | L1: X PPG | M1: M TU | N1: M Neg | O1: M PPG | P1: C TU | Q1: C Neg | R1: C PPG | S1: E TU | T1: E Neg | U1: E PPG | V1: B TU | W1: B Neg | X1: B PPG | Y1: P TU | Z1: P Neg | AA1: P PPG
A2: Aldric | B2: WWPN | C2: 8 | D2: 192 | E2: 54 | F2: 9 | G2: 6 | H2: 180 | I2: 22.5 | J2: 11 | K2: 2 | L2: 4.5 | M2: 1 | N2: 1 | O2: 0 | P2: 7 | Q2: 0 | R2: 3.5 | S2: 13 | T2: 0 | U2: 6.5 | V2: 12 | W2: 4 | X2: 4 | Y2: 10 | Z2: 2 | AA2: 4
A3: Brendan | B3: Morris Hills | C3: 7 | D3: 168 | E3: 33 | F3: 1 | G3: 33 | H3: 128 | I3: 18.285714 | J3: 6 | K3: 0 | L3: 3.4285714 | M3: 7 | N3: 0 | O3: 4 | P3: 3 | Q3: 0 | R3: 1.7142857 | S3: 6 | T3: 0 | U3: 3.4285714 | V3: 5 | W3: 0 | X3: 2.8571429 | Y3: 6 | Z3: 1 | AA3: 2.8571429
A4: Aivin | B4: Shen B | C4: 8 | D4: 192 | E4: 31 | F4: 0 | G4: Infinity | H4: 124 | I4: 15.5 | J4: 7 | K4: 0 | L4: 3.5 | M4: 5 | N4: 0 | O4: 2.5 | P4: 8 | Q4: 0 | R4: 4 | S4: 3 | T4: 0 | U4: 1.5 | V4: 4 | W4: 0 | X4: 2 | Y4: 4 | Z4: 0 | AA4: 2
A5: Aarush | B5: Niskayuna B | C5: 10 | D5: 240 | E5: 32 | F5: 2 | G5: 16 | H5: 120 | I5: 12 | J5: 6 | K5: 0 | L5: 2.4 | M5: 4 | N5: 1 | O5: 1.2 | P5: 3 | Q5: 0 | R5: 1.2 | S5: 2 | T5: 0 | U5: 0.8 | V5: 10 | W5: 1 | X5: 3.6 | Y5: 7 | Z5: 0 | AA5: 2.8
A6: Liam | B6: BHBL B | C6: 4 | D6: 96 | E6: 14 | F6: 3 | G6: 4.6666667 | H6: 44 | I6: 11 | J6: 1 | K6: 1 | L6: 0 | M6: 3 | N6: 0 | O6: 3 | P6: 5 | Q6: 1 | R6: 4 | S6: 1 | T6: 0 | U6: 1 | V6: 2 | W6: 1 | X6: 1 | Y6: 2 | Z6: 0 | AA6: 2
A7: Kevin | B7: Bethlehem | C7: 7 | D7: 168 | E7: 18 | F7: 0 | G7: Infinity | H7: 72 | I7: 10.285714 | J7: 5 | K7: 0 | L7: 2.8571429 | M7: 0 | N7: 0 | O7: 0 | P7: 3 | Q7: 0 | R7: 1.7142857 | S7: 2 | T7: 0 | U7: 1.1428571 | V7: 7 | W7: 0 | X7: 4 | Y7: 1 | Z7: 0 | AA7: 0.57142857
A8: Eashan | B8: Morris Hills | C8: 7 | D8: 168 | E8: 16 | F8: 0 | G8: Infinity | H8: 64 | I8: 9.1428571 | J8: 1 | K8: 0 | L8: 0.57142857 | M8: 2 | N8: 0 | O8: 1.1428571 | P8: 6 | Q8: 0 | R8: 3.4285714 | S8: 2 | T8: 0 | U8: 1.1428571 | V8: 1 | W8: 0 | X8: 0.57142857 | Y8: 4 | Z8: 0 | AA8: 2.2857143
A9: Jamis | B9: Shen C | C9: 7 | D9: 168 | E9: 15 | F9: 0 | G9: Infinity | H9: 60 | I9: 8.5714286 | J9: 4 | K9: 0 | L9: 2.2857143 | M9: 2 | N9: 0 | O9: 1.1428571 | P9: 1 | Q9: 0 | R9: 0.57142857 | S9: 2 | T9: 0 | U9: 1.1428571 | V9: 3 | W9: 0 | X9: 1.7142857 | Y9: 3 | Z9: 0 | AA9: 1.7142857
A10: Faiz | B10: Niskayuna A | C10: 8 | D10: 192 | E10: 17 | F10: 0 | G10: Infinity | H10: 68 | I10: 8.5 | J10: 3 | K10: 0 | L10: 1.5 | M10: 2 | N10: 0 | O10: 1 | P10: 10 | Q10: 0 | R10: 5 | S10: 0 | T10: 0 | U10: 0 | V10: 0 | W10: 0 | X10: 0 | Y10: 2 | Z10: 0 | AA10: 1
A11: Ankur | B11: Shen C | C11: 7 | D11: 168 | E11: 14 | F11: 0 | G11: Infinity | H11: 56 | I11: 8 | J11: 1 | K11: 0 | L11: 0.57142857 | M11: 5 | N11: 0 | O11: 2.8571429 | P11: 2 | Q11: 0 | R11: 1.1428571 | S11: 1 | T11: 0 | U11: 0.57142857 | V11: 2 | W11: 0 | X11: 1.1428571 | Y11: 3 | Z11: 0 | AA11: 1.7142857
A12: Rithik | B12: WWPN | C12: 8 | D12: 192 | E12: 19 | F12: 4 | G12: 4.75 | H12: 60 | I12: 7.5 | J12: 1 | K12: 2 | L12: -0.5 | M12: 16 | N12: 1 | O12: 7.5 | P12: 1 | Q12: 0 | R12: 0.5 | S12: 0 | T12: 0 | U12: 0 | V12: 0 | W12: 0 | X12: 0 | Y12: 1 | Z12: 1 | AA12: 0
A13: Ian | B13: Bethlehem | C13: 6 | D13: 144 | E13: 11 | F13: 0 | G13: Infinity | H13: 44 | I13: 7.3333333 | J13: 4 | K13: 0 | L13: 2.6666667 | M13: 1 | N13: 0 | O13: 0.66666667 | P13: 2 | Q13: 0 | R13: 1.3333333 | S13: 1 | T13: 0 | U13: 0.66666667 | V13: 1 | W13: 0 | X13: 0.66666667 | Y13: 2 | Z13: 0 | AA13: 1.3333333
A14: Arjun | B14: Niskayuna A | C14: 9 | D14: 216 | E14: 16 | F14: 0 | G14: Infinity | H14: 64 | I14: 7.1111111 | J14: 2 | K14: 0 | L14: 0.88888889 | M14: 7 | N14: 0 | O14: 3.1111111 | P14: 2 | Q14: 0 | R14: 0.88888889 | S14: 2 | T14: 0 | U14: 0.88888889 | V14: 2 | W14: 0 | X14: 0.88888889 | Y14: 1 | Z14: 0 | AA14: 0.44444444
A15: Alex | B15: Niskayuna B | C15: 10 | D15: 240 | E15: 18 | F15: 1 | G15: 18 | H15: 68 | I15: 6.8 | J15: 5 | K15: 1 | L15: 1.6 | M15: 0 | N15: 0 | O15: 0 | P15: 0 | Q15: 0 | R15: 0 | S15: 13 | T15: 0 | U15: 5.2 | V15: 0 | W15: 0 | X15: 0 | Y15: 0 | Z15: 0 | AA15: 0
A16: Jacob | B16: Shen B | C16: 8 | D16: 192 | E16: 13 | F16: 0 | G16: Infinity | H16: 52 | I16: 6.5 | J16: 0 | K16: 0 | L16: 0 | M16: 5 | N16: 0 | O16: 2.5 | P16: 0 | Q16: 0 | R16: 0 | S16: 0 | T16: 0 | U16: 0 | V16: 0 | W16: 0 | X16: 0 | Y16: 8 | Z16: 0 | AA16: 4
A17: Mihir | B17: Niskayuna A | C17: 8 | D17: 192 | E17: 13 | F17: 0 | G17: Infinity | H17: 52 | I17: 6.5 | J17: 1 | K17: 0 | L17: 0.5 | M17: 6 | N17: 0 | O17: 3 | P17: 0 | Q17: 0 | R17: 0 | S17: 1 | T17: 0 | U17: 0.5 | V17: 4 | W17: 0 | X17: 2 | Y17: 1 | Z17: 0 | AA17: 0.5
A18: Kevin | B18: Shen B | C18: 7 | D18: 168 | E18: 11 | F18: 0 | G18: Infinity | H18: 44 | I18: 6.2857143 | J18: 3 | K18: 0 | L18: 1.7142857 | M18: 0 | N18: 0 | O18: 0 | P18: 3 | Q18: 0 | R18: 1.7142857 | S18: 0 | T18: 0 | U18: 0 | V18: 4 | W18: 0 | X18: 2.2857143 | Y18: 1 | Z18: 0 | AA18: 0.57142857
A19: Chad | B19: BHBL A | C19: 4 | D19: 96 | E19: 7 | F19: 1 | G19: 7 | H19: 24 | I19: 6 | J19: 1 | K19: 0 | L19: 1 | M19: 2 | N19: 0 | O19: 2 | P19: 2 | Q19: 1 | R19: 1 | S19: 0 | T19: 0 | U19: 0 | V19: 1 | W19: 0 | X19: 1 | Y19: 1 | Z19: 0 | AA19: 1
A20: Jo | B20: Shen B | C20: 8 | D20: 192 | E20: 11 | F20: 1 | G20: 11 | H20: 40 | I20: 5 | J20: 1 | K20: 0 | L20: 0.5 | M20: 0 | N20: 0 | O20: 0 | P20: 1 | Q20: 0 | R20: 0.5 | S20: 8 | T20: 1 | U20: 3.5 | V20: 1 | W20: 0 | X20: 0.5 | Y20: 0 | Z20: 0 | AA20: 0
A21: Arjun | B21: WWPN | C21: 7 | D21: 168 | E21: 9 | F21: 1 | G21: 9 | H21: 32 | I21: 4.5714286 | J21: 1 | K21: 0 | L21: 0.57142857 | M21: 0 | N21: 0 | O21: 0 | P21: 5 | Q21: 0 | R21: 2.8571429 | S21: 1 | T21: 1 | U21: 0 | V21: 1 | W21: 0 | X21: 0.57142857 | Y21: 1 | Z21: 0 | AA21: 0.57142857
A22: Daniel | B22: Niskayuna A | C22: 8 | D22: 192 | E22: 12 | F22: 3 | G22: 4 | H22: 36 | I22: 4.5 | J22: 5 | K22: 0 | L22: 2.5 | M22: 0 | N22: 0 | O22: 0 | P22: 0 | Q22: 0 | R22: 0 | S22: 5 | T22: 0 | U22: 2.5 | V22: 2 | W22: 3 | X22: -0.5 | Y22: 0 | Z22: 0 | AA22: 0
A23: Shreyash | B23: WWPN | C23: 8 | D23: 192 | E23: 12 | F23: 3 | G23: 4 | H23: 36 | I23: 4.5 | J23: 2 | K23: 1 | L23: 0.5 | M23: 4 | N23: 0 | O23: 2 | P23: 0 | Q23: 0 | R23: 0 | S23: 5 | T23: 2 | U23: 1.5 | V23: 0 | W23: 0 | X23: 0 | Y23: 1 | Z23: 0 | AA23: 0.5
A24: Cheuk | B24: Niskayuna B | C24: 10 | D24: 240 | E24: 11 | F24: 0 | G24: Infinity | H24: 44 | I24: 4.4 | J24: 2 | K24: 0 | L24: 0.8 | M24: 5 | N24: 0 | O24: 2 | P24: 1 | Q24: 0 | R24: 0.4 | S24: 1 | T24: 0 | U24: 0.4 | V24: 0 | W24: 0 | X24: 0 | Y24: 2 | Z24: 0 | AA24: 0.8
A25: Iris | B25: Niskayuna B | C25: 10 | D25: 240 | E25: 12 | F25: 1 | G25: 12 | H25: 44 | I25: 4.4 | J25: 2 | K25: 0 | L25: 0.8 | M25: 1 | N25: 0 | O25: 0.4 | P25: 3 | Q25: 0 | R25: 1.2 | S25: 0 | T25: 0 | U25: 0 | V25: 6 | W25: 1 | X25: 2 | Y25: 0 | Z25: 0 | AA25: 0
A26: Aditya | B26: Morris Hills | C26: 7 | D26: 168 | E26: 7 | F26: 0 | G26: Infinity | H26: 28 | I26: 4 | J26: 3 | K26: 0 | L26: 1.7142857 | M26: 0 | N26: 0 | O26: 0 | P26: 0 | Q26: 0 | R26: 0 | S26: 0 | T26: 0 | U26: 0 | V26: 4 | W26: 0 | X26: 2.2857143 | Y26: 0 | Z26: 0 | AA26: 0
A27: Colin | B27: CBA | C27: 6 | D27: 144 | E27: 7 | F27: 1 | G27: 7 | H27: 24 | I27: 4 | J27: 0 | K27: 0 | L27: 0 | M27: 2 | N27: 0 | O27: 1.3333333 | P27: 5 | Q27: 0 | R27: 3.3333333 | S27: 0 | T27: 0 | U27: 0 | V27: 0 | W27: 1 | X27: -0.66666667 | Y27: 0 | Z27: 0 | AA27: 0
A28: Joseph | B28: Shen C | C28: 7 | D28: 168 | E28: 8 | F28: 1 | G28: 8 | H28: 28 | I28: 4 | J28: 1 | K28: 0 | L28: 0.57142857 | M28: 0 | N28: 0 | O28: 0 | P28: 0 | Q28: 0 | R28: 0 | S28: 4 | T28: 1 | U28: 1.7142857 | V28: 0 | W28: 0 | X28: 0 | Y28: 3 | Z28: 0 | AA28: 1.7142857
A29: Ethan | B29: CBA | C29: 6 | D29: 144 | E29: 6 | F29: 1 | G29: 6 | H29: 20 | I29: 3.3333333 | J29: 1 | K29: 0 | L29: 0.66666667 | M29: 1 | N29: 0 | O29: 0.66666667 | P29: 2 | Q29: 0 | R29: 1.3333333 | S29: 0 | T29: 1 | U29: -0.66666667 | V29: 0 | W29: 0 | X29: 0 | Y29: 2 | Z29: 0 | AA29: 1.3333333
A30: Madeline | B30: BHBL A | C30: 4 | D30: 96 | E30: 3 | F30: 0 | G30: Infinity | H30: 12 | I30: 3 | J30: 0 | K30: 0 | L30: 0 | M30: 0 | N30: 0 | O30: 0 | P30: 0 | Q30: 0 | R30: 0 | S30: 2 | T30: 0 | U30: 2 | V30: 1 | W30: 0 | X30: 1 | Y30: 0 | Z30: 0 | AA30: 0
A31: Myles | B31: BHBL A | C31: 4 | D31: 96 | E31: 3 | F31: 0 | G31: Infinity | H31: 12 | I31: 3 | J31: 0 | K31: 0 | L31: 0 | M31: 3 | N31: 0 | O31: 3 | P31: 0 | Q31: 0 | R31: 0 | S31: 0 | T31: 0 | U31: 0 | V31: 0 | W31: 0 | X31: 0 | Y31: 0 | Z31: 0 | AA31: 0
A32: Hubert | B32: CBA | C32: 6 | D32: 144 | E32: 4 | F32: 0 | G32: Infinity | H32: 16 | I32: 2.6666667 | J32: 1 | K32: 0 | L32: 0.66666667 | M32: 1 | N32: 0 | O32: 0.66666667 | P32: 0 | Q32: 0 | R32: 0 | S32: 1 | T32: 0 | U32: 0.66666667 | V32: 0 | W32: 0 | X32: 0 | Y32: 1 | Z32: 0 | AA32: 0.66666667
A33: Jack | B33: BHBL A | C33: 4 | D33: 96 | E33: 2 | F33: 0 | G33: Infinity | H33: 8 | I33: 2 | J33: 1 | K33: 0 | L33: 1 | M33: 0 | N33: 0 | O33: 0 | P33: 0 | Q33: 0 | R33: 0 | S33: 1 | T33: 0 | U33: 1 | V33: 0 | W33: 0 | X33: 0 | Y33: 0 | Z33: 0 | AA33: 0
A34: Kagame | B34: CBA | C34: 6 | D34: 144 | E34: 4 | F34: 1 | G34: 4 | H34: 12 | I34: 2 | J34: 0 | K34: 0 | L34: 0 | M34: 2 | N34: 1 | O34: 0.66666667 | P34: 0 | Q34: 0 | R34: 0 | S34: 1 | T34: 0 | U34: 0.66666667 | V34: 0 | W34: 0 | X34: 0 | Y34: 1 | Z34: 0 | AA34: 0.66666667
A35: Lily | B35: BHBL B | C35: 4 | D35: 96 | E35: 2 | F35: 0 | G35: Infinity | H35: 8 | I35: 2 | J35: 0 | K35: 0 | L35: 0 | M35: 0 | N35: 0 | O35: 0 | P35: 0 | Q35: 0 | R35: 0 | S35: 1 | T35: 0 | U35: 1 | V35: 0 | W35: 0 | X35: 0 | Y35: 1 | Z35: 0 | AA35: 1
A36: Nicole | B36: BHBL B | C36: 4 | D36: 96 | E36: 2 | F36: 0 | G36: Infinity | H36: 8 | I36: 2 | J36: 0 | K36: 0 | L36: 0 | M36: 0 | N36: 0 | O36: 0 | P36: 1 | Q36: 0 | R36: 1 | S36: 0 | T36: 0 | U36: 0 | V36: 0 | W36: 0 | X36: 0 | Y36: 1 | Z36: 0 | AA36: 1
A37: Wyatt | B37: BHBL B | C37: 4 | D37: 96 | E37: 2 | F37: 0 | G37: Infinity | H37: 8 | I37: 2 | J37: 0 | K37: 0 | L37: 0 | M37: 2 | N37: 0 | O37: 2 | P37: 0 | Q37: 0 | R37: 0 | S37: 0 | T37: 0 | U37: 0 | V37: 0 | W37: 0 | X37: 0 | Y37: 0 | Z37: 0 | AA37: 0
A38: Aakaash | B38: Shen B | C38: 7 | D38: 168 | E38: 3 | F38: 0 | G38: Infinity | H38: 12 | I38: 1.7142857 | J38: 1 | K38: 0 | L38: 0.57142857 | M38: 0 | N38: 0 | O38: 0 | P38: 0 | Q38: 0 | R38: 0 | S38: 1 | T38: 0 | U38: 0.57142857 | V38: 1 | W38: 0 | X38: 0.57142857 | Y38: 0 | Z38: 0 | AA38: 0
A39: Tarun | B39: Niskayuna A | C39: 4 | D39: 96 | E39: 6 | F39: 5 | G39: 1.2 | H39: 4 | I39: 1 | J39: 0 | K39: 0 | L39: 0 | M39: 0 | N39: 0 | O39: 0 | P39: 1 | Q39: 0 | R39: 1 | S39: 1 | T39: 2 | U39: -1 | V39: 1 | W39: 0 | X39: 1 | Y39: 3 | Z39: 3 | AA39: 0
A40: Asif | B40: CBA | C40: 6 | D40: 144 | E40: 1 | F40: 0 | G40: Infinity | H40: 4 | I40: 0.66666667 | J40: 0 | K40: 0 | L40: 0 | M40: 0 | N40: 0 | O40: 0 | P40: 0 | Q40: 0 | R40: 0 | S40: 0 | T40: 0 | U40: 0 | V40: 1 | W40: 0 | X40: 0.66666667 | Y40: 0 | Z40: 0 | AA40: 0
...

Sheet Team Stats
A1: {=sort(transpose('Sorted Team'!A331:T347),2,false)} | B1: PPG | C1: GP | D1: Bonus | E1: Bonus % | F1: X Bonus | G1: X Bonus % | H1: M Bonus | I1: M Bonus % | J1: C Bonus | K1: C Bonus % | L1: E Bonus | M1: E Bonus % | N1: B Bonus | O1: B Bonus % | P1: P Bonus | Q1: P Bonus %
A2: WWPN | B2: 117.75 | C2: 8 | D2: 53 | E2: 0.56382979 | F2: 7 | G2: 0.46666667 | H2: 15 | I2: 0.71428571 | J2: 7 | K2: 0.53846154 | L2: 13 | M2: 0.68421053 | N2: 6 | O2: 0.46153846 | P2: 5 | Q2: 0.38461538
A3: Niskayuna A | B3: 71.25 | C3: 8 | D3: 29 | E3: 0.453125 | F3: 5 | G3: 0.45454545 | H3: 9 | I3: 0.6 | J3: 6 | K3: 0.46153846 | L3: 4 | M3: 0.44444444 | N3: 2 | O3: 0.22222222 | P3: 3 | Q3: 0.42857143
A4: Shen B | B4: 71.25 | C4: 8 | D4: 27 | E4: 0.39130435 | F4: 8 | G4: 0.66666667 | H4: 4 | I4: 0.4 | J4: 4 | K4: 0.33333333 | L4: 5 | M4: 0.41666667 | N4: 4 | O4: 0.4 | P4: 2 | Q4: 0.15384615
A5: Morris Hills | B5: 68 | C5: 7 | D5: 24 | E5: 0.42857143 | F5: 7 | G5: 0.7 | H5: 3 | I5: 0.33333333 | J5: 3 | K5: 0.33333333 | L5: 4 | M5: 0.5 | N5: 3 | O5: 0.3 | P5: 4 | Q5: 0.4
A6: Niskayuna B | B6: 63.8 | C6: 10 | D6: 31 | E6: 0.43055556 | F6: 10 | G6: 0.66666667 | H6: 3 | I6: 0.3 | J6: 4 | K6: 0.57142857 | L6: 7 | M6: 0.4375 | N6: 4 | O6: 0.25 | P6: 3 | Q6: 0.375
A7: Shen C | B7: 47.142857 | C7: 7 | D7: 17 | E7: 0.425 | F7: 6 | G7: 0.75 | H7: 3 | I7: 0.375 | J7: 2 | K7: 0.66666667 | L7: 3 | M7: 0.42857143 | N7: 1 | O7: 0.2 | P7: 2 | Q7: 0.22222222
A8: BHBL B | B8: 38.5 | C8: 4 | D8: 7 | E8: 0.35 | F8: 1 | G8: 1 | H8: 2 | I8: 0.4 | J8: 1 | K8: 0.16666667 | L8: 0 | M8: 0 | N8: 1 | O8: 0.5 | P8: 2 | Q8: 0.5
A9: Bethlehem | B9: 35.666667 | C9: 6 | D9: 9 | E9: 0.31034483 | F9: 3 | G9: 0.33333333 | H9: 0 | I9: 0 | J9: 3 | K9: 0.6 | L9: 0 | M9: 0 | N9: 3 | O9: 0.375 | P9: 0 | Q9: 0
A10: CBA | B10: 28 | C10: 6 | D10: 6 | E10: 0.27272727 | F10: 0 | G10: 0 | H10: 1 | I10: 0.16666667 | J10: 4 | K10: 0.57142857 | L10: 0 | M10: 0 | N10: 0 | O10: 0 | P10: 1 | Q10: 0.25
A11: BHBL A | B11: 21 | C11: 4 | D11: 2 | E11: 0.13333333 | F11: 0 | G11: 0 | H11: 0 | I11: 0 | J11: 0 | K11: 0 | L11: 1 | M11: 0.33333333 | N11: 1 | O11: 0.5 | P11: 0 | Q11: 0

Sheet X-Risk
A1: {=sort(Stats!A1:A1000,Stats!L1:L1000,false)} -> Overall | B1: {=sort(Stats!D1:D1000,Stats!L1:L1000,false)} -> TUH | C1: {=sort(Stats!J1:L1000,Stats!L1:L1000,false)} -> X TU | D1: X Neg | E1: X PPG
A2: Aldric | B2: 192 | C2: 11 | D2: 2 | E2: 4.5
A3: Aivin | B3: 192 | C3: 7 | D3: 0 | E3: 3.5
A4: Brendan | B4: 168 | C4: 6 | D4: 0 | E4: 3.4285714
A5: Kevin | B5: 168 | C5: 5 | D5: 0 | E5: 2.8571429
A6: Ian | B6: 144 | C6: 4 | D6: 0 | E6: 2.6666667
A7: Daniel | B7: 192 | C7: 5 | D7: 0 | E7: 2.5
A8: Aarush | B8: 240 | C8: 6 | D8: 0 | E8: 2.4
A9: Jamis | B9: 168 | C9: 4 | D9: 0 | E9: 2.2857143
A10: Kevin | B10: 168 | C10: 3 | D10: 0 | E10: 1.7142857
A11: Aditya | B11: 168 | C11: 3 | D11: 0 | E11: 1.7142857
A12: Alex | B12: 240 | C12: 5 | D12: 1 | E12: 1.6
A13: Faiz | B13: 192 | C13: 3 | D13: 0 | E13: 1.5
... A43: Rithik | B43: 192 | C43: 1 | D43: 2 | E43: -0.5

Sheet Math
A1: {=sort(Stats!A1:A1000,Stats!O1:O1000,false)} -> Overall | B1: {=sort(Stats!D1:D1000,Stats!O1:O1000,false)} -> TUH | C1: {=sort(Stats!M1:O1000,Stats!O1:O1000,false)} -> M TU | D1: M Neg | E1: M PPG
A2: Rithik | B2: 192 | C2: 16 | D2: 1 | E2: 7.5
A3: Brendan | B3: 168 | C3: 7 | D3: 0 | E3: 4
A4: Arjun | B4: 216 | C4: 7 | D4: 0 | E4: 3.1111111
A5: Liam | B5: 96 | C5: 3 | D5: 0 | E5: 3
A6: Mihir | B6: 192 | C6: 6 | D6: 0 | E6: 3
A7: Myles | B7: 96 | C7: 3 | D7: 0 | E7: 3
A8: Ankur | B8: 168 | C8: 5 | D8: 0 | E8: 2.8571429
A9: Aivin | B9: 192 | C9: 5 | D9: 0 | E9: 2.5
A10: Jacob | B10: 192 | C10: 5 | D10: 0 | E10: 2.5
A11: Chad | B11: 96 | C11: 2 | D11: 0 | E11: 2
A12: Shreyash | B12: 192 | C12: 4 | D12: 0 | E12: 2
A13: Cheuk | B13: 240 | C13: 5 | D13: 0 | E13: 2
... A43: Matthew | B43: 72 | C43: 0 | D43: 0 | E43: 0

Sheet Chemistry
A1: {=sort(Stats!A1:A1000,Stats!R1:R1000,false)} -> Overall | B1: {=sort(Stats!D1:D1000,Stats!R1:R1000,false)} -> TUH | C1: {=sort(Stats!P1:R1000,Stats!R1:R1000,false)} -> C TU | D1: C Neg | E1: C PPG
A2: Faiz | B2: 192 | C2: 10 | D2: 0 | E2: 5
A3: Aivin | B3: 192 | C3: 8 | D3: 0 | E3: 4
A4: Liam | B4: 96 | C4: 5 | D4: 1 | E4: 4
A5: Aldric | B5: 192 | C5: 7 | D5: 0 | E5: 3.5
A6: Eashan | B6: 168 | C6: 6 | D6: 0 | E6: 3.4285714
A7: Colin | B7: 144 | C7: 5 | D7: 0 | E7: 3.3333333
A8: Arjun | B8: 168 | C8: 5 | D8: 0 | E8: 2.8571429
A9: Brendan | B9: 168 | C9: 3 | D9: 0 | E9: 1.7142857
A10: Kevin | B10: 168 | C10: 3 | D10: 0 | E10: 1.7142857
A11: Kevin | B11: 168 | C11: 3 | D11: 0 | E11: 1.7142857
A12: Ian | B12: 144 | C12: 2 | D12: 0 | E12: 1.3333333
A13: Ethan | B13: 144 | C13: 2 | D13: 0 | E13: 1.3333333
... A43: Matthew | B43: 72 | C43: 0 | D43: 0 | E43: 0

Sheet EarthSpace
A1: {=sort(Stats!A1:A1000,Stats!U1:U1000,false)} -> Overall | B1: {=sort(Stats!D1:D1000,Stats!U1:U1000,false)} -> TUH | C1: {=sort(Stats!S1:U1000,Stats!U1:U1000,false)} -> E TU | D1: E Neg | E1: E PPG
A2: Aldric | B2: 192 | C2: 13 | D2: 0 | E2: 6.5
A3: Alex | B3: 240 | C3: 13 | D3: 0 | E3: 5.2
A4: Jo | B4: 192 | C4: 8 | D4: 1 | E4: 3.5
A5: Brendan | B5: 168 | C5: 6 | D5: 0 | E5: 3.4285714
A6: Daniel | B6: 192 | C6: 5 | D6: 0 | E6: 2.5
A7: Madeline | B7: 96 | C7: 2 | D7: 0 | E7: 2
A8: Joseph | B8: 168 | C8: 4 | D8: 1 | E8: 1.7142857
A9: Aivin | B9: 192 | C9: 3 | D9: 0 | E9: 1.5
A10: Shreyash | B10: 192 | C10: 5 | D10: 2 | E10: 1.5
A11: Kevin | B11: 168 | C11: 2 | D11: 0 | E11: 1.1428571
A12: Eashan | B12: 168 | C12: 2 | D12: 0 | E12: 1.1428571
A13: Jamis | B13: 168 | C13: 2 | D13: 0 | E13: 1.1428571
... A43: Tarun | B43: 96 | C43: 1 | D43: 2 | E43: -1

Sheet Biology
A1: {=sort(Stats!A1:A1000,Stats!X1:X1000,false)} -> Overall | B1: {=sort(Stats!D1:D1000,Stats!X1:X1000,false)} -> TUH | C1: {=sort(Stats!V1:X1000,Stats!X1:X1000,false)} -> B TU | D1: B Neg | E1: B PPG
A2: Aldric | B2: 192 | C2: 12 | D2: 4 | E2: 4
A3: Kevin | B3: 168 | C3: 7 | D3: 0 | E3: 4
A4: Aarush | B4: 240 | C4: 10 | D4: 1 | E4: 3.6
A5: Brendan | B5: 168 | C5: 5 | D5: 0 | E5: 2.8571429
A6: Kevin | B6: 168 | C6: 4 | D6: 0 | E6: 2.2857143
A7: Aditya | B7: 168 | C7: 4 | D7: 0 | E7: 2.2857143
A8: Aivin | B8: 192 | C8: 4 | D8: 0 | E8: 2
A9: Mihir | B9: 192 | C9: 4 | D9: 0 | E9: 2
A10: Iris | B10: 240 | C10: 6 | D10: 1 | E10: 2
A11: Jamis | B11: 168 | C11: 3 | D11: 0 | E11: 1.7142857
A12: Ankur | B12: 168 | C12: 2 | D12: 0 | E12: 1.1428571
A13: Liam | B13: 96 | C13: 2 | D13: 1 | E13: 1
... A43: Colin | B43: 144 | C43: 0 | D43: 1 | E43: -0.66666667

Sheet Physics
A1: {=sort(Stats!A1:A1000,Stats!AA1:AA1000,false)} -> Overall | B1: {=sort(Stats!D1:D1000,Stats!AA1:AA1000,false)} -> TUH | C1: {=sort(Stats!Y1:AA1000,Stats!AA1:AA1000,false)} -> P TU | D1: P Neg | E1: P PPG
A2: Aldric | B2: 192 | C2: 10 | D2: 2 | E2: 4
A3: Jacob | B3: 192 | C3: 8 | D3: 0 | E3: 4
A4: Brendan | B4: 168 | C4: 6 | D4: 1 | E4: 2.8571429
A5: Aarush | B5: 240 | C5: 7 | D5: 0 | E5: 2.8
A6: Eashan | B6: 168 | C6: 4 | D6: 0 | E6: 2.2857143
A7: Aivin | B7: 192 | C7: 4 | D7: 0 | E7: 2
A8: Liam | B8: 96 | C8: 2 | D8: 0 | E8: 2
A9: Jamis | B9: 168 | C9: 3 | D9: 0 | E9: 1.7142857
A10: Ankur | B10: 168 | C10: 3 | D10: 0 | E10: 1.7142857
A11: Joseph | B11: 168 | C11: 3 | D11: 0 | E11: 1.7142857
A12: Ian | B12: 144 | C12: 2 | D12: 0 | E12: 1.3333333
A13: Ethan | B13: 144 | C13: 2 | D13: 0 | E13: 1.3333333
... A43: Matthew | B43: 72 | C43: 0 | D43: 0 | E43: 0
