Workbook
Name Group2: LiveScoresheet!$J$6:$O$11

Sheet Team List
A1: Teams
A2: Code | B2: Team | C2: RR Group
A3: A1 | B3: BYE | C3: Amalgam
A4: A2 | B4: Basis Silicon Valley A | C4: Amalgam
A5: A3 | B5: Montgomery Blair B | C5: Amalgam
A6: A4 | B6: Enloe A | C6: Amalgam
A7: A5 | B7: Ward Melville C | C7: Amalgam
A8: A6 | B8: Collierville C | C8: Amalgam
A9: B1 | B9: Basis Chandler A | C9: Brass
A10: B2 | B10: Mission San Jose B | C10: Brass
A11: B3 | B11: Enloe B | C11: Brass
A12: B4 | B12: WWPS A | C12: Brass
A13: B5 | B13: Deep Run A | C13: Brass
... A44: G6 | B44: Princeton | C44: Steel

Sheet RR Pairings and Schedule
A1: RR Pairings and Schedule
A3: RR Pairings | H3: Schedule (Times in PDT)
H5: TIME | J5: ROUND
A6: Amalgam
A7: ROOM | B7: RR1 | C7: RR2 | D7: RR3 | E7: RR4 | F7: RR5 | H7: 7:45 - 8:00 a.m. PDT | J7: OPENING CEREMONY
A8: Amalgam-1 | B8: A1 — A2 | C8: A4— A5 | D8: A2 — A3 | E8: A1 — A5 | F8: A3 — A4
A9: Amalgam-2 | B9: A3 — A5 | C9: A1 — A3 | D9: A5 — A6 | E9: A2 — A4 | F9: A1 — A6 | H9: 8:00 - 8:35 a.m. PDT | J9: Round Robin 1
A10: Amalgam-3 | B10: A4 — A6 | C10: A2 — A6 | D10: A1 — A4 | E10: A3 — A6 | F10: A2 — A5
H11: 8:40 - 9:15 a.m. PDT | J11: Round Robin 2
A12: Brass
A13: ROOM | B13: RR1 | C13: RR2 | D13: RR3 | E13: RR4 | F13: RR5 | H13: 9:20 - 9:55 a.m. PDT | J13: Round Robin 3
A14: Brass-1 | B14: B1 — B2 | C14: B4— B5 | D14: B2 — B3 | E14: B1 — B5 | F14: B3 — B4
A15: Brass-2 | B15: B3 — B5 | C15: B1 — B3 | D15: B5 — B6 | E15: B2 — B4 | F15: B1 — B6 | H15: 10:00 - 10:35 a.m. PDT | J15: Round Robin 4
A16: Brass-3 | B16: B4 — B6 | C16: B2 — B6 | D16: B1 — B4 | E16: B3 — B6 | F16: B2 — B5
H17: 10:40 - 11:15 a.m. PDT | J17: Round Robin 5
A18: Bronze
A19: ROOM | B19: RR1 | C19: RR2 | D19: RR3 | E19: RR4 | F19: RR5 | H19: 11:15 - 12:15 p.m. PDT | J19: LUNCH BREAK
A20: Bronze-1 | B20: C1 — C2 | C20: C4— C5 | D20: C2 — C3 | E20: C1 — C5 | F20: C3 — C4
A21: Bronze-2 | B21: C3 — C5 | C21: C1 — C3 | D21: C5 — C6 | E21: C2 — C4 | F21: C1 — C6 | H21: 12:20 - 12:55 p.m. PDT | J21: Double Elimination 1 (top 16)
A22: Bronze-3 | B22: C4 — C6 | C22: C2 — C6 | D22: C1 — C4 | E22: C3 — C6 | F22: C2 — C5
H23: 1:00 - 1:35 p.m. PDT | J23: Double Elimination 2 (top 12)
A24: Nichrome
A25: ROOM | B25: RR1 | C25: RR2 | D25: RR3 | E25: RR4 | F25: RR5 | H25: 1:40 - 2:15 p.m. PDT | J25: Double Elimination 3 (top 8)
A26: Nichrome-1 | B26: D1 — D2 | C26: D4— D5 | D26: D2 — D3 | E26: D1 — D5 | F26: D3 — D4
A27: Nichrome-2 | B27: D3 — D5 | C27: D1 — D3 | D27: D5 — D6 | E27: D2 — D4 | F27: D1 — D6 | H27: 2:20 - 2:55 p.m. PDT | J27: Double Elimination 4 (top 6)
A28: Nichrome-3 | B28: D4 — D6 | C28: D2 — D6 | D28: D1 — D4 | E28: D3 — D6 | F28: D2 — D5
H29: 3:00 - 3:35 p.m. PDT | J29: Double Elimination 5 (top 4)
A30: Pewter
A31: ROOM | B31: RR1 | C31: RR2 | D31: RR3 | E31: RR4 | F31: RR5 | H31: 3:40 - 3:55 p.m. PDT | J31: BREAK
A32: Pewter-1 | B32: E1 — E2 | C32: E4— E5 | D32: E2 — E3 | E32: E1 — E5 | F32: E3 — E4
A33: Pewter-2 | B33: E3 — E5 | C33: E1 — E3 | D33: E5 — E6 | E33: E2 — E4 | F33: E1 — E6 | H33: 4:00 - 4:35 p.m. PDT | J33: Double Elimination 6 (top 3)
A34: Pewter-3 | B34: E4 — E6 | C34: E2 — E6 | D34: E1 — E4 | E34: E3 — E6 | F34: E2 — E5
H35: 4:40 - 5:15 p.m. PDT | J35: Double Elimination 7 (top 2)
A36: Solder
A37: ROOM | B37: RR1 | C37: RR2 | D37: RR3 | E37: RR4 | F37: RR5 | H37: 5:20 - 5:55 p.m. PDT | J37: Double Elimination 8 (if necessary)
A38: Solder-1 | B38: F1 — F2 | C38: F4— F5 | D38: F2 — F3 | E38: F1 — F5 | F38: F3 — F4
A39: Solder-2 | B39: F3 — F5 | C39: F1 — F3 | D39: F5 — F6 | E39: F2 — F4 | F39: F1 — F6 | H39: 6:20 - 6:35 p.m. PDT | J39: CLOSING CEREMONY
A40: Solder-3 | B40: F4 — F6 | C40: F2 — F6 | D40: F1 — F4 | E40: F3 — F6 | F40: F2 — F5
A42: Steel
A43: ROOM | B43: RR1 | C43: RR2 | D43: RR3 | E43: RR4 | F43: RR5
...

Sheet LiveScoresheet
A1: RR Live Scoresheet
A4: Amalgam | I4: Brass
A5: =SUM(B6:G11) -> 1234 | B5: {=INDEX(A6,0)} -> A1 | C5: {=INDEX(A7,0)} -> A2 | D5: {=INDEX(A8,0)} -> A3 | E5: {=INDEX(A9,0)} -> A4 | F5: {=INDEX(A10,0)} -> A5 | G5: {=INDEX(A11,0)} -> A6 | I5: =SUM(J6:O11) -> 2632 | J5: {=INDEX(I6,0)} -> B1 | K5: {=INDEX(I7,0)} -> B2 | L5: {=INDEX(I8,0)} -> B3 | M5: {=INDEX(I9,0)} -> B4 | N5: {=INDEX(I10,0)} -> B5 | O5: {=INDEX(I11,0)} -> B6
A6: A1 | C6: - | D6: - | E6: - | F6: - | G6: - | I6: B1 | K6: 32 | L6: 166 | M6: 66 | N6: 154 | O6: 96
A7: A2 | D7: 82 | E7: 104 | F7: 86 | G7: 138 | I7: B2 | J7: 114 | L7: 146 | M7: 78 | N7: 130 | O7: 68
A8: A3 | C8: 84 | E8: 102 | F8: 116 | G8: 100 | I8: B3 | J8: 18 | K8: 54 | M8: 14 | N8: 88 | O8: 26
A9: A4 | C9: 26 | D9: 64 | F9: 90 | G9: 82 | I9: B4 | J9: 104 | K9: 146 | L9: 118 | N9: 126 | O9: 144
A10: A5 | C10: 12 | D10: 30 | E10: 26 | G10: 24 | I10: B5 | J10: 50 | K10: 92 | L10: 134 | M10: 76 | O10: 118
A11: A6 | C11: 0 | D11: 4 | E11: 42 | F11: 22 | I11: B6 | J11: 6 | K11: 64 | L11: 66 | M11: 88 | N11: 50
A13: Bronze | I13: Nichrome
A14: =SUM(B15:G20) -> 2158 | B14: {=INDEX(A15,0)} -> C1 | C14: {=INDEX(A16,0)} -> C2 | D14: {=INDEX(A17,0)} -> C3 | E14: {=INDEX(A18,0)} -> C4 | F14: {=INDEX(A19,0)} -> C5 | G14: {=INDEX(A20,0)} -> C6 | I14: =SUM(J15:O20) -> 1676 | J14: {=INDEX(I15,0)} -> D1 | K14: {=INDEX(I16,0)} -> D2 | L14: {=INDEX(I17,0)} -> D3 | M14: {=INDEX(I18,0)} -> D4 | N14: {=INDEX(I19,0)} -> D5 | O14: {=INDEX(I20,0)} -> D6
A15: C1 | C15: 108 | D15: 64 | E15: 106 | F15: 36 | G15: 82 | I15: D1 | K15: - | L15: - | M15: - | N15: - | O15: -
A16: C2 | B16: 70 | D16: 50 | E16: 62 | F16: 40 | G16: 26 | I16: D2 | L16: 44 | M16: 54 | N16: 94 | O16: 14
A17: C3 | B17: 32 | C17: 110 | E17: 98 | F17: 140 | G17: 50 | I17: D3 | K17: 34 | M17: 4 | N17: 116 | O17: 8
A18: C4 | B18: 68 | C18: 104 | D18: 72 | F18: 82 | G18: 98 | I18: D4 | K18: 154 | L18: 172 | N18: 140 | O18: 182
A19: C5 | B19: 128 | C19: 54 | D19: 80 | E19: 106 | G19: 68 | I19: D5 | K19: 36 | L19: 56 | M19: 4 | O19: 18
A20: C6 | B20: 36 | C20: 36 | D20: 26 | E20: 80 | F20: 46 | I20: D6 | K20: 154 | L20: 184 | M20: 46 | N20: 162
A22: Pewter | I22: Solder
A23: =SUM(B24:G29) -> 2138 | B23: {=INDEX(A24,0)} -> E1 | C23: {=INDEX(A25,0)} -> E2 | D23: {=INDEX(A26,0)} -> E3 | E23: {=INDEX(A27,0)} -> E4 | F23: {=INDEX(A28,0)} -> E5 | G23: {=INDEX(A29,0)} -> E6 | I23: =SUM(J24:O29) -> 2700 | J23: {=INDEX(I24,0)} -> F1 | K23: {=INDEX(I25,0)} -> F2 | L23: {=INDEX(I26,0)} -> F3 | M23: {=INDEX(I27,0)} -> F4 | N23: {=INDEX(I28,0)} -> F5 | O23: {=INDEX(I29,0)} -> F6
A24: E1 | C24: 42 | D24: 8 | E24: 60 | F24: 20 | G24: 70 | I24: F1 | K24: 174 | L24: 142 | M24: 106 | N24: 122 | O24: 136
A25: E2 | B25: 138 | D25: 54 | E25: 72 | F25: 88 | G25: 58 | I25: F2 | J25: 28 | L25: 102 | M25: 22 | N25: 8 | O25: 12
A26: E3 | B26: 138 | C26: 154 | E26: 144 | F26: 164 | G26: 190 | I26: F3 | J26: 22 | K26: 14 | M26: 18 | N26: 0 | O26: 28
A27: E4 | B27: 56 | C27: 68 | D27: 16 | F27: 130 | G27: 150 | I27: F4 | J27: 84 | K27: 92 | L27: 178 | N27: 146 | O27: 158
A28: E5 | B28: 78 | C28: 36 | D28: 34 | E28: 16 | G28: 98 | I28: F5 | J28: 100 | K28: 142 | L28: 256 | M28: 84 | O28: 116
A29: E6 | B29: 12 | C29: 32 | D29: -4 | E29: 16 | F29: 0 | I29: F6 | J29: 56 | K29: 84 | L29: 114 | M29: 64 | N29: 92
A31: Steel
A32: =SUM(B33:G38) -> 1412 | B32: {=INDEX(A33,0)} -> G1 | C32: {=INDEX(A34,0)} -> G2 | D32: {=INDEX(A35,0)} -> G3 | E32: {=INDEX(A36,0)} -> G4 | F32: {=INDEX(A37,0)} -> G5 | G32: {=INDEX(A38,0)} -> G6
A33: G1 | C33: - | D33: - | E33: - | F33: - | G33: -
A34: G2 | D34: 64 | E34: 8 | F34: 18 | G34: 20
A35: G3 | C35: 40 | E35: 40 | F35: 26 | G35: 16
A36: G4 | C36: 120 | D36: 88 | F36: 14 | G36: 94
A37: G5 | C37: 128 | D37: 160 | E37: 218 | G37: 186
A38: G6 | C38: 34 | D38: 42 | E38: 50 | F38: 46

Sheet DE Seeding
A1: DE Seeding
A2: Code | B2: School | C2: DE Score
A3: G5 | B3: =VLOOKUP(A3, 'Team List'!$A$1:$C$44, 2, FALSE) -> Dulles | C3: 1404.25
A4: D4 | B4: =VLOOKUP(A4, 'Team List'!$A$1:$C$44, 2, FALSE) -> Montgomery Blair A | C4: 1354.2
A5: E3 | B5: =VLOOKUP(A5, 'Team List'!$A$1:$C$44, 2, FALSE) -> Mission San Jose A | C5: 1335.11
A6: F1 | B6: =VLOOKUP(A6, 'Team List'!$A$1:$C$44, 2, FALSE) -> Ward Melville A | C6: 1236.97
A7: B4 | B7: =VLOOKUP(A7, 'Team List'!$A$1:$C$44, 2, FALSE) -> WWPS A | C7: 1194.72
A8: F4 | B8: =VLOOKUP(A8, 'Team List'!$A$1:$C$44, 2, FALSE) -> School of Biology | C8: 1142.97
A9: D6 | B9: =VLOOKUP(A9, 'Team List'!$A$1:$C$44, 2, FALSE) -> Johnson A | C9: 1101.7
A10: F5 | B10: =VLOOKUP(A10, 'Team List'!$A$1:$C$44, 2, FALSE) -> North Hollywood B | C10: 1082.97
A11: A3 | B11: =VLOOKUP(A11, 'Team List'!$A$1:$C$44, 2, FALSE) -> Montgomery Blair B | C11: 1035.05
A12: B2 | B12: =VLOOKUP(A12, 'Team List'!$A$1:$C$44, 2, FALSE) -> Mission San Jose B | C12: 992.717
A13: A2 | B13: =VLOOKUP(A13, 'Team List'!$A$1:$C$44, 2, FALSE) -> Basis Silicon Valley A | C13: 980.047
A14: C3 | B14: =VLOOKUP(A14, 'Team List'!$A$1:$C$44, 2, FALSE) -> North Hollywood A | C14: 893.534
... A18: C1 | B18: =VLOOKUP(A18, 'Team List'!$A$1:$C$44, 2, FALSE) -> Arcadia A | C18: 841.534

Sheet DE Bracket
A1: 13:00-13:35 | C1: 13:40-14:15 | E1: 14:20-14:55 | G1: 15:00-15:35 | I1: 15:40-16:15 | K1: 16:55-17:30
A2: TIMES IN PST
A4: Dulles | B4: 96
A5: ROOM 1 | E5: Dulles | F5: 22
A6: North Hollywood B | B6: 58
E7: ROOM 1 | I7: Ward Melville A | J7: 34
A8: Ward Melville A | B8: 88
A9: ROOM 2 | E9: Ward Melville A | F9: 88
A10: WWPS A | B10: 72
I11: STAGE 1 | M11: Montgomery Blair A | N11: 16
A12: Mission San Jose A | B12: 74
A13: ROOM 3 | E13: School of Biology | F13: 52
A14: School of Biology | B14: 134
E15: ROOM 2 | I15: Montgomery Blair A | J15: 60
A16: Montgomery Blair A | B16: 96
A17: ROOM 4 | E17: Montgomery Blair A | F17: 84
A18: Johnson A | B18: 62 | K18: Ward Melville A | L18: 96
G22: Dulles | H22: 58
C24: North Hollywood B | D24: 150
C26: ROOM 5 | E26: North Hollywood B | F26: 106 | G26: ROOM 3 | I26: Dulles | J26: 62 | M26: Ward Melville A | N26: 0
A27: North Hollywood A | B27: 74
A28: ROOM 5 | C28: Basis Chandler A | D28: 28
A29: Basis Chandler A | B29: 92
E30: ROOM 3 | G30: North Hollywood B | H30: 30
C32: WWPS A | D32: 42
C34: ROOM 6 | E34: James Clemens | F34: 32 | I34: STAGE 2 | K34: Dulles | L34: 12
A35: Basis Silicon Valley A | B35: 28
A36: ROOM 6 | C36: James Clemens | D36: 76
A37: James Clemens | B37: 48
G38: School of Biology | H38: 96
C40: Mission San Jose A | D40: 156
C42: ROOM 7 | E42: Mission San Jose A | F42: 58 | G42: ROOM 4 | I42: School of Biology | J42: 56
A43: Mission San Jose B | B43: 120
A44: ROOM 7 | C44: Mission San Jose B | D44: 16
A45: Arcadia B | B45: 42
E46: ROOM 4 | G46: Mission San Jose A | H46: 72
C48: Johnson A | D48: 78
C50: ROOM 8 | E50: Johnson A | F50: 50
A51: Montgomery Blair B | B51: 80
A52: ROOM 8 | C52: Montgomery Blair B | D52: 60
...
