Workbook

Sheet All
B1: Eisenhower B | C1: Eisenhower B | D1: Eisenhower B | E1: Eisenhower B | F1: Eisenhower B | G1: Middleton A | H1: Middleton A | I1: Middleton A | J1: Middleton A | K1: Middleton A | L1: Middleton C | M1: Middleton C | N1: Middleton C | O1: Middleton C | P1: Middleton C | Q1: Whitney Young | R1: Whitney Young | S1: Whitney Young | T1: Whitney Young | U1: Whitney Young | V1: Brookfield | W1: Brookfield | X1: Brookfield | Y1: Brookfield | Z1: Brookfield | AA1: Eisenhower A | AB1: Eisenhower A | AC1: Eisenhower A | AD1: Eisenhower A | AE1: Eisenhower A | AF1: West | AG1: West | AH1: West | AI1: West | AJ1: West | AK1: Middleton B | AL1: Middleton B | AM1: Middleton B | AN1: Middleton B | AO1: Middleton B
B2: Nathan | C2: Pratyush | D2: Ethan | E2: Sai | F2: Alex | G2: Harry | H2: Nihar | I2: Ray | J2: Owen | L2: Frank | M2: Abhinav | N2: Sai K | O2: Arjun | Q2: Arnav | R2: Evan | S2: Miller | T2: Stephen | U2: Sam | V2: Kartik | W2: Josh | X2: Saathvik | Y2: Avaneesh | Z2: Om | AA2: Sujay | AB2: Dhruva | AC2: Manzoor | AD2: Andrew | AE2: Prani | AF2: Kevin | AG2: Tim | AH2: Samanyu | AI2: William | AK2: Li | AL2: Vaidya | AM2: Kriti | AN2: Ian
B3: TRUE | C3: TRUE | D3: TRUE | E3: TRUE | F3: TRUE | G3: TRUE | H3: TRUE | I3: TRUE | J3: TRUE | K3: FALSE | L3: TRUE | M3: TRUE | N3: TRUE | O3: TRUE | P3: FALSE | Q3: TRUE | R3: TRUE | S3: TRUE | T3: TRUE | U3: TRUE | V3: TRUE | W3: TRUE | X3: TRUE | Y3: TRUE | Z3: TRUE | AA3: TRUE | AB3: TRUE | AC3: TRUE | AD3: TRUE | AE3: TRUE | AF3: TRUE | AG3: TRUE | AH3: TRUE | AI3: TRUE | AJ3: FALSE | AK3: TRUE | AL3: TRUE | AM3: TRUE | AN3: TRUE | AO3: FALSE
A4: X | H4: -4 | K4: 0 | L4: 4 | P4: 0 | AB4: 4 | AJ4: 0 | AM4: 4 | AO4: 0
A5: M | C5: 4 | K5: 0 | P5: 0 | Q5: 4 | W5: 4 | AI5: -4 | AJ5: 0 | AO5: 0
A6: C | G6: 4 | K6: 0 | P6: 0 | R6: 4 | W6: 4 | AJ6: 0 | AK6: 4 | AO6: 0
A7: E | C7: 4 | K7: 0 | L7: 4 | P7: 0 | AB7: 4 | AJ7: 0 | AN7: 4 | AO7: 0
A8: B | G8: 4 | K8: 0 | P8: 0 | R8: 4 | W8: 4 | AJ8: 0 | AK8: 4 | AO8: 0
A9: P | J9: 4 | K9: 0 | P9: 0 | Q9: 4 | AD9: 4 | AJ9: 0 | AN9: 4 | AO9: 0
A10: X | I10: 4 | K10: 0 | P10: 0 | W10: 4 | AG10: 4 | AJ10: 0 | AO10: 0
A11: M | K11: 0 | P11: 0 | Q11: 4 | AC11: 4 | AI11: 4 | AJ11: 0 | AO11: 0
A12: C | K12: 0 | P12: 0 | R12: 4 | W12: -4 | AC12: 4 | AJ12: 0 | AO12: 0
A13: E | I13: 4 | K13: 0 | P13: 0 | R13: 4 | W13: 4 | AI13: 4 | AJ13: 0 | AO13: 0
A14: B | J14: -4 | K14: 0 | N14: 4 | P14: 0 | W14: 4 | AJ14: 0 | AO14: 0
A15: P | I15: 4 | K15: 0 | P15: 0 | R15: 4 | W15: 4 | AJ15: 0 | AK15: 4 | AO15: 0
B16: TRUE | C16: TRUE | D16: TRUE | E16: TRUE | F16: TRUE | G16: TRUE | H16: TRUE | I16: TRUE | J16: TRUE | K16: TRUE | L16: TRUE | M16: TRUE | N16: TRUE | O16: TRUE | P16: FALSE | Q16: TRUE | R16: TRUE | S16: TRUE | T16: TRUE | U16: TRUE | V16: TRUE | W16: TRUE | X16: TRUE | Y16: TRUE | Z16: TRUE | AA16: TRUE | AB16: TRUE | AC16: TRUE | AD16: TRUE | AE16: TRUE | AF16: TRUE | AG16: TRUE | AH16: TRUE | AI16: TRUE | AJ16: FALSE | AK16: TRUE | AL16: TRUE | AM16: TRUE | AN16: TRUE | AO16: FALSE
A17: X | G17: 4 | P17: 0 | R17: 4 | V17: 4 | AF17: 4 | AJ17: 0 | AO17: 0
A18: M | G18: 4 | P18: 0 | R18: 4 | W18: 4 | AI18: 4 | AJ18: 0 | AO18: 0
A19: C | G19: 4 | P19: 0 | AC19: 4 | AJ19: 0 | AO19: 0
A20: E | G20: 4 | N20: -4 | P20: 0 | W20: 4 | AI20: -4 | AJ20: 0 | AO20: 0
A21: B | I21: 4 | P21: 0 | S21: 4 | W21: 4 | AH21: 4 | AJ21: 0 | AO21: 0
A22: P | C22: 4 | P22: 0 | S22: 4 | AC22: 4 | AI22: 4 | AJ22: 0 | AO22: 0
A23: X | J23: 4 | P23: 0 | Q23: 4 | AB23: 4 | AI23: 4 | AJ23: 0 | AO23: 0
A24: M | I24: 4 | P24: 0 | Q24: 4 | W24: 4 | AJ24: 0 | AK24: 4 | AO24: 0
A25: C | G25: 4 | P25: 0 | R25: 4 | W25: 4 | AH25: 4 | AJ25: 0 | AO25: 0
A26: E | H26: 4 | P26: 0 | R26: 4 | W26: 4 | AJ26: 0 | AM26: 4 | AO26: 0
A27: B | J27: 4 | P27: 0 | T27: 4 | AC27: 4 | AH27: 4 | AJ27: 0 | AO27: 0
A28: P | J28: 4 | L28: 4 | P28: 0 | AD28: 4 | AJ28: 0 | AN28: 4 | AO28: 0
B31: Middleton A | C31: Middleton A | D31: Middleton A | E31: Middleton A | F31: Middleton A | G31: Whitney Young | H31: Whitney Young | I31: Whitney Young | J31: Whitney Young | K31: Whitney Young | L31: Middleton C | M31: Middleton C | N31: Middleton C | O31: Middleton C | P31: Middleton C | Q31: Eisenhower B | R31: Eisenhower B | S31: Eisenhower B | T31: Eisenhower B | U31: Eisenhower B | V31: West | W31: West | X31: West | Y31: West | Z31: West | AA31: Eisenhower A | AB31: Eisenhower A | AC31: Eisenhower A | AD31: Eisenhower A | AE31: Eisenhower A | AF31: Brookfield | AG31: Brookfield | AH31: Brookfield | AI31: Brookfield | AJ31: Brookfield | AK31: Middleton B | AL31: Middleton B | AM31: Middleton B | AN31: Middleton B | AO31: Middleton B
B32: Harry | C32: Nihar | D32: Ray | E32: Owen | G32: Arnav | H32: Evan | I32: Miller | J32: Stephen | K32: Sam | L32: Frank | M32: Abhinav | N32: Sai K | O32: Arjun | Q32: Nathan | R32: Ethan | S32: Pratyush | T32: Sai | U32: Alex | V32: Kevin | W32: Tim | X32: Samanyu | Y32: William | AA32: Sujay | AB32: Dhruva | AC32: Manzoor | AD32: Andrew | AE32: Prani | AF32: Kartik | AG32: Josh | AH32: Saathvik | AI32: Avaneesh | AJ32: Om | AK32: Li | AL32: Vaidya | AM32: Kriti | AN32: Ian
B33: TRUE | C33: TRUE | D33: TRUE | E33: TRUE | F33: FALSE | G33: TRUE | H33: TRUE | I33: TRUE | J33: TRUE | K33: TRUE | L33: TRUE | M33: TRUE | N33: TRUE | O33: TRUE | P33: FALSE | Q33: TRUE | R33: TRUE | S33: TRUE | T33: TRUE | U33: TRUE | V33: TRUE | W33: TRUE | X33: TRUE | Y33: TRUE | Z33: FALSE | AA33: TRUE | AB33: TRUE | AC33: TRUE | AD33: TRUE | AE33: TRUE | AF33: TRUE | AG33: TRUE | AH33: TRUE | AI33: TRUE | AJ33: TRUE | AK33: TRUE | AL33: TRUE | AM33: TRUE | AN33: TRUE | AO33: FALSE
A34: X | F34: 0 | J34: 4 | N34: 4 | P34: 0 | Z34: 0 | AE34: 4 | AH34: 4 | AO34: 0
A35: M | B35: 4 | F35: 0 | P35: 0 | S35: 4 | Z35: 0 | AD35: 4 | AG35: 4 | AO35: 0
A36: C | B36: -4 | F36: 0 | G36: 4 | P36: 0 | Z36: 0 | AC36: 4 | AG36: 4 | AO36: 0
A37: E | B37: 4 | F37: 0 | O37: -4 | P37: 0 | S37: 4 | Z37: 0 | AB37: 4 | AH37: 4 | AO37: 0
A38: B | E38: 4 | F38: 0 | P38: 0 | S38: 4 | Z38: 0 | AE38: 4 | AG38: 4 | AO38: 0
A39: P | D39: 4 | F39: 0 | P39: 0 | S39: 4 | Z39: 0 | AC39: 4 | AG39: 4 | AO39: 0
A40: X | B40: 4 | F40: 0 | P40: 0 | Z40: 0 | AC40: 4 | AG40: 4 | AO40: 0
A41: M | F41: 0 | G41: 4 | P41: 0 | V41: 4 | Z41: 0 | AF41: 4 | AO41: 0
A42: C | B42: 4 | F42: 0 | P42: 0 | Z42: 0 | AC42: 4 | AH42: 0 | AN42: 0 | AO42: 0
...

Sheet Full
A1: Eisenhower B | B1: Eisenhower B | C1: Middleton A | D1: Middleton A | E1: Middleton C | F1: Middleton C | G1: Whitney Young | H1: Whitney Young | I1: Brookfield | J1: Brookfield | K1: Eisenhower A | L1: Eisenhower A | M1: West | N1: West | O1: Middleton B | P1: Middleton B
A2: Bonus | B2: Score | C2: Bonus | D2: Score | E2: Bonus | F2: Score | G2: Bonus | H2: Score | I2: Bonus | J2: Score | K2: Bonus | L2: Score | M2: Bonus | N2: Score | O2: Bonus | P2: Score
B4: 4 | D4: 0 | F4: 4 | H4: 0 | J4: 0 | K4: 10 | L4: 14 | N4: 0 | O4: 10 | P4: 14
A5: 0 | B5: 8 | D5: 0 | F5: 4 | G5: 10 | H5: 14 | I5: 10 | J5: 14 | L5: 14 | N5: 0 | P5: 18
B6: 8 | C6: 0 | D6: 4 | F6: 4 | G6: 0 | H6: 18 | I6: 10 | J6: 28 | L6: 14 | N6: 0 | O6: 0 | P6: 22
A7: 0 | B7: 12 | D7: 4 | E7: 10 | F7: 18 | H7: 18 | J7: 28 | K7: 0 | L7: 18 | N7: 0 | O7: 10 | P7: 36
B8: 12 | C8: 10 | D8: 18 | F8: 18 | G8: 10 | H8: 32 | I8: 10 | J8: 42 | L8: 18 | N8: 0 | O8: 10 | P8: 50
B9: 12 | C9: 10 | D9: 32 | F9: 18 | G9: 10 | H9: 46 | J9: 42 | K9: 0 | L9: 22 | N9: 0 | O9: 0 | P9: 54
B10: 12 | C10: 10 | D10: 46 | F10: 18 | H10: 46 | I10: 10 | J10: 56 | L10: 22 | M10: 10 | N10: 14 | P10: 54
B11: 12 | D11: 46 | F11: 18 | G11: 10 | H11: 60 | J11: 56 | K11: 10 | L11: 36 | M11: 10 | N11: 28 | P11: 54
B12: 12 | D12: 46 | F12: 18 | G12: 10 | H12: 74 | J12: 56 | K12: 10 | L12: 54 | N12: 28 | P12: 54
B13: 12 | C13: 10 | D13: 60 | F13: 18 | G13: 10 | H13: 88 | I13: 10 | J13: 70 | L13: 54 | M13: 10 | N13: 42 | P13: 54
B14: 16 | D14: 60 | E14: 0 | F14: 22 | H14: 88 | I14: 10 | J14: 84 | L14: 54 | N14: 42 | P14: 54
B15: 16 | C15: 10 | D15: 74 | F15: 22 | G15: 0 | H15: 92 | I15: 10 | J15: 98 | L15: 54 | N15: 42 | O15: 0 | P15: 58
B17: 16 | C17: 10 | D17: 88 | F17: 22 | G17: 10 | H17: 106 | I17: 10 | J17: 112 | L17: 54 | M17: 0 | N17: 46 | P17: 58
B18: 16 | C18: 10 | D18: 102 | F18: 22 | G18: 10 | H18: 120 | I18: 10 | J18: 126 | L18: 54 | M18: 10 | N18: 60 | P18: 58
B19: 16 | C19: 10 | D19: 116 | F19: 22 | H19: 120 | J19: 126 | K19: 0 | L19: 58 | N19: 60 | P19: 58
B20: 16 | C20: 10 | D20: 130 | F20: 22 | H20: 124 | I20: 10 | J20: 140 | L20: 58 | N20: 60 | P20: 62
B21: 16 | C21: 10 | D21: 144 | F21: 22 | G21: 10 | H21: 138 | I21: 10 | J21: 154 | L21: 58 | M21: 10 | N21: 74 | P21: 62
A22: 0 | B22: 20 | D22: 144 | F22: 22 | G22: 0 | H22: 142 | J22: 154 | K22: 0 | L22: 62 | M22: 0 | N22: 78 | P22: 62
B23: 20 | C23: 10 | D23: 158 | F23: 22 | G23: 0 | H23: 146 | J23: 154 | K23: 10 | L23: 76 | M23: 0 | N23: 82 | P23: 62
B24: 20 | C24: 10 | D24: 172 | F24: 22 | G24: 10 | H24: 160 | I24: 10 | J24: 168 | L24: 76 | N24: 82 | O24: 10 | P24: 76
B25: 20 | C25: 10 | D25: 186 | F25: 22 | G25: 10 | H25: 174 | I25: 10 | J25: 182 | L25: 76 | M25: 10 | N25: 96 | P25: 76
B26: 20 | C26: 10 | D26: 200 | F26: 22 | G26: 0 | H26: 178 | I26: 10 | J26: 196 | L26: 76 | N26: 96 | O26: 10 | P26: 90
B27: 20 | C27: 10 | D27: 214 | F27: 22 | G27: 0 | H27: 182 | J27: 196 | K27: 10 | L27: 90 | M27: 0 | N27: 100 | P27: 90
B28: 20 | C28: 0 | D28: 218 | E28: 0 | F28: 26 | H28: 182 | J28: 196 | K28: 0 | L28: 94 | N28: 100 | O28: 0 | P28: 94
A31: Middleton A | B31: Middleton A | C31: Whitney Young | D31: Whitney Young | E31: Middleton C | F31: Middleton C | G31: Eisenhower B | H31: Eisenhower B | I31: West | J31: West | K31: Eisenhower A | L31: Eisenhower A | M31: Brookfield | N31: Brookfield | O31: Middleton B | P31: Middleton B
A32: Bonus | B32: Score | C32: Bonus | D32: Score | E32: Bonus | F32: Score | G32: Bonus | H32: Score | I32: Bonus | J32: Score | K32: Bonus | L32: Score | M32: Bonus | N32: Score | O32: Bonus | P32: Score
B34: 0 | C34: 10 | D34: 14 | E34: 10 | F34: 14 | H34: 0 | J34: 0 | K34: 10 | L34: 14 | M34: 10 | N34: 14 | P34: 0
A35: 10 | B35: 14 | D35: 14 | F35: 14 | G35: 0 | H35: 4 | J35: 0 | K35: 0 | L35: 18 | M35: 10 | N35: 28 | P35: 0
B36: 14 | C36: 10 | D36: 32 | F36: 14 | H36: 4 | J36: 0 | K36: 10 | L36: 32 | M36: 10 | N36: 42 | P36: 0
A37: 10 | B37: 28 | D37: 32 | F37: 14 | G37: 10 | H37: 22 | J37: 0 | K37: 0 | L37: 36 | M37: 10 | N37: 56 | P37: 0
A38: 0 | B38: 32 | D38: 32 | F38: 14 | G38: 0 | H38: 26 | J38: 0 | K38: 10 | L38: 50 | M38: 0 | N38: 60 | P38: 0
A39: 0 | B39: 36 | D39: 32 | F39: 14 | G39: 0 | H39: 30 | J39: 0 | K39: 0 | L39: 54 | M39: 10 | N39: 74 | P39: 0
A40: 10 | B40: 50 | D40: 32 | F40: 14 | H40: 30 | J40: 0 | K40: 10 | L40: 68 | M40: 10 | N40: 88 | P40: 0
B41: 50 | C41: 10 | D41: 46 | F41: 14 | H41: 30 | I41: 0 | J41: 4 | L41: 68 | M41: 0 | N41: 92 | P41: 0
A42: 10 | B42: 64 | D42: 46 | F42: 14 | H42: 30 | J42: 4 | K42: 0 | L42: 72 | N42: 92 | P42: 0
A43: 10 | B43: 78 | D43: 46 | E43: 0 | F43: 18 | H43: 30 | J43: 4 | K43: 10 | L43: 86 | M43: 10 | N43: 106 | P43: 0
B44: 78 | D44: 46 | F44: 18 | H44: 30 | J44: 4 | L44: 86 | M44: 10 | N44: 120 | P44: 0
B45: 78 | C45: 0 | D45: 50 | F45: 18 | H45: 30 | I45: 10 | J45: 18 | L45: 86 | M45: 10 | N45: 134 | P45: 0
...

Sheet Sorted
B1: {=transpose(sort(transpose(All!B1:AO30),2,true))} -> Middleton C | C1: Eisenhower B | D1: Eisenhower A | E1: Middleton C | F1: Whitney Young | G1: Brookfield | H1: Eisenhower A | I1: Eisenhower B | J1: Whitney Young | K1: Middleton C | L1: Middleton A | M1: Middleton B | N1: Brookfield | O1: Brookfield | P1: West | Q1: Middleton B | R1: Middleton B | S1: Eisenhower A | T1: Whitney Young | U1: Eisenhower B | V1: Middleton A | W1: Brookfield | X1: Middleton A | Y1: Eisenhower A | Z1: Eisenhower B | AA1: Middleton A | AB1: Brookfield | AC1: Eisenhower B | AD1: Middleton C | AE1: Whitney Young | AF1: West | AG1: Whitney Young | AH1: Eisenhower A | AI1: West | AJ1: Middleton B | AK1: West | AL1: Middleton A | AM1: Middleton C | AN1: West | AO1: Middleton B
B2: Abhinav | C2: Alex | D2: Andrew | E2: Arjun | F2: Arnav | G2: Avaneesh | H2: Dhruva | I2: Ethan | J2: Evan | K2: Frank | L2: Harry | M2: Ian | N2: Josh | O2: Kartik | P2: Kevin | Q2: Kriti | R2: Li | S2: Manzoor | T2: Miller | U2: Nathan | V2: Nihar | W2: Om | X2: Owen | Y2: Prani | Z2: Pratyush | AA2: Ray | AB2: Saathvik | AC2: Sai | AD2: Sai K | AE2: Sam | AF2: Samanyu | AG2: Stephen | AH2: Sujay | AI2: Tim | AJ2: Vaidya | AK2: William
B3: TRUE | C3: TRUE | D3: TRUE | E3: TRUE | F3: TRUE | G3: TRUE | H3: TRUE | I3: TRUE | J3: TRUE | K3: TRUE | L3: TRUE | M3: TRUE | N3: TRUE | O3: TRUE | P3: TRUE | Q3: TRUE | R3: TRUE | S3: TRUE | T3: TRUE | U3: TRUE | V3: TRUE | W3: TRUE | X3: TRUE | Y3: TRUE | Z3: TRUE | AA3: TRUE | AB3: TRUE | AC3: TRUE | AD3: TRUE | AE3: TRUE | AF3: TRUE | AG3: TRUE | AH3: TRUE | AI3: TRUE | AJ3: TRUE | AK3: TRUE | AL3: FALSE | AM3: FALSE | AN3: FALSE | AO3: FALSE
A4: X | H4: 4 | K4: 4 | Q4: 4 | V4: -4 | AL4: 0 | AM4: 0 | AN4: 0 | AO4: 0
A5: M | F5: 4 | N5: 4 | Z5: 4 | AK5: -4 | AL5: 0 | AM5: 0 | AN5: 0 | AO5: 0
A6: C | J6: 4 | L6: 4 | N6: 4 | R6: 4 | AL6: 0 | AM6: 0 | AN6: 0 | AO6: 0
A7: E | H7: 4 | K7: 4 | M7: 4 | Z7: 4 | AL7: 0 | AM7: 0 | AN7: 0 | AO7: 0
A8: B | J8: 4 | L8: 4 | N8: 4 | R8: 4 | AL8: 0 | AM8: 0 | AN8: 0 | AO8: 0
A9: P | D9: 4 | F9: 4 | M9: 4 | X9: 4 | AL9: 0 | AM9: 0 | AN9: 0 | AO9: 0
A10: X | N10: 4 | AA10: 4 | AI10: 4 | AL10: 0 | AM10: 0 | AN10: 0 | AO10: 0
A11: M | F11: 4 | S11: 4 | AK11: 4 | AL11: 0 | AM11: 0 | AN11: 0 | AO11: 0
A12: C | J12: 4 | N12: -4 | S12: 4 | AL12: 0 | AM12: 0 | AN12: 0 | AO12: 0
A13: E | J13: 4 | N13: 4 | AA13: 4 | AK13: 4 | AL13: 0 | AM13: 0 | AN13: 0 | AO13: 0
A14: B | N14: 4 | X14: -4 | AD14: 4 | AL14: 0 | AM14: 0 | AN14: 0 | AO14: 0
A15: P | J15: 4 | N15: 4 | R15: 4 | AA15: 4 | AL15: 0 | AM15: 0 | AN15: 0 | AO15: 0
B16: TRUE | C16: TRUE | D16: TRUE | E16: TRUE | F16: TRUE | G16: TRUE | H16: TRUE | I16: TRUE | J16: TRUE | K16: TRUE | L16: TRUE | M16: TRUE | N16: TRUE | O16: TRUE | P16: TRUE | Q16: TRUE | R16: TRUE | S16: TRUE | T16: TRUE | U16: TRUE | V16: TRUE | W16: TRUE | X16: TRUE | Y16: TRUE | Z16: TRUE | AA16: TRUE | AB16: TRUE | AC16: TRUE | AD16: TRUE | AE16: TRUE | AF16: TRUE | AG16: TRUE | AH16: TRUE | AI16: TRUE | AJ16: TRUE | AK16: TRUE | AL16: TRUE | AM16: FALSE | AN16: FALSE | AO16: FALSE
A17: X | J17: 4 | L17: 4 | O17: 4 | P17: 4 | AM17: 0 | AN17: 0 | AO17: 0
A18: M | J18: 4 | L18: 4 | N18: 4 | AK18: 4 | AM18: 0 | AN18: 0 | AO18: 0
A19: C | L19: 4 | S19: 4 | AM19: 0 | AN19: 0 | AO19: 0
A20: E | L20: 4 | N20: 4 | AD20: -4 | AK20: -4 | AM20: 0 | AN20: 0 | AO20: 0
A21: B | N21: 4 | T21: 4 | AA21: 4 | AF21: 4 | AM21: 0 | AN21: 0 | AO21: 0
A22: P | S22: 4 | T22: 4 | Z22: 4 | AK22: 4 | AM22: 0 | AN22: 0 | AO22: 0
A23: X | F23: 4 | H23: 4 | X23: 4 | AK23: 4 | AM23: 0 | AN23: 0 | AO23: 0
A24: M | F24: 4 | N24: 4 | R24: 4 | AA24: 4 | AM24: 0 | AN24: 0 | AO24: 0
A25: C | J25: 4 | L25: 4 | N25: 4 | AF25: 4 | AM25: 0 | AN25: 0 | AO25: 0
A26: E | J26: 4 | N26: 4 | Q26: 4 | V26: 4 | AM26: 0 | AN26: 0 | AO26: 0
A27: B | S27: 4 | X27: 4 | AF27: 4 | AG27: 4 | AM27: 0 | AN27: 0 | AO27: 0
A28: P | D28: 4 | K28: 4 | M28: 4 | X28: 4 | AM28: 0 | AN28: 0 | AO28: 0
B31: {=transpose(sort(transpose(All!B31:AO60),2,true))} -> Middleton C | C31: Eisenhower B | D31: Eisenhower A | E31: Middleton C | F31: Whitney Young | G31: Brookfield | H31: Eisenhower A | I31: Eisenhower B | J31: Whitney Young | K31: Middleton C | L31: Middleton A | M31: Middleton B | N31: Brookfield | O31: Brookfield | P31: West | Q31: Middleton B | R31: Middleton B | S31: Eisenhower A | T31: Whitney Young | U31: Eisenhower B | V31: Middleton A | W31: Brookfield | X31: Middleton A | Y31: Eisenhower A | Z31: Eisenhower B | AA31: Middleton A | AB31: Brookfield | AC31: Eisenhower B | AD31: Middleton C | AE31: Whitney Young | AF31: West | AG31: Whitney Young | AH31: Eisenhower A | AI31: West | AJ31: Middleton B | AK31: West | AL31: Middleton A | AM31: Middleton C | AN31: West | AO31: Middleton B
B32: Abhinav | C32: Alex | D32: Andrew | E32: Arjun | F32: Arnav | G32: Avaneesh | H32: Dhruva | I32: Ethan | J32: Evan | K32: Frank | L32: Harry | M32: Ian | N32: Josh | O32: Kartik | P32: Kevin | Q32: Kriti | R32: Li | S32: Manzoor | T32: Miller | U32: Nathan | V32: Nihar | W32: Om | X32: Owen | Y32: Prani | Z32: Pratyush | AA32: Ray | AB32: Saathvik | AC32: Sai | AD32: Sai K | AE32: Sam | AF32: Samanyu | AG32: Stephen | AH32: Sujay | AI32: Tim | AJ32: Vaidya | AK32: William
B33: TRUE | C33: TRUE | D33: TRUE | E33: TRUE | F33: TRUE | G33: TRUE | H33: TRUE | I33: TRUE | J33: TRUE | K33: TRUE | L33: TRUE | M33: TRUE | N33: TRUE | O33: TRUE | P33: TRUE | Q33: TRUE | R33: TRUE | S33: TRUE | T33: TRUE | U33: TRUE | V33: TRUE | W33: TRUE | X33: TRUE | Y33: TRUE | Z33: TRUE | AA33: TRUE | AB33: TRUE | AC33: TRUE | AD33: TRUE | AE33: TRUE | AF33: TRUE | AG33: TRUE | AH33: TRUE | AI33: TRUE | AJ33: TRUE | AK33: TRUE | AL33: FALSE | AM33: FALSE | AN33: FALSE | AO33: FALSE
A34: X | Y34: 4 | AB34: 4 | AD34: 4 | AG34: 4 | AL34: 0 | AM34: 0 | AN34: 0 | AO34: 0
A35: M | D35: 4 | L35: 4 | N35: 4 | Z35: 4 | AL35: 0 | AM35: 0 | AN35: 0 | AO35: 0
A36: C | F36: 4 | L36: -4 | N36: 4 | S36: 4 | AL36: 0 | AM36: 0 | AN36: 0 | AO36: 0
A37: E | E37: -4 | H37: 4 | L37: 4 | Z37: 4 | AB37: 4 | AL37: 0 | AM37: 0 | AN37: 0 | AO37: 0
A38: B | N38: 4 | X38: 4 | Y38: 4 | Z38: 4 | AL38: 0 | AM38: 0 | AN38: 0 | AO38: 0
A39: P | N39: 4 | S39: 4 | Z39: 4 | AA39: 4 | AL39: 0 | AM39: 0 | AN39: 0 | AO39: 0
A40: X | L40: 4 | N40: 4 | S40: 4 | AL40: 0 | AM40: 0 | AN40: 0 | AO40: 0
A41: M | F41: 4 | O41: 4 | P41: 4 | AL41: 0 | AM41: 0 | AN41: 0 | AO41: 0
A42: C | L42: 4 | M42: 0 | S42: 4 | AB42: 0 | AL42: 0 | AM42: 0 | AN42: 0 | AO42: 0
...

Sheet Sorted Team
B1: {=transpose(sort(transpose(Full!A1:R30),1,true))} -> Brookfield | C1: Brookfield | D1: Eisenhower A | E1: Eisenhower A | F1: Eisenhower B | G1: Eisenhower B | H1: Middleton A | I1: Middleton A | J1: Middleton B | K1: Middleton B | L1: Middleton C | M1: Middleton C | N1: West | O1: West | P1: Whitney Young | Q1: Whitney Young
B2: Bonus | C2: Score | D2: Bonus | E2: Score | F2: Bonus | G2: Score | H2: Bonus | I2: Score | J2: Bonus | K2: Score | L2: Bonus | M2: Score | N2: Bonus | O2: Score | P2: Bonus | Q2: Score
A4: X | C4: 0 | D4: 10 | E4: 14 | G4: 4 | I4: 0 | J4: 10 | K4: 14 | M4: 4 | O4: 0 | Q4: 0
A5: M | B5: 10 | C5: 14 | E5: 14 | F5: 0 | G5: 8 | I5: 0 | K5: 18 | M5: 4 | O5: 0 | P5: 10 | Q5: 14
A6: C | B6: 10 | C6: 28 | E6: 14 | G6: 8 | H6: 0 | I6: 4 | J6: 0 | K6: 22 | M6: 4 | O6: 0 | P6: 0 | Q6: 18
A7: E | C7: 28 | D7: 0 | E7: 18 | F7: 0 | G7: 12 | I7: 4 | J7: 10 | K7: 36 | L7: 10 | M7: 18 | O7: 0 | Q7: 18
A8: B | B8: 10 | C8: 42 | E8: 18 | G8: 12 | H8: 10 | I8: 18 | J8: 10 | K8: 50 | M8: 18 | O8: 0 | P8: 10 | Q8: 32
A9: P | C9: 42 | D9: 0 | E9: 22 | G9: 12 | H9: 10 | I9: 32 | J9: 0 | K9: 54 | M9: 18 | O9: 0 | P9: 10 | Q9: 46
A10: X | B10: 10 | C10: 56 | E10: 22 | G10: 12 | H10: 10 | I10: 46 | K10: 54 | M10: 18 | N10: 10 | O10: 14 | Q10: 46
A11: M | C11: 56 | D11: 10 | E11: 36 | G11: 12 | I11: 46 | K11: 54 | M11: 18 | N11: 10 | O11: 28 | P11: 10 | Q11: 60
A12: C | C12: 56 | D12: 10 | E12: 54 | G12: 12 | I12: 46 | K12: 54 | M12: 18 | O12: 28 | P12: 10 | Q12: 74
A13: E | B13: 10 | C13: 70 | E13: 54 | G13: 12 | H13: 10 | I13: 60 | K13: 54 | M13: 18 | N13: 10 | O13: 42 | P13: 10 | Q13: 88
A14: B | B14: 10 | C14: 84 | E14: 54 | G14: 16 | I14: 60 | K14: 54 | L14: 0 | M14: 22 | O14: 42 | Q14: 88
A15: P | B15: 10 | C15: 98 | E15: 54 | G15: 16 | H15: 10 | I15: 74 | J15: 0 | K15: 58 | M15: 22 | O15: 42 | P15: 0 | Q15: 92
A17: X | B17: 10 | C17: 112 | E17: 54 | G17: 16 | H17: 10 | I17: 88 | K17: 58 | M17: 22 | N17: 0 | O17: 46 | P17: 10 | Q17: 106
A18: M | B18: 10 | C18: 126 | E18: 54 | G18: 16 | H18: 10 | I18: 102 | K18: 58 | M18: 22 | N18: 10 | O18: 60 | P18: 10 | Q18: 120
A19: C | C19: 126 | D19: 0 | E19: 58 | G19: 16 | H19: 10 | I19: 116 | K19: 58 | M19: 22 | O19: 60 | Q19: 120
A20: E | B20: 10 | C20: 140 | E20: 58 | G20: 16 | H20: 10 | I20: 130 | K20: 62 | M20: 22 | O20: 60 | Q20: 124
A21: B | B21: 10 | C21: 154 | E21: 58 | G21: 16 | H21: 10 | I21: 144 | K21: 62 | M21: 22 | N21: 10 | O21: 74 | P21: 10 | Q21: 138
A22: P | C22: 154 | D22: 0 | E22: 62 | F22: 0 | G22: 20 | I22: 144 | K22: 62 | M22: 22 | N22: 0 | O22: 78 | P22: 0 | Q22: 142
A23: X | C23: 154 | D23: 10 | E23: 76 | G23: 20 | H23: 10 | I23: 158 | K23: 62 | M23: 22 | N23: 0 | O23: 82 | P23: 0 | Q23: 146
A24: M | B24: 10 | C24: 168 | E24: 76 | G24: 20 | H24: 10 | I24: 172 | J24: 10 | K24: 76 | M24: 22 | O24: 82 | P24: 10 | Q24: 160
A25: C | B25: 10 | C25: 182 | E25: 76 | G25: 20 | H25: 10 | I25: 186 | K25: 76 | M25: 22 | N25: 10 | O25: 96 | P25: 10 | Q25: 174
A26: E | B26: 10 | C26: 196 | E26: 76 | G26: 20 | H26: 10 | I26: 200 | J26: 10 | K26: 90 | M26: 22 | O26: 96 | P26: 0 | Q26: 178
A27: B | C27: 196 | D27: 10 | E27: 90 | G27: 20 | H27: 10 | I27: 214 | K27: 90 | M27: 22 | N27: 0 | O27: 100 | P27: 0 | Q27: 182
A28: P | C28: 196 | D28: 0 | E28: 94 | G28: 20 | H28: 0 | I28: 218 | J28: 0 | K28: 94 | L28: 0 | M28: 26 | O28: 100 | Q28: 182
B31: {=transpose(sort(transpose(Full!A31:R60),1,true))} -> Brookfield | C31: Brookfield | D31: Eisenhower A | E31: Eisenhower A | F31: Eisenhower B | G31: Eisenhower B | H31: Middleton A | I31: Middleton A | J31: Middleton B | K31: Middleton B | L31: Middleton C | M31: Middleton C | N31: West | O31: West | P31: Whitney Young | Q31: Whitney Young
B32: Bonus | C32: Score | D32: Bonus | E32: Score | F32: Bonus | G32: Score | H32: Bonus | I32: Score | J32: Bonus | K32: Score | L32: Bonus | M32: Score | N32: Bonus | O32: Score | P32: Bonus | Q32: Score
A34: X | B34: 10 | C34: 14 | D34: 10 | E34: 14 | G34: 0 | I34: 0 | K34: 0 | L34: 10 | M34: 14 | O34: 0 | P34: 10 | Q34: 14
A35: M | B35: 10 | C35: 28 | D35: 0 | E35: 18 | F35: 0 | G35: 4 | H35: 10 | I35: 14 | K35: 0 | M35: 14 | O35: 0 | Q35: 14
A36: C | B36: 10 | C36: 42 | D36: 10 | E36: 32 | G36: 4 | I36: 14 | K36: 0 | M36: 14 | O36: 0 | P36: 10 | Q36: 32
A37: E | B37: 10 | C37: 56 | D37: 0 | E37: 36 | F37: 10 | G37: 22 | H37: 10 | I37: 28 | K37: 0 | M37: 14 | O37: 0 | Q37: 32
A38: B | B38: 0 | C38: 60 | D38: 10 | E38: 50 | F38: 0 | G38: 26 | H38: 0 | I38: 32 | K38: 0 | M38: 14 | O38: 0 | Q38: 32
A39: P | B39: 10 | C39: 74 | D39: 0 | E39: 54 | F39: 0 | G39: 30 | H39: 0 | I39: 36 | K39: 0 | M39: 14 | O39: 0 | Q39: 32
A40: X | B40: 10 | C40: 88 | D40: 10 | E40: 68 | G40: 30 | H40: 10 | I40: 50 | K40: 0 | M40: 14 | O40: 0 | Q40: 32
A41: M | B41: 0 | C41: 92 | E41: 68 | G41: 30 | I41: 50 | K41: 0 | M41: 14 | N41: 0 | O41: 4 | P41: 10 | Q41: 46
A42: C | C42: 92 | D42: 0 | E42: 72 | G42: 30 | H42: 10 | I42: 64 | K42: 0 | M42: 14 | O42: 4 | Q42: 46
A43: E | B43: 10 | C43: 106 | D43: 10 | E43: 86 | G43: 30 | H43: 10 | I43: 78 | K43: 0 | L43: 0 | M43: 18 | O43: 4 | Q43: 46
A44: B | B44: 10 | C44: 120 | E44: 86 | G44: 30 | I44: 78 | K44: 0 | M44: 18 | O44: 4 | Q44: 46
A45: P | B45: 10 | C45: 134 | E45: 86 | G45: 30 | I45: 78 | K45: 0 | M45: 18 | N45: 10 | O45: 18 | P45: 0 | Q45: 50
...

Sheet Stats
A1: Player | B1: Team | C1: GP | D1: TU | E1: Neg | F1: TU/Neg | G1: Points | H1: PPG | I1: X TU | J1: X Neg | K1: X PPG | L1: M TU | M1: M Neg | N1: M PPG | O1: C TU | P1: C Neg | Q1: C PPG | R1: E TU | S1: E Neg | T1: E PPG | U1: B TU | V1: B Neg | W1: B PPG | X1: P TU | Y1: P Neg | Z1: P PPG
A2: Josh | B2: Brookfield | C2: 8 | D2: 72 | E2: 9 | F2: 8 | G2: 252 | H2: 31.5 | I2: 9 | J2: 5 | K2: 2 | L2: 10 | M2: 0 | N2: 5 | O2: 18 | P2: 1 | Q2: 8.5 | R2: 12 | S2: 1 | T2: 5.5 | U2: 11 | V2: 1 | W2: 5 | X2: 12 | Y2: 1 | Z2: 5.5
A3: Harry | B3: Middleton A | C3: 9 | D3: 52 | E3: 5 | F3: 10.4 | G3: 188 | H3: 20.888889 | I3: 8 | J3: 2 | K3: 2.6666667 | L3: 11 | M3: 1 | N3: 4.4444444 | O3: 18 | P3: 1 | Q3: 7.5555556 | R3: 12 | S3: 1 | T3: 4.8888889 | U3: 1 | V3: 0 | W3: 0.44444444 | X3: 2 | Y3: 0 | Z3: 0.88888889
A4: Arnav | B4: Whitney Young | C4: 9 | D4: 33 | E4: 0 | F4: Infinity | G4: 132 | H4: 14.666667 | I4: 2 | J4: 0 | K4: 0.88888889 | L4: 20 | M4: 0 | N4: 8.8888889 | O4: 2 | P4: 0 | Q4: 0.88888889 | R4: 2 | S4: 0 | T4: 0.88888889 | U4: 1 | V4: 0 | W4: 0.44444444 | X4: 6 | Y4: 0 | Z4: 2.6666667
A5: Li | B5: Middleton B | C5: 8 | D5: 27 | E5: 1 | F5: 27 | G5: 104 | H5: 13 | I5: 1 | J5: 0 | K5: 0.5 | L5: 10 | M5: 0 | N5: 5 | O5: 4 | P5: 0 | Q5: 2 | R5: 2 | S5: 0 | T5: 1 | U5: 5 | V5: 0 | W5: 2.5 | X5: 5 | Y5: 1 | Z5: 2
A6: Pratyush | B6: Eisenhower B | C6: 6 | D6: 19 | E6: 0 | F6: Infinity | G6: 76 | H6: 12.666667 | I6: 3 | J6: 0 | K6: 2 | L6: 4 | M6: 0 | N6: 2.6666667 | O6: 1 | P6: 0 | Q6: 0.66666667 | R6: 2 | S6: 0 | T6: 1.3333333 | U6: 3 | V6: 0 | W6: 2 | X6: 6 | Y6: 0 | Z6: 4
A7: Kartik | B7: Brookfield | C7: 8 | D7: 24 | E7: 3 | F7: 8 | G7: 84 | H7: 10.5 | I7: 3 | J7: 0 | K7: 1.5 | L7: 10 | M7: 2 | N7: 4 | O7: 1 | P7: 0 | Q7: 0.5 | R7: 2 | S7: 0 | T7: 1 | U7: 0 | V7: 0 | W7: 0 | X7: 8 | Y7: 1 | Z7: 3.5
A8: Manzoor | B8: Eisenhower A | C8: 8 | D8: 29 | E8: 8 | F8: 3.625 | G8: 84 | H8: 10.5 | I8: 4 | J8: 0 | K8: 2 | L8: 3 | M8: 1 | N8: 1 | O8: 10 | P8: 6 | Q8: 2 | R8: 1 | S8: 0 | T8: 0.5 | U8: 2 | V8: 0 | W8: 1 | X8: 9 | Y8: 1 | Z8: 4
A9: William | B9: West | C9: 6 | D9: 16 | E9: 4 | F9: 4 | G9: 48 | H9: 8 | I9: 2 | J9: 1 | K9: 0.66666667 | L9: 4 | M9: 1 | N9: 2 | O9: 3 | P9: 1 | Q9: 1.3333333 | R9: 6 | S9: 1 | T9: 3.3333333 | U9: 0 | V9: 0 | W9: 0 | X9: 1 | Y9: 0 | Z9: 0.66666667
A10: Evan | B10: Whitney Young | C10: 9 | D10: 19 | E10: 2 | F10: 9.5 | G10: 68 | H10: 7.5555556 | I10: 5 | J10: 0 | K10: 2.2222222 | L10: 2 | M10: 0 | N10: 0.88888889 | O10: 6 | P10: 1 | Q10: 2.2222222 | R10: 4 | S10: 1 | T10: 1.3333333 | U10: 1 | V10: 0 | W10: 0.44444444 | X10: 1 | Y10: 0 | Z10: 0.44444444
A11: Owen | B11: Middleton A | C11: 9 | D11: 24 | E11: 9 | F11: 2.6666667 | G11: 60 | H11: 6.6666667 | I11: 5 | J11: 2 | K11: 1.3333333 | L11: 0 | M11: 1 | N11: -0.44444444 | O11: 0 | P11: 0 | Q11: 0 | R11: 0 | S11: 0 | T11: 0 | U11: 16 | V11: 6 | W11: 4.4444444 | X11: 3 | Y11: 0 | Z11: 1.3333333
A12: Arjun | B12: Middleton C | C12: 7 | D12: 17 | E12: 6 | F12: 2.8333333 | G12: 44 | H12: 6.2857143 | I12: 2 | J12: 1 | K12: 0.57142857 | L12: 7 | M12: 1 | N12: 3.4285714 | O12: 0 | P12: 1 | Q12: -0.57142857 | R12: 3 | S12: 3 | T12: 0 | U12: 4 | V12: 0 | W12: 2.2857143 | X12: 1 | Y12: 0 | Z12: 0.57142857
A13: Miller | B13: Whitney Young | C13: 9 | D13: 15 | E13: 1 | F13: 15 | G13: 56 | H13: 6.2222222 | I13: 3 | J13: 0 | K13: 1.3333333 | L13: 0 | M13: 0 | N13: 0 | O13: 0 | P13: 0 | Q13: 0 | R13: 6 | S13: 1 | T13: 2.2222222 | U13: 1 | V13: 0 | W13: 0.44444444 | X13: 5 | Y13: 0 | Z13: 2.2222222
A14: Ray | B14: Middleton A | C14: 9 | D14: 19 | E14: 6 | F14: 3.1666667 | G14: 52 | H14: 5.7777778 | I14: 3 | J14: 1 | K14: 0.88888889 | L14: 1 | M14: 0 | N14: 0.44444444 | O14: 1 | P14: 1 | Q14: 0 | R14: 9 | S14: 2 | T14: 3.1111111 | U14: 1 | V14: 0 | W14: 0.44444444 | X14: 4 | Y14: 2 | Z14: 0.88888889
A15: Andrew | B15: Eisenhower A | C15: 8 | D15: 12 | E15: 1 | F15: 12 | G15: 44 | H15: 5.5 | I15: 0 | J15: 0 | K15: 0 | L15: 6 | M15: 1 | N15: 2.5 | O15: 0 | P15: 0 | Q15: 0 | R15: 2 | S15: 0 | T15: 1 | U15: 0 | V15: 0 | W15: 0 | X15: 4 | Y15: 0 | Z15: 2
A16: Ian | B16: Middleton B | C16: 8 | D16: 11 | E16: 0 | F16: Infinity | G16: 44 | H16: 5.5 | I16: 3 | J16: 0 | K16: 1.5 | L16: 1 | M16: 0 | N16: 0.5 | O16: 0 | P16: 0 | Q16: 0 | R16: 3 | S16: 0 | T16: 1.5 | U16: 0 | V16: 0 | W16: 0 | X16: 4 | Y16: 0 | Z16: 2
A17: Tim | B17: West | C17: 6 | D17: 9 | E17: 1 | F17: 9 | G17: 32 | H17: 5.3333333 | I17: 3 | J17: 0 | K17: 2 | L17: 5 | M17: 0 | N17: 3.3333333 | O17: 0 | P17: 0 | Q17: 0 | R17: 0 | S17: 0 | T17: 0 | U17: 0 | V17: 0 | W17: 0 | X17: 1 | Y17: 1 | Z17: 0
A18: Frank | B18: Middleton C | C18: 8 | D18: 9 | E18: 1 | F18: 9 | G18: 32 | H18: 4 | I18: 4 | J18: 0 | K18: 2 | L18: 0 | M18: 0 | N18: 0 | O18: 1 | P18: 0 | Q18: 0.5 | R18: 2 | S18: 1 | T18: 0.5 | U18: 0 | V18: 0 | W18: 0 | X18: 2 | Y18: 0 | Z18: 1
A19: Saathvik | B19: Brookfield | C19: 8 | D19: 10 | E19: 2 | F19: 5 | G19: 32 | H19: 4 | I19: 4 | J19: 1 | K19: 1.5 | L19: 0 | M19: 0 | N19: 0 | O19: 1 | P19: 0 | Q19: 0.5 | R19: 1 | S19: 0 | T19: 0.5 | U19: 4 | V19: 0 | W19: 2 | X19: 0 | Y19: 1 | Z19: -0.5
A20: Sai | B20: Eisenhower B | C20: 6 | D20: 6 | E20: 0 | F20: Infinity | G20: 24 | H20: 4 | I20: 1 | J20: 0 | K20: 0.66666667 | L20: 0 | M20: 0 | N20: 0 | O20: 1 | P20: 0 | Q20: 0.66666667 | R20: 1 | S20: 0 | T20: 0.66666667 | U20: 3 | V20: 0 | W20: 2 | X20: 0 | Y20: 0 | Z20: 0
A21: Samanyu | B21: West | C21: 6 | D21: 6 | E21: 0 | F21: Infinity | G21: 24 | H21: 4 | I21: 0 | J21: 0 | K21: 0 | L21: 0 | M21: 0 | N21: 0 | O21: 1 | P21: 0 | Q21: 0.66666667 | R21: 0 | S21: 0 | T21: 0 | U21: 4 | V21: 0 | W21: 2.6666667 | X21: 1 | Y21: 0 | Z21: 0.66666667
A22: Sujay | B22: Eisenhower A | C22: 8 | D22: 9 | E22: 1 | F22: 9 | G22: 32 | H22: 4 | I22: 0 | J22: 1 | K22: -0.5 | L22: 0 | M22: 0 | N22: 0 | O22: 2 | P22: 0 | Q22: 1 | R22: 1 | S22: 0 | T22: 0.5 | U22: 6 | V22: 0 | W22: 3 | X22: 0 | Y22: 0 | Z22: 0
A23: Dhruva | B23: Eisenhower A | C23: 8 | D23: 9 | E23: 2 | F23: 4.5 | G23: 28 | H23: 3.5 | I23: 2 | J23: 1 | K23: 0.5 | L23: 0 | M23: 0 | N23: 0 | O23: 0 | P23: 0 | Q23: 0 | R23: 7 | S23: 1 | T23: 3 | U23: 0 | V23: 0 | W23: 0 | X23: 0 | Y23: 0 | Z23: 0
A24: Kriti | B24: Middleton B | C24: 8 | D24: 6 | E24: 0 | F24: Infinity | G24: 24 | H24: 3 | I24: 1 | J24: 0 | K24: 0.5 | L24: 0 | M24: 0 | N24: 0 | O24: 0 | P24: 0 | Q24: 0 | R24: 5 | S24: 0 | T24: 2.5 | U24: 0 | V24: 0 | W24: 0 | X24: 0 | Y24: 0 | Z24: 0
A25: Kevin | B25: West | C25: 6 | D25: 4 | E25: 0 | F25: Infinity | G25: 16 | H25: 2.6666667 | I25: 1 | J25: 0 | K25: 0.66666667 | L25: 1 | M25: 0 | N25: 0.66666667 | O25: 1 | P25: 0 | Q25: 0.66666667 | R25: 1 | S25: 0 | T25: 0.66666667 | U25: 0 | V25: 0 | W25: 0 | X25: 0 | Y25: 0 | Z25: 0
A26: Nihar | B26: Middleton A | C26: 9 | D26: 8 | E26: 2 | F26: 4 | G26: 24 | H26: 2.6666667 | I26: 0 | J26: 1 | K26: -0.44444444 | L26: 3 | M26: 0 | N26: 1.3333333 | O26: 0 | P26: 0 | Q26: 0 | R26: 3 | S26: 0 | T26: 1.3333333 | U26: 0 | V26: 0 | W26: 0 | X26: 2 | Y26: 1 | Z26: 0.44444444
A27: Prani | B27: Eisenhower A | C27: 8 | D27: 5 | E27: 0 | F27: Infinity | G27: 20 | H27: 2.5 | I27: 2 | J27: 0 | K27: 1 | L27: 0 | M27: 0 | N27: 0 | O27: 0 | P27: 0 | Q27: 0 | R27: 1 | S27: 0 | T27: 0.5 | U27: 2 | V27: 0 | W27: 1 | X27: 0 | Y27: 0 | Z27: 0
A28: Stephen | B28: Whitney Young | C28: 9 | D28: 7 | E28: 2 | F28: 3.5 | G28: 20 | H28: 2.2222222 | I28: 1 | J28: 0 | K28: 0.44444444 | L28: 0 | M28: 1 | N28: -0.44444444 | O28: 2 | P28: 0 | Q28: 0.88888889 | R28: 2 | S28: 0 | T28: 0.88888889 | U28: 2 | V28: 1 | W28: 0.44444444 | X28: 0 | Y28: 0 | Z28: 0
A29: Alex | B29: Eisenhower B | C29: 6 | D29: 3 | E29: 0 | F29: Infinity | G29: 12 | H29: 2 | I29: 1 | J29: 0 | K29: 0.66666667 | L29: 0 | M29: 0 | N29: 0 | O29: 0 | P29: 0 | Q29: 0 | R29: 1 | S29: 0 | T29: 0.66666667 | U29: 1 | V29: 0 | W29: 0.66666667 | X29: 0 | Y29: 0 | Z29: 0
A30: Vaidya | B30: Middleton B | C30: 8 | D30: 4 | E30: 0 | F30: Infinity | G30: 16 | H30: 2 | I30: 1 | J30: 0 | K30: 0.5 | L30: 0 | M30: 0 | N30: 0 | O30: 0 | P30: 0 | Q30: 0 | R30: 1 | S30: 0 | T30: 0.5 | U30: 2 | V30: 0 | W30: 1 | X30: 0 | Y30: 0 | Z30: 0
A31: Sai | B31: Middleton C | C31: 8 | D31: 11 | E31: 8 | F31: 1.375 | G31: 12 | H31: 1.5 | I31: 1 | J31: 2 | K31: -0.5 | L31: 2 | M31: 1 | N31: 0.5 | O31: 1 | P31: 1 | Q31: 0 | R31: 1 | S31: 1 | T31: 0 | U31: 3 | V31: 0 | W31: 1.5 | X31: 3 | Y31: 3 | Z31: 0
A32: Ethan | B32: Eisenhower B | C32: 6 | D32: 2 | E32: 0 | F32: Infinity | G32: 8 | H32: 1.3333333 | I32: 0 | J32: 0 | K32: 0 | L32: 1 | M32: 0 | N32: 0.66666667 | O32: 1 | P32: 0 | Q32: 0.66666667 | R32: 0 | S32: 0 | T32: 0 | U32: 0 | V32: 0 | W32: 0 | X32: 0 | Y32: 0 | Z32: 0
A33: Avaneesh | B33: Brookfield | C33: 8 | D33: 0 | E33: 0 | F33: Infinity | G33: 0 | H33: 0 | I33: 0 | J33: 0 | K33: 0 | L33: 0 | M33: 0 | N33: 0 | O33: 0 | P33: 0 | Q33: 0 | R33: 0 | S33: 0 | T33: 0 | U33: 0 | V33: 0 | W33: 0 | X33: 0 | Y33: 0 | Z33: 0
A34: Nathan | B34: Eisenhower B | C34: 6 | D34: 0 | E34: 0 | F34: Infinity | G34: 0 | H34: 0 | I34: 0 | J34: 0 | K34: 0 | L34: 0 | M34: 0 | N34: 0 | O34: 0 | P34: 0 | Q34: 0 | R34: 0 | S34: 0 | T34: 0 | U34: 0 | V34: 0 | W34: 0 | X34: 0 | Y34: 0 | Z34: 0
A35: Om | B35: Brookfield | C35: 8 | D35: 0 | E35: 0 | F35: Infinity | G35: 0 | H35: 0 | I35: 0 | J35: 0 | K35: 0 | L35: 0 | M35: 0 | N35: 0 | O35: 0 | P35: 0 | Q35: 0 | R35: 0 | S35: 0 | T35: 0 | U35: 0 | V35: 0 | W35: 0 | X35: 0 | Y35: 0 | Z35: 0
A36: Sam | B36: Whitney Young | C36: 9 | D36: 0 | E36: 0 | F36: Infinity | G36: 0 | H36: 0 | I36: 0 | J36: 0 | K36: 0 | L36: 0 | M36: 0 | N36: 0 | O36: 0 | P36: 0 | Q36: 0 | R36: 0 | S36: 0 | T36: 0 | U36: 0 | V36: 0 | W36: 0 | X36: 0 | Y36: 0 | Z36: 0
A37: Abhinav | B37: Middleton C | C37: 8 | D37: 0 | E37: 1 | F37: 0 | G37: -4 | H37: -0.5 | I37: 0 | J37: 1 | K37: -0.5 | L37: 0 | M37: 0 | N37: 0 | O37: 0 | P37: 0 | Q37: 0 | R37: 0 | S37: 0 | T37: 0 | U37: 0 | V37: 0 | W37: 0 | X37: 0 | Y37: 0 | Z37: 0

Sheet Team Stats
A1: Team | B1: PPG | C1: GP | D1: Bonus | E1: Bonus % | F1: X Bonus | G1: X Bonus % | H1: M Bonus | I1: M Bonus % | J1: C Bonus | K1: C Bonus % | L1: E Bonus | M1: E Bonus % | N1: B Bonus | O1: B Bonus % | P1: P Bonus | Q1: P Bonus %
A2: Brookfield | B2: 152.75 | C2: 8 | D2: 77 | E2: 0.72641509 | F2: 14 | G2: 0.875 | H2: 12 | I2: 0.6 | J2: 16 | K2: 0.8 | L2: 11 | M2: 0.73333333 | N2: 9 | O2: 0.6 | P2: 15 | Q2: 0.75
A3: Middleton A | B3: 136 | C3: 9 | D3: 76 | E3: 0.73786408 | F3: 12 | G3: 0.75 | H3: 10 | I3: 0.66666667 | J3: 15 | K3: 0.78947368 | L3: 20 | M3: 0.83333333 | N3: 14 | O3: 0.77777778 | P3: 5 | Q3: 0.45454545
A4: Whitney Young | B4: 77.111111 | C4: 9 | D4: 33 | E4: 0.44594595 | F4: 5 | G4: 0.45454545 | H4: 13 | I4: 0.59090909 | J4: 4 | K4: 0.4 | L4: 4 | M4: 0.28571429 | N4: 2 | O4: 0.4 | P4: 5 | Q4: 0.41666667
A5: Eisenhower A | B5: 69 | C5: 8 | D5: 26 | E5: 0.40625 | F5: 5 | G5: 0.625 | H5: 2 | I5: 0.22222222 | J5: 5 | K5: 0.41666667 | L5: 6 | M5: 0.5 | N5: 5 | O5: 0.5 | P5: 3 | Q5: 0.23076923
A6: West | B6: 56.333333 | C6: 6 | D6: 17 | E6: 0.48571429 | F6: 2 | G6: 0.33333333 | H6: 6 | I6: 0.6 | J6: 2 | K6: 0.4 | L6: 5 | M6: 0.71428571 | N6: 1 | O6: 0.25 | P6: 1 | Q6: 0.33333333
A7: Middleton B | B7: 49 | C7: 8 | D7: 16 | E7: 0.33333333 | F7: 2 | G7: 0.33333333 | H7: 5 | I7: 0.45454545 | J7: 2 | K7: 0.5 | L7: 5 | M7: 0.45454545 | N7: 2 | O7: 0.28571429 | P7: 0 | Q7: 0
A8: Middleton C | B8: 38 | C8: 8 | D8: 12 | E8: 0.32432432 | F8: 6 | G8: 0.85714286 | H8: 1 | I8: 0.11111111 | J8: 0 | K8: 0 | L8: 3 | M8: 0.5 | N8: 0 | O8: 0 | P8: 2 | Q8: 0.4
A9: Eisenhower B | B9: 35.333333 | C9: 6 | D9: 8 | E9: 0.27586207 | F9: 4 | G9: 1 | H9: 0 | I9: 0 | J9: 1 | K9: 0.33333333 | L9: 1 | M9: 0.25 | N9: 2 | O9: 0.33333333 | P9: 0 | Q9: 0

Sheet X-Risk
A1: {=sort(Stats!A1:A1000,Stats!K1:K1000,false)} -> Player | B1: {=sort(Stats!C1:C1000,Stats!K1:K1000,false)} -> GP | C1: {=sort(Stats!I1:K1000,Stats!K1:K1000,false)} -> X TU | D1: X Neg | E1: X PPG
A2: Harry | B2: 9 | C2: 8 | D2: 2 | E2: 2.6666667
A3: Evan | B3: 9 | C3: 5 | D3: 0 | E3: 2.2222222
A4: Josh | B4: 8 | C4: 9 | D4: 5 | E4: 2
A5: Pratyush | B5: 6 | C5: 3 | D5: 0 | E5: 2
A6: Manzoor | B6: 8 | C6: 4 | D6: 0 | E6: 2
A7: Tim | B7: 6 | C7: 3 | D7: 0 | E7: 2
A8: Frank | B8: 8 | C8: 4 | D8: 0 | E8: 2
A9: Kartik | B9: 8 | C9: 3 | D9: 0 | E9: 1.5
A10: Ian | B10: 8 | C10: 3 | D10: 0 | E10: 1.5
A11: Saathvik | B11: 8 | C11: 4 | D11: 1 | E11: 1.5
A12: Owen | B12: 9 | C12: 5 | D12: 2 | E12: 1.3333333
A13: Miller | B13: 9 | C13: 3 | D13: 0 | E13: 1.3333333
... A37: Abhinav | B37: 8 | C37: 0 | D37: 1 | E37: -0.5

Sheet Math
A1: {=sort(Stats!A1:A1000,Stats!N1:N1000,false)} -> Player | B1: {=sort(Stats!C1:C1000,Stats!N1:N1000,false)} -> GP | C1: {=sort(Stats!L1:N1000,Stats!N1:N1000,false)} -> M TU | D1: M Neg | E1: M PPG
A2: Arnav | B2: 9 | C2: 20 | D2: 0 | E2: 8.8888889
A3: Josh | B3: 8 | C3: 10 | D3: 0 | E3: 5
A4: Li | B4: 8 | C4: 10 | D4: 0 | E4: 5
A5: Harry | B5: 9 | C5: 11 | D5: 1 | E5: 4.4444444
A6: Kartik | B6: 8 | C6: 10 | D6: 2 | E6: 4
A7: Arjun | B7: 7 | C7: 7 | D7: 1 | E7: 3.4285714
A8: Tim | B8: 6 | C8: 5 | D8: 0 | E8: 3.3333333
A9: Pratyush | B9: 6 | C9: 4 | D9: 0 | E9: 2.6666667
A10: Andrew | B10: 8 | C10: 6 | D10: 1 | E10: 2.5
A11: William | B11: 6 | C11: 4 | D11: 1 | E11: 2
A12: Nihar | B12: 9 | C12: 3 | D12: 0 | E12: 1.3333333
A13: Manzoor | B13: 8 | C13: 3 | D13: 1 | E13: 1
... A37: Stephen | B37: 9 | C37: 0 | D37: 1 | E37: -0.44444444

Sheet Chemistry
A1: {=sort(Stats!A1:A1000,Stats!Q1:Q1000,false)} -> Player | B1: {=sort(Stats!C1:C1000,Stats!Q1:Q1000,false)} -> GP | C1: {=sort(Stats!O1:Q1000,Stats!Q1:Q1000,false)} -> C TU | D1: C Neg | E1: C PPG
A2: Josh | B2: 8 | C2: 18 | D2: 1 | E2: 8.5
A3: Harry | B3: 9 | C3: 18 | D3: 1 | E3: 7.5555556
A4: Evan | B4: 9 | C4: 6 | D4: 1 | E4: 2.2222222
A5: Li | B5: 8 | C5: 4 | D5: 0 | E5: 2
A6: Manzoor | B6: 8 | C6: 10 | D6: 6 | E6: 2
A7: William | B7: 6 | C7: 3 | D7: 1 | E7: 1.3333333
A8: Sujay | B8: 8 | C8: 2 | D8: 0 | E8: 1
A9: Arnav | B9: 9 | C9: 2 | D9: 0 | E9: 0.88888889
A10: Stephen | B10: 9 | C10: 2 | D10: 0 | E10: 0.88888889
A11: Pratyush | B11: 6 | C11: 1 | D11: 0 | E11: 0.66666667
A12: Sai | B12: 6 | C12: 1 | D12: 0 | E12: 0.66666667
A13: Samanyu | B13: 6 | C13: 1 | D13: 0 | E13: 0.66666667
... A37: Arjun | B37: 7 | C37: 0 | D37: 1 | E37: -0.57142857

Sheet EarthSpace
A1: {=sort(Stats!A1:A1000,Stats!T1:T1000,false)} -> Player | B1: {=sort(Stats!C1:C1000,Stats!T1:T1000,false)} -> GP | C1: {=sort(Stats!R1:T1000,Stats!T1:T1000,false)} -> E TU | D1: E Neg | E1: E PPG
A2: Josh | B2: 8 | C2: 12 | D2: 1 | E2: 5.5
A3: Harry | B3: 9 | C3: 12 | D3: 1 | E3: 4.8888889
A4: William | B4: 6 | C4: 6 | D4: 1 | E4: 3.3333333
A5: Ray | B5: 9 | C5: 9 | D5: 2 | E5: 3.1111111
A6: Dhruva | B6: 8 | C6: 7 | D6: 1 | E6: 3
A7: Kriti | B7: 8 | C7: 5 | D7: 0 | E7: 2.5
A8: Miller | B8: 9 | C8: 6 | D8: 1 | E8: 2.2222222
A9: Ian | B9: 8 | C9: 3 | D9: 0 | E9: 1.5
A10: Pratyush | B10: 6 | C10: 2 | D10: 0 | E10: 1.3333333
A11: Evan | B11: 9 | C11: 4 | D11: 1 | E11: 1.3333333
A12: Nihar | B12: 9 | C12: 3 | D12: 0 | E12: 1.3333333
A13: Li | B13: 8 | C13: 2 | D13: 0 | E13: 1
... A37: Abhinav | B37: 8 | C37: 0 | D37: 0 | E37: 0

Sheet Biology
A1: {=sort(Stats!A1:A1000,Stats!W1:W1000,false)} -> Player | B1: {=sort(Stats!C1:C1000,Stats!W1:W1000,false)} -> GP | C1: {=sort(Stats!U1:W1000,Stats!W1:W1000,false)} -> B TU | D1: B Neg | E1: B PPG
A2: Josh | B2: 8 | C2: 11 | D2: 1 | E2: 5
A3: Owen | B3: 9 | C3: 16 | D3: 6 | E3: 4.4444444
A4: Sujay | B4: 8 | C4: 6 | D4: 0 | E4: 3
A5: Samanyu | B5: 6 | C5: 4 | D5: 0 | E5: 2.6666667
A6: Li | B6: 8 | C6: 5 | D6: 0 | E6: 2.5
A7: Arjun | B7: 7 | C7: 4 | D7: 0 | E7: 2.2857143
A8: Pratyush | B8: 6 | C8: 3 | D8: 0 | E8: 2
A9: Saathvik | B9: 8 | C9: 4 | D9: 0 | E9: 2
A10: Sai | B10: 6 | C10: 3 | D10: 0 | E10: 2
A11: Sai | B11: 8 | C11: 3 | D11: 0 | E11: 1.5
A12: Manzoor | B12: 8 | C12: 2 | D12: 0 | E12: 1
A13: Prani | B13: 8 | C13: 2 | D13: 0 | E13: 1
... A37: Abhinav | B37: 8 | C37: 0 | D37: 0 | E37: 0

Sheet Physics
A1: {=sort(Stats!A1:A1000,Stats!Z1:Z1000,false)} -> Player | B1: {=sort(Stats!C1:C1000,Stats!Z1:Z1000,false)} -> GP | C1: {=sort(Stats!X1:Z1000,Stats!Z1:Z1000,false)} -> P TU | D1: P Neg | E1: P PPG
A2: Josh | B2: 8 | C2: 12 | D2: 1 | E2: 5.5
A3: Pratyush | B3: 6 | C3: 6 | D3: 0 | E3: 4
A4: Manzoor | B4: 8 | C4: 9 | D4: 1 | E4: 4
A5: Kartik | B5: 8 | C5: 8 | D5: 1 | E5: 3.5
A6: Arnav | B6: 9 | C6: 6 | D6: 0 | E6: 2.6666667
A7: Miller | B7: 9 | C7: 5 | D7: 0 | E7: 2.2222222
A8: Li | B8: 8 | C8: 5 | D8: 1 | E8: 2
A9: Andrew | B9: 8 | C9: 4 | D9: 0 | E9: 2
A10: Ian | B10: 8 | C10: 4 | D10: 0 | E10: 2
A11: Owen | B11: 9 | C11: 3 | D11: 0 | E11: 1.3333333
A12: Frank | B12: 8 | C12: 2 | D12: 0 | E12: 1
A13: Harry | B13: 9 | C13: 2 | D13: 0 | E13: 0.88888889
... A37: Saathvik | B37: 8 | C37: 0 | D37: 1 | E37: -0.5
