Workbook

Sheet Cumulative Player Stats
C1: Earth | I1: Space | O1: Combined | U1: Median
A2: Player | B2: GP | C2: C | D2: IC | E2: P | F2: Gain | G2: Net | H2: %✅ | I2: C | J2: IC | K2: P | L2: Gain | M2: Net | N2: %✅ | O2: C | P2: IC | Q2: P | R2: Gain | S2: Net | T2: %✅ | U2: C | V2: IC | W2: P | X2: Gain | Y2: Net | Z2: %✅
A3: [4.4] Roshan A | B3: =COUNTIF('RR1 Player Stats'!$A$3:$A$50,$A3)+COUNTIF('RR2 Player Stats'!$A$3:$A$50,$A3)+COUNTIF('RR3 Player Stats'!$A$3:$A$50,$A3)+COUNTIF('RR4 Player Stats'!$A$3:$A$50,$A3)+COUNTIF('RR5 Player Stats'!$A$3:$A$50,$A3) -> 5 | C3: =IFERROR(__xludf.DUMMYFUNCTION("IFERROR(FILTER('RR1 Player Stats'!V$3:V$50, ISNUMBER(SEARCH($A3,'RR1 Player Stats'!$A$3:$A$50))),0) +IFERROR(FILTER('RR2 Player Stats'!V$3:V$50, ISNUMBER(SEARCH($A3,'RR2 Player Stats'!$A$3:$A$50))),0) +IFERROR(FILTER('RR3 Player Stats'!V$3:V$50, ISNUMBER("&"SEARCH($A3,'RR3 Player Stats'!$A$3:$A$50))),0) +IFERROR(FILTER('RR4 Player Stats'!V$3:V$50, ISNUMBER(SEARCH($A3,'RR4 Player Stats'!$A$3:$A$50))),0) +IFERROR(FILTER('RR5 Player Stats'!V$3:V$50, ISNUMBER(SEARCH($A3,'RR5 Player Stats'!$A$3:$A$50))),0)"),7.0) -> 7 | D3: =IFERROR(__xludf.DUMMYFUNCTION("IFERROR(FILTER('RR1 Player Stats'!W$3:W$50, ISNUMBER(SEARCH($A3,'RR1 Player Stats'!$A$3:$A$50))),0) +IFERROR(FILTER('RR2 Player Stats'!W$3:W$50, ISNUMBER(SEARCH($A3,'RR2 Player Stats'!$A$3:$A$50))),0) +IFERROR(FILTER('RR3 Player Stats'!W$3:W$50, ISNUMBER("&"SEARCH($A3,'RR3 Player Stats'!$A$3:$A$50))),0) +IFERROR(FILTER('RR4 Player Stats'!W$3:W$50, ISNUMBER(SEARCH($A3,'RR4 Player Stats'!$A$3:$A$50))),0) +IFERROR(FILTER('RR5 Player Stats'!W$3:W$50, ISNUMBER(SEARCH($A3,'RR5 Player Stats'!$A$3:$A$50))),0)"),31.0) -> 31 | E3: =IFERROR(__xludf.DUMMYFUNCTION("IFERROR(FILTER('RR1 Player Stats'!X$3:X$50, ISNUMBER(SEARCH($A3,'RR1 Player Stats'!$A$3:$A$50))),0) +IFERROR(FILTER('RR2 Player Stats'!X$3:X$50, ISNUMBER(SEARCH($A3,'RR2 Player Stats'!$A$3:$A$50))),0) +IFERROR(FILTER('RR3 Player Stats'!X$3:X$50, ISNUMBER("&"SEARCH($A3,'RR3 Player Stats'!$A$3:$A$50))),0) +IFERROR(FILTER('RR4 Player Stats'!X$3:X$50, ISNUMBER(SEARCH($A3,'RR4 Player Stats'!$A$3:$A$50))),0) +IFERROR(FILTER('RR5 Player Stats'!X$3:X$50, ISNUMBER(SEARCH($A3,'RR5 Player Stats'!$A$3:$A$50))),0)"),16.0) -> 16 | F3: =IFERROR(__xludf.DUMMYFUNCTION("IFERROR(FILTER('RR1 Player Stats'!Y$3:Y$50, ISNUMBER(SEARCH($A3,'RR1 Player Stats'!$A$3:$A$50))),0) +IFERROR(FILTER('RR2 Player Stats'!Y$3:Y$50, ISNUMBER(SEARCH($A3,'RR2 Player Stats'!$A$3:$A$50))),0) +IFERROR(FILTER('RR3 Player Stats'!Y$3:Y$50, ISNUMBER("&"SEARCH($A3,'RR3 Player Stats'!$A$3:$A$50))),0) +IFERROR(FILTER('RR4 Player Stats'!Y$3:Y$50, ISNUMBER(SEARCH($A3,'RR4 Player Stats'!$A$3:$A$50))),0) +IFERROR(FILTER('RR5 Player Stats'!Y$3:Y$50, ISNUMBER(SEARCH($A3,'RR5 Player Stats'!$A$3:$A$50))),0)"),214.0) -> 214 | G3: =IFERROR(__xludf.DUMMYFUNCTION("IFERROR(FILTER('RR1 Player Stats'!Z$3:Z$50, ISNUMBER(SEARCH($A3,'RR1 Player Stats'!$A$3:$A$50))),0) +IFERROR(FILTER('RR2 Player Stats'!Z$3:Z$50, ISNUMBER(SEARCH($A3,'RR2 Player Stats'!$A$3:$A$50))),0) +IFERROR(FILTER('RR3 Player Stats'!Z$3:Z$50, ISNUMBER("&"SEARCH($A3,'RR3 Player Stats'!$A$3:$A$50))),0) +IFERROR(FILTER('RR4 Player Stats'!Z$3:Z$50, ISNUMBER(SEARCH($A3,'RR4 Player Stats'!$A$3:$A$50))),0) +IFERROR(FILTER('RR5 Player Stats'!Z$3:Z$50, ISNUMBER(SEARCH($A3,'RR5 Player Stats'!$A$3:$A$50))),0)"),150.0) -> 150 | H3: =IFERROR(__xludf.DUMMYFUNCTION("(IFERROR(FILTER('RR1 Player Stats'!AA$3:AA$50, ISNUMBER(SEARCH($A3,'RR1 Player Stats'!$A$3:$A$50))),0) +IFERROR(FILTER('RR2 Player Stats'!AA$3:AA$50, ISNUMBER(SEARCH($A3,'RR2 Player Stats'!$A$3:$A$50))),0) +IFERROR(FILTER('RR3 Player Stats'!AA$3:AA$50, IS"&"NUMBER(SEARCH($A3,'RR3 Player Stats'!$A$3:$A$50))),0) +IFERROR(FILTER('RR4 Player Stats'!AA$3:AA$50, ISNUMBER(SEARCH($A3,'RR4 Player Stats'!$A$3:$A$50))),0) +IFERROR(FILTER('RR5 Player Stats'!AA$3:AA$50, ISNUMBER(SEARCH($A3,'RR5 Player Stats'!$A$3:$A$50))"&"),0))/5"),0.634) -> 0.634 | I3: =IFERROR(__xludf.DUMMYFUNCTION("IFERROR(FILTER('RR1 Player Stats'!AB$3:AB$50, ISNUMBER(SEARCH($A3,'RR1 Player Stats'!$A$3:$A$50))),0) +IFERROR(FILTER('RR2 Player Stats'!AB$3:AB$50, ISNUMBER(SEARCH($A3,'RR2 Player Stats'!$A$3:$A$50))),0) +IFERROR(FILTER('RR3 Player Stats'!AB$3:AB$50, ISN"&"UMBER(SEARCH($A3,'RR3 Player Stats'!$A$3:$A$50))),0) +IFERROR(FILTER('RR4 Player Stats'!AB$3:AB$50, ISNUMBER(SEARCH($A3,'RR4 Player Stats'!$A$3:$A$50))),0) +IFERROR(FILTER('RR5 Player Stats'!AB$3:AB$50, ISNUMBER(SEARCH($A3,'RR5 Player Stats'!$A$3:$A$50)))"&",0)"),6.0) -> 6 | J3: =IFERROR(__xludf.DUMMYFUNCTION("IFERROR(FILTER('RR1 Player Stats'!AC$3:AC$50, ISNUMBER(SEARCH($A3,'RR1 Player Stats'!$A$3:$A$50))),0) +IFERROR(FILTER('RR2 Player Stats'!AC$3:AC$50, ISNUMBER(SEARCH($A3,'RR2 Player Stats'!$A$3:$A$50))),0) +IFERROR(FILTER('RR3 Player Stats'!AC$3:AC$50, ISN"&"UMBER(SEARCH($A3,'RR3 Player Stats'!$A$3:$A$50))),0) +IFERROR(FILTER('RR4 Player Stats'!AC$3:AC$50, ISNUMBER(SEARCH($A3,'RR4 Player Stats'!$A$3:$A$50))),0) +IFERROR(FILTER('RR5 Player Stats'!AC$3:AC$50, ISNUMBER(SEARCH($A3,'RR5 Player Stats'!$A$3:$A$50)))"&",0)"),17.0) -> 17 | K3: =IFERROR(__xludf.DUMMYFUNCTION("IFERROR(FILTER('RR1 Player Stats'!AD$3:AD$50, ISNUMBER(SEARCH($A3,'RR1 Player Stats'!$A$3:$A$50))),0) +IFERROR(FILTER('RR2 Player Stats'!AD$3:AD$50, ISNUMBER(SEARCH($A3,'RR2 Player Stats'!$A$3:$A$50))),0) +IFERROR(FILTER('RR3 Player Stats'!AD$3:AD$50, ISN"&"UMBER(SEARCH($A3,'RR3 Player Stats'!$A$3:$A$50))),0) +IFERROR(FILTER('RR4 Player Stats'!AD$3:AD$50, ISNUMBER(SEARCH($A3,'RR4 Player Stats'!$A$3:$A$50))),0) +IFERROR(FILTER('RR5 Player Stats'!AD$3:AD$50, ISNUMBER(SEARCH($A3,'RR5 Player Stats'!$A$3:$A$50)))"&",0)"),14.0) -> 14 | L3: =IFERROR(__xludf.DUMMYFUNCTION("IFERROR(FILTER('RR1 Player Stats'!AE$3:AE$50, ISNUMBER(SEARCH($A3,'RR1 Player Stats'!$A$3:$A$50))),0) +IFERROR(FILTER('RR2 Player Stats'!AE$3:AE$50, ISNUMBER(SEARCH($A3,'RR2 Player Stats'!$A$3:$A$50))),0) +IFERROR(FILTER('RR3 Player Stats'!AE$3:AE$50, ISN"&"UMBER(SEARCH($A3,'RR3 Player Stats'!$A$3:$A$50))),0) +IFERROR(FILTER('RR4 Player Stats'!AE$3:AE$50, ISNUMBER(SEARCH($A3,'RR4 Player Stats'!$A$3:$A$50))),0) +IFERROR(FILTER('RR5 Player Stats'!AE$3:AE$50, ISNUMBER(SEARCH($A3,'RR5 Player Stats'!$A$3:$A$50)))"&",0)"),126.0) -> 126 | M3: =IFERROR(__xludf.DUMMYFUNCTION("IFERROR(FILTER('RR1 Player Stats'!AF$3:AF$50, ISNUMBER(SEARCH($A3,'RR1 Player Stats'!$A$3:$A$50))),0) +IFERROR(FILTER('RR2 Player Stats'!AF$3:AF$50, ISNUMBER(SEARCH($A3,'RR2 Player Stats'!$A$3:$A$50))),0) +IFERROR(FILTER('RR3 Player Stats'!AF$3:AF$50, ISN"&"UMBER(SEARCH($A3,'RR3 Player Stats'!$A$3:$A$50))),0) +IFERROR(FILTER('RR4 Player Stats'!AF$3:AF$50, ISNUMBER(SEARCH($A3,'RR4 Player Stats'!$A$3:$A$50))),0) +IFERROR(FILTER('RR5 Player Stats'!AF$3:AF$50, ISNUMBER(SEARCH($A3,'RR5 Player Stats'!$A$3:$A$50)))"&",0)"),70.0) -> 70 | N3: =IFERROR(__xludf.DUMMYFUNCTION("(IFERROR(FILTER('RR1 Player Stats'!AG$3:AG$50, ISNUMBER(SEARCH($A3,'RR1 Player Stats'!$A$3:$A$50))),0) +IFERROR(FILTER('RR2 Player Stats'!AG$3:AG$50, ISNUMBER(SEARCH($A3,'RR2 Player Stats'!$A$3:$A$50))),0) +IFERROR(FILTER('RR3 Player Stats'!AG$3:AG$50, IS"&"NUMBER(SEARCH($A3,'RR3 Player Stats'!$A$3:$A$50))),0) +IFERROR(FILTER('RR4 Player Stats'!AG$3:AG$50, ISNUMBER(SEARCH($A3,'RR4 Player Stats'!$A$3:$A$50))),0) +IFERROR(FILTER('RR5 Player Stats'!AG$3:AG$50, ISNUMBER(SEARCH($A3,'RR5 Player Stats'!$A$3:$A$50))"&"),0))/5"),0.578) -> 0.578 | O3: =IFERROR(__xludf.DUMMYFUNCTION("IFERROR(FILTER('RR1 Player Stats'!AH$3:AH$50, ISNUMBER(SEARCH($A3,'RR1 Player Stats'!$A$3:$A$50))),0) +IFERROR(FILTER('RR2 Player Stats'!AH$3:AH$50, ISNUMBER(SEARCH($A3,'RR2 Player Stats'!$A$3:$A$50))),0) +IFERROR(FILTER('RR3 Player Stats'!AH$3:AH$50, ISN"&"UMBER(SEARCH($A3,'RR3 Player Stats'!$A$3:$A$50))),0) +IFERROR(FILTER('RR4 Player Stats'!AH$3:AH$50, ISNUMBER(SEARCH($A3,'RR4 Player Stats'!$A$3:$A$50))),0) +IFERROR(FILTER('RR5 Player Stats'!AH$3:AH$50, ISNUMBER(SEARCH($A3,'RR5 Player Stats'!$A$3:$A$50)))"&",0)"),13.0) -> 13 | P3: =IFERROR(__xludf.DUMMYFUNCTION("IFERROR(FILTER('RR1 Player Stats'!AI$3:AI$50, ISNUMBER(SEARCH($A3,'RR1 Player Stats'!$A$3:$A$50))),0) +IFERROR(FILTER('RR2 Player Stats'!AI$3:AI$50, ISNUMBER(SEARCH($A3,'RR2 Player Stats'!$A$3:$A$50))),0) +IFERROR(FILTER('RR3 Player Stats'!AI$3:AI$50, ISN"&"UMBER(SEARCH($A3,'RR3 Player Stats'!$A$3:$A$50))),0) +IFERROR(FILTER('RR4 Player Stats'!AI$3:AI$50, ISNUMBER(SEARCH($A3,'RR4 Player Stats'!$A$3:$A$50))),0) +IFERROR(FILTER('RR5 Player Stats'!AI$3:AI$50, ISNUMBER(SEARCH($A3,'RR5 Player Stats'!$A$3:$A$50)))"&",0)"),48.0) -> 48 | Q3: =IFERROR(__xludf.DUMMYFUNCTION("IFERROR(FILTER('RR1 Player Stats'!AJ$3:AJ$50, ISNUMBER(SEARCH($A3,'RR1 Player Stats'!$A$3:$A$50))),0) +IFERROR(FILTER('RR2 Player Stats'!AJ$3:AJ$50, ISNUMBER(SEARCH($A3,'RR2 Player Stats'!$A$3:$A$50))),0) +IFERROR(FILTER('RR3 Player Stats'!AJ$3:AJ$50, ISN"&"UMBER(SEARCH($A3,'RR3 Player Stats'!$A$3:$A$50))),0) +IFERROR(FILTER('RR4 Player Stats'!AJ$3:AJ$50, ISNUMBER(SEARCH($A3,'RR4 Player Stats'!$A$3:$A$50))),0) +IFERROR(FILTER('RR5 Player Stats'!AJ$3:AJ$50, ISNUMBER(SEARCH($A3,'RR5 Player Stats'!$A$3:$A$50)))"&",0)"),30.0) -> 30 | R3: =IFERROR(__xludf.DUMMYFUNCTION("IFERROR(FILTER('RR1 Player Stats'!AK$3:AK$50, ISNUMBER(SEARCH($A3,'RR1 Player Stats'!$A$3:$A$50))),0) +IFERROR(FILTER('RR2 Player Stats'!AK$3:AK$50, ISNUMBER(SEARCH($A3,'RR2 Player Stats'!$A$3:$A$50))),0) +IFERROR(FILTER('RR3 Player Stats'!AK$3:AK$50, ISN"&"UMBER(SEARCH($A3,'RR3 Player Stats'!$A$3:$A$50))),0) +IFERROR(FILTER('RR4 Player Stats'!AK$3:AK$50, ISNUMBER(SEARCH($A3,'RR4 Player Stats'!$A$3:$A$50))),0) +IFERROR(FILTER('RR5 Player Stats'!AK$3:AK$50, ISNUMBER(SEARCH($A3,'RR5 Player Stats'!$A$3:$A$50)))"&",0)"),340.0) -> 340 | S3: =IFERROR(__xludf.DUMMYFUNCTION("IFERROR(FILTER('RR1 Player Stats'!AL$3:AL$50, ISNUMBER(SEARCH($A3,'RR1 Player Stats'!$A$3:$A$50))),0) +IFERROR(FILTER('RR2 Player Stats'!AL$3:AL$50, ISNUMBER(SEARCH($A3,'RR2 Player Stats'!$A$3:$A$50))),0) +IFERROR(FILTER('RR3 Player Stats'!AL$3:AL$50, ISN"&"UMBER(SEARCH($A3,'RR3 Player Stats'!$A$3:$A$50))),0) +IFERROR(FILTER('RR4 Player Stats'!AL$3:AL$50, ISNUMBER(SEARCH($A3,'RR4 Player Stats'!$A$3:$A$50))),0) +IFERROR(FILTER('RR5 Player Stats'!AL$3:AL$50, ISNUMBER(SEARCH($A3,'RR5 Player Stats'!$A$3:$A$50)))"&",0)"),220.0) -> 220 | T3: =IFERROR(__xludf.DUMMYFUNCTION("(IFERROR(FILTER('RR1 Player Stats'!AM$3:AM$50, ISNUMBER(SEARCH($A3,'RR1 Player Stats'!$A$3:$A$50))),0) +IFERROR(FILTER('RR2 Player Stats'!AM$3:AM$50, ISNUMBER(SEARCH($A3,'RR2 Player Stats'!$A$3:$A$50))),0) +IFERROR(FILTER('RR3 Player Stats'!AM$3:AM$50, IS"&"NUMBER(SEARCH($A3,'RR3 Player Stats'!$A$3:$A$50))),0) +IFERROR(FILTER('RR4 Player Stats'!AM$3:AM$50, ISNUMBER(SEARCH($A3,'RR4 Player Stats'!$A$3:$A$50))),0) +IFERROR(FILTER('RR5 Player Stats'!AM$3:AM$50, ISNUMBER(SEARCH($A3,'RR5 Player Stats'!$A$3:$A$50))"&"),0))/B3"),0.61) -> 0.61 | U3: =IFERROR(__xludf.DUMMYFUNCTION("MEDIAN(IFERROR(FILTER('RR1 Player Stats'!AH$3:AH$50, ISNUMBER(SEARCH($A3,'RR1 Player Stats'!$A$3:$A$50))),0),IFERROR(FILTER('RR2 Player Stats'!AH$3:AH$50, ISNUMBER(SEARCH($A3,'RR2 Player Stats'!$A$3:$A$50))),0),IFERROR(FILTER('RR3 Player Stats'!AH$3:AH$50"&", ISNUMBER(SEARCH($A3,'RR3 Player Stats'!$A$3:$A$50))),0),IFERROR(FILTER('RR4 Player Stats'!AH$3:AH$50, ISNUMBER(SEARCH($A3,'RR4 Player Stats'!$A$3:$A$50))),0),IFERROR(FILTER('RR5 Player Stats'!AH$3:AH$50, ISNUMBER(SEARCH($A3,'RR5 Player Stats'!$A$3:$A$50"&"))),0))"),3.0) -> 3 | V3: =IFERROR(__xludf.DUMMYFUNCTION("MEDIAN(IFERROR(FILTER('RR1 Player Stats'!AI$3:AI$50, ISNUMBER(SEARCH($A3,'RR1 Player Stats'!$A$3:$A$50))),0),IFERROR(FILTER('RR2 Player Stats'!AI$3:AI$50, ISNUMBER(SEARCH($A3,'RR2 Player Stats'!$A$3:$A$50))),0),IFERROR(FILTER('RR3 Player Stats'!AI$3:AI$50"&", ISNUMBER(SEARCH($A3,'RR3 Player Stats'!$A$3:$A$50))),0),IFERROR(FILTER('RR4 Player Stats'!AI$3:AI$50, ISNUMBER(SEARCH($A3,'RR4 Player Stats'!$A$3:$A$50))),0),IFERROR(FILTER('RR5 Player Stats'!AI$3:AI$50, ISNUMBER(SEARCH($A3,'RR5 Player Stats'!$A$3:$A$50"&"))),0))"),9.0) -> 9 | W3: =IFERROR(__xludf.DUMMYFUNCTION("MEDIAN(IFERROR(FILTER('RR1 Player Stats'!AJ$3:AJ$50, ISNUMBER(SEARCH($A3,'RR1 Player Stats'!$A$3:$A$50))),0),IFERROR(FILTER('RR2 Player Stats'!AJ$3:AJ$50, ISNUMBER(SEARCH($A3,'RR2 Player Stats'!$A$3:$A$50))),0),IFERROR(FILTER('RR3 Player Stats'!AJ$3:AJ$50"&", ISNUMBER(SEARCH($A3,'RR3 Player Stats'!$A$3:$A$50))),0),IFERROR(FILTER('RR4 Player Stats'!AJ$3:AJ$50, ISNUMBER(SEARCH($A3,'RR4 Player Stats'!$A$3:$A$50))),0),IFERROR(FILTER('RR5 Player Stats'!AJ$3:AJ$50, ISNUMBER(SEARCH($A3,'RR5 Player Stats'!$A$3:$A$50"&"))),0))"),6.0) -> 6 | X3: =IFERROR(__xludf.DUMMYFUNCTION("MEDIAN(IFERROR(FILTER('RR1 Player Stats'!AK$3:AK$50, ISNUMBER(SEARCH($A3,'RR1 Player Stats'!$A$3:$A$50))),0),IFERROR(FILTER('RR2 Player Stats'!AK$3:AK$50, ISNUMBER(SEARCH($A3,'RR2 Player Stats'!$A$3:$A$50))),0),IFERROR(FILTER('RR3 Player Stats'!AK$3:AK$50"&", ISNUMBER(SEARCH($A3,'RR3 Player Stats'!$A$3:$A$50))),0),IFERROR(FILTER('RR4 Player Stats'!AK$3:AK$50, ISNUMBER(SEARCH($A3,'RR4 Player Stats'!$A$3:$A$50))),0),IFERROR(FILTER('RR5 Player Stats'!AK$3:AK$50, ISNUMBER(SEARCH($A3,'RR5 Player Stats'!$A$3:$A$50"&"))),0))"),58.0) -> 58 | Y3: =IFERROR(__xludf.DUMMYFUNCTION("MEDIAN(IFERROR(FILTER('RR1 Player Stats'!AL$3:AL$50, ISNUMBER(SEARCH($A3,'RR1 Player Stats'!$A$3:$A$50))),0),IFERROR(FILTER('RR2 Player Stats'!AL$3:AL$50, ISNUMBER(SEARCH($A3,'RR2 Player Stats'!$A$3:$A$50))),0),IFERROR(FILTER('RR3 Player Stats'!AL$3:AL$50"&", ISNUMBER(SEARCH($A3,'RR3 Player Stats'!$A$3:$A$50))),0),IFERROR(FILTER('RR4 Player Stats'!AL$3:AL$50, ISNUMBER(SEARCH($A3,'RR4 Player Stats'!$A$3:$A$50))),0),IFERROR(FILTER('RR5 Player Stats'!AL$3:AL$50, ISNUMBER(SEARCH($A3,'RR5 Player Stats'!$A$3:$A$50"&"))),0))"),34.0) -> 34 | Z3: =IFERROR(__xludf.DUMMYFUNCTION("MEDIAN(IFERROR(FILTER('RR1 Player Stats'!AM$3:AM$50, ISNUMBER(SEARCH($A3,'RR1 Player Stats'!$A$3:$A$50))),0),IFERROR(FILTER('RR2 Player Stats'!AM$3:AM$50, ISNUMBER(SEARCH($A3,'RR2 Player Stats'!$A$3:$A$50))),0),IFERROR(FILTER('RR3 Player Stats'!AM$3:AM$50"&", ISNUMBER(SEARCH($A3,'RR3 Player Stats'!$A$3:$A$50))),0),IFERROR(FILTER('RR4 Player Stats'!AM$3:AM$50, ISNUMBER(SEARCH($A3,'RR4 Player Stats'!$A$3:$A$50))),0),IFERROR(FILTER('RR5 Player Stats'!AM$3:AM$50, ISNUMBER(SEARCH($A3,'RR5 Player Stats'!$A$3:$A$50"&"))),0))"),0.55) -> 0.55
A4: [2.2] Suzuko O | B4: =COUNTIF('RR1 Player Stats'!$A$3:$A$50,$A4)+COUNTIF('RR2 Player Stats'!$A$3:$A$50,$A4)+COUNTIF('RR3 Player Stats'!$A$3:$A$50,$A4)+COUNTIF('RR4 Player Stats'!$A$3:$A$50,$A4)+COUNTIF('RR5 Player Stats'!$A$3:$A$50,$A4) -> 5 | C4: =IFERROR(__xludf.DUMMYFUNCTION("IFERROR(FILTER('RR1 Player Stats'!V$3:V$50, ISNUMBER(SEARCH($A4,'RR1 Player Stats'!$A$3:$A$50))),0) +IFERROR(FILTER('RR2 Player Stats'!V$3:V$50, ISNUMBER(SEARCH($A4,'RR2 Player Stats'!$A$3:$A$50))),0) +IFERROR(FILTER('RR3 Player Stats'!V$3:V$50, ISNUMBER("&"SEARCH($A4,'RR3 Player Stats'!$A$3:$A$50))),0) +IFERROR(FILTER('RR4 Player Stats'!V$3:V$50, ISNUMBER(SEARCH($A4,'RR4 Player Stats'!$A$3:$A$50))),0) +IFERROR(FILTER('RR5 Player Stats'!V$3:V$50, ISNUMBER(SEARCH($A4,'RR5 Player Stats'!$A$3:$A$50))),0)"),12.0) -> 12 | D4: =IFERROR(__xludf.DUMMYFUNCTION("IFERROR(FILTER('RR1 Player Stats'!W$3:W$50, ISNUMBER(SEARCH($A4,'RR1 Player Stats'!$A$3:$A$50))),0) +IFERROR(FILTER('RR2 Player Stats'!W$3:W$50, ISNUMBER(SEARCH($A4,'RR2 Player Stats'!$A$3:$A$50))),0) +IFERROR(FILTER('RR3 Player Stats'!W$3:W$50, ISNUMBER("&"SEARCH($A4,'RR3 Player Stats'!$A$3:$A$50))),0) +IFERROR(FILTER('RR4 Player Stats'!W$3:W$50, ISNUMBER(SEARCH($A4,'RR4 Player Stats'!$A$3:$A$50))),0) +IFERROR(FILTER('RR5 Player Stats'!W$3:W$50, ISNUMBER(SEARCH($A4,'RR5 Player Stats'!$A$3:$A$50))),0)"),27.0) -> 27 | E4: =IFERROR(__xludf.DUMMYFUNCTION("IFERROR(FILTER('RR1 Player Stats'!X$3:X$50, ISNUMBER(SEARCH($A4,'RR1 Player Stats'!$A$3:$A$50))),0) +IFERROR(FILTER('RR2 Player Stats'!X$3:X$50, ISNUMBER(SEARCH($A4,'RR2 Player Stats'!$A$3:$A$50))),0) +IFERROR(FILTER('RR3 Player Stats'!X$3:X$50, ISNUMBER("&"SEARCH($A4,'RR3 Player Stats'!$A$3:$A$50))),0) +IFERROR(FILTER('RR4 Player Stats'!X$3:X$50, ISNUMBER(SEARCH($A4,'RR4 Player Stats'!$A$3:$A$50))),0) +IFERROR(FILTER('RR5 Player Stats'!X$3:X$50, ISNUMBER(SEARCH($A4,'RR5 Player Stats'!$A$3:$A$50))),0)"),6.0) -> 6 | F4: =IFERROR(__xludf.DUMMYFUNCTION("IFERROR(FILTER('RR1 Player Stats'!Y$3:Y$50, ISNUMBER(SEARCH($A4,'RR1 Player Stats'!$A$3:$A$50))),0) +IFERROR(FILTER('RR2 Player Stats'!Y$3:Y$50, ISNUMBER(SEARCH($A4,'RR2 Player Stats'!$A$3:$A$50))),0) +IFERROR(FILTER('RR3 Player Stats'!Y$3:Y$50, ISNUMBER("&"SEARCH($A4,'RR3 Player Stats'!$A$3:$A$50))),0) +IFERROR(FILTER('RR4 Player Stats'!Y$3:Y$50, ISNUMBER(SEARCH($A4,'RR4 Player Stats'!$A$3:$A$50))),0) +IFERROR(FILTER('RR5 Player Stats'!Y$3:Y$50, ISNUMBER(SEARCH($A4,'RR5 Player Stats'!$A$3:$A$50))),0)"),210.0) -> 210 | G4: =IFERROR(__xludf.DUMMYFUNCTION("IFERROR(FILTER('RR1 Player Stats'!Z$3:Z$50, ISNUMBER(SEARCH($A4,'RR1 Player Stats'!$A$3:$A$50))),0) +IFERROR(FILTER('RR2 Player Stats'!Z$3:Z$50, ISNUMBER(SEARCH($A4,'RR2 Player Stats'!$A$3:$A$50))),0) +IFERROR(FILTER('RR3 Player Stats'!Z$3:Z$50, ISNUMBER("&"SEARCH($A4,'RR3 Player Stats'!$A$3:$A$50))),0) +IFERROR(FILTER('RR4 Player Stats'!Z$3:Z$50, ISNUMBER(SEARCH($A4,'RR4 Player Stats'!$A$3:$A$50))),0) +IFERROR(FILTER('RR5 Player Stats'!Z$3:Z$50, ISNUMBER(SEARCH($A4,'RR5 Player Stats'!$A$3:$A$50))),0)"),186.0) -> 186 | H4: =IFERROR(__xludf.DUMMYFUNCTION("(IFERROR(FILTER('RR1 Player Stats'!AA$3:AA$50, ISNUMBER(SEARCH($A4,'RR1 Player Stats'!$A$3:$A$50))),0) +IFERROR(FILTER('RR2 Player Stats'!AA$3:AA$50, ISNUMBER(SEARCH($A4,'RR2 Player Stats'!$A$3:$A$50))),0) +IFERROR(FILTER('RR3 Player Stats'!AA$3:AA$50, IS"&"NUMBER(SEARCH($A4,'RR3 Player Stats'!$A$3:$A$50))),0) +IFERROR(FILTER('RR4 Player Stats'!AA$3:AA$50, ISNUMBER(SEARCH($A4,'RR4 Player Stats'!$A$3:$A$50))),0) +IFERROR(FILTER('RR5 Player Stats'!AA$3:AA$50, ISNUMBER(SEARCH($A4,'RR5 Player Stats'!$A$3:$A$50))"&"),0))/5"),0.6519999999999999) -> 0.652 | I4: =IFERROR(__xludf.DUMMYFUNCTION("IFERROR(FILTER('RR1 Player Stats'!AB$3:AB$50, ISNUMBER(SEARCH($A4,'RR1 Player Stats'!$A$3:$A$50))),0) +IFERROR(FILTER('RR2 Player Stats'!AB$3:AB$50, ISNUMBER(SEARCH($A4,'RR2 Player Stats'!$A$3:$A$50))),0) +IFERROR(FILTER('RR3 Player Stats'!AB$3:AB$50, ISN"&"UMBER(SEARCH($A4,'RR3 Player Stats'!$A$3:$A$50))),0) +IFERROR(FILTER('RR4 Player Stats'!AB$3:AB$50, ISNUMBER(SEARCH($A4,'RR4 Player Stats'!$A$3:$A$50))),0) +IFERROR(FILTER('RR5 Player Stats'!AB$3:AB$50, ISNUMBER(SEARCH($A4,'RR5 Player Stats'!$A$3:$A$50)))"&",0)"),10.0) -> 10 | J4: =IFERROR(__xludf.DUMMYFUNCTION("IFERROR(FILTER('RR1 Player Stats'!AC$3:AC$50, ISNUMBER(SEARCH($A4,'RR1 Player Stats'!$A$3:$A$50))),0) +IFERROR(FILTER('RR2 Player Stats'!AC$3:AC$50, ISNUMBER(SEARCH($A4,'RR2 Player Stats'!$A$3:$A$50))),0) +IFERROR(FILTER('RR3 Player Stats'!AC$3:AC$50, ISN"&"UMBER(SEARCH($A4,'RR3 Player Stats'!$A$3:$A$50))),0) +IFERROR(FILTER('RR4 Player Stats'!AC$3:AC$50, ISNUMBER(SEARCH($A4,'RR4 Player Stats'!$A$3:$A$50))),0) +IFERROR(FILTER('RR5 Player Stats'!AC$3:AC$50, ISNUMBER(SEARCH($A4,'RR5 Player Stats'!$A$3:$A$50)))"&",0)"),10.0) -> 10 | K4: =IFERROR(__xludf.DUMMYFUNCTION("IFERROR(FILTER('RR1 Player Stats'!AD$3:AD$50, ISNUMBER(SEARCH($A4,'RR1 Player Stats'!$A$3:$A$50))),0) +IFERROR(FILTER('RR2 Player Stats'!AD$3:AD$50, ISNUMBER(SEARCH($A4,'RR2 Player Stats'!$A$3:$A$50))),0) +IFERROR(FILTER('RR3 Player Stats'!AD$3:AD$50, ISN"&"UMBER(SEARCH($A4,'RR3 Player Stats'!$A$3:$A$50))),0) +IFERROR(FILTER('RR4 Player Stats'!AD$3:AD$50, ISNUMBER(SEARCH($A4,'RR4 Player Stats'!$A$3:$A$50))),0) +IFERROR(FILTER('RR5 Player Stats'!AD$3:AD$50, ISNUMBER(SEARCH($A4,'RR5 Player Stats'!$A$3:$A$50)))"&",0)"),6.0) -> 6 | L4: =IFERROR(__xludf.DUMMYFUNCTION("IFERROR(FILTER('RR1 Player Stats'!AE$3:AE$50, ISNUMBER(SEARCH($A4,'RR1 Player Stats'!$A$3:$A$50))),0) +IFERROR(FILTER('RR2 Player Stats'!AE$3:AE$50, ISNUMBER(SEARCH($A4,'RR2 Player Stats'!$A$3:$A$50))),0) +IFERROR(FILTER('RR3 Player Stats'!AE$3:AE$50, ISN"&"UMBER(SEARCH($A4,'RR3 Player Stats'!$A$3:$A$50))),0) +IFERROR(FILTER('RR4 Player Stats'!AE$3:AE$50, ISNUMBER(SEARCH($A4,'RR4 Player Stats'!$A$3:$A$50))),0) +IFERROR(FILTER('RR5 Player Stats'!AE$3:AE$50, ISNUMBER(SEARCH($A4,'RR5 Player Stats'!$A$3:$A$50)))"&",0)"),100.0) -> 100 | M4: =IFERROR(__xludf.DUMMYFUNCTION("IFERROR(FILTER('RR1 Player Stats'!AF$3:AF$50, ISNUMBER(SEARCH($A4,'RR1 Player Stats'!$A$3:$A$50))),0) +IFERROR(FILTER('RR2 Player Stats'!AF$3:AF$50, ISNUMBER(SEARCH($A4,'RR2 Player Stats'!$A$3:$A$50))),0) +IFERROR(FILTER('RR3 Player Stats'!AF$3:AF$50, ISN"&"UMBER(SEARCH($A4,'RR3 Player Stats'!$A$3:$A$50))),0) +IFERROR(FILTER('RR4 Player Stats'!AF$3:AF$50, ISNUMBER(SEARCH($A4,'RR4 Player Stats'!$A$3:$A$50))),0) +IFERROR(FILTER('RR5 Player Stats'!AF$3:AF$50, ISNUMBER(SEARCH($A4,'RR5 Player Stats'!$A$3:$A$50)))"&",0)"),76.0) -> 76 | N4: =IFERROR(__xludf.DUMMYFUNCTION("(IFERROR(FILTER('RR1 Player Stats'!AG$3:AG$50, ISNUMBER(SEARCH($A4,'RR1 Player Stats'!$A$3:$A$50))),0) +IFERROR(FILTER('RR2 Player Stats'!AG$3:AG$50, ISNUMBER(SEARCH($A4,'RR2 Player Stats'!$A$3:$A$50))),0) +IFERROR(FILTER('RR3 Player Stats'!AG$3:AG$50, IS"&"NUMBER(SEARCH($A4,'RR3 Player Stats'!$A$3:$A$50))),0) +IFERROR(FILTER('RR4 Player Stats'!AG$3:AG$50, ISNUMBER(SEARCH($A4,'RR4 Player Stats'!$A$3:$A$50))),0) +IFERROR(FILTER('RR5 Player Stats'!AG$3:AG$50, ISNUMBER(SEARCH($A4,'RR5 Player Stats'!$A$3:$A$50))"&"),0))/5"),0.504) -> 0.504 | O4: =IFERROR(__xludf.DUMMYFUNCTION("IFERROR(FILTER('RR1 Player Stats'!AH$3:AH$50, ISNUMBER(SEARCH($A4,'RR1 Player Stats'!$A$3:$A$50))),0) +IFERROR(FILTER('RR2 Player Stats'!AH$3:AH$50, ISNUMBER(SEARCH($A4,'RR2 Player Stats'!$A$3:$A$50))),0) +IFERROR(FILTER('RR3 Player Stats'!AH$3:AH$50, ISN"&"UMBER(SEARCH($A4,'RR3 Player Stats'!$A$3:$A$50))),0) +IFERROR(FILTER('RR4 Player Stats'!AH$3:AH$50, ISNUMBER(SEARCH($A4,'RR4 Player Stats'!$A$3:$A$50))),0) +IFERROR(FILTER('RR5 Player Stats'!AH$3:AH$50, ISNUMBER(SEARCH($A4,'RR5 Player Stats'!$A$3:$A$50)))"&",0)"),22.0) -> 22 | P4: =IFERROR(__xludf.DUMMYFUNCTION("IFERROR(FILTER('RR1 Player Stats'!AI$3:AI$50, ISNUMBER(SEARCH($A4,'RR1 Player Stats'!$A$3:$A$50))),0) +IFERROR(FILTER('RR2 Player Stats'!AI$3:AI$50, ISNUMBER(SEARCH($A4,'RR2 Player Stats'!$A$3:$A$50))),0) +IFERROR(FILTER('RR3 Player Stats'!AI$3:AI$50, ISN"&"UMBER(SEARCH($A4,'RR3 Player Stats'!$A$3:$A$50))),0) +IFERROR(FILTER('RR4 Player Stats'!AI$3:AI$50, ISNUMBER(SEARCH($A4,'RR4 Player Stats'!$A$3:$A$50))),0) +IFERROR(FILTER('RR5 Player Stats'!AI$3:AI$50, ISNUMBER(SEARCH($A4,'RR5 Player Stats'!$A$3:$A$50)))"&",0)"),37.0) -> 37 | Q4: =IFERROR(__xludf.DUMMYFUNCTION("IFERROR(FILTER('RR1 Player Stats'!AJ$3:AJ$50, ISNUMBER(SEARCH($A4,'RR1 Player Stats'!$A$3:$A$50))),0) +IFERROR(FILTER('RR2 Player Stats'!AJ$3:AJ$50, ISNUMBER(SEARCH($A4,'RR2 Player Stats'!$A$3:$A$50))),0) +IFERROR(FILTER('RR3 Player Stats'!AJ$3:AJ$50, ISN"&"UMBER(SEARCH($A4,'RR3 Player Stats'!$A$3:$A$50))),0) +IFERROR(FILTER('RR4 Player Stats'!AJ$3:AJ$50, ISNUMBER(SEARCH($A4,'RR4 Player Stats'!$A$3:$A$50))),0) +IFERROR(FILTER('RR5 Player Stats'!AJ$3:AJ$50, ISNUMBER(SEARCH($A4,'RR5 Player Stats'!$A$3:$A$50)))"&",0)"),12.0) -> 12 | R4: =IFERROR(__xludf.DUMMYFUNCTION("IFERROR(FILTER('RR1 Player Stats'!AK$3:AK$50, ISNUMBER(SEARCH($A4,'RR1 Player Stats'!$A$3:$A$50))),0) +IFERROR(FILTER('RR2 Player Stats'!AK$3:AK$50, ISNUMBER(SEARCH($A4,'RR2 Player Stats'!$A$3:$A$50))),0) +IFERROR(FILTER('RR3 Player Stats'!AK$3:AK$50, ISN"&"UMBER(SEARCH($A4,'RR3 Player Stats'!$A$3:$A$50))),0) +IFERROR(FILTER('RR4 Player Stats'!AK$3:AK$50, ISNUMBER(SEARCH($A4,'RR4 Player Stats'!$A$3:$A$50))),0) +IFERROR(FILTER('RR5 Player Stats'!AK$3:AK$50, ISNUMBER(SEARCH($A4,'RR5 Player Stats'!$A$3:$A$50)))"&",0)"),310.0) -> 310 | S4: =IFERROR(__xludf.DUMMYFUNCTION("IFERROR(FILTER('RR1 Player Stats'!AL$3:AL$50, ISNUMBER(SEARCH($A4,'RR1 Player Stats'!$A$3:$A$50))),0) +IFERROR(FILTER('RR2 Player Stats'!AL$3:AL$50, ISNUMBER(SEARCH($A4,'RR2 Player Stats'!$A$3:$A$50))),0) +IFERROR(FILTER('RR3 Player Stats'!AL$3:AL$50, ISN"&"UMBER(SEARCH($A4,'RR3 Player Stats'!$A$3:$A$50))),0) +IFERROR(FILTER('RR4 Player Stats'!AL$3:AL$50, ISNUMBER(SEARCH($A4,'RR4 Player Stats'!$A$3:$A$50))),0) +IFERROR(FILTER('RR5 Player Stats'!AL$3:AL$50, ISNUMBER(SEARCH($A4,'RR5 Player Stats'!$A$3:$A$50)))"&",0)"),262.0) -> 262 | T4: =IFERROR(__xludf.DUMMYFUNCTION("(IFERROR(FILTER('RR1 Player Stats'!AM$3:AM$50, ISNUMBER(SEARCH($A4,'RR1 Player Stats'!$A$3:$A$50))),0) +IFERROR(FILTER('RR2 Player Stats'!AM$3:AM$50, ISNUMBER(SEARCH($A4,'RR2 Player Stats'!$A$3:$A$50))),0) +IFERROR(FILTER('RR3 Player Stats'!AM$3:AM$50, IS"&"NUMBER(SEARCH($A4,'RR3 Player Stats'!$A$3:$A$50))),0) +IFERROR(FILTER('RR4 Player Stats'!AM$3:AM$50, ISNUMBER(SEARCH($A4,'RR4 Player Stats'!$A$3:$A$50))),0) +IFERROR(FILTER('RR5 Player Stats'!AM$3:AM$50, ISNUMBER(SEARCH($A4,'RR5 Player Stats'!$A$3:$A$50))"&"),0))/B4"),0.5900000000000001) -> 0.59 | U4: =IFERROR(__xludf.DUMMYFUNCTION("MEDIAN(IFERROR(FILTER('RR1 Player Stats'!AH$3:AH$50, ISNUMBER(SEARCH($A4,'RR1 Player Stats'!$A$3:$A$50))),0),IFERROR(FILTER('RR2 Player Stats'!AH$3:AH$50, ISNUMBER(SEARCH($A4,'RR2 Player Stats'!$A$3:$A$50))),0),IFERROR(FILTER('RR3 Player Stats'!AH$3:AH$50"&", ISNUMBER(SEARCH($A4,'RR3 Player Stats'!$A$3:$A$50))),0),IFERROR(FILTER('RR4 Player Stats'!AH$3:AH$50, ISNUMBER(SEARCH($A4,'RR4 Player Stats'!$A$3:$A$50))),0),IFERROR(FILTER('RR5 Player Stats'!AH$3:AH$50, ISNUMBER(SEARCH($A4,'RR5 Player Stats'!$A$3:$A$50"&"))),0))"),5.0) -> 5 | V4: =IFERROR(__xludf.DUMMYFUNCTION("MEDIAN(IFERROR(FILTER('RR1 Player Stats'!AI$3:AI$50, ISNUMBER(SEARCH($A4,'RR1 Player Stats'!$A$3:$A$50))),0),IFERROR(FILTER('RR2 Player Stats'!AI$3:AI$50, ISNUMBER(SEARCH($A4,'RR2 Player Stats'!$A$3:$A$50))),0),IFERROR(FILTER('RR3 Player Stats'!AI$3:AI$50"&", ISNUMBER(SEARCH($A4,'RR3 Player Stats'!$A$3:$A$50))),0),IFERROR(FILTER('RR4 Player Stats'!AI$3:AI$50, ISNUMBER(SEARCH($A4,'RR4 Player Stats'!$A$3:$A$50))),0),IFERROR(FILTER('RR5 Player Stats'!AI$3:AI$50, ISNUMBER(SEARCH($A4,'RR5 Player Stats'!$A$3:$A$50"&"))),0))"),7.0) -> 7 | W4: =IFERROR(__xludf.DUMMYFUNCTION("MEDIAN(IFERROR(FILTER('RR1 Player Stats'!AJ$3:AJ$50, ISNUMBER(SEARCH($A4,'RR1 Player Stats'!$A$3:$A$50))),0),IFERROR(FILTER('RR2 Player Stats'!AJ$3:AJ$50, ISNUMBER(SEARCH($A4,'RR2 Player Stats'!$A$3:$A$50))),0),IFERROR(FILTER('RR3 Player Stats'!AJ$3:AJ$50"&", ISNUMBER(SEARCH($A4,'RR3 Player Stats'!$A$3:$A$50))),0),IFERROR(FILTER('RR4 Player Stats'!AJ$3:AJ$50, ISNUMBER(SEARCH($A4,'RR4 Player Stats'!$A$3:$A$50))),0),IFERROR(FILTER('RR5 Player Stats'!AJ$3:AJ$50, ISNUMBER(SEARCH($A4,'RR5 Player Stats'!$A$3:$A$50"&"))),0))"),2.0) -> 2 | X4: =IFERROR(__xludf.DUMMYFUNCTION("MEDIAN(IFERROR(FILTER('RR1 Player Stats'!AK$3:AK$50, ISNUMBER(SEARCH($A4,'RR1 Player Stats'!$A$3:$A$50))),0),IFERROR(FILTER('RR2 Player Stats'!AK$3:AK$50, ISNUMBER(SEARCH($A4,'RR2 Player Stats'!$A$3:$A$50))),0),IFERROR(FILTER('RR3 Player Stats'!AK$3:AK$50"&", ISNUMBER(SEARCH($A4,'RR3 Player Stats'!$A$3:$A$50))),0),IFERROR(FILTER('RR4 Player Stats'!AK$3:AK$50, ISNUMBER(SEARCH($A4,'RR4 Player Stats'!$A$3:$A$50))),0),IFERROR(FILTER('RR5 Player Stats'!AK$3:AK$50, ISNUMBER(SEARCH($A4,'RR5 Player Stats'!$A$3:$A$50"&"))),0))"),66.0) -> 66 | Y4: =IFERROR(__xludf.DUMMYFUNCTION("MEDIAN(IFERROR(FILTER('RR1 Player Stats'!AL$3:AL$50, ISNUMBER(SEARCH($A4,'RR1 Player Stats'!$A$3:$A$50))),0),IFERROR(FILTER('RR2 Player Stats'!AL$3:AL$50, ISNUMBER(SEARCH($A4,'RR2 Player Stats'!$A$3:$A$50))),0),IFERROR(FILTER('RR3 Player Stats'!AL$3:AL$50"&", ISNUMBER(SEARCH($A4,'RR3 Player Stats'!$A$3:$A$50))),0),IFERROR(FILTER('RR4 Player Stats'!AL$3:AL$50, ISNUMBER(SEARCH($A4,'RR4 Player Stats'!$A$3:$A$50))),0),IFERROR(FILTER('RR5 Player Stats'!AL$3:AL$50, ISNUMBER(SEARCH($A4,'RR5 Player Stats'!$A$3:$A$50"&"))),0))"),58.0) -> 58 | Z4: =IFERROR(__xludf.DUMMYFUNCTION("MEDIAN(IFERROR(FILTER('RR1 Player Stats'!AM$3:AM$50, ISNUMBER(SEARCH($A4,'RR1 Player Stats'!$A$3:$A$50))),0),IFERROR(FILTER('RR2 Player Stats'!AM$3:AM$50, ISNUMBER(SEARCH($A4,'RR2 Player Stats'!$A$3:$A$50))),0),IFERROR(FILTER('RR3 Player Stats'!AM$3:AM$50"&", ISNUMBER(SEARCH($A4,'RR3 Player Stats'!$A$3:$A$50))),0),IFERROR(FILTER('RR4 Player Stats'!AM$3:AM$50, ISNUMBER(SEARCH($A4,'RR4 Player Stats'!$A$3:$A$50))),0),IFERROR(FILTER('RR5 Player Stats'!AM$3:AM$50, ISNUMBER(SEARCH($A4,'RR5 Player Stats'!$A$3:$A$50"&"))),0))"),0.65) -> 0.65
A5: [7.5] Kensuke O | B5: =COUNTIF('RR1 Player Stats'!$A$3:$A$50,$A5)+COUNTIF('RR2 Player Stats'!$A$3:$A$50,$A5)+COUNTIF('RR3 Player Stats'!$A$3:$A$50,$A5)+COUNTIF('RR4 Player Stats'!$A$3:$A$50,$A5)+COUNTIF('RR5 Player Stats'!$A$3:$A$50,$A5) -> 5 | C5: =IFERROR(__xludf.DUMMYFUNCTION("IFERROR(FILTER('RR1 Player Stats'!V$3:V$50, ISNUMBER(SEARCH($A5,'RR1 Player Stats'!$A$3:$A$50))),0) +IFERROR(FILTER('RR2 Player Stats'!V$3:V$50, ISNUMBER(SEARCH($A5,'RR2 Player Stats'!$A$3:$A$50))),0) +IFERROR(FILTER('RR3 Player Stats'!V$3:V$50, ISNUMBER("&"SEARCH($A5,'RR3 Player Stats'!$A$3:$A$50))),0) +IFERROR(FILTER('RR4 Player Stats'!V$3:V$50, ISNUMBER(SEARCH($A5,'RR4 Player Stats'!$A$3:$A$50))),0) +IFERROR(FILTER('RR5 Player Stats'!V$3:V$50, ISNUMBER(SEARCH($A5,'RR5 Player Stats'!$A$3:$A$50))),0)"),21.0) -> 21 | D5: =IFERROR(__xludf.DUMMYFUNCTION("IFERROR(FILTER('RR1 Player Stats'!W$3:W$50, ISNUMBER(SEARCH($A5,'RR1 Player Stats'!$A$3:$A$50))),0) +IFERROR(FILTER('RR2 Player Stats'!W$3:W$50, ISNUMBER(SEARCH($A5,'RR2 Player Stats'!$A$3:$A$50))),0) +IFERROR(FILTER('RR3 Player Stats'!W$3:W$50, ISNUMBER("&"SEARCH($A5,'RR3 Player Stats'!$A$3:$A$50))),0) +IFERROR(FILTER('RR4 Player Stats'!W$3:W$50, ISNUMBER(SEARCH($A5,'RR4 Player Stats'!$A$3:$A$50))),0) +IFERROR(FILTER('RR5 Player Stats'!W$3:W$50, ISNUMBER(SEARCH($A5,'RR5 Player Stats'!$A$3:$A$50))),0)"),18.0) -> 18 | E5: =IFERROR(__xludf.DUMMYFUNCTION("IFERROR(FILTER('RR1 Player Stats'!X$3:X$50, ISNUMBER(SEARCH($A5,'RR1 Player Stats'!$A$3:$A$50))),0) +IFERROR(FILTER('RR2 Player Stats'!X$3:X$50, ISNUMBER(SEARCH($A5,'RR2 Player Stats'!$A$3:$A$50))),0) +IFERROR(FILTER('RR3 Player Stats'!X$3:X$50, ISNUMBER("&"SEARCH($A5,'RR3 Player Stats'!$A$3:$A$50))),0) +IFERROR(FILTER('RR4 Player Stats'!X$3:X$50, ISNUMBER(SEARCH($A5,'RR4 Player Stats'!$A$3:$A$50))),0) +IFERROR(FILTER('RR5 Player Stats'!X$3:X$50, ISNUMBER(SEARCH($A5,'RR5 Player Stats'!$A$3:$A$50))),0)"),4.0) -> 4 | F5: =IFERROR(__xludf.DUMMYFUNCTION("IFERROR(FILTER('RR1 Player Stats'!Y$3:Y$50, ISNUMBER(SEARCH($A5,'RR1 Player Stats'!$A$3:$A$50))),0) +IFERROR(FILTER('RR2 Player Stats'!Y$3:Y$50, ISNUMBER(SEARCH($A5,'RR2 Player Stats'!$A$3:$A$50))),0) +IFERROR(FILTER('RR3 Player Stats'!Y$3:Y$50, ISNUMBER("&"SEARCH($A5,'RR3 Player Stats'!$A$3:$A$50))),0) +IFERROR(FILTER('RR4 Player Stats'!Y$3:Y$50, ISNUMBER(SEARCH($A5,'RR4 Player Stats'!$A$3:$A$50))),0) +IFERROR(FILTER('RR5 Player Stats'!Y$3:Y$50, ISNUMBER(SEARCH($A5,'RR5 Player Stats'!$A$3:$A$50))),0)"),192.0) -> 192 | G5: =IFERROR(__xludf.DUMMYFUNCTION("IFERROR(FILTER('RR1 Player Stats'!Z$3:Z$50, ISNUMBER(SEARCH($A5,'RR1 Player Stats'!$A$3:$A$50))),0) +IFERROR(FILTER('RR2 Player Stats'!Z$3:Z$50, ISNUMBER(SEARCH($A5,'RR2 Player Stats'!$A$3:$A$50))),0) +IFERROR(FILTER('RR3 Player Stats'!Z$3:Z$50, ISNUMBER("&"SEARCH($A5,'RR3 Player Stats'!$A$3:$A$50))),0) +IFERROR(FILTER('RR4 Player Stats'!Z$3:Z$50, ISNUMBER(SEARCH($A5,'RR4 Player Stats'!$A$3:$A$50))),0) +IFERROR(FILTER('RR5 Player Stats'!Z$3:Z$50, ISNUMBER(SEARCH($A5,'RR5 Player Stats'!$A$3:$A$50))),0)"),176.0) -> 176 | H5: =IFERROR(__xludf.DUMMYFUNCTION("(IFERROR(FILTER('RR1 Player Stats'!AA$3:AA$50, ISNUMBER(SEARCH($A5,'RR1 Player Stats'!$A$3:$A$50))),0) +IFERROR(FILTER('RR2 Player Stats'!AA$3:AA$50, ISNUMBER(SEARCH($A5,'RR2 Player Stats'!$A$3:$A$50))),0) +IFERROR(FILTER('RR3 Player Stats'!AA$3:AA$50, IS"&"NUMBER(SEARCH($A5,'RR3 Player Stats'!$A$3:$A$50))),0) +IFERROR(FILTER('RR4 Player Stats'!AA$3:AA$50, ISNUMBER(SEARCH($A5,'RR4 Player Stats'!$A$3:$A$50))),0) +IFERROR(FILTER('RR5 Player Stats'!AA$3:AA$50, ISNUMBER(SEARCH($A5,'RR5 Player Stats'!$A$3:$A$50))"&"),0))/5"),0.6519999999999999) -> 0.652 | I5: =IFERROR(__xludf.DUMMYFUNCTION("IFERROR(FILTER('RR1 Player Stats'!AB$3:AB$50, ISNUMBER(SEARCH($A5,'RR1 Player Stats'!$A$3:$A$50))),0) +IFERROR(FILTER('RR2 Player Stats'!AB$3:AB$50, ISNUMBER(SEARCH($A5,'RR2 Player Stats'!$A$3:$A$50))),0) +IFERROR(FILTER('RR3 Player Stats'!AB$3:AB$50, ISN"&"UMBER(SEARCH($A5,'RR3 Player Stats'!$A$3:$A$50))),0) +IFERROR(FILTER('RR4 Player Stats'!AB$3:AB$50, ISNUMBER(SEARCH($A5,'RR4 Player Stats'!$A$3:$A$50))),0) +IFERROR(FILTER('RR5 Player Stats'!AB$3:AB$50, ISNUMBER(SEARCH($A5,'RR5 Player Stats'!$A$3:$A$50)))"&",0)"),10.0) -> 10 | J5: =IFERROR(__xludf.DUMMYFUNCTION("IFERROR(FILTER('RR1 Player Stats'!AC$3:AC$50, ISNUMBER(SEARCH($A5,'RR1 Player Stats'!$A$3:$A$50))),0) +IFERROR(FILTER('RR2 Player Stats'!AC$3:AC$50, ISNUMBER(SEARCH($A5,'RR2 Player Stats'!$A$3:$A$50))),0) +IFERROR(FILTER('RR3 Player Stats'!AC$3:AC$50, ISN"&"UMBER(SEARCH($A5,'RR3 Player Stats'!$A$3:$A$50))),0) +IFERROR(FILTER('RR4 Player Stats'!AC$3:AC$50, ISNUMBER(SEARCH($A5,'RR4 Player Stats'!$A$3:$A$50))),0) +IFERROR(FILTER('RR5 Player Stats'!AC$3:AC$50, ISNUMBER(SEARCH($A5,'RR5 Player Stats'!$A$3:$A$50)))"&",0)"),10.0) -> 10 | K5: =IFERROR(__xludf.DUMMYFUNCTION("IFERROR(FILTER('RR1 Player Stats'!AD$3:AD$50, ISNUMBER(SEARCH($A5,'RR1 Player Stats'!$A$3:$A$50))),0) +IFERROR(FILTER('RR2 Player Stats'!AD$3:AD$50, ISNUMBER(SEARCH($A5,'RR2 Player Stats'!$A$3:$A$50))),0) +IFERROR(FILTER('RR3 Player Stats'!AD$3:AD$50, ISN"&"UMBER(SEARCH($A5,'RR3 Player Stats'!$A$3:$A$50))),0) +IFERROR(FILTER('RR4 Player Stats'!AD$3:AD$50, ISNUMBER(SEARCH($A5,'RR4 Player Stats'!$A$3:$A$50))),0) +IFERROR(FILTER('RR5 Player Stats'!AD$3:AD$50, ISNUMBER(SEARCH($A5,'RR5 Player Stats'!$A$3:$A$50)))"&",0)"),1.0) -> 1 | L5: =IFERROR(__xludf.DUMMYFUNCTION("IFERROR(FILTER('RR1 Player Stats'!AE$3:AE$50, ISNUMBER(SEARCH($A5,'RR1 Player Stats'!$A$3:$A$50))),0) +IFERROR(FILTER('RR2 Player Stats'!AE$3:AE$50, ISNUMBER(SEARCH($A5,'RR2 Player Stats'!$A$3:$A$50))),0) +IFERROR(FILTER('RR3 Player Stats'!AE$3:AE$50, ISN"&"UMBER(SEARCH($A5,'RR3 Player Stats'!$A$3:$A$50))),0) +IFERROR(FILTER('RR4 Player Stats'!AE$3:AE$50, ISNUMBER(SEARCH($A5,'RR4 Player Stats'!$A$3:$A$50))),0) +IFERROR(FILTER('RR5 Player Stats'!AE$3:AE$50, ISNUMBER(SEARCH($A5,'RR5 Player Stats'!$A$3:$A$50)))"&",0)"),100.0) -> 100 | M5: =IFERROR(__xludf.DUMMYFUNCTION("IFERROR(FILTER('RR1 Player Stats'!AF$3:AF$50, ISNUMBER(SEARCH($A5,'RR1 Player Stats'!$A$3:$A$50))),0) +IFERROR(FILTER('RR2 Player Stats'!AF$3:AF$50, ISNUMBER(SEARCH($A5,'RR2 Player Stats'!$A$3:$A$50))),0) +IFERROR(FILTER('RR3 Player Stats'!AF$3:AF$50, ISN"&"UMBER(SEARCH($A5,'RR3 Player Stats'!$A$3:$A$50))),0) +IFERROR(FILTER('RR4 Player Stats'!AF$3:AF$50, ISNUMBER(SEARCH($A5,'RR4 Player Stats'!$A$3:$A$50))),0) +IFERROR(FILTER('RR5 Player Stats'!AF$3:AF$50, ISNUMBER(SEARCH($A5,'RR5 Player Stats'!$A$3:$A$50)))"&",0)"),96.0) -> 96 | N5: =IFERROR(__xludf.DUMMYFUNCTION("(IFERROR(FILTER('RR1 Player Stats'!AG$3:AG$50, ISNUMBER(SEARCH($A5,'RR1 Player Stats'!$A$3:$A$50))),0) +IFERROR(FILTER('RR2 Player Stats'!AG$3:AG$50, ISNUMBER(SEARCH($A5,'RR2 Player Stats'!$A$3:$A$50))),0) +IFERROR(FILTER('RR3 Player Stats'!AG$3:AG$50, IS"&"NUMBER(SEARCH($A5,'RR3 Player Stats'!$A$3:$A$50))),0) +IFERROR(FILTER('RR4 Player Stats'!AG$3:AG$50, ISNUMBER(SEARCH($A5,'RR4 Player Stats'!$A$3:$A$50))),0) +IFERROR(FILTER('RR5 Player Stats'!AG$3:AG$50, ISNUMBER(SEARCH($A5,'RR5 Player Stats'!$A$3:$A$50))"&"),0))/5"),0.502) -> 0.502 | O5: =IFERROR(__xludf.DUMMYFUNCTION("IFERROR(FILTER('RR1 Player Stats'!AH$3:AH$50, ISNUMBER(SEARCH($A5,'RR1 Player Stats'!$A$3:$A$50))),0) +IFERROR(FILTER('RR2 Player Stats'!AH$3:AH$50, ISNUMBER(SEARCH($A5,'RR2 Player Stats'!$A$3:$A$50))),0) +IFERROR(FILTER('RR3 Player Stats'!AH$3:AH$50, ISN"&"UMBER(SEARCH($A5,'RR3 Player Stats'!$A$3:$A$50))),0) +IFERROR(FILTER('RR4 Player Stats'!AH$3:AH$50, ISNUMBER(SEARCH($A5,'RR4 Player Stats'!$A$3:$A$50))),0) +IFERROR(FILTER('RR5 Player Stats'!AH$3:AH$50, ISNUMBER(SEARCH($A5,'RR5 Player Stats'!$A$3:$A$50)))"&",0)"),31.0) -> 31 | P5: =IFERROR(__xludf.DUMMYFUNCTION("IFERROR(FILTER('RR1 Player Stats'!AI$3:AI$50, ISNUMBER(SEARCH($A5,'RR1 Player Stats'!$A$3:$A$50))),0) +IFERROR(FILTER('RR2 Player Stats'!AI$3:AI$50, ISNUMBER(SEARCH($A5,'RR2 Player Stats'!$A$3:$A$50))),0) +IFERROR(FILTER('RR3 Player Stats'!AI$3:AI$50, ISN"&"UMBER(SEARCH($A5,'RR3 Player Stats'!$A$3:$A$50))),0) +IFERROR(FILTER('RR4 Player Stats'!AI$3:AI$50, ISNUMBER(SEARCH($A5,'RR4 Player Stats'!$A$3:$A$50))),0) +IFERROR(FILTER('RR5 Player Stats'!AI$3:AI$50, ISNUMBER(SEARCH($A5,'RR5 Player Stats'!$A$3:$A$50)))"&",0)"),28.0) -> 28 | Q5: =IFERROR(__xludf.DUMMYFUNCTION("IFERROR(FILTER('RR1 Player Stats'!AJ$3:AJ$50, ISNUMBER(SEARCH($A5,'RR1 Player Stats'!$A$3:$A$50))),0) +IFERROR(FILTER('RR2 Player Stats'!AJ$3:AJ$50, ISNUMBER(SEARCH($A5,'RR2 Player Stats'!$A$3:$A$50))),0) +IFERROR(FILTER('RR3 Player Stats'!AJ$3:AJ$50, ISN"&"UMBER(SEARCH($A5,'RR3 Player Stats'!$A$3:$A$50))),0) +IFERROR(FILTER('RR4 Player Stats'!AJ$3:AJ$50, ISNUMBER(SEARCH($A5,'RR4 Player Stats'!$A$3:$A$50))),0) +IFERROR(FILTER('RR5 Player Stats'!AJ$3:AJ$50, ISNUMBER(SEARCH($A5,'RR5 Player Stats'!$A$3:$A$50)))"&",0)"),5.0) -> 5 | R5: =IFERROR(__xludf.DUMMYFUNCTION("IFERROR(FILTER('RR1 Player Stats'!AK$3:AK$50, ISNUMBER(SEARCH($A5,'RR1 Player Stats'!$A$3:$A$50))),0) +IFERROR(FILTER('RR2 Player Stats'!AK$3:AK$50, ISNUMBER(SEARCH($A5,'RR2 Player Stats'!$A$3:$A$50))),0) +IFERROR(FILTER('RR3 Player Stats'!AK$3:AK$50, ISN"&"UMBER(SEARCH($A5,'RR3 Player Stats'!$A$3:$A$50))),0) +IFERROR(FILTER('RR4 Player Stats'!AK$3:AK$50, ISNUMBER(SEARCH($A5,'RR4 Player Stats'!$A$3:$A$50))),0) +IFERROR(FILTER('RR5 Player Stats'!AK$3:AK$50, ISNUMBER(SEARCH($A5,'RR5 Player Stats'!$A$3:$A$50)))"&",0)"),292.0) -> 292 | S5: =IFERROR(__xludf.DUMMYFUNCTION("IFERROR(FILTER('RR1 Player Stats'!AL$3:AL$50, ISNUMBER(SEARCH($A5,'RR1 Player Stats'!$A$3:$A$50))),0) +IFERROR(FILTER('RR2 Player Stats'!AL$3:AL$50, ISNUMBER(SEARCH($A5,'RR2 Player Stats'!$A$3:$A$50))),0) +IFERROR(FILTER('RR3 Player Stats'!AL$3:AL$50, ISN"&"UMBER(SEARCH($A5,'RR3 Player Stats'!$A$3:$A$50))),0) +IFERROR(FILTER('RR4 Player Stats'!AL$3:AL$50, ISNUMBER(SEARCH($A5,'RR4 Player Stats'!$A$3:$A$50))),0) +IFERROR(FILTER('RR5 Player Stats'!AL$3:AL$50, ISNUMBER(SEARCH($A5,'RR5 Player Stats'!$A$3:$A$50)))"&",0)"),272.0) -> 272 | T5: =IFERROR(__xludf.DUMMYFUNCTION("(IFERROR(FILTER('RR1 Player Stats'!AM$3:AM$50, ISNUMBER(SEARCH($A5,'RR1 Player Stats'!$A$3:$A$50))),0) +IFERROR(FILTER('RR2 Player Stats'!AM$3:AM$50, ISNUMBER(SEARCH($A5,'RR2 Player Stats'!$A$3:$A$50))),0) +IFERROR(FILTER('RR3 Player Stats'!AM$3:AM$50, IS"&"NUMBER(SEARCH($A5,'RR3 Player Stats'!$A$3:$A$50))),0) +IFERROR(FILTER('RR4 Player Stats'!AM$3:AM$50, ISNUMBER(SEARCH($A5,'RR4 Player Stats'!$A$3:$A$50))),0) +IFERROR(FILTER('RR5 Player Stats'!AM$3:AM$50, ISNUMBER(SEARCH($A5,'RR5 Player Stats'!$A$3:$A$50))"&"),0))/B5"),0.59) -> 0.59 | U5: =IFERROR(__xludf.DUMMYFUNCTION("MEDIAN(IFERROR(FILTER('RR1 Player Stats'!AH$3:AH$50, ISNUMBER(SEARCH($A5,'RR1 Player Stats'!$A$3:$A$50))),0),IFERROR(FILTER('RR2 Player Stats'!AH$3:AH$50, ISNUMBER(SEARCH($A5,'RR2 Player Stats'!$A$3:$A$50))),0),IFERROR(FILTER('RR3 Player Stats'!AH$3:AH$50"&", ISNUMBER(SEARCH($A5,'RR3 Player Stats'!$A$3:$A$50))),0),IFERROR(FILTER('RR4 Player Stats'!AH$3:AH$50, ISNUMBER(SEARCH($A5,'RR4 Player Stats'!$A$3:$A$50))),0),IFERROR(FILTER('RR5 Player Stats'!AH$3:AH$50, ISNUMBER(SEARCH($A5,'RR5 Player Stats'!$A$3:$A$50"&"))),0))"),4.0) -> 4 | V5: =IFERROR(__xludf.DUMMYFUNCTION("MEDIAN(IFERROR(FILTER('RR1 Player Stats'!AI$3:AI$50, ISNUMBER(SEARCH($A5,'RR1 Player Stats'!$A$3:$A$50))),0),IFERROR(FILTER('RR2 Player Stats'!AI$3:AI$50, ISNUMBER(SEARCH($A5,'RR2 Player Stats'!$A$3:$A$50))),0),IFERROR(FILTER('RR3 Player Stats'!AI$3:AI$50"&", ISNUMBER(SEARCH($A5,'RR3 Player Stats'!$A$3:$A$50))),0),IFERROR(FILTER('RR4 Player Stats'!AI$3:AI$50, ISNUMBER(SEARCH($A5,'RR4 Player Stats'!$A$3:$A$50))),0),IFERROR(FILTER('RR5 Player Stats'!AI$3:AI$50, ISNUMBER(SEARCH($A5,'RR5 Player Stats'!$A$3:$A$50"&"))),0))"),5.0) -> 5 | W5: =IFERROR(__xludf.DUMMYFUNCTION("MEDIAN(IFERROR(FILTER('RR1 Player Stats'!AJ$3:AJ$50, ISNUMBER(SEARCH($A5,'RR1 Player Stats'!$A$3:$A$50))),0),IFERROR(FILTER('RR2 Player Stats'!AJ$3:AJ$50, ISNUMBER(SEARCH($A5,'RR2 Player Stats'!$A$3:$A$50))),0),IFERROR(FILTER('RR3 Player Stats'!AJ$3:AJ$50"&", ISNUMBER(SEARCH($A5,'RR3 Player Stats'!$A$3:$A$50))),0),IFERROR(FILTER('RR4 Player Stats'!AJ$3:AJ$50, ISNUMBER(SEARCH($A5,'RR4 Player Stats'!$A$3:$A$50))),0),IFERROR(FILTER('RR5 Player Stats'!AJ$3:AJ$50, ISNUMBER(SEARCH($A5,'RR5 Player Stats'!$A$3:$A$50"&"))),0))"),1.0) -> 1 | X5: =IFERROR(__xludf.DUMMYFUNCTION("MEDIAN(IFERROR(FILTER('RR1 Player Stats'!AK$3:AK$50, ISNUMBER(SEARCH($A5,'RR1 Player Stats'!$A$3:$A$50))),0),IFERROR(FILTER('RR2 Player Stats'!AK$3:AK$50, ISNUMBER(SEARCH($A5,'RR2 Player Stats'!$A$3:$A$50))),0),IFERROR(FILTER('RR3 Player Stats'!AK$3:AK$50"&", ISNUMBER(SEARCH($A5,'RR3 Player Stats'!$A$3:$A$50))),0),IFERROR(FILTER('RR4 Player Stats'!AK$3:AK$50, ISNUMBER(SEARCH($A5,'RR4 Player Stats'!$A$3:$A$50))),0),IFERROR(FILTER('RR5 Player Stats'!AK$3:AK$50, ISNUMBER(SEARCH($A5,'RR5 Player Stats'!$A$3:$A$50"&"))),0))"),64.0) -> 64 | Y5: =IFERROR(__xludf.DUMMYFUNCTION("MEDIAN(IFERROR(FILTER('RR1 Player Stats'!AL$3:AL$50, ISNUMBER(SEARCH($A5,'RR1 Player Stats'!$A$3:$A$50))),0),IFERROR(FILTER('RR2 Player Stats'!AL$3:AL$50, ISNUMBER(SEARCH($A5,'RR2 Player Stats'!$A$3:$A$50))),0),IFERROR(FILTER('RR3 Player Stats'!AL$3:AL$50"&", ISNUMBER(SEARCH($A5,'RR3 Player Stats'!$A$3:$A$50))),0),IFERROR(FILTER('RR4 Player Stats'!AL$3:AL$50, ISNUMBER(SEARCH($A5,'RR4 Player Stats'!$A$3:$A$50))),0),IFERROR(FILTER('RR5 Player Stats'!AL$3:AL$50, ISNUMBER(SEARCH($A5,'RR5 Player Stats'!$A$3:$A$50"&"))),0))"),60.0) -> 60 | Z5: =IFERROR(__xludf.DUMMYFUNCTION("MEDIAN(IFERROR(FILTER('RR1 Player Stats'!AM$3:AM$50, ISNUMBER(SEARCH($A5,'RR1 Player Stats'!$A$3:$A$50))),0),IFERROR(FILTER('RR2 Player Stats'!AM$3:AM$50, ISNUMBER(SEARCH($A5,'RR2 Player Stats'!$A$3:$A$50))),0),IFERROR(FILTER('RR3 Player Stats'!AM$3:AM$50"&", ISNUMBER(SEARCH($A5,'RR3 Player Stats'!$A$3:$A$50))),0),IFERROR(FILTER('RR4 Player Stats'!AM$3:AM$50, ISNUMBER(SEARCH($A5,'RR4 Player Stats'!$A$3:$A$50))),0),IFERROR(FILTER('RR5 Player Stats'!AM$3:AM$50, ISNUMBER(SEARCH($A5,'RR5 Player Stats'!$A$3:$A$50"&"))),0))"),0.6) -> 0.6
A6: [3.5] Ryan E | B6: =COUNTIF('RR1 Player Stats'!$A$3:$A$50,$A6)+COUNTIF('RR2 Player Stats'!$A$3:$A$50,$A6)+COUNTIF('RR3 Player Stats'!$A$3:$A$50,$A6)+COUNTIF('RR4 Player Stats'!$A$3:$A$50,$A6)+COUNTIF('RR5 Player Stats'!$A$3:$A$50,$A6) -> 5 | C6: =IFERROR(__xludf.DUMMYFUNCTION("IFERROR(FILTER('RR1 Player Stats'!V$3:V$50, ISNUMBER(SEARCH($A6,'RR1 Player Stats'!$A$3:$A$50))),0) +IFERROR(FILTER('RR2 Player Stats'!V$3:V$50, ISNUMBER(SEARCH($A6,'RR2 Player Stats'!$A$3:$A$50))),0) +IFERROR(FILTER('RR3 Player Stats'!V$3:V$50, ISNUMBER("&"SEARCH($A6,'RR3 Player Stats'!$A$3:$A$50))),0) +IFERROR(FILTER('RR4 Player Stats'!V$3:V$50, ISNUMBER(SEARCH($A6,'RR4 Player Stats'!$A$3:$A$50))),0) +IFERROR(FILTER('RR5 Player Stats'!V$3:V$50, ISNUMBER(SEARCH($A6,'RR5 Player Stats'!$A$3:$A$50))),0)"),18.0) -> 18 | D6: =IFERROR(__xludf.DUMMYFUNCTION("IFERROR(FILTER('RR1 Player Stats'!W$3:W$50, ISNUMBER(SEARCH($A6,'RR1 Player Stats'!$A$3:$A$50))),0) +IFERROR(FILTER('RR2 Player Stats'!W$3:W$50, ISNUMBER(SEARCH($A6,'RR2 Player Stats'!$A$3:$A$50))),0) +IFERROR(FILTER('RR3 Player Stats'!W$3:W$50, ISNUMBER("&"SEARCH($A6,'RR3 Player Stats'!$A$3:$A$50))),0) +IFERROR(FILTER('RR4 Player Stats'!W$3:W$50, ISNUMBER(SEARCH($A6,'RR4 Player Stats'!$A$3:$A$50))),0) +IFERROR(FILTER('RR5 Player Stats'!W$3:W$50, ISNUMBER(SEARCH($A6,'RR5 Player Stats'!$A$3:$A$50))),0)"),20.0) -> 20 | E6: =IFERROR(__xludf.DUMMYFUNCTION("IFERROR(FILTER('RR1 Player Stats'!X$3:X$50, ISNUMBER(SEARCH($A6,'RR1 Player Stats'!$A$3:$A$50))),0) +IFERROR(FILTER('RR2 Player Stats'!X$3:X$50, ISNUMBER(SEARCH($A6,'RR2 Player Stats'!$A$3:$A$50))),0) +IFERROR(FILTER('RR3 Player Stats'!X$3:X$50, ISNUMBER("&"SEARCH($A6,'RR3 Player Stats'!$A$3:$A$50))),0) +IFERROR(FILTER('RR4 Player Stats'!X$3:X$50, ISNUMBER(SEARCH($A6,'RR4 Player Stats'!$A$3:$A$50))),0) +IFERROR(FILTER('RR5 Player Stats'!X$3:X$50, ISNUMBER(SEARCH($A6,'RR5 Player Stats'!$A$3:$A$50))),0)"),7.0) -> 7 | F6: =IFERROR(__xludf.DUMMYFUNCTION("IFERROR(FILTER('RR1 Player Stats'!Y$3:Y$50, ISNUMBER(SEARCH($A6,'RR1 Player Stats'!$A$3:$A$50))),0) +IFERROR(FILTER('RR2 Player Stats'!Y$3:Y$50, ISNUMBER(SEARCH($A6,'RR2 Player Stats'!$A$3:$A$50))),0) +IFERROR(FILTER('RR3 Player Stats'!Y$3:Y$50, ISNUMBER("&"SEARCH($A6,'RR3 Player Stats'!$A$3:$A$50))),0) +IFERROR(FILTER('RR4 Player Stats'!Y$3:Y$50, ISNUMBER(SEARCH($A6,'RR4 Player Stats'!$A$3:$A$50))),0) +IFERROR(FILTER('RR5 Player Stats'!Y$3:Y$50, ISNUMBER(SEARCH($A6,'RR5 Player Stats'!$A$3:$A$50))),0)"),192.0) -> 192 | G6: =IFERROR(__xludf.DUMMYFUNCTION("IFERROR(FILTER('RR1 Player Stats'!Z$3:Z$50, ISNUMBER(SEARCH($A6,'RR1 Player Stats'!$A$3:$A$50))),0) +IFERROR(FILTER('RR2 Player Stats'!Z$3:Z$50, ISNUMBER(SEARCH($A6,'RR2 Player Stats'!$A$3:$A$50))),0) +IFERROR(FILTER('RR3 Player Stats'!Z$3:Z$50, ISNUMBER("&"SEARCH($A6,'RR3 Player Stats'!$A$3:$A$50))),0) +IFERROR(FILTER('RR4 Player Stats'!Z$3:Z$50, ISNUMBER(SEARCH($A6,'RR4 Player Stats'!$A$3:$A$50))),0) +IFERROR(FILTER('RR5 Player Stats'!Z$3:Z$50, ISNUMBER(SEARCH($A6,'RR5 Player Stats'!$A$3:$A$50))),0)"),164.0) -> 164 | H6: =IFERROR(__xludf.DUMMYFUNCTION("(IFERROR(FILTER('RR1 Player Stats'!AA$3:AA$50, ISNUMBER(SEARCH($A6,'RR1 Player Stats'!$A$3:$A$50))),0) +IFERROR(FILTER('RR2 Player Stats'!AA$3:AA$50, ISNUMBER(SEARCH($A6,'RR2 Player Stats'!$A$3:$A$50))),0) +IFERROR(FILTER('RR3 Player Stats'!AA$3:AA$50, IS"&"NUMBER(SEARCH($A6,'RR3 Player Stats'!$A$3:$A$50))),0) +IFERROR(FILTER('RR4 Player Stats'!AA$3:AA$50, ISNUMBER(SEARCH($A6,'RR4 Player Stats'!$A$3:$A$50))),0) +IFERROR(FILTER('RR5 Player Stats'!AA$3:AA$50, ISNUMBER(SEARCH($A6,'RR5 Player Stats'!$A$3:$A$50))"&"),0))/5"),0.634) -> 0.634 | I6: =IFERROR(__xludf.DUMMYFUNCTION("IFERROR(FILTER('RR1 Player Stats'!AB$3:AB$50, ISNUMBER(SEARCH($A6,'RR1 Player Stats'!$A$3:$A$50))),0) +IFERROR(FILTER('RR2 Player Stats'!AB$3:AB$50, ISNUMBER(SEARCH($A6,'RR2 Player Stats'!$A$3:$A$50))),0) +IFERROR(FILTER('RR3 Player Stats'!AB$3:AB$50, ISN"&"UMBER(SEARCH($A6,'RR3 Player Stats'!$A$3:$A$50))),0) +IFERROR(FILTER('RR4 Player Stats'!AB$3:AB$50, ISNUMBER(SEARCH($A6,'RR4 Player Stats'!$A$3:$A$50))),0) +IFERROR(FILTER('RR5 Player Stats'!AB$3:AB$50, ISNUMBER(SEARCH($A6,'RR5 Player Stats'!$A$3:$A$50)))"&",0)"),11.0) -> 11 | J6: =IFERROR(__xludf.DUMMYFUNCTION("IFERROR(FILTER('RR1 Player Stats'!AC$3:AC$50, ISNUMBER(SEARCH($A6,'RR1 Player Stats'!$A$3:$A$50))),0) +IFERROR(FILTER('RR2 Player Stats'!AC$3:AC$50, ISNUMBER(SEARCH($A6,'RR2 Player Stats'!$A$3:$A$50))),0) +IFERROR(FILTER('RR3 Player Stats'!AC$3:AC$50, ISN"&"UMBER(SEARCH($A6,'RR3 Player Stats'!$A$3:$A$50))),0) +IFERROR(FILTER('RR4 Player Stats'!AC$3:AC$50, ISNUMBER(SEARCH($A6,'RR4 Player Stats'!$A$3:$A$50))),0) +IFERROR(FILTER('RR5 Player Stats'!AC$3:AC$50, ISNUMBER(SEARCH($A6,'RR5 Player Stats'!$A$3:$A$50)))"&",0)"),7.0) -> 7 | K6: =IFERROR(__xludf.DUMMYFUNCTION("IFERROR(FILTER('RR1 Player Stats'!AD$3:AD$50, ISNUMBER(SEARCH($A6,'RR1 Player Stats'!$A$3:$A$50))),0) +IFERROR(FILTER('RR2 Player Stats'!AD$3:AD$50, ISNUMBER(SEARCH($A6,'RR2 Player Stats'!$A$3:$A$50))),0) +IFERROR(FILTER('RR3 Player Stats'!AD$3:AD$50, ISN"&"UMBER(SEARCH($A6,'RR3 Player Stats'!$A$3:$A$50))),0) +IFERROR(FILTER('RR4 Player Stats'!AD$3:AD$50, ISNUMBER(SEARCH($A6,'RR4 Player Stats'!$A$3:$A$50))),0) +IFERROR(FILTER('RR5 Player Stats'!AD$3:AD$50, ISNUMBER(SEARCH($A6,'RR5 Player Stats'!$A$3:$A$50)))"&",0)"),0.0) -> 0 | L6: =IFERROR(__xludf.DUMMYFUNCTION("IFERROR(FILTER('RR1 Player Stats'!AE$3:AE$50, ISNUMBER(SEARCH($A6,'RR1 Player Stats'!$A$3:$A$50))),0) +IFERROR(FILTER('RR2 Player Stats'!AE$3:AE$50, ISNUMBER(SEARCH($A6,'RR2 Player Stats'!$A$3:$A$50))),0) +IFERROR(FILTER('RR3 Player Stats'!AE$3:AE$50, ISN"&"UMBER(SEARCH($A6,'RR3 Player Stats'!$A$3:$A$50))),0) +IFERROR(FILTER('RR4 Player Stats'!AE$3:AE$50, ISNUMBER(SEARCH($A6,'RR4 Player Stats'!$A$3:$A$50))),0) +IFERROR(FILTER('RR5 Player Stats'!AE$3:AE$50, ISNUMBER(SEARCH($A6,'RR5 Player Stats'!$A$3:$A$50)))"&",0)"),86.0) -> 86 | M6: =IFERROR(__xludf.DUMMYFUNCTION("IFERROR(FILTER('RR1 Player Stats'!AF$3:AF$50, ISNUMBER(SEARCH($A6,'RR1 Player Stats'!$A$3:$A$50))),0) +IFERROR(FILTER('RR2 Player Stats'!AF$3:AF$50, ISNUMBER(SEARCH($A6,'RR2 Player Stats'!$A$3:$A$50))),0) +IFERROR(FILTER('RR3 Player Stats'!AF$3:AF$50, ISN"&"UMBER(SEARCH($A6,'RR3 Player Stats'!$A$3:$A$50))),0) +IFERROR(FILTER('RR4 Player Stats'!AF$3:AF$50, ISNUMBER(SEARCH($A6,'RR4 Player Stats'!$A$3:$A$50))),0) +IFERROR(FILTER('RR5 Player Stats'!AF$3:AF$50, ISNUMBER(SEARCH($A6,'RR5 Player Stats'!$A$3:$A$50)))"&",0)"),86.0) -> 86 | N6: =IFERROR(__xludf.DUMMYFUNCTION("(IFERROR(FILTER('RR1 Player Stats'!AG$3:AG$50, ISNUMBER(SEARCH($A6,'RR1 Player Stats'!$A$3:$A$50))),0) +IFERROR(FILTER('RR2 Player Stats'!AG$3:AG$50, ISNUMBER(SEARCH($A6,'RR2 Player Stats'!$A$3:$A$50))),0) +IFERROR(FILTER('RR3 Player Stats'!AG$3:AG$50, IS"&"NUMBER(SEARCH($A6,'RR3 Player Stats'!$A$3:$A$50))),0) +IFERROR(FILTER('RR4 Player Stats'!AG$3:AG$50, ISNUMBER(SEARCH($A6,'RR4 Player Stats'!$A$3:$A$50))),0) +IFERROR(FILTER('RR5 Player Stats'!AG$3:AG$50, ISNUMBER(SEARCH($A6,'RR5 Player Stats'!$A$3:$A$50))"&"),0))/5"),0.45199999999999996) -> 0.452 | O6: =IFERROR(__xludf.DUMMYFUNCTION("IFERROR(FILTER('RR1 Player Stats'!AH$3:AH$50, ISNUMBER(SEARCH($A6,'RR1 Player Stats'!$A$3:$A$50))),0) +IFERROR(FILTER('RR2 Player Stats'!AH$3:AH$50, ISNUMBER(SEARCH($A6,'RR2 Player Stats'!$A$3:$A$50))),0) +IFERROR(FILTER('RR3 Player Stats'!AH$3:AH$50, ISN"&"UMBER(SEARCH($A6,'RR3 Player Stats'!$A$3:$A$50))),0) +IFERROR(FILTER('RR4 Player Stats'!AH$3:AH$50, ISNUMBER(SEARCH($A6,'RR4 Player Stats'!$A$3:$A$50))),0) +IFERROR(FILTER('RR5 Player Stats'!AH$3:AH$50, ISNUMBER(SEARCH($A6,'RR5 Player Stats'!$A$3:$A$50)))"&",0)"),29.0) -> 29 | P6: =IFERROR(__xludf.DUMMYFUNCTION("IFERROR(FILTER('RR1 Player Stats'!AI$3:AI$50, ISNUMBER(SEARCH($A6,'RR1 Player Stats'!$A$3:$A$50))),0) +IFERROR(FILTER('RR2 Player Stats'!AI$3:AI$50, ISNUMBER(SEARCH($A6,'RR2 Player Stats'!$A$3:$A$50))),0) +IFERROR(FILTER('RR3 Player Stats'!AI$3:AI$50, ISN"&"UMBER(SEARCH($A6,'RR3 Player Stats'!$A$3:$A$50))),0) +IFERROR(FILTER('RR4 Player Stats'!AI$3:AI$50, ISNUMBER(SEARCH($A6,'RR4 Player Stats'!$A$3:$A$50))),0) +IFERROR(FILTER('RR5 Player Stats'!AI$3:AI$50, ISNUMBER(SEARCH($A6,'RR5 Player Stats'!$A$3:$A$50)))"&",0)"),27.0) -> 27 | Q6: =IFERROR(__xludf.DUMMYFUNCTION("IFERROR(FILTER('RR1 Player Stats'!AJ$3:AJ$50, ISNUMBER(SEARCH($A6,'RR1 Player Stats'!$A$3:$A$50))),0) +IFERROR(FILTER('RR2 Player Stats'!AJ$3:AJ$50, ISNUMBER(SEARCH($A6,'RR2 Player Stats'!$A$3:$A$50))),0) +IFERROR(FILTER('RR3 Player Stats'!AJ$3:AJ$50, ISN"&"UMBER(SEARCH($A6,'RR3 Player Stats'!$A$3:$A$50))),0) +IFERROR(FILTER('RR4 Player Stats'!AJ$3:AJ$50, ISNUMBER(SEARCH($A6,'RR4 Player Stats'!$A$3:$A$50))),0) +IFERROR(FILTER('RR5 Player Stats'!AJ$3:AJ$50, ISNUMBER(SEARCH($A6,'RR5 Player Stats'!$A$3:$A$50)))"&",0)"),7.0) -> 7 | R6: =IFERROR(__xludf.DUMMYFUNCTION("IFERROR(FILTER('RR1 Player Stats'!AK$3:AK$50, ISNUMBER(SEARCH($A6,'RR1 Player Stats'!$A$3:$A$50))),0) +IFERROR(FILTER('RR2 Player Stats'!AK$3:AK$50, ISNUMBER(SEARCH($A6,'RR2 Player Stats'!$A$3:$A$50))),0) +IFERROR(FILTER('RR3 Player Stats'!AK$3:AK$50, ISN"&"UMBER(SEARCH($A6,'RR3 Player Stats'!$A$3:$A$50))),0) +IFERROR(FILTER('RR4 Player Stats'!AK$3:AK$50, ISNUMBER(SEARCH($A6,'RR4 Player Stats'!$A$3:$A$50))),0) +IFERROR(FILTER('RR5 Player Stats'!AK$3:AK$50, ISNUMBER(SEARCH($A6,'RR5 Player Stats'!$A$3:$A$50)))"&",0)"),278.0) -> 278 | S6: =IFERROR(__xludf.DUMMYFUNCTION("IFERROR(FILTER('RR1 Player Stats'!AL$3:AL$50, ISNUMBER(SEARCH($A6,'RR1 Player Stats'!$A$3:$A$50))),0) +IFERROR(FILTER('RR2 Player Stats'!AL$3:AL$50, ISNUMBER(SEARCH($A6,'RR2 Player Stats'!$A$3:$A$50))),0) +IFERROR(FILTER('RR3 Player Stats'!AL$3:AL$50, ISN"&"UMBER(SEARCH($A6,'RR3 Player Stats'!$A$3:$A$50))),0) +IFERROR(FILTER('RR4 Player Stats'!AL$3:AL$50, ISNUMBER(SEARCH($A6,'RR4 Player Stats'!$A$3:$A$50))),0) +IFERROR(FILTER('RR5 Player Stats'!AL$3:AL$50, ISNUMBER(SEARCH($A6,'RR5 Player Stats'!$A$3:$A$50)))"&",0)"),250.0) -> 250 | T6: =IFERROR(__xludf.DUMMYFUNCTION("(IFERROR(FILTER('RR1 Player Stats'!AM$3:AM$50, ISNUMBER(SEARCH($A6,'RR1 Player Stats'!$A$3:$A$50))),0) +IFERROR(FILTER('RR2 Player Stats'!AM$3:AM$50, ISNUMBER(SEARCH($A6,'RR2 Player Stats'!$A$3:$A$50))),0) +IFERROR(FILTER('RR3 Player Stats'!AM$3:AM$50, IS"&"NUMBER(SEARCH($A6,'RR3 Player Stats'!$A$3:$A$50))),0) +IFERROR(FILTER('RR4 Player Stats'!AM$3:AM$50, ISNUMBER(SEARCH($A6,'RR4 Player Stats'!$A$3:$A$50))),0) +IFERROR(FILTER('RR5 Player Stats'!AM$3:AM$50, ISNUMBER(SEARCH($A6,'RR5 Player Stats'!$A$3:$A$50))"&"),0))/B6"),0.5599999999999999) -> 0.56 | U6: =IFERROR(__xludf.DUMMYFUNCTION("MEDIAN(IFERROR(FILTER('RR1 Player Stats'!AH$3:AH$50, ISNUMBER(SEARCH($A6,'RR1 Player Stats'!$A$3:$A$50))),0),IFERROR(FILTER('RR2 Player Stats'!AH$3:AH$50, ISNUMBER(SEARCH($A6,'RR2 Player Stats'!$A$3:$A$50))),0),IFERROR(FILTER('RR3 Player Stats'!AH$3:AH$50"&", ISNUMBER(SEARCH($A6,'RR3 Player Stats'!$A$3:$A$50))),0),IFERROR(FILTER('RR4 Player Stats'!AH$3:AH$50, ISNUMBER(SEARCH($A6,'RR4 Player Stats'!$A$3:$A$50))),0),IFERROR(FILTER('RR5 Player Stats'!AH$3:AH$50, ISNUMBER(SEARCH($A6,'RR5 Player Stats'!$A$3:$A$50"&"))),0))"),5.0) -> 5 | V6: =IFERROR(__xludf.DUMMYFUNCTION("MEDIAN(IFERROR(FILTER('RR1 Player Stats'!AI$3:AI$50, ISNUMBER(SEARCH($A6,'RR1 Player Stats'!$A$3:$A$50))),0),IFERROR(FILTER('RR2 Player Stats'!AI$3:AI$50, ISNUMBER(SEARCH($A6,'RR2 Player Stats'!$A$3:$A$50))),0),IFERROR(FILTER('RR3 Player Stats'!AI$3:AI$50"&", ISNUMBER(SEARCH($A6,'RR3 Player Stats'!$A$3:$A$50))),0),IFERROR(FILTER('RR4 Player Stats'!AI$3:AI$50, ISNUMBER(SEARCH($A6,'RR4 Player Stats'!$A$3:$A$50))),0),IFERROR(FILTER('RR5 Player Stats'!AI$3:AI$50, ISNUMBER(SEARCH($A6,'RR5 Player Stats'!$A$3:$A$50"&"))),0))"),6.0) -> 6 | W6: =IFERROR(__xludf.DUMMYFUNCTION("MEDIAN(IFERROR(FILTER('RR1 Player Stats'!AJ$3:AJ$50, ISNUMBER(SEARCH($A6,'RR1 Player Stats'!$A$3:$A$50))),0),IFERROR(FILTER('RR2 Player Stats'!AJ$3:AJ$50, ISNUMBER(SEARCH($A6,'RR2 Player Stats'!$A$3:$A$50))),0),IFERROR(FILTER('RR3 Player Stats'!AJ$3:AJ$50"&", ISNUMBER(SEARCH($A6,'RR3 Player Stats'!$A$3:$A$50))),0),IFERROR(FILTER('RR4 Player Stats'!AJ$3:AJ$50, ISNUMBER(SEARCH($A6,'RR4 Player Stats'!$A$3:$A$50))),0),IFERROR(FILTER('RR5 Player Stats'!AJ$3:AJ$50, ISNUMBER(SEARCH($A6,'RR5 Player Stats'!$A$3:$A$50"&"))),0))"),1.0) -> 1 | X6: =IFERROR(__xludf.DUMMYFUNCTION("MEDIAN(IFERROR(FILTER('RR1 Player Stats'!AK$3:AK$50, ISNUMBER(SEARCH($A6,'RR1 Player Stats'!$A$3:$A$50))),0),IFERROR(FILTER('RR2 Player Stats'!AK$3:AK$50, ISNUMBER(SEARCH($A6,'RR2 Player Stats'!$A$3:$A$50))),0),IFERROR(FILTER('RR3 Player Stats'!AK$3:AK$50"&", ISNUMBER(SEARCH($A6,'RR3 Player Stats'!$A$3:$A$50))),0),IFERROR(FILTER('RR4 Player Stats'!AK$3:AK$50, ISNUMBER(SEARCH($A6,'RR4 Player Stats'!$A$3:$A$50))),0),IFERROR(FILTER('RR5 Player Stats'!AK$3:AK$50, ISNUMBER(SEARCH($A6,'RR5 Player Stats'!$A$3:$A$50"&"))),0))"),56.0) -> 56 | Y6: =IFERROR(__xludf.DUMMYFUNCTION("MEDIAN(IFERROR(FILTER('RR1 Player Stats'!AL$3:AL$50, ISNUMBER(SEARCH($A6,'RR1 Player Stats'!$A$3:$A$50))),0),IFERROR(FILTER('RR2 Player Stats'!AL$3:AL$50, ISNUMBER(SEARCH($A6,'RR2 Player Stats'!$A$3:$A$50))),0),IFERROR(FILTER('RR3 Player Stats'!AL$3:AL$50"&", ISNUMBER(SEARCH($A6,'RR3 Player Stats'!$A$3:$A$50))),0),IFERROR(FILTER('RR4 Player Stats'!AL$3:AL$50, ISNUMBER(SEARCH($A6,'RR4 Player Stats'!$A$3:$A$50))),0),IFERROR(FILTER('RR5 Player Stats'!AL$3:AL$50, ISNUMBER(SEARCH($A6,'RR5 Player Stats'!$A$3:$A$50"&"))),0))"),52.0) -> 52 | Z6: =IFERROR(__xludf.DUMMYFUNCTION("MEDIAN(IFERROR(FILTER('RR1 Player Stats'!AM$3:AM$50, ISNUMBER(SEARCH($A6,'RR1 Player Stats'!$A$3:$A$50))),0),IFERROR(FILTER('RR2 Player Stats'!AM$3:AM$50, ISNUMBER(SEARCH($A6,'RR2 Player Stats'!$A$3:$A$50))),0),IFERROR(FILTER('RR3 Player Stats'!AM$3:AM$50"&", ISNUMBER(SEARCH($A6,'RR3 Player Stats'!$A$3:$A$50))),0),IFERROR(FILTER('RR4 Player Stats'!AM$3:AM$50, ISNUMBER(SEARCH($A6,'RR4 Player Stats'!$A$3:$A$50))),0),IFERROR(FILTER('RR5 Player Stats'!AM$3:AM$50, ISNUMBER(SEARCH($A6,'RR5 Player Stats'!$A$3:$A$50"&"))),0))"),0.55) -> 0.55
