Workbook

Sheet Round Robin Subject Scores
A1: Round Robin Subject Scores
A3: Score = (# Correct Tossups) - (# Penalized Tossups) + 0.5 * (# of Correct Bonuses)
A5: Team Name: | B5: Cupertino A | D5: Team Members: | E5: {=IF(ISBLANK(B5),"Choose team",VLOOKUP(B5,'Check-in Import'!B2:I100,{4,5,6,7,8},false))} -> Aaditya Karnataki | F5: Jake Wang | G5: Minseo Park | H5: Aditi Gargeshwari | I5: Namita Gaidhani
A6: Subject: | B6: Math | D6: Score: | E6: =IFERROR(__xludf.DUMMYFUNCTION("IF(ISBLANK($B$6),""Choose Subject"",IFERROR(SUM(ARRAYFORMULA(INDEX(SPLIT(FILTER({FILTER('Round Robin Matchups'!$M$2:$M100,'Round Robin Matchups'!$B$2:$B100=$B$5);FILTER('Round Robin Matchups'!$R$2:$R100,'Round Robin Matchups'!$C$2:$C100=$B$5)},{FILTER('Ro"&"und Robin Matchups'!$M$2:$M100,'Round Robin Matchups'!$B$2:$B100=$B$5);FILTER('Round Robin Matchups'!$R$2:$R100,'Round Robin Matchups'!$C$2:$C100=$B$5)}<>""""),"",""),0,IF($B$6=""Biology"",1,IF($B$6=""Chemistry"",2,IF($B$6=""Earth & Space"",3,IF($B$6=""En"&"ergy"",4,IF($B$6=""Math"",5,6)))))))),))"),1.5) -> 1.5 | F6: =IFERROR(__xludf.DUMMYFUNCTION("IF(ISBLANK($B$6),""Choose Subject"",IFERROR(SUM(ARRAYFORMULA(INDEX(SPLIT(FILTER({FILTER('Round Robin Matchups'!$M$2:$M100,'Round Robin Matchups'!$B$2:$B100=$B$5);FILTER('Round Robin Matchups'!$R$2:$R100,'Round Robin Matchups'!$C$2:$C100=$B$5)},{FILTER('Ro"&"und Robin Matchups'!$M$2:$M100,'Round Robin Matchups'!$B$2:$B100=$B$5);FILTER('Round Robin Matchups'!$R$2:$R100,'Round Robin Matchups'!$C$2:$C100=$B$5)}<>""""),"",""),1,IF($B$6=""Biology"",1,IF($B$6=""Chemistry"",2,IF($B$6=""Earth & Space"",3,IF($B$6=""En"&"ergy"",4,IF($B$6=""Math"",5,6)))))))),))"),0.0) -> 0 | G6: =IFERROR(__xludf.DUMMYFUNCTION("IF(ISBLANK($B$6),""Choose Subject"",IFERROR(SUM(ARRAYFORMULA(INDEX(SPLIT(FILTER({FILTER('Round Robin Matchups'!$M$2:$M100,'Round Robin Matchups'!$B$2:$B100=$B$5);FILTER('Round Robin Matchups'!$R$2:$R100,'Round Robin Matchups'!$C$2:$C100=$B$5)},{FILTER('Ro"&"und Robin Matchups'!$M$2:$M100,'Round Robin Matchups'!$B$2:$B100=$B$5);FILTER('Round Robin Matchups'!$R$2:$R100,'Round Robin Matchups'!$C$2:$C100=$B$5)}<>""""),"",""),2,IF($B$6=""Biology"",1,IF($B$6=""Chemistry"",2,IF($B$6=""Earth & Space"",3,IF($B$6=""En"&"ergy"",4,IF($B$6=""Math"",5,6)))))))),))"),0.0) -> 0 | H6: =IFERROR(__xludf.DUMMYFUNCTION("IF(ISBLANK($B$6),""Choose Subject"",IFERROR(SUM(ARRAYFORMULA(INDEX(SPLIT(FILTER({FILTER('Round Robin Matchups'!$M$2:$M100,'Round Robin Matchups'!$B$2:$B100=$B$5);FILTER('Round Robin Matchups'!$R$2:$R100,'Round Robin Matchups'!$C$2:$C100=$B$5)},{FILTER('Ro"&"und Robin Matchups'!$M$2:$M100,'Round Robin Matchups'!$B$2:$B100=$B$5);FILTER('Round Robin Matchups'!$R$2:$R100,'Round Robin Matchups'!$C$2:$C100=$B$5)}<>""""),"",""),3,IF($B$6=""Biology"",1,IF($B$6=""Chemistry"",2,IF($B$6=""Earth & Space"",3,IF($B$6=""En"&"ergy"",4,IF($B$6=""Math"",5,6)))))))),))"),0.0) -> 0 | I6: =IFERROR(__xludf.DUMMYFUNCTION("IF(ISBLANK($B$6),""Choose Subject"",IFERROR(SUM(ARRAYFORMULA(INDEX(SPLIT(FILTER({FILTER('Round Robin Matchups'!$M$2:$M100,'Round Robin Matchups'!$B$2:$B100=$B$5);FILTER('Round Robin Matchups'!$R$2:$R100,'Round Robin Matchups'!$C$2:$C100=$B$5)},{FILTER('Ro"&"und Robin Matchups'!$M$2:$M100,'Round Robin Matchups'!$B$2:$B100=$B$5);FILTER('Round Robin Matchups'!$R$2:$R100,'Round Robin Matchups'!$C$2:$C100=$B$5)}<>""""),"",""),4,IF($B$6=""Biology"",1,IF($B$6=""Chemistry"",2,IF($B$6=""Earth & Space"",3,IF($B$6=""En"&"ergy"",4,IF($B$6=""Math"",5,6)))))))),))"),0.0) -> 0

Sheet Round Robin Individual Rankings
A1: 20 | B1: Biology | F1: Chemistry | J1: Earth & Space | N1: Energy | R1: Math | V1: Physics
A2: {=RANK(INDIRECT("C2:C"&($A$1+1)),C$2:C$21)} -> 1 | B2: =IFERROR(__xludf.DUMMYFUNCTION("QUERY(INDIRECT(B1&""!K2:M""),""select M order by L desc limit ""&$A$1)"),"Theenash Sengupta") -> Theenash Sengupta | C2: =IFERROR(__xludf.DUMMYFUNCTION("QUERY(INDIRECT(B1&""!K2:M""),""select L order by L desc limit ""&$A$1)"),21.0) -> 21 | E2: {=RANK(INDIRECT("G2:G"&($A$1+1)),G$2:G$21)} -> 1 | F2: =IFERROR(__xludf.DUMMYFUNCTION("QUERY(INDIRECT(F1&""!K2:M""),""select M order by L desc limit ""&$A$1)"),"Annie Xu") -> Annie Xu | G2: =IFERROR(__xludf.DUMMYFUNCTION("QUERY(INDIRECT(F1&""!K2:M""),""select L order by L desc limit ""&$A$1)"),19.0) -> 19 | I2: {=RANK(INDIRECT("K2:K"&($A$1+1)),K$2:K$21)} -> 1 | J2: =IFERROR(__xludf.DUMMYFUNCTION("QUERY(INDIRECT(J1&""!K2:M""),""select M order by L desc limit ""&$A$1)"),"Roshan Annamalai") -> Roshan Annamalai | K2: =IFERROR(__xludf.DUMMYFUNCTION("QUERY(INDIRECT(J1&""!K2:M""),""select L order by L desc limit ""&$A$1)"),15.5) -> 15.5 | M2: {=RANK(INDIRECT("O2:O"&($A$1+1)),O$2:O$21)} -> 1 | N2: =IFERROR(__xludf.DUMMYFUNCTION("QUERY(INDIRECT(N1&""!K2:M""),""select M order by L desc limit ""&$A$1)"),"Aatreyo Bhattacharyya ") -> Aatreyo Bhattacharyya | O2: =IFERROR(__xludf.DUMMYFUNCTION("QUERY(INDIRECT(N1&""!K2:M""),""select L order by L desc limit ""&$A$1)"),9.0) -> 9 | Q2: {=RANK(INDIRECT("S2:S"&($A$1+1)),S$2:S$21)} -> 1 | R2: =IFERROR(__xludf.DUMMYFUNCTION("QUERY(INDIRECT(R1&""!K2:M""),""select M order by L desc limit ""&$A$1)"),"Skyler Mao") -> Skyler Mao | S2: =IFERROR(__xludf.DUMMYFUNCTION("QUERY(INDIRECT(R1&""!K2:M""),""select L order by L desc limit ""&$A$1)"),15.5) -> 15.5 | U2: {=RANK(INDIRECT("W2:W"&($A$1+1)),W$2:W$21)} -> 1 | V2: =IFERROR(__xludf.DUMMYFUNCTION("QUERY(INDIRECT(V1&""!K2:M""),""select M order by L desc limit ""&$A$1)"),"Jake Wang") -> Jake Wang | W2: =IFERROR(__xludf.DUMMYFUNCTION("QUERY(INDIRECT(V1&""!K2:M""),""select L order by L desc limit ""&$A$1)"),14.0) -> 14
A3: 2 | B3: =IFERROR(__xludf.DUMMYFUNCTION("""COMPUTED_VALUE"""),"Sean Yu") -> Sean Yu | C3: =IFERROR(__xludf.DUMMYFUNCTION("""COMPUTED_VALUE"""),15.5) -> 15.5 | E3: 2 | F3: =IFERROR(__xludf.DUMMYFUNCTION("""COMPUTED_VALUE"""),"Forrest Chou") -> Forrest Chou | G3: =IFERROR(__xludf.DUMMYFUNCTION("""COMPUTED_VALUE"""),14.0) -> 14 | I3: 2 | J3: =IFERROR(__xludf.DUMMYFUNCTION("""COMPUTED_VALUE"""),"Flora Jiang") -> Flora Jiang | K3: =IFERROR(__xludf.DUMMYFUNCTION("""COMPUTED_VALUE"""),15.0) -> 15 | M3: 2 | N3: =IFERROR(__xludf.DUMMYFUNCTION("""COMPUTED_VALUE"""),"Ishan Pachauri") -> Ishan Pachauri | O3: =IFERROR(__xludf.DUMMYFUNCTION("""COMPUTED_VALUE"""),7.5) -> 7.5 | Q3: 2 | R3: =IFERROR(__xludf.DUMMYFUNCTION("""COMPUTED_VALUE"""),"Boheng Cao") -> Boheng Cao | S3: =IFERROR(__xludf.DUMMYFUNCTION("""COMPUTED_VALUE"""),14.0) -> 14 | U3: 2 | V3: =IFERROR(__xludf.DUMMYFUNCTION("""COMPUTED_VALUE"""),"Sohil Rathi") -> Sohil Rathi | W3: =IFERROR(__xludf.DUMMYFUNCTION("""COMPUTED_VALUE"""),13.0) -> 13
A4: 2 | B4: =IFERROR(__xludf.DUMMYFUNCTION("""COMPUTED_VALUE"""),"Gokulanath Mahesh Kumar") -> Gokulanath Mahesh Kumar | C4: =IFERROR(__xludf.DUMMYFUNCTION("""COMPUTED_VALUE"""),15.5) -> 15.5 | E4: 3 | F4: =IFERROR(__xludf.DUMMYFUNCTION("""COMPUTED_VALUE"""),"Alex Xu") -> Alex Xu | G4: =IFERROR(__xludf.DUMMYFUNCTION("""COMPUTED_VALUE"""),13.5) -> 13.5 | I4: 3 | J4: =IFERROR(__xludf.DUMMYFUNCTION("""COMPUTED_VALUE"""),"Thomas Wu") -> Thomas Wu | K4: =IFERROR(__xludf.DUMMYFUNCTION("""COMPUTED_VALUE"""),12.0) -> 12 | M4: 2 | N4: =IFERROR(__xludf.DUMMYFUNCTION("""COMPUTED_VALUE"""),"Aaditya Karnataki") -> Aaditya Karnataki | O4: =IFERROR(__xludf.DUMMYFUNCTION("""COMPUTED_VALUE"""),7.5) -> 7.5 | Q4: 2 | R4: =IFERROR(__xludf.DUMMYFUNCTION("""COMPUTED_VALUE"""),"Rohan Garg") -> Rohan Garg | S4: =IFERROR(__xludf.DUMMYFUNCTION("""COMPUTED_VALUE"""),14.0) -> 14 | U4: 3 | V4: =IFERROR(__xludf.DUMMYFUNCTION("""COMPUTED_VALUE"""),"Alex Xu") -> Alex Xu | W4: =IFERROR(__xludf.DUMMYFUNCTION("""COMPUTED_VALUE"""),10.5) -> 10.5
A5: 4 | B5: =IFERROR(__xludf.DUMMYFUNCTION("""COMPUTED_VALUE"""),"Edwin He") -> Edwin He | C5: =IFERROR(__xludf.DUMMYFUNCTION("""COMPUTED_VALUE"""),15.0) -> 15 | E5: 4 | F5: =IFERROR(__xludf.DUMMYFUNCTION("""COMPUTED_VALUE"""),"Ishan Pachauri") -> Ishan Pachauri | G5: =IFERROR(__xludf.DUMMYFUNCTION("""COMPUTED_VALUE"""),11.5) -> 11.5 | I5: 4 | J5: =IFERROR(__xludf.DUMMYFUNCTION("""COMPUTED_VALUE"""),"Jake Wang") -> Jake Wang | K5: =IFERROR(__xludf.DUMMYFUNCTION("""COMPUTED_VALUE"""),10.5) -> 10.5 | M5: 2 | N5: =IFERROR(__xludf.DUMMYFUNCTION("""COMPUTED_VALUE"""),"Theenash Sengupta") -> Theenash Sengupta | O5: =IFERROR(__xludf.DUMMYFUNCTION("""COMPUTED_VALUE"""),7.5) -> 7.5 | Q5: 4 | R5: =IFERROR(__xludf.DUMMYFUNCTION("""COMPUTED_VALUE"""),"Sohil Rathi") -> Sohil Rathi | S5: =IFERROR(__xludf.DUMMYFUNCTION("""COMPUTED_VALUE"""),12.5) -> 12.5 | U5: 4 | V5: =IFERROR(__xludf.DUMMYFUNCTION("""COMPUTED_VALUE"""),"William Zhao") -> William Zhao | W5: =IFERROR(__xludf.DUMMYFUNCTION("""COMPUTED_VALUE"""),9.5) -> 9.5
A6: 5 | B6: =IFERROR(__xludf.DUMMYFUNCTION("""COMPUTED_VALUE"""),"Austin Xu") -> Austin Xu | C6: =IFERROR(__xludf.DUMMYFUNCTION("""COMPUTED_VALUE"""),12.0) -> 12 | E6: 5 | F6: =IFERROR(__xludf.DUMMYFUNCTION("""COMPUTED_VALUE"""),"Sidhant Chaliha") -> Sidhant Chaliha | G6: =IFERROR(__xludf.DUMMYFUNCTION("""COMPUTED_VALUE"""),10.5) -> 10.5 | I6: 5 | J6: =IFERROR(__xludf.DUMMYFUNCTION("""COMPUTED_VALUE"""),"Ishan Pachauri") -> Ishan Pachauri | K6: =IFERROR(__xludf.DUMMYFUNCTION("""COMPUTED_VALUE"""),9.5) -> 9.5 | M6: 2 | N6: =IFERROR(__xludf.DUMMYFUNCTION("""COMPUTED_VALUE"""),"Edwin He") -> Edwin He | O6: =IFERROR(__xludf.DUMMYFUNCTION("""COMPUTED_VALUE"""),7.5) -> 7.5 | Q6: 4 | R6: =IFERROR(__xludf.DUMMYFUNCTION("""COMPUTED_VALUE"""),"Ryan Bansal") -> Ryan Bansal | S6: =IFERROR(__xludf.DUMMYFUNCTION("""COMPUTED_VALUE"""),12.5) -> 12.5 | U6: 5 | V6: =IFERROR(__xludf.DUMMYFUNCTION("""COMPUTED_VALUE"""),"Boheng Cao") -> Boheng Cao | W6: =IFERROR(__xludf.DUMMYFUNCTION("""COMPUTED_VALUE"""),8.5) -> 8.5
A7: 6 | B7: =IFERROR(__xludf.DUMMYFUNCTION("""COMPUTED_VALUE"""),"Shripriya Kalbhavi") -> Shripriya Kalbhavi | C7: =IFERROR(__xludf.DUMMYFUNCTION("""COMPUTED_VALUE"""),11.0) -> 11 | E7: 5 | F7: =IFERROR(__xludf.DUMMYFUNCTION("""COMPUTED_VALUE"""),"Siddhant Jain ") -> Siddhant Jain | G7: =IFERROR(__xludf.DUMMYFUNCTION("""COMPUTED_VALUE"""),10.5) -> 10.5 | I7: 5 | J7: =IFERROR(__xludf.DUMMYFUNCTION("""COMPUTED_VALUE"""),"Samuel Wang") -> Samuel Wang | K7: =IFERROR(__xludf.DUMMYFUNCTION("""COMPUTED_VALUE"""),9.5) -> 9.5 | M7: 6 | N7: =IFERROR(__xludf.DUMMYFUNCTION("""COMPUTED_VALUE"""),"Austin Xu") -> Austin Xu | O7: =IFERROR(__xludf.DUMMYFUNCTION("""COMPUTED_VALUE"""),7.0) -> 7 | Q7: 4 | R7: =IFERROR(__xludf.DUMMYFUNCTION("""COMPUTED_VALUE"""),"Michelle Liang") -> Michelle Liang | S7: =IFERROR(__xludf.DUMMYFUNCTION("""COMPUTED_VALUE"""),12.5) -> 12.5 | U7: 5 | V7: =IFERROR(__xludf.DUMMYFUNCTION("""COMPUTED_VALUE"""),"Siddhant Jain ") -> Siddhant Jain | W7: =IFERROR(__xludf.DUMMYFUNCTION("""COMPUTED_VALUE"""),8.5) -> 8.5
A8: 7 | B8: =IFERROR(__xludf.DUMMYFUNCTION("""COMPUTED_VALUE"""),"Ishan Pachauri") -> Ishan Pachauri | C8: =IFERROR(__xludf.DUMMYFUNCTION("""COMPUTED_VALUE"""),10.0) -> 10 | E8: 7 | F8: =IFERROR(__xludf.DUMMYFUNCTION("""COMPUTED_VALUE"""),"Evan Liu") -> Evan Liu | G8: =IFERROR(__xludf.DUMMYFUNCTION("""COMPUTED_VALUE"""),9.0) -> 9 | I8: 7 | J8: =IFERROR(__xludf.DUMMYFUNCTION("""COMPUTED_VALUE"""),"Sidhant Chaliha") -> Sidhant Chaliha | K8: =IFERROR(__xludf.DUMMYFUNCTION("""COMPUTED_VALUE"""),8.5) -> 8.5 | M8: 6 | N8: =IFERROR(__xludf.DUMMYFUNCTION("""COMPUTED_VALUE"""),"Connor Zhao") -> Connor Zhao | O8: =IFERROR(__xludf.DUMMYFUNCTION("""COMPUTED_VALUE"""),7.0) -> 7 | Q8: 7 | R8: =IFERROR(__xludf.DUMMYFUNCTION("""COMPUTED_VALUE"""),"William Zhao") -> William Zhao | S8: =IFERROR(__xludf.DUMMYFUNCTION("""COMPUTED_VALUE"""),12.0) -> 12 | U8: 7 | V8: =IFERROR(__xludf.DUMMYFUNCTION("""COMPUTED_VALUE"""),"Rohan Garg") -> Rohan Garg | W8: =IFERROR(__xludf.DUMMYFUNCTION("""COMPUTED_VALUE"""),8.0) -> 8
A9: 8 | B9: =IFERROR(__xludf.DUMMYFUNCTION("""COMPUTED_VALUE"""),"Aatreyo Bhattacharyya ") -> Aatreyo Bhattacharyya | C9: =IFERROR(__xludf.DUMMYFUNCTION("""COMPUTED_VALUE"""),9.5) -> 9.5 | E9: 8 | F9: =IFERROR(__xludf.DUMMYFUNCTION("""COMPUTED_VALUE"""),"Theenash Sengupta") -> Theenash Sengupta | G9: =IFERROR(__xludf.DUMMYFUNCTION("""COMPUTED_VALUE"""),8.0) -> 8 | I9: 8 | J9: =IFERROR(__xludf.DUMMYFUNCTION("""COMPUTED_VALUE"""),"Theenash Sengupta") -> Theenash Sengupta | K9: =IFERROR(__xludf.DUMMYFUNCTION("""COMPUTED_VALUE"""),7.5) -> 7.5 | M9: 8 | N9: =IFERROR(__xludf.DUMMYFUNCTION("""COMPUTED_VALUE"""),"Skyler Mao") -> Skyler Mao | O9: =IFERROR(__xludf.DUMMYFUNCTION("""COMPUTED_VALUE"""),6.0) -> 6 | Q9: 8 | R9: =IFERROR(__xludf.DUMMYFUNCTION("""COMPUTED_VALUE"""),"Aniket Mangalampalli ") -> Aniket Mangalampalli | S9: =IFERROR(__xludf.DUMMYFUNCTION("""COMPUTED_VALUE"""),11.0) -> 11 | U9: 7 | V9: =IFERROR(__xludf.DUMMYFUNCTION("""COMPUTED_VALUE"""),"Athithan Elamaran") -> Athithan Elamaran | W9: =IFERROR(__xludf.DUMMYFUNCTION("""COMPUTED_VALUE"""),8.0) -> 8
A10: 9 | B10: =IFERROR(__xludf.DUMMYFUNCTION("""COMPUTED_VALUE"""),"Arnava Bharadwaja") -> Arnava Bharadwaja | C10: =IFERROR(__xludf.DUMMYFUNCTION("""COMPUTED_VALUE"""),9.0) -> 9 | E10: 9 | F10: =IFERROR(__xludf.DUMMYFUNCTION("""COMPUTED_VALUE"""),"Jianyu Wang") -> Jianyu Wang | G10: =IFERROR(__xludf.DUMMYFUNCTION("""COMPUTED_VALUE"""),7.5) -> 7.5 | I10: 9 | J10: =IFERROR(__xludf.DUMMYFUNCTION("""COMPUTED_VALUE"""),"Nishanth Karanam") -> Nishanth Karanam | K10: =IFERROR(__xludf.DUMMYFUNCTION("""COMPUTED_VALUE"""),6.5) -> 6.5 | M10: 9 | N10: =IFERROR(__xludf.DUMMYFUNCTION("""COMPUTED_VALUE"""),"Gokulanath Mahesh Kumar") -> Gokulanath Mahesh Kumar | O10: =IFERROR(__xludf.DUMMYFUNCTION("""COMPUTED_VALUE"""),5.5) -> 5.5 | Q10: 9 | R10: =IFERROR(__xludf.DUMMYFUNCTION("""COMPUTED_VALUE"""),"Yueqian Zhang") -> Yueqian Zhang | S10: =IFERROR(__xludf.DUMMYFUNCTION("""COMPUTED_VALUE"""),10.5) -> 10.5 | U10: 9 | V10: =IFERROR(__xludf.DUMMYFUNCTION("""COMPUTED_VALUE"""),"Forrest Chou") -> Forrest Chou | W10: =IFERROR(__xludf.DUMMYFUNCTION("""COMPUTED_VALUE"""),7.5) -> 7.5
A11: 9 | B11: =IFERROR(__xludf.DUMMYFUNCTION("""COMPUTED_VALUE"""),"Selena Yang") -> Selena Yang | C11: =IFERROR(__xludf.DUMMYFUNCTION("""COMPUTED_VALUE"""),9.0) -> 9 | E11: 10 | F11: =IFERROR(__xludf.DUMMYFUNCTION("""COMPUTED_VALUE"""),"Pleban Mishra") -> Pleban Mishra | G11: =IFERROR(__xludf.DUMMYFUNCTION("""COMPUTED_VALUE"""),7.0) -> 7 | I11: 10 | J11: =IFERROR(__xludf.DUMMYFUNCTION("""COMPUTED_VALUE"""),"Alex Xu") -> Alex Xu | K11: =IFERROR(__xludf.DUMMYFUNCTION("""COMPUTED_VALUE"""),6.0) -> 6 | M11: 10 | N11: =IFERROR(__xludf.DUMMYFUNCTION("""COMPUTED_VALUE"""),"Jonathan Yu") -> Jonathan Yu | O11: =IFERROR(__xludf.DUMMYFUNCTION("""COMPUTED_VALUE"""),5.0) -> 5 | Q11: 10 | R11: =IFERROR(__xludf.DUMMYFUNCTION("""COMPUTED_VALUE"""),"Anish Roy") -> Anish Roy | S11: =IFERROR(__xludf.DUMMYFUNCTION("""COMPUTED_VALUE"""),10.0) -> 10 | U11: 10 | V11: =IFERROR(__xludf.DUMMYFUNCTION("""COMPUTED_VALUE"""),"Harish Premkumar") -> Harish Premkumar | W11: =IFERROR(__xludf.DUMMYFUNCTION("""COMPUTED_VALUE"""),7.0) -> 7
A12: 11 | B12: =IFERROR(__xludf.DUMMYFUNCTION("""COMPUTED_VALUE"""),"Ashrith Beeravelli") -> Ashrith Beeravelli | C12: =IFERROR(__xludf.DUMMYFUNCTION("""COMPUTED_VALUE"""),8.5) -> 8.5 | E12: 11 | F12: =IFERROR(__xludf.DUMMYFUNCTION("""COMPUTED_VALUE"""),"Aaditya Karnataki") -> Aaditya Karnataki | G12: =IFERROR(__xludf.DUMMYFUNCTION("""COMPUTED_VALUE"""),6.0) -> 6 | I12: 10 | J12: =IFERROR(__xludf.DUMMYFUNCTION("""COMPUTED_VALUE"""),"Forrest Chou") -> Forrest Chou | K12: =IFERROR(__xludf.DUMMYFUNCTION("""COMPUTED_VALUE"""),6.0) -> 6 | M12: 11 | N12: =IFERROR(__xludf.DUMMYFUNCTION("""COMPUTED_VALUE"""),"Anish Bayyapu") -> Anish Bayyapu | O12: =IFERROR(__xludf.DUMMYFUNCTION("""COMPUTED_VALUE"""),4.5) -> 4.5 | Q12: 10 | R12: =IFERROR(__xludf.DUMMYFUNCTION("""COMPUTED_VALUE"""),"Matthew Yuan") -> Matthew Yuan | S12: =IFERROR(__xludf.DUMMYFUNCTION("""COMPUTED_VALUE"""),10.0) -> 10 | U12: 10 | V12: =IFERROR(__xludf.DUMMYFUNCTION("""COMPUTED_VALUE"""),"Anirudh Kannan") -> Anirudh Kannan | W12: =IFERROR(__xludf.DUMMYFUNCTION("""COMPUTED_VALUE"""),7.0) -> 7
A13: 12 | B13: =IFERROR(__xludf.DUMMYFUNCTION("""COMPUTED_VALUE"""),"Stavya Gaonkar") -> Stavya Gaonkar | C13: =IFERROR(__xludf.DUMMYFUNCTION("""COMPUTED_VALUE"""),7.5) -> 7.5 | E13: 11 | F13: =IFERROR(__xludf.DUMMYFUNCTION("""COMPUTED_VALUE"""),"Jake Wang") -> Jake Wang | G13: =IFERROR(__xludf.DUMMYFUNCTION("""COMPUTED_VALUE"""),6.0) -> 6 | I13: 10 | J13: =IFERROR(__xludf.DUMMYFUNCTION("""COMPUTED_VALUE"""),"Aya Ahmad") -> Aya Ahmad | K13: =IFERROR(__xludf.DUMMYFUNCTION("""COMPUTED_VALUE"""),6.0) -> 6 | M13: 11 | N13: =IFERROR(__xludf.DUMMYFUNCTION("""COMPUTED_VALUE"""),"Jake Wang") -> Jake Wang | O13: =IFERROR(__xludf.DUMMYFUNCTION("""COMPUTED_VALUE"""),4.5) -> 4.5 | Q13: 12 | R13: =IFERROR(__xludf.DUMMYFUNCTION("""COMPUTED_VALUE"""),"Athithan Elamaran") -> Athithan Elamaran | S13: =IFERROR(__xludf.DUMMYFUNCTION("""COMPUTED_VALUE"""),8.0) -> 8 | U13: 10 | V13: =IFERROR(__xludf.DUMMYFUNCTION("""COMPUTED_VALUE"""),"Evan Liu") -> Evan Liu | W13: =IFERROR(__xludf.DUMMYFUNCTION("""COMPUTED_VALUE"""),7.0) -> 7
A14: 12 | B14: =IFERROR(__xludf.DUMMYFUNCTION("""COMPUTED_VALUE"""),"Siddhant Jain ") -> Siddhant Jain | C14: =IFERROR(__xludf.DUMMYFUNCTION("""COMPUTED_VALUE"""),7.5) -> 7.5 | E14: 11 | F14: =IFERROR(__xludf.DUMMYFUNCTION("""COMPUTED_VALUE"""),"Chaas Kandregula") -> Chaas Kandregula | G14: =IFERROR(__xludf.DUMMYFUNCTION("""COMPUTED_VALUE"""),6.0) -> 6 | I14: 10 | J14: =IFERROR(__xludf.DUMMYFUNCTION("""COMPUTED_VALUE"""),"Edwin He") -> Edwin He | K14: =IFERROR(__xludf.DUMMYFUNCTION("""COMPUTED_VALUE"""),6.0) -> 6 | M14: 13 | N14: =IFERROR(__xludf.DUMMYFUNCTION("""COMPUTED_VALUE"""),"Alex Xu") -> Alex Xu | O14: =IFERROR(__xludf.DUMMYFUNCTION("""COMPUTED_VALUE"""),4.0) -> 4 | Q14: 13 | R14: =IFERROR(__xludf.DUMMYFUNCTION("""COMPUTED_VALUE"""),"Aatreyo Bhattacharyya ") -> Aatreyo Bhattacharyya | S14: =IFERROR(__xludf.DUMMYFUNCTION("""COMPUTED_VALUE"""),7.5) -> 7.5 | U14: 13 | V14: =IFERROR(__xludf.DUMMYFUNCTION("""COMPUTED_VALUE"""),"Stavya Gaonkar") -> Stavya Gaonkar | W14: =IFERROR(__xludf.DUMMYFUNCTION("""COMPUTED_VALUE"""),6.5) -> 6.5
A15: 14 | B15: =IFERROR(__xludf.DUMMYFUNCTION("""COMPUTED_VALUE"""),"Sebastian Leung") -> Sebastian Leung | C15: =IFERROR(__xludf.DUMMYFUNCTION("""COMPUTED_VALUE"""),7.0) -> 7 | E15: 14 | F15: =IFERROR(__xludf.DUMMYFUNCTION("""COMPUTED_VALUE"""),"Brady Yang") -> Brady Yang | G15: =IFERROR(__xludf.DUMMYFUNCTION("""COMPUTED_VALUE"""),5.5) -> 5.5 | I15: 10 | J15: =IFERROR(__xludf.DUMMYFUNCTION("""COMPUTED_VALUE"""),"Ian Chen") -> Ian Chen | K15: =IFERROR(__xludf.DUMMYFUNCTION("""COMPUTED_VALUE"""),6.0) -> 6 | M15: 13 | N15: =IFERROR(__xludf.DUMMYFUNCTION("""COMPUTED_VALUE"""),"Stavya Gaonkar") -> Stavya Gaonkar | O15: =IFERROR(__xludf.DUMMYFUNCTION("""COMPUTED_VALUE"""),4.0) -> 4 | Q15: 14 | R15: =IFERROR(__xludf.DUMMYFUNCTION("""COMPUTED_VALUE"""),"Austin Xu") -> Austin Xu | S15: =IFERROR(__xludf.DUMMYFUNCTION("""COMPUTED_VALUE"""),7.0) -> 7 | U15: 14 | V15: =IFERROR(__xludf.DUMMYFUNCTION("""COMPUTED_VALUE"""),"Sidhant Chaliha") -> Sidhant Chaliha | W15: =IFERROR(__xludf.DUMMYFUNCTION("""COMPUTED_VALUE"""),6.0) -> 6
A16: 14 | B16: =IFERROR(__xludf.DUMMYFUNCTION("""COMPUTED_VALUE"""),"Suzuko Ohshima") -> Suzuko Ohshima | C16: =IFERROR(__xludf.DUMMYFUNCTION("""COMPUTED_VALUE"""),7.0) -> 7 | E16: 14 | F16: =IFERROR(__xludf.DUMMYFUNCTION("""COMPUTED_VALUE"""),"Elyas Nuh") -> Elyas Nuh | G16: =IFERROR(__xludf.DUMMYFUNCTION("""COMPUTED_VALUE"""),5.5) -> 5.5 | I16: 15 | J16: =IFERROR(__xludf.DUMMYFUNCTION("""COMPUTED_VALUE"""),"Ashrith Beeravelli") -> Ashrith Beeravelli | K16: =IFERROR(__xludf.DUMMYFUNCTION("""COMPUTED_VALUE"""),5.5) -> 5.5 | M16: 13 | N16: =IFERROR(__xludf.DUMMYFUNCTION("""COMPUTED_VALUE"""),"Raaghav Chakravarty") -> Raaghav Chakravarty | O16: =IFERROR(__xludf.DUMMYFUNCTION("""COMPUTED_VALUE"""),4.0) -> 4 | Q16: 15 | R16: =IFERROR(__xludf.DUMMYFUNCTION("""COMPUTED_VALUE"""),"Harish Premkumar") -> Harish Premkumar | S16: =IFERROR(__xludf.DUMMYFUNCTION("""COMPUTED_VALUE"""),6.5) -> 6.5 | U16: 15 | V16: =IFERROR(__xludf.DUMMYFUNCTION("""COMPUTED_VALUE"""),"Elyas Nuh") -> Elyas Nuh | W16: =IFERROR(__xludf.DUMMYFUNCTION("""COMPUTED_VALUE"""),5.0) -> 5
A17: 16 | B17: =IFERROR(__xludf.DUMMYFUNCTION("""COMPUTED_VALUE"""),"Skyler Mao") -> Skyler Mao | C17: =IFERROR(__xludf.DUMMYFUNCTION("""COMPUTED_VALUE"""),6.5) -> 6.5 | E17: 16 | F17: =IFERROR(__xludf.DUMMYFUNCTION("""COMPUTED_VALUE"""),"Connor Zhao") -> Connor Zhao | G17: =IFERROR(__xludf.DUMMYFUNCTION("""COMPUTED_VALUE"""),5.0) -> 5 | I17: 15 | J17: =IFERROR(__xludf.DUMMYFUNCTION("""COMPUTED_VALUE"""),"Siddhant Jain ") -> Siddhant Jain | K17: =IFERROR(__xludf.DUMMYFUNCTION("""COMPUTED_VALUE"""),5.5) -> 5.5 | M17: 13 | N17: =IFERROR(__xludf.DUMMYFUNCTION("""COMPUTED_VALUE"""),"Samuel Wang") -> Samuel Wang | O17: =IFERROR(__xludf.DUMMYFUNCTION("""COMPUTED_VALUE"""),4.0) -> 4 | Q17: 15 | R17: =IFERROR(__xludf.DUMMYFUNCTION("""COMPUTED_VALUE"""),"Krishay Garg") -> Krishay Garg | S17: =IFERROR(__xludf.DUMMYFUNCTION("""COMPUTED_VALUE"""),6.5) -> 6.5 | U17: 15 | V17: =IFERROR(__xludf.DUMMYFUNCTION("""COMPUTED_VALUE"""),"Larry Wu") -> Larry Wu | W17: =IFERROR(__xludf.DUMMYFUNCTION("""COMPUTED_VALUE"""),5.0) -> 5
A18: 16 | B18: =IFERROR(__xludf.DUMMYFUNCTION("""COMPUTED_VALUE"""),"Jishnu Balaji") -> Jishnu Balaji | C18: =IFERROR(__xludf.DUMMYFUNCTION("""COMPUTED_VALUE"""),6.5) -> 6.5 | E18: 16 | F18: =IFERROR(__xludf.DUMMYFUNCTION("""COMPUTED_VALUE"""),"Krishay Garg") -> Krishay Garg | G18: =IFERROR(__xludf.DUMMYFUNCTION("""COMPUTED_VALUE"""),5.0) -> 5 | I18: 17 | J18: =IFERROR(__xludf.DUMMYFUNCTION("""COMPUTED_VALUE"""),"Gaurav Gupta") -> Gaurav Gupta | K18: =IFERROR(__xludf.DUMMYFUNCTION("""COMPUTED_VALUE"""),5.0) -> 5 | M18: 13 | N18: =IFERROR(__xludf.DUMMYFUNCTION("""COMPUTED_VALUE"""),"Varun Challa") -> Varun Challa | O18: =IFERROR(__xludf.DUMMYFUNCTION("""COMPUTED_VALUE"""),4.0) -> 4 | Q18: 17 | R18: =IFERROR(__xludf.DUMMYFUNCTION("""COMPUTED_VALUE"""),"Jake Wang") -> Jake Wang | S18: =IFERROR(__xludf.DUMMYFUNCTION("""COMPUTED_VALUE"""),6.0) -> 6 | U18: 15 | V18: =IFERROR(__xludf.DUMMYFUNCTION("""COMPUTED_VALUE"""),"Andrew Wang") -> Andrew Wang | W18: =IFERROR(__xludf.DUMMYFUNCTION("""COMPUTED_VALUE"""),5.0) -> 5
A19: 18 | B19: =IFERROR(__xludf.DUMMYFUNCTION("""COMPUTED_VALUE"""),"Lakshanya Palani") -> Lakshanya Palani | C19: =IFERROR(__xludf.DUMMYFUNCTION("""COMPUTED_VALUE"""),6.0) -> 6 | E19: 18 | F19: =IFERROR(__xludf.DUMMYFUNCTION("""COMPUTED_VALUE"""),"Aahana Biswal") -> Aahana Biswal | G19: =IFERROR(__xludf.DUMMYFUNCTION("""COMPUTED_VALUE"""),4.5) -> 4.5 | I19: 17 | J19: =IFERROR(__xludf.DUMMYFUNCTION("""COMPUTED_VALUE"""),"Nicholas Pantino ") -> Nicholas Pantino | K19: =IFERROR(__xludf.DUMMYFUNCTION("""COMPUTED_VALUE"""),5.0) -> 5 | M19: 18 | N19: =IFERROR(__xludf.DUMMYFUNCTION("""COMPUTED_VALUE"""),"Sidhant Chaliha") -> Sidhant Chaliha | O19: =IFERROR(__xludf.DUMMYFUNCTION("""COMPUTED_VALUE"""),3.5) -> 3.5 | Q19: 17 | R19: =IFERROR(__xludf.DUMMYFUNCTION("""COMPUTED_VALUE"""),"Larry Wu") -> Larry Wu | S19: =IFERROR(__xludf.DUMMYFUNCTION("""COMPUTED_VALUE"""),6.0) -> 6 | U19: 15 | V19: =IFERROR(__xludf.DUMMYFUNCTION("""COMPUTED_VALUE"""),"Advaith Mopuri") -> Advaith Mopuri | W19: =IFERROR(__xludf.DUMMYFUNCTION("""COMPUTED_VALUE"""),5.0) -> 5
A20: 18 | B20: =IFERROR(__xludf.DUMMYFUNCTION("""COMPUTED_VALUE"""),"Aaditya Karnataki") -> Aaditya Karnataki | C20: =IFERROR(__xludf.DUMMYFUNCTION("""COMPUTED_VALUE"""),6.0) -> 6 | E20: 18 | F20: =IFERROR(__xludf.DUMMYFUNCTION("""COMPUTED_VALUE"""),"Rohan Hablani") -> Rohan Hablani | G20: =IFERROR(__xludf.DUMMYFUNCTION("""COMPUTED_VALUE"""),4.5) -> 4.5 | I20: 19 | J20: =IFERROR(__xludf.DUMMYFUNCTION("""COMPUTED_VALUE"""),"Suyog Vibhuti") -> Suyog Vibhuti | K20: =IFERROR(__xludf.DUMMYFUNCTION("""COMPUTED_VALUE"""),4.5) -> 4.5 | M20: 19 | N20: =IFERROR(__xludf.DUMMYFUNCTION("""COMPUTED_VALUE"""),"Suyog Vibhuti") -> Suyog Vibhuti | O20: =IFERROR(__xludf.DUMMYFUNCTION("""COMPUTED_VALUE"""),3.0) -> 3 | Q20: 17 | R20: =IFERROR(__xludf.DUMMYFUNCTION("""COMPUTED_VALUE"""),"Advaith Mopuri") -> Advaith Mopuri | S20: =IFERROR(__xludf.DUMMYFUNCTION("""COMPUTED_VALUE"""),6.0) -> 6 | U20: 15 | V20: =IFERROR(__xludf.DUMMYFUNCTION("""COMPUTED_VALUE"""),"Rex Ouyang") -> Rex Ouyang | W20: =IFERROR(__xludf.DUMMYFUNCTION("""COMPUTED_VALUE"""),5.0) -> 5
A21: 18 | B21: =IFERROR(__xludf.DUMMYFUNCTION("""COMPUTED_VALUE"""),"Elyas Nuh") -> Elyas Nuh | C21: =IFERROR(__xludf.DUMMYFUNCTION("""COMPUTED_VALUE"""),6.0) -> 6 | E21: 18 | F21: =IFERROR(__xludf.DUMMYFUNCTION("""COMPUTED_VALUE"""),"Sohil Rathi") -> Sohil Rathi | G21: =IFERROR(__xludf.DUMMYFUNCTION("""COMPUTED_VALUE"""),4.5) -> 4.5 | I21: 19 | J21: =IFERROR(__xludf.DUMMYFUNCTION("""COMPUTED_VALUE"""),"Jeremy Yuen") -> Jeremy Yuen | K21: =IFERROR(__xludf.DUMMYFUNCTION("""COMPUTED_VALUE"""),4.5) -> 4.5 | M21: 19 | N21: =IFERROR(__xludf.DUMMYFUNCTION("""COMPUTED_VALUE"""),"Alex Ge") -> Alex Ge | O21: =IFERROR(__xludf.DUMMYFUNCTION("""COMPUTED_VALUE"""),3.0) -> 3 | Q21: 20 | R21: =IFERROR(__xludf.DUMMYFUNCTION("""COMPUTED_VALUE"""),"Amaan Mohammad") -> Amaan Mohammad | S21: =IFERROR(__xludf.DUMMYFUNCTION("""COMPUTED_VALUE"""),5.0) -> 5 | U21: 15 | V21: =IFERROR(__xludf.DUMMYFUNCTION("""COMPUTED_VALUE"""),"Inhoo Chang") -> Inhoo Chang | W21: =IFERROR(__xludf.DUMMYFUNCTION("""COMPUTED_VALUE"""),5.0) -> 5
B23: Score = (# Correct Tossups) - (# Penalized Tossups) + 0.5 * (# of Correct Bonuses)

Sheet Round Robin Team Rankings
A1: 20 | B1: Biology | F1: Chemistry | J1: Earth & Space | N1: Energy | R1: Math | V1: Physics
A2: {=RANK(INDIRECT("C2:C"&($A$1+1)),C$2:C$21)} -> 1 | B2: =IFERROR(__xludf.DUMMYFUNCTION("QUERY( INDIRECT(B1&""!A2:G""),""select A order by G desc limit ""&$A$1)"),"Mission San Jose B") -> Mission San Jose B | C2: =IFERROR(__xludf.DUMMYFUNCTION("QUERY(INDIRECT(B1&""!A2:G""),""select G order by G desc limit ""&$A$1)"),25.5) -> 25.5 | E2: {=RANK(INDIRECT("G2:G"&($A$1+1)),G$2:G$21)} -> 1 | F2: =IFERROR(__xludf.DUMMYFUNCTION("QUERY(INDIRECT(F1&""!A2:G""),""select A order by G desc limit ""&$A$1)"),"Mission San Jose A") -> Mission San Jose A | G2: =IFERROR(__xludf.DUMMYFUNCTION("QUERY(INDIRECT(F1&""!A2:G""),""select G order by G desc limit ""&$A$1)"),22.0) -> 22 | I2: {=RANK(INDIRECT("K2:K"&($A$1+1)),K$2:K$21)} -> 1 | J2: =IFERROR(__xludf.DUMMYFUNCTION("QUERY(INDIRECT(J1&""!A2:G""),""select A order by G desc limit ""&$A$1)"),"Canyon Crest A") -> Canyon Crest A | K2: =IFERROR(__xludf.DUMMYFUNCTION("QUERY(INDIRECT(J1&""!A2:G""),""select G order by G desc limit ""&$A$1)"),23.5) -> 23.5 | M2: {=RANK(INDIRECT("O2:O"&($A$1+1)),O$2:O$21)} -> 1 | N2: =IFERROR(__xludf.DUMMYFUNCTION("QUERY(INDIRECT(N1&""!A2:G""),""select A order by G desc limit ""&$A$1)"),"Mira Loma A") -> Mira Loma A | O2: =IFERROR(__xludf.DUMMYFUNCTION("QUERY(INDIRECT(N1&""!A2:G""),""select G order by G desc limit ""&$A$1)"),15.5) -> 15.5 | Q2: {=RANK(INDIRECT("S2:S"&($A$1+1)),S$2:S$21)} -> 1 | R2: =IFERROR(__xludf.DUMMYFUNCTION("QUERY(INDIRECT(R1&""!A2:G""),""select A order by G desc limit ""&$A$1)"),"North Hollywood") -> North Hollywood | S2: =IFERROR(__xludf.DUMMYFUNCTION("QUERY(INDIRECT(R1&""!A2:G""),""select G order by G desc limit ""&$A$1)"),19.0) -> 19 | U2: {=RANK(INDIRECT("W2:W"&($A$1+1)),W$2:W$21)} -> 1 | V2: =IFERROR(__xludf.DUMMYFUNCTION("QUERY(INDIRECT(V1&""!A2:G""),""select A order by G desc limit ""&$A$1)"),"Lynbrook A") -> Lynbrook A | W2: =IFERROR(__xludf.DUMMYFUNCTION("QUERY(INDIRECT(V1&""!A2:G""),""select G order by G desc limit ""&$A$1)"),17.0) -> 17
A3: 2 | B3: =IFERROR(__xludf.DUMMYFUNCTION("""COMPUTED_VALUE"""),"Canyon Crest A") -> Canyon Crest A | C3: =IFERROR(__xludf.DUMMYFUNCTION("""COMPUTED_VALUE"""),21.5) -> 21.5 | E3: 2 | F3: =IFERROR(__xludf.DUMMYFUNCTION("""COMPUTED_VALUE"""),"Canyon Crest A") -> Canyon Crest A | G3: =IFERROR(__xludf.DUMMYFUNCTION("""COMPUTED_VALUE"""),16.5) -> 16.5 | I3: 2 | J3: =IFERROR(__xludf.DUMMYFUNCTION("""COMPUTED_VALUE"""),"Mission San Jose A") -> Mission San Jose A | K3: =IFERROR(__xludf.DUMMYFUNCTION("""COMPUTED_VALUE"""),17.0) -> 17 | M3: 2 | N3: =IFERROR(__xludf.DUMMYFUNCTION("""COMPUTED_VALUE"""),"Lynbrook A") -> Lynbrook A | O3: =IFERROR(__xludf.DUMMYFUNCTION("""COMPUTED_VALUE"""),13.5) -> 13.5 | Q3: 2 | R3: =IFERROR(__xludf.DUMMYFUNCTION("""COMPUTED_VALUE"""),"Lynbrook C") -> Lynbrook C | S3: =IFERROR(__xludf.DUMMYFUNCTION("""COMPUTED_VALUE"""),16.0) -> 16 | U3: 2 | V3: =IFERROR(__xludf.DUMMYFUNCTION("""COMPUTED_VALUE"""),"Mission San Jose A") -> Mission San Jose A | W3: =IFERROR(__xludf.DUMMYFUNCTION("""COMPUTED_VALUE"""),16.5) -> 16.5
A4: 3 | B4: =IFERROR(__xludf.DUMMYFUNCTION("""COMPUTED_VALUE"""),"Amador Valley A") -> Amador Valley A | C4: =IFERROR(__xludf.DUMMYFUNCTION("""COMPUTED_VALUE"""),21.0) -> 21 | E4: 3 | F4: =IFERROR(__xludf.DUMMYFUNCTION("""COMPUTED_VALUE"""),"Lynbrook C") -> Lynbrook C | G4: =IFERROR(__xludf.DUMMYFUNCTION("""COMPUTED_VALUE"""),16.0) -> 16 | I4: 3 | J4: =IFERROR(__xludf.DUMMYFUNCTION("""COMPUTED_VALUE"""),"Lynbrook A") -> Lynbrook A | K4: =IFERROR(__xludf.DUMMYFUNCTION("""COMPUTED_VALUE"""),15.0) -> 15 | M4: 3 | N4: =IFERROR(__xludf.DUMMYFUNCTION("""COMPUTED_VALUE"""),"Cupertino A") -> Cupertino A | O4: =IFERROR(__xludf.DUMMYFUNCTION("""COMPUTED_VALUE"""),12.0) -> 12 | Q4: 3 | R4: =IFERROR(__xludf.DUMMYFUNCTION("""COMPUTED_VALUE"""),"Saratoga") -> Saratoga | S4: =IFERROR(__xludf.DUMMYFUNCTION("""COMPUTED_VALUE"""),15.5) -> 15.5 | U4: 3 | V4: =IFERROR(__xludf.DUMMYFUNCTION("""COMPUTED_VALUE"""),"Canyon Crest A") -> Canyon Crest A | W4: =IFERROR(__xludf.DUMMYFUNCTION("""COMPUTED_VALUE"""),14.5) -> 14.5
A5: 4 | B5: =IFERROR(__xludf.DUMMYFUNCTION("""COMPUTED_VALUE"""),"Mission San Jose A") -> Mission San Jose A | C5: =IFERROR(__xludf.DUMMYFUNCTION("""COMPUTED_VALUE"""),17.0) -> 17 | E5: 4 | F5: =IFERROR(__xludf.DUMMYFUNCTION("""COMPUTED_VALUE"""),"Lynbrook A") -> Lynbrook A | G5: =IFERROR(__xludf.DUMMYFUNCTION("""COMPUTED_VALUE"""),15.5) -> 15.5 | I5: 4 | J5: =IFERROR(__xludf.DUMMYFUNCTION("""COMPUTED_VALUE"""),"Lynbrook C") -> Lynbrook C | K5: =IFERROR(__xludf.DUMMYFUNCTION("""COMPUTED_VALUE"""),13.5) -> 13.5 | M5: 4 | N5: =IFERROR(__xludf.DUMMYFUNCTION("""COMPUTED_VALUE"""),"Saratoga") -> Saratoga | O5: =IFERROR(__xludf.DUMMYFUNCTION("""COMPUTED_VALUE"""),11.5) -> 11.5 | Q5: 4 | R5: =IFERROR(__xludf.DUMMYFUNCTION("""COMPUTED_VALUE"""),"BASIS Independent A") -> BASIS Independent A | S5: =IFERROR(__xludf.DUMMYFUNCTION("""COMPUTED_VALUE"""),15.0) -> 15 | U5: 4 | V5: =IFERROR(__xludf.DUMMYFUNCTION("""COMPUTED_VALUE"""),"Cupertino A") -> Cupertino A | W5: =IFERROR(__xludf.DUMMYFUNCTION("""COMPUTED_VALUE"""),14.0) -> 14
A6: 5 | B6: =IFERROR(__xludf.DUMMYFUNCTION("""COMPUTED_VALUE"""),"Canyon Crest B") -> Canyon Crest B | C6: =IFERROR(__xludf.DUMMYFUNCTION("""COMPUTED_VALUE"""),16.0) -> 16 | E6: 5 | F6: =IFERROR(__xludf.DUMMYFUNCTION("""COMPUTED_VALUE"""),"Mira Loma A") -> Mira Loma A | G6: =IFERROR(__xludf.DUMMYFUNCTION("""COMPUTED_VALUE"""),14.5) -> 14.5 | I6: 5 | J6: =IFERROR(__xludf.DUMMYFUNCTION("""COMPUTED_VALUE"""),"Amador Valley A") -> Amador Valley A | K6: =IFERROR(__xludf.DUMMYFUNCTION("""COMPUTED_VALUE"""),13.0) -> 13 | M6: 5 | N6: =IFERROR(__xludf.DUMMYFUNCTION("""COMPUTED_VALUE"""),"Amador Valley A") -> Amador Valley A | O6: =IFERROR(__xludf.DUMMYFUNCTION("""COMPUTED_VALUE"""),11.0) -> 11 | Q6: 5 | R6: =IFERROR(__xludf.DUMMYFUNCTION("""COMPUTED_VALUE"""),"Canyon Crest A") -> Canyon Crest A | S6: =IFERROR(__xludf.DUMMYFUNCTION("""COMPUTED_VALUE"""),14.0) -> 14 | U6: 5 | V6: =IFERROR(__xludf.DUMMYFUNCTION("""COMPUTED_VALUE"""),"Mira Loma A") -> Mira Loma A | W6: =IFERROR(__xludf.DUMMYFUNCTION("""COMPUTED_VALUE"""),13.5) -> 13.5
A7: 6 | B7: =IFERROR(__xludf.DUMMYFUNCTION("""COMPUTED_VALUE"""),"Mira Loma A") -> Mira Loma A | C7: =IFERROR(__xludf.DUMMYFUNCTION("""COMPUTED_VALUE"""),15.5) -> 15.5 | E7: 5 | F7: =IFERROR(__xludf.DUMMYFUNCTION("""COMPUTED_VALUE"""),"Cupertino A") -> Cupertino A | G7: =IFERROR(__xludf.DUMMYFUNCTION("""COMPUTED_VALUE"""),14.5) -> 14.5 | I7: 6 | J7: =IFERROR(__xludf.DUMMYFUNCTION("""COMPUTED_VALUE"""),"Mira Loma A") -> Mira Loma A | K7: =IFERROR(__xludf.DUMMYFUNCTION("""COMPUTED_VALUE"""),12.5) -> 12.5 | M7: 6 | N7: =IFERROR(__xludf.DUMMYFUNCTION("""COMPUTED_VALUE"""),"Archbishop Mitty B") -> Archbishop Mitty B | O7: =IFERROR(__xludf.DUMMYFUNCTION("""COMPUTED_VALUE"""),10.5) -> 10.5 | Q7: 5 | R7: =IFERROR(__xludf.DUMMYFUNCTION("""COMPUTED_VALUE"""),"Canyon Crest B") -> Canyon Crest B | S7: =IFERROR(__xludf.DUMMYFUNCTION("""COMPUTED_VALUE"""),14.0) -> 14 | U7: 6 | V7: =IFERROR(__xludf.DUMMYFUNCTION("""COMPUTED_VALUE"""),"Monta Vista A") -> Monta Vista A | W7: =IFERROR(__xludf.DUMMYFUNCTION("""COMPUTED_VALUE"""),13.0) -> 13
A8: 6 | B8: =IFERROR(__xludf.DUMMYFUNCTION("""COMPUTED_VALUE"""),"Lynbrook C") -> Lynbrook C | C8: =IFERROR(__xludf.DUMMYFUNCTION("""COMPUTED_VALUE"""),15.5) -> 15.5 | E8: 7 | F8: =IFERROR(__xludf.DUMMYFUNCTION("""COMPUTED_VALUE"""),"Palo Alto A") -> Palo Alto A | G8: =IFERROR(__xludf.DUMMYFUNCTION("""COMPUTED_VALUE"""),14.0) -> 14 | I8: 7 | J8: =IFERROR(__xludf.DUMMYFUNCTION("""COMPUTED_VALUE"""),"Mission San Jose B") -> Mission San Jose B | K8: =IFERROR(__xludf.DUMMYFUNCTION("""COMPUTED_VALUE"""),12.0) -> 12 | M8: 7 | N8: =IFERROR(__xludf.DUMMYFUNCTION("""COMPUTED_VALUE"""),"Saint Francis") -> Saint Francis | O8: =IFERROR(__xludf.DUMMYFUNCTION("""COMPUTED_VALUE"""),10.0) -> 10 | Q8: 5 | R8: =IFERROR(__xludf.DUMMYFUNCTION("""COMPUTED_VALUE"""),"Mira Loma A") -> Mira Loma A | S8: =IFERROR(__xludf.DUMMYFUNCTION("""COMPUTED_VALUE"""),14.0) -> 14 | U8: 7 | V8: =IFERROR(__xludf.DUMMYFUNCTION("""COMPUTED_VALUE"""),"Saint Francis") -> Saint Francis | W8: =IFERROR(__xludf.DUMMYFUNCTION("""COMPUTED_VALUE"""),12.5) -> 12.5
A9: 6 | B9: =IFERROR(__xludf.DUMMYFUNCTION("""COMPUTED_VALUE"""),"Lynbrook A") -> Lynbrook A | C9: =IFERROR(__xludf.DUMMYFUNCTION("""COMPUTED_VALUE"""),15.5) -> 15.5 | E9: 7 | F9: =IFERROR(__xludf.DUMMYFUNCTION("""COMPUTED_VALUE"""),"Monta Vista A") -> Monta Vista A | G9: =IFERROR(__xludf.DUMMYFUNCTION("""COMPUTED_VALUE"""),14.0) -> 14 | I9: 7 | J9: =IFERROR(__xludf.DUMMYFUNCTION("""COMPUTED_VALUE"""),"Cupertino A") -> Cupertino A | K9: =IFERROR(__xludf.DUMMYFUNCTION("""COMPUTED_VALUE"""),12.0) -> 12 | M9: 7 | N9: =IFERROR(__xludf.DUMMYFUNCTION("""COMPUTED_VALUE"""),"Canyon Crest B") -> Canyon Crest B | O9: =IFERROR(__xludf.DUMMYFUNCTION("""COMPUTED_VALUE"""),10.0) -> 10 | Q9: 5 | R9: =IFERROR(__xludf.DUMMYFUNCTION("""COMPUTED_VALUE"""),"Amador Valley A") -> Amador Valley A | S9: =IFERROR(__xludf.DUMMYFUNCTION("""COMPUTED_VALUE"""),14.0) -> 14 | U9: 8 | V9: =IFERROR(__xludf.DUMMYFUNCTION("""COMPUTED_VALUE"""),"North Hollywood") -> North Hollywood | W9: =IFERROR(__xludf.DUMMYFUNCTION("""COMPUTED_VALUE"""),11.5) -> 11.5
A10: 9 | B10: =IFERROR(__xludf.DUMMYFUNCTION("""COMPUTED_VALUE"""),"Cupertino A") -> Cupertino A | C10: =IFERROR(__xludf.DUMMYFUNCTION("""COMPUTED_VALUE"""),15.0) -> 15 | E10: 9 | F10: =IFERROR(__xludf.DUMMYFUNCTION("""COMPUTED_VALUE"""),"Saint Francis") -> Saint Francis | G10: =IFERROR(__xludf.DUMMYFUNCTION("""COMPUTED_VALUE"""),13.0) -> 13 | I10: 9 | J10: =IFERROR(__xludf.DUMMYFUNCTION("""COMPUTED_VALUE"""),"Saint Francis") -> Saint Francis | K10: =IFERROR(__xludf.DUMMYFUNCTION("""COMPUTED_VALUE"""),11.5) -> 11.5 | M10: 7 | N10: =IFERROR(__xludf.DUMMYFUNCTION("""COMPUTED_VALUE"""),"Mission San Jose A") -> Mission San Jose A | O10: =IFERROR(__xludf.DUMMYFUNCTION("""COMPUTED_VALUE"""),10.0) -> 10 | Q10: 5 | R10: =IFERROR(__xludf.DUMMYFUNCTION("""COMPUTED_VALUE"""),"Lynbrook B") -> Lynbrook B | S10: =IFERROR(__xludf.DUMMYFUNCTION("""COMPUTED_VALUE"""),14.0) -> 14 | U10: 9 | V10: =IFERROR(__xludf.DUMMYFUNCTION("""COMPUTED_VALUE"""),"Palo Alto B") -> Palo Alto B | W10: =IFERROR(__xludf.DUMMYFUNCTION("""COMPUTED_VALUE"""),11.0) -> 11
A11: 10 | B11: =IFERROR(__xludf.DUMMYFUNCTION("""COMPUTED_VALUE"""),"Lynbrook B") -> Lynbrook B | C11: =IFERROR(__xludf.DUMMYFUNCTION("""COMPUTED_VALUE"""),13.5) -> 13.5 | E11: 10 | F11: =IFERROR(__xludf.DUMMYFUNCTION("""COMPUTED_VALUE"""),"BASIS Independent A") -> BASIS Independent A | G11: =IFERROR(__xludf.DUMMYFUNCTION("""COMPUTED_VALUE"""),10.5) -> 10.5 | I11: 10 | J11: =IFERROR(__xludf.DUMMYFUNCTION("""COMPUTED_VALUE"""),"BASIS Independent A") -> BASIS Independent A | K11: =IFERROR(__xludf.DUMMYFUNCTION("""COMPUTED_VALUE"""),11.0) -> 11 | M11: 10 | N11: =IFERROR(__xludf.DUMMYFUNCTION("""COMPUTED_VALUE"""),"North Hollywood") -> North Hollywood | O11: =IFERROR(__xludf.DUMMYFUNCTION("""COMPUTED_VALUE"""),9.0) -> 9 | Q11: 10 | R11: =IFERROR(__xludf.DUMMYFUNCTION("""COMPUTED_VALUE"""),"American A") -> American A | S11: =IFERROR(__xludf.DUMMYFUNCTION("""COMPUTED_VALUE"""),13.5) -> 13.5 | U11: 10 | V11: =IFERROR(__xludf.DUMMYFUNCTION("""COMPUTED_VALUE"""),"American A") -> American A | W11: =IFERROR(__xludf.DUMMYFUNCTION("""COMPUTED_VALUE"""),10.0) -> 10
A12: 11 | B12: =IFERROR(__xludf.DUMMYFUNCTION("""COMPUTED_VALUE"""),"Foothill A") -> Foothill A | C12: =IFERROR(__xludf.DUMMYFUNCTION("""COMPUTED_VALUE"""),11.5) -> 11.5 | E12: 11 | F12: =IFERROR(__xludf.DUMMYFUNCTION("""COMPUTED_VALUE"""),"American A") -> American A | G12: =IFERROR(__xludf.DUMMYFUNCTION("""COMPUTED_VALUE"""),9.0) -> 9 | I12: 10 | J12: =IFERROR(__xludf.DUMMYFUNCTION("""COMPUTED_VALUE"""),"Mira Loma B") -> Mira Loma B | K12: =IFERROR(__xludf.DUMMYFUNCTION("""COMPUTED_VALUE"""),11.0) -> 11 | M12: 11 | N12: =IFERROR(__xludf.DUMMYFUNCTION("""COMPUTED_VALUE"""),"BASIS Independent A") -> BASIS Independent A | O12: =IFERROR(__xludf.DUMMYFUNCTION("""COMPUTED_VALUE"""),7.5) -> 7.5 | Q12: 11 | R12: =IFERROR(__xludf.DUMMYFUNCTION("""COMPUTED_VALUE"""),"Mission San Jose B") -> Mission San Jose B | S12: =IFERROR(__xludf.DUMMYFUNCTION("""COMPUTED_VALUE"""),12.5) -> 12.5 | U12: 11 | V12: =IFERROR(__xludf.DUMMYFUNCTION("""COMPUTED_VALUE"""),"Dougherty Valley A") -> Dougherty Valley A | W12: =IFERROR(__xludf.DUMMYFUNCTION("""COMPUTED_VALUE"""),9.5) -> 9.5
A13: 11 | B13: =IFERROR(__xludf.DUMMYFUNCTION("""COMPUTED_VALUE"""),"American A") -> American A | C13: =IFERROR(__xludf.DUMMYFUNCTION("""COMPUTED_VALUE"""),11.5) -> 11.5 | E13: 11 | F13: =IFERROR(__xludf.DUMMYFUNCTION("""COMPUTED_VALUE"""),"Lynbrook B") -> Lynbrook B | G13: =IFERROR(__xludf.DUMMYFUNCTION("""COMPUTED_VALUE"""),9.0) -> 9 | I13: 12 | J13: =IFERROR(__xludf.DUMMYFUNCTION("""COMPUTED_VALUE"""),"Lynbrook B") -> Lynbrook B | K13: =IFERROR(__xludf.DUMMYFUNCTION("""COMPUTED_VALUE"""),10.5) -> 10.5 | M13: 12 | N13: =IFERROR(__xludf.DUMMYFUNCTION("""COMPUTED_VALUE"""),"Canyon Crest A") -> Canyon Crest A | O13: =IFERROR(__xludf.DUMMYFUNCTION("""COMPUTED_VALUE"""),7.0) -> 7 | Q13: 12 | R13: =IFERROR(__xludf.DUMMYFUNCTION("""COMPUTED_VALUE"""),"Cupertino A") -> Cupertino A | S13: =IFERROR(__xludf.DUMMYFUNCTION("""COMPUTED_VALUE"""),12.0) -> 12 | U13: 11 | V13: =IFERROR(__xludf.DUMMYFUNCTION("""COMPUTED_VALUE"""),"Amador Valley A") -> Amador Valley A | W13: =IFERROR(__xludf.DUMMYFUNCTION("""COMPUTED_VALUE"""),9.5) -> 9.5
A14: 11 | B14: =IFERROR(__xludf.DUMMYFUNCTION("""COMPUTED_VALUE"""),"Stanford Online") -> Stanford Online | C14: =IFERROR(__xludf.DUMMYFUNCTION("""COMPUTED_VALUE"""),11.5) -> 11.5 | E14: 13 | F14: =IFERROR(__xludf.DUMMYFUNCTION("""COMPUTED_VALUE"""),"California B") -> California B | G14: =IFERROR(__xludf.DUMMYFUNCTION("""COMPUTED_VALUE"""),8.0) -> 8 | I14: 13 | J14: =IFERROR(__xludf.DUMMYFUNCTION("""COMPUTED_VALUE"""),"Monta Vista A") -> Monta Vista A | K14: =IFERROR(__xludf.DUMMYFUNCTION("""COMPUTED_VALUE"""),9.0) -> 9 | M14: 13 | N14: =IFERROR(__xludf.DUMMYFUNCTION("""COMPUTED_VALUE"""),"Mission San Jose B") -> Mission San Jose B | O14: =IFERROR(__xludf.DUMMYFUNCTION("""COMPUTED_VALUE"""),6.5) -> 6.5 | Q14: 12 | R14: =IFERROR(__xludf.DUMMYFUNCTION("""COMPUTED_VALUE"""),"Dougherty Valley A") -> Dougherty Valley A | S14: =IFERROR(__xludf.DUMMYFUNCTION("""COMPUTED_VALUE"""),12.0) -> 12 | U14: 13 | V14: =IFERROR(__xludf.DUMMYFUNCTION("""COMPUTED_VALUE"""),"California A") -> California A | W14: =IFERROR(__xludf.DUMMYFUNCTION("""COMPUTED_VALUE"""),9.0) -> 9
A15: 14 | B15: =IFERROR(__xludf.DUMMYFUNCTION("""COMPUTED_VALUE"""),"Saint Francis") -> Saint Francis | C15: =IFERROR(__xludf.DUMMYFUNCTION("""COMPUTED_VALUE"""),10.5) -> 10.5 | E15: 13 | F15: =IFERROR(__xludf.DUMMYFUNCTION("""COMPUTED_VALUE"""),"Dougherty Valley A") -> Dougherty Valley A | G15: =IFERROR(__xludf.DUMMYFUNCTION("""COMPUTED_VALUE"""),8.0) -> 8 | I15: 14 | J15: =IFERROR(__xludf.DUMMYFUNCTION("""COMPUTED_VALUE"""),"Palo Alto A") -> Palo Alto A | K15: =IFERROR(__xludf.DUMMYFUNCTION("""COMPUTED_VALUE"""),7.5) -> 7.5 | M15: 14 | N15: =IFERROR(__xludf.DUMMYFUNCTION("""COMPUTED_VALUE"""),"American A") -> American A | O15: =IFERROR(__xludf.DUMMYFUNCTION("""COMPUTED_VALUE"""),6.0) -> 6 | Q15: 14 | R15: =IFERROR(__xludf.DUMMYFUNCTION("""COMPUTED_VALUE"""),"Mission San Jose A") -> Mission San Jose A | S15: =IFERROR(__xludf.DUMMYFUNCTION("""COMPUTED_VALUE"""),11.5) -> 11.5 | U15: 14 | V15: =IFERROR(__xludf.DUMMYFUNCTION("""COMPUTED_VALUE"""),"Foothill B") -> Foothill B | W15: =IFERROR(__xludf.DUMMYFUNCTION("""COMPUTED_VALUE"""),8.0) -> 8
A16: 14 | B16: =IFERROR(__xludf.DUMMYFUNCTION("""COMPUTED_VALUE"""),"California A") -> California A | C16: =IFERROR(__xludf.DUMMYFUNCTION("""COMPUTED_VALUE"""),10.5) -> 10.5 | E16: 15 | F16: =IFERROR(__xludf.DUMMYFUNCTION("""COMPUTED_VALUE"""),"BASIS Independent B") -> BASIS Independent B | G16: =IFERROR(__xludf.DUMMYFUNCTION("""COMPUTED_VALUE"""),7.5) -> 7.5 | I16: 15 | J16: =IFERROR(__xludf.DUMMYFUNCTION("""COMPUTED_VALUE"""),"North Hollywood") -> North Hollywood | K16: =IFERROR(__xludf.DUMMYFUNCTION("""COMPUTED_VALUE"""),7.0) -> 7 | M16: 14 | N16: =IFERROR(__xludf.DUMMYFUNCTION("""COMPUTED_VALUE"""),"Monta Vista A") -> Monta Vista A | O16: =IFERROR(__xludf.DUMMYFUNCTION("""COMPUTED_VALUE"""),6.0) -> 6 | Q16: 14 | R16: =IFERROR(__xludf.DUMMYFUNCTION("""COMPUTED_VALUE"""),"Lynbrook A") -> Lynbrook A | S16: =IFERROR(__xludf.DUMMYFUNCTION("""COMPUTED_VALUE"""),11.5) -> 11.5 | U16: 15 | V16: =IFERROR(__xludf.DUMMYFUNCTION("""COMPUTED_VALUE"""),"BASIS Independent A") -> BASIS Independent A | W16: =IFERROR(__xludf.DUMMYFUNCTION("""COMPUTED_VALUE"""),7.5) -> 7.5
A17: 14 | B17: =IFERROR(__xludf.DUMMYFUNCTION("""COMPUTED_VALUE"""),"Cupertino B") -> Cupertino B | C17: =IFERROR(__xludf.DUMMYFUNCTION("""COMPUTED_VALUE"""),10.5) -> 10.5 | E17: 15 | F17: =IFERROR(__xludf.DUMMYFUNCTION("""COMPUTED_VALUE"""),"Foothill B") -> Foothill B | G17: =IFERROR(__xludf.DUMMYFUNCTION("""COMPUTED_VALUE"""),7.5) -> 7.5 | I17: 16 | J17: =IFERROR(__xludf.DUMMYFUNCTION("""COMPUTED_VALUE"""),"BASIS Independent B") -> BASIS Independent B | K17: =IFERROR(__xludf.DUMMYFUNCTION("""COMPUTED_VALUE"""),6.0) -> 6 | M17: 16 | N17: =IFERROR(__xludf.DUMMYFUNCTION("""COMPUTED_VALUE"""),"Lynbrook C") -> Lynbrook C | O17: =IFERROR(__xludf.DUMMYFUNCTION("""COMPUTED_VALUE"""),5.5) -> 5.5 | Q17: 16 | R17: =IFERROR(__xludf.DUMMYFUNCTION("""COMPUTED_VALUE"""),"Archbishop Mitty B") -> Archbishop Mitty B | S17: =IFERROR(__xludf.DUMMYFUNCTION("""COMPUTED_VALUE"""),11.0) -> 11 | U17: 15 | V17: =IFERROR(__xludf.DUMMYFUNCTION("""COMPUTED_VALUE"""),"Canyon Crest B") -> Canyon Crest B | W17: =IFERROR(__xludf.DUMMYFUNCTION("""COMPUTED_VALUE"""),7.5) -> 7.5
A18: 14 | B18: =IFERROR(__xludf.DUMMYFUNCTION("""COMPUTED_VALUE"""),"Monta Vista A") -> Monta Vista A | C18: =IFERROR(__xludf.DUMMYFUNCTION("""COMPUTED_VALUE"""),10.5) -> 10.5 | E18: 15 | F18: =IFERROR(__xludf.DUMMYFUNCTION("""COMPUTED_VALUE"""),"Stanford Online") -> Stanford Online | G18: =IFERROR(__xludf.DUMMYFUNCTION("""COMPUTED_VALUE"""),7.5) -> 7.5 | I18: 16 | J18: =IFERROR(__xludf.DUMMYFUNCTION("""COMPUTED_VALUE"""),"Archbishop Mitty A") -> Archbishop Mitty A | K18: =IFERROR(__xludf.DUMMYFUNCTION("""COMPUTED_VALUE"""),6.0) -> 6 | M18: 16 | N18: =IFERROR(__xludf.DUMMYFUNCTION("""COMPUTED_VALUE"""),"Dougherty Valley B") -> Dougherty Valley B | O18: =IFERROR(__xludf.DUMMYFUNCTION("""COMPUTED_VALUE"""),5.5) -> 5.5 | Q18: 17 | R18: =IFERROR(__xludf.DUMMYFUNCTION("""COMPUTED_VALUE"""),"Saint Francis") -> Saint Francis | S18: =IFERROR(__xludf.DUMMYFUNCTION("""COMPUTED_VALUE"""),9.0) -> 9 | U18: 15 | V18: =IFERROR(__xludf.DUMMYFUNCTION("""COMPUTED_VALUE"""),"Palo Alto A") -> Palo Alto A | W18: =IFERROR(__xludf.DUMMYFUNCTION("""COMPUTED_VALUE"""),7.5) -> 7.5
A19: 18 | B19: =IFERROR(__xludf.DUMMYFUNCTION("""COMPUTED_VALUE"""),"American B") -> American B | C19: =IFERROR(__xludf.DUMMYFUNCTION("""COMPUTED_VALUE"""),10.0) -> 10 | E19: 18 | F19: =IFERROR(__xludf.DUMMYFUNCTION("""COMPUTED_VALUE"""),"Mission San Jose B") -> Mission San Jose B | G19: =IFERROR(__xludf.DUMMYFUNCTION("""COMPUTED_VALUE"""),7.0) -> 7 | I19: 16 | J19: =IFERROR(__xludf.DUMMYFUNCTION("""COMPUTED_VALUE"""),"Dougherty Valley A") -> Dougherty Valley A | K19: =IFERROR(__xludf.DUMMYFUNCTION("""COMPUTED_VALUE"""),6.0) -> 6 | M19: 18 | N19: =IFERROR(__xludf.DUMMYFUNCTION("""COMPUTED_VALUE"""),"BASIS Independent B") -> BASIS Independent B | O19: =IFERROR(__xludf.DUMMYFUNCTION("""COMPUTED_VALUE"""),5.0) -> 5 | Q19: 17 | R19: =IFERROR(__xludf.DUMMYFUNCTION("""COMPUTED_VALUE"""),"Mira Loma B") -> Mira Loma B | S19: =IFERROR(__xludf.DUMMYFUNCTION("""COMPUTED_VALUE"""),9.0) -> 9 | U19: 18 | V19: =IFERROR(__xludf.DUMMYFUNCTION("""COMPUTED_VALUE"""),"Lynbrook C") -> Lynbrook C | W19: =IFERROR(__xludf.DUMMYFUNCTION("""COMPUTED_VALUE"""),7.0) -> 7
A20: 19 | B20: =IFERROR(__xludf.DUMMYFUNCTION("""COMPUTED_VALUE"""),"Mira Loma B") -> Mira Loma B | C20: =IFERROR(__xludf.DUMMYFUNCTION("""COMPUTED_VALUE"""),9.5) -> 9.5 | E20: 19 | F20: =IFERROR(__xludf.DUMMYFUNCTION("""COMPUTED_VALUE"""),"North Hollywood") -> North Hollywood | G20: =IFERROR(__xludf.DUMMYFUNCTION("""COMPUTED_VALUE"""),6.5) -> 6.5 | I20: 19 | J20: =IFERROR(__xludf.DUMMYFUNCTION("""COMPUTED_VALUE"""),"Saratoga") -> Saratoga | K20: =IFERROR(__xludf.DUMMYFUNCTION("""COMPUTED_VALUE"""),5.5) -> 5.5 | M20: 18 | N20: =IFERROR(__xludf.DUMMYFUNCTION("""COMPUTED_VALUE"""),"Palo Alto A") -> Palo Alto A | O20: =IFERROR(__xludf.DUMMYFUNCTION("""COMPUTED_VALUE"""),5.0) -> 5 | Q20: 19 | R20: =IFERROR(__xludf.DUMMYFUNCTION("""COMPUTED_VALUE"""),"Foothill B") -> Foothill B | S20: =IFERROR(__xludf.DUMMYFUNCTION("""COMPUTED_VALUE"""),8.0) -> 8 | U20: 19 | V20: =IFERROR(__xludf.DUMMYFUNCTION("""COMPUTED_VALUE"""),"Lynbrook B") -> Lynbrook B | W20: =IFERROR(__xludf.DUMMYFUNCTION("""COMPUTED_VALUE"""),6.5) -> 6.5
A21: 19 | B21: =IFERROR(__xludf.DUMMYFUNCTION("""COMPUTED_VALUE"""),"Palo Alto A") -> Palo Alto A | C21: =IFERROR(__xludf.DUMMYFUNCTION("""COMPUTED_VALUE"""),9.5) -> 9.5 | E21: 20 | F21: =IFERROR(__xludf.DUMMYFUNCTION("""COMPUTED_VALUE"""),"Archbishop Mitty A") -> Archbishop Mitty A | G21: =IFERROR(__xludf.DUMMYFUNCTION("""COMPUTED_VALUE"""),6.0) -> 6 | I21: 19 | J21: =IFERROR(__xludf.DUMMYFUNCTION("""COMPUTED_VALUE"""),"American A") -> American A | K21: =IFERROR(__xludf.DUMMYFUNCTION("""COMPUTED_VALUE"""),5.5) -> 5.5 | M21: 18 | N21: =IFERROR(__xludf.DUMMYFUNCTION("""COMPUTED_VALUE"""),"Dougherty Valley A") -> Dougherty Valley A | O21: =IFERROR(__xludf.DUMMYFUNCTION("""COMPUTED_VALUE"""),5.0) -> 5 | Q21: 20 | R21: =IFERROR(__xludf.DUMMYFUNCTION("""COMPUTED_VALUE"""),"Palo Alto A") -> Palo Alto A | S21: =IFERROR(__xludf.DUMMYFUNCTION("""COMPUTED_VALUE"""),7.0) -> 7 | U21: 20 | V21: =IFERROR(__xludf.DUMMYFUNCTION("""COMPUTED_VALUE"""),"Mira Loma B") -> Mira Loma B | W21: =IFERROR(__xludf.DUMMYFUNCTION("""COMPUTED_VALUE"""),5.0) -> 5
B23: Score = (# Correct Tossups) - (# Penalized Tossups) + 0.5 * (# of Correct Bonuses)

Sheet Round Robin Matchups
A1: =IFERROR(__xludf.DUMMYFUNCTION("IMPORTRANGE(""https://docs.google.com/spreadsheets/d/1hF3sefURNb_ssJk7SkIRKX6ByBcDxRkk4SZazZtucFY/edit#gid=135815300"",""Round Robin Matchups!A1:W"")"),"Interface Index") -> Interface Index | B1: =IFERROR(__xludf.DUMMYFUNCTION("""COMPUTED_VALUE"""),"First Team") -> First Team | C1: =IFERROR(__xludf.DUMMYFUNCTION("""COMPUTED_VALUE"""),"Second Team") -> Second Team | D1: =IFERROR(__xludf.DUMMYFUNCTION("""COMPUTED_VALUE"""),"Round #") -> Round # | E1: =IFERROR(__xludf.DUMMYFUNCTION("""COMPUTED_VALUE"""),"Type") -> Type | F1: =IFERROR(__xludf.DUMMYFUNCTION("""COMPUTED_VALUE"""),"Division") -> Division | G1: =IFERROR(__xludf.DUMMYFUNCTION("""COMPUTED_VALUE"""),"Room") -> Room | H1: =IFERROR(__xludf.DUMMYFUNCTION("""COMPUTED_VALUE"""),"Interface ID") -> Interface ID | I1: =IFERROR(__xludf.DUMMYFUNCTION("""COMPUTED_VALUE"""),"Interface Link") -> Interface Link | J1: =IFERROR(__xludf.DUMMYFUNCTION("""COMPUTED_VALUE"""),"Round Done") -> Round Done | K1: =IFERROR(__xludf.DUMMYFUNCTION("""COMPUTED_VALUE"""),"First Team Score") -> First Team Score | L1: =IFERROR(__xludf.DUMMYFUNCTION("""COMPUTED_VALUE"""),"Second Team Score") -> Second Team Score | M1: =IFERROR(__xludf.DUMMYFUNCTION("""COMPUTED_VALUE"""),"T1, Student 1") -> T1, Student 1 | N1: =IFERROR(__xludf.DUMMYFUNCTION("""COMPUTED_VALUE"""),"T1, Student 2") -> T1, Student 2 | O1: =IFERROR(__xludf.DUMMYFUNCTION("""COMPUTED_VALUE"""),"T1, Student 3") -> T1, Student 3 | P1: =IFERROR(__xludf.DUMMYFUNCTION("""COMPUTED_VALUE"""),"T1, Student 4") -> T1, Student 4 | Q1: =IFERROR(__xludf.DUMMYFUNCTION("""COMPUTED_VALUE"""),"T1, Student 5") -> T1, Student 5 | R1: =IFERROR(__xludf.DUMMYFUNCTION("""COMPUTED_VALUE"""),"T2, Student 1") -> T2, Student 1 | S1: =IFERROR(__xludf.DUMMYFUNCTION("""COMPUTED_VALUE"""),"T2, Student 2") -> T2, Student 2 | T1: =IFERROR(__xludf.DUMMYFUNCTION("""COMPUTED_VALUE"""),"T2, Student 3") -> T2, Student 3 | U1: =IFERROR(__xludf.DUMMYFUNCTION("""COMPUTED_VALUE"""),"T2, Student 4") -> T2, Student 4 | V1: =IFERROR(__xludf.DUMMYFUNCTION("""COMPUTED_VALUE"""),"T2, Student 5") -> T2, Student 5 | W1: =IFERROR(__xludf.DUMMYFUNCTION("""COMPUTED_VALUE"""),"Folder ID") -> Folder ID
A2: =IFERROR(__xludf.DUMMYFUNCTION("""COMPUTED_VALUE"""),1.0) -> 1 | B2: =IFERROR(__xludf.DUMMYFUNCTION("""COMPUTED_VALUE"""),"Mission San Jose B") -> Mission San Jose B | C2: =IFERROR(__xludf.DUMMYFUNCTION("""COMPUTED_VALUE"""),"Palo Alto B") -> Palo Alto B | D2: =IFERROR(__xludf.DUMMYFUNCTION("""COMPUTED_VALUE"""),1.0) -> 1 | E2: =IFERROR(__xludf.DUMMYFUNCTION("""COMPUTED_VALUE"""),"Round Robin") -> Round Robin | F2: =IFERROR(__xludf.DUMMYFUNCTION("""COMPUTED_VALUE"""),"A") -> A | G2: =IFERROR(__xludf.DUMMYFUNCTION("""COMPUTED_VALUE"""),"DWINELLE 87") -> DWINELLE 87 | H2: =IFERROR(__xludf.DUMMYFUNCTION("""COMPUTED_VALUE"""),"17E6ywICRh3DH2kuT_GY3LWRXJ-YRPGe96jB5rilwQBQ") -> 17E6ywICRh3DH2kuT_GY3LWRXJ-YRPGe96jB5rilwQBQ | I2: =IFERROR(__xludf.DUMMYFUNCTION("""COMPUTED_VALUE"""),"https://docs.google.com/spreadsheets/d/17E6ywICRh3DH2kuT_GY3LWRXJ-YRPGe96jB5rilwQBQ") -> https://docs.google.com/spreadsheets/d/17E6ywICRh3DH2kuT_GY3LWRXJ-YRPGe96jB5rilwQBQ | J2: =IFERROR(__xludf.DUMMYFUNCTION("""COMPUTED_VALUE"""),TRUE) -> TRUE | K2: =IFERROR(__xludf.DUMMYFUNCTION("""COMPUTED_VALUE"""),126.0) -> 126 | L2: =IFERROR(__xludf.DUMMYFUNCTION("""COMPUTED_VALUE"""),18.0) -> 18 | M2: =IFERROR(__xludf.DUMMYFUNCTION("""COMPUTED_VALUE"""),"1.5,0,1,0,0,0") -> 1.5,0,1,0,0,0 | N2: =IFERROR(__xludf.DUMMYFUNCTION("""COMPUTED_VALUE"""),"4.5,2,0,1,0,0") -> 4.5,2,0,1,0,0 | O2: =IFERROR(__xludf.DUMMYFUNCTION("""COMPUTED_VALUE"""),"0,0,0,0,0,0") -> 0,0,0,0,0,0 | P2: =IFERROR(__xludf.DUMMYFUNCTION("""COMPUTED_VALUE"""),"0,0,1.5,0,5,0") -> 0,0,1.5,0,5,0 | Q2: =IFERROR(__xludf.DUMMYFUNCTION("""COMPUTED_VALUE"""),"0,0,0,0,0,0") -> 0,0,0,0,0,0 | R2: =IFERROR(__xludf.DUMMYFUNCTION("""COMPUTED_VALUE"""),"0,0,0,0,0,0") -> 0,0,0,0,0,0 | S2: =IFERROR(__xludf.DUMMYFUNCTION("""COMPUTED_VALUE"""),"0,0,0,0,0,0") -> 0,0,0,0,0,0 | T2: =IFERROR(__xludf.DUMMYFUNCTION("""COMPUTED_VALUE"""),"0,0,0,0,0,1.5") -> 0,0,0,0,0,1.5 | U2: =IFERROR(__xludf.DUMMYFUNCTION("""COMPUTED_VALUE"""),"0,0,0,0,0,0") -> 0,0,0,0,0,0 | V2: =IFERROR(__xludf.DUMMYFUNCTION("""COMPUTED_VALUE"""),"0,0,0,0,0,0") -> 0,0,0,0,0,0 | W2: =IFERROR(__xludf.DUMMYFUNCTION("""COMPUTED_VALUE"""),"1wU8ddNcIDYy_LNgK50_oAheTJQ7qxrnc") -> 1wU8ddNcIDYy_LNgK50_oAheTJQ7qxrnc
A3: =IFERROR(__xludf.DUMMYFUNCTION("""COMPUTED_VALUE"""),2.0) -> 2 | B3: =IFERROR(__xludf.DUMMYFUNCTION("""COMPUTED_VALUE"""),"Saint Francis") -> Saint Francis | C3: =IFERROR(__xludf.DUMMYFUNCTION("""COMPUTED_VALUE"""),"Dougherty Valley A") -> Dougherty Valley A | D3: =IFERROR(__xludf.DUMMYFUNCTION("""COMPUTED_VALUE"""),1.0) -> 1 | E3: =IFERROR(__xludf.DUMMYFUNCTION("""COMPUTED_VALUE"""),"Round Robin") -> Round Robin | F3: =IFERROR(__xludf.DUMMYFUNCTION("""COMPUTED_VALUE"""),"A") -> A | G3: =IFERROR(__xludf.DUMMYFUNCTION("""COMPUTED_VALUE"""),"DWINELLE 88") -> DWINELLE 88 | H3: =IFERROR(__xludf.DUMMYFUNCTION("""COMPUTED_VALUE"""),"170z1HffuXseDb5NpZ_nzJQINmBXrztcqgbYM9hO5_BM") -> 170z1HffuXseDb5NpZ_nzJQINmBXrztcqgbYM9hO5_BM | I3: =IFERROR(__xludf.DUMMYFUNCTION("""COMPUTED_VALUE"""),"https://docs.google.com/spreadsheets/d/170z1HffuXseDb5NpZ_nzJQINmBXrztcqgbYM9hO5_BM") -> https://docs.google.com/spreadsheets/d/170z1HffuXseDb5NpZ_nzJQINmBXrztcqgbYM9hO5_BM | J3: =IFERROR(__xludf.DUMMYFUNCTION("""COMPUTED_VALUE"""),TRUE) -> TRUE | K3: =IFERROR(__xludf.DUMMYFUNCTION("""COMPUTED_VALUE"""),114.0) -> 114 | L3: =IFERROR(__xludf.DUMMYFUNCTION("""COMPUTED_VALUE"""),82.0) -> 82 | M3: =IFERROR(__xludf.DUMMYFUNCTION("""COMPUTED_VALUE"""),"3.5,4,1.5,3,0,0") -> 3.5,4,1.5,3,0,0 | N3: =IFERROR(__xludf.DUMMYFUNCTION("""COMPUTED_VALUE"""),"#N/A") -> #N/A | O3: =IFERROR(__xludf.DUMMYFUNCTION("""COMPUTED_VALUE"""),"0,0,0,1,0,1.5") -> 0,0,0,1,0,1.5 | P3: =IFERROR(__xludf.DUMMYFUNCTION("""COMPUTED_VALUE"""),"0,0,0,0,0,0") -> 0,0,0,0,0,0 | Q3: =IFERROR(__xludf.DUMMYFUNCTION("""COMPUTED_VALUE"""),"0,0,0,0,0,0") -> 0,0,0,0,0,0 | R3: =IFERROR(__xludf.DUMMYFUNCTION("""COMPUTED_VALUE"""),"0,0,0,0,0,0") -> 0,0,0,0,0,0 | S3: =IFERROR(__xludf.DUMMYFUNCTION("""COMPUTED_VALUE"""),"0,0,1,0,5,3") -> 0,0,1,0,5,3 | T3: =IFERROR(__xludf.DUMMYFUNCTION("""COMPUTED_VALUE"""),"0,0,0,0,0,0") -> 0,0,0,0,0,0 | U3: =IFERROR(__xludf.DUMMYFUNCTION("""COMPUTED_VALUE"""),"1.5,0,0,0,0,0") -> 1.5,0,0,0,0,0 | V3: =IFERROR(__xludf.DUMMYFUNCTION("""COMPUTED_VALUE"""),",,,,,") -> ,,,,, | W3: =IFERROR(__xludf.DUMMYFUNCTION("""COMPUTED_VALUE"""),"103JTGMew8yagYGeIoIvugJ7A3dBmouHQ") -> 103JTGMew8yagYGeIoIvugJ7A3dBmouHQ
A4: =IFERROR(__xludf.DUMMYFUNCTION("""COMPUTED_VALUE"""),3.0) -> 3 | B4: =IFERROR(__xludf.DUMMYFUNCTION("""COMPUTED_VALUE"""),"BASIS Independent B") -> BASIS Independent B | C4: =IFERROR(__xludf.DUMMYFUNCTION("""COMPUTED_VALUE"""),"Stanford Online") -> Stanford Online | D4: =IFERROR(__xludf.DUMMYFUNCTION("""COMPUTED_VALUE"""),1.0) -> 1 | E4: =IFERROR(__xludf.DUMMYFUNCTION("""COMPUTED_VALUE"""),"Round Robin") -> Round Robin | F4: =IFERROR(__xludf.DUMMYFUNCTION("""COMPUTED_VALUE"""),"A") -> A | G4: =IFERROR(__xludf.DUMMYFUNCTION("""COMPUTED_VALUE"""),"DWINELLE 89") -> DWINELLE 89 | H4: =IFERROR(__xludf.DUMMYFUNCTION("""COMPUTED_VALUE"""),"1itbJVFJOyyBh0337RHlvKAm74IA5JbzVGvQpcQSZE-A") -> 1itbJVFJOyyBh0337RHlvKAm74IA5JbzVGvQpcQSZE-A | I4: =IFERROR(__xludf.DUMMYFUNCTION("""COMPUTED_VALUE"""),"https://docs.google.com/spreadsheets/d/1itbJVFJOyyBh0337RHlvKAm74IA5JbzVGvQpcQSZE-A") -> https://docs.google.com/spreadsheets/d/1itbJVFJOyyBh0337RHlvKAm74IA5JbzVGvQpcQSZE-A | J4: =IFERROR(__xludf.DUMMYFUNCTION("""COMPUTED_VALUE"""),TRUE) -> TRUE | K4: =IFERROR(__xludf.DUMMYFUNCTION("""COMPUTED_VALUE"""),48.0) -> 48 | L4: =IFERROR(__xludf.DUMMYFUNCTION("""COMPUTED_VALUE"""),76.0) -> 76 | M4: =IFERROR(__xludf.DUMMYFUNCTION("""COMPUTED_VALUE"""),"0,1,0,1,1,0") -> 0,1,0,1,1,0 | N4: =IFERROR(__xludf.DUMMYFUNCTION("""COMPUTED_VALUE"""),"0,0,1,0,1.5,0") -> 0,0,1,0,1.5,0 | O4: =IFERROR(__xludf.DUMMYFUNCTION("""COMPUTED_VALUE"""),"1.5,0,0,0,0,0") -> 1.5,0,0,0,0,0 | P4: =IFERROR(__xludf.DUMMYFUNCTION("""COMPUTED_VALUE"""),"0,0,0,0,0,0") -> 0,0,0,0,0,0 | Q4: =IFERROR(__xludf.DUMMYFUNCTION("""COMPUTED_VALUE"""),",,,,,") -> ,,,,, | R4: =IFERROR(__xludf.DUMMYFUNCTION("""COMPUTED_VALUE"""),"-1,1.5,0,0,0,1.5") -> -1,1.5,0,0,0,1.5 | S4: =IFERROR(__xludf.DUMMYFUNCTION("""COMPUTED_VALUE"""),"3,0,1,0,0,0") -> 3,0,1,0,0,0 | T4: =IFERROR(__xludf.DUMMYFUNCTION("""COMPUTED_VALUE"""),"1.5,1.5,0,0,0,1") -> 1.5,1.5,0,0,0,1 | U4: =IFERROR(__xludf.DUMMYFUNCTION("""COMPUTED_VALUE"""),"0,0,0,0,1,0") -> 0,0,0,0,1,0 | V4: =IFERROR(__xludf.DUMMYFUNCTION("""COMPUTED_VALUE"""),",,,,,") -> ,,,,, | W4: =IFERROR(__xludf.DUMMYFUNCTION("""COMPUTED_VALUE"""),"1iE_5-GNdmwZ6YBR19NoryqpaMeSaQNwX") -> 1iE_5-GNdmwZ6YBR19NoryqpaMeSaQNwX
A5: =IFERROR(__xludf.DUMMYFUNCTION("""COMPUTED_VALUE"""),4.0) -> 4 | B5: =IFERROR(__xludf.DUMMYFUNCTION("""COMPUTED_VALUE"""),"California B") -> California B | C5: =IFERROR(__xludf.DUMMYFUNCTION("""COMPUTED_VALUE"""),"North Hollywood") -> North Hollywood | D5: =IFERROR(__xludf.DUMMYFUNCTION("""COMPUTED_VALUE"""),1.0) -> 1 | E5: =IFERROR(__xludf.DUMMYFUNCTION("""COMPUTED_VALUE"""),"Round Robin") -> Round Robin | F5: =IFERROR(__xludf.DUMMYFUNCTION("""COMPUTED_VALUE"""),"B") -> B | G5: =IFERROR(__xludf.DUMMYFUNCTION("""COMPUTED_VALUE"""),"DWINELLE 105") -> DWINELLE 105 | H5: =IFERROR(__xludf.DUMMYFUNCTION("""COMPUTED_VALUE"""),"1n-s0YJuErF_1mcp_jaKFpVqRd7PZSnZN8omjpo3pH2k") -> 1n-s0YJuErF_1mcp_jaKFpVqRd7PZSnZN8omjpo3pH2k | I5: =IFERROR(__xludf.DUMMYFUNCTION("""COMPUTED_VALUE"""),"https://docs.google.com/spreadsheets/d/1n-s0YJuErF_1mcp_jaKFpVqRd7PZSnZN8omjpo3pH2k") -> https://docs.google.com/spreadsheets/d/1n-s0YJuErF_1mcp_jaKFpVqRd7PZSnZN8omjpo3pH2k | J5: =IFERROR(__xludf.DUMMYFUNCTION("""COMPUTED_VALUE"""),TRUE) -> TRUE | K5: =IFERROR(__xludf.DUMMYFUNCTION("""COMPUTED_VALUE"""),26.0) -> 26 | L5: =IFERROR(__xludf.DUMMYFUNCTION("""COMPUTED_VALUE"""),202.0) -> 202 | M5: =IFERROR(__xludf.DUMMYFUNCTION("""COMPUTED_VALUE"""),"0,1,0,0,0,0") -> 0,1,0,0,0,0 | N5: =IFERROR(__xludf.DUMMYFUNCTION("""COMPUTED_VALUE"""),"0,0,0,0,0,0") -> 0,0,0,0,0,0 | O5: =IFERROR(__xludf.DUMMYFUNCTION("""COMPUTED_VALUE"""),"#N/A") -> #N/A | P5: =IFERROR(__xludf.DUMMYFUNCTION("""COMPUTED_VALUE"""),"0,0,0,0,0,0") -> 0,0,0,0,0,0 | Q5: =IFERROR(__xludf.DUMMYFUNCTION("""COMPUTED_VALUE"""),"1.5,0,1,0,0,0") -> 1.5,0,1,0,0,0 | R5: =IFERROR(__xludf.DUMMYFUNCTION("""COMPUTED_VALUE"""),"0,0,0,0,4.5,5.5") -> 0,0,0,0,4.5,5.5 | S5: =IFERROR(__xludf.DUMMYFUNCTION("""COMPUTED_VALUE"""),"0,2,2.5,2.5,0,0") -> 0,2,2.5,2.5,0,0 | T5: =IFERROR(__xludf.DUMMYFUNCTION("""COMPUTED_VALUE"""),"0,0,0,0,1.5,0") -> 0,0,0,0,1.5,0 | U5: =IFERROR(__xludf.DUMMYFUNCTION("""COMPUTED_VALUE"""),"4.5,0,0.5,0,0,0") -> 4.5,0,0.5,0,0,0 | V5: =IFERROR(__xludf.DUMMYFUNCTION("""COMPUTED_VALUE"""),",,,,,") -> ,,,,, | W5: =IFERROR(__xludf.DUMMYFUNCTION("""COMPUTED_VALUE"""),"1fnjyoidcVE3Yg85FHmTdFy4Wd_jCu9Cr") -> 1fnjyoidcVE3Yg85FHmTdFy4Wd_jCu9Cr
