Workbook

Sheet All
B1: Cupertino B | G1: Stanford OHS | L1: Mira Loma A | Q1: Saratoga B | V1: Mira Loma B | AA1: Saratoga A | AF1: Palo Alto A | AK1: Palo Alto B | AP1: Cupertino A
B2: Mithilesh | C2: Amitabh | D2: Namita | E2: Richard | F2: Shubhi | G2: Tanish | H2: Syaon | L2: Nipun | M2: Aditya | N2: Sarthak | O2: Shohom | Q2: Levana | R2: Nolan | S2: Arjun | T2: Warren | V2: Harish | W2: Elyas | X2: Tanay | Y2: Ashrith | AA2: Adam | AB2: Nilay | AC2: Anthony | AD2: Advaith | AF2: Carissa | AG2: Forrest | AH2: Johnathan | AI2: Atticus | AJ2: Matthew | AK2: Nathan | AL2: Jeremy | AM2: Johnathan | AN2: Jarvis | AO2: Claire | AP2: Aaditya | AQ2: Jake | AR2: Aditi | AS2: Minseo
B3: TRUE | C3: TRUE | D3: TRUE | E3: TRUE | F3: TRUE | G3: TRUE | H3: TRUE | I3: FALSE | J3: FALSE | K3: FALSE | L3: TRUE | M3: TRUE | N3: TRUE | O3: TRUE | P3: FALSE | Q3: TRUE | R3: FALSE | S3: TRUE | T3: FALSE | U3: FALSE | V3: TRUE | W3: TRUE | X3: TRUE | Y3: TRUE | Z3: FALSE | AA3: TRUE | AB3: TRUE | AC3: TRUE | AD3: TRUE | AE3: FALSE | AF3: TRUE | AG3: TRUE | AH3: TRUE | AI3: TRUE | AJ3: FALSE | AK3: TRUE | AL3: TRUE | AM3: TRUE | AN3: TRUE | AO3: TRUE | AP3: FALSE | AQ3: FALSE | AR3: FALSE | AS3: FALSE | AT3: FALSE
A4: X | D4: 4 | L4: 4 | W4: 4 | AM4: 4
A5: M | G5: 4 | M5: -4 | AB5: 4 | AG5: 4
A6: C | G6: 4 | L6: 4 | W6: 4 | AI6: 4
A7: E | L7: -4 | AC7: 4 | AI7: -4 | AL7: 4
A8: B | G8: 4 | M8: 4 | AA8: 4 | AH8: -4
A9: P | N9: 4 | V9: 4 | AK9: 4
A10: X | M10: 4 | AD10: 4
A11: M | AD11: 4 | AG11: 4
A12: C | G12: 4 | L12: 4 | X12: 4 | AG12: 4
A13: E | O13: 4 | AC13: 4 | AM13: 4
A14: B | M14: 4 | AC14: 4 | AO14: 4
A15: P | G15: 4 | O15: -4 | S15: 4 | AD15: 4 | AL15: 4
B16: TRUE | C16: TRUE | D16: TRUE | E16: TRUE | F16: TRUE | G16: TRUE | H16: TRUE | I16: FALSE | J16: FALSE | K16: FALSE | L16: TRUE | M16: TRUE | N16: TRUE | O16: TRUE | P16: FALSE | Q16: TRUE | R16: FALSE | S16: TRUE | T16: FALSE | U16: FALSE | V16: TRUE | W16: TRUE | X16: TRUE | Y16: TRUE | Z16: FALSE | AA16: TRUE | AB16: TRUE | AC16: TRUE | AD16: TRUE | AE16: FALSE | AF16: TRUE | AG16: TRUE | AH16: TRUE | AI16: TRUE | AJ16: FALSE | AK16: TRUE | AL16: TRUE | AM16: TRUE | AN16: TRUE | AO16: TRUE | AP16: FALSE | AQ16: FALSE | AR16: FALSE | AS16: FALSE | AT16: FALSE
A17: X | C17: -4 | G17: 4 | M17: 4 | AA17: 4 | AH17: 4
A18: M | L18: -4 | S18: 4 | AD18: 4 | AH18: 4
A19: C | G19: 4 | L19: -4 | X19: 4 | AH19: 4
A20: E | D20: 4 | M20: 4 | AC20: 4 | AL20: 4
A21: B | G21: 4 | M21: 4 | Y21: 4 | AH21: 4
A22: P | C22: 4 | O22: 4 | V22: 4 | AI22: 4 | AK22: -4
A23: X | O23: 4 | AC23: 4 | AL23: 4
A24: M | G24: 4 | M24: 4 | AB24: 4 | AG24: 4
A25: C | G25: 4 | M25: 4 | W25: 4 | AM25: 4
A26: E | G26: 4 | M26: 4 | AC26: 4 | AG26: 4
A27: B | M27: 4 | AD27: 4 | AH27: 4
A28: P | G28: 4 | M28: 4 | V28: 4 | AI28: 4
B31: Mira Loma B | G31: Palo Alto B | L31: Cupertino A | Q31: Stanford OHS | V31: Cupertino B | AA31: Saratoga B | AF31: Mira Loma A | AK31: Saratoga A | AP31: Palo Alto A
B32: Harish | C32: Elyas | D32: Tanay | E32: Ashrith | G32: Claire | H32: Jeremy | I32: Jarvis | J32: Nathan | K32: Jonathen | L32: Aaditya | M32: Jake | N32: Aditi | O32: Minseo | Q32: Tanish | R32: Syaon | V32: Mithilesh | W32: Amitabh | X32: Namita | Y32: Richard | Z32: Shubhi | AA32: Levana | AB32: Nolan | AC32: Arjun | AD32: Warren | AF32: Sholom | AG32: Sarthak | AH32: Nipun | AI32: Aditya | AL32: Anthony | AM32: Advaith | AN32: Nilay | AO32: Adam | AP32: Carissa | AQ32: Forrest | AR32: Johnathan | AS32: Atticus | AT32: Matthew
B33: TRUE | C33: TRUE | D33: TRUE | E33: TRUE | F33: FALSE | G33: TRUE | H33: TRUE | I33: TRUE | J33: TRUE | K33: TRUE | L33: TRUE | M33: TRUE | N33: TRUE | O33: TRUE | P33: FALSE | Q33: TRUE | R33: TRUE | S33: FALSE | T33: FALSE | U33: FALSE | V33: TRUE | W33: TRUE | X33: TRUE | Y33: TRUE | Z33: TRUE | AA33: TRUE | AB33: FALSE | AC33: TRUE | AD33: FALSE | AE33: FALSE | AF33: TRUE | AG33: TRUE | AH33: TRUE | AI33: TRUE | AJ33: FALSE | AK33: FALSE | AL33: TRUE | AM33: TRUE | AN33: TRUE | AO33: TRUE | AP33: FALSE | AQ33: FALSE | AR33: FALSE | AS33: FALSE | AT33: FALSE
A34: X | Q34: 4 | V34: 4 | AN34: 4
A35: M | D35: 4 | Q35: 4 | AA35: 4 | AF35: 4 | AM35: -4
A36: C | C36: 4 | M36: -4 | AA36: 4 | AH36: 4
A37: E | C37: 4 | L37: 4 | AI37: 4
A38: B | B38: 4 | M38: 4 | Z38: 4 | AI38: 4
A39: P | C39: 4 | M39: 4 | AA39: 4 | AI39: 4
A40: X | C40: 4 | M40: 4 | AH40: 4
A41: M | J41: 4 | M41: 4 | AN41: 4
A42: C | K42: 4 | M42: 4 | AH42: 4
...

Sheet Sorted
A1: =AM1 | B1: {=transpose(sort(transpose(All!A1:AT30),2,true))} -> Cupertino A | C1: Saratoga A | L1: Palo Alto A | P1: Mira Loma B | V1: Saratoga B | Y1: Cupertino B | AA1: Palo Alto B | AC1: Mira Loma A | AK1: Stanford OHS
A2: =AM2 | B2: Aaditya | C2: Adam | D2: Aditi | E2: Aditya | F2: Advaith | G2: Amitabh | H2: Anthony | I2: Arjun | J2: Ashrith | K2: Atticus | L2: Carissa | M2: Claire | N2: Elyas | O2: Forrest | P2: Harish | Q2: Jake | R2: Jarvis | S2: Jeremy | T2: Johnathan | U2: Johnathan | V2: Levana | W2: Matthew | X2: Minseo | Y2: Mithilesh | Z2: Namita | AA2: Nathan | AB2: Nilay | AC2: Nipun | AD2: Nolan | AE2: Richard | AF2: Sarthak | AG2: Shohom | AH2: Shubhi | AI2: Syaon | AJ2: Tanay | AK2: Tanish | AL2: Warren
A3: =AM3 | B3: FALSE | C3: TRUE | D3: FALSE | E3: TRUE | F3: TRUE | G3: TRUE | H3: TRUE | I3: TRUE | J3: TRUE | K3: TRUE | L3: TRUE | M3: TRUE | N3: TRUE | O3: TRUE | P3: TRUE | Q3: FALSE | R3: TRUE | S3: TRUE | T3: TRUE | U3: TRUE | V3: TRUE | W3: FALSE | X3: FALSE | Y3: TRUE | Z3: TRUE | AA3: TRUE | AB3: TRUE | AC3: TRUE | AD3: FALSE | AE3: TRUE | AF3: TRUE | AG3: TRUE | AH3: TRUE | AI3: TRUE | AJ3: TRUE | AK3: TRUE | AL3: FALSE | AN3: FALSE | AO3: FALSE | AP3: FALSE | AQ3: FALSE | AR3: FALSE | AS3: FALSE | AT3: FALSE | AU3: FALSE
A4: =AM4 -> X | N4: 4 | U4: 4 | Z4: 4 | AC4: 4 | AM4: X
A5: =AM5 -> M | E5: -4 | O5: 4 | AB5: 4 | AK5: 4 | AM5: M
A6: =AM6 -> C | K6: 4 | N6: 4 | AC6: 4 | AK6: 4 | AM6: C
A7: =AM7 -> E | H7: 4 | K7: -4 | S7: 4 | AC7: -4 | AM7: E
A8: =AM8 -> B | C8: 4 | E8: 4 | T8: -4 | AK8: 4 | AM8: B
A9: =AM9 -> P | P9: 4 | AA9: 4 | AF9: 4 | AM9: P
A10: =AM10 -> X | E10: 4 | F10: 4 | AM10: X
A11: =AM11 -> M | F11: 4 | O11: 4 | AM11: M
A12: =AM12 -> C | O12: 4 | AC12: 4 | AJ12: 4 | AK12: 4 | AM12: C
A13: =AM13 -> E | H13: 4 | U13: 4 | AG13: 4 | AM13: E
A14: =AM14 -> B | E14: 4 | H14: 4 | M14: 4 | AM14: B
A15: =AM15 -> P | F15: 4 | I15: 4 | S15: 4 | AG15: -4 | AK15: 4 | AM15: P
A16: =AM16 | B16: FALSE | C16: TRUE | D16: FALSE | E16: TRUE | F16: TRUE | G16: TRUE | H16: TRUE | I16: TRUE | J16: TRUE | K16: TRUE | L16: TRUE | M16: TRUE | N16: TRUE | O16: TRUE | P16: TRUE | Q16: FALSE | R16: TRUE | S16: TRUE | T16: TRUE | U16: TRUE | V16: TRUE | W16: FALSE | X16: FALSE | Y16: TRUE | Z16: TRUE | AA16: TRUE | AB16: TRUE | AC16: TRUE | AD16: FALSE | AE16: TRUE | AF16: TRUE | AG16: TRUE | AH16: TRUE | AI16: TRUE | AJ16: TRUE | AK16: TRUE | AL16: FALSE | AN16: FALSE | AO16: FALSE | AP16: FALSE | AQ16: FALSE | AR16: FALSE | AS16: FALSE | AT16: FALSE | AU16: FALSE
A17: =AM17 -> X | C17: 4 | E17: 4 | G17: -4 | T17: 4 | AK17: 4 | AM17: X
A18: =AM18 -> M | F18: 4 | I18: 4 | T18: 4 | AC18: -4 | AM18: M
A19: =AM19 -> C | T19: 4 | AC19: -4 | AJ19: 4 | AK19: 4 | AM19: C
A20: =AM20 -> E | E20: 4 | H20: 4 | S20: 4 | Z20: 4 | AM20: E
A21: =AM21 -> B | E21: 4 | J21: 4 | T21: 4 | AK21: 4 | AM21: B
A22: =AM22 -> P | G22: 4 | K22: 4 | P22: 4 | AA22: -4 | AG22: 4 | AM22: P
A23: =AM23 -> X | H23: 4 | S23: 4 | AG23: 4 | AM23: X
A24: =AM24 -> M | E24: 4 | O24: 4 | AB24: 4 | AK24: 4 | AM24: M
A25: =AM25 -> C | E25: 4 | N25: 4 | U25: 4 | AK25: 4 | AM25: C
A26: =AM26 -> E | E26: 4 | H26: 4 | O26: 4 | AK26: 4 | AM26: E
A27: =AM27 -> B | E27: 4 | F27: 4 | T27: 4 | AM27: B
A28: =AM28 -> P | E28: 4 | K28: 4 | P28: 4 | AK28: 4 | AM28: P
A29: =AM29
A30: =AM30
A31: =AM31 | B31: {=transpose(sort(transpose(All!A31:AT60),2,true))} -> Cupertino A | L31: Palo Alto A | M31: Palo Alto B | P31: Mira Loma B | V31: Saratoga B | Y31: Cupertino B | AG31: Mira Loma A | AK31: Stanford OHS | AU31: Saratoga A
A32: =AM32 | B32: Aaditya | C32: Adam | D32: Aditi | E32: Aditya | F32: Advaith | G32: Amitabh | H32: Anthony | I32: Arjun | J32: Ashrith | K32: Atticus | L32: Carissa | M32: Claire | N32: Elyas | O32: Forrest | P32: Harish | Q32: Jake | R32: Jarvis | S32: Jeremy | T32: Johnathan | U32: Jonathen | V32: Levana | W32: Matthew | X32: Minseo | Y32: Mithilesh | Z32: Namita | AA32: Nathan | AB32: Nilay | AC32: Nipun | AD32: Nolan | AE32: Richard | AF32: Sarthak | AG32: Sholom | AH32: Shubhi | AI32: Syaon | AJ32: Tanay | AK32: Tanish | AL32: Warren
A33: =AM33 | B33: TRUE | C33: TRUE | D33: TRUE | E33: TRUE | F33: TRUE | G33: TRUE | H33: TRUE | I33: TRUE | J33: TRUE | K33: FALSE | L33: FALSE | M33: TRUE | N33: TRUE | O33: FALSE | P33: TRUE | Q33: TRUE | R33: TRUE | S33: TRUE | T33: FALSE | U33: TRUE | V33: TRUE | W33: FALSE | X33: TRUE | Y33: TRUE | Z33: TRUE | AA33: TRUE | AB33: TRUE | AC33: TRUE | AD33: FALSE | AE33: TRUE | AF33: TRUE | AG33: TRUE | AH33: TRUE | AI33: TRUE | AJ33: TRUE | AK33: TRUE | AL33: FALSE | AN33: FALSE | AO33: FALSE | AP33: FALSE | AQ33: FALSE | AR33: FALSE | AS33: FALSE | AT33: FALSE | AU33: FALSE
A34: =AM34 -> X | Y34: 4 | AB34: 4 | AK34: 4 | AM34: X
A35: =AM35 -> M | F35: -4 | V35: 4 | AG35: 4 | AJ35: 4 | AK35: 4 | AM35: M
A36: =AM36 -> C | N36: 4 | Q36: -4 | V36: 4 | AC36: 4 | AM36: C
A37: =AM37 -> E | B37: 4 | E37: 4 | N37: 4 | AM37: E
A38: =AM38 -> B | E38: 4 | P38: 4 | Q38: 4 | AH38: 4 | AM38: B
A39: =AM39 -> P | E39: 4 | N39: 4 | Q39: 4 | V39: 4 | AM39: P
A40: =AM40 -> X | N40: 4 | Q40: 4 | AC40: 4 | AM40: X
...

Sheet Full
A1: Cupertino B | B1: Cupertino B | C1: Stanford OHS | D1: Stanford OHS | E1: Mira Loma A | F1: Mira Loma A | G1: Saratoga B | H1: Saratoga B | I1: Mira Loma B | J1: Mira Loma B | K1: Saratoga A | L1: Saratoga A | M1: Palo Alto A | N1: Palo Alto A | O1: Palo Alto B | P1: Palo Alto B | Q1: Cupertino A | R1: Cupertino A
A2: Bonus | B2: Score | C2: Bonus | D2: Score | E2: Bonus | F2: Score | G2: Bonus | H2: Score | I2: Bonus | J2: Score | K2: Bonus | L2: Score | M2: Bonus | N2: Score | O2: Bonus | P2: Score | Q2: Bonus | R2: Score
A4: 0 | B4: 4 | D4: 0 | E4: 0 | F4: 4 | H4: 0 | I4: 0 | J4: 4 | L4: 0 | N4: 0 | P4: 4
B5: 4 | C5: 10 | D5: 14 | F5: 4 | H5: 4 | J5: 4 | K5: 10 | L5: 14 | M5: 10 | N5: 14 | P5: 4
B6: 4 | C6: 0 | D6: 18 | E6: 10 | F6: 18 | H6: 4 | I6: 10 | J6: 18 | L6: 14 | M6: 10 | N6: 28 | P6: 4
B7: 4 | D7: 18 | F7: 18 | H7: 8 | J7: 18 | K7: 10 | L7: 28 | N7: 28 | O7: 10 | P7: 22
B8: 4 | C8: 10 | D8: 32 | E8: 10 | F8: 32 | H8: 8 | J8: 18 | K8: 10 | L8: 42 | N8: 28 | P8: 26
B9: 4 | D9: 32 | E9: 10 | F9: 46 | H9: 8 | I9: 10 | J9: 32 | L9: 42 | N9: 28 | O9: 0 | P9: 30
B10: 4 | D10: 32 | E10: 10 | F10: 60 | H10: 8 | J10: 32 | K10: 10 | L10: 56 | N10: 28 | P10: 30
B11: 4 | D11: 32 | F11: 60 | H11: 8 | J11: 32 | K11: 10 | L11: 70 | M11: 10 | N11: 42 | P11: 30
B12: 4 | C12: 0 | D12: 36 | E12: 10 | F12: 74 | H12: 8 | I12: 10 | J12: 46 | L12: 70 | M12: 10 | N12: 56 | P12: 30
B13: 4 | D13: 36 | E13: 0 | F13: 78 | H13: 8 | J13: 46 | K13: 10 | L13: 84 | N13: 56 | O13: 10 | P13: 44
B14: 4 | D14: 36 | E14: 10 | F14: 92 | H14: 8 | J14: 46 | K14: 10 | L14: 98 | N14: 56 | O14: 0 | P14: 48
B15: 4 | C15: 0 | D15: 40 | F15: 92 | G15: 0 | H15: 16 | J15: 46 | K15: 10 | L15: 112 | N15: 56 | O15: 0 | P15: 52
B17: 4 | C17: 10 | D17: 58 | E17: 10 | F17: 106 | H17: 16 | J17: 46 | K17: 10 | L17: 126 | M17: 10 | N17: 70 | P17: 52
B18: 4 | D18: 58 | F18: 106 | G18: 10 | H18: 34 | J18: 46 | K18: 10 | L18: 140 | M18: 10 | N18: 84 | P18: 52
B19: 4 | C19: 0 | D19: 62 | F19: 106 | H19: 38 | I19: 10 | J19: 60 | L19: 140 | M19: 10 | N19: 98 | P19: 52
A20: 0 | B20: 8 | D20: 62 | E20: 10 | F20: 120 | H20: 38 | J20: 60 | K20: 0 | L20: 144 | N20: 98 | O20: 10 | P20: 66
B21: 8 | C21: 10 | D21: 76 | E21: 10 | F21: 134 | H21: 38 | I21: 10 | J21: 74 | L21: 144 | M21: 10 | N21: 112 | P21: 66
A22: 0 | B22: 12 | D22: 76 | E22: 0 | F22: 138 | H22: 38 | I22: 0 | J22: 78 | L22: 144 | M22: 10 | N22: 130 | P22: 66
B23: 12 | D23: 76 | E23: 10 | F23: 152 | H23: 38 | J23: 78 | K23: 0 | L23: 148 | N23: 130 | P23: 70
B24: 12 | C24: 10 | D24: 90 | E24: 10 | F24: 166 | H24: 38 | J24: 78 | K24: 10 | L24: 162 | M24: 10 | N24: 144 | P24: 70
B25: 12 | C25: 10 | D25: 104 | E25: 10 | F25: 180 | H25: 38 | I25: 10 | J25: 92 | L25: 162 | N25: 144 | O25: 0 | P25: 74
B26: 12 | C26: 0 | D26: 108 | E26: 10 | F26: 194 | H26: 38 | J26: 92 | K26: 10 | L26: 176 | M26: 10 | N26: 158 | P26: 74
B27: 12 | D27: 108 | E27: 10 | F27: 208 | H27: 38 | J27: 92 | K27: 0 | L27: 180 | M27: 0 | N27: 162 | P27: 74
B28: 12 | C28: 0 | D28: 112 | E28: 10 | F28: 222 | H28: 38 | I28: 10 | J28: 106 | L28: 180 | M28: 10 | N28: 176 | P28: 74
A31: Mira Loma B | B31: Mira Loma B | C31: Palo Alto B | D31: Palo Alto B | E31: Cupertino A | F31: Cupertino A | G31: Stanford OHS | H31: Stanford OHS | I31: Cupertino B | J31: Cupertino B | K31: Saratoga B | L31: Saratoga B | M31: Mira Loma A | N31: Mira Loma A | O31: Saratoga A | P31: Saratoga A | Q31: Palo Alto A | R31: Palo Alto A
A32: Bonus | B32: Score | C32: Bonus | D32: Score | E32: Bonus | F32: Score | G32: Bonus | H32: Score | I32: Bonus | J32: Score | K32: Bonus | L32: Score | M32: Bonus | N32: Score | O32: Bonus | P32: Score | Q32: Bonus | R32: Score
B34: 0 | D34: 0 | F34: 0 | G34: 0 | H34: 4 | I34: 10 | J34: 14 | L34: 0 | N34: 0 | O34: 10 | P34: 14
A35: 10 | B35: 14 | D35: 0 | F35: 0 | G35: 10 | H35: 18 | J35: 14 | K35: 10 | L35: 14 | M35: 10 | N35: 18 | P35: 14
A36: 10 | B36: 28 | D36: 0 | F36: 0 | H36: 22 | J36: 14 | K36: 10 | L36: 28 | M36: 10 | N36: 32 | P36: 14
A37: 10 | B37: 42 | D37: 0 | E37: 10 | F37: 14 | H37: 22 | J37: 14 | L37: 28 | M37: 10 | N37: 46 | P37: 14
A38: 0 | B38: 46 | D38: 0 | E38: 0 | F38: 18 | H38: 22 | I38: 0 | J38: 18 | L38: 28 | M38: 0 | N38: 50 | P38: 14
A39: 0 | B39: 50 | D39: 0 | E39: 0 | F39: 22 | H39: 22 | J39: 18 | K39: 0 | L39: 32 | M39: 0 | N39: 54 | P39: 14
A40: 10 | B40: 64 | D40: 0 | E40: 0 | F40: 26 | H40: 22 | J40: 18 | L40: 32 | M40: 10 | N40: 68 | P40: 14
B41: 64 | C41: 0 | D41: 4 | E41: 10 | F41: 40 | H41: 22 | J41: 18 | L41: 32 | N41: 68 | O41: 10 | P41: 28
B42: 64 | C42: 10 | D42: 18 | E42: 10 | F42: 54 | H42: 22 | J42: 18 | L42: 32 | M42: 10 | N42: 82 | P42: 28
B43: 64 | C43: 0 | D43: 22 | E43: 0 | F43: 58 | H43: 22 | J43: 18 | L43: 32 | N43: 82 | O43: 10 | P43: 46
B44: 64 | D44: 22 | E44: 10 | F44: 72 | H44: 22 | J44: 18 | L44: 32 | M44: 10 | N44: 96 | P44: 46
B45: 64 | C45: 0 | D45: 26 | F45: 72 | G45: 10 | H45: 36 | J45: 18 | L45: 32 | M45: 10 | N45: 110 | P45: 46
...

Sheet Sorted Team
B1: {=transpose(sort(transpose(Full!A1:R30),1,true))} -> Cupertino A | C1: Cupertino A | D1: Cupertino B | E1: Cupertino B | F1: Mira Loma A | G1: Mira Loma A | H1: Mira Loma B | I1: Mira Loma B | J1: Palo Alto A | K1: Palo Alto A | L1: Palo Alto B | M1: Palo Alto B | N1: Saratoga A | O1: Saratoga A | P1: Saratoga B | Q1: Saratoga B | R1: Stanford OHS | S1: Stanford OHS
B2: Bonus | C2: Score | D2: Bonus | E2: Score | F2: Bonus | G2: Score | H2: Bonus | I2: Score | J2: Bonus | K2: Score | L2: Bonus | M2: Score | N2: Bonus | O2: Score | P2: Bonus | Q2: Score | R2: Bonus | S2: Score
A4: X | D4: 0 | E4: 4 | F4: 0 | G4: 4 | H4: 0 | I4: 4 | K4: 0 | M4: 4 | O4: 0 | Q4: 0 | S4: 0
A5: M | E5: 4 | G5: 4 | I5: 4 | J5: 10 | K5: 14 | M5: 4 | N5: 10 | O5: 14 | Q5: 4 | R5: 10 | S5: 14
A6: C | E6: 4 | F6: 10 | G6: 18 | H6: 10 | I6: 18 | J6: 10 | K6: 28 | M6: 4 | O6: 14 | Q6: 4 | R6: 0 | S6: 18
A7: E | E7: 4 | G7: 18 | I7: 18 | K7: 28 | L7: 10 | M7: 22 | N7: 10 | O7: 28 | Q7: 8 | S7: 18
A8: B | E8: 4 | F8: 10 | G8: 32 | I8: 18 | K8: 28 | M8: 26 | N8: 10 | O8: 42 | Q8: 8 | R8: 10 | S8: 32
A9: P | E9: 4 | F9: 10 | G9: 46 | H9: 10 | I9: 32 | K9: 28 | L9: 0 | M9: 30 | O9: 42 | Q9: 8 | S9: 32
A10: X | E10: 4 | F10: 10 | G10: 60 | I10: 32 | K10: 28 | M10: 30 | N10: 10 | O10: 56 | Q10: 8 | S10: 32
A11: M | E11: 4 | G11: 60 | I11: 32 | J11: 10 | K11: 42 | M11: 30 | N11: 10 | O11: 70 | Q11: 8 | S11: 32
A12: C | E12: 4 | F12: 10 | G12: 74 | H12: 10 | I12: 46 | J12: 10 | K12: 56 | M12: 30 | O12: 70 | Q12: 8 | R12: 0 | S12: 36
A13: E | E13: 4 | F13: 0 | G13: 78 | I13: 46 | K13: 56 | L13: 10 | M13: 44 | N13: 10 | O13: 84 | Q13: 8 | S13: 36
A14: B | E14: 4 | F14: 10 | G14: 92 | I14: 46 | K14: 56 | L14: 0 | M14: 48 | N14: 10 | O14: 98 | Q14: 8 | S14: 36
A15: P | E15: 4 | G15: 92 | I15: 46 | K15: 56 | L15: 0 | M15: 52 | N15: 10 | O15: 112 | P15: 0 | Q15: 16 | R15: 0 | S15: 40
A17: X | E17: 4 | F17: 10 | G17: 106 | I17: 46 | J17: 10 | K17: 70 | M17: 52 | N17: 10 | O17: 126 | Q17: 16 | R17: 10 | S17: 58
A18: M | E18: 4 | G18: 106 | I18: 46 | J18: 10 | K18: 84 | M18: 52 | N18: 10 | O18: 140 | P18: 10 | Q18: 34 | S18: 58
A19: C | E19: 4 | G19: 106 | H19: 10 | I19: 60 | J19: 10 | K19: 98 | M19: 52 | O19: 140 | Q19: 38 | R19: 0 | S19: 62
A20: E | D20: 0 | E20: 8 | F20: 10 | G20: 120 | I20: 60 | K20: 98 | L20: 10 | M20: 66 | N20: 0 | O20: 144 | Q20: 38 | S20: 62
A21: B | E21: 8 | F21: 10 | G21: 134 | H21: 10 | I21: 74 | J21: 10 | K21: 112 | M21: 66 | O21: 144 | Q21: 38 | R21: 10 | S21: 76
A22: P | D22: 0 | E22: 12 | F22: 0 | G22: 138 | H22: 0 | I22: 78 | J22: 10 | K22: 130 | M22: 66 | O22: 144 | Q22: 38 | S22: 76
A23: X | E23: 12 | F23: 10 | G23: 152 | I23: 78 | K23: 130 | M23: 70 | N23: 0 | O23: 148 | Q23: 38 | S23: 76
A24: M | E24: 12 | F24: 10 | G24: 166 | I24: 78 | J24: 10 | K24: 144 | M24: 70 | N24: 10 | O24: 162 | Q24: 38 | R24: 10 | S24: 90
A25: C | E25: 12 | F25: 10 | G25: 180 | H25: 10 | I25: 92 | K25: 144 | L25: 0 | M25: 74 | O25: 162 | Q25: 38 | R25: 10 | S25: 104
A26: E | E26: 12 | F26: 10 | G26: 194 | I26: 92 | J26: 10 | K26: 158 | M26: 74 | N26: 10 | O26: 176 | Q26: 38 | R26: 0 | S26: 108
A27: B | E27: 12 | F27: 10 | G27: 208 | I27: 92 | J27: 0 | K27: 162 | M27: 74 | N27: 0 | O27: 180 | Q27: 38 | S27: 108
A28: P | E28: 12 | F28: 10 | G28: 222 | H28: 10 | I28: 106 | J28: 10 | K28: 176 | M28: 74 | O28: 180 | Q28: 38 | R28: 0 | S28: 112
B31: {=transpose(sort(transpose(Full!A31:R60),1,true))} -> Cupertino A | C31: Cupertino A | D31: Cupertino B | E31: Cupertino B | F31: Mira Loma A | G31: Mira Loma A | H31: Mira Loma B | I31: Mira Loma B | J31: Palo Alto A | K31: Palo Alto A | L31: Palo Alto B | M31: Palo Alto B | N31: Saratoga A | O31: Saratoga A | P31: Saratoga B | Q31: Saratoga B | R31: Stanford OHS | S31: Stanford OHS
B32: Bonus | C32: Score | D32: Bonus | E32: Score | F32: Bonus | G32: Score | H32: Bonus | I32: Score | J32: Bonus | K32: Score | L32: Bonus | M32: Score | N32: Bonus | O32: Score | P32: Bonus | Q32: Score | R32: Bonus | S32: Score
A34: X | C34: 0 | D34: 10 | E34: 14 | G34: 0 | I34: 0 | M34: 0 | N34: 10 | O34: 14 | Q34: 0 | R34: 0 | S34: 4
A35: M | C35: 0 | E35: 14 | F35: 10 | G35: 18 | H35: 10 | I35: 14 | M35: 0 | O35: 14 | P35: 10 | Q35: 14 | R35: 10 | S35: 18
A36: C | C36: 0 | E36: 14 | F36: 10 | G36: 32 | H36: 10 | I36: 28 | M36: 0 | O36: 14 | P36: 10 | Q36: 28 | S36: 22
A37: E | B37: 10 | C37: 14 | E37: 14 | F37: 10 | G37: 46 | H37: 10 | I37: 42 | M37: 0 | O37: 14 | Q37: 28 | S37: 22
A38: B | B38: 0 | C38: 18 | D38: 0 | E38: 18 | F38: 0 | G38: 50 | H38: 0 | I38: 46 | M38: 0 | O38: 14 | Q38: 28 | S38: 22
A39: P | B39: 0 | C39: 22 | E39: 18 | F39: 0 | G39: 54 | H39: 0 | I39: 50 | M39: 0 | O39: 14 | P39: 0 | Q39: 32 | S39: 22
A40: X | B40: 0 | C40: 26 | E40: 18 | F40: 10 | G40: 68 | H40: 10 | I40: 64 | M40: 0 | O40: 14 | Q40: 32 | S40: 22
A41: M | B41: 10 | C41: 40 | E41: 18 | G41: 68 | I41: 64 | L41: 0 | M41: 4 | N41: 10 | O41: 28 | Q41: 32 | S41: 22
A42: C | B42: 10 | C42: 54 | E42: 18 | F42: 10 | G42: 82 | I42: 64 | L42: 10 | M42: 18 | O42: 28 | Q42: 32 | S42: 22
A43: E | B43: 0 | C43: 58 | E43: 18 | G43: 82 | I43: 64 | L43: 0 | M43: 22 | N43: 10 | O43: 46 | Q43: 32 | S43: 22
A44: B | B44: 10 | C44: 72 | E44: 18 | F44: 10 | G44: 96 | I44: 64 | M44: 22 | O44: 46 | Q44: 32 | S44: 22
A45: P | C45: 72 | E45: 18 | F45: 10 | G45: 110 | I45: 64 | L45: 0 | M45: 26 | O45: 46 | Q45: 32 | R45: 10 | S45: 36
...

Sheet Stats
A1: Player | B1: Team | C1: GP | D1: TU | E1: Neg | F1: TU/Neg | G1: Points | H1: PPG | I1: X TU | J1: X Neg | K1: X PPG | L1: M TU | M1: M Neg | N1: M PPG | O1: C TU | P1: C Neg | Q1: C PPG | R1: E TU | S1: E Neg | T1: E PPG | U1: B TU | V1: B Neg | W1: B PPG | X1: P TU | Y1: P Neg | Z1: P PPG
A2: Aditya | B2: Mira Loma A | C2: 10 | D2: 73 | E2: 23 | F2: 3.173913 | G2: 200 | H2: 20 | I2: 14 | J2: 6 | K2: 3.2 | L2: 7 | M2: 1 | N2: 2.4 | O2: 7 | P2: 3 | Q2: 1.6 | R2: 11 | S2: 4 | T2: 2.8 | U2: 26 | V2: 6 | W2: 8 | X2: 8 | Y2: 3 | Z2: 2
A3: Tanish | B3: Stanford OHS | C3: 8 | D3: 37 | E3: 5 | F3: 7.4 | G3: 128 | H3: 16 | I3: 6 | J3: 1 | K3: 2.5 | L3: 4 | M3: 1 | N3: 1.5 | O3: 9 | P3: 0 | Q3: 4.5 | R3: 4 | S3: 0 | T3: 2 | U3: 6 | V3: 0 | W3: 3 | X3: 8 | Y3: 3 | Z3: 2.5
A4: Jake | B4: Cupertino A | C4: 8 | D4: 34 | E4: 3 | F4: 11.333333 | G4: 124 | H4: 15.5 | I4: 5 | J4: 1 | K4: 2 | L4: 5 | M4: 1 | N4: 2 | O4: 4 | P4: 1 | Q4: 1.5 | R4: 11 | S4: 0 | T4: 5.5 | U4: 1 | V4: 0 | W4: 0.5 | X4: 8 | Y4: 0 | Z4: 4
A5: Aaditya | B5: Cupertino A | C5: 8 | D5: 34 | E5: 5 | F5: 6.8 | G5: 116 | H5: 14.5 | I5: 9 | J5: 2 | K5: 3.5 | L5: 1 | M5: 0 | N5: 0.5 | O5: 5 | P5: 0 | Q5: 2.5 | R5: 4 | S5: 1 | T5: 1.5 | U5: 13 | V5: 2 | W5: 5.5 | X5: 2 | Y5: 0 | Z5: 1
A6: Anthony | B6: Saratoga A | C6: 10 | D6: 39 | E6: 3 | F6: 13 | G6: 144 | H6: 14.4 | I6: 5 | J6: 0 | K6: 2 | L6: 2 | M6: 0 | N6: 0.8 | O6: 1 | P6: 0 | Q6: 0.4 | R6: 21 | S6: 2 | T6: 7.6 | U6: 3 | V6: 0 | W6: 1.2 | X6: 7 | Y6: 1 | Z6: 2.4
A7: Elyas | B7: Mira Loma B | C7: 8 | D7: 27 | E7: 4 | F7: 6.75 | G7: 92 | H7: 11.5 | I7: 5 | J7: 3 | K7: 1 | L7: 2 | M7: 0 | N7: 1 | O7: 10 | P7: 1 | Q7: 4.5 | R7: 3 | S7: 0 | T7: 1.5 | U7: 2 | V7: 0 | W7: 1 | X7: 5 | Y7: 0 | Z7: 2.5
A8: Arjun | B8: Saratoga B | C8: 8 | D8: 22 | E8: 0 | F8: Infinity | G8: 88 | H8: 11 | I8: 2 | J8: 0 | K8: 1 | L8: 5 | M8: 0 | N8: 2.5 | O8: 2 | P8: 0 | Q8: 1 | R8: 3 | S8: 0 | T8: 1.5 | U8: 9 | V8: 0 | W8: 4.5 | X8: 1 | Y8: 0 | Z8: 0.5
A9: Harish | B9: Mira Loma B | C9: 8 | D9: 25 | E9: 3 | F9: 8.3333333 | G9: 88 | H9: 11 | I9: 0 | J9: 0 | K9: 0 | L9: 10 | M9: 1 | N9: 4.5 | O9: 0 | P9: 0 | Q9: 0 | R9: 1 | S9: 0 | T9: 0.5 | U9: 2 | V9: 0 | W9: 1 | X9: 12 | Y9: 2 | Z9: 5
A10: Nilay | B10: Saratoga A | C10: 10 | D10: 32 | E10: 5 | F10: 6.4 | G10: 108 | H10: 10.8 | I10: 5 | J10: 0 | K10: 2 | L10: 16 | M10: 3 | N10: 5.2 | O10: 7 | P10: 1 | Q10: 2.4 | R10: 0 | S10: 0 | T10: 0 | U10: 0 | V10: 0 | W10: 0 | X10: 4 | Y10: 1 | Z10: 1.2
A11: Nipun | B11: Mira Loma A | C11: 10 | D11: 33 | E11: 6 | F11: 5.5 | G11: 108 | H11: 10.8 | I11: 3 | J11: 0 | K11: 1.2 | L11: 3 | M11: 1 | N11: 0.8 | O11: 20 | P11: 4 | Q11: 6.4 | R11: 6 | S11: 1 | T11: 2 | U11: 0 | V11: 0 | W11: 0 | X11: 1 | Y11: 0 | Z11: 0.4
A12: Johnathen | B12: Palo Alto A | C12: 8 | D12: 26 | E12: 5 | F12: 5.2 | G12: 84 | H12: 10.5 | I12: 9 | J12: 0 | K12: 4.5 | L12: 2 | M12: 1 | N12: 0.5 | O12: 4 | P12: 0 | Q12: 2 | R12: 1 | S12: 0 | T12: 0.5 | U12: 9 | V12: 4 | W12: 2.5 | X12: 1 | Y12: 0 | Z12: 0.5
A13: Advaith | B13: Saratoga A | C13: 10 | D13: 27 | E13: 5 | F13: 5.4 | G13: 88 | H13: 8.8 | I13: 5 | J13: 1 | K13: 1.6 | L13: 6 | M13: 1 | N13: 2 | O13: 5 | P13: 0 | Q13: 2 | R13: 1 | S13: 1 | T13: 0 | U13: 6 | V13: 1 | W13: 2 | X13: 4 | Y13: 1 | Z13: 1.2
A14: Atticus | B14: Palo Alto A | C14: 8 | D14: 18 | E14: 1 | F14: 18 | G14: 68 | H14: 8.5 | I14: 4 | J14: 0 | K14: 2 | L14: 3 | M14: 0 | N14: 1.5 | O14: 5 | P14: 0 | Q14: 2.5 | R14: 0 | S14: 1 | T14: -0.5 | U14: 1 | V14: 0 | W14: 0.5 | X14: 5 | Y14: 0 | Z14: 2.5
A15: Nolan | B15: Saratoga B | C15: 4 | D15: 8 | E15: 0 | F15: Infinity | G15: 32 | H15: 8 | I15: 1 | J15: 0 | K15: 1 | L15: 1 | M15: 0 | N15: 1 | O15: 0 | P15: 0 | Q15: 0 | R15: 1 | S15: 0 | T15: 1 | U15: 0 | V15: 0 | W15: 0 | X15: 5 | Y15: 0 | Z15: 5
A16: Forrest | B16: Palo Alto A | C16: 8 | D16: 16 | E16: 1 | F16: 16 | G16: 60 | H16: 7.5 | I16: 1 | J16: 0 | K16: 0.5 | L16: 5 | M16: 1 | N16: 2 | O16: 1 | P16: 0 | Q16: 0.5 | R16: 2 | S16: 0 | T16: 1 | U16: 1 | V16: 0 | W16: 0.5 | X16: 6 | Y16: 0 | Z16: 3
A17: Tanay | B17: Mira Loma B | C17: 8 | D17: 16 | E17: 1 | F17: 16 | G17: 60 | H17: 7.5 | I17: 1 | J17: 0 | K17: 0.5 | L17: 1 | M17: 0 | N17: 0.5 | O17: 8 | P17: 1 | Q17: 3.5 | R17: 5 | S17: 0 | T17: 2.5 | U17: 0 | V17: 0 | W17: 0 | X17: 1 | Y17: 0 | Z17: 0.5
A18: Adam | B18: Saratoga A | C18: 10 | D18: 18 | E18: 0 | F18: Infinity | G18: 72 | H18: 7.2 | I18: 8 | J18: 0 | K18: 3.2 | L18: 0 | M18: 0 | N18: 0 | O18: 1 | P18: 0 | Q18: 0.4 | R18: 0 | S18: 0 | T18: 0 | U18: 8 | V18: 0 | W18: 3.2 | X18: 1 | Y18: 0 | Z18: 0.4
A19: Ashrith | B19: Mira Loma B | C19: 8 | D19: 15 | E19: 2 | F19: 7.5 | G19: 52 | H19: 6.5 | I19: 0 | J19: 0 | K19: 0 | L19: 0 | M19: 0 | N19: 0 | O19: 1 | P19: 0 | Q19: 0.5 | R19: 4 | S19: 1 | T19: 1.5 | U19: 8 | V19: 1 | W19: 3.5 | X19: 2 | Y19: 0 | Z19: 1
A20: Mithilesh | B20: Cupertino B | C20: 8 | D20: 13 | E20: 1 | F20: 13 | G20: 48 | H20: 6 | I20: 2 | J20: 0 | K20: 1 | L20: 1 | M20: 0 | N20: 0.5 | O20: 7 | P20: 1 | Q20: 3 | R20: 2 | S20: 0 | T20: 1 | U20: 1 | V20: 0 | W20: 0.5 | X20: 0 | Y20: 0 | Z20: 0
A21: Shohom | B21: Mira Loma A | C21: 10 | D21: 23 | E21: 8 | F21: 2.875 | G21: 60 | H21: 6 | I21: 5 | J21: 1 | K21: 1.6 | L21: 1 | M21: 1 | N21: 0 | O21: 1 | P21: 0 | Q21: 0.4 | R21: 10 | S21: 0 | T21: 4 | U21: 0 | V21: 1 | W21: -0.4 | X21: 6 | Y21: 5 | Z21: 0.4
A22: Jonathen | B22: Palo Alto B | C22: 8 | D22: 11 | E22: 0 | F22: Infinity | G22: 44 | H22: 5.5 | I22: 1 | J22: 0 | K22: 0.5 | L22: 0 | M22: 0 | N22: 0 | O22: 5 | P22: 0 | Q22: 2.5 | R22: 4 | S22: 0 | T22: 2 | U22: 1 | V22: 0 | W22: 0.5 | X22: 0 | Y22: 0 | Z22: 0
A23: Levana | B23: Saratoga B | C23: 8 | D23: 10 | E23: 0 | F23: Infinity | G23: 40 | H23: 5 | I23: 0 | J23: 0 | K23: 0 | L23: 3 | M23: 0 | N23: 1.5 | O23: 6 | P23: 0 | Q23: 3 | R23: 0 | S23: 0 | T23: 0 | U23: 0 | V23: 0 | W23: 0 | X23: 1 | Y23: 0 | Z23: 0.5
A24: Aditi | B24: Cupertino A | C24: 8 | D24: 10 | E24: 1 | F24: 10 | G24: 36 | H24: 4.5 | I24: 0 | J24: 0 | K24: 0 | L24: 4 | M24: 0 | N24: 2 | O24: 1 | P24: 0 | Q24: 0.5 | R24: 0 | S24: 0 | T24: 0 | U24: 3 | V24: 0 | W24: 1.5 | X24: 2 | Y24: 1 | Z24: 0.5
A25: Jeremy | B25: Palo Alto B | C25: 8 | D25: 9 | E25: 0 | F25: Infinity | G25: 36 | H25: 4.5 | I25: 2 | J25: 0 | K25: 1 | L25: 0 | M25: 0 | N25: 0 | O25: 1 | P25: 0 | Q25: 0.5 | R25: 3 | S25: 0 | T25: 1.5 | U25: 0 | V25: 0 | W25: 0 | X25: 3 | Y25: 0 | Z25: 1.5
A26: Amitabh | B26: Cupertino B | C26: 8 | D26: 10 | E26: 3 | F26: 3.3333333 | G26: 28 | H26: 3.5 | I26: 0 | J26: 1 | K26: -0.5 | L26: 3 | M26: 0 | N26: 1.5 | O26: 0 | P26: 1 | Q26: -0.5 | R26: 1 | S26: 0 | T26: 0.5 | U26: 1 | V26: 0 | W26: 0.5 | X26: 5 | Y26: 1 | Z26: 2
A27: Carissa | B27: Palo Alto A | C27: 8 | D27: 7 | E27: 0 | F27: Infinity | G27: 28 | H27: 3.5 | I27: 2 | J27: 0 | K27: 1 | L27: 1 | M27: 0 | N27: 0.5 | O27: 2 | P27: 0 | Q27: 1 | R27: 1 | S27: 0 | T27: 0.5 | U27: 0 | V27: 0 | W27: 0 | X27: 1 | Y27: 0 | Z27: 0.5
A28: Minseo | B28: Cupertino A | C28: 8 | D28: 7 | E28: 0 | F28: Infinity | G28: 28 | H28: 3.5 | I28: 2 | J28: 0 | K28: 1 | L28: 2 | M28: 0 | N28: 1 | O28: 2 | P28: 0 | Q28: 1 | R28: 0 | S28: 0 | T28: 0 | U28: 1 | V28: 0 | W28: 0.5 | X28: 0 | Y28: 0 | Z28: 0
A29: Namita | B29: Cupertino B | C29: 8 | D29: 7 | E29: 0 | F29: Infinity | G29: 28 | H29: 3.5 | I29: 1 | J29: 0 | K29: 0.5 | L29: 0 | M29: 0 | N29: 0 | O29: 0 | P29: 0 | Q29: 0 | R29: 6 | S29: 0 | T29: 3 | U29: 0 | V29: 0 | W29: 0 | X29: 0 | Y29: 0 | Z29: 0
A30: Nathan | B30: Palo Alto B | C30: 8 | D30: 8 | E30: 1 | F30: 8 | G30: 28 | H30: 3.5 | I30: 1 | J30: 0 | K30: 0.5 | L30: 4 | M30: 0 | N30: 2 | O30: 0 | P30: 0 | Q30: 0 | R30: 0 | S30: 0 | T30: 0 | U30: 0 | V30: 0 | W30: 0 | X30: 3 | Y30: 1 | Z30: 1
A31: Shubhi | B31: Cupertino B | C31: 8 | D31: 3 | E31: 0 | F31: Infinity | G31: 12 | H31: 1.5 | I31: 0 | J31: 0 | K31: 0 | L31: 0 | M31: 0 | N31: 0 | O31: 0 | P31: 0 | Q31: 0 | R31: 0 | S31: 0 | T31: 0 | U31: 3 | V31: 0 | W31: 1.5 | X31: 0 | Y31: 0 | Z31: 0
A32: Syaon | B32: Stanford OHS | C32: 8 | D32: 3 | E32: 0 | F32: Infinity | G32: 12 | H32: 1.5 | I32: 1 | J32: 0 | K32: 0.5 | L32: 0 | M32: 0 | N32: 0 | O32: 0 | P32: 0 | Q32: 0 | R32: 1 | S32: 0 | T32: 0.5 | U32: 0 | V32: 0 | W32: 0 | X32: 1 | Y32: 0 | Z32: 0.5
A33: Claire | B33: Palo Alto B | C33: 8 | D33: 4 | E33: 2 | F33: 2 | G33: 8 | H33: 1 | I33: 1 | J33: 1 | K33: 0 | L33: 0 | M33: 0 | N33: 0 | O33: 0 | P33: 0 | Q33: 0 | R33: 0 | S33: 1 | T33: -0.5 | U33: 3 | V33: 0 | W33: 1.5 | X33: 0 | Y33: 0 | Z33: 0
A34: Sarthak | B34: Mira Loma A | C34: 10 | D34: 5 | E34: 3 | F34: 1.6666667 | G34: 8 | H34: 0.8 | I34: 0 | J34: 0 | K34: 0 | L34: 0 | M34: 0 | N34: 0 | O34: 0 | P34: 0 | Q34: 0 | R34: 0 | S34: 0 | T34: 0 | U34: 0 | V34: 0 | W34: 0 | X34: 5 | Y34: 3 | Z34: 0.8
A35: Richard | B35: Cupertino B | C35: 8 | D35: 1 | E35: 0 | F35: Infinity | G35: 4 | H35: 0.5 | I35: 0 | J35: 0 | K35: 0 | L35: 0 | M35: 0 | N35: 0 | O35: 1 | P35: 0 | Q35: 0.5 | R35: 0 | S35: 0 | T35: 0 | U35: 0 | V35: 0 | W35: 0 | X35: 0 | Y35: 0 | Z35: 0
A36: Jarvis | B36: Palo Alto B | C36: 8 | D36: 0 | E36: 0 | F36: Infinity | G36: 0 | H36: 0 | I36: 0 | J36: 0 | K36: 0 | L36: 0 | M36: 0 | N36: 0 | O36: 0 | P36: 0 | Q36: 0 | R36: 0 | S36: 0 | T36: 0 | U36: 0 | V36: 0 | W36: 0 | X36: 0 | Y36: 0 | Z36: 0

Sheet Team Stats
A1: Team | B1: PPG | C1: GP | D1: Bonus | E1: Bonus % | F1: X Bonus | G1: X Bonus % | H1: M Bonus | I1: M Bonus % | J1: C Bonus | K1: C Bonus % | L1: E Bonus | M1: E Bonus % | N1: B Bonus | O1: B Bonus % | P1: P Bonus | Q1: P Bonus %
A2: Mira Loma A | B2: 155.8 | C2: 8 | D2: 99 | E2: 0.7443609 | F2: 18 | G2: 0.81818182 | H2: 10 | I2: 0.90909091 | J2: 21 | K2: 0.75 | L2: 19 | M2: 0.7037037 | N2: 18 | O2: 0.72 | P2: 13 | Q2: 0.65
A3: Saratoga A | B3: 126 | C3: 8 | D3: 72 | E3: 0.62068966 | F3: 14 | G3: 0.60869565 | H3: 21 | I3: 0.875 | J3: 5 | K3: 0.35714286 | L3: 11 | M3: 0.5 | N3: 11 | O3: 0.64705882 | P3: 10 | Q3: 0.625
A4: Mira Loma B | B4: 105.25 | C4: 8 | D4: 49 | E4: 0.59036145 | F4: 3 | G4: 0.5 | H4: 6 | I4: 0.46153846 | J4: 16 | K4: 0.84210526 | L4: 5 | M4: 0.38461538 | N4: 6 | O4: 0.5 | P4: 13 | Q4: 0.65
A5: Cupertino A | B5: 104.25 | C5: 8 | D5: 45 | E5: 0.52941176 | F5: 10 | G5: 0.625 | H5: 8 | I5: 0.66666667 | J5: 5 | K5: 0.41666667 | L5: 7 | M5: 0.46666667 | N5: 9 | O5: 0.5 | P5: 6 | Q5: 0.5
A6: Palo Alto A | B6: 81.25 | C6: 8 | D6: 33 | E6: 0.49253731 | F6: 10 | G6: 0.625 | H6: 7 | I6: 0.63636364 | J6: 5 | K6: 0.41666667 | L6: 3 | M6: 0.75 | N6: 2 | O6: 0.18181818 | P6: 6 | Q6: 0.46153846
A7: Stanford OHS | B7: 50.5 | C7: 8 | D7: 22 | E7: 0.55 | F7: 3 | G7: 0.42857143 | H7: 3 | I7: 0.75 | J7: 4 | K7: 0.44444444 | L7: 3 | M7: 0.6 | N7: 3 | O7: 0.5 | P7: 6 | Q7: 0.66666667
A8: Cupertino B | B8: 37.5 | C8: 8 | D8: 12 | E8: 0.35294118 | F8: 1 | G8: 0.33333333 | H8: 3 | I8: 0.75 | J8: 1 | K8: 0.125 | L8: 4 | M8: 0.44444444 | N8: 2 | O8: 0.4 | P8: 1 | Q8: 0.2
A9: Palo Alto B | B9: 33.5 | C9: 8 | D9: 10 | E9: 0.33333333 | F9: 1 | G9: 0.33333333 | H9: 1 | I9: 0.25 | J9: 3 | K9: 0.5 | L9: 5 | M9: 0.71428571 | N9: 0 | O9: 0 | P9: 0 | Q9: 0
A10: Saratoga B | B10: 32.75 | C10: 8 | D10: 7 | E10: 0.175 | F10: 0 | G10: 0 | H10: 4 | I10: 0.44444444 | J10: 2 | K10: 0.25 | L10: 0 | M10: 0 | N10: 0 | O10: 0 | P10: 1 | Q10: 0.14285714

Sheet X-Risk
A1: {=sort(Stats!A1:A1000,Stats!K1:K1000,false)} -> Player | B1: {=sort(Stats!C1:C1000,Stats!K1:K1000,false)} -> GP | C1: {=sort(Stats!I1:K1000,Stats!K1:K1000,false)} -> X TU | D1: X Neg | E1: X PPG
A2: Johnathen | B2: 8 | C2: 9 | D2: 0 | E2: 4.5
A3: Aaditya | B3: 8 | C3: 9 | D3: 2 | E3: 3.5
A4: Aditya | B4: 10 | C4: 14 | D4: 6 | E4: 3.2
A5: Adam | B5: 10 | C5: 8 | D5: 0 | E5: 3.2
A6: Tanish | B6: 8 | C6: 6 | D6: 1 | E6: 2.5
A7: Jake | B7: 8 | C7: 5 | D7: 1 | E7: 2
A8: Anthony | B8: 10 | C8: 5 | D8: 0 | E8: 2
A9: Nilay | B9: 10 | C9: 5 | D9: 0 | E9: 2
A10: Atticus | B10: 8 | C10: 4 | D10: 0 | E10: 2
A11: Advaith | B11: 10 | C11: 5 | D11: 1 | E11: 1.6
A12: Shohom | B12: 10 | C12: 5 | D12: 1 | E12: 1.6
A13: Nipun | B13: 10 | C13: 3 | D13: 0 | E13: 1.2
... A36: Amitabh | B36: 8 | C36: 0 | D36: 1 | E36: -0.5

Sheet Math
A1: {=sort(Stats!A1:A1000,Stats!N1:N1000,false)} -> Player | B1: {=sort(Stats!C1:C1000,Stats!N1:N1000,false)} -> GP | C1: {=sort(Stats!L1:N1000,Stats!N1:N1000,false)} -> M TU | D1: M Neg | E1: M PPG
A2: Nilay | B2: 10 | C2: 16 | D2: 3 | E2: 5.2
A3: Harish | B3: 8 | C3: 10 | D3: 1 | E3: 4.5
A4: Arjun | B4: 8 | C4: 5 | D4: 0 | E4: 2.5
A5: Aditya | B5: 10 | C5: 7 | D5: 1 | E5: 2.4
A6: Jake | B6: 8 | C6: 5 | D6: 1 | E6: 2
A7: Advaith | B7: 10 | C7: 6 | D7: 1 | E7: 2
A8: Forrest | B8: 8 | C8: 5 | D8: 1 | E8: 2
A9: Aditi | B9: 8 | C9: 4 | D9: 0 | E9: 2
A10: Nathan | B10: 8 | C10: 4 | D10: 0 | E10: 2
A11: Tanish | B11: 8 | C11: 4 | D11: 1 | E11: 1.5
A12: Atticus | B12: 8 | C12: 3 | D12: 0 | E12: 1.5
A13: Levana | B13: 8 | C13: 3 | D13: 0 | E13: 1.5
... A36: Jarvis | B36: 8 | C36: 0 | D36: 0 | E36: 0

Sheet Chemistry
A1: {=sort(Stats!A1:A1000,Stats!Q1:Q1000,false)} -> Player | B1: {=sort(Stats!C1:C1000,Stats!Q1:Q1000,false)} -> GP | C1: {=sort(Stats!O1:Q1000,Stats!Q1:Q1000,false)} -> C TU | D1: C Neg | E1: C PPG
A2: Nipun | B2: 10 | C2: 20 | D2: 4 | E2: 6.4
A3: Tanish | B3: 8 | C3: 9 | D3: 0 | E3: 4.5
A4: Elyas | B4: 8 | C4: 10 | D4: 1 | E4: 4.5
A5: Tanay | B5: 8 | C5: 8 | D5: 1 | E5: 3.5
A6: Mithilesh | B6: 8 | C6: 7 | D6: 1 | E6: 3
A7: Levana | B7: 8 | C7: 6 | D7: 0 | E7: 3
A8: Aaditya | B8: 8 | C8: 5 | D8: 0 | E8: 2.5
A9: Atticus | B9: 8 | C9: 5 | D9: 0 | E9: 2.5
A10: Jonathen | B10: 8 | C10: 5 | D10: 0 | E10: 2.5
A11: Nilay | B11: 10 | C11: 7 | D11: 1 | E11: 2.4
A12: Johnathen | B12: 8 | C12: 4 | D12: 0 | E12: 2
A13: Advaith | B13: 10 | C13: 5 | D13: 0 | E13: 2
... A36: Amitabh | B36: 8 | C36: 0 | D36: 1 | E36: -0.5

Sheet EarthSpace
A1: {=sort(Stats!A1:A1000,Stats!T1:T1000,false)} -> Player | B1: {=sort(Stats!C1:C1000,Stats!T1:T1000,false)} -> GP | C1: {=sort(Stats!R1:T1000,Stats!T1:T1000,false)} -> E TU | D1: E Neg | E1: E PPG
A2: Anthony | B2: 10 | C2: 21 | D2: 2 | E2: 7.6
A3: Jake | B3: 8 | C3: 11 | D3: 0 | E3: 5.5
A4: Shohom | B4: 10 | C4: 10 | D4: 0 | E4: 4
A5: Namita | B5: 8 | C5: 6 | D5: 0 | E5: 3
A6: Aditya | B6: 10 | C6: 11 | D6: 4 | E6: 2.8
A7: Tanay | B7: 8 | C7: 5 | D7: 0 | E7: 2.5
A8: Tanish | B8: 8 | C8: 4 | D8: 0 | E8: 2
A9: Nipun | B9: 10 | C9: 6 | D9: 1 | E9: 2
A10: Jonathen | B10: 8 | C10: 4 | D10: 0 | E10: 2
A11: Aaditya | B11: 8 | C11: 4 | D11: 1 | E11: 1.5
A12: Elyas | B12: 8 | C12: 3 | D12: 0 | E12: 1.5
A13: Arjun | B13: 8 | C13: 3 | D13: 0 | E13: 1.5
... A36: Claire | B36: 8 | C36: 0 | D36: 1 | E36: -0.5

Sheet Biology
A1: {=sort(Stats!A1:A1000,Stats!W1:W1000,false)} -> Player | B1: {=sort(Stats!C1:C1000,Stats!W1:W1000,false)} -> GP | C1: {=sort(Stats!U1:W1000,Stats!W1:W1000,false)} -> B TU | D1: B Neg | E1: B PPG
A2: Aditya | B2: 10 | C2: 26 | D2: 6 | E2: 8
A3: Aaditya | B3: 8 | C3: 13 | D3: 2 | E3: 5.5
A4: Arjun | B4: 8 | C4: 9 | D4: 0 | E4: 4.5
A5: Ashrith | B5: 8 | C5: 8 | D5: 1 | E5: 3.5
A6: Adam | B6: 10 | C6: 8 | D6: 0 | E6: 3.2
A7: Tanish | B7: 8 | C7: 6 | D7: 0 | E7: 3
A8: Johnathen | B8: 8 | C8: 9 | D8: 4 | E8: 2.5
A9: Advaith | B9: 10 | C9: 6 | D9: 1 | E9: 2
A10: Aditi | B10: 8 | C10: 3 | D10: 0 | E10: 1.5
A11: Shubhi | B11: 8 | C11: 3 | D11: 0 | E11: 1.5
A12: Claire | B12: 8 | C12: 3 | D12: 0 | E12: 1.5
A13: Anthony | B13: 10 | C13: 3 | D13: 0 | E13: 1.2
... A36: Shohom | B36: 10 | C36: 0 | D36: 1 | E36: -0.4

Sheet Physics
A1: {=sort(Stats!A1:A1000,Stats!Z1:Z1000,false)} -> Player | B1: {=sort(Stats!C1:C1000,Stats!Z1:Z1000,false)} -> GP | C1: {=sort(Stats!X1:Z1000,Stats!Z1:Z1000,false)} -> P TU | D1: P Neg | E1: P PPG
A2: Harish | B2: 8 | C2: 12 | D2: 2 | E2: 5
A3: Nolan | B3: 4 | C3: 5 | D3: 0 | E3: 5
A4: Jake | B4: 8 | C4: 8 | D4: 0 | E4: 4
A5: Forrest | B5: 8 | C5: 6 | D5: 0 | E5: 3
A6: Tanish | B6: 8 | C6: 8 | D6: 3 | E6: 2.5
A7: Elyas | B7: 8 | C7: 5 | D7: 0 | E7: 2.5
A8: Atticus | B8: 8 | C8: 5 | D8: 0 | E8: 2.5
A9: Anthony | B9: 10 | C9: 7 | D9: 1 | E9: 2.4
A10: Aditya | B10: 10 | C10: 8 | D10: 3 | E10: 2
A11: Amitabh | B11: 8 | C11: 5 | D11: 1 | E11: 2
A12: Jeremy | B12: 8 | C12: 3 | D12: 0 | E12: 1.5
A13: Nilay | B13: 10 | C13: 4 | D13: 1 | E13: 1.2
... A36: Jarvis | B36: 8 | C36: 0 | D36: 0 | E36: 0
