Workbook
Name Group2: LiveScoresheet!$J$6:$O$11

Sheet Team List
A1: Teams
A2: Code | B2: Team | C2: Roster
A3: A1 | B3: Alabama School of Fine Arts 2 | C3: Advik S, Michael M, Shreyas K, Raymond L, Skylar B
A4: A2 | B4: Lynbrook 1 | C4: Sohil R, Selena Y, Jianyu W, Thomas W
A5: A3 | B5: California HS | C5: Vladislav K, Jishnu B, Vihaan T, Lucas C
A6: A4 | B6: Canyon Crest Academy 2 | C6: Ishank K, Dennis S, Kaden S, Shail B
A7: A5 | B7: North Hollywood 2 | C7: Charlotte C, Ilinca S, Nathaniel O, Soureesh T, Patrick L
A8: A6 | B8: Middleton | C8: Owen W, Harry J, Ray F, Arjun S, Li Y
A9: B1 | B9: Niskayuna | C9: Mihir K, Arjun R, Daniel Y, Aarush I, Andrew Z
A10: B2 | B10: Interlake 1 | C10: Daniel L, Aryan A, Evan W, Devesh A
A11: B3 | B11: Iolani High School 2 | C11: Keisuke K, Min S, Alex C, Donovan H, Chloe S
A12: B4 | B12: Arnold O. Beckman High School | C12: Diego P, Rayan M, Derrick C, Reza H
A13: B5 | B13: The Frazer School 1 | C13: James J, Michael W, Ajay S, Abhiram P, Anish P
... A44: G6 | B44: Lynbrook 2 | C44: Evan L, Chaas K, Shripriya K, Matthew Y, Kush G

Sheet RR Pairings and Schedule
A1: RR Pairings and Schedule
A3: RR Pairings | H3: Schedule (Times in PDT)
H5: TIME | J5: ROUND
A6: Avadavats
A7: ROOM | B7: RR1 | C7: RR2 | D7: RR3 | E7: RR4 | F7: RR5 | H7: 7:45 - 8:00 a.m. PDT | J7: OPENING CEREMONY
A8: Avadavats-1 | B8: A1 — A2 | C8: A4— A5 | D8: A2 — A3 | E8: A1 — A5 | F8: A3 — A4
A9: Avadavats-2 | B9: A3 — A5 | C9: A1 — A3 | D9: A5 — A6 | E9: A2 — A4 | F9: A1 — A6 | H9: 8:05 - 9:00 a.m. PDT | J9: Round Robin 1
A10: Avadavats-3 | B10: A4 — A6 | C10: A2 — A6 | D10: A1 — A4 | E10: A3 — A6 | F10: A2 — A5
H11: 9:00 - 9:40 a.m. PDT | J11: Round Robin 2
A12: Bellbirds
A13: ROOM | B13: RR1 | C13: RR2 | D13: RR3 | E13: RR4 | F13: RR5 | H13: 9:40 - 10:20 a.m. PDT | J13: Round Robin 3
A14: Bellbirds-1 | B14: B1 — B2 | C14: B4— B5 | D14: B2 — B3 | E14: B1 — B5 | F14: B3 — B4
A15: Bellbirds-2 | B15: B3 — B5 | C15: B1 — B3 | D15: B5 — B6 | E15: B2 — B4 | F15: B1 — B6 | H15: 10:20 - 11:00 a.m. PDT | J15: Round Robin 4
A16: Bellbirds-3 | B16: B4 — B6 | C16: B2 — B6 | D16: B1 — B4 | E16: B3 — B6 | F16: B2 — B5
H17: 11:00 - 11:40 a.m. PDT | J17: Round Robin 5
A18: Condors
A19: ROOM | B19: RR1 | C19: RR2 | D19: RR3 | E19: RR4 | F19: RR5 | H19: 11:40 - 12:20 p.m. PDT | J19: LUNCH BREAK
A20: Condors-1 | B20: C1 — C2 | C20: C4— C5 | D20: C2 — C3 | E20: C1 — C5 | F20: C3 — C4
A21: Condors-2 | B21: C3 — C5 | C21: C1 — C3 | D21: C5 — C6 | E21: C2 — C4 | F21: C1 — C6 | H21: 12:20 - 1:00 p.m. PDT | J21: Double Elimination 1 (top 16)
A22: Condors-3 | B22: C4 — C6 | C22: C2 — C6 | D22: C1 — C4 | E22: C3 — C6 | F22: C2 — C5
H23: 1:00 - 1:40 p.m. PDT | J23: Double Elimination 2 (top 12)
A24: Dovekies
A25: ROOM | B25: RR1 | C25: RR2 | D25: RR3 | E25: RR4 | F25: RR5 | H25: 1:40 - 2:20 p.m. PDT | J25: Double Elimination 3 (top 8)
A26: Dovekies-1 | B26: D1 — D2 | C26: D4— D5 | D26: D2 — D3 | E26: D1 — D5 | F26: D3 — D4
A27: Dovekies-2 | B27: D3 — D5 | C27: D1 — D3 | D27: D5 — D6 | E27: D2 — D4 | F27: D1 — D6 | H27: 2:20 - 2:50 p.m. PDT | J27: Double Elimination 4 (top 6)
A28: Dovekies-3 | B28: D4 — D6 | C28: D2 — D6 | D28: D1 — D4 | E28: D3 — D6 | F28: D2 — D5
H29: 2:50 - 3:20 p.m. PDT | J29: Double Elimination 5 (top 4)
A30: Egrets
A31: ROOM | B31: RR1 | C31: RR2 | D31: RR3 | E31: RR4 | F31: RR5 | H31: 3:20 - 3:30 p.m. PDT | J31: BREAK
A32: Egrets-1 | B32: E1 — E2 | C32: E4— E5 | D32: E2 — E3 | E32: E1 — E5 | F32: E3 — E4
A33: Egrets-2 | B33: E3 — E5 | C33: E1 — E3 | D33: E5 — E6 | E33: E2 — E4 | F33: E1 — E6 | H33: 3:30 - 4:00 p.m. PDT | J33: Double Elimination 6 (top 3)
A34: Egrets-3 | B34: E4 — E6 | C34: E2 — E6 | D34: E1 — E4 | E34: E3 — E6 | F34: E2 — E5
H35: 4:00 - 4:30 p.m. PDT | J35: Double Elimination 7 (top 2)
A36: Frigatebirds
A37: ROOM | B37: RR1 | C37: RR2 | D37: RR3 | E37: RR4 | F37: RR5 | H37: 4:30 - 5:00 p.m. PDT | J37: Double Elimination 8 (if necessary)
A38: Frigatebirds-1 | B38: F1 — F2 | C38: F4— F5 | D38: F2 — F3 | E38: F1 — F5 | F38: F3 — F4
A39: Frigatebirds-2 | B39: F3 — F5 | C39: F1 — F3 | D39: F5 — F6 | E39: F2 — F4 | F39: F1 — F6 | H39: 5:00 - 5:20 p.m. PDT | J39: CLOSING CEREMONY
A40: Frigatebirds-3 | B40: F4 — F6 | C40: F2 — F6 | D40: F1 — F4 | E40: F3 — F6 | F40: F2 — F5
A42: Godwits
A43: ROOM | B43: RR1 | C43: RR2 | D43: RR3 | E43: RR4 | F43: RR5
...

Sheet LiveScoresheet
A1: RR Live Scoresheet
A2: RR 1: 8:05-9:00 AM | D2: RR 2: 9:00-9:40 AM | G2: RR 3: 9:40-10:20 AM | J2: RR 4: 10:20-11:00 AM | M2: RR 5: 11:00-11:40 AM
A4: Avadavats | I4: Bellbirds
A5: =SUM(B6:G11) -> 2486 | B5: {=INDEX(A6,0)} -> A1 | C5: {=INDEX(A7,0)} -> A2 | D5: {=INDEX(A8,0)} -> A3 | E5: {=INDEX(A9,0)} -> A4 | F5: {=INDEX(A10,0)} -> A5 | G5: {=INDEX(A11,0)} -> A6 | I5: =SUM(J6:O11) -> 2744 | J5: {=INDEX(I6,0)} -> B1 | K5: {=INDEX(I7,0)} -> B2 | L5: {=INDEX(I8,0)} -> B3 | M5: {=INDEX(I9,0)} -> B4 | N5: {=INDEX(I10,0)} -> B5 | O5: {=INDEX(I11,0)} -> B6
A6: A1 | C6: =IFERROR(__xludf.DUMMYFUNCTION("IMPORTRANGE(""https://docs.google.com/spreadsheets/d/13_UcftIhRFc8Wdh5sQ-JghNmvplAeKYrOfyqerMoP4E/edit?gid=2010738230#gid=2010738230"",""A1 vs A2!K24"")"),44.0) -> 44 | D6: =IFERROR(__xludf.DUMMYFUNCTION("IMPORTRANGE(""https://docs.google.com/spreadsheets/d/1iErVLlc1_s37p2bIQGBV-ueQhrFErR8_rQgkEu4dw_A/edit?gid=1105689284#gid=1105689284"",""A1 vs A3!K24"")"),76.0) -> 76 | E6: =IFERROR(__xludf.DUMMYFUNCTION("IMPORTRANGE(""https://docs.google.com/spreadsheets/d/1gvVcUWK0DrU9Prr-pNKoq3-2DQjDQ1i9v2BBpB5lu8o/edit?gid=1105689284#gid=1105689284"",""A1 vs A4!K24"")"),34.0) -> 34 | F6: =IFERROR(__xludf.DUMMYFUNCTION("IMPORTRANGE(""https://docs.google.com/spreadsheets/d/1ZyVAgyLL_HCFyUsFR06BNJrd3d8klI6YuciQugxLR6o/edit?gid=1105689284#gid=1105689284"",""A1 vs A5!K24"")"),56.0) -> 56 | G6: =IFERROR(__xludf.DUMMYFUNCTION("IMPORTRANGE(""https://docs.google.com/spreadsheets/d/1Iv6yZlS3FQWzzgGpdJyYBvJdrkdMPqx_bl527u5CA1U/edit?gid=1105689284#gid=1105689284"",""A1 vs A6!K24"")"),16.0) -> 16 | I6: B1 | K6: =IFERROR(__xludf.DUMMYFUNCTION("IMPORTRANGE(""https://docs.google.com/spreadsheets/d/13_UcftIhRFc8Wdh5sQ-JghNmvplAeKYrOfyqerMoP4E/edit?gid=2010738230#gid=2010738230"",""B1 vs B2!K24"")"),120.0) -> 120 | L6: =IFERROR(__xludf.DUMMYFUNCTION("IMPORTRANGE(""https://docs.google.com/spreadsheets/d/1iErVLlc1_s37p2bIQGBV-ueQhrFErR8_rQgkEu4dw_A/edit?gid=1105689284#gid=1105689284"",""B1 vs B3!K24"")"),138.0) -> 138 | M6: =IFERROR(__xludf.DUMMYFUNCTION("IMPORTRANGE(""https://docs.google.com/spreadsheets/d/1gvVcUWK0DrU9Prr-pNKoq3-2DQjDQ1i9v2BBpB5lu8o/edit?gid=1105689284#gid=1105689284"",""B1 vs B4!K24"")"),70.0) -> 70 | N6: =IFERROR(__xludf.DUMMYFUNCTION("IMPORTRANGE(""https://docs.google.com/spreadsheets/d/1ZyVAgyLL_HCFyUsFR06BNJrd3d8klI6YuciQugxLR6o/edit?gid=1105689284#gid=1105689284"",""B1 vs B5!K24"")"),116.0) -> 116 | O6: =IFERROR(__xludf.DUMMYFUNCTION("IMPORTRANGE(""https://docs.google.com/spreadsheets/d/1Iv6yZlS3FQWzzgGpdJyYBvJdrkdMPqx_bl527u5CA1U/edit?gid=1105689284#gid=1105689284"",""B1 vs B6!K24"")"),116.0) -> 116
A7: A2 | B7: =IFERROR(__xludf.DUMMYFUNCTION("IMPORTRANGE(""https://docs.google.com/spreadsheets/d/13_UcftIhRFc8Wdh5sQ-JghNmvplAeKYrOfyqerMoP4E/edit?gid=2010738230#gid=2010738230"",""A1 vs A2!T24"")"),186.0) -> 186 | D7: =IFERROR(__xludf.DUMMYFUNCTION("IMPORTRANGE(""https://docs.google.com/spreadsheets/d/1gvVcUWK0DrU9Prr-pNKoq3-2DQjDQ1i9v2BBpB5lu8o/edit?gid=1105689284#gid=1105689284"",""A2 vs A3!K24"")"),156.0) -> 156 | E7: =IFERROR(__xludf.DUMMYFUNCTION("IMPORTRANGE(""https://docs.google.com/spreadsheets/d/1ZyVAgyLL_HCFyUsFR06BNJrd3d8klI6YuciQugxLR6o/edit?gid=1105689284#gid=1105689284"",""A2 vs A4!K24"")"),162.0) -> 162 | F7: =IFERROR(__xludf.DUMMYFUNCTION("IMPORTRANGE(""https://docs.google.com/spreadsheets/d/1Iv6yZlS3FQWzzgGpdJyYBvJdrkdMPqx_bl527u5CA1U/edit?gid=1105689284#gid=1105689284"",""A2 vs A5!K24"")"),208.0) -> 208 | G7: =IFERROR(__xludf.DUMMYFUNCTION("IMPORTRANGE(""https://docs.google.com/spreadsheets/d/1iErVLlc1_s37p2bIQGBV-ueQhrFErR8_rQgkEu4dw_A/edit?gid=1105689284#gid=1105689284"",""A2 vs A6!K24"")"),152.0) -> 152 | I7: B2 | J7: =IFERROR(__xludf.DUMMYFUNCTION("IMPORTRANGE(""https://docs.google.com/spreadsheets/d/13_UcftIhRFc8Wdh5sQ-JghNmvplAeKYrOfyqerMoP4E/edit?gid=2010738230#gid=2010738230"",""B1 vs B2!T24"")"),128.0) -> 128 | L7: =IFERROR(__xludf.DUMMYFUNCTION("IMPORTRANGE(""https://docs.google.com/spreadsheets/d/1gvVcUWK0DrU9Prr-pNKoq3-2DQjDQ1i9v2BBpB5lu8o/edit?gid=1105689284#gid=1105689284"",""B2 vs B3!K24"")"),140.0) -> 140 | M7: =IFERROR(__xludf.DUMMYFUNCTION("IMPORTRANGE(""https://docs.google.com/spreadsheets/d/1ZyVAgyLL_HCFyUsFR06BNJrd3d8klI6YuciQugxLR6o/edit?gid=1105689284#gid=1105689284"",""B2 vs B4!K24"")"),146.0) -> 146 | N7: =IFERROR(__xludf.DUMMYFUNCTION("IMPORTRANGE(""https://docs.google.com/spreadsheets/d/1Iv6yZlS3FQWzzgGpdJyYBvJdrkdMPqx_bl527u5CA1U/edit?gid=1105689284#gid=1105689284"",""B2 vs B5!K24"")"),62.0) -> 62 | O7: =IFERROR(__xludf.DUMMYFUNCTION("IMPORTRANGE(""https://docs.google.com/spreadsheets/d/1iErVLlc1_s37p2bIQGBV-ueQhrFErR8_rQgkEu4dw_A/edit?gid=1105689284#gid=1105689284"",""B2 vs B6!K24"")"),106.0) -> 106
A8: A3 | B8: =IFERROR(__xludf.DUMMYFUNCTION("IMPORTRANGE(""https://docs.google.com/spreadsheets/d/1iErVLlc1_s37p2bIQGBV-ueQhrFErR8_rQgkEu4dw_A/edit?gid=1105689284#gid=1105689284"",""A1 vs A3!T24"")"),44.0) -> 44 | C8: =IFERROR(__xludf.DUMMYFUNCTION("IMPORTRANGE(""https://docs.google.com/spreadsheets/d/1gvVcUWK0DrU9Prr-pNKoq3-2DQjDQ1i9v2BBpB5lu8o/edit?gid=1105689284#gid=1105689284"",""A2 vs A3!T24"")"),34.0) -> 34 | E8: =IFERROR(__xludf.DUMMYFUNCTION("IMPORTRANGE(""https://docs.google.com/spreadsheets/d/1Iv6yZlS3FQWzzgGpdJyYBvJdrkdMPqx_bl527u5CA1U/edit?gid=1105689284#gid=1105689284"",""A3 vs A4!K24"")"),36.0) -> 36 | F8: =IFERROR(__xludf.DUMMYFUNCTION("IMPORTRANGE(""https://docs.google.com/spreadsheets/d/13_UcftIhRFc8Wdh5sQ-JghNmvplAeKYrOfyqerMoP4E/edit?gid=2010738230#gid=2010738230"",""A3 vs A5!K24"")"),34.0) -> 34 | G8: =IFERROR(__xludf.DUMMYFUNCTION("IMPORTRANGE(""https://docs.google.com/spreadsheets/d/1ZyVAgyLL_HCFyUsFR06BNJrd3d8klI6YuciQugxLR6o/edit?gid=1105689284#gid=1105689284"",""A3 vs A6!K24"")"),30.0) -> 30 | I8: B3 | J8: =IFERROR(__xludf.DUMMYFUNCTION("IMPORTRANGE(""https://docs.google.com/spreadsheets/d/1iErVLlc1_s37p2bIQGBV-ueQhrFErR8_rQgkEu4dw_A/edit?gid=1105689284#gid=1105689284"",""B1 vs B3!T24"")"),92.0) -> 92 | K8: =IFERROR(__xludf.DUMMYFUNCTION("IMPORTRANGE(""https://docs.google.com/spreadsheets/d/1gvVcUWK0DrU9Prr-pNKoq3-2DQjDQ1i9v2BBpB5lu8o/edit?gid=1105689284#gid=1105689284"",""B2 vs B3!T24"")"),22.0) -> 22 | M8: =IFERROR(__xludf.DUMMYFUNCTION("IMPORTRANGE(""https://docs.google.com/spreadsheets/d/1Iv6yZlS3FQWzzgGpdJyYBvJdrkdMPqx_bl527u5CA1U/edit?gid=1105689284#gid=1105689284"",""B3 vs B4!K24"")"),66.0) -> 66 | N8: =IFERROR(__xludf.DUMMYFUNCTION("IMPORTRANGE(""https://docs.google.com/spreadsheets/d/13_UcftIhRFc8Wdh5sQ-JghNmvplAeKYrOfyqerMoP4E/edit?gid=2010738230#gid=2010738230"",""B3 vs B5!K24"")"),50.0) -> 50 | O8: =IFERROR(__xludf.DUMMYFUNCTION("IMPORTRANGE(""https://docs.google.com/spreadsheets/d/1ZyVAgyLL_HCFyUsFR06BNJrd3d8klI6YuciQugxLR6o/edit?gid=1105689284#gid=1105689284"",""B3 vs B6!K24"")"),54.0) -> 54
A9: A4 | B9: =IFERROR(__xludf.DUMMYFUNCTION("IMPORTRANGE(""https://docs.google.com/spreadsheets/d/1gvVcUWK0DrU9Prr-pNKoq3-2DQjDQ1i9v2BBpB5lu8o/edit?gid=1105689284#gid=1105689284"",""A1 vs A4!T24"")"),60.0) -> 60 | C9: =IFERROR(__xludf.DUMMYFUNCTION("IMPORTRANGE(""https://docs.google.com/spreadsheets/d/1ZyVAgyLL_HCFyUsFR06BNJrd3d8klI6YuciQugxLR6o/edit?gid=1105689284#gid=1105689284"",""A2 vs A4!T24"")"),16.0) -> 16 | D9: =IFERROR(__xludf.DUMMYFUNCTION("IMPORTRANGE(""https://docs.google.com/spreadsheets/d/1Iv6yZlS3FQWzzgGpdJyYBvJdrkdMPqx_bl527u5CA1U/edit?gid=1105689284#gid=1105689284"",""A3 vs A4!T24"")"),62.0) -> 62 | F9: =IFERROR(__xludf.DUMMYFUNCTION("IMPORTRANGE(""https://docs.google.com/spreadsheets/d/1iErVLlc1_s37p2bIQGBV-ueQhrFErR8_rQgkEu4dw_A/edit?gid=1105689284#gid=1105689284"",""A4 vs A5!K24"")"),90.0) -> 90 | G9: =IFERROR(__xludf.DUMMYFUNCTION("IMPORTRANGE(""https://docs.google.com/spreadsheets/d/13_UcftIhRFc8Wdh5sQ-JghNmvplAeKYrOfyqerMoP4E/edit?gid=2010738230#gid=2010738230"",""A4 vs A6!K24"")"),90.0) -> 90 | I9: B4 | J9: =IFERROR(__xludf.DUMMYFUNCTION("IMPORTRANGE(""https://docs.google.com/spreadsheets/d/1gvVcUWK0DrU9Prr-pNKoq3-2DQjDQ1i9v2BBpB5lu8o/edit?gid=1105689284#gid=1105689284"",""B1 vs B4!T24"")"),42.0) -> 42 | K9: =IFERROR(__xludf.DUMMYFUNCTION("IMPORTRANGE(""https://docs.google.com/spreadsheets/d/1ZyVAgyLL_HCFyUsFR06BNJrd3d8klI6YuciQugxLR6o/edit?gid=1105689284#gid=1105689284"",""B2 vs B4!T24"")"),16.0) -> 16 | L9: =IFERROR(__xludf.DUMMYFUNCTION("IMPORTRANGE(""https://docs.google.com/spreadsheets/d/1Iv6yZlS3FQWzzgGpdJyYBvJdrkdMPqx_bl527u5CA1U/edit?gid=1105689284#gid=1105689284"",""B3 vs B4!T24"")"),20.0) -> 20 | N9: =IFERROR(__xludf.DUMMYFUNCTION("IMPORTRANGE(""https://docs.google.com/spreadsheets/d/1iErVLlc1_s37p2bIQGBV-ueQhrFErR8_rQgkEu4dw_A/edit?gid=1105689284#gid=1105689284"",""B4 vs B5!K24"")"),12.0) -> 12 | O9: =IFERROR(__xludf.DUMMYFUNCTION("IMPORTRANGE(""https://docs.google.com/spreadsheets/d/13_UcftIhRFc8Wdh5sQ-JghNmvplAeKYrOfyqerMoP4E/edit?gid=2010738230#gid=2010738230"",""B4 vs B6!K24"")"),40.0) -> 40
A10: A5 | B10: =IFERROR(__xludf.DUMMYFUNCTION("IMPORTRANGE(""https://docs.google.com/spreadsheets/d/1ZyVAgyLL_HCFyUsFR06BNJrd3d8klI6YuciQugxLR6o/edit?gid=1105689284#gid=1105689284"",""A1 vs A5!T24"")"),38.0) -> 38 | C10: =IFERROR(__xludf.DUMMYFUNCTION("IMPORTRANGE(""https://docs.google.com/spreadsheets/d/1Iv6yZlS3FQWzzgGpdJyYBvJdrkdMPqx_bl527u5CA1U/edit?gid=1105689284#gid=1105689284"",""A2 vs A5!T24"")"),22.0) -> 22 | D10: =IFERROR(__xludf.DUMMYFUNCTION("IMPORTRANGE(""https://docs.google.com/spreadsheets/d/13_UcftIhRFc8Wdh5sQ-JghNmvplAeKYrOfyqerMoP4E/edit?gid=2010738230#gid=2010738230"",""A3 vs A5!T24"")"),128.0) -> 128 | E10: =IFERROR(__xludf.DUMMYFUNCTION("IMPORTRANGE(""https://docs.google.com/spreadsheets/d/1iErVLlc1_s37p2bIQGBV-ueQhrFErR8_rQgkEu4dw_A/edit?gid=1105689284#gid=1105689284"",""A4 vs A5!T24"")"),48.0) -> 48 | G10: =IFERROR(__xludf.DUMMYFUNCTION("IMPORTRANGE(""https://docs.google.com/spreadsheets/d/1gvVcUWK0DrU9Prr-pNKoq3-2DQjDQ1i9v2BBpB5lu8o/edit?gid=1105689284#gid=1105689284"",""A5 vs A6!K24"")"),20.0) -> 20 | I10: B5 | J10: =IFERROR(__xludf.DUMMYFUNCTION("IMPORTRANGE(""https://docs.google.com/spreadsheets/d/1ZyVAgyLL_HCFyUsFR06BNJrd3d8klI6YuciQugxLR6o/edit?gid=1105689284#gid=1105689284"",""B1 vs B5!T24"")"),94.0) -> 94 | K10: =IFERROR(__xludf.DUMMYFUNCTION("IMPORTRANGE(""https://docs.google.com/spreadsheets/d/1Iv6yZlS3FQWzzgGpdJyYBvJdrkdMPqx_bl527u5CA1U/edit?gid=1105689284#gid=1105689284"",""B2 vs B5!T24"")"),144.0) -> 144 | L10: =IFERROR(__xludf.DUMMYFUNCTION("IMPORTRANGE(""https://docs.google.com/spreadsheets/d/13_UcftIhRFc8Wdh5sQ-JghNmvplAeKYrOfyqerMoP4E/edit?gid=2010738230#gid=2010738230"",""B3 vs B5!T24"")"),208.0) -> 208 | M10: =IFERROR(__xludf.DUMMYFUNCTION("IMPORTRANGE(""https://docs.google.com/spreadsheets/d/1iErVLlc1_s37p2bIQGBV-ueQhrFErR8_rQgkEu4dw_A/edit?gid=1105689284#gid=1105689284"",""B4 vs B5!T24"")"),226.0) -> 226 | O10: =IFERROR(__xludf.DUMMYFUNCTION("IMPORTRANGE(""https://docs.google.com/spreadsheets/d/1gvVcUWK0DrU9Prr-pNKoq3-2DQjDQ1i9v2BBpB5lu8o/edit?gid=1105689284#gid=1105689284"",""B5 vs B6!K24"")"),190.0) -> 190
A11: A6 | B11: =IFERROR(__xludf.DUMMYFUNCTION("IMPORTRANGE(""https://docs.google.com/spreadsheets/d/1Iv6yZlS3FQWzzgGpdJyYBvJdrkdMPqx_bl527u5CA1U/edit?gid=1105689284#gid=1105689284"",""A1 vs A6!T24"")"),132.0) -> 132 | C11: =IFERROR(__xludf.DUMMYFUNCTION("IMPORTRANGE(""https://docs.google.com/spreadsheets/d/1iErVLlc1_s37p2bIQGBV-ueQhrFErR8_rQgkEu4dw_A/edit?gid=1105689284#gid=1105689284"",""A2 vs A6!T24"")"),76.0) -> 76 | D11: =IFERROR(__xludf.DUMMYFUNCTION("IMPORTRANGE(""https://docs.google.com/spreadsheets/d/1ZyVAgyLL_HCFyUsFR06BNJrd3d8klI6YuciQugxLR6o/edit?gid=1105689284#gid=1105689284"",""A3 vs A6!T24"")"),142.0) -> 142 | E11: =IFERROR(__xludf.DUMMYFUNCTION("IMPORTRANGE(""https://docs.google.com/spreadsheets/d/13_UcftIhRFc8Wdh5sQ-JghNmvplAeKYrOfyqerMoP4E/edit?gid=2010738230#gid=2010738230"",""A4 vs A6!T24"")"),120.0) -> 120 | F11: =IFERROR(__xludf.DUMMYFUNCTION("IMPORTRANGE(""https://docs.google.com/spreadsheets/d/1gvVcUWK0DrU9Prr-pNKoq3-2DQjDQ1i9v2BBpB5lu8o/edit?gid=1105689284#gid=1105689284"",""A5 vs A6!T24"")"),174.0) -> 174 | I11: B6 | J11: =IFERROR(__xludf.DUMMYFUNCTION("IMPORTRANGE(""https://docs.google.com/spreadsheets/d/1Iv6yZlS3FQWzzgGpdJyYBvJdrkdMPqx_bl527u5CA1U/edit?gid=1105689284#gid=1105689284"",""B1 vs B6!T24"")"),22.0) -> 22 | K11: =IFERROR(__xludf.DUMMYFUNCTION("IMPORTRANGE(""https://docs.google.com/spreadsheets/d/1iErVLlc1_s37p2bIQGBV-ueQhrFErR8_rQgkEu4dw_A/edit?gid=1105689284#gid=1105689284"",""B2 vs B6!T24"")"),62.0) -> 62 | L11: =IFERROR(__xludf.DUMMYFUNCTION("IMPORTRANGE(""https://docs.google.com/spreadsheets/d/1ZyVAgyLL_HCFyUsFR06BNJrd3d8klI6YuciQugxLR6o/edit?gid=1105689284#gid=1105689284"",""B3 vs B6!T24"")"),60.0) -> 60 | M11: =IFERROR(__xludf.DUMMYFUNCTION("IMPORTRANGE(""https://docs.google.com/spreadsheets/d/13_UcftIhRFc8Wdh5sQ-JghNmvplAeKYrOfyqerMoP4E/edit?gid=2010738230#gid=2010738230"",""B4 vs B6!T24"")"),136.0) -> 136 | N11: =IFERROR(__xludf.DUMMYFUNCTION("IMPORTRANGE(""https://docs.google.com/spreadsheets/d/1gvVcUWK0DrU9Prr-pNKoq3-2DQjDQ1i9v2BBpB5lu8o/edit?gid=1105689284#gid=1105689284"",""B5 vs B6!T24"")"),46.0) -> 46
A13: Condors | I13: Dovekies
A14: =SUM(B15:G20) -> 2540 | B14: {=INDEX(A15,0)} -> C1 | C14: {=INDEX(A16,0)} -> C2 | D14: {=INDEX(A17,0)} -> C3 | E14: {=INDEX(A18,0)} -> C4 | F14: {=INDEX(A19,0)} -> C5 | G14: {=INDEX(A20,0)} -> C6 | I14: =SUM(J15:O20) -> 2738 | J14: {=INDEX(I15,0)} -> D1 | K14: {=INDEX(I16,0)} -> D2 | L14: {=INDEX(I17,0)} -> D3 | M14: {=INDEX(I18,0)} -> D4 | N14: {=INDEX(I19,0)} -> D5 | O14: {=INDEX(I20,0)} -> D6
A15: C1 | C15: =IFERROR(__xludf.DUMMYFUNCTION("IMPORTRANGE(""https://docs.google.com/spreadsheets/d/13_UcftIhRFc8Wdh5sQ-JghNmvplAeKYrOfyqerMoP4E/edit?gid=2010738230#gid=2010738230"",""C1 vs C2!K24"")"),118.0) -> 118 | D15: =IFERROR(__xludf.DUMMYFUNCTION("IMPORTRANGE(""https://docs.google.com/spreadsheets/d/1iErVLlc1_s37p2bIQGBV-ueQhrFErR8_rQgkEu4dw_A/edit?gid=1105689284#gid=1105689284"",""C1 vs C3!K24"")"),50.0) -> 50 | E15: =IFERROR(__xludf.DUMMYFUNCTION("IMPORTRANGE(""https://docs.google.com/spreadsheets/d/1gvVcUWK0DrU9Prr-pNKoq3-2DQjDQ1i9v2BBpB5lu8o/edit?gid=1105689284#gid=1105689284"",""C1 vs C4!K24"")"),98.0) -> 98 | F15: =IFERROR(__xludf.DUMMYFUNCTION("IMPORTRANGE(""https://docs.google.com/spreadsheets/d/1ZyVAgyLL_HCFyUsFR06BNJrd3d8klI6YuciQugxLR6o/edit?gid=1105689284#gid=1105689284"",""C1 vs C5!K24"")"),118.0) -> 118 | G15: =IFERROR(__xludf.DUMMYFUNCTION("IMPORTRANGE(""https://docs.google.com/spreadsheets/d/1Iv6yZlS3FQWzzgGpdJyYBvJdrkdMPqx_bl527u5CA1U/edit?gid=1105689284#gid=1105689284"",""C1 vs C6!K24"")"),32.0) -> 32 | I15: D1 | K15: =IFERROR(__xludf.DUMMYFUNCTION("IMPORTRANGE(""https://docs.google.com/spreadsheets/d/13_UcftIhRFc8Wdh5sQ-JghNmvplAeKYrOfyqerMoP4E/edit?gid=2010738230#gid=2010738230"",""D1 vs D2!K24"")"),58.0) -> 58 | L15: =IFERROR(__xludf.DUMMYFUNCTION("IMPORTRANGE(""https://docs.google.com/spreadsheets/d/1iErVLlc1_s37p2bIQGBV-ueQhrFErR8_rQgkEu4dw_A/edit?gid=1105689284#gid=1105689284"",""D1 vs D3!K24"")"),38.0) -> 38 | M15: =IFERROR(__xludf.DUMMYFUNCTION("IMPORTRANGE(""https://docs.google.com/spreadsheets/d/1gvVcUWK0DrU9Prr-pNKoq3-2DQjDQ1i9v2BBpB5lu8o/edit?gid=1105689284#gid=1105689284"",""D1 vs D4!K24"")"),36.0) -> 36 | N15: =IFERROR(__xludf.DUMMYFUNCTION("IMPORTRANGE(""https://docs.google.com/spreadsheets/d/1ZyVAgyLL_HCFyUsFR06BNJrd3d8klI6YuciQugxLR6o/edit?gid=1105689284#gid=1105689284"",""D1 vs D5!K24"")"),34.0) -> 34 | O15: =IFERROR(__xludf.DUMMYFUNCTION("IMPORTRANGE(""https://docs.google.com/spreadsheets/d/1Iv6yZlS3FQWzzgGpdJyYBvJdrkdMPqx_bl527u5CA1U/edit?gid=1105689284#gid=1105689284"",""D1 vs D6!K24"")"),52.0) -> 52
A16: C2 | B16: =IFERROR(__xludf.DUMMYFUNCTION("IMPORTRANGE(""https://docs.google.com/spreadsheets/d/13_UcftIhRFc8Wdh5sQ-JghNmvplAeKYrOfyqerMoP4E/edit?gid=2010738230#gid=2010738230"",""C1 vs C2!T24"")"),148.0) -> 148 | D16: =IFERROR(__xludf.DUMMYFUNCTION("IMPORTRANGE(""https://docs.google.com/spreadsheets/d/1gvVcUWK0DrU9Prr-pNKoq3-2DQjDQ1i9v2BBpB5lu8o/edit?gid=1105689284#gid=1105689284"",""C2 vs C3!K24"")"),96.0) -> 96 | E16: =IFERROR(__xludf.DUMMYFUNCTION("IMPORTRANGE(""https://docs.google.com/spreadsheets/d/1ZyVAgyLL_HCFyUsFR06BNJrd3d8klI6YuciQugxLR6o/edit?gid=1105689284#gid=1105689284"",""C2 vs C4!K24"")"),114.0) -> 114 | F16: =IFERROR(__xludf.DUMMYFUNCTION("IMPORTRANGE(""https://docs.google.com/spreadsheets/d/1Iv6yZlS3FQWzzgGpdJyYBvJdrkdMPqx_bl527u5CA1U/edit?gid=1105689284#gid=1105689284"",""C2 vs C5!K24"")"),104.0) -> 104 | G16: =IFERROR(__xludf.DUMMYFUNCTION("IMPORTRANGE(""https://docs.google.com/spreadsheets/d/1iErVLlc1_s37p2bIQGBV-ueQhrFErR8_rQgkEu4dw_A/edit?gid=1105689284#gid=1105689284"",""C2 vs C6!K24"")"),112.0) -> 112 | I16: D2 | J16: =IFERROR(__xludf.DUMMYFUNCTION("IMPORTRANGE(""https://docs.google.com/spreadsheets/d/13_UcftIhRFc8Wdh5sQ-JghNmvplAeKYrOfyqerMoP4E/edit?gid=2010738230#gid=2010738230"",""D1 vs D2!T24"")"),110.0) -> 110 | L16: =IFERROR(__xludf.DUMMYFUNCTION("IMPORTRANGE(""https://docs.google.com/spreadsheets/d/1gvVcUWK0DrU9Prr-pNKoq3-2DQjDQ1i9v2BBpB5lu8o/edit?gid=1105689284#gid=1105689284"",""D2 vs D3!K24"")"),20.0) -> 20 | M16: =IFERROR(__xludf.DUMMYFUNCTION("IMPORTRANGE(""https://docs.google.com/spreadsheets/d/1ZyVAgyLL_HCFyUsFR06BNJrd3d8klI6YuciQugxLR6o/edit?gid=1105689284#gid=1105689284"",""D2 vs D4!K24"")"),58.0) -> 58 | N16: =IFERROR(__xludf.DUMMYFUNCTION("IMPORTRANGE(""https://docs.google.com/spreadsheets/d/1Iv6yZlS3FQWzzgGpdJyYBvJdrkdMPqx_bl527u5CA1U/edit?gid=1105689284#gid=1105689284"",""D2 vs D5!K24"")"),34.0) -> 34 | O16: =IFERROR(__xludf.DUMMYFUNCTION("IMPORTRANGE(""https://docs.google.com/spreadsheets/d/1iErVLlc1_s37p2bIQGBV-ueQhrFErR8_rQgkEu4dw_A/edit?gid=1105689284#gid=1105689284"",""D2 vs D6!K24"")"),104.0) -> 104
A17: C3 | B17: =IFERROR(__xludf.DUMMYFUNCTION("IMPORTRANGE(""https://docs.google.com/spreadsheets/d/1iErVLlc1_s37p2bIQGBV-ueQhrFErR8_rQgkEu4dw_A/edit?gid=1105689284#gid=1105689284"",""C1 vs C3!T24"")"),138.0) -> 138 | C17: =IFERROR(__xludf.DUMMYFUNCTION("IMPORTRANGE(""https://docs.google.com/spreadsheets/d/1gvVcUWK0DrU9Prr-pNKoq3-2DQjDQ1i9v2BBpB5lu8o/edit?gid=1105689284#gid=1105689284"",""C2 vs C3!T24"")"),66.0) -> 66 | E17: =IFERROR(__xludf.DUMMYFUNCTION("IMPORTRANGE(""https://docs.google.com/spreadsheets/d/1Iv6yZlS3FQWzzgGpdJyYBvJdrkdMPqx_bl527u5CA1U/edit?gid=1105689284#gid=1105689284"",""C3 vs C4!K24"")"),82.0) -> 82 | F17: =IFERROR(__xludf.DUMMYFUNCTION("IMPORTRANGE(""https://docs.google.com/spreadsheets/d/13_UcftIhRFc8Wdh5sQ-JghNmvplAeKYrOfyqerMoP4E/edit?gid=2010738230#gid=2010738230"",""C3 vs C5!K24"")"),82.0) -> 82 | G17: =IFERROR(__xludf.DUMMYFUNCTION("IMPORTRANGE(""https://docs.google.com/spreadsheets/d/1ZyVAgyLL_HCFyUsFR06BNJrd3d8klI6YuciQugxLR6o/edit?gid=1105689284#gid=1105689284"",""C3 vs C6!K24"")"),122.0) -> 122 | I17: D3 | J17: =IFERROR(__xludf.DUMMYFUNCTION("IMPORTRANGE(""https://docs.google.com/spreadsheets/d/1iErVLlc1_s37p2bIQGBV-ueQhrFErR8_rQgkEu4dw_A/edit?gid=1105689284#gid=1105689284"",""D1 vs D3!T24"")"),182.0) -> 182 | K17: =IFERROR(__xludf.DUMMYFUNCTION("IMPORTRANGE(""https://docs.google.com/spreadsheets/d/1gvVcUWK0DrU9Prr-pNKoq3-2DQjDQ1i9v2BBpB5lu8o/edit?gid=1105689284#gid=1105689284"",""D2 vs D3!T24"")"),152.0) -> 152 | M17: =IFERROR(__xludf.DUMMYFUNCTION("IMPORTRANGE(""https://docs.google.com/spreadsheets/d/1Iv6yZlS3FQWzzgGpdJyYBvJdrkdMPqx_bl527u5CA1U/edit?gid=1105689284#gid=1105689284"",""D3 vs D4!K24"")"),132.0) -> 132 | N17: =IFERROR(__xludf.DUMMYFUNCTION("IMPORTRANGE(""https://docs.google.com/spreadsheets/d/13_UcftIhRFc8Wdh5sQ-JghNmvplAeKYrOfyqerMoP4E/edit?gid=2010738230#gid=2010738230"",""D3 vs D5!K24"")"),190.0) -> 190 | O17: =IFERROR(__xludf.DUMMYFUNCTION("IMPORTRANGE(""https://docs.google.com/spreadsheets/d/1ZyVAgyLL_HCFyUsFR06BNJrd3d8klI6YuciQugxLR6o/edit?gid=1105689284#gid=1105689284"",""D3 vs D6!K24"")"),260.0) -> 260
A18: C4 | B18: =IFERROR(__xludf.DUMMYFUNCTION("IMPORTRANGE(""https://docs.google.com/spreadsheets/d/1gvVcUWK0DrU9Prr-pNKoq3-2DQjDQ1i9v2BBpB5lu8o/edit?gid=1105689284#gid=1105689284"",""C1 vs C4!T24"")"),36.0) -> 36 | C18: =IFERROR(__xludf.DUMMYFUNCTION("IMPORTRANGE(""https://docs.google.com/spreadsheets/d/1ZyVAgyLL_HCFyUsFR06BNJrd3d8klI6YuciQugxLR6o/edit?gid=1105689284#gid=1105689284"",""C2 vs C4!T24"")"),16.0) -> 16 | D18: =IFERROR(__xludf.DUMMYFUNCTION("IMPORTRANGE(""https://docs.google.com/spreadsheets/d/1Iv6yZlS3FQWzzgGpdJyYBvJdrkdMPqx_bl527u5CA1U/edit?gid=1105689284#gid=1105689284"",""C3 vs C4!T24"")"),30.0) -> 30 | F18: =IFERROR(__xludf.DUMMYFUNCTION("IMPORTRANGE(""https://docs.google.com/spreadsheets/d/1iErVLlc1_s37p2bIQGBV-ueQhrFErR8_rQgkEu4dw_A/edit?gid=1105689284#gid=1105689284"",""C4 vs C5!K24"")"),72.0) -> 72 | G18: =IFERROR(__xludf.DUMMYFUNCTION("IMPORTRANGE(""https://docs.google.com/spreadsheets/d/13_UcftIhRFc8Wdh5sQ-JghNmvplAeKYrOfyqerMoP4E/edit?gid=2010738230#gid=2010738230"",""C4 vs C6!K24"")"),12.0) -> 12 | I18: D4 | J18: =IFERROR(__xludf.DUMMYFUNCTION("IMPORTRANGE(""https://docs.google.com/spreadsheets/d/1gvVcUWK0DrU9Prr-pNKoq3-2DQjDQ1i9v2BBpB5lu8o/edit?gid=1105689284#gid=1105689284"",""D1 vs D4!T24"")"),150.0) -> 150 | K18: =IFERROR(__xludf.DUMMYFUNCTION("IMPORTRANGE(""https://docs.google.com/spreadsheets/d/1ZyVAgyLL_HCFyUsFR06BNJrd3d8klI6YuciQugxLR6o/edit?gid=1105689284#gid=1105689284"",""D2 vs D4!T24"")"),110.0) -> 110 | L18: =IFERROR(__xludf.DUMMYFUNCTION("IMPORTRANGE(""https://docs.google.com/spreadsheets/d/1Iv6yZlS3FQWzzgGpdJyYBvJdrkdMPqx_bl527u5CA1U/edit?gid=1105689284#gid=1105689284"",""D3 vs D4!T24"")"),60.0) -> 60 | N18: =IFERROR(__xludf.DUMMYFUNCTION("IMPORTRANGE(""https://docs.google.com/spreadsheets/d/1iErVLlc1_s37p2bIQGBV-ueQhrFErR8_rQgkEu4dw_A/edit?gid=1105689284#gid=1105689284"",""D4 vs D5!K24"")"),130.0) -> 130 | O18: =IFERROR(__xludf.DUMMYFUNCTION("IMPORTRANGE(""https://docs.google.com/spreadsheets/d/13_UcftIhRFc8Wdh5sQ-JghNmvplAeKYrOfyqerMoP4E/edit?gid=2010738230#gid=2010738230"",""D4 vs D6!K24"")"),166.0) -> 166
A19: C5 | B19: =IFERROR(__xludf.DUMMYFUNCTION("IMPORTRANGE(""https://docs.google.com/spreadsheets/d/1ZyVAgyLL_HCFyUsFR06BNJrd3d8klI6YuciQugxLR6o/edit?gid=1105689284#gid=1105689284"",""C1 vs C5!T24"")"),40.0) -> 40 | C19: =IFERROR(__xludf.DUMMYFUNCTION("IMPORTRANGE(""https://docs.google.com/spreadsheets/d/1Iv6yZlS3FQWzzgGpdJyYBvJdrkdMPqx_bl527u5CA1U/edit?gid=1105689284#gid=1105689284"",""C2 vs C5!T24"")"),26.0) -> 26 | D19: =IFERROR(__xludf.DUMMYFUNCTION("IMPORTRANGE(""https://docs.google.com/spreadsheets/d/13_UcftIhRFc8Wdh5sQ-JghNmvplAeKYrOfyqerMoP4E/edit?gid=2010738230#gid=2010738230"",""C3 vs C5!T24"")"),106.0) -> 106 | E19: =IFERROR(__xludf.DUMMYFUNCTION("IMPORTRANGE(""https://docs.google.com/spreadsheets/d/1iErVLlc1_s37p2bIQGBV-ueQhrFErR8_rQgkEu4dw_A/edit?gid=1105689284#gid=1105689284"",""C4 vs C5!T24"")"),82.0) -> 82 | G19: =IFERROR(__xludf.DUMMYFUNCTION("IMPORTRANGE(""https://docs.google.com/spreadsheets/d/1gvVcUWK0DrU9Prr-pNKoq3-2DQjDQ1i9v2BBpB5lu8o/edit?gid=1105689284#gid=1105689284"",""C5 vs C6!K24"")"),8.0) -> 8 | I19: D5 | J19: =IFERROR(__xludf.DUMMYFUNCTION("IMPORTRANGE(""https://docs.google.com/spreadsheets/d/1ZyVAgyLL_HCFyUsFR06BNJrd3d8klI6YuciQugxLR6o/edit?gid=1105689284#gid=1105689284"",""D1 vs D5!T24"")"),92.0) -> 92 | K19: =IFERROR(__xludf.DUMMYFUNCTION("IMPORTRANGE(""https://docs.google.com/spreadsheets/d/1Iv6yZlS3FQWzzgGpdJyYBvJdrkdMPqx_bl527u5CA1U/edit?gid=1105689284#gid=1105689284"",""D2 vs D5!T24"")"),80.0) -> 80 | L19: =IFERROR(__xludf.DUMMYFUNCTION("IMPORTRANGE(""https://docs.google.com/spreadsheets/d/13_UcftIhRFc8Wdh5sQ-JghNmvplAeKYrOfyqerMoP4E/edit?gid=2010738230#gid=2010738230"",""D3 vs D5!T24"")"),92.0) -> 92 | M19: =IFERROR(__xludf.DUMMYFUNCTION("IMPORTRANGE(""https://docs.google.com/spreadsheets/d/1iErVLlc1_s37p2bIQGBV-ueQhrFErR8_rQgkEu4dw_A/edit?gid=1105689284#gid=1105689284"",""D4 vs D5!T24"")"),82.0) -> 82 | O19: =IFERROR(__xludf.DUMMYFUNCTION("IMPORTRANGE(""https://docs.google.com/spreadsheets/d/1gvVcUWK0DrU9Prr-pNKoq3-2DQjDQ1i9v2BBpB5lu8o/edit?gid=1105689284#gid=1105689284"",""D5 vs D6!K24"")"),114.0) -> 114
A20: C6 | B20: =IFERROR(__xludf.DUMMYFUNCTION("IMPORTRANGE(""https://docs.google.com/spreadsheets/d/1Iv6yZlS3FQWzzgGpdJyYBvJdrkdMPqx_bl527u5CA1U/edit?gid=1105689284#gid=1105689284"",""C1 vs C6!T24"")"),102.0) -> 102 | C20: =IFERROR(__xludf.DUMMYFUNCTION("IMPORTRANGE(""https://docs.google.com/spreadsheets/d/1iErVLlc1_s37p2bIQGBV-ueQhrFErR8_rQgkEu4dw_A/edit?gid=1105689284#gid=1105689284"",""C2 vs C6!T24"")"),112.0) -> 112 | D20: =IFERROR(__xludf.DUMMYFUNCTION("IMPORTRANGE(""https://docs.google.com/spreadsheets/d/1ZyVAgyLL_HCFyUsFR06BNJrd3d8klI6YuciQugxLR6o/edit?gid=1105689284#gid=1105689284"",""C3 vs C6!T24"")"),58.0) -> 58 | E20: =IFERROR(__xludf.DUMMYFUNCTION("IMPORTRANGE(""https://docs.google.com/spreadsheets/d/13_UcftIhRFc8Wdh5sQ-JghNmvplAeKYrOfyqerMoP4E/edit?gid=2010738230#gid=2010738230"",""C4 vs C6!T24"")"),218.0) -> 218 | F20: =IFERROR(__xludf.DUMMYFUNCTION("IMPORTRANGE(""https://docs.google.com/spreadsheets/d/1gvVcUWK0DrU9Prr-pNKoq3-2DQjDQ1i9v2BBpB5lu8o/edit?gid=1105689284#gid=1105689284"",""C5 vs C6!T24"")"),142.0) -> 142 | I20: D6 | J20: =IFERROR(__xludf.DUMMYFUNCTION("IMPORTRANGE(""https://docs.google.com/spreadsheets/d/1Iv6yZlS3FQWzzgGpdJyYBvJdrkdMPqx_bl527u5CA1U/edit?gid=1105689284#gid=1105689284"",""D1 vs D6!T24"")"),12.0) -> 12 | K20: =IFERROR(__xludf.DUMMYFUNCTION("IMPORTRANGE(""https://docs.google.com/spreadsheets/d/1iErVLlc1_s37p2bIQGBV-ueQhrFErR8_rQgkEu4dw_A/edit?gid=1105689284#gid=1105689284"",""D2 vs D6!T24"")"),66.0) -> 66 | L20: =IFERROR(__xludf.DUMMYFUNCTION("IMPORTRANGE(""https://docs.google.com/spreadsheets/d/1ZyVAgyLL_HCFyUsFR06BNJrd3d8klI6YuciQugxLR6o/edit?gid=1105689284#gid=1105689284"",""D3 vs D6!T24"")"),4.0) -> 4 | M20: =IFERROR(__xludf.DUMMYFUNCTION("IMPORTRANGE(""https://docs.google.com/spreadsheets/d/13_UcftIhRFc8Wdh5sQ-JghNmvplAeKYrOfyqerMoP4E/edit?gid=2010738230#gid=2010738230"",""D4 vs D6!T24"")"),64.0) -> 64 | N20: =IFERROR(__xludf.DUMMYFUNCTION("IMPORTRANGE(""https://docs.google.com/spreadsheets/d/1gvVcUWK0DrU9Prr-pNKoq3-2DQjDQ1i9v2BBpB5lu8o/edit?gid=1105689284#gid=1105689284"",""D5 vs D6!T24"")"),56.0) -> 56
A22: Egrets | I22: Frigatebirds
A23: =SUM(B24:G29) -> 2726 | B23: {=INDEX(A24,0)} -> E1 | C23: {=INDEX(A25,0)} -> E2 | D23: {=INDEX(A26,0)} -> E3 | E23: {=INDEX(A27,0)} -> E4 | F23: {=INDEX(A28,0)} -> E5 | G23: {=INDEX(A29,0)} -> E6 | I23: =SUM(J24:O29) -> 2878 | J23: {=INDEX(I24,0)} -> F1 | K23: {=INDEX(I25,0)} -> F2 | L23: {=INDEX(I26,0)} -> F3 | M23: {=INDEX(I27,0)} -> F4 | N23: {=INDEX(I28,0)} -> F5 | O23: {=INDEX(I29,0)} -> F6
A24: E1 | C24: =IFERROR(__xludf.DUMMYFUNCTION("IMPORTRANGE(""https://docs.google.com/spreadsheets/d/13_UcftIhRFc8Wdh5sQ-JghNmvplAeKYrOfyqerMoP4E/edit?gid=2010738230#gid=2010738230"",""E1 vs E2!K24"")"),14.0) -> 14 | D24: =IFERROR(__xludf.DUMMYFUNCTION("IMPORTRANGE(""https://docs.google.com/spreadsheets/d/1iErVLlc1_s37p2bIQGBV-ueQhrFErR8_rQgkEu4dw_A/edit?gid=1105689284#gid=1105689284"",""E1 vs E3!K24"")"),16.0) -> 16 | E24: =IFERROR(__xludf.DUMMYFUNCTION("IMPORTRANGE(""https://docs.google.com/spreadsheets/d/1gvVcUWK0DrU9Prr-pNKoq3-2DQjDQ1i9v2BBpB5lu8o/edit?gid=1105689284#gid=1105689284"",""E1 vs E4!K24"")"),16.0) -> 16 | F24: =IFERROR(__xludf.DUMMYFUNCTION("IMPORTRANGE(""https://docs.google.com/spreadsheets/d/1ZyVAgyLL_HCFyUsFR06BNJrd3d8klI6YuciQugxLR6o/edit?gid=1105689284#gid=1105689284"",""E1 vs E5!K24"")"),8.0) -> 8 | G24: =IFERROR(__xludf.DUMMYFUNCTION("IMPORTRANGE(""https://docs.google.com/spreadsheets/d/1Iv6yZlS3FQWzzgGpdJyYBvJdrkdMPqx_bl527u5CA1U/edit?gid=1105689284#gid=1105689284"",""E1 vs E6!K24"")"),12.0) -> 12 | I24: F1 | K24: =IFERROR(__xludf.DUMMYFUNCTION("IMPORTRANGE(""https://docs.google.com/spreadsheets/d/13_UcftIhRFc8Wdh5sQ-JghNmvplAeKYrOfyqerMoP4E/edit?gid=2010738230#gid=2010738230"",""F1 vs F2!K24"")"),90.0) -> 90 | L24: =IFERROR(__xludf.DUMMYFUNCTION("IMPORTRANGE(""https://docs.google.com/spreadsheets/d/1iErVLlc1_s37p2bIQGBV-ueQhrFErR8_rQgkEu4dw_A/edit?gid=1105689284#gid=1105689284"",""F1 vs F3!K24"")"),70.0) -> 70 | M24: =IFERROR(__xludf.DUMMYFUNCTION("IMPORTRANGE(""https://docs.google.com/spreadsheets/d/1gvVcUWK0DrU9Prr-pNKoq3-2DQjDQ1i9v2BBpB5lu8o/edit?gid=1105689284#gid=1105689284"",""F1 vs F4!K24"")"),64.0) -> 64 | N24: =IFERROR(__xludf.DUMMYFUNCTION("IMPORTRANGE(""https://docs.google.com/spreadsheets/d/1ZyVAgyLL_HCFyUsFR06BNJrd3d8klI6YuciQugxLR6o/edit?gid=1105689284#gid=1105689284"",""F1 vs F5!K24"")"),50.0) -> 50 | O24: =IFERROR(__xludf.DUMMYFUNCTION("IMPORTRANGE(""https://docs.google.com/spreadsheets/d/1Iv6yZlS3FQWzzgGpdJyYBvJdrkdMPqx_bl527u5CA1U/edit?gid=1105689284#gid=1105689284"",""F1 vs F6!K24"")"),28.0) -> 28
A25: E2 | B25: =IFERROR(__xludf.DUMMYFUNCTION("IMPORTRANGE(""https://docs.google.com/spreadsheets/d/13_UcftIhRFc8Wdh5sQ-JghNmvplAeKYrOfyqerMoP4E/edit?gid=2010738230#gid=2010738230"",""E1 vs E2!T24"")"),246.0) -> 246 | D25: =IFERROR(__xludf.DUMMYFUNCTION("IMPORTRANGE(""https://docs.google.com/spreadsheets/d/1gvVcUWK0DrU9Prr-pNKoq3-2DQjDQ1i9v2BBpB5lu8o/edit?gid=1105689284#gid=1105689284"",""E2 vs E3!K24"")"),94.0) -> 94 | E25: =IFERROR(__xludf.DUMMYFUNCTION("IMPORTRANGE(""https://docs.google.com/spreadsheets/d/1ZyVAgyLL_HCFyUsFR06BNJrd3d8klI6YuciQugxLR6o/edit?gid=1105689284#gid=1105689284"",""E2 vs E4!K24"")"),118.0) -> 118 | F25: =IFERROR(__xludf.DUMMYFUNCTION("IMPORTRANGE(""https://docs.google.com/spreadsheets/d/1Iv6yZlS3FQWzzgGpdJyYBvJdrkdMPqx_bl527u5CA1U/edit?gid=1105689284#gid=1105689284"",""E2 vs E5!K24"")"),72.0) -> 72 | G25: =IFERROR(__xludf.DUMMYFUNCTION("IMPORTRANGE(""https://docs.google.com/spreadsheets/d/1iErVLlc1_s37p2bIQGBV-ueQhrFErR8_rQgkEu4dw_A/edit?gid=1105689284#gid=1105689284"",""E2 vs E6!K24"")"),130.0) -> 130 | I25: F2 | J25: =IFERROR(__xludf.DUMMYFUNCTION("IMPORTRANGE(""https://docs.google.com/spreadsheets/d/13_UcftIhRFc8Wdh5sQ-JghNmvplAeKYrOfyqerMoP4E/edit?gid=2010738230#gid=2010738230"",""F1 vs F2!T24"")"),90.0) -> 90 | L25: =IFERROR(__xludf.DUMMYFUNCTION("IMPORTRANGE(""https://docs.google.com/spreadsheets/d/1gvVcUWK0DrU9Prr-pNKoq3-2DQjDQ1i9v2BBpB5lu8o/edit?gid=1105689284#gid=1105689284"",""F2 vs F3!K24"")"),58.0) -> 58 | M25: =IFERROR(__xludf.DUMMYFUNCTION("IMPORTRANGE(""https://docs.google.com/spreadsheets/d/1ZyVAgyLL_HCFyUsFR06BNJrd3d8klI6YuciQugxLR6o/edit?gid=1105689284#gid=1105689284"",""F2 vs F4!K24"")"),46.0) -> 46 | N25: =IFERROR(__xludf.DUMMYFUNCTION("IMPORTRANGE(""https://docs.google.com/spreadsheets/d/1Iv6yZlS3FQWzzgGpdJyYBvJdrkdMPqx_bl527u5CA1U/edit?gid=1105689284#gid=1105689284"",""F2 vs F5!K24"")"),66.0) -> 66 | O25: =IFERROR(__xludf.DUMMYFUNCTION("IMPORTRANGE(""https://docs.google.com/spreadsheets/d/1iErVLlc1_s37p2bIQGBV-ueQhrFErR8_rQgkEu4dw_A/edit?gid=1105689284#gid=1105689284"",""F2 vs F6!K24"")"),94.0) -> 94
A26: E3 | B26: =IFERROR(__xludf.DUMMYFUNCTION("IMPORTRANGE(""https://docs.google.com/spreadsheets/d/1iErVLlc1_s37p2bIQGBV-ueQhrFErR8_rQgkEu4dw_A/edit?gid=1105689284#gid=1105689284"",""E1 vs E3!T24"")"),162.0) -> 162 | C26: =IFERROR(__xludf.DUMMYFUNCTION("IMPORTRANGE(""https://docs.google.com/spreadsheets/d/1gvVcUWK0DrU9Prr-pNKoq3-2DQjDQ1i9v2BBpB5lu8o/edit?gid=1105689284#gid=1105689284"",""E2 vs E3!T24"")"),90.0) -> 90 | E26: =IFERROR(__xludf.DUMMYFUNCTION("IMPORTRANGE(""https://docs.google.com/spreadsheets/d/1Iv6yZlS3FQWzzgGpdJyYBvJdrkdMPqx_bl527u5CA1U/edit?gid=1105689284#gid=1105689284"",""E3 vs E4!K24"")"),86.0) -> 86 | F26: =IFERROR(__xludf.DUMMYFUNCTION("IMPORTRANGE(""https://docs.google.com/spreadsheets/d/13_UcftIhRFc8Wdh5sQ-JghNmvplAeKYrOfyqerMoP4E/edit?gid=2010738230#gid=2010738230"",""E3 vs E5!K24"")"),60.0) -> 60 | G26: =IFERROR(__xludf.DUMMYFUNCTION("IMPORTRANGE(""https://docs.google.com/spreadsheets/d/1ZyVAgyLL_HCFyUsFR06BNJrd3d8klI6YuciQugxLR6o/edit?gid=1105689284#gid=1105689284"",""E3 vs E6!K24"")"),186.0) -> 186 | I26: F3 | J26: =IFERROR(__xludf.DUMMYFUNCTION("IMPORTRANGE(""https://docs.google.com/spreadsheets/d/1iErVLlc1_s37p2bIQGBV-ueQhrFErR8_rQgkEu4dw_A/edit?gid=1105689284#gid=1105689284"",""F1 vs F3!T24"")"),166.0) -> 166 | K26: =IFERROR(__xludf.DUMMYFUNCTION("IMPORTRANGE(""https://docs.google.com/spreadsheets/d/1gvVcUWK0DrU9Prr-pNKoq3-2DQjDQ1i9v2BBpB5lu8o/edit?gid=1105689284#gid=1105689284"",""F2 vs F3!T24"")"),156.0) -> 156 | M26: =IFERROR(__xludf.DUMMYFUNCTION("IMPORTRANGE(""https://docs.google.com/spreadsheets/d/1Iv6yZlS3FQWzzgGpdJyYBvJdrkdMPqx_bl527u5CA1U/edit?gid=1105689284#gid=1105689284"",""F3 vs F4!K24"")"),124.0) -> 124 | N26: =IFERROR(__xludf.DUMMYFUNCTION("IMPORTRANGE(""https://docs.google.com/spreadsheets/d/13_UcftIhRFc8Wdh5sQ-JghNmvplAeKYrOfyqerMoP4E/edit?gid=2010738230#gid=2010738230"",""F3 vs F5!K24"")"),166.0) -> 166 | O26: =IFERROR(__xludf.DUMMYFUNCTION("IMPORTRANGE(""https://docs.google.com/spreadsheets/d/1ZyVAgyLL_HCFyUsFR06BNJrd3d8klI6YuciQugxLR6o/edit?gid=1105689284#gid=1105689284"",""F3 vs F6!K24"")"),138.0) -> 138
A27: E4 | B27: =IFERROR(__xludf.DUMMYFUNCTION("IMPORTRANGE(""https://docs.google.com/spreadsheets/d/1gvVcUWK0DrU9Prr-pNKoq3-2DQjDQ1i9v2BBpB5lu8o/edit?gid=1105689284#gid=1105689284"",""E1 vs E4!T24"")"),78.0) -> 78 | C27: =IFERROR(__xludf.DUMMYFUNCTION("IMPORTRANGE(""https://docs.google.com/spreadsheets/d/1ZyVAgyLL_HCFyUsFR06BNJrd3d8klI6YuciQugxLR6o/edit?gid=1105689284#gid=1105689284"",""E2 vs E4!T24"")"),76.0) -> 76 | D27: =IFERROR(__xludf.DUMMYFUNCTION("IMPORTRANGE(""https://docs.google.com/spreadsheets/d/1Iv6yZlS3FQWzzgGpdJyYBvJdrkdMPqx_bl527u5CA1U/edit?gid=1105689284#gid=1105689284"",""E3 vs E4!T24"")"),72.0) -> 72 | F27: =IFERROR(__xludf.DUMMYFUNCTION("IMPORTRANGE(""https://docs.google.com/spreadsheets/d/1iErVLlc1_s37p2bIQGBV-ueQhrFErR8_rQgkEu4dw_A/edit?gid=1105689284#gid=1105689284"",""E4 vs E5!K24"")"),62.0) -> 62 | G27: =IFERROR(__xludf.DUMMYFUNCTION("IMPORTRANGE(""https://docs.google.com/spreadsheets/d/13_UcftIhRFc8Wdh5sQ-JghNmvplAeKYrOfyqerMoP4E/edit?gid=2010738230#gid=2010738230"",""E4 vs E6!K24"")"),148.0) -> 148 | I27: F4 | J27: =IFERROR(__xludf.DUMMYFUNCTION("IMPORTRANGE(""https://docs.google.com/spreadsheets/d/1gvVcUWK0DrU9Prr-pNKoq3-2DQjDQ1i9v2BBpB5lu8o/edit?gid=1105689284#gid=1105689284"",""F1 vs F4!T24"")"),160.0) -> 160 | K27: =IFERROR(__xludf.DUMMYFUNCTION("IMPORTRANGE(""https://docs.google.com/spreadsheets/d/1ZyVAgyLL_HCFyUsFR06BNJrd3d8klI6YuciQugxLR6o/edit?gid=1105689284#gid=1105689284"",""F2 vs F4!T24"")"),180.0) -> 180 | L27: =IFERROR(__xludf.DUMMYFUNCTION("IMPORTRANGE(""https://docs.google.com/spreadsheets/d/1Iv6yZlS3FQWzzgGpdJyYBvJdrkdMPqx_bl527u5CA1U/edit?gid=1105689284#gid=1105689284"",""F3 vs F4!T24"")"),114.0) -> 114 | N27: =IFERROR(__xludf.DUMMYFUNCTION("IMPORTRANGE(""https://docs.google.com/spreadsheets/d/1iErVLlc1_s37p2bIQGBV-ueQhrFErR8_rQgkEu4dw_A/edit?gid=1105689284#gid=1105689284"",""F4 vs F5!K24"")"),174.0) -> 174 | O27: =IFERROR(__xludf.DUMMYFUNCTION("IMPORTRANGE(""https://docs.google.com/spreadsheets/d/13_UcftIhRFc8Wdh5sQ-JghNmvplAeKYrOfyqerMoP4E/edit?gid=2010738230#gid=2010738230"",""F4 vs F6!K24"")"),220.0) -> 220
A28: E5 | B28: =IFERROR(__xludf.DUMMYFUNCTION("IMPORTRANGE(""https://docs.google.com/spreadsheets/d/1ZyVAgyLL_HCFyUsFR06BNJrd3d8klI6YuciQugxLR6o/edit?gid=1105689284#gid=1105689284"",""E1 vs E5!T24"")"),126.0) -> 126 | C28: =IFERROR(__xludf.DUMMYFUNCTION("IMPORTRANGE(""https://docs.google.com/spreadsheets/d/1Iv6yZlS3FQWzzgGpdJyYBvJdrkdMPqx_bl527u5CA1U/edit?gid=1105689284#gid=1105689284"",""E2 vs E5!T24"")"),106.0) -> 106 | D28: =IFERROR(__xludf.DUMMYFUNCTION("IMPORTRANGE(""https://docs.google.com/spreadsheets/d/13_UcftIhRFc8Wdh5sQ-JghNmvplAeKYrOfyqerMoP4E/edit?gid=2010738230#gid=2010738230"",""E3 vs E5!T24"")"),190.0) -> 190 | E28: =IFERROR(__xludf.DUMMYFUNCTION("IMPORTRANGE(""https://docs.google.com/spreadsheets/d/1iErVLlc1_s37p2bIQGBV-ueQhrFErR8_rQgkEu4dw_A/edit?gid=1105689284#gid=1105689284"",""E4 vs E5!T24"")"),152.0) -> 152 | G28: =IFERROR(__xludf.DUMMYFUNCTION("IMPORTRANGE(""https://docs.google.com/spreadsheets/d/1gvVcUWK0DrU9Prr-pNKoq3-2DQjDQ1i9v2BBpB5lu8o/edit?gid=1105689284#gid=1105689284"",""E5 vs E6!K24"")"),132.0) -> 132 | I28: F5 | J28: =IFERROR(__xludf.DUMMYFUNCTION("IMPORTRANGE(""https://docs.google.com/spreadsheets/d/1ZyVAgyLL_HCFyUsFR06BNJrd3d8klI6YuciQugxLR6o/edit?gid=1105689284#gid=1105689284"",""F1 vs F5!T24"")"),50.0) -> 50 | K28: =IFERROR(__xludf.DUMMYFUNCTION("IMPORTRANGE(""https://docs.google.com/spreadsheets/d/1Iv6yZlS3FQWzzgGpdJyYBvJdrkdMPqx_bl527u5CA1U/edit?gid=1105689284#gid=1105689284"",""F2 vs F5!T24"")"),46.0) -> 46 | L28: =IFERROR(__xludf.DUMMYFUNCTION("IMPORTRANGE(""https://docs.google.com/spreadsheets/d/13_UcftIhRFc8Wdh5sQ-JghNmvplAeKYrOfyqerMoP4E/edit?gid=2010738230#gid=2010738230"",""F3 vs F5!T24"")"),94.0) -> 94 | M28: =IFERROR(__xludf.DUMMYFUNCTION("IMPORTRANGE(""https://docs.google.com/spreadsheets/d/1iErVLlc1_s37p2bIQGBV-ueQhrFErR8_rQgkEu4dw_A/edit?gid=1105689284#gid=1105689284"",""F4 vs F5!T24"")"),66.0) -> 66 | O28: =IFERROR(__xludf.DUMMYFUNCTION("IMPORTRANGE(""https://docs.google.com/spreadsheets/d/1gvVcUWK0DrU9Prr-pNKoq3-2DQjDQ1i9v2BBpB5lu8o/edit?gid=1105689284#gid=1105689284"",""F5 vs F6!K24"")"),38.0) -> 38
A29: E6 | B29: =IFERROR(__xludf.DUMMYFUNCTION("IMPORTRANGE(""https://docs.google.com/spreadsheets/d/1Iv6yZlS3FQWzzgGpdJyYBvJdrkdMPqx_bl527u5CA1U/edit?gid=1105689284#gid=1105689284"",""E1 vs E6!T24"")"),44.0) -> 44 | C29: =IFERROR(__xludf.DUMMYFUNCTION("IMPORTRANGE(""https://docs.google.com/spreadsheets/d/1iErVLlc1_s37p2bIQGBV-ueQhrFErR8_rQgkEu4dw_A/edit?gid=1105689284#gid=1105689284"",""E2 vs E6!T24"")"),76.0) -> 76 | D29: =IFERROR(__xludf.DUMMYFUNCTION("IMPORTRANGE(""https://docs.google.com/spreadsheets/d/1ZyVAgyLL_HCFyUsFR06BNJrd3d8klI6YuciQugxLR6o/edit?gid=1105689284#gid=1105689284"",""E3 vs E6!T24"")"),42.0) -> 42 | E29: =IFERROR(__xludf.DUMMYFUNCTION("IMPORTRANGE(""https://docs.google.com/spreadsheets/d/13_UcftIhRFc8Wdh5sQ-JghNmvplAeKYrOfyqerMoP4E/edit?gid=2010738230#gid=2010738230"",""E4 vs E6!T24"")"),72.0) -> 72 | F29: =IFERROR(__xludf.DUMMYFUNCTION("IMPORTRANGE(""https://docs.google.com/spreadsheets/d/1gvVcUWK0DrU9Prr-pNKoq3-2DQjDQ1i9v2BBpB5lu8o/edit?gid=1105689284#gid=1105689284"",""E5 vs E6!T24"")"),40.0) -> 40 | I29: F6 | J29: =IFERROR(__xludf.DUMMYFUNCTION("IMPORTRANGE(""https://docs.google.com/spreadsheets/d/1Iv6yZlS3FQWzzgGpdJyYBvJdrkdMPqx_bl527u5CA1U/edit?gid=1105689284#gid=1105689284"",""F1 vs F6!T24"")"),114.0) -> 114 | K29: =IFERROR(__xludf.DUMMYFUNCTION("IMPORTRANGE(""https://docs.google.com/spreadsheets/d/1iErVLlc1_s37p2bIQGBV-ueQhrFErR8_rQgkEu4dw_A/edit?gid=1105689284#gid=1105689284"",""F2 vs F6!T24"")"),72.0) -> 72 | L29: =IFERROR(__xludf.DUMMYFUNCTION("IMPORTRANGE(""https://docs.google.com/spreadsheets/d/1ZyVAgyLL_HCFyUsFR06BNJrd3d8klI6YuciQugxLR6o/edit?gid=1105689284#gid=1105689284"",""F3 vs F6!T24"")"),50.0) -> 50 | M29: =IFERROR(__xludf.DUMMYFUNCTION("IMPORTRANGE(""https://docs.google.com/spreadsheets/d/13_UcftIhRFc8Wdh5sQ-JghNmvplAeKYrOfyqerMoP4E/edit?gid=2010738230#gid=2010738230"",""F4 vs F6!T24"")"),14.0) -> 14 | N29: =IFERROR(__xludf.DUMMYFUNCTION("IMPORTRANGE(""https://docs.google.com/spreadsheets/d/1gvVcUWK0DrU9Prr-pNKoq3-2DQjDQ1i9v2BBpB5lu8o/edit?gid=1105689284#gid=1105689284"",""F5 vs F6!T24"")"),80.0) -> 80
A31: Godwits
A32: =SUM(B33:G38) -> 2660 | B32: {=INDEX(A33,0)} -> G1 | C32: {=INDEX(A34,0)} -> G2 | D32: {=INDEX(A35,0)} -> G3 | E32: {=INDEX(A36,0)} -> G4 | F32: {=INDEX(A37,0)} -> G5 | G32: {=INDEX(A38,0)} -> G6
A33: G1 | C33: =IFERROR(__xludf.DUMMYFUNCTION("IMPORTRANGE(""https://docs.google.com/spreadsheets/d/13_UcftIhRFc8Wdh5sQ-JghNmvplAeKYrOfyqerMoP4E/edit?gid=2010738230#gid=2010738230"",""G1 vs G2!K24"")"),130.0) -> 130 | D33: =IFERROR(__xludf.DUMMYFUNCTION("IMPORTRANGE(""https://docs.google.com/spreadsheets/d/1iErVLlc1_s37p2bIQGBV-ueQhrFErR8_rQgkEu4dw_A/edit?gid=1105689284#gid=1105689284"",""G1 vs G3!K24"")"),146.0) -> 146 | E33: =IFERROR(__xludf.DUMMYFUNCTION("IMPORTRANGE(""https://docs.google.com/spreadsheets/d/1gvVcUWK0DrU9Prr-pNKoq3-2DQjDQ1i9v2BBpB5lu8o/edit?gid=1105689284#gid=1105689284"",""G1 vs G4!K24"")"),60.0) -> 60 | F33: =IFERROR(__xludf.DUMMYFUNCTION("IMPORTRANGE(""https://docs.google.com/spreadsheets/d/1ZyVAgyLL_HCFyUsFR06BNJrd3d8klI6YuciQugxLR6o/edit?gid=1105689284#gid=1105689284"",""G1 vs G5!K24"")"),36.0) -> 36 | G33: =IFERROR(__xludf.DUMMYFUNCTION("IMPORTRANGE(""https://docs.google.com/spreadsheets/d/1Iv6yZlS3FQWzzgGpdJyYBvJdrkdMPqx_bl527u5CA1U/edit?gid=1105689284#gid=1105689284"",""G1 vs G6!K24"")"),100.0) -> 100
A34: G2 | B34: =IFERROR(__xludf.DUMMYFUNCTION("IMPORTRANGE(""https://docs.google.com/spreadsheets/d/13_UcftIhRFc8Wdh5sQ-JghNmvplAeKYrOfyqerMoP4E/edit?gid=2010738230#gid=2010738230"",""G1 vs G2!T24"")"),138.0) -> 138 | D34: =IFERROR(__xludf.DUMMYFUNCTION("IMPORTRANGE(""https://docs.google.com/spreadsheets/d/1gvVcUWK0DrU9Prr-pNKoq3-2DQjDQ1i9v2BBpB5lu8o/edit?gid=1105689284#gid=1105689284"",""G2 vs G3!K24"")"),170.0) -> 170 | E34: =IFERROR(__xludf.DUMMYFUNCTION("IMPORTRANGE(""https://docs.google.com/spreadsheets/d/1ZyVAgyLL_HCFyUsFR06BNJrd3d8klI6YuciQugxLR6o/edit?gid=1105689284#gid=1105689284"",""G2 vs G4!K24"")"),194.0) -> 194 | F34: =IFERROR(__xludf.DUMMYFUNCTION("IMPORTRANGE(""https://docs.google.com/spreadsheets/d/1Iv6yZlS3FQWzzgGpdJyYBvJdrkdMPqx_bl527u5CA1U/edit?gid=1105689284#gid=1105689284"",""G2 vs G5!K24"")"),122.0) -> 122 | G34: =IFERROR(__xludf.DUMMYFUNCTION("IMPORTRANGE(""https://docs.google.com/spreadsheets/d/1iErVLlc1_s37p2bIQGBV-ueQhrFErR8_rQgkEu4dw_A/edit?gid=1105689284#gid=1105689284"",""G2 vs G6!K24"")"),122.0) -> 122
A35: G3 | B35: =IFERROR(__xludf.DUMMYFUNCTION("IMPORTRANGE(""https://docs.google.com/spreadsheets/d/1iErVLlc1_s37p2bIQGBV-ueQhrFErR8_rQgkEu4dw_A/edit?gid=1105689284#gid=1105689284"",""G1 vs G3!T24"")"),24.0) -> 24 | C35: =IFERROR(__xludf.DUMMYFUNCTION("IMPORTRANGE(""https://docs.google.com/spreadsheets/d/1gvVcUWK0DrU9Prr-pNKoq3-2DQjDQ1i9v2BBpB5lu8o/edit?gid=1105689284#gid=1105689284"",""G2 vs G3!T24"")"),26.0) -> 26 | E35: =IFERROR(__xludf.DUMMYFUNCTION("IMPORTRANGE(""https://docs.google.com/spreadsheets/d/1Iv6yZlS3FQWzzgGpdJyYBvJdrkdMPqx_bl527u5CA1U/edit?gid=1105689284#gid=1105689284"",""G3 vs G4!K24"")"),48.0) -> 48 | F35: =IFERROR(__xludf.DUMMYFUNCTION("IMPORTRANGE(""https://docs.google.com/spreadsheets/d/13_UcftIhRFc8Wdh5sQ-JghNmvplAeKYrOfyqerMoP4E/edit?gid=2010738230#gid=2010738230"",""G3 vs G5!K24"")"),36.0) -> 36 | G35: =IFERROR(__xludf.DUMMYFUNCTION("IMPORTRANGE(""https://docs.google.com/spreadsheets/d/1ZyVAgyLL_HCFyUsFR06BNJrd3d8klI6YuciQugxLR6o/edit?gid=1105689284#gid=1105689284"",""G3 vs G6!K24"")"),18.0) -> 18
A36: G4 | B36: =IFERROR(__xludf.DUMMYFUNCTION("IMPORTRANGE(""https://docs.google.com/spreadsheets/d/1gvVcUWK0DrU9Prr-pNKoq3-2DQjDQ1i9v2BBpB5lu8o/edit?gid=1105689284#gid=1105689284"",""G1 vs G4!T24"")"),80.0) -> 80 | C36: =IFERROR(__xludf.DUMMYFUNCTION("IMPORTRANGE(""https://docs.google.com/spreadsheets/d/1ZyVAgyLL_HCFyUsFR06BNJrd3d8klI6YuciQugxLR6o/edit?gid=1105689284#gid=1105689284"",""G2 vs G4!T24"")"),46.0) -> 46 | D36: =IFERROR(__xludf.DUMMYFUNCTION("IMPORTRANGE(""https://docs.google.com/spreadsheets/d/1Iv6yZlS3FQWzzgGpdJyYBvJdrkdMPqx_bl527u5CA1U/edit?gid=1105689284#gid=1105689284"",""G3 vs G4!T24"")"),72.0) -> 72 | F36: =IFERROR(__xludf.DUMMYFUNCTION("IMPORTRANGE(""https://docs.google.com/spreadsheets/d/1iErVLlc1_s37p2bIQGBV-ueQhrFErR8_rQgkEu4dw_A/edit?gid=1105689284#gid=1105689284"",""G4 vs G5!K24"")"),76.0) -> 76 | G36: =IFERROR(__xludf.DUMMYFUNCTION("IMPORTRANGE(""https://docs.google.com/spreadsheets/d/13_UcftIhRFc8Wdh5sQ-JghNmvplAeKYrOfyqerMoP4E/edit?gid=2010738230#gid=2010738230"",""G4 vs G6!K24"")"),88.0) -> 88
A37: G5 | B37: =IFERROR(__xludf.DUMMYFUNCTION("IMPORTRANGE(""https://docs.google.com/spreadsheets/d/1ZyVAgyLL_HCFyUsFR06BNJrd3d8klI6YuciQugxLR6o/edit?gid=1105689284#gid=1105689284"",""G1 vs G5!T24"")"),138.0) -> 138 | C37: =IFERROR(__xludf.DUMMYFUNCTION("IMPORTRANGE(""https://docs.google.com/spreadsheets/d/1Iv6yZlS3FQWzzgGpdJyYBvJdrkdMPqx_bl527u5CA1U/edit?gid=1105689284#gid=1105689284"",""G2 vs G5!T24"")"),64.0) -> 64 | D37: =IFERROR(__xludf.DUMMYFUNCTION("IMPORTRANGE(""https://docs.google.com/spreadsheets/d/13_UcftIhRFc8Wdh5sQ-JghNmvplAeKYrOfyqerMoP4E/edit?gid=2010738230#gid=2010738230"",""G3 vs G5!T24"")"),140.0) -> 140 | E37: =IFERROR(__xludf.DUMMYFUNCTION("IMPORTRANGE(""https://docs.google.com/spreadsheets/d/1iErVLlc1_s37p2bIQGBV-ueQhrFErR8_rQgkEu4dw_A/edit?gid=1105689284#gid=1105689284"",""G4 vs G5!T24"")"),126.0) -> 126 | G37: =IFERROR(__xludf.DUMMYFUNCTION("IMPORTRANGE(""https://docs.google.com/spreadsheets/d/1gvVcUWK0DrU9Prr-pNKoq3-2DQjDQ1i9v2BBpB5lu8o/edit?gid=1105689284#gid=1105689284"",""G5 vs G6!K24"")"),76.0) -> 76
A38: G6 | B38: =IFERROR(__xludf.DUMMYFUNCTION("IMPORTRANGE(""https://docs.google.com/spreadsheets/d/1Iv6yZlS3FQWzzgGpdJyYBvJdrkdMPqx_bl527u5CA1U/edit?gid=1105689284#gid=1105689284"",""G1 vs G6!T24"")"),58.0) -> 58 | C38: =IFERROR(__xludf.DUMMYFUNCTION("IMPORTRANGE(""https://docs.google.com/spreadsheets/d/1iErVLlc1_s37p2bIQGBV-ueQhrFErR8_rQgkEu4dw_A/edit?gid=1105689284#gid=1105689284"",""G2 vs G6!T24"")"),60.0) -> 60 | D38: =IFERROR(__xludf.DUMMYFUNCTION("IMPORTRANGE(""https://docs.google.com/spreadsheets/d/1ZyVAgyLL_HCFyUsFR06BNJrd3d8klI6YuciQugxLR6o/edit?gid=1105689284#gid=1105689284"",""G3 vs G6!T24"")"),102.0) -> 102 | E38: =IFERROR(__xludf.DUMMYFUNCTION("IMPORTRANGE(""https://docs.google.com/spreadsheets/d/13_UcftIhRFc8Wdh5sQ-JghNmvplAeKYrOfyqerMoP4E/edit?gid=2010738230#gid=2010738230"",""G4 vs G6!T24"")"),92.0) -> 92 | F38: =IFERROR(__xludf.DUMMYFUNCTION("IMPORTRANGE(""https://docs.google.com/spreadsheets/d/1gvVcUWK0DrU9Prr-pNKoq3-2DQjDQ1i9v2BBpB5lu8o/edit?gid=1105689284#gid=1105689284"",""G5 vs G6!T24"")"),72.0) -> 72

Sheet DE Seeding
A1: DE Seeding
A2: Code | B2: School | C2: DE Score | D2: Total Points | E2: Games Won
A3: D3 | B3: Montgomery Blair | C3: =SUM(LiveScoresheet!J17:O17) +LiveScoresheet!I14*0.0211+IF(LiveScoresheet!J17>LiveScoresheet!L15, 100, MAX(LiveScoresheet!J17-LiveScoresheet!L15+50,0))+IF(LiveScoresheet!K17>LiveScoresheet!L16, 100, MAX(LiveScoresheet!K17-LiveScoresheet!L16+50,0))+IF(LiveScoresheet!M17>LiveScoresheet!L18, 100, MAX(LiveScoresheet!M17-LiveScoresheet!L18+50,0))+IF(LiveScoresheet!N17>LiveScoresheet!L19, 100, MAX(LiveScoresheet!N17-LiveScoresheet!L19+50,0))+IF(LiveScoresheet!O17>LiveScoresheet!L20, 100, MAX(LiveScoresheet!O17-LiveScoresheet!L20+50,0)) -> 1473.7718 | D3: =SUM(LiveScoresheet!J17:O17) -> 916 | E3: =0+IF(LiveScoresheet!J17>LiveScoresheet!L15, 1, 0)+IF(LiveScoresheet!K17>LiveScoresheet!L16, 1, 0)+IF(LiveScoresheet!M17>LiveScoresheet!L18, 1, 0)+IF(LiveScoresheet!N17>LiveScoresheet!L19, 1, 0)+IF(LiveScoresheet!O17>LiveScoresheet!L20, 1, 0) -> 5
A4: A2 | B4: Lynbrook 1 | C4: =SUM(LiveScoresheet!B7:G7) +LiveScoresheet!A5*0.0211+IF(LiveScoresheet!B7>LiveScoresheet!C6, 100, MAX(LiveScoresheet!B7-LiveScoresheet!C6+50,0))+IF(LiveScoresheet!D7>LiveScoresheet!C8, 100, MAX(LiveScoresheet!D7-LiveScoresheet!C8+50,0))+IF(LiveScoresheet!E7>LiveScoresheet!C9, 100, MAX(LiveScoresheet!E7-LiveScoresheet!C9+50,0))+IF(LiveScoresheet!F7>LiveScoresheet!C10, 100, MAX(LiveScoresheet!F7-LiveScoresheet!C10+50,0))+IF(LiveScoresheet!G7>LiveScoresheet!C11, 100, MAX(LiveScoresheet!G7-LiveScoresheet!C11+50,0)) -> 1416.4546 | D4: =SUM(LiveScoresheet!B7:G7) -> 864 | E4: =0+IF(LiveScoresheet!B7>LiveScoresheet!C6, 1, 0)+IF(LiveScoresheet!D7>LiveScoresheet!C8, 1, 0)+IF(LiveScoresheet!E7>LiveScoresheet!C9, 1, 0)+IF(LiveScoresheet!F7>LiveScoresheet!C10, 1, 0)+IF(LiveScoresheet!G7>LiveScoresheet!C11, 1, 0) -> 5
A5: F4 | B5: North Hollywood 1 | C5: =SUM(LiveScoresheet!J27:O27) +LiveScoresheet!I23*0.0211+IF(LiveScoresheet!J27>LiveScoresheet!M24, 100, MAX(LiveScoresheet!J27-LiveScoresheet!M24+50,0))+IF(LiveScoresheet!K27>LiveScoresheet!M25, 100, MAX(LiveScoresheet!K27-LiveScoresheet!M25+50,0))+IF(LiveScoresheet!L27>LiveScoresheet!M26, 100, MAX(LiveScoresheet!L27-LiveScoresheet!M26+50,0))+IF(LiveScoresheet!N27>LiveScoresheet!M28, 100, MAX(LiveScoresheet!N27-LiveScoresheet!M28+50,0))+IF(LiveScoresheet!O27>LiveScoresheet!M29, 100, MAX(LiveScoresheet!O27-LiveScoresheet!M29+50,0)) -> 1348.7258 | D5: =SUM(LiveScoresheet!J27:O27) -> 848 | E5: =0+IF(LiveScoresheet!J27>LiveScoresheet!M24, 1, 0)+IF(LiveScoresheet!K27>LiveScoresheet!M25, 1, 0)+IF(LiveScoresheet!L27>LiveScoresheet!M26, 1, 0)+IF(LiveScoresheet!N27>LiveScoresheet!M28, 1, 0)+IF(LiveScoresheet!O27>LiveScoresheet!M29, 1, 0) -> 4
A6: B5 | B6: The Frazer School 1 | C6: =SUM(LiveScoresheet!J10:O10) +LiveScoresheet!I5*0.0211+IF(LiveScoresheet!J10>LiveScoresheet!N6, 100, MAX(LiveScoresheet!J10-LiveScoresheet!N6+50,0))+IF(LiveScoresheet!K10>LiveScoresheet!N7, 100, MAX(LiveScoresheet!K10-LiveScoresheet!N7+50,0))+IF(LiveScoresheet!L10>LiveScoresheet!N8, 100, MAX(LiveScoresheet!L10-LiveScoresheet!N8+50,0))+IF(LiveScoresheet!M10>LiveScoresheet!N9, 100, MAX(LiveScoresheet!M10-LiveScoresheet!N9+50,0))+IF(LiveScoresheet!O10>LiveScoresheet!N11, 100, MAX(LiveScoresheet!O10-LiveScoresheet!N11+50,0)) -> 1347.8984 | D6: =SUM(LiveScoresheet!J10:O10) -> 862 | E6: =0+IF(LiveScoresheet!J10>LiveScoresheet!N6, 1, 0)+IF(LiveScoresheet!K10>LiveScoresheet!N7, 1, 0)+IF(LiveScoresheet!L10>LiveScoresheet!N8, 1, 0)+IF(LiveScoresheet!M10>LiveScoresheet!N9, 1, 0)+IF(LiveScoresheet!O10>LiveScoresheet!N11, 1, 0) -> 4
A7: F3 | B7: Mission San Jose 1 | C7: =SUM(LiveScoresheet!J26:O26) +LiveScoresheet!I23*0.0211+IF(LiveScoresheet!J26>LiveScoresheet!L24, 100, MAX(LiveScoresheet!J26-LiveScoresheet!L24+50,0))+IF(LiveScoresheet!K26>LiveScoresheet!L25, 100, MAX(LiveScoresheet!K26-LiveScoresheet!L25+50,0))+IF(LiveScoresheet!M26>LiveScoresheet!L27, 100, MAX(LiveScoresheet!M26-LiveScoresheet!L27+50,0))+IF(LiveScoresheet!N26>LiveScoresheet!L28, 100, MAX(LiveScoresheet!N26-LiveScoresheet!L28+50,0))+IF(LiveScoresheet!O26>LiveScoresheet!L29, 100, MAX(LiveScoresheet!O26-LiveScoresheet!L29+50,0)) -> 1310.7258 | D7: =SUM(LiveScoresheet!J26:O26) -> 750 | E7: =0+IF(LiveScoresheet!J26>LiveScoresheet!L24, 1, 0)+IF(LiveScoresheet!K26>LiveScoresheet!L25, 1, 0)+IF(LiveScoresheet!M26>LiveScoresheet!L27, 1, 0)+IF(LiveScoresheet!N26>LiveScoresheet!L28, 1, 0)+IF(LiveScoresheet!O26>LiveScoresheet!L29, 1, 0) -> 5
A8: G2 | B8: Lakeside | C8: =SUM(LiveScoresheet!B34:G34) +LiveScoresheet!A32*0.0211+IF(LiveScoresheet!B34>LiveScoresheet!C33, 100, MAX(LiveScoresheet!B34-LiveScoresheet!C33+50,0))+IF(LiveScoresheet!D34>LiveScoresheet!C35, 100, MAX(LiveScoresheet!D34-LiveScoresheet!C35+50,0))+IF(LiveScoresheet!E34>LiveScoresheet!C36, 100, MAX(LiveScoresheet!E34-LiveScoresheet!C36+50,0))+IF(LiveScoresheet!F34>LiveScoresheet!C37, 100, MAX(LiveScoresheet!F34-LiveScoresheet!C37+50,0))+IF(LiveScoresheet!G34>LiveScoresheet!C38, 100, MAX(LiveScoresheet!G34-LiveScoresheet!C38+50,0)) -> 1302.126 | D8: =SUM(LiveScoresheet!B34:G34) -> 746 | E8: =0+IF(LiveScoresheet!B34>LiveScoresheet!C33, 1, 0)+IF(LiveScoresheet!D34>LiveScoresheet!C35, 1, 0)+IF(LiveScoresheet!E34>LiveScoresheet!C36, 1, 0)+IF(LiveScoresheet!F34>LiveScoresheet!C37, 1, 0)+IF(LiveScoresheet!G34>LiveScoresheet!C38, 1, 0) -> 5
A9: E5 | B9: TJHSST | C9: =SUM(LiveScoresheet!B28:G28) +LiveScoresheet!A23*0.0211+IF(LiveScoresheet!B28>LiveScoresheet!F24, 100, MAX(LiveScoresheet!B28-LiveScoresheet!F24+50,0))+IF(LiveScoresheet!C28>LiveScoresheet!F25, 100, MAX(LiveScoresheet!C28-LiveScoresheet!F25+50,0))+IF(LiveScoresheet!D28>LiveScoresheet!F16, 100, MAX(LiveScoresheet!D28-LiveScoresheet!F16+50,0))+IF(LiveScoresheet!E28>LiveScoresheet!F27, 100, MAX(LiveScoresheet!E28-LiveScoresheet!F27+50,0))+IF(LiveScoresheet!G28>LiveScoresheet!F29, 100, MAX(LiveScoresheet!G28-LiveScoresheet!F29+50,0)) -> 1263.5186 | D9: =SUM(LiveScoresheet!B28:G28) -> 706 | E9: =0+IF(LiveScoresheet!B28>LiveScoresheet!F24, 1, 0)+IF(LiveScoresheet!C28>LiveScoresheet!F25, 1, 0)+IF(LiveScoresheet!D28>LiveScoresheet!F26, 1, 0)+IF(LiveScoresheet!E28>LiveScoresheet!F27, 1, 0)+IF(LiveScoresheet!G28>LiveScoresheet!F29, 1, 0) -> 5
A10: E2 | B10: Iolani High School 1 | C10: =SUM(LiveScoresheet!B25:G25) +LiveScoresheet!A23*0.0211+IF(LiveScoresheet!B25>LiveScoresheet!C24, 100, MAX(LiveScoresheet!B25-LiveScoresheet!C24+50,0))+IF(LiveScoresheet!D25>LiveScoresheet!C16, 100, MAX(LiveScoresheet!D25-LiveScoresheet!C16+50,0))+IF(LiveScoresheet!E25>LiveScoresheet!C27, 100, MAX(LiveScoresheet!E25-LiveScoresheet!C27+50,0))+IF(LiveScoresheet!F25>LiveScoresheet!C28, 100, MAX(LiveScoresheet!F25-LiveScoresheet!C28+50,0))+IF(LiveScoresheet!G25>LiveScoresheet!C29, 100, MAX(LiveScoresheet!G25-LiveScoresheet!C29+50,0)) -> 1133.5186 | D10: =SUM(LiveScoresheet!B25:G25) -> 660 | E10: =0+IF(LiveScoresheet!B25>LiveScoresheet!C24, 1, 0)+IF(LiveScoresheet!D25>LiveScoresheet!C26, 1, 0)+IF(LiveScoresheet!E25>LiveScoresheet!C27, 1, 0)+IF(LiveScoresheet!F25>LiveScoresheet!C28, 1, 0)+IF(LiveScoresheet!G25>LiveScoresheet!C29, 1, 0) -> 4
A11: A6 | B11: Middleton | C11: =SUM(LiveScoresheet!B11:G11) +LiveScoresheet!A5*0.0211+IF(LiveScoresheet!B11>LiveScoresheet!G6, 100, MAX(LiveScoresheet!B11-LiveScoresheet!G6+50,0))+IF(LiveScoresheet!C11>LiveScoresheet!G7, 100, MAX(LiveScoresheet!C11-LiveScoresheet!G7+50,0))+IF(LiveScoresheet!D11>LiveScoresheet!G8, 100, MAX(LiveScoresheet!D11-LiveScoresheet!G8+50,0))+IF(LiveScoresheet!E11>LiveScoresheet!G9, 100, MAX(LiveScoresheet!E11-LiveScoresheet!G9+50,0))+IF(LiveScoresheet!F11>LiveScoresheet!G10, 100, MAX(LiveScoresheet!F11-LiveScoresheet!G10+50,0)) -> 1096.4546 | D11: =SUM(LiveScoresheet!B11:G11) -> 644 | E11: =0+IF(LiveScoresheet!B11>LiveScoresheet!G6, 1, 0)+IF(LiveScoresheet!C11>LiveScoresheet!G7, 1, 0)+IF(LiveScoresheet!D11>LiveScoresheet!G8, 1, 0)+IF(LiveScoresheet!E11>LiveScoresheet!G9, 1, 0)+IF(LiveScoresheet!F11>LiveScoresheet!G10, 1, 0) -> 4
A12: C2 | B12: West Windsor-Plainsboro NORTH 1 | C12: =SUM(LiveScoresheet!B16:G16) +LiveScoresheet!A14*0.0211+IF(LiveScoresheet!B16>LiveScoresheet!C15, 100, MAX(LiveScoresheet!B16-LiveScoresheet!C15+50,0))+IF(LiveScoresheet!D16>LiveScoresheet!C17, 100, MAX(LiveScoresheet!D16-LiveScoresheet!C17+50,0))+IF(LiveScoresheet!E16>LiveScoresheet!C18, 100, MAX(LiveScoresheet!E16-LiveScoresheet!C18+50,0))+IF(LiveScoresheet!F16>LiveScoresheet!C19, 100, MAX(LiveScoresheet!F16-LiveScoresheet!C19+50,0))+IF(LiveScoresheet!G16>LiveScoresheet!C20, 100, MAX(LiveScoresheet!G16-LiveScoresheet!C20+50,0)) -> 1077.594 | D12: =SUM(LiveScoresheet!B16:G16) -> 574 | E12: =0.5+IF(LiveScoresheet!B16>LiveScoresheet!C15, 1, 0)+IF(LiveScoresheet!D16>LiveScoresheet!C17, 1, 0)+IF(LiveScoresheet!E16>LiveScoresheet!C18, 1, 0)+IF(LiveScoresheet!F16>LiveScoresheet!C19, 1, 0)+IF(LiveScoresheet!G16>LiveScoresheet!C20, 1, 0) -> 4.5
A13: D4 | B13: Canyon Crest Academy 1 | C13: =SUM(LiveScoresheet!J18:O18) +LiveScoresheet!I14*0.0211+IF(LiveScoresheet!J18>LiveScoresheet!M15, 100, MAX(LiveScoresheet!J18-LiveScoresheet!M15+50,0))+IF(LiveScoresheet!K18>LiveScoresheet!M16, 100, MAX(LiveScoresheet!K18-LiveScoresheet!M16+50,0))+IF(LiveScoresheet!L18>LiveScoresheet!M17, 100, MAX(LiveScoresheet!L18-LiveScoresheet!M17+50,0))+IF(LiveScoresheet!N18>LiveScoresheet!M19, 100, MAX(LiveScoresheet!N18-LiveScoresheet!M19+50,0))+IF(LiveScoresheet!O18>LiveScoresheet!M20, 100, MAX(LiveScoresheet!O18-LiveScoresheet!M20+50,0)) -> 1073.7718 | D13: =SUM(LiveScoresheet!J18:O18) -> 616 | E13: =0+IF(LiveScoresheet!J18>LiveScoresheet!M15, 1, 0)+IF(LiveScoresheet!K18>LiveScoresheet!M16, 1, 0)+IF(LiveScoresheet!L18>LiveScoresheet!M17, 1, 0)+IF(LiveScoresheet!N18>LiveScoresheet!M19, 1, 0)+IF(LiveScoresheet!O18>LiveScoresheet!M20, 1, 0) -> 4
