Workbook

Sheet TUHStand
A1: Username | B1: Team | C1: Round 1 | D1: Round 2 | E1: Round 3 | F1: Round 4 | G1: Round 5 | H1: Round 6 | I1: Round 7 | J1: Round 8 | K1: Round 9 | L1: Round 10 | M1: Round 11 | N1: Round 12 | O1: Round 13 | P1: Round 14 | Q1: Round 15 | R1: TUH
A2: Daniel Z | B2: ASFA B | C2: 23 | D2: 23 | E2: 23 | F2: 23 | G2: 23 | H2: =IFERROR(__xludf.DUMMYFUNCTION("HLOOKUP($A2,IMPORTRANGE(""https://docs.google.com/spreadsheets/d/16J5ie7OD1E99qGO9lMDm8w5Yls-v190B7DTolJ5TmFc/edit#gid=0"",""'Game 3'!$B$2:$Q$31""),30,False)"),23.0) -> 23 | I2: 23 | J2: =IFERROR(__xludf.DUMMYFUNCTION("IFERROR(HLOOKUP($A2,IMPORTRANGE(""https://docs.google.com/spreadsheets/d/1CTYfdyRk_RFGM3I2iN9bKeD9zUPzEm1ajzml6VgwfIU/edit#gid=0"",""'Game 1'!$B$2:$Q$31""),30,False),0)"),23.0) -> 23 | K2: =IFERROR(__xludf.DUMMYFUNCTION("IFERROR(HLOOKUP($A2,IMPORTRANGE(""https://docs.google.com/spreadsheets/d/11NFkzOdQyW-OtxSDuGslNCgNjx7HUb2FU7KnlNnPMgY/edit#gid=0"",""'Game 12'!$B$2:$Q$31""),30,False),0)"),23.0) -> 23 | L2: =IFERROR(__xludf.DUMMYFUNCTION("IFERROR(HLOOKUP($A2,IMPORTRANGE(""https://docs.google.com/spreadsheets/d/1CLg5-jaE4ta0-u4oE1qbBplQ5Mf3Oj9ONFgL0zJ7Ol4/edit#gid=0"",""'Game 13'!$B$2:$Q$31""),30,False),1)"),23.0) -> 23 | M2: =IFERROR(__xludf.DUMMYFUNCTION("IFERROR(HLOOKUP($A2,IMPORTRANGE(""https://docs.google.com/spreadsheets/d/1CeexgK4KxWj3k_7nql_k8-RPxXMwTJyB4Q3vAASeDlA/edit#gid=0"",""'Game 13'!$B$2:$Q$31""),30,False),1)"),23.0) -> 23 | N2: =IFERROR(__xludf.DUMMYFUNCTION("IFERROR(HLOOKUP($A2,IMPORTRANGE(""https://docs.google.com/spreadsheets/d/1MNwUNMjcwK6bEgCXwB73jpbK5gJAXS8ZMpbEMLJEP3E/edit#gid=0"",""'Game 8'!$B$2:$Q$31""),30,False),1)"),23.0) -> 23 | O2: =IFERROR(__xludf.DUMMYFUNCTION("IFERROR(HLOOKUP($A2,IMPORTRANGE(""https://docs.google.com/spreadsheets/d/1UrzyxmT40kDZwVrLMf1yyXfP-pyczRAw9Y8Rw-uXG3c/edit#gid=0"",""'Game 13'!$B$2:$Q$31""),30,False),1)"),23.0) -> 23 | P2: =IFERROR(__xludf.DUMMYFUNCTION("IFERROR(HLOOKUP($A2,IMPORTRANGE(""https://docs.google.com/spreadsheets/d/1iyMhSYWifw-KGFtyeBpNxVZr4BhcV9hVZuShgJ9Ia0E/edit#gid=0"",""'Game 6'!$B$2:$Q$31""),30,False),1)"),23.0) -> 23 | Q2: =IFERROR(__xludf.DUMMYFUNCTION("IFERROR(HLOOKUP($A2,IMPORTRANGE(""https://docs.google.com/spreadsheets/d/1sSbIK-vvHsSY0LghLJ9gcnW8Hec_ITI2tFmpeqI999A/edit#gid=0"",""'Game 9'!$B$2:$Q$31""),30,False),1)"),23.0) -> 23 | R2: =SUM(C2:Q2) -> 345
A3: Henna | B3: ASFA B | C3: 23 | D3: 23 | E3: 12 | F3: 23 | G3: 12 | H3: =IFERROR(__xludf.DUMMYFUNCTION("HLOOKUP($A3,IMPORTRANGE(""https://docs.google.com/spreadsheets/d/16J5ie7OD1E99qGO9lMDm8w5Yls-v190B7DTolJ5TmFc/edit#gid=0"",""'Game 3'!$B$2:$Q$31""),30,False)"),23.0) -> 23 | I3: 23 | J3: =IFERROR(__xludf.DUMMYFUNCTION("IFERROR(HLOOKUP($A3,IMPORTRANGE(""https://docs.google.com/spreadsheets/d/1CTYfdyRk_RFGM3I2iN9bKeD9zUPzEm1ajzml6VgwfIU/edit#gid=0"",""'Game 1'!$B$2:$Q$31""),30,False),0)"),23.0) -> 23 | K3: =IFERROR(__xludf.DUMMYFUNCTION("IFERROR(HLOOKUP($A3,IMPORTRANGE(""https://docs.google.com/spreadsheets/d/11NFkzOdQyW-OtxSDuGslNCgNjx7HUb2FU7KnlNnPMgY/edit#gid=0"",""'Game 12'!$B$2:$Q$31""),30,False),0)"),23.0) -> 23 | L3: =IFERROR(__xludf.DUMMYFUNCTION("IFERROR(HLOOKUP($A3,IMPORTRANGE(""https://docs.google.com/spreadsheets/d/1CLg5-jaE4ta0-u4oE1qbBplQ5Mf3Oj9ONFgL0zJ7Ol4/edit#gid=0"",""'Game 13'!$B$2:$Q$31""),30,False),1)"),12.0) -> 12 | M3: =IFERROR(__xludf.DUMMYFUNCTION("IFERROR(HLOOKUP($A3,IMPORTRANGE(""https://docs.google.com/spreadsheets/d/1CeexgK4KxWj3k_7nql_k8-RPxXMwTJyB4Q3vAASeDlA/edit#gid=0"",""'Game 13'!$B$2:$Q$31""),30,False),1)"),23.0) -> 23 | N3: =IFERROR(__xludf.DUMMYFUNCTION("IFERROR(HLOOKUP($A3,IMPORTRANGE(""https://docs.google.com/spreadsheets/d/1MNwUNMjcwK6bEgCXwB73jpbK5gJAXS8ZMpbEMLJEP3E/edit#gid=0"",""'Game 8'!$B$2:$Q$31""),30,False),1)"),0.0) -> 0 | O3: =IFERROR(__xludf.DUMMYFUNCTION("IFERROR(HLOOKUP($A3,IMPORTRANGE(""https://docs.google.com/spreadsheets/d/1UrzyxmT40kDZwVrLMf1yyXfP-pyczRAw9Y8Rw-uXG3c/edit#gid=0"",""'Game 13'!$B$2:$Q$31""),30,False),1)"),23.0) -> 23 | P3: =IFERROR(__xludf.DUMMYFUNCTION("IFERROR(HLOOKUP($A3,IMPORTRANGE(""https://docs.google.com/spreadsheets/d/1iyMhSYWifw-KGFtyeBpNxVZr4BhcV9hVZuShgJ9Ia0E/edit#gid=0"",""'Game 6'!$B$2:$Q$31""),30,False),1)"),23.0) -> 23 | Q3: =IFERROR(__xludf.DUMMYFUNCTION("IFERROR(HLOOKUP($A3,IMPORTRANGE(""https://docs.google.com/spreadsheets/d/1sSbIK-vvHsSY0LghLJ9gcnW8Hec_ITI2tFmpeqI999A/edit#gid=0"",""'Game 9'!$B$2:$Q$31""),30,False),1)"),11.0) -> 11 | R3: =SUM(C3:Q3) -> 277
A4: Sofia | B4: ASFA B | C4: 23 | D4: 23 | E4: 23 | F4: 23 | G4: 23 | H4: =IFERROR(__xludf.DUMMYFUNCTION("HLOOKUP($A4,IMPORTRANGE(""https://docs.google.com/spreadsheets/d/16J5ie7OD1E99qGO9lMDm8w5Yls-v190B7DTolJ5TmFc/edit#gid=0"",""'Game 3'!$B$2:$Q$31""),30,False)"),23.0) -> 23 | I4: 0 | J4: =IFERROR(__xludf.DUMMYFUNCTION("IFERROR(HLOOKUP($A4,IMPORTRANGE(""https://docs.google.com/spreadsheets/d/1CTYfdyRk_RFGM3I2iN9bKeD9zUPzEm1ajzml6VgwfIU/edit#gid=0"",""'Game 1'!$B$2:$Q$31""),30,False),0)"),23.0) -> 23 | K4: =IFERROR(__xludf.DUMMYFUNCTION("IFERROR(HLOOKUP($A4,IMPORTRANGE(""https://docs.google.com/spreadsheets/d/11NFkzOdQyW-OtxSDuGslNCgNjx7HUb2FU7KnlNnPMgY/edit#gid=0"",""'Game 12'!$B$2:$Q$31""),30,False),0)"),23.0) -> 23 | L4: =IFERROR(__xludf.DUMMYFUNCTION("IFERROR(HLOOKUP($A4,IMPORTRANGE(""https://docs.google.com/spreadsheets/d/1CLg5-jaE4ta0-u4oE1qbBplQ5Mf3Oj9ONFgL0zJ7Ol4/edit#gid=0"",""'Game 13'!$B$2:$Q$31""),30,False),1)"),23.0) -> 23 | M4: =IFERROR(__xludf.DUMMYFUNCTION("IFERROR(HLOOKUP($A4,IMPORTRANGE(""https://docs.google.com/spreadsheets/d/1CeexgK4KxWj3k_7nql_k8-RPxXMwTJyB4Q3vAASeDlA/edit#gid=0"",""'Game 13'!$B$2:$Q$31""),30,False),1)"),23.0) -> 23 | N4: =IFERROR(__xludf.DUMMYFUNCTION("IFERROR(HLOOKUP($A4,IMPORTRANGE(""https://docs.google.com/spreadsheets/d/1MNwUNMjcwK6bEgCXwB73jpbK5gJAXS8ZMpbEMLJEP3E/edit#gid=0"",""'Game 8'!$B$2:$Q$31""),30,False),1)"),0.0) -> 0 | O4: =IFERROR(__xludf.DUMMYFUNCTION("IFERROR(HLOOKUP($A4,IMPORTRANGE(""https://docs.google.com/spreadsheets/d/1UrzyxmT40kDZwVrLMf1yyXfP-pyczRAw9Y8Rw-uXG3c/edit#gid=0"",""'Game 13'!$B$2:$Q$31""),30,False),1)"),23.0) -> 23 | P4: =IFERROR(__xludf.DUMMYFUNCTION("IFERROR(HLOOKUP($A4,IMPORTRANGE(""https://docs.google.com/spreadsheets/d/1iyMhSYWifw-KGFtyeBpNxVZr4BhcV9hVZuShgJ9Ia0E/edit#gid=0"",""'Game 6'!$B$2:$Q$31""),30,False),1)"),0.0) -> 0 | Q4: =IFERROR(__xludf.DUMMYFUNCTION("IFERROR(HLOOKUP($A4,IMPORTRANGE(""https://docs.google.com/spreadsheets/d/1sSbIK-vvHsSY0LghLJ9gcnW8Hec_ITI2tFmpeqI999A/edit#gid=0"",""'Game 9'!$B$2:$Q$31""),30,False),1)"),23.0) -> 23 | R4: =SUM(C4:Q4) -> 276
A5: Trisha | B5: ASFA B | C5: 0 | D5: 0 | E5: 23 | F5: 23 | G5: 23 | H5: =IFERROR(__xludf.DUMMYFUNCTION("HLOOKUP($A5,IMPORTRANGE(""https://docs.google.com/spreadsheets/d/16J5ie7OD1E99qGO9lMDm8w5Yls-v190B7DTolJ5TmFc/edit#gid=0"",""'Game 3'!$B$2:$Q$31""),30,False)"),12.0) -> 12 | I5: 23 | J5: =IFERROR(__xludf.DUMMYFUNCTION("IFERROR(HLOOKUP($A5,IMPORTRANGE(""https://docs.google.com/spreadsheets/d/1CTYfdyRk_RFGM3I2iN9bKeD9zUPzEm1ajzml6VgwfIU/edit#gid=0"",""'Game 1'!$B$2:$Q$31""),30,False),0)"),23.0) -> 23 | K5: =IFERROR(__xludf.DUMMYFUNCTION("IFERROR(HLOOKUP($A5,IMPORTRANGE(""https://docs.google.com/spreadsheets/d/11NFkzOdQyW-OtxSDuGslNCgNjx7HUb2FU7KnlNnPMgY/edit#gid=0"",""'Game 12'!$B$2:$Q$31""),30,False),0)"),0.0) -> 0 | L5: =IFERROR(__xludf.DUMMYFUNCTION("IFERROR(HLOOKUP($A5,IMPORTRANGE(""https://docs.google.com/spreadsheets/d/1CLg5-jaE4ta0-u4oE1qbBplQ5Mf3Oj9ONFgL0zJ7Ol4/edit#gid=0"",""'Game 13'!$B$2:$Q$31""),30,False),1)"),11.0) -> 11 | M5: =IFERROR(__xludf.DUMMYFUNCTION("IFERROR(HLOOKUP($A5,IMPORTRANGE(""https://docs.google.com/spreadsheets/d/1CeexgK4KxWj3k_7nql_k8-RPxXMwTJyB4Q3vAASeDlA/edit#gid=0"",""'Game 13'!$B$2:$Q$31""),30,False),1)"),12.0) -> 12 | N5: =IFERROR(__xludf.DUMMYFUNCTION("IFERROR(HLOOKUP($A5,IMPORTRANGE(""https://docs.google.com/spreadsheets/d/1MNwUNMjcwK6bEgCXwB73jpbK5gJAXS8ZMpbEMLJEP3E/edit#gid=0"",""'Game 8'!$B$2:$Q$31""),30,False),1)"),23.0) -> 23 | O5: =IFERROR(__xludf.DUMMYFUNCTION("IFERROR(HLOOKUP($A5,IMPORTRANGE(""https://docs.google.com/spreadsheets/d/1UrzyxmT40kDZwVrLMf1yyXfP-pyczRAw9Y8Rw-uXG3c/edit#gid=0"",""'Game 13'!$B$2:$Q$31""),30,False),1)"),12.0) -> 12 | P5: =IFERROR(__xludf.DUMMYFUNCTION("IFERROR(HLOOKUP($A5,IMPORTRANGE(""https://docs.google.com/spreadsheets/d/1iyMhSYWifw-KGFtyeBpNxVZr4BhcV9hVZuShgJ9Ia0E/edit#gid=0"",""'Game 6'!$B$2:$Q$31""),30,False),1)"),23.0) -> 23 | Q5: =IFERROR(__xludf.DUMMYFUNCTION("IFERROR(HLOOKUP($A5,IMPORTRANGE(""https://docs.google.com/spreadsheets/d/1sSbIK-vvHsSY0LghLJ9gcnW8Hec_ITI2tFmpeqI999A/edit#gid=0"",""'Game 9'!$B$2:$Q$31""),30,False),1)"),12.0) -> 12 | R5: =SUM(C5:Q5) -> 220
A6: William | B6: ASFA B | C6: 23 | D6: 23 | E6: 11 | F6: 0 | G6: 11 | H6: =IFERROR(__xludf.DUMMYFUNCTION("HLOOKUP($A6,IMPORTRANGE(""https://docs.google.com/spreadsheets/d/16J5ie7OD1E99qGO9lMDm8w5Yls-v190B7DTolJ5TmFc/edit#gid=0"",""'Game 3'!$B$2:$Q$31""),30,False)"),11.0) -> 11 | I6: 23 | J6: =IFERROR(__xludf.DUMMYFUNCTION("IFERROR(HLOOKUP($A6,IMPORTRANGE(""https://docs.google.com/spreadsheets/d/1CTYfdyRk_RFGM3I2iN9bKeD9zUPzEm1ajzml6VgwfIU/edit#gid=0"",""'Game 1'!$B$2:$Q$31""),30,False),0)"),0.0) -> 0 | K6: =IFERROR(__xludf.DUMMYFUNCTION("IFERROR(HLOOKUP($A6,IMPORTRANGE(""https://docs.google.com/spreadsheets/d/11NFkzOdQyW-OtxSDuGslNCgNjx7HUb2FU7KnlNnPMgY/edit#gid=0"",""'Game 12'!$B$2:$Q$31""),30,False),0)"),23.0) -> 23 | L6: =IFERROR(__xludf.DUMMYFUNCTION("IFERROR(HLOOKUP($A6,IMPORTRANGE(""https://docs.google.com/spreadsheets/d/1CLg5-jaE4ta0-u4oE1qbBplQ5Mf3Oj9ONFgL0zJ7Ol4/edit#gid=0"",""'Game 13'!$B$2:$Q$31""),30,False),1)"),23.0) -> 23 | M6: =IFERROR(__xludf.DUMMYFUNCTION("IFERROR(HLOOKUP($A6,IMPORTRANGE(""https://docs.google.com/spreadsheets/d/1CeexgK4KxWj3k_7nql_k8-RPxXMwTJyB4Q3vAASeDlA/edit#gid=0"",""'Game 13'!$B$2:$Q$31""),30,False),1)"),11.0) -> 11 | N6: =IFERROR(__xludf.DUMMYFUNCTION("IFERROR(HLOOKUP($A6,IMPORTRANGE(""https://docs.google.com/spreadsheets/d/1MNwUNMjcwK6bEgCXwB73jpbK5gJAXS8ZMpbEMLJEP3E/edit#gid=0"",""'Game 8'!$B$2:$Q$31""),30,False),1)"),23.0) -> 23 | O6: =IFERROR(__xludf.DUMMYFUNCTION("IFERROR(HLOOKUP($A6,IMPORTRANGE(""https://docs.google.com/spreadsheets/d/1UrzyxmT40kDZwVrLMf1yyXfP-pyczRAw9Y8Rw-uXG3c/edit#gid=0"",""'Game 13'!$B$2:$Q$31""),30,False),1)"),11.0) -> 11 | P6: =IFERROR(__xludf.DUMMYFUNCTION("IFERROR(HLOOKUP($A6,IMPORTRANGE(""https://docs.google.com/spreadsheets/d/1iyMhSYWifw-KGFtyeBpNxVZr4BhcV9hVZuShgJ9Ia0E/edit#gid=0"",""'Game 6'!$B$2:$Q$31""),30,False),1)"),23.0) -> 23 | Q6: =IFERROR(__xludf.DUMMYFUNCTION("IFERROR(HLOOKUP($A6,IMPORTRANGE(""https://docs.google.com/spreadsheets/d/1sSbIK-vvHsSY0LghLJ9gcnW8Hec_ITI2tFmpeqI999A/edit#gid=0"",""'Game 9'!$B$2:$Q$31""),30,False),1)"),23.0) -> 23 | R6: =SUM(C6:Q6) -> 239
A7: Albert H | B7: Beltway Blazers B | C7: 23 | D7: 12 | E7: 23 | F7: 23 | G7: 23 | H7: =IFERROR(__xludf.DUMMYFUNCTION("HLOOKUP($A7,IMPORTRANGE(""https://docs.google.com/spreadsheets/d/16J5ie7OD1E99qGO9lMDm8w5Yls-v190B7DTolJ5TmFc/edit#gid=0"",""'Game 5'!$B$2:$Q$31""),30,False)"),23.0) -> 23 | I7: 23 | J7: =IFERROR(__xludf.DUMMYFUNCTION("IFERROR(HLOOKUP($A7,IMPORTRANGE(""https://docs.google.com/spreadsheets/d/1CTYfdyRk_RFGM3I2iN9bKeD9zUPzEm1ajzml6VgwfIU/edit#gid=0"",""'Game 12'!$B$2:$Q$31""),30,False),0)"),23.0) -> 23 | K7: =IFERROR(__xludf.DUMMYFUNCTION("IFERROR(HLOOKUP($A7,IMPORTRANGE(""https://docs.google.com/spreadsheets/d/11NFkzOdQyW-OtxSDuGslNCgNjx7HUb2FU7KnlNnPMgY/edit#gid=0"",""'Game 3'!$B$2:$Q$31""),30,False),0)"),12.0) -> 12 | L7: =IFERROR(__xludf.DUMMYFUNCTION("IFERROR(HLOOKUP($A7,IMPORTRANGE(""https://docs.google.com/spreadsheets/d/1CLg5-jaE4ta0-u4oE1qbBplQ5Mf3Oj9ONFgL0zJ7Ol4/edit#gid=0"",""'Game 11'!$B$2:$Q$31""),30,False),1)"),23.0) -> 23 | M7: =IFERROR(__xludf.DUMMYFUNCTION("IFERROR(HLOOKUP($A7,IMPORTRANGE(""https://docs.google.com/spreadsheets/d/1CeexgK4KxWj3k_7nql_k8-RPxXMwTJyB4Q3vAASeDlA/edit#gid=0"",""'Game 10'!$B$2:$Q$31""),30,False),1)"),11.0) -> 11 | N7: =IFERROR(__xludf.DUMMYFUNCTION("IFERROR(HLOOKUP($A7,IMPORTRANGE(""https://docs.google.com/spreadsheets/d/1MNwUNMjcwK6bEgCXwB73jpbK5gJAXS8ZMpbEMLJEP3E/edit#gid=0"",""'Game 10'!$B$2:$Q$31""),30,False),1)"),23.0) -> 23 | O7: =IFERROR(__xludf.DUMMYFUNCTION("IFERROR(HLOOKUP($A7,IMPORTRANGE(""https://docs.google.com/spreadsheets/d/1UrzyxmT40kDZwVrLMf1yyXfP-pyczRAw9Y8Rw-uXG3c/edit#gid=0"",""'Game 4'!$B$2:$Q$31""),30,False),1)"),23.0) -> 23 | P7: =IFERROR(__xludf.DUMMYFUNCTION("IFERROR(HLOOKUP($A7,IMPORTRANGE(""https://docs.google.com/spreadsheets/d/1iyMhSYWifw-KGFtyeBpNxVZr4BhcV9hVZuShgJ9Ia0E/edit#gid=0"",""'Game 11'!$B$2:$Q$31""),30,False),1)"),23.0) -> 23 | Q7: =IFERROR(__xludf.DUMMYFUNCTION("IFERROR(HLOOKUP($A7,IMPORTRANGE(""https://docs.google.com/spreadsheets/d/1sSbIK-vvHsSY0LghLJ9gcnW8Hec_ITI2tFmpeqI999A/edit#gid=0"",""'Game 9'!$B$2:$Q$31""),30,False),1)"),23.0) -> 23 | R7: =SUM(C7:Q7) -> 311
A8: Ashley | B8: Beltway Blazers B | C8: 12 | D8: 23 | E8: 0 | F8: 23 | G8: 23 | H8: =IFERROR(__xludf.DUMMYFUNCTION("HLOOKUP($A8,IMPORTRANGE(""https://docs.google.com/spreadsheets/d/16J5ie7OD1E99qGO9lMDm8w5Yls-v190B7DTolJ5TmFc/edit#gid=0"",""'Game 5'!$B$2:$Q$31""),30,False)"),0.0) -> 0 | I8: 23 | J8: =IFERROR(__xludf.DUMMYFUNCTION("IFERROR(HLOOKUP($A8,IMPORTRANGE(""https://docs.google.com/spreadsheets/d/1CTYfdyRk_RFGM3I2iN9bKeD9zUPzEm1ajzml6VgwfIU/edit#gid=0"",""'Game 12'!$B$2:$Q$31""),30,False),0)"),23.0) -> 23 | K8: =IFERROR(__xludf.DUMMYFUNCTION("IFERROR(HLOOKUP($A8,IMPORTRANGE(""https://docs.google.com/spreadsheets/d/11NFkzOdQyW-OtxSDuGslNCgNjx7HUb2FU7KnlNnPMgY/edit#gid=0"",""'Game 3'!$B$2:$Q$31""),30,False),0)"),23.0) -> 23 | L8: =IFERROR(__xludf.DUMMYFUNCTION("IFERROR(HLOOKUP($A8,IMPORTRANGE(""https://docs.google.com/spreadsheets/d/1CLg5-jaE4ta0-u4oE1qbBplQ5Mf3Oj9ONFgL0zJ7Ol4/edit#gid=0"",""'Game 11'!$B$2:$Q$31""),30,False),1)"),23.0) -> 23 | M8: =IFERROR(__xludf.DUMMYFUNCTION("IFERROR(HLOOKUP($A8,IMPORTRANGE(""https://docs.google.com/spreadsheets/d/1CeexgK4KxWj3k_7nql_k8-RPxXMwTJyB4Q3vAASeDlA/edit#gid=0"",""'Game 10'!$B$2:$Q$31""),30,False),1)"),23.0) -> 23 | N8: =IFERROR(__xludf.DUMMYFUNCTION("IFERROR(HLOOKUP($A8,IMPORTRANGE(""https://docs.google.com/spreadsheets/d/1MNwUNMjcwK6bEgCXwB73jpbK5gJAXS8ZMpbEMLJEP3E/edit#gid=0"",""'Game 10'!$B$2:$Q$31""),30,False),1)"),23.0) -> 23 | O8: =IFERROR(__xludf.DUMMYFUNCTION("IFERROR(HLOOKUP($A8,IMPORTRANGE(""https://docs.google.com/spreadsheets/d/1UrzyxmT40kDZwVrLMf1yyXfP-pyczRAw9Y8Rw-uXG3c/edit#gid=0"",""'Game 4'!$B$2:$Q$31""),30,False),1)"),23.0) -> 23 | P8: =IFERROR(__xludf.DUMMYFUNCTION("IFERROR(HLOOKUP($A8,IMPORTRANGE(""https://docs.google.com/spreadsheets/d/1iyMhSYWifw-KGFtyeBpNxVZr4BhcV9hVZuShgJ9Ia0E/edit#gid=0"",""'Game 11'!$B$2:$Q$31""),30,False),1)"),23.0) -> 23 | Q8: =IFERROR(__xludf.DUMMYFUNCTION("IFERROR(HLOOKUP($A8,IMPORTRANGE(""https://docs.google.com/spreadsheets/d/1sSbIK-vvHsSY0LghLJ9gcnW8Hec_ITI2tFmpeqI999A/edit#gid=0"",""'Game 9'!$B$2:$Q$31""),30,False),1)"),23.0) -> 23 | R8: =SUM(C8:Q8) -> 288
A9: Daniel Y | B9: Beltway Blazers B | C9: 23 | D9: 23 | E9: 23 | F9: 11 | G9: 0 | H9: =IFERROR(__xludf.DUMMYFUNCTION("HLOOKUP($A9,IMPORTRANGE(""https://docs.google.com/spreadsheets/d/16J5ie7OD1E99qGO9lMDm8w5Yls-v190B7DTolJ5TmFc/edit#gid=0"",""'Game 5'!$B$2:$Q$31""),30,False)"),23.0) -> 23 | I9: 0 | J9: =IFERROR(__xludf.DUMMYFUNCTION("IFERROR(HLOOKUP($A9,IMPORTRANGE(""https://docs.google.com/spreadsheets/d/1CTYfdyRk_RFGM3I2iN9bKeD9zUPzEm1ajzml6VgwfIU/edit#gid=0"",""'Game 12'!$B$2:$Q$31""),30,False),0)"),0.0) -> 0 | K9: =IFERROR(__xludf.DUMMYFUNCTION("IFERROR(HLOOKUP($A9,IMPORTRANGE(""https://docs.google.com/spreadsheets/d/11NFkzOdQyW-OtxSDuGslNCgNjx7HUb2FU7KnlNnPMgY/edit#gid=0"",""'Game 3'!$B$2:$Q$31""),30,False),0)"),23.0) -> 23 | L9: =IFERROR(__xludf.DUMMYFUNCTION("IFERROR(HLOOKUP($A9,IMPORTRANGE(""https://docs.google.com/spreadsheets/d/1CLg5-jaE4ta0-u4oE1qbBplQ5Mf3Oj9ONFgL0zJ7Ol4/edit#gid=0"",""'Game 11'!$B$2:$Q$31""),30,False),1)"),0.0) -> 0 | M9: =IFERROR(__xludf.DUMMYFUNCTION("IFERROR(HLOOKUP($A9,IMPORTRANGE(""https://docs.google.com/spreadsheets/d/1CeexgK4KxWj3k_7nql_k8-RPxXMwTJyB4Q3vAASeDlA/edit#gid=0"",""'Game 10'!$B$2:$Q$31""),30,False),1)"),23.0) -> 23 | N9: =IFERROR(__xludf.DUMMYFUNCTION("IFERROR(HLOOKUP($A9,IMPORTRANGE(""https://docs.google.com/spreadsheets/d/1MNwUNMjcwK6bEgCXwB73jpbK5gJAXS8ZMpbEMLJEP3E/edit#gid=0"",""'Game 10'!$B$2:$Q$31""),30,False),1)"),0.0) -> 0 | O9: =IFERROR(__xludf.DUMMYFUNCTION("IFERROR(HLOOKUP($A9,IMPORTRANGE(""https://docs.google.com/spreadsheets/d/1UrzyxmT40kDZwVrLMf1yyXfP-pyczRAw9Y8Rw-uXG3c/edit#gid=0"",""'Game 4'!$B$2:$Q$31""),30,False),1)"),0.0) -> 0 | P9: =IFERROR(__xludf.DUMMYFUNCTION("IFERROR(HLOOKUP($A9,IMPORTRANGE(""https://docs.google.com/spreadsheets/d/1iyMhSYWifw-KGFtyeBpNxVZr4BhcV9hVZuShgJ9Ia0E/edit#gid=0"",""'Game 11'!$B$2:$Q$31""),30,False),1)"),0.0) -> 0 | Q9: =IFERROR(__xludf.DUMMYFUNCTION("IFERROR(HLOOKUP($A9,IMPORTRANGE(""https://docs.google.com/spreadsheets/d/1sSbIK-vvHsSY0LghLJ9gcnW8Hec_ITI2tFmpeqI999A/edit#gid=0"",""'Game 9'!$B$2:$Q$31""),30,False),1)"),0.0) -> 0 | R9: =SUM(C9:Q9) -> 149
A10: Leela | B10: Beltway Blazers B | C10: 23 | D10: 11 | E10: 23 | F10: 12 | G10: 23 | H10: =IFERROR(__xludf.DUMMYFUNCTION("HLOOKUP($A10,IMPORTRANGE(""https://docs.google.com/spreadsheets/d/16J5ie7OD1E99qGO9lMDm8w5Yls-v190B7DTolJ5TmFc/edit#gid=0"",""'Game 5'!$B$2:$Q$31""),30,False)"),23.0) -> 23 | I10: 0 | J10: =IFERROR(__xludf.DUMMYFUNCTION("IFERROR(HLOOKUP($A10,IMPORTRANGE(""https://docs.google.com/spreadsheets/d/1CTYfdyRk_RFGM3I2iN9bKeD9zUPzEm1ajzml6VgwfIU/edit#gid=0"",""'Game 12'!$B$2:$Q$31""),30,False),0)"),23.0) -> 23 | K10: =IFERROR(__xludf.DUMMYFUNCTION("IFERROR(HLOOKUP($A10,IMPORTRANGE(""https://docs.google.com/spreadsheets/d/11NFkzOdQyW-OtxSDuGslNCgNjx7HUb2FU7KnlNnPMgY/edit#gid=0"",""'Game 3'!$B$2:$Q$31""),30,False),0)"),23.0) -> 23 | L10: =IFERROR(__xludf.DUMMYFUNCTION("IFERROR(HLOOKUP($A10,IMPORTRANGE(""https://docs.google.com/spreadsheets/d/1CLg5-jaE4ta0-u4oE1qbBplQ5Mf3Oj9ONFgL0zJ7Ol4/edit#gid=0"",""'Game 11'!$B$2:$Q$31""),30,False),1)"),23.0) -> 23 | M10: =IFERROR(__xludf.DUMMYFUNCTION("IFERROR(HLOOKUP($A10,IMPORTRANGE(""https://docs.google.com/spreadsheets/d/1CeexgK4KxWj3k_7nql_k8-RPxXMwTJyB4Q3vAASeDlA/edit#gid=0"",""'Game 10'!$B$2:$Q$31""),30,False),1)"),12.0) -> 12 | N10: =IFERROR(__xludf.DUMMYFUNCTION("IFERROR(HLOOKUP($A10,IMPORTRANGE(""https://docs.google.com/spreadsheets/d/1MNwUNMjcwK6bEgCXwB73jpbK5gJAXS8ZMpbEMLJEP3E/edit#gid=0"",""'Game 10'!$B$2:$Q$31""),30,False),1)"),23.0) -> 23 | O10: =IFERROR(__xludf.DUMMYFUNCTION("IFERROR(HLOOKUP($A10,IMPORTRANGE(""https://docs.google.com/spreadsheets/d/1UrzyxmT40kDZwVrLMf1yyXfP-pyczRAw9Y8Rw-uXG3c/edit#gid=0"",""'Game 4'!$B$2:$Q$31""),30,False),1)"),0.0) -> 0 | P10: =IFERROR(__xludf.DUMMYFUNCTION("IFERROR(HLOOKUP($A10,IMPORTRANGE(""https://docs.google.com/spreadsheets/d/1iyMhSYWifw-KGFtyeBpNxVZr4BhcV9hVZuShgJ9Ia0E/edit#gid=0"",""'Game 11'!$B$2:$Q$31""),30,False),1)"),0.0) -> 0 | Q10: =IFERROR(__xludf.DUMMYFUNCTION("IFERROR(HLOOKUP($A10,IMPORTRANGE(""https://docs.google.com/spreadsheets/d/1sSbIK-vvHsSY0LghLJ9gcnW8Hec_ITI2tFmpeqI999A/edit#gid=0"",""'Game 9'!$B$2:$Q$31""),30,False),1)"),23.0) -> 23 | R10: =SUM(C10:Q10) -> 242
A11: Stephen | B11: Beltway Blazers B | C11: 11 | D11: 23 | E11: 23 | F11: 23 | G11: 23 | H11: =IFERROR(__xludf.DUMMYFUNCTION("HLOOKUP($A11,IMPORTRANGE(""https://docs.google.com/spreadsheets/d/16J5ie7OD1E99qGO9lMDm8w5Yls-v190B7DTolJ5TmFc/edit#gid=0"",""'Game 5'!$B$2:$Q$31""),30,False)"),23.0) -> 23 | I11: 23 | J11: =IFERROR(__xludf.DUMMYFUNCTION("IFERROR(HLOOKUP($A11,IMPORTRANGE(""https://docs.google.com/spreadsheets/d/1CTYfdyRk_RFGM3I2iN9bKeD9zUPzEm1ajzml6VgwfIU/edit#gid=0"",""'Game 12'!$B$2:$Q$31""),30,False),0)"),23.0) -> 23 | K11: =IFERROR(__xludf.DUMMYFUNCTION("IFERROR(HLOOKUP($A11,IMPORTRANGE(""https://docs.google.com/spreadsheets/d/11NFkzOdQyW-OtxSDuGslNCgNjx7HUb2FU7KnlNnPMgY/edit#gid=0"",""'Game 3'!$B$2:$Q$31""),30,False),0)"),11.0) -> 11 | L11: =IFERROR(__xludf.DUMMYFUNCTION("IFERROR(HLOOKUP($A11,IMPORTRANGE(""https://docs.google.com/spreadsheets/d/1CLg5-jaE4ta0-u4oE1qbBplQ5Mf3Oj9ONFgL0zJ7Ol4/edit#gid=0"",""'Game 11'!$B$2:$Q$31""),30,False),1)"),23.0) -> 23 | M11: =IFERROR(__xludf.DUMMYFUNCTION("IFERROR(HLOOKUP($A11,IMPORTRANGE(""https://docs.google.com/spreadsheets/d/1CeexgK4KxWj3k_7nql_k8-RPxXMwTJyB4Q3vAASeDlA/edit#gid=0"",""'Game 10'!$B$2:$Q$31""),30,False),1)"),23.0) -> 23 | N11: =IFERROR(__xludf.DUMMYFUNCTION("IFERROR(HLOOKUP($A11,IMPORTRANGE(""https://docs.google.com/spreadsheets/d/1MNwUNMjcwK6bEgCXwB73jpbK5gJAXS8ZMpbEMLJEP3E/edit#gid=0"",""'Game 10'!$B$2:$Q$31""),30,False),1)"),23.0) -> 23 | O11: =IFERROR(__xludf.DUMMYFUNCTION("IFERROR(HLOOKUP($A11,IMPORTRANGE(""https://docs.google.com/spreadsheets/d/1UrzyxmT40kDZwVrLMf1yyXfP-pyczRAw9Y8Rw-uXG3c/edit#gid=0"",""'Game 4'!$B$2:$Q$31""),30,False),1)"),23.0) -> 23 | P11: =IFERROR(__xludf.DUMMYFUNCTION("IFERROR(HLOOKUP($A11,IMPORTRANGE(""https://docs.google.com/spreadsheets/d/1iyMhSYWifw-KGFtyeBpNxVZr4BhcV9hVZuShgJ9Ia0E/edit#gid=0"",""'Game 11'!$B$2:$Q$31""),30,False),1)"),23.0) -> 23 | Q11: =IFERROR(__xludf.DUMMYFUNCTION("IFERROR(HLOOKUP($A11,IMPORTRANGE(""https://docs.google.com/spreadsheets/d/1sSbIK-vvHsSY0LghLJ9gcnW8Hec_ITI2tFmpeqI999A/edit#gid=0"",""'Game 9'!$B$2:$Q$31""),30,False),1)"),23.0) -> 23 | R11: =SUM(C11:Q11) -> 321
A12: Aaron | B12: BOW B | C12: 23 | D12: 23 | E12: 23 | F12: 23 | G12: 23 | H12: =IFERROR(__xludf.DUMMYFUNCTION("HLOOKUP($A12,IMPORTRANGE(""https://docs.google.com/spreadsheets/d/16J5ie7OD1E99qGO9lMDm8w5Yls-v190B7DTolJ5TmFc/edit#gid=0"",""'Game 11'!$B$2:$Q$31""),30,False)"),23.0) -> 23 | I12: 23 | J12: =IFERROR(__xludf.DUMMYFUNCTION("IFERROR(HLOOKUP($A12,IMPORTRANGE(""https://docs.google.com/spreadsheets/d/1CTYfdyRk_RFGM3I2iN9bKeD9zUPzEm1ajzml6VgwfIU/edit#gid=0"",""'Game 4'!$B$2:$Q$31""),30,False),0)"),23.0) -> 23 | K12: =IFERROR(__xludf.DUMMYFUNCTION("IFERROR(HLOOKUP($A12,IMPORTRANGE(""https://docs.google.com/spreadsheets/d/11NFkzOdQyW-OtxSDuGslNCgNjx7HUb2FU7KnlNnPMgY/edit#gid=0"",""'Game 4'!$B$2:$Q$31""),30,False),0)"),23.0) -> 23 | L12: =IFERROR(__xludf.DUMMYFUNCTION("IFERROR(HLOOKUP($A12,IMPORTRANGE(""https://docs.google.com/spreadsheets/d/1CLg5-jaE4ta0-u4oE1qbBplQ5Mf3Oj9ONFgL0zJ7Ol4/edit#gid=0"",""'Game 4'!$B$2:$Q$31""),30,False),1)"),23.0) -> 23 | M12: =IFERROR(__xludf.DUMMYFUNCTION("IFERROR(HLOOKUP($A12,IMPORTRANGE(""https://docs.google.com/spreadsheets/d/1CeexgK4KxWj3k_7nql_k8-RPxXMwTJyB4Q3vAASeDlA/edit#gid=0"",""'Game 4'!$B$2:$Q$31""),30,False),1)"),23.0) -> 23 | N12: =IFERROR(__xludf.DUMMYFUNCTION("IFERROR(HLOOKUP($A12,IMPORTRANGE(""https://docs.google.com/spreadsheets/d/1MNwUNMjcwK6bEgCXwB73jpbK5gJAXS8ZMpbEMLJEP3E/edit#gid=0"",""'Game 4'!$B$2:$Q$31""),30,False),1)"),23.0) -> 23 | O12: =IFERROR(__xludf.DUMMYFUNCTION("IFERROR(HLOOKUP($A12,IMPORTRANGE(""https://docs.google.com/spreadsheets/d/1UrzyxmT40kDZwVrLMf1yyXfP-pyczRAw9Y8Rw-uXG3c/edit#gid=0"",""'Game 4'!$B$2:$Q$31""),30,False),1)"),23.0) -> 23 | P12: =IFERROR(__xludf.DUMMYFUNCTION("IFERROR(HLOOKUP($A12,IMPORTRANGE(""https://docs.google.com/spreadsheets/d/1iyMhSYWifw-KGFtyeBpNxVZr4BhcV9hVZuShgJ9Ia0E/edit#gid=0"",""'Game 4'!$B$2:$Q$31""),30,False),1)"),23.0) -> 23 | Q12: =IFERROR(__xludf.DUMMYFUNCTION("IFERROR(HLOOKUP($A12,IMPORTRANGE(""https://docs.google.com/spreadsheets/d/1sSbIK-vvHsSY0LghLJ9gcnW8Hec_ITI2tFmpeqI999A/edit#gid=0"",""'Game 3'!$B$2:$Q$31""),30,False),1)"),23.0) -> 23 | R12: =SUM(C12:Q12) -> 345
A13: Jonathan F | B13: BOW B | C13: 0 | D13: 23 | E13: 0 | F13: 0 | G13: 23 | H13: =IFERROR(__xludf.DUMMYFUNCTION("HLOOKUP($A13,IMPORTRANGE(""https://docs.google.com/spreadsheets/d/16J5ie7OD1E99qGO9lMDm8w5Yls-v190B7DTolJ5TmFc/edit#gid=0"",""'Game 11'!$B$2:$Q$31""),30,False)"),0.0) -> 0 | I13: 23 | J13: =IFERROR(__xludf.DUMMYFUNCTION("IFERROR(HLOOKUP($A13,IMPORTRANGE(""https://docs.google.com/spreadsheets/d/1CTYfdyRk_RFGM3I2iN9bKeD9zUPzEm1ajzml6VgwfIU/edit#gid=0"",""'Game 4'!$B$2:$Q$31""),30,False),0)"),0.0) -> 0 | K13: =IFERROR(__xludf.DUMMYFUNCTION("IFERROR(HLOOKUP($A13,IMPORTRANGE(""https://docs.google.com/spreadsheets/d/11NFkzOdQyW-OtxSDuGslNCgNjx7HUb2FU7KnlNnPMgY/edit#gid=0"",""'Game 4'!$B$2:$Q$31""),30,False),0)"),0.0) -> 0 | L13: =IFERROR(__xludf.DUMMYFUNCTION("IFERROR(HLOOKUP($A13,IMPORTRANGE(""https://docs.google.com/spreadsheets/d/1CLg5-jaE4ta0-u4oE1qbBplQ5Mf3Oj9ONFgL0zJ7Ol4/edit#gid=0"",""'Game 4'!$B$2:$Q$31""),30,False),1)"),0.0) -> 0 | M13: =IFERROR(__xludf.DUMMYFUNCTION("IFERROR(HLOOKUP($A13,IMPORTRANGE(""https://docs.google.com/spreadsheets/d/1CeexgK4KxWj3k_7nql_k8-RPxXMwTJyB4Q3vAASeDlA/edit#gid=0"",""'Game 4'!$B$2:$Q$31""),30,False),1)"),0.0) -> 0 | N13: =IFERROR(__xludf.DUMMYFUNCTION("IFERROR(HLOOKUP($A13,IMPORTRANGE(""https://docs.google.com/spreadsheets/d/1MNwUNMjcwK6bEgCXwB73jpbK5gJAXS8ZMpbEMLJEP3E/edit#gid=0"",""'Game 4'!$B$2:$Q$31""),30,False),1)"),0.0) -> 0 | O13: =IFERROR(__xludf.DUMMYFUNCTION("IFERROR(HLOOKUP($A13,IMPORTRANGE(""https://docs.google.com/spreadsheets/d/1UrzyxmT40kDZwVrLMf1yyXfP-pyczRAw9Y8Rw-uXG3c/edit#gid=0"",""'Game 4'!$B$2:$Q$31""),30,False),1)"),0.0) -> 0 | P13: =IFERROR(__xludf.DUMMYFUNCTION("IFERROR(HLOOKUP($A13,IMPORTRANGE(""https://docs.google.com/spreadsheets/d/1iyMhSYWifw-KGFtyeBpNxVZr4BhcV9hVZuShgJ9Ia0E/edit#gid=0"",""'Game 4'!$B$2:$Q$31""),30,False),1)"),0.0) -> 0 | Q13: =IFERROR(__xludf.DUMMYFUNCTION("IFERROR(HLOOKUP($A13,IMPORTRANGE(""https://docs.google.com/spreadsheets/d/1sSbIK-vvHsSY0LghLJ9gcnW8Hec_ITI2tFmpeqI999A/edit#gid=0"",""'Game 3'!$B$2:$Q$31""),30,False),1)"),0.0) -> 0 | R13: =SUM(C13:Q13) -> 69
A14: Margaret L | B14: BOW B | C14: 23 | D14: 23 | E14: 0 | F14: 23 | G14: 0 | H14: =IFERROR(__xludf.DUMMYFUNCTION("HLOOKUP($A14,IMPORTRANGE(""https://docs.google.com/spreadsheets/d/16J5ie7OD1E99qGO9lMDm8w5Yls-v190B7DTolJ5TmFc/edit#gid=0"",""'Game 11'!$B$2:$Q$31""),30,False)"),23.0) -> 23 | I14: 0 | J14: =IFERROR(__xludf.DUMMYFUNCTION("IFERROR(HLOOKUP($A14,IMPORTRANGE(""https://docs.google.com/spreadsheets/d/1CTYfdyRk_RFGM3I2iN9bKeD9zUPzEm1ajzml6VgwfIU/edit#gid=0"",""'Game 4'!$B$2:$Q$31""),30,False),0)"),0.0) -> 0 | K14: =IFERROR(__xludf.DUMMYFUNCTION("IFERROR(HLOOKUP($A14,IMPORTRANGE(""https://docs.google.com/spreadsheets/d/11NFkzOdQyW-OtxSDuGslNCgNjx7HUb2FU7KnlNnPMgY/edit#gid=0"",""'Game 4'!$B$2:$Q$31""),30,False),0)"),23.0) -> 23 | L14: =IFERROR(__xludf.DUMMYFUNCTION("IFERROR(HLOOKUP($A14,IMPORTRANGE(""https://docs.google.com/spreadsheets/d/1CLg5-jaE4ta0-u4oE1qbBplQ5Mf3Oj9ONFgL0zJ7Ol4/edit#gid=0"",""'Game 4'!$B$2:$Q$31""),30,False),1)"),0.0) -> 0 | M14: =IFERROR(__xludf.DUMMYFUNCTION("IFERROR(HLOOKUP($A14,IMPORTRANGE(""https://docs.google.com/spreadsheets/d/1CeexgK4KxWj3k_7nql_k8-RPxXMwTJyB4Q3vAASeDlA/edit#gid=0"",""'Game 4'!$B$2:$Q$31""),30,False),1)"),0.0) -> 0 | N14: =IFERROR(__xludf.DUMMYFUNCTION("IFERROR(HLOOKUP($A14,IMPORTRANGE(""https://docs.google.com/spreadsheets/d/1MNwUNMjcwK6bEgCXwB73jpbK5gJAXS8ZMpbEMLJEP3E/edit#gid=0"",""'Game 4'!$B$2:$Q$31""),30,False),1)"),0.0) -> 0 | O14: =IFERROR(__xludf.DUMMYFUNCTION("IFERROR(HLOOKUP($A14,IMPORTRANGE(""https://docs.google.com/spreadsheets/d/1UrzyxmT40kDZwVrLMf1yyXfP-pyczRAw9Y8Rw-uXG3c/edit#gid=0"",""'Game 4'!$B$2:$Q$31""),30,False),1)"),23.0) -> 23 | P14: =IFERROR(__xludf.DUMMYFUNCTION("IFERROR(HLOOKUP($A14,IMPORTRANGE(""https://docs.google.com/spreadsheets/d/1iyMhSYWifw-KGFtyeBpNxVZr4BhcV9hVZuShgJ9Ia0E/edit#gid=0"",""'Game 4'!$B$2:$Q$31""),30,False),1)"),0.0) -> 0 | Q14: =IFERROR(__xludf.DUMMYFUNCTION("IFERROR(HLOOKUP($A14,IMPORTRANGE(""https://docs.google.com/spreadsheets/d/1sSbIK-vvHsSY0LghLJ9gcnW8Hec_ITI2tFmpeqI999A/edit#gid=0"",""'Game 3'!$B$2:$Q$31""),30,False),1)"),0.0) -> 0 | R14: =SUM(C14:Q14) -> 138
A15: Piyush | B15: BOW B | C15: 23 | D15: 23 | E15: 23 | F15: 0 | G15: 23 | H15: =IFERROR(__xludf.DUMMYFUNCTION("HLOOKUP($A15,IMPORTRANGE(""https://docs.google.com/spreadsheets/d/16J5ie7OD1E99qGO9lMDm8w5Yls-v190B7DTolJ5TmFc/edit#gid=0"",""'Game 11'!$B$2:$Q$31""),30,False)"),0.0) -> 0 | I15: 23 | J15: =IFERROR(__xludf.DUMMYFUNCTION("IFERROR(HLOOKUP($A15,IMPORTRANGE(""https://docs.google.com/spreadsheets/d/1CTYfdyRk_RFGM3I2iN9bKeD9zUPzEm1ajzml6VgwfIU/edit#gid=0"",""'Game 4'!$B$2:$Q$31""),30,False),0)"),23.0) -> 23 | K15: =IFERROR(__xludf.DUMMYFUNCTION("IFERROR(HLOOKUP($A15,IMPORTRANGE(""https://docs.google.com/spreadsheets/d/11NFkzOdQyW-OtxSDuGslNCgNjx7HUb2FU7KnlNnPMgY/edit#gid=0"",""'Game 4'!$B$2:$Q$31""),30,False),0)"),0.0) -> 0 | L15: =IFERROR(__xludf.DUMMYFUNCTION("IFERROR(HLOOKUP($A15,IMPORTRANGE(""https://docs.google.com/spreadsheets/d/1CLg5-jaE4ta0-u4oE1qbBplQ5Mf3Oj9ONFgL0zJ7Ol4/edit#gid=0"",""'Game 4'!$B$2:$Q$31""),30,False),1)"),0.0) -> 0 | M15: =IFERROR(__xludf.DUMMYFUNCTION("IFERROR(HLOOKUP($A15,IMPORTRANGE(""https://docs.google.com/spreadsheets/d/1CeexgK4KxWj3k_7nql_k8-RPxXMwTJyB4Q3vAASeDlA/edit#gid=0"",""'Game 4'!$B$2:$Q$31""),30,False),1)"),0.0) -> 0 | N15: =IFERROR(__xludf.DUMMYFUNCTION("IFERROR(HLOOKUP($A15,IMPORTRANGE(""https://docs.google.com/spreadsheets/d/1MNwUNMjcwK6bEgCXwB73jpbK5gJAXS8ZMpbEMLJEP3E/edit#gid=0"",""'Game 4'!$B$2:$Q$31""),30,False),1)"),23.0) -> 23 | O15: =IFERROR(__xludf.DUMMYFUNCTION("IFERROR(HLOOKUP($A15,IMPORTRANGE(""https://docs.google.com/spreadsheets/d/1UrzyxmT40kDZwVrLMf1yyXfP-pyczRAw9Y8Rw-uXG3c/edit#gid=0"",""'Game 4'!$B$2:$Q$31""),30,False),1)"),0.0) -> 0 | P15: =IFERROR(__xludf.DUMMYFUNCTION("IFERROR(HLOOKUP($A15,IMPORTRANGE(""https://docs.google.com/spreadsheets/d/1iyMhSYWifw-KGFtyeBpNxVZr4BhcV9hVZuShgJ9Ia0E/edit#gid=0"",""'Game 4'!$B$2:$Q$31""),30,False),1)"),0.0) -> 0 | Q15: =IFERROR(__xludf.DUMMYFUNCTION("IFERROR(HLOOKUP($A15,IMPORTRANGE(""https://docs.google.com/spreadsheets/d/1sSbIK-vvHsSY0LghLJ9gcnW8Hec_ITI2tFmpeqI999A/edit#gid=0"",""'Game 3'!$B$2:$Q$31""),30,False),1)"),23.0) -> 23 | R15: =SUM(C15:Q15) -> 184
A16: Wardell | B16: BOW B | C16: 23 | D16: 0 | E16: 0 | F16: 0 | G16: 23 | H16: =IFERROR(__xludf.DUMMYFUNCTION("HLOOKUP($A16,IMPORTRANGE(""https://docs.google.com/spreadsheets/d/16J5ie7OD1E99qGO9lMDm8w5Yls-v190B7DTolJ5TmFc/edit#gid=0"",""'Game 11'!$B$2:$Q$31""),30,False)"),0.0) -> 0 | I16: 0 | J16: =IFERROR(__xludf.DUMMYFUNCTION("IFERROR(HLOOKUP($A16,IMPORTRANGE(""https://docs.google.com/spreadsheets/d/1CTYfdyRk_RFGM3I2iN9bKeD9zUPzEm1ajzml6VgwfIU/edit#gid=0"",""'Game 4'!$B$2:$Q$31""),30,False),0)"),0.0) -> 0 | K16: =IFERROR(__xludf.DUMMYFUNCTION("IFERROR(HLOOKUP($A16,IMPORTRANGE(""https://docs.google.com/spreadsheets/d/11NFkzOdQyW-OtxSDuGslNCgNjx7HUb2FU7KnlNnPMgY/edit#gid=0"",""'Game 4'!$B$2:$Q$31""),30,False),0)"),23.0) -> 23 | L16: =IFERROR(__xludf.DUMMYFUNCTION("IFERROR(HLOOKUP($A16,IMPORTRANGE(""https://docs.google.com/spreadsheets/d/1CLg5-jaE4ta0-u4oE1qbBplQ5Mf3Oj9ONFgL0zJ7Ol4/edit#gid=0"",""'Game 4'!$B$2:$Q$31""),30,False),1)"),0.0) -> 0 | M16: =IFERROR(__xludf.DUMMYFUNCTION("IFERROR(HLOOKUP($A16,IMPORTRANGE(""https://docs.google.com/spreadsheets/d/1CeexgK4KxWj3k_7nql_k8-RPxXMwTJyB4Q3vAASeDlA/edit#gid=0"",""'Game 4'!$B$2:$Q$31""),30,False),1)"),23.0) -> 23 | N16: =IFERROR(__xludf.DUMMYFUNCTION("IFERROR(HLOOKUP($A16,IMPORTRANGE(""https://docs.google.com/spreadsheets/d/1MNwUNMjcwK6bEgCXwB73jpbK5gJAXS8ZMpbEMLJEP3E/edit#gid=0"",""'Game 4'!$B$2:$Q$31""),30,False),1)"),0.0) -> 0 | O16: =IFERROR(__xludf.DUMMYFUNCTION("IFERROR(HLOOKUP($A16,IMPORTRANGE(""https://docs.google.com/spreadsheets/d/1UrzyxmT40kDZwVrLMf1yyXfP-pyczRAw9Y8Rw-uXG3c/edit#gid=0"",""'Game 4'!$B$2:$Q$31""),30,False),1)"),0.0) -> 0 | P16: =IFERROR(__xludf.DUMMYFUNCTION("IFERROR(HLOOKUP($A16,IMPORTRANGE(""https://docs.google.com/spreadsheets/d/1iyMhSYWifw-KGFtyeBpNxVZr4BhcV9hVZuShgJ9Ia0E/edit#gid=0"",""'Game 4'!$B$2:$Q$31""),30,False),1)"),23.0) -> 23 | Q16: =IFERROR(__xludf.DUMMYFUNCTION("IFERROR(HLOOKUP($A16,IMPORTRANGE(""https://docs.google.com/spreadsheets/d/1sSbIK-vvHsSY0LghLJ9gcnW8Hec_ITI2tFmpeqI999A/edit#gid=0"",""'Game 3'!$B$2:$Q$31""),30,False),1)"),0.0) -> 0 | R16: =SUM(C16:Q16) -> 115
A17: Adarsh | B17: CCA B | C17: 23 | D17: 23 | E17: 23 | F17: 23 | G17: 23 | H17: =IFERROR(__xludf.DUMMYFUNCTION("HLOOKUP($A17,IMPORTRANGE(""https://docs.google.com/spreadsheets/d/16J5ie7OD1E99qGO9lMDm8w5Yls-v190B7DTolJ5TmFc/edit#gid=0"",""'Game 5'!$B$2:$Q$31""),30,False)"),23.0) -> 23 | I17: 23 | J17: =IFERROR(__xludf.DUMMYFUNCTION("IFERROR(HLOOKUP($A17,IMPORTRANGE(""https://docs.google.com/spreadsheets/d/1CTYfdyRk_RFGM3I2iN9bKeD9zUPzEm1ajzml6VgwfIU/edit#gid=0"",""'Game 7'!$B$2:$Q$31""),30,False),0)"),23.0) -> 23 | K17: =IFERROR(__xludf.DUMMYFUNCTION("IFERROR(HLOOKUP($A17,IMPORTRANGE(""https://docs.google.com/spreadsheets/d/11NFkzOdQyW-OtxSDuGslNCgNjx7HUb2FU7KnlNnPMgY/edit#gid=0"",""'Game 11'!$B$2:$Q$31""),30,False),0)"),23.0) -> 23 | L17: =IFERROR(__xludf.DUMMYFUNCTION("IFERROR(HLOOKUP($A17,IMPORTRANGE(""https://docs.google.com/spreadsheets/d/1CLg5-jaE4ta0-u4oE1qbBplQ5Mf3Oj9ONFgL0zJ7Ol4/edit#gid=0"",""'Game 1'!$B$2:$Q$31""),30,False),1)"),23.0) -> 23 | M17: =IFERROR(__xludf.DUMMYFUNCTION("IFERROR(HLOOKUP($A17,IMPORTRANGE(""https://docs.google.com/spreadsheets/d/1CeexgK4KxWj3k_7nql_k8-RPxXMwTJyB4Q3vAASeDlA/edit#gid=0"",""'Game 12'!$B$2:$Q$31""),30,False),1)"),23.0) -> 23 | N17: =IFERROR(__xludf.DUMMYFUNCTION("IFERROR(HLOOKUP($A17,IMPORTRANGE(""https://docs.google.com/spreadsheets/d/1MNwUNMjcwK6bEgCXwB73jpbK5gJAXS8ZMpbEMLJEP3E/edit#gid=0"",""'Game 11'!$B$2:$Q$31""),30,False),1)"),23.0) -> 23 | O17: =IFERROR(__xludf.DUMMYFUNCTION("IFERROR(HLOOKUP($A17,IMPORTRANGE(""https://docs.google.com/spreadsheets/d/1UrzyxmT40kDZwVrLMf1yyXfP-pyczRAw9Y8Rw-uXG3c/edit#gid=0"",""'Game 8'!$B$2:$Q$31""),30,False),1)"),23.0) -> 23 | P17: =IFERROR(__xludf.DUMMYFUNCTION("IFERROR(HLOOKUP($A17,IMPORTRANGE(""https://docs.google.com/spreadsheets/d/1iyMhSYWifw-KGFtyeBpNxVZr4BhcV9hVZuShgJ9Ia0E/edit#gid=0"",""'Game 5'!$B$2:$Q$31""),30,False),1)"),23.0) -> 23 | Q17: =IFERROR(__xludf.DUMMYFUNCTION("IFERROR(HLOOKUP($A17,IMPORTRANGE(""https://docs.google.com/spreadsheets/d/1sSbIK-vvHsSY0LghLJ9gcnW8Hec_ITI2tFmpeqI999A/edit#gid=0"",""'Game 11'!$B$2:$Q$31""),30,False),1)"),23.0) -> 23 | R17: =SUM(C17:Q17) -> 345
A18: Andrew S | B18: CCA B | C18: 23 | D18: 23 | E18: 23 | F18: 23 | G18: 23 | H18: =IFERROR(__xludf.DUMMYFUNCTION("HLOOKUP($A18,IMPORTRANGE(""https://docs.google.com/spreadsheets/d/16J5ie7OD1E99qGO9lMDm8w5Yls-v190B7DTolJ5TmFc/edit#gid=0"",""'Game 5'!$B$2:$Q$31""),30,False)"),23.0) -> 23 | I18: 23 | J18: =IFERROR(__xludf.DUMMYFUNCTION("IFERROR(HLOOKUP($A18,IMPORTRANGE(""https://docs.google.com/spreadsheets/d/1CTYfdyRk_RFGM3I2iN9bKeD9zUPzEm1ajzml6VgwfIU/edit#gid=0"",""'Game 7'!$B$2:$Q$31""),30,False),0)"),23.0) -> 23 | K18: =IFERROR(__xludf.DUMMYFUNCTION("IFERROR(HLOOKUP($A18,IMPORTRANGE(""https://docs.google.com/spreadsheets/d/11NFkzOdQyW-OtxSDuGslNCgNjx7HUb2FU7KnlNnPMgY/edit#gid=0"",""'Game 11'!$B$2:$Q$31""),30,False),0)"),23.0) -> 23 | L18: =IFERROR(__xludf.DUMMYFUNCTION("IFERROR(HLOOKUP($A18,IMPORTRANGE(""https://docs.google.com/spreadsheets/d/1CLg5-jaE4ta0-u4oE1qbBplQ5Mf3Oj9ONFgL0zJ7Ol4/edit#gid=0"",""'Game 1'!$B$2:$Q$31""),30,False),1)"),23.0) -> 23 | M18: =IFERROR(__xludf.DUMMYFUNCTION("IFERROR(HLOOKUP($A18,IMPORTRANGE(""https://docs.google.com/spreadsheets/d/1CeexgK4KxWj3k_7nql_k8-RPxXMwTJyB4Q3vAASeDlA/edit#gid=0"",""'Game 12'!$B$2:$Q$31""),30,False),1)"),23.0) -> 23 | N18: =IFERROR(__xludf.DUMMYFUNCTION("IFERROR(HLOOKUP($A18,IMPORTRANGE(""https://docs.google.com/spreadsheets/d/1MNwUNMjcwK6bEgCXwB73jpbK5gJAXS8ZMpbEMLJEP3E/edit#gid=0"",""'Game 11'!$B$2:$Q$31""),30,False),1)"),23.0) -> 23 | O18: =IFERROR(__xludf.DUMMYFUNCTION("IFERROR(HLOOKUP($A18,IMPORTRANGE(""https://docs.google.com/spreadsheets/d/1UrzyxmT40kDZwVrLMf1yyXfP-pyczRAw9Y8Rw-uXG3c/edit#gid=0"",""'Game 8'!$B$2:$Q$31""),30,False),1)"),23.0) -> 23 | P18: =IFERROR(__xludf.DUMMYFUNCTION("IFERROR(HLOOKUP($A18,IMPORTRANGE(""https://docs.google.com/spreadsheets/d/1iyMhSYWifw-KGFtyeBpNxVZr4BhcV9hVZuShgJ9Ia0E/edit#gid=0"",""'Game 5'!$B$2:$Q$31""),30,False),1)"),23.0) -> 23 | Q18: =IFERROR(__xludf.DUMMYFUNCTION("IFERROR(HLOOKUP($A18,IMPORTRANGE(""https://docs.google.com/spreadsheets/d/1sSbIK-vvHsSY0LghLJ9gcnW8Hec_ITI2tFmpeqI999A/edit#gid=0"",""'Game 11'!$B$2:$Q$31""),30,False),1)"),23.0) -> 23 | R18: =SUM(C18:Q18) -> 345
A19: Arnav V | B19: CCA B | C19: 23 | D19: 23 | E19: 23 | F19: 23 | G19: 23 | H19: =IFERROR(__xludf.DUMMYFUNCTION("HLOOKUP($A19,IMPORTRANGE(""https://docs.google.com/spreadsheets/d/16J5ie7OD1E99qGO9lMDm8w5Yls-v190B7DTolJ5TmFc/edit#gid=0"",""'Game 5'!$B$2:$Q$31""),30,False)"),23.0) -> 23 | I19: 23 | J19: =IFERROR(__xludf.DUMMYFUNCTION("IFERROR(HLOOKUP($A19,IMPORTRANGE(""https://docs.google.com/spreadsheets/d/1CTYfdyRk_RFGM3I2iN9bKeD9zUPzEm1ajzml6VgwfIU/edit#gid=0"",""'Game 7'!$B$2:$Q$31""),30,False),0)"),23.0) -> 23 | K19: =IFERROR(__xludf.DUMMYFUNCTION("IFERROR(HLOOKUP($A19,IMPORTRANGE(""https://docs.google.com/spreadsheets/d/11NFkzOdQyW-OtxSDuGslNCgNjx7HUb2FU7KnlNnPMgY/edit#gid=0"",""'Game 11'!$B$2:$Q$31""),30,False),0)"),23.0) -> 23 | L19: =IFERROR(__xludf.DUMMYFUNCTION("IFERROR(HLOOKUP($A19,IMPORTRANGE(""https://docs.google.com/spreadsheets/d/1CLg5-jaE4ta0-u4oE1qbBplQ5Mf3Oj9ONFgL0zJ7Ol4/edit#gid=0"",""'Game 1'!$B$2:$Q$31""),30,False),1)"),23.0) -> 23 | M19: =IFERROR(__xludf.DUMMYFUNCTION("IFERROR(HLOOKUP($A19,IMPORTRANGE(""https://docs.google.com/spreadsheets/d/1CeexgK4KxWj3k_7nql_k8-RPxXMwTJyB4Q3vAASeDlA/edit#gid=0"",""'Game 12'!$B$2:$Q$31""),30,False),1)"),23.0) -> 23 | N19: =IFERROR(__xludf.DUMMYFUNCTION("IFERROR(HLOOKUP($A19,IMPORTRANGE(""https://docs.google.com/spreadsheets/d/1MNwUNMjcwK6bEgCXwB73jpbK5gJAXS8ZMpbEMLJEP3E/edit#gid=0"",""'Game 11'!$B$2:$Q$31""),30,False),1)"),23.0) -> 23 | O19: =IFERROR(__xludf.DUMMYFUNCTION("IFERROR(HLOOKUP($A19,IMPORTRANGE(""https://docs.google.com/spreadsheets/d/1UrzyxmT40kDZwVrLMf1yyXfP-pyczRAw9Y8Rw-uXG3c/edit#gid=0"",""'Game 8'!$B$2:$Q$31""),30,False),1)"),23.0) -> 23 | P19: =IFERROR(__xludf.DUMMYFUNCTION("IFERROR(HLOOKUP($A19,IMPORTRANGE(""https://docs.google.com/spreadsheets/d/1iyMhSYWifw-KGFtyeBpNxVZr4BhcV9hVZuShgJ9Ia0E/edit#gid=0"",""'Game 5'!$B$2:$Q$31""),30,False),1)"),23.0) -> 23 | Q19: =IFERROR(__xludf.DUMMYFUNCTION("IFERROR(HLOOKUP($A19,IMPORTRANGE(""https://docs.google.com/spreadsheets/d/1sSbIK-vvHsSY0LghLJ9gcnW8Hec_ITI2tFmpeqI999A/edit#gid=0"",""'Game 11'!$B$2:$Q$31""),30,False),1)"),23.0) -> 23 | R19: =SUM(C19:Q19) -> 345
A20: Chris J | B20: CCA B | C20: 23 | D20: 23 | E20: 23 | F20: 23 | G20: 23 | H20: =IFERROR(__xludf.DUMMYFUNCTION("HLOOKUP($A20,IMPORTRANGE(""https://docs.google.com/spreadsheets/d/16J5ie7OD1E99qGO9lMDm8w5Yls-v190B7DTolJ5TmFc/edit#gid=0"",""'Game 5'!$B$2:$Q$31""),30,False)"),23.0) -> 23 | I20: 23 | J20: =IFERROR(__xludf.DUMMYFUNCTION("IFERROR(HLOOKUP($A20,IMPORTRANGE(""https://docs.google.com/spreadsheets/d/1CTYfdyRk_RFGM3I2iN9bKeD9zUPzEm1ajzml6VgwfIU/edit#gid=0"",""'Game 7'!$B$2:$Q$31""),30,False),0)"),23.0) -> 23 | K20: =IFERROR(__xludf.DUMMYFUNCTION("IFERROR(HLOOKUP($A20,IMPORTRANGE(""https://docs.google.com/spreadsheets/d/11NFkzOdQyW-OtxSDuGslNCgNjx7HUb2FU7KnlNnPMgY/edit#gid=0"",""'Game 11'!$B$2:$Q$31""),30,False),0)"),23.0) -> 23 | L20: =IFERROR(__xludf.DUMMYFUNCTION("IFERROR(HLOOKUP($A20,IMPORTRANGE(""https://docs.google.com/spreadsheets/d/1CLg5-jaE4ta0-u4oE1qbBplQ5Mf3Oj9ONFgL0zJ7Ol4/edit#gid=0"",""'Game 1'!$B$2:$Q$31""),30,False),1)"),23.0) -> 23 | M20: =IFERROR(__xludf.DUMMYFUNCTION("IFERROR(HLOOKUP($A20,IMPORTRANGE(""https://docs.google.com/spreadsheets/d/1CeexgK4KxWj3k_7nql_k8-RPxXMwTJyB4Q3vAASeDlA/edit#gid=0"",""'Game 12'!$B$2:$Q$31""),30,False),1)"),23.0) -> 23 | N20: =IFERROR(__xludf.DUMMYFUNCTION("IFERROR(HLOOKUP($A20,IMPORTRANGE(""https://docs.google.com/spreadsheets/d/1MNwUNMjcwK6bEgCXwB73jpbK5gJAXS8ZMpbEMLJEP3E/edit#gid=0"",""'Game 11'!$B$2:$Q$31""),30,False),1)"),23.0) -> 23 | O20: =IFERROR(__xludf.DUMMYFUNCTION("IFERROR(HLOOKUP($A20,IMPORTRANGE(""https://docs.google.com/spreadsheets/d/1UrzyxmT40kDZwVrLMf1yyXfP-pyczRAw9Y8Rw-uXG3c/edit#gid=0"",""'Game 8'!$B$2:$Q$31""),30,False),1)"),0.0) -> 0 | P20: =IFERROR(__xludf.DUMMYFUNCTION("IFERROR(HLOOKUP($A20,IMPORTRANGE(""https://docs.google.com/spreadsheets/d/1iyMhSYWifw-KGFtyeBpNxVZr4BhcV9hVZuShgJ9Ia0E/edit#gid=0"",""'Game 5'!$B$2:$Q$31""),30,False),1)"),23.0) -> 23 | Q20: =IFERROR(__xludf.DUMMYFUNCTION("IFERROR(HLOOKUP($A20,IMPORTRANGE(""https://docs.google.com/spreadsheets/d/1sSbIK-vvHsSY0LghLJ9gcnW8Hec_ITI2tFmpeqI999A/edit#gid=0"",""'Game 11'!$B$2:$Q$31""),30,False),1)"),23.0) -> 23 | R20: =SUM(C20:Q20) -> 322
A21: Anurag | B21: Centennial | C21: 23 | D21: 23 | E21: 23 | F21: 23 | G21: 23 | H21: =IFERROR(__xludf.DUMMYFUNCTION("HLOOKUP($A21,IMPORTRANGE(""https://docs.google.com/spreadsheets/d/16J5ie7OD1E99qGO9lMDm8w5Yls-v190B7DTolJ5TmFc/edit#gid=0"",""'Game 7'!$B$2:$Q$31""),30,False)"),23.0) -> 23 | I21: 23 | J21: =IFERROR(__xludf.DUMMYFUNCTION("IFERROR(HLOOKUP($A21,IMPORTRANGE(""https://docs.google.com/spreadsheets/d/1CTYfdyRk_RFGM3I2iN9bKeD9zUPzEm1ajzml6VgwfIU/edit#gid=0"",""'Game 9'!$B$2:$Q$31""),30,False),0)"),23.0) -> 23 | K21: =IFERROR(__xludf.DUMMYFUNCTION("IFERROR(HLOOKUP($A21,IMPORTRANGE(""https://docs.google.com/spreadsheets/d/11NFkzOdQyW-OtxSDuGslNCgNjx7HUb2FU7KnlNnPMgY/edit#gid=0"",""'Game 9'!$B$2:$Q$31""),30,False),0)"),23.0) -> 23 | L21: =IFERROR(__xludf.DUMMYFUNCTION("IFERROR(HLOOKUP($A21,IMPORTRANGE(""https://docs.google.com/spreadsheets/d/1CLg5-jaE4ta0-u4oE1qbBplQ5Mf3Oj9ONFgL0zJ7Ol4/edit#gid=0"",""'Game 6'!$B$2:$Q$31""),30,False),1)"),23.0) -> 23 | M21: =IFERROR(__xludf.DUMMYFUNCTION("IFERROR(HLOOKUP($A21,IMPORTRANGE(""https://docs.google.com/spreadsheets/d/1CeexgK4KxWj3k_7nql_k8-RPxXMwTJyB4Q3vAASeDlA/edit#gid=0"",""'Game 4'!$B$2:$Q$31""),30,False),1)"),23.0) -> 23 | N21: =IFERROR(__xludf.DUMMYFUNCTION("IFERROR(HLOOKUP($A21,IMPORTRANGE(""https://docs.google.com/spreadsheets/d/1MNwUNMjcwK6bEgCXwB73jpbK5gJAXS8ZMpbEMLJEP3E/edit#gid=0"",""'Game 3'!$B$2:$Q$31""),30,False),1)"),23.0) -> 23 | O21: =IFERROR(__xludf.DUMMYFUNCTION("IFERROR(HLOOKUP($A21,IMPORTRANGE(""https://docs.google.com/spreadsheets/d/1UrzyxmT40kDZwVrLMf1yyXfP-pyczRAw9Y8Rw-uXG3c/edit#gid=0"",""'Game 9'!$B$2:$Q$31""),30,False),1)"),23.0) -> 23 | P21: =IFERROR(__xludf.DUMMYFUNCTION("IFERROR(HLOOKUP($A21,IMPORTRANGE(""https://docs.google.com/spreadsheets/d/1iyMhSYWifw-KGFtyeBpNxVZr4BhcV9hVZuShgJ9Ia0E/edit#gid=0"",""'Game 9'!$B$2:$Q$31""),30,False),1)"),23.0) -> 23 | Q21: =IFERROR(__xludf.DUMMYFUNCTION("IFERROR(HLOOKUP($A21,IMPORTRANGE(""https://docs.google.com/spreadsheets/d/1sSbIK-vvHsSY0LghLJ9gcnW8Hec_ITI2tFmpeqI999A/edit#gid=0"",""'Game 4'!$B$2:$Q$31""),30,False),1)"),23.0) -> 23 | R21: =SUM(C21:Q21) -> 345
A22: Brandon | B22: Centennial | C22: 0 | D22: 23 | E22: 0 | F22: 23 | G22: 0 | H22: =IFERROR(__xludf.DUMMYFUNCTION("HLOOKUP($A22,IMPORTRANGE(""https://docs.google.com/spreadsheets/d/16J5ie7OD1E99qGO9lMDm8w5Yls-v190B7DTolJ5TmFc/edit#gid=0"",""'Game 7'!$B$2:$Q$31""),30,False)"),23.0) -> 23 | I22: 23 | J22: =IFERROR(__xludf.DUMMYFUNCTION("IFERROR(HLOOKUP($A22,IMPORTRANGE(""https://docs.google.com/spreadsheets/d/1CTYfdyRk_RFGM3I2iN9bKeD9zUPzEm1ajzml6VgwfIU/edit#gid=0"",""'Game 9'!$B$2:$Q$31""),30,False),0)"),0.0) -> 0 | K22: =IFERROR(__xludf.DUMMYFUNCTION("IFERROR(HLOOKUP($A22,IMPORTRANGE(""https://docs.google.com/spreadsheets/d/11NFkzOdQyW-OtxSDuGslNCgNjx7HUb2FU7KnlNnPMgY/edit#gid=0"",""'Game 9'!$B$2:$Q$31""),30,False),0)"),0.0) -> 0 | L22: =IFERROR(__xludf.DUMMYFUNCTION("IFERROR(HLOOKUP($A22,IMPORTRANGE(""https://docs.google.com/spreadsheets/d/1CLg5-jaE4ta0-u4oE1qbBplQ5Mf3Oj9ONFgL0zJ7Ol4/edit#gid=0"",""'Game 6'!$B$2:$Q$31""),30,False),1)"),23.0) -> 23 | M22: =IFERROR(__xludf.DUMMYFUNCTION("IFERROR(HLOOKUP($A22,IMPORTRANGE(""https://docs.google.com/spreadsheets/d/1CeexgK4KxWj3k_7nql_k8-RPxXMwTJyB4Q3vAASeDlA/edit#gid=0"",""'Game 4'!$B$2:$Q$31""),30,False),1)"),23.0) -> 23 | N22: =IFERROR(__xludf.DUMMYFUNCTION("IFERROR(HLOOKUP($A22,IMPORTRANGE(""https://docs.google.com/spreadsheets/d/1MNwUNMjcwK6bEgCXwB73jpbK5gJAXS8ZMpbEMLJEP3E/edit#gid=0"",""'Game 3'!$B$2:$Q$31""),30,False),1)"),11.0) -> 11 | O22: =IFERROR(__xludf.DUMMYFUNCTION("IFERROR(HLOOKUP($A22,IMPORTRANGE(""https://docs.google.com/spreadsheets/d/1UrzyxmT40kDZwVrLMf1yyXfP-pyczRAw9Y8Rw-uXG3c/edit#gid=0"",""'Game 9'!$B$2:$Q$31""),30,False),1)"),23.0) -> 23 | P22: =IFERROR(__xludf.DUMMYFUNCTION("IFERROR(HLOOKUP($A22,IMPORTRANGE(""https://docs.google.com/spreadsheets/d/1iyMhSYWifw-KGFtyeBpNxVZr4BhcV9hVZuShgJ9Ia0E/edit#gid=0"",""'Game 9'!$B$2:$Q$31""),30,False),1)"),0.0) -> 0 | Q22: =IFERROR(__xludf.DUMMYFUNCTION("IFERROR(HLOOKUP($A22,IMPORTRANGE(""https://docs.google.com/spreadsheets/d/1sSbIK-vvHsSY0LghLJ9gcnW8Hec_ITI2tFmpeqI999A/edit#gid=0"",""'Game 4'!$B$2:$Q$31""),30,False),1)"),23.0) -> 23 | R22: =SUM(C22:Q22) -> 195
A23: Emily | B23: Centennial | C23: 23 | D23: 0 | E23: 12 | F23: 0 | G23: 0 | H23: =IFERROR(__xludf.DUMMYFUNCTION("HLOOKUP($A23,IMPORTRANGE(""https://docs.google.com/spreadsheets/d/16J5ie7OD1E99qGO9lMDm8w5Yls-v190B7DTolJ5TmFc/edit#gid=0"",""'Game 7'!$B$2:$Q$31""),30,False)"),0.0) -> 0 | I23: 23 | J23: =IFERROR(__xludf.DUMMYFUNCTION("IFERROR(HLOOKUP($A23,IMPORTRANGE(""https://docs.google.com/spreadsheets/d/1CTYfdyRk_RFGM3I2iN9bKeD9zUPzEm1ajzml6VgwfIU/edit#gid=0"",""'Game 9'!$B$2:$Q$31""),30,False),0)"),0.0) -> 0 | K23: =IFERROR(__xludf.DUMMYFUNCTION("IFERROR(HLOOKUP($A23,IMPORTRANGE(""https://docs.google.com/spreadsheets/d/11NFkzOdQyW-OtxSDuGslNCgNjx7HUb2FU7KnlNnPMgY/edit#gid=0"",""'Game 9'!$B$2:$Q$31""),30,False),0)"),23.0) -> 23 | L23: =IFERROR(__xludf.DUMMYFUNCTION("IFERROR(HLOOKUP($A23,IMPORTRANGE(""https://docs.google.com/spreadsheets/d/1CLg5-jaE4ta0-u4oE1qbBplQ5Mf3Oj9ONFgL0zJ7Ol4/edit#gid=0"",""'Game 6'!$B$2:$Q$31""),30,False),1)"),0.0) -> 0 | M23: =IFERROR(__xludf.DUMMYFUNCTION("IFERROR(HLOOKUP($A23,IMPORTRANGE(""https://docs.google.com/spreadsheets/d/1CeexgK4KxWj3k_7nql_k8-RPxXMwTJyB4Q3vAASeDlA/edit#gid=0"",""'Game 4'!$B$2:$Q$31""),30,False),1)"),12.0) -> 12 | N23: =IFERROR(__xludf.DUMMYFUNCTION("IFERROR(HLOOKUP($A23,IMPORTRANGE(""https://docs.google.com/spreadsheets/d/1MNwUNMjcwK6bEgCXwB73jpbK5gJAXS8ZMpbEMLJEP3E/edit#gid=0"",""'Game 3'!$B$2:$Q$31""),30,False),1)"),11.0) -> 11 | O23: =IFERROR(__xludf.DUMMYFUNCTION("IFERROR(HLOOKUP($A23,IMPORTRANGE(""https://docs.google.com/spreadsheets/d/1UrzyxmT40kDZwVrLMf1yyXfP-pyczRAw9Y8Rw-uXG3c/edit#gid=0"",""'Game 9'!$B$2:$Q$31""),30,False),1)"),0.0) -> 0 | P23: =IFERROR(__xludf.DUMMYFUNCTION("IFERROR(HLOOKUP($A23,IMPORTRANGE(""https://docs.google.com/spreadsheets/d/1iyMhSYWifw-KGFtyeBpNxVZr4BhcV9hVZuShgJ9Ia0E/edit#gid=0"",""'Game 9'!$B$2:$Q$31""),30,False),1)"),0.0) -> 0 | Q23: =IFERROR(__xludf.DUMMYFUNCTION("IFERROR(HLOOKUP($A23,IMPORTRANGE(""https://docs.google.com/spreadsheets/d/1sSbIK-vvHsSY0LghLJ9gcnW8Hec_ITI2tFmpeqI999A/edit#gid=0"",""'Game 4'!$B$2:$Q$31""),30,False),1)"),12.0) -> 12 | R23: =SUM(C23:Q23) -> 116
A24: Isaac | B24: Centennial | C24: 0 | D24: 23 | E24: 11 | F24: 23 | G24: 23 | H24: =IFERROR(__xludf.DUMMYFUNCTION("HLOOKUP($A24,IMPORTRANGE(""https://docs.google.com/spreadsheets/d/16J5ie7OD1E99qGO9lMDm8w5Yls-v190B7DTolJ5TmFc/edit#gid=0"",""'Game 7'!$B$2:$Q$31""),30,False)"),0.0) -> 0 | I24: 0 | J24: =IFERROR(__xludf.DUMMYFUNCTION("IFERROR(HLOOKUP($A24,IMPORTRANGE(""https://docs.google.com/spreadsheets/d/1CTYfdyRk_RFGM3I2iN9bKeD9zUPzEm1ajzml6VgwfIU/edit#gid=0"",""'Game 9'!$B$2:$Q$31""),30,False),0)"),23.0) -> 23 | K24: =IFERROR(__xludf.DUMMYFUNCTION("IFERROR(HLOOKUP($A24,IMPORTRANGE(""https://docs.google.com/spreadsheets/d/11NFkzOdQyW-OtxSDuGslNCgNjx7HUb2FU7KnlNnPMgY/edit#gid=0"",""'Game 9'!$B$2:$Q$31""),30,False),0)"),12.0) -> 12 | L24: =IFERROR(__xludf.DUMMYFUNCTION("IFERROR(HLOOKUP($A24,IMPORTRANGE(""https://docs.google.com/spreadsheets/d/1CLg5-jaE4ta0-u4oE1qbBplQ5Mf3Oj9ONFgL0zJ7Ol4/edit#gid=0"",""'Game 6'!$B$2:$Q$31""),30,False),1)"),23.0) -> 23 | M24: =IFERROR(__xludf.DUMMYFUNCTION("IFERROR(HLOOKUP($A24,IMPORTRANGE(""https://docs.google.com/spreadsheets/d/1CeexgK4KxWj3k_7nql_k8-RPxXMwTJyB4Q3vAASeDlA/edit#gid=0"",""'Game 4'!$B$2:$Q$31""),30,False),1)"),0.0) -> 0 | N24: =IFERROR(__xludf.DUMMYFUNCTION("IFERROR(HLOOKUP($A24,IMPORTRANGE(""https://docs.google.com/spreadsheets/d/1MNwUNMjcwK6bEgCXwB73jpbK5gJAXS8ZMpbEMLJEP3E/edit#gid=0"",""'Game 3'!$B$2:$Q$31""),30,False),1)"),12.0) -> 12 | O24: =IFERROR(__xludf.DUMMYFUNCTION("IFERROR(HLOOKUP($A24,IMPORTRANGE(""https://docs.google.com/spreadsheets/d/1UrzyxmT40kDZwVrLMf1yyXfP-pyczRAw9Y8Rw-uXG3c/edit#gid=0"",""'Game 9'!$B$2:$Q$31""),30,False),1)"),0.0) -> 0 | P24: =IFERROR(__xludf.DUMMYFUNCTION("IFERROR(HLOOKUP($A24,IMPORTRANGE(""https://docs.google.com/spreadsheets/d/1iyMhSYWifw-KGFtyeBpNxVZr4BhcV9hVZuShgJ9Ia0E/edit#gid=0"",""'Game 9'!$B$2:$Q$31""),30,False),1)"),23.0) -> 23 | Q24: =IFERROR(__xludf.DUMMYFUNCTION("IFERROR(HLOOKUP($A24,IMPORTRANGE(""https://docs.google.com/spreadsheets/d/1sSbIK-vvHsSY0LghLJ9gcnW8Hec_ITI2tFmpeqI999A/edit#gid=0"",""'Game 4'!$B$2:$Q$31""),30,False),1)"),11.0) -> 11 | R24: =SUM(C24:Q24) -> 184
A25: Larry | B25: Centennial | C25: 23 | D25: 0 | E25: 0 | F25: 0 | G25: 23 | H25: =IFERROR(__xludf.DUMMYFUNCTION("HLOOKUP($A25,IMPORTRANGE(""https://docs.google.com/spreadsheets/d/16J5ie7OD1E99qGO9lMDm8w5Yls-v190B7DTolJ5TmFc/edit#gid=0"",""'Game 7'!$B$2:$Q$31""),30,False)"),23.0) -> 23 | I25: 0 | J25: =IFERROR(__xludf.DUMMYFUNCTION("IFERROR(HLOOKUP($A25,IMPORTRANGE(""https://docs.google.com/spreadsheets/d/1CTYfdyRk_RFGM3I2iN9bKeD9zUPzEm1ajzml6VgwfIU/edit#gid=0"",""'Game 9'!$B$2:$Q$31""),30,False),0)"),23.0) -> 23 | K25: =IFERROR(__xludf.DUMMYFUNCTION("IFERROR(HLOOKUP($A25,IMPORTRANGE(""https://docs.google.com/spreadsheets/d/11NFkzOdQyW-OtxSDuGslNCgNjx7HUb2FU7KnlNnPMgY/edit#gid=0"",""'Game 9'!$B$2:$Q$31""),30,False),0)"),0.0) -> 0 | L25: =IFERROR(__xludf.DUMMYFUNCTION("IFERROR(HLOOKUP($A25,IMPORTRANGE(""https://docs.google.com/spreadsheets/d/1CLg5-jaE4ta0-u4oE1qbBplQ5Mf3Oj9ONFgL0zJ7Ol4/edit#gid=0"",""'Game 6'!$B$2:$Q$31""),30,False),1)"),23.0) -> 23 | M25: =IFERROR(__xludf.DUMMYFUNCTION("IFERROR(HLOOKUP($A25,IMPORTRANGE(""https://docs.google.com/spreadsheets/d/1CeexgK4KxWj3k_7nql_k8-RPxXMwTJyB4Q3vAASeDlA/edit#gid=0"",""'Game 4'!$B$2:$Q$31""),30,False),1)"),11.0) -> 11 | N25: =IFERROR(__xludf.DUMMYFUNCTION("IFERROR(HLOOKUP($A25,IMPORTRANGE(""https://docs.google.com/spreadsheets/d/1MNwUNMjcwK6bEgCXwB73jpbK5gJAXS8ZMpbEMLJEP3E/edit#gid=0"",""'Game 3'!$B$2:$Q$31""),30,False),1)"),12.0) -> 12 | O25: =IFERROR(__xludf.DUMMYFUNCTION("IFERROR(HLOOKUP($A25,IMPORTRANGE(""https://docs.google.com/spreadsheets/d/1UrzyxmT40kDZwVrLMf1yyXfP-pyczRAw9Y8Rw-uXG3c/edit#gid=0"",""'Game 9'!$B$2:$Q$31""),30,False),1)"),23.0) -> 23 | P25: =IFERROR(__xludf.DUMMYFUNCTION("IFERROR(HLOOKUP($A25,IMPORTRANGE(""https://docs.google.com/spreadsheets/d/1iyMhSYWifw-KGFtyeBpNxVZr4BhcV9hVZuShgJ9Ia0E/edit#gid=0"",""'Game 9'!$B$2:$Q$31""),30,False),1)"),23.0) -> 23 | Q25: =IFERROR(__xludf.DUMMYFUNCTION("IFERROR(HLOOKUP($A25,IMPORTRANGE(""https://docs.google.com/spreadsheets/d/1sSbIK-vvHsSY0LghLJ9gcnW8Hec_ITI2tFmpeqI999A/edit#gid=0"",""'Game 4'!$B$2:$Q$31""),30,False),1)"),0.0) -> 0 | R25: =SUM(C25:Q25) -> 184
A26: Mario BM | B26: Centennial | C26: 0 | D26: 0 | E26: 23 | F26: 0 | G26: 0 | H26: =IFERROR(__xludf.DUMMYFUNCTION("HLOOKUP($A26,IMPORTRANGE(""https://docs.google.com/spreadsheets/d/16J5ie7OD1E99qGO9lMDm8w5Yls-v190B7DTolJ5TmFc/edit#gid=0"",""'Game 7'!$B$2:$Q$31""),30,False)"),23.0) -> 23 | I26: 0 | J26: =IFERROR(__xludf.DUMMYFUNCTION("IFERROR(HLOOKUP($A26,IMPORTRANGE(""https://docs.google.com/spreadsheets/d/1CTYfdyRk_RFGM3I2iN9bKeD9zUPzEm1ajzml6VgwfIU/edit#gid=0"",""'Game 9'!$B$2:$Q$31""),30,False),0)"),23.0) -> 23 | K26: =IFERROR(__xludf.DUMMYFUNCTION("IFERROR(HLOOKUP($A26,IMPORTRANGE(""https://docs.google.com/spreadsheets/d/11NFkzOdQyW-OtxSDuGslNCgNjx7HUb2FU7KnlNnPMgY/edit#gid=0"",""'Game 9'!$B$2:$Q$31""),30,False),0)"),23.0) -> 23 | L26: =IFERROR(__xludf.DUMMYFUNCTION("IFERROR(HLOOKUP($A26,IMPORTRANGE(""https://docs.google.com/spreadsheets/d/1CLg5-jaE4ta0-u4oE1qbBplQ5Mf3Oj9ONFgL0zJ7Ol4/edit#gid=0"",""'Game 6'!$B$2:$Q$31""),30,False),1)"),0.0) -> 0 | M26: =IFERROR(__xludf.DUMMYFUNCTION("IFERROR(HLOOKUP($A26,IMPORTRANGE(""https://docs.google.com/spreadsheets/d/1CeexgK4KxWj3k_7nql_k8-RPxXMwTJyB4Q3vAASeDlA/edit#gid=0"",""'Game 4'!$B$2:$Q$31""),30,False),1)"),12.0) -> 12 | N26: =IFERROR(__xludf.DUMMYFUNCTION("IFERROR(HLOOKUP($A26,IMPORTRANGE(""https://docs.google.com/spreadsheets/d/1MNwUNMjcwK6bEgCXwB73jpbK5gJAXS8ZMpbEMLJEP3E/edit#gid=0"",""'Game 3'!$B$2:$Q$31""),30,False),1)"),0.0) -> 0 | O26: =IFERROR(__xludf.DUMMYFUNCTION("IFERROR(HLOOKUP($A26,IMPORTRANGE(""https://docs.google.com/spreadsheets/d/1UrzyxmT40kDZwVrLMf1yyXfP-pyczRAw9Y8Rw-uXG3c/edit#gid=0"",""'Game 9'!$B$2:$Q$31""),30,False),1)"),23.0) -> 23 | P26: =IFERROR(__xludf.DUMMYFUNCTION("IFERROR(HLOOKUP($A26,IMPORTRANGE(""https://docs.google.com/spreadsheets/d/1iyMhSYWifw-KGFtyeBpNxVZr4BhcV9hVZuShgJ9Ia0E/edit#gid=0"",""'Game 9'!$B$2:$Q$31""),30,False),1)"),0.0) -> 0 | Q26: =IFERROR(__xludf.DUMMYFUNCTION("IFERROR(HLOOKUP($A26,IMPORTRANGE(""https://docs.google.com/spreadsheets/d/1sSbIK-vvHsSY0LghLJ9gcnW8Hec_ITI2tFmpeqI999A/edit#gid=0"",""'Game 4'!$B$2:$Q$31""),30,False),1)"),12.0) -> 12 | R26: =SUM(C26:Q26) -> 139
A27: Tomas | B27: Centennial | C27: 23 | D27: 23 | E27: 23 | F27: 23 | G27: 23 | H27: =IFERROR(__xludf.DUMMYFUNCTION("HLOOKUP($A27,IMPORTRANGE(""https://docs.google.com/spreadsheets/d/16J5ie7OD1E99qGO9lMDm8w5Yls-v190B7DTolJ5TmFc/edit#gid=0"",""'Game 7'!$B$2:$Q$31""),30,False)"),0.0) -> 0 | I27: 23 | J27: =IFERROR(__xludf.DUMMYFUNCTION("IFERROR(HLOOKUP($A27,IMPORTRANGE(""https://docs.google.com/spreadsheets/d/1CTYfdyRk_RFGM3I2iN9bKeD9zUPzEm1ajzml6VgwfIU/edit#gid=0"",""'Game 9'!$B$2:$Q$31""),30,False),0)"),0.0) -> 0 | K27: =IFERROR(__xludf.DUMMYFUNCTION("IFERROR(HLOOKUP($A27,IMPORTRANGE(""https://docs.google.com/spreadsheets/d/11NFkzOdQyW-OtxSDuGslNCgNjx7HUb2FU7KnlNnPMgY/edit#gid=0"",""'Game 9'!$B$2:$Q$31""),30,False),0)"),11.0) -> 11 | L27: =IFERROR(__xludf.DUMMYFUNCTION("IFERROR(HLOOKUP($A27,IMPORTRANGE(""https://docs.google.com/spreadsheets/d/1CLg5-jaE4ta0-u4oE1qbBplQ5Mf3Oj9ONFgL0zJ7Ol4/edit#gid=0"",""'Game 6'!$B$2:$Q$31""),30,False),1)"),0.0) -> 0 | M27: =IFERROR(__xludf.DUMMYFUNCTION("IFERROR(HLOOKUP($A27,IMPORTRANGE(""https://docs.google.com/spreadsheets/d/1CeexgK4KxWj3k_7nql_k8-RPxXMwTJyB4Q3vAASeDlA/edit#gid=0"",""'Game 4'!$B$2:$Q$31""),30,False),1)"),11.0) -> 11 | N27: =IFERROR(__xludf.DUMMYFUNCTION("IFERROR(HLOOKUP($A27,IMPORTRANGE(""https://docs.google.com/spreadsheets/d/1MNwUNMjcwK6bEgCXwB73jpbK5gJAXS8ZMpbEMLJEP3E/edit#gid=0"",""'Game 3'!$B$2:$Q$31""),30,False),1)"),23.0) -> 23 | O27: =IFERROR(__xludf.DUMMYFUNCTION("IFERROR(HLOOKUP($A27,IMPORTRANGE(""https://docs.google.com/spreadsheets/d/1UrzyxmT40kDZwVrLMf1yyXfP-pyczRAw9Y8Rw-uXG3c/edit#gid=0"",""'Game 9'!$B$2:$Q$31""),30,False),1)"),0.0) -> 0 | P27: =IFERROR(__xludf.DUMMYFUNCTION("IFERROR(HLOOKUP($A27,IMPORTRANGE(""https://docs.google.com/spreadsheets/d/1iyMhSYWifw-KGFtyeBpNxVZr4BhcV9hVZuShgJ9Ia0E/edit#gid=0"",""'Game 9'!$B$2:$Q$31""),30,False),1)"),23.0) -> 23 | Q27: =IFERROR(__xludf.DUMMYFUNCTION("IFERROR(HLOOKUP($A27,IMPORTRANGE(""https://docs.google.com/spreadsheets/d/1sSbIK-vvHsSY0LghLJ9gcnW8Hec_ITI2tFmpeqI999A/edit#gid=0"",""'Game 4'!$B$2:$Q$31""),30,False),1)"),11.0) -> 11 | R27: =SUM(C27:Q27) -> 217
A28: Gabriel | B28: Fantastic Four | C28: 23 | D28: 23 | E28: 23 | F28: 0 | G28: 23 | H28: =IFERROR(__xludf.DUMMYFUNCTION("HLOOKUP($A28,IMPORTRANGE(""https://docs.google.com/spreadsheets/d/16J5ie7OD1E99qGO9lMDm8w5Yls-v190B7DTolJ5TmFc/edit#gid=0"",""'Game 7'!$B$2:$Q$31""),30,False)"),23.0) -> 23 | I28: 12 | J28: =IFERROR(__xludf.DUMMYFUNCTION("IFERROR(HLOOKUP($A28,IMPORTRANGE(""https://docs.google.com/spreadsheets/d/1CTYfdyRk_RFGM3I2iN9bKeD9zUPzEm1ajzml6VgwfIU/edit#gid=0"",""'Game 2'!$B$2:$Q$31""),30,False),0)"),23.0) -> 23 | K28: =IFERROR(__xludf.DUMMYFUNCTION("IFERROR(HLOOKUP($A28,IMPORTRANGE(""https://docs.google.com/spreadsheets/d/11NFkzOdQyW-OtxSDuGslNCgNjx7HUb2FU7KnlNnPMgY/edit#gid=0"",""'Game 10'!$B$2:$Q$31""),30,False),0)"),12.0) -> 12 | L28: =IFERROR(__xludf.DUMMYFUNCTION("IFERROR(HLOOKUP($A28,IMPORTRANGE(""https://docs.google.com/spreadsheets/d/1CLg5-jaE4ta0-u4oE1qbBplQ5Mf3Oj9ONFgL0zJ7Ol4/edit#gid=0"",""'Game 8'!$B$2:$Q$31""),30,False),1)"),23.0) -> 23 | M28: =IFERROR(__xludf.DUMMYFUNCTION("IFERROR(HLOOKUP($A28,IMPORTRANGE(""https://docs.google.com/spreadsheets/d/1CeexgK4KxWj3k_7nql_k8-RPxXMwTJyB4Q3vAASeDlA/edit#gid=0"",""'Game 8'!$B$2:$Q$31""),30,False),1)"),23.0) -> 23 | N28: =IFERROR(__xludf.DUMMYFUNCTION("IFERROR(HLOOKUP($A28,IMPORTRANGE(""https://docs.google.com/spreadsheets/d/1MNwUNMjcwK6bEgCXwB73jpbK5gJAXS8ZMpbEMLJEP3E/edit#gid=0"",""'Game 9'!$B$2:$Q$31""),30,False),1)"),23.0) -> 23 | O28: =IFERROR(__xludf.DUMMYFUNCTION("IFERROR(HLOOKUP($A28,IMPORTRANGE(""https://docs.google.com/spreadsheets/d/1UrzyxmT40kDZwVrLMf1yyXfP-pyczRAw9Y8Rw-uXG3c/edit#gid=0"",""'Game 10'!$B$2:$Q$31""),30,False),1)"),23.0) -> 23 | P28: =IFERROR(__xludf.DUMMYFUNCTION("IFERROR(HLOOKUP($A28,IMPORTRANGE(""https://docs.google.com/spreadsheets/d/1iyMhSYWifw-KGFtyeBpNxVZr4BhcV9hVZuShgJ9Ia0E/edit#gid=0"",""'Game 3'!$B$2:$Q$31""),30,False),1)"),23.0) -> 23 | Q28: =IFERROR(__xludf.DUMMYFUNCTION("IFERROR(HLOOKUP($A28,IMPORTRANGE(""https://docs.google.com/spreadsheets/d/1sSbIK-vvHsSY0LghLJ9gcnW8Hec_ITI2tFmpeqI999A/edit#gid=0"",""'Game 5'!$B$2:$Q$31""),30,False),1)"),0.0) -> 0 | R28: =SUM(C28:Q28) -> 277
A29: Ivan G | B29: Fantastic Four | C29: 23 | D29: 23 | E29: 0 | F29: 23 | G29: 23 | H29: =IFERROR(__xludf.DUMMYFUNCTION("HLOOKUP($A29,IMPORTRANGE(""https://docs.google.com/spreadsheets/d/16J5ie7OD1E99qGO9lMDm8w5Yls-v190B7DTolJ5TmFc/edit#gid=0"",""'Game 7'!$B$2:$Q$31""),30,False)"),23.0) -> 23 | I29: 23 | J29: =IFERROR(__xludf.DUMMYFUNCTION("IFERROR(HLOOKUP($A29,IMPORTRANGE(""https://docs.google.com/spreadsheets/d/1CTYfdyRk_RFGM3I2iN9bKeD9zUPzEm1ajzml6VgwfIU/edit#gid=0"",""'Game 2'!$B$2:$Q$31""),30,False),0)"),23.0) -> 23 | K29: =IFERROR(__xludf.DUMMYFUNCTION("IFERROR(HLOOKUP($A29,IMPORTRANGE(""https://docs.google.com/spreadsheets/d/11NFkzOdQyW-OtxSDuGslNCgNjx7HUb2FU7KnlNnPMgY/edit#gid=0"",""'Game 10'!$B$2:$Q$31""),30,False),0)"),23.0) -> 23 | L29: =IFERROR(__xludf.DUMMYFUNCTION("IFERROR(HLOOKUP($A29,IMPORTRANGE(""https://docs.google.com/spreadsheets/d/1CLg5-jaE4ta0-u4oE1qbBplQ5Mf3Oj9ONFgL0zJ7Ol4/edit#gid=0"",""'Game 8'!$B$2:$Q$31""),30,False),1)"),23.0) -> 23 | M29: =IFERROR(__xludf.DUMMYFUNCTION("IFERROR(HLOOKUP($A29,IMPORTRANGE(""https://docs.google.com/spreadsheets/d/1CeexgK4KxWj3k_7nql_k8-RPxXMwTJyB4Q3vAASeDlA/edit#gid=0"",""'Game 8'!$B$2:$Q$31""),30,False),1)"),23.0) -> 23 | N29: =IFERROR(__xludf.DUMMYFUNCTION("IFERROR(HLOOKUP($A29,IMPORTRANGE(""https://docs.google.com/spreadsheets/d/1MNwUNMjcwK6bEgCXwB73jpbK5gJAXS8ZMpbEMLJEP3E/edit#gid=0"",""'Game 9'!$B$2:$Q$31""),30,False),1)"),23.0) -> 23 | O29: =IFERROR(__xludf.DUMMYFUNCTION("IFERROR(HLOOKUP($A29,IMPORTRANGE(""https://docs.google.com/spreadsheets/d/1UrzyxmT40kDZwVrLMf1yyXfP-pyczRAw9Y8Rw-uXG3c/edit#gid=0"",""'Game 10'!$B$2:$Q$31""),30,False),1)"),23.0) -> 23 | P29: =IFERROR(__xludf.DUMMYFUNCTION("IFERROR(HLOOKUP($A29,IMPORTRANGE(""https://docs.google.com/spreadsheets/d/1iyMhSYWifw-KGFtyeBpNxVZr4BhcV9hVZuShgJ9Ia0E/edit#gid=0"",""'Game 3'!$B$2:$Q$31""),30,False),1)"),0.0) -> 0 | Q29: =IFERROR(__xludf.DUMMYFUNCTION("IFERROR(HLOOKUP($A29,IMPORTRANGE(""https://docs.google.com/spreadsheets/d/1sSbIK-vvHsSY0LghLJ9gcnW8Hec_ITI2tFmpeqI999A/edit#gid=0"",""'Game 5'!$B$2:$Q$31""),30,False),1)"),23.0) -> 23 | R29: =SUM(C29:Q29) -> 299
