Workbook

Sheet Tournament Schedule
B2: SMH League Cup - January 4, 2025
B4: Schedule | F4: Playoff Pairings
B5: all listed times are in pacific time (PT) | F5: all listed times are in pacific time (PT)
B7: Start Time | C7: End Time | D7: Description | G7: Start Time | I7: Room 1 | J7: Room 2 | K7: Bye
B8: 0.36458333 | C8: 0.39583333 | D8: Opening Ceremony + League Match 1 | G8: 0.55208333 | H8: PO1 | I8: 45293 | J8: 45355 | K8: 5
B9: 0.39583333 | C9: 0.41666667 | D9: League Match 2 | G9: 0.57291667 | H9: PO2 | I9: 45327 | J9: 45295 | K9: 3
B10: 0.41666667 | C10: 0.4375 | D10: League Match 3 | G10: 0.59375 | H10: PO3 | I10: 45294 | J10: 45387 | K10: 2
G11: 0.61458333 | H11: PO4 | I11: 45326 | J11: 45356 | K11: 1
B12: 0.4375 | C12: 0.45833333 | D12: Break | G12: 0.63541667 | H12: PO5 | I12: 45296 | J12: 45325 | K12: 4
B14: 0.45833333 | C14: 0.47916667 | D14: League Match 4 | G14: For example, in RR3, the fourth team in each division (e.g. Albatross-4) would play in Room 2 against the fifth team in each division (e.g. Albatross-5).
B15: 0.47916667 | C15: 0.5 | D15: League Match 5
B16: 0.5 | C16: 0.52083333 | D16: League Match 6
B18: 0.52083333 | C18: 0.54166667 | D18: Break | F18: Important Links
B19: 0.54166667 | C19: 0.55208333 | D19: Halftime Show
B21: 0.55208333 | C21: 0.57291667 | D21: Playoff Match 1
B22: 0.57291667 | C22: 0.59375 | D22: Playoff Match 2 | G22: Discord server: | I22: https://discord.gg/N87yVFa3vM
B23: 0.59375 | C23: 0.61458333 | D23: Playoff Match 3 | G23: Official website: | I23: https://dannyridel44.wixsite.com/smClements024
B24: 0.61458333 | C24: 0.63541667 | D24: Playoff Match 4 | G24: Information document: | I24: https://docs.google.com/document/d/1RRNL41UogzexBgWP4H1yVr-53sru8julP50ghC_3KJ0/edit?usp=sharing
B25: 0.63541667 | C25: 0.65625 | D25: Playoff Match 5
B27: 0.67708333 | C27: 0.6875 | D27: Closing Ceremony

Sheet Team Hub
B2: League Phase Team Hub
B3: the team code to the left of team name is the Home channel of each team; H - Home Game, A - Away Game (other team's Home channel)
C6: a-1 | D6: Hunter | J6: a-2 | K6: Palo Alto | Q6: a-3 | R6: Middleton
D8: Opponent | F8: For | G8: Against | H8: Difference | K8: Opponent | M8: For | N8: Against | O8: Difference | R8: Opponent | T8: For | U8: Against | V8: Difference
C9: Match 1 | D9: Frazer | E9: A | F9: ='League Scoreboard'!E10 -> 94 | G9: ='League Scoreboard'!E8 -> 178 | H9: =F9-G9 -> -84 | J9: Match 1 | K9: JP Stevens | L9: H | M9: ='League Scoreboard'!I8 -> 140 | N9: ='League Scoreboard'!I10 -> 90 | O9: =M9-N9 -> 50 | Q9: Match 1 | R9: Ward Melville | S9: H | T9: ='League Scoreboard'!M8 -> 4 | U9: ='League Scoreboard'!M10 -> 256 | V9: =T9-U9 -> -252
C11: Match 2 | D11: ASFA | E11: H | F11: ='League Scoreboard'!E22 -> 60 | G11: ='League Scoreboard'!E24 -> 180 | H11: =F11-G11 -> -120 | J11: Match 2 | K11: Mira Loma | L11: H | M11: ='League Scoreboard'!E26 -> 106 | N11: ='League Scoreboard'!E28 -> 102 | O11: =M11-N11 -> 4 | Q11: Match 2 | R11: PRISMS | S11: A | T11: ='League Scoreboard'!E32 -> 128 | U11: ='League Scoreboard'!E30 -> 88 | V11: =T11-U11 -> 40
C13: Match 3 | D13: Stuyvesant | E13: H | F13: ='League Scoreboard'!E36 -> 130 | G13: ='League Scoreboard'!E38 -> 138 | H13: =F13-G13 -> -8 | J13: Match 3 | K13: Interlake | L13: H | M13: ='League Scoreboard'!E40 -> 150 | N13: ='League Scoreboard'!E42 -> 144 | O13: =M13-N13 -> 6 | Q13: Match 3 | R13: Frazer | S13: A | T13: ='League Scoreboard'!E46 -> 10 | U13: ='League Scoreboard'!E44 -> 214 | V13: =T13-U13 -> -204
C15: Match 4 | D15: Amador Valley | E15: H | F15: ='League Scoreboard'!E50 -> 36 | G15: ='League Scoreboard'!E52 -> 218 | H15: =F15-G15 -> -182 | J15: Match 4 | K15: Blair | L15: A | M15: ='League Scoreboard'!E56 -> 56 | N15: ='League Scoreboard'!E54 -> 186 | O15: =M15-N15 -> -130 | Q15: Match 4 | R15: Clements | S15: A | T15: ='League Scoreboard'!E60 -> 60 | U15: ='League Scoreboard'!E58 -> 134 | V15: =T15-U15 -> -74
C17: Match 5 | D17: Ward Melville | E17: A | F17: ='League Scoreboard'!E66 -> 78 | G17: ='League Scoreboard'!E64 -> 148 | H17: =F17-G17 -> -70 | J17: Match 5 | K17: Lakeside | L17: A | M17: ='League Scoreboard'!E70 -> 158 | N17: ='League Scoreboard'!E68 -> 84 | O17: =M17-N17 -> 74 | Q17: Match 5 | R17: Blair | S17: H | T17: ='League Scoreboard'!E72 -> 18 | U17: ='League Scoreboard'!E74 -> 152 | V17: =T17-U17 -> -134
C19: Match 6 | D19: Winston Churchill | E19: A | F19: ='League Scoreboard'!E80 -> 126 | G19: ='League Scoreboard'!E78 -> -4 | H19: =F19-G19 -> 130 | J19: Match 6 | K19: Ward Melville | L19: A | M19: ='League Scoreboard'!E84 -> 88 | N19: ='League Scoreboard'!E82 -> 152 | O19: =M19-N19 -> -64 | Q19: Match 6 | R19: Mira Loma | S19: H | T19: ='League Scoreboard'!E86 -> 8 | U19: ='League Scoreboard'!E88 -> 200 | V19: =T19-U19 -> -192
F20: =countif(H9:H19, ">0") -> 1 | G20: =countif(H9:H19, "<0") -> 5 | H20: =countif(H9:H19, "=0") -> 0 | M20: =countif(O9:O19, ">0") -> 4 | N20: =countif(O9:O19, "<0") -> 2 | O20: =countif(O9:O19, "=0") -> 0 | T20: =countif(V9:V19, ">0") -> 1 | U20: =countif(V9:V19, "<0") -> 5 | V20: =countif(V9:V19, "=0") -> 0
C21: League Total | E21: =3*countifs(H9:H19, ">0")+countifs(H9:H19, "=0") -> 3 | F21: =sum(F9:F19) -> 524 | G21: =sum(G9:G19) -> 858 | H21: =sum(H9:H19) -> -334 | J21: League Total | L21: =3*countifs(O9:O19, ">0")+countifs(O9:O19, "=0") -> 12 | M21: =sum(M9:M19) -> 698 | N21: =sum(N9:N19) -> 758 | O21: =sum(O9:O19) -> -60 | Q21: League Total | S21: =3*countifs(V9:V19, ">0")+countifs(V9:V19, "=0") -> 3 | T21: =sum(T9:T19) -> 228 | U21: =sum(U9:U19) -> 1044 | V21: =sum(V9:V19) -> -816
C23: Playoff 1 | D23: bye | H23: =F23-G23 -> 0 | J23: Playoff 1 | K23: Mira Loma | M23: ='Playoff Scoring'!E17 -> 94 | N23: ='Playoff Scoring'!D18 -> 108 | O23: =M23-N23 -> -14 | Q23: Playoff 1 | R23: Winston Churchill | T23: ='Playoff Scoring'!L27 -> 40 | U23: ='Playoff Scoring'!M26 -> 26 | V23: =T23-U23 -> 14
C25: Playoff 2 | D25: OCSA | F25: ='Playoff Scoring'!E30 -> 102 | G25: ='Playoff Scoring'!H27 -> 36 | H25: =F25-G25 -> 66 | J25: Playoff 2 | K25: Saratoga | M25: ='Playoff Scoring'!G17 -> 58 | N25: ='Playoff Scoring'!D20 -> 130 | O25: =M25-N25 -> -72 | Q25: Playoff 2 | R25: JP Stevens | T25: ='Playoff Scoring'!P27 -> 36 | U25: ='Playoff Scoring'!M30 -> 64 | V25: =T25-U25 -> -28
C27: Playoff 3 | D27: Clements | F27: ='Playoff Scoring'!G30 -> 50 | G27: ='Playoff Scoring'!H29 -> 130 | H27: =F27-G27 -> -80 | J27: Playoff 3 | K27: ASFA | M27: ='Playoff Scoring'!F17 -> 58 | N27: ='Playoff Scoring'!D19 -> 78 | O27: =M27-N27 -> -20 | Q27: Playoff 3 | R27: bye | V27: =T27-U27 -> 0
C29: Playoff 4 | D29: Dulles | F29: ='Playoff Scoring'!F30 -> 72 | G29: ='Playoff Scoring'!H28 -> 42 | H29: =F29-G29 -> 30 | J29: Playoff 4 | K29: bye | O29: =M29-N29 -> 0 | Q29: Playoff 4 | R29: Tokay | T29: ='Playoff Scoring'!O27 -> 16 | U29: ='Playoff Scoring'!M29 -> 0 | V29: =T29-U29 -> 16
C31: Playoff 5 | D31: PRISMS | F31: ='Playoff Scoring'!D30 -> 42 | G31: ='Playoff Scoring'!H26 -> 58 | H31: =F31-G31 -> -16 | J31: Playoff 5 | K31: University | M31: ='Playoff Scoring'!H17 -> 88 | N31: ='Playoff Scoring'!D21 -> 100 | O31: =M31-N31 -> -12 | Q31: Playoff 5 | R31: Lexington | T31: ='Playoff Scoring'!N27 -> 52 | U31: ='Playoff Scoring'!M28 -> 14 | V31: =T31-U31 -> 38
C33: Playoff Total | E33: =2*countifs(H23:H31, ">0")+countifs(H23:H31, "=0") -> 5 | F33: =sum(F23:F31) -> 266 | G33: =sum(G23:G31) -> 266 | H33: =sum(H23:H31) -> 0 | J33: Playoff Total | L33: =2*countifs(O23:O31, ">0")+countifs(O23:O31, "=0") -> 1 | M33: =sum(M23:M31) -> 298 | N33: =sum(N23:N31) -> 416 | O33: =sum(O23:O31) -> -118 | Q33: Playoff Total | S33: =2*countifs(V23:V31, ">0")+countifs(V23:V31, "=0") -> 7 | T33: =sum(T23:T31) -> 144 | U33: =sum(U23:U31) -> 104 | V33: =sum(V23:V31) -> 40
F34: =COUNTIF(H9:H19, ">0")+countif(H23:H31, ">0") -> 3 | G34: =COUNTIF(H9:H19, "<0")+countif(H23:H31, "<0") -> 7 | H34: =COUNTIF(H9:H19, "=0")+countif(H23:H31, "=0") -> 1 | M34: =COUNTIF(O9:O19, ">0")+countif(O23:O31, ">0") -> 4 | N34: =COUNTIF(O9:O19, "<0")+countif(O23:O31, "<0") -> 6 | O34: =COUNTIF(O9:O19, "=0")+countif(O23:O31, "=0") -> 1 | T34: =COUNTIF(V9:V19, ">0")+countif(V23:V31, ">0") -> 4 | U34: =COUNTIF(V9:V19, "<0")+countif(V23:V31, "<0") -> 6 | V34: =COUNTIF(V9:V19, "=0")+countif(V23:V31, "=0") -> 1
C35: Grand Total | E35: =sum(E21,E33) -> 8 | F35: =sum(F21,F33) -> 790 | G35: =sum(G21,G33) -> 1124 | H35: =sum(H21,H33) -> -334 | J35: Grand Total | L35: =sum(L21,L33) -> 13 | M35: =sum(M21,M33) -> 996 | N35: =sum(N21,N33) -> 1174 | O35: =sum(O21,O33) -> -178 | Q35: Grand Total | S35: =sum(S21,S33) -> 10 | T35: =sum(T21,T33) -> 372 | U35: =sum(U21,U33) -> 1148 | V35: =sum(V21,V33) -> -776
C37: c-1 | D37: Lexington | J37: c-2 | K37: Ward Melville | Q37: c-3 | R37: Tokay
D39: Opponent | F39: For | G39: Against | H39: Difference | K39: Opponent | M39: For | N39: Against | O39: Difference | R39: Opponent | T39: For | U39: Against | V39: Difference
C40: Match 1 | D40: Stuyvesant | E40: H | F40: ='League Scoreboard'!Q8 -> 78 | G40: ='League Scoreboard'!Q10 -> 112 | H40: =F40-G40 -> -34 | J40: Match 1 | K40: Middleton | L40: A | M40: ='League Scoreboard'!M10 -> 256 | N40: ='League Scoreboard'!M8 -> 4 | O40: =M40-N40 -> 252 | Q40: Match 1 | R40: University | S40: A | T40: ='League Scoreboard'!U8 -> 28 | U40: ='League Scoreboard'!U10 -> 224 | V40: =T40-U40 -> -196
C42: Match 2 | D42: TJHSST | E42: H | F42: ='League Scoreboard'!I22 -> 28 | G42: ='League Scoreboard'!I24 -> 172 | H42: =F42-G42 -> -144 | J42: Match 2 | K42: Dulles | L42: A | M42: ='League Scoreboard'!I28 -> 126 | N42: ='League Scoreboard'!I26 -> 110 | O42: =M42-N42 -> 16 | Q42: Match 2 | R42: Wayzata | S42: H | T42: ='League Scoreboard'!I30 -> 28 | U42: ='League Scoreboard'!I32 -> 238 | V42: =T42-U42 -> -210
C44: Match 3 | D44: Missions San Jose | E44: H | F44: ='League Scoreboard'!I36 -> 74 | G44: ='League Scoreboard'!I38 -> 130 | H44: =F44-G44 -> -56 | J44: Match 3 | K44: TJHSST | L44: A | M44: ='League Scoreboard'!I42 -> 116 | N44: ='League Scoreboard'!I40 -> 154 | O44: =M44-N44 -> -38 | Q44: Match 3 | R44: Winston Churchill | S44: H | T44: ='League Scoreboard'!I44 -> 68 | U44: ='League Scoreboard'!I46 -> 84 | V44: =T44-U44 -> -16
C46: Match 4 | D46: Arcadia | E46: A | F46: ='League Scoreboard'!I52 -> 32 | G46: ='League Scoreboard'!I50 -> 148 | H46: =F46-G46 -> -116 | J46: Match 4 | K46: Foothill | L46: H | M46: ='League Scoreboard'!I54 -> 140 | N46: ='League Scoreboard'!I56 -> 126 | O46: =M46-N46 -> 14 | Q46: Match 4 | R46: Lynbrook | S46: H | T46: ='League Scoreboard'!I58 -> 26 | U46: ='League Scoreboard'!I60 -> 196 | V46: =T46-U46 -> -170
C48: Match 5 | D48: Canyon Crest | E48: A | F48: ='League Scoreboard'!I66 -> 28 | G48: ='League Scoreboard'!I64 -> 162 | H48: =F48-G48 -> -134 | J48: Match 5 | K48: Hunter | L48: H | M48: ='League Scoreboard'!E64 -> 148 | N48: ='League Scoreboard'!E66 -> 78 | O48: =M48-N48 -> 70 | Q48: Match 5 | R48: Interlake | S48: A | T48: ='League Scoreboard'!I70 -> 22 | U48: ='League Scoreboard'!I68 -> 162 | V48: =T48-U48 -> -140
C50: Match 6 | D50: Foothill | E50: A | F50: ='League Scoreboard'!I80 -> 58 | G50: ='League Scoreboard'!I78 -> 96 | H50: =F50-G50 -> -38 | J50: Match 6 | K50: Palo Alto | L50: H | M50: ='League Scoreboard'!E82 -> 152 | N50: ='League Scoreboard'!E84 -> 88 | O50: =M50-N50 -> 64 | Q50: Match 6 | R50: Arcadia | S50: A | T50: ='League Scoreboard'!I84 -> 26 | U50: ='League Scoreboard'!I82 -> 114 | V50: =T50-U50 -> -88
F51: =countif(H40:H50, ">0") -> 0 | G51: =countif(H40:H50, "<0") -> 6 | H51: =countif(H40:H50, "=0") -> 0 | M51: =countif(O40:O50, ">0") -> 5 | N51: =countif(O40:O50, "<0") -> 1 | O51: =countif(O40:O50, "=0") -> 0 | T51: =countif(V40:V50, ">0") -> 0 | U51: =countif(V40:V50, "<0") -> 6 | V51: =countif(V40:V50, "=0") -> 0
C52: League Total | E52: =3*countifs(H40:H50, ">0")+countifs(H40:H50, "=0") -> 0 | F52: =sum(F40:F50) -> 298 | G52: =sum(G40:G50) -> 820 | H52: =sum(H40:H50) -> -522 | J52: League Total | L52: =3*countifs(O40:O50, ">0")+countifs(O40:O50, "=0") -> 15 | M52: =sum(M40:M50) -> 938 | N52: =sum(N40:N50) -> 560 | O52: =sum(O40:O50) -> 378 | Q52: League Total | S52: =3*countifs(V40:V50, ">0")+countifs(V40:V50, "=0") -> 0 | T52: =sum(T40:T50) -> 198 | U52: =sum(U40:U50) -> 1018 | V52: =sum(V40:V50) -> -820
C54: Playoff 1 | D54: Tokay | F54: ='Playoff Scoring'!O28 -> 68 | G54: ='Playoff Scoring'!N29 -> 8 | H54: =F54-G54 -> 60 | J54: Playoff 1 | K54: Blair | M54: ='Playoff Scoring'!M8 -> 18 | N54: ='Playoff Scoring'!L9 -> 116 | O54: =M54-N54 -> -98 | Q54: Playoff 1 | R54: Lexington | T54: 8 | U54: 68 | V54: =T54-U54 -> -60
C56: Playoff 2 | D56: bye | H56: =F56-G56 -> 0 | J56: Playoff 2 | K56: Frazer | M56: ='Playoff Scoring'!O8 -> 58 | N56: ='Playoff Scoring'!L11 -> 144 | O56: =M56-N56 -> -86 | Q56: Playoff 2 | R56: Winston Churchill | T56: 0 | U56: ='Playoff Scoring'!O26 -> 0 | V56: =T56-U56 -> 0
C58: Playoff 3 | D58: Winston Churchill | F58: ='Playoff Scoring'!L28 -> 40 | G58: ='Playoff Scoring'!N26 -> 30 | H58: =F58-G58 -> 10 | J58: Playoff 3 | K58: Arcadia | M58: ='Playoff Scoring'!N8 -> 110 | N58: ='Playoff Scoring'!L10 -> 80 | O58: =M58-N58 -> 30 | Q58: Playoff 3 | R58: JP Stevens | T58: 0 | U58: ='Playoff Scoring'!O30 -> 32 | V58: =T58-U58 -> -32
C60: Playoff 4 | D60: JP Stevens | F60: ='Playoff Scoring'!P28 -> 48 | G60: ='Playoff Scoring'!N30 -> 18 | H60: =F60-G60 -> 30 | J60: Playoff 4 | K60: bye | O60: =M60-N60 -> 0 | Q60: Playoff 4 | R60: Middleton | T60: 0 | U60: ='Playoff Scoring'!O27 -> 16 | V60: =T60-U60 -> -16
C62: Playoff 5 | D62: Middleton | F62: ='Playoff Scoring'!M28 -> 14 | G62: ='Playoff Scoring'!N27 -> 52 | H62: =F62-G62 -> -38 | J62: Playoff 5 | K62: MSJ | M62: ='Playoff Scoring'!P8 -> 92 | N62: ='Playoff Scoring'!L12 -> 86 | O62: =M62-N62 -> 6 | Q62: Playoff 5 | R62: bye | V62: =T62-U62 -> 0
C64: Playoff Total | E64: =2*countifs(H54:H62, ">0")+countifs(H54:H62, "=0") -> 7 | F64: =sum(F54:F62) -> 170 | G64: =sum(G54:G62) -> 108 | H64: =sum(H54:H62) -> 62 | J64: Playoff Total | L64: =2*countifs(O54:O62, ">0")+countifs(O54:O62, "=0") -> 5 | M64: =sum(M54:M62) -> 278 | N64: =sum(N54:N62) -> 426 | O64: =sum(O54:O62) -> -148 | Q64: Playoff Total | S64: =2*countifs(V54:V62, ">0")+countifs(V54:V62, "=0") -> 2 | T64: =sum(T54:T62) -> 8 | U64: =sum(U54:U62) -> 116 | V64: =sum(V54:V62) -> -108
F65: =COUNTIF(H40:H50, ">0")+countif(H54:H62, ">0") -> 3 | G65: =COUNTIF(H40:H50, "<0")+countif(H54:H62, "<0") -> 7 | H65: =COUNTIF(H40:H50, "=0")+countif(H54:H62, "=0") -> 1 | M65: =COUNTIF(O40:O50, ">0")+countif(O54:O62, ">0") -> 7 | N65: =COUNTIF(O40:O50, "<0")+countif(O54:O62, "<0") -> 3 | O65: =COUNTIF(O40:O50, "=0")+countif(O54:O62, "=0") -> 1 | T65: =COUNTIF(V40:V50, ">0")+countif(V54:V62, ">0") -> 0 | U65: =COUNTIF(V40:V50, "<0")+countif(V54:V62, "<0") -> 9 | V65: =COUNTIF(V40:V50, "=0")+countif(V54:V62, "=0") -> 2
C66: Grand Total | E66: =sum(E52,E64) -> 7 | F66: =sum(F52,F64) -> 468 | G66: =sum(G52,G64) -> 928 | H66: =sum(H52,H64) -> -460 | J66: Grand Total | L66: =sum(L52,L64) -> 20 | M66: =sum(M52,M64) -> 1216 | N66: =sum(N52,N64) -> 986 | O66: =sum(O52,O64) -> 230 | Q66: Grand Total | S66: =sum(S52,S64) -> 2 | T66: =sum(T52,T64) -> 206 | U66: =sum(U52,U64) -> 1134 | V66: =sum(V52,V64) -> -928
C68: d-1 | D68: OCSA | J68: d-2 | K68: Canyon Crest | Q68: d-3 | R68: WWPS
D70: Opponent | F70: For | G70: Against | H70: Difference | K70: Opponent | M70: For | N70: Against | O70: Difference | R70: Opponent | T70: For | U70: Against | V70: Difference
...

Sheet Catstats Hub
A1: League Phase | E1: Playoff Phase
A4: League Team Overall | C4: League Individual Overall | E4: Playoff Phase Team Overall | G4: Playoff Individual Overall
A6: League Team Biology | C6: League Individual Biology | E6: Playoff Team Biology | G6: Playoff Individual Biology
A7: League Team Chemistry | C7: League Individual Chemistry | E7: Playoff Team Chemistry | G7: Playoff Individual Chemistry
A8: League Team Physics | C8: League Individual Physics | E8: Playoff Team Physics | G8: Playoff Individual Physics
A9: League Team Math | C9: League Individual Math | E9: Playoff Team Math | G9: Playoff Individual Math
A10: League Team ESS | C10: League Individual ESS | E10: Playoff Team ESS | G10: Playoff Individual ESS
A11: League Team Energy | C11: League Individual Energy | E11: Playoff Team Energy | G11: Playoff Individual Energy
B15: Use the hyperlink on the top left of each of these sheets to come back to the Cat Stats Hub!

Sheet League Scoreboard
B2: League Matchup Scoreboard
B3: the team listed on top is the Home team for all matches
C6: League Phase 1 | I6: Home Team Avg: | M6: =average(E8,I8,M8,Q8,U8,E12,I12,M12,Q12,U12,E16,I16,M16,Q16,U16) -> 138.66667 | O6: Away Team Avg: | S6: =average(E10,I10,M10,Q10,U10,E14,I14,M14,Q14,U14,E18,I18,M18,Q18,U18) -> 118.13333
C8: Frazer | E8: 178 | G8: Palo Alto | I8: 140 | K8: Middleton | M8: 4 | O8: Lexington | Q8: 78 | S8: Tokay | U8: 28
C10: Hunter | E10: 94 | G10: JP Stevens | I10: 90 | K10: Ward Melville | M10: 256 | O10: Stuyvesant | Q10: 112 | S10: University | U10: 224
C12: Mira Loma | E12: 204 | G12: Canyon Crest | I12: 138 | K12: ASFA | M12: 182 | O12: Wayzata | Q12: 48 | S12: TJHSST | U12: 206
C14: OCSA | E14: 80 | G14: PRISMS | I14: 76 | K14: WWPS | M14: 52 | O14: Interlake | Q14: 242 | S14: Dulles | U14: 66
C16: Lakeside | E16: 136 | G16: Foothill | I16: 134 | K16: Amador Valley | M16: 222 | O16: Saratoga | Q16: 136 | S16: Lynbrook | U16: 246
C18: Blair | E18: 128 | G18: Mission San Jose | I18: 126 | K18: Arcadia | M18: 80 | O18: Clements | Q18: 124 | S18: Winston Churchill | U18: 22
C20: League Phase 2 | I20: Home Team Avg: | M20: =average(E22,I22,M22,Q22,U22,E26,I26,M26,Q26,U26,E30,I30,M30,Q30,U30) -> 85.733333 | O20: Away Team Avg: | S20: =average(E24,I24,M24,Q24,U24,E28,I28,M28,Q28,U28,E32,I32,M32,Q32,U32) -> 144.53333
C22: Hunter | E22: 60 | G22: Lexington | I22: 28 | K22: OCSA | M22: 56 | O22: University | Q22: 154 | S22: Blair | U22: 116
C24: ASFA | E24: 180 | G24: TJHSST | I24: 172 | K24: Interlake | M24: 210 | O24: Lakeside | Q24: 102 | S24: Clements | U24: 92
C26: Palo Alto | E26: 106 | G26: Dulles | I26: 110 | K26: Lynbrook | M26: 208 | O26: Winston Churchill | Q26: 30 | S26: Stuyvesant | U26: 40
C28: Mira Loma | E28: 102 | G28: Ward Melville | I28: 126 | K28: Canyon Crest | M28: 58 | O28: Mission San Jose | Q28: 148 | S28: Foothill | U28: 168
C30: PRISMS | E30: 88 | G30: Tokay | I30: 28 | K30: JP Stevens | M30: 60 | O30: Frazer | Q30: 50 | S30: Arcadia | U30: 152
C32: Middleton | E32: 128 | G32: Wayzata | I32: 238 | K32: WWPS | M32: 148 | O32: Amador Valley | Q32: 220 | S32: Saratoga | U32: 76
C34: League Phase 3 | I34: Home Team Avg: | M34: =average(E36,I36,M36,Q36,U36,E40,I40,M40,Q40,U40,E44,I44,M44,Q44,U44) -> 143.73333 | O34: Away Team Avg: | S34: =average(E38,I38,M38,Q38,U38,E42,I42,M42,Q42,U42,E46,I46,M46,Q46,U46) -> 108.93333
C36: Hunter | E36: 130 | G36: Lexington | I36: 74 | K36: OCSA | M36: 108 | O36: Amador Valley | Q36: 194 | S36: PRISMS | U36: 136
C38: Stuyvesant | E38: 138 | G38: Mission San Jose | I38: 130 | K38: Blair | M38: 126 | O38: Wayzata | Q38: 84 | S38: Arcadia | U38: 150
C40: Palo Alto | E40: 150 | G40: TJHSST | I40: 154 | K40: Canyon Crest | M40: 134 | O40: Dulles | Q40: 230 | S40: University | U40: 86
C42: Interlake | E42: 144 | G42: Ward Melville | I42: 116 | K42: ASFA | M42: 82 | O42: JP Stevens | Q42: 46 | S42: Saratoga | U42: 192
C44: Frazer | E44: 214 | G44: Tokay | I44: 68 | K44: Mira Loma | M44: 126 | O44: Lakeside | Q44: 182 | S44: Lynbrook | U44: 170
C46: Middleton | E46: 10 | G46: Winston Churchill | I46: 84 | K46: WWPS | M46: 132 | O46: Clements | Q46: 106 | S46: Foothill | U46: 94
C48: League Phase 4 | I48: Home Team Avg: | M48: =average(E50,I50,M50,Q50,U50,E54,I54,M54,Q54,U54,E58,I58,M58,Q58,U58) -> 86.933333 | O48: Away Team Avg: | S48: =average(E52,I52,M52,Q52,U52,E56,I56,M56,Q56,U56,E60,I60,M60,Q60,U60) -> 146.13333
C50: Hunter | E50: 36 | G50: Arcadia | I50: 148 | K50: OCSA | M50: 40 | O50: WWPS | Q50: 98 | S50: PRISMS | U50: 144
C52: Amador Valley | E52: 218 | G52: Lexington | I52: 32 | K52: Lakeside | M52: 166 | O52: Wayzata | Q52: 136 | S52: University | U52: 88
C54: Blair | E54: 186 | G54: Ward Melville | I54: 140 | K54: JP Stevens | M54: 22 | O54: Dulles | Q54: 82 | S54: Stuyvesant | U54: 38
C56: Palo Alto | E56: 56 | G56: Foothill | I56: 126 | K56: Canyon Crest | M56: 274 | O56: Mira Loma | Q56: 126 | S56: TJHSST | U56: 232
C58: Clements | E58: 134 | G58: Tokay | I58: 26 | K58: Winston Churchill | M58: 16 | O58: Mission San Jose | Q58: 40 | S58: Interlake | U58: 154
C60: Middleton | E60: 60 | G60: Lynbrook | I60: 196 | K60: Frazer | M60: 200 | O60: ASFA | Q60: 162 | S60: Saratoga | U60: 120
C62: League Phase 5 | I62: Home Team Avg: | M62: =average(E64,I64,M64,Q64,U64,E68,I68,M68,Q68,U68,E72,I72,M72,Q72,U72) -> 118.93333 | O62: Away Team Avg: | S62: =average(E66,I66,M66,Q66,U66,E70,I70,M70,Q70,U70,E74,I74,M74,Q74,U74) -> 91.733333
C64: Ward Melville | E64: 148 | G64: Canyon Crest | I64: 162 | K64: WWPS | M64: 128 | O64: Mira Loma | Q64: 76 | S64: Foothill | U64: 66
C66: Hunter | E66: 78 | G66: Lexington | I66: 28 | K66: Winston Churchill | M66: 60 | O66: Frazer | Q66: 134 | S66: Arcadia | U66: 136
C68: Lakeside | E68: 84 | G68: Interlake | I68: 162 | K68: Wayzata | M68: 174 | O68: ASFA | Q68: 58 | S68: TJHSST | U68: 114
C70: Palo Alto | E70: 158 | G70: Tokay | I70: 22 | K70: Stuyvesant | M70: 64 | O70: PRISMS | Q70: 102 | S70: Lynbrook | U70: 122
C72: Middleton | E72: 18 | G72: Clements | I72: 94 | K72: Mission San Jose | M72: 154 | O72: Amador Valley | Q72: 148 | S72: Saratoga | U72: 198
C74: Blair | E74: 152 | G74: OCSA | I74: 110 | K74: Dulles | M74: 88 | O74: University | Q74: 102 | S74: JP Stevens | U74: 20
C76: League Phase 6 | I76: Home Team Avg: | M76: =average(E78,I78,M78,Q78,U78,E82,I82,M82,Q82,U82,E86,I86,M86,Q86,U86) -> 81.466667 | O76: Away Team Avg: | S76: =average(E80,I80,M80,Q80,U80,E84,I84,M84,Q84,U84,E88,I88,M88,Q88,U88) -> 111.6
C78: Winston Churchill | E78: -4 | G78: Foothill | I78: 96 | K78: WWPS | M78: 66 | O78: Mission San Jose | Q78: 156 | S78: ASFA | U78: 70
C80: Hunter | E80: 126 | G80: Lexington | I80: 58 | K80: Lynbrook | M80: 180 | O80: Lakeside | Q80: 64 | S80: University | U80: 126
...

Sheet League Phase Table
B2: League Phase Table
B3: teams are ranked by league points, point difference, then median-buchholz scale
D5: School Name | H5: Wins | I5: Ties | J5: Losses | K5: Point Difference | L5: League Points
C6: h-1 | D6: Amador Valley | H6: ='Team Hub'!F175 -> 6 | I6: ='Team Hub'!H175 -> 0 | J6: ='Team Hub'!G175 -> 0 | K6: ='Team Hub'!H176 -> 812 | L6: ='Team Hub'!E176 -> 18
C7: p-1 | D7: Lynbrook | H7: ='Team Hub'!F237 -> 6 | I7: ='Team Hub'!H237 -> 0 | J7: ='Team Hub'!G237 -> 0 | K7: ='Team Hub'!H238 -> 742 | L7: ='Team Hub'!E238 -> 18
C8: s-1 | D8: Interlake | H8: ='Team Hub'!F268 -> 5 | I8: ='Team Hub'!H268 -> 0 | J8: ='Team Hub'!G268 -> 1 | K8: ='Team Hub'!H269 -> 602 | L8: ='Team Hub'!E269 -> 15
C9: s-3 | D9: TJHSST | H9: ='Team Hub'!T268 -> 5 | I9: ='Team Hub'!V268 -> 0 | J9: ='Team Hub'!U268 -> 1 | K9: ='Team Hub'!V269 -> 572 | L9: ='Team Hub'!S269 -> 15
C10: d-2 | D10: Canyon Crest | H10: ='Team Hub'!M82 -> 5 | I10: ='Team Hub'!O82 -> 0 | J10: ='Team Hub'!N82 -> 1 | K10: ='Team Hub'!O83 -> 428 | L10: ='Team Hub'!L83 -> 15
C11: c-2 | D11: Ward Melville | H11: ='Team Hub'!M51 -> 5 | I11: ='Team Hub'!O51 -> 0 | J11: ='Team Hub'!N51 -> 1 | K11: ='Team Hub'!O52 -> 378 | L11: ='Team Hub'!L52 -> 15
C12: p-3 | D12: Blair | H12: ='Team Hub'!T237 -> 5 | I12: ='Team Hub'!V237 -> 0 | J12: ='Team Hub'!U237 -> 1 | K12: ='Team Hub'!V238 -> 306 | L12: ='Team Hub'!S238 -> 15
C13: i-1 | D13: Arcadia | H13: ='Team Hub'!F206 -> 5 | I13: ='Team Hub'!H206 -> 0 | J13: ='Team Hub'!G206 -> 1 | K13: ='Team Hub'!H207 -> 222 | L13: ='Team Hub'!E207 -> 15
C14: w-3 | D14: Frazer | H14: ='Team Hub'!T299 -> 4 | I14: ='Team Hub'!V299 -> 0 | J14: ='Team Hub'!U299 -> 2 | K14: ='Team Hub'!V300 -> 274 | L14: ='Team Hub'!S300 -> 12
C15: f-2 | D15: Mission San Jose | H15: ='Team Hub'!M144 -> 4 | I15: ='Team Hub'!O144 -> 0 | J15: ='Team Hub'!N144 -> 2 | K15: ='Team Hub'!O145 -> 202 | L15: ='Team Hub'!L145 -> 12
C16: a-2 | D16: Palo Alto | H16: ='Team Hub'!M20 -> 4 | I16: ='Team Hub'!O20 -> 0 | J16: ='Team Hub'!N20 -> 2 | K16: ='Team Hub'!O21 -> -60 | L16: ='Team Hub'!L21 -> 12
C17: e-3 | D17: Mira Loma | H17: ='Team Hub'!T113 -> 3 | I17: ='Team Hub'!V113 -> 0 | J17: ='Team Hub'!U113 -> 3 | K17: ='Team Hub'!V114 -> 292 | L17: ='Team Hub'!S114 -> 9
C18: w-1 | D18: ASFA | H18: ='Team Hub'!F299 -> 3 | I18: ='Team Hub'!H299 -> 0 | J18: ='Team Hub'!G299 -> 3 | K18: ='Team Hub'!H300 -> 220 | L18: ='Team Hub'!E300 -> 9
C19: p-2 | D19: Saratoga | H19: ='Team Hub'!M237 -> 3 | I19: ='Team Hub'!O237 -> 0 | J19: ='Team Hub'!N237 -> 3 | K19: ='Team Hub'!O238 -> 108 | L19: ='Team Hub'!L238 -> 9
C20: i-2 | D20: University | H20: ='Team Hub'!M206 -> 3 | I20: ='Team Hub'!O206 -> 0 | J20: ='Team Hub'!N206 -> 3 | K20: ='Team Hub'!O207 -> 96 | L20: ='Team Hub'!L207 -> 9
C21: i-3 | D21: Foothill | H21: ='Team Hub'!T206 -> 3 | I21: ='Team Hub'!V206 -> 0 | J21: ='Team Hub'!U206 -> 3 | K21: ='Team Hub'!V207 -> 14 | L21: ='Team Hub'!S207 -> 9
C22: f-1 | D22: Lakeside | H22: ='Team Hub'!F144 -> 3 | I22: ='Team Hub'!H144 -> 0 | J22: ='Team Hub'!G144 -> 3 | K22: ='Team Hub'!H145 -> -8 | L22: ='Team Hub'!E145 -> 9
C23: e-1 | D23: Wayzata | H23: ='Team Hub'!F113 -> 3 | I23: ='Team Hub'!H113 -> 0 | J23: ='Team Hub'!G113 -> 3 | K23: ='Team Hub'!H114 -> -10 | L23: ='Team Hub'!E114 -> 9
C24: d-3 | D24: WWPS | H24: ='Team Hub'!T82 -> 3 | I24: ='Team Hub'!V82 -> 0 | J24: ='Team Hub'!U82 -> 3 | K24: ='Team Hub'!V83 -> -136 | L24: ='Team Hub'!S83 -> 9
C25: h-3 | D25: Stuyvesant | H25: ='Team Hub'!T175 -> 3 | I25: ='Team Hub'!V175 -> 0 | J25: ='Team Hub'!U175 -> 3 | K25: ='Team Hub'!V176 -> -352 | L25: ='Team Hub'!S176 -> 9
C26: f-3 | D26: PRISMS | H26: ='Team Hub'!T144 -> 2 | I26: ='Team Hub'!V144 -> 0 | J26: ='Team Hub'!U144 -> 4 | K26: ='Team Hub'!V145 -> -122 | L26: ='Team Hub'!S145 -> 6
C27: d-1 | D27: OCSA | H27: ='Team Hub'!F82 -> 2 | I27: ='Team Hub'!H82 -> 0 | J27: ='Team Hub'!G82 -> 4 | K27: ='Team Hub'!H83 -> -336 | L27: ='Team Hub'!E83 -> 6
C28: e-2 | D28: Dulles | H28: ='Team Hub'!M113 -> 1 | I28: ='Team Hub'!O113 -> 0 | J28: ='Team Hub'!N113 -> 5 | K28: ='Team Hub'!O114 -> -90 | L28: ='Team Hub'!L114 -> 3
C29: h-2 | D29: Clements | H29: ='Team Hub'!M175 -> 1 | I29: ='Team Hub'!O175 -> 0 | J29: ='Team Hub'!N175 -> 5 | K29: ='Team Hub'!O176 -> -216 | L29: ='Team Hub'!L176 -> 3
C30: a-1 | D30: Hunter | H30: ='Team Hub'!F20 -> 1 | I30: ='Team Hub'!H20 -> 0 | J30: ='Team Hub'!G20 -> 5 | K30: ='Team Hub'!H21 -> -334 | L30: ='Team Hub'!E21 -> 3
C31: s-2 | D31: Winston Churchill | H31: ='Team Hub'!M268 -> 1 | I31: ='Team Hub'!O268 -> 0 | J31: ='Team Hub'!N268 -> 5 | K31: ='Team Hub'!O269 -> -708 | L31: ='Team Hub'!L269 -> 3
C32: a-3 | D32: Middleton | H32: ='Team Hub'!T20 -> 1 | I32: ='Team Hub'!V20 -> 0 | J32: ='Team Hub'!U20 -> 5 | K32: ='Team Hub'!V21 -> -816 | L32: ='Team Hub'!S21 -> 3
C33: c-1 | D33: Lexington | H33: ='Team Hub'!F51 -> 0 | I33: ='Team Hub'!H51 -> 0 | J33: ='Team Hub'!G51 -> 6 | K33: ='Team Hub'!H52 -> -522 | L33: ='Team Hub'!E52 -> 0
C34: c-3 | D34: Tokay | H34: ='Team Hub'!T51 -> 0 | I34: ='Team Hub'!V51 -> 0 | J34: ='Team Hub'!U51 -> 6 | K34: ='Team Hub'!V52 -> -820 | L34: ='Team Hub'!S52 -> 0
C35: w-2 | D35: JP Stevens | H35: ='Team Hub'!M299 -> 0 | I35: ='Team Hub'!O299 -> 0 | J35: ='Team Hub'!N299 -> 6 | K35: ='Team Hub'!O300 -> -822 | L35: ='Team Hub'!L300 -> 0

Sheet Playoff Groups
B2: Playoff Groups
B3: yay playoff groups
D6: albatross | G6: starlight | J6: champagne
C7: 1 | D7: Amador Valley | F7: 1 | G7: Ward Melville | I7: 1 | J7: Palo Alto
C8: 2 | D8: Lynbrook | F8: 2 | G8: Blair | I8: 2 | J8: Mira Loma
C9: 3 | D9: Interlake | F9: 3 | G9: Arcadia | I9: 3 | J9: ASFA
C10: 4 | D10: TJHSST | F10: 4 | G10: Frazer | I10: 4 | J10: Saratoga
C11: 5 | D11: Canyon Crest | F11: 5 | G11: Mission San Jose | I11: 5 | J11: University
D13: daylight | G13: exile | J13: fiction
C14: 1 | D14: Foothill | F14: 1 | G14: PRISMS | I14: 1 | J14: Churchill
C15: 2 | D15: Lakeside | F15: 2 | G15: OCSA | I15: 2 | J15: Middleton
C16: 3 | D16: Wayzata | F16: 3 | G16: Dulles | I16: 3 | J16: Lexington
C17: 4 | D17: WWPS | F17: 4 | G17: Clements | I17: 4 | J17: Tokay
C18: 5 | D18: Stuyvesant | F18: 5 | G18: Hunter | I18: 5 | J18: JP Stevens

Sheet Playoff Scoring
B2: Playoff Scoring
B3: team scores are summed over a row, opponents' scores summed over a column
C6: albatross | K6: starlight
C7: =sum(D8:H12) -> 1896 | D7: =C8 -> Amador Valley | E7: =C9 -> Lynbrook | F7: =C10 -> Interlake | G7: =C11 -> TJHSST | H7: =C12 -> Canyon Crest | I7: Total | K7: =sum(L8:P12) -> 1474 | L7: =K8 -> Ward Melville | M7: =K9 -> Blair | N7: =K10 -> Arcadia | O7: =K11 -> Frazer | P7: =K12 -> MSJ | Q7: Total
C8: ='Playoff Groups'!D7 -> Amador Valley | E8: 88 | F8: 124 | G8: 110 | H8: 84 | I8: =sum(D8:H8) -> 406 | K8: ='Playoff Groups'!G7 -> Ward Melville | M8: 18 | N8: 110 | O8: 58 | P8: 92 | Q8: =sum(L8:P8) -> 278
C9: ='Playoff Groups'!D8 -> Lynbrook | D9: 154 | F9: 72 | G9: 120 | H9: 144 | I9: =sum(D9:H9) -> 490 | K9: ='Playoff Groups'!G8 -> Blair | L9: 116 | N9: 32 | O9: 48 | P9: 54 | Q9: =sum(L9:P9) -> 250
C10: ='Playoff Groups'!D9 -> Interlake | D10: 130 | E10: 82 | G10: 98 | H10: 96 | I10: =sum(D10:H10) -> 406 | K10: ='Playoff Groups'!G9 -> Arcadia | L10: 80 | M10: 34 | O10: -6 | P10: 26 | Q10: =sum(L10:P10) -> 134
C11: ='Playoff Groups'!D10 -> TJHSST | D11: 34 | E11: 70 | F11: 106 | H11: 76 | I11: =sum(D11:H11) -> 286 | K11: ='Playoff Groups'!G10 -> Frazer | L11: 144 | M11: 74 | N11: 160 | P11: 114 | Q11: =sum(L11:P11) -> 492
C12: ='Playoff Groups'!D11 -> Canyon Crest | D12: 82 | E12: 74 | F12: 78 | G12: 74 | I12: =sum(D12:H12) -> 308 | K12: MSJ | L12: 86 | M12: 82 | N12: 98 | O12: 54 | Q12: =sum(L12:P12) -> 320
C13: Against | D13: =sum(D8:D12) -> 400 | E13: =sum(E8:E12) -> 314 | F13: =sum(F8:F12) -> 380 | G13: =sum(G8:G12) -> 402 | H13: =sum(H8:H12) -> 400 | K13: Against | L13: =sum(L8:L12) -> 426 | M13: =sum(M8:M12) -> 208 | N13: =sum(N8:N12) -> 400 | O13: =sum(O8:O12) -> 154 | P13: =sum(P8:P12) -> 286
C15: champagne | K15: daylight
C16: =sum(D17:H21) -> 1648 | D16: =C17 -> Palo Alto | E16: =C18 -> Mira Loma | F16: =C19 -> ASFA | G16: =C20 -> Saratoga | H16: =C21 -> University | I16: Total | K16: =sum(L17:P21) -> 1394 | L16: =K17 -> Foothill | M16: =K18 -> Lakeside | N16: =K19 -> Wayzata | O16: =K20 -> WWPS | P16: =K21 -> Stuyvesant | Q16: Total
C17: ='Playoff Groups'!J7 -> Palo Alto | E17: 94 | F17: 58 | G17: 58 | H17: 88 | I17: =sum(D17:H17) -> 298 | K17: ='Playoff Groups'!D14 -> Foothill | M17: 42 | N17: 64 | O17: 22 | P17: 42 | Q17: =sum(L17:P17) -> 170
C18: ='Playoff Groups'!J8 -> Mira Loma | D18: 108 | F18: 42 | G18: 102 | H18: 96 | I18: =sum(D18:H18) -> 348 | K18: ='Playoff Groups'!D15 -> Lakeside | L18: 82 | N18: 78 | O18: 58 | P18: 50 | Q18: =sum(L18:P18) -> 268
C19: ='Playoff Groups'!J9 -> ASFA | D19: 78 | E19: 124 | G19: 70 | H19: 24 | I19: =sum(D19:H19) -> 296 | K19: ='Playoff Groups'!D16 -> Wayzata | L19: 88 | M19: 66 | O19: 92 | P19: 50 | Q19: =sum(L19:P19) -> 296
C20: ='Playoff Groups'!J10 -> Saratoga | D20: 130 | E20: 42 | F20: 102 | H20: 94 | I20: =sum(D20:H20) -> 368 | K20: ='Playoff Groups'!D17 -> WWPS | L20: 106 | M20: 78 | N20: 80 | P20: 102 | Q20: =sum(L20:P20) -> 366
C21: ='Playoff Groups'!J11 -> University | D21: 100 | E21: 24 | F21: 102 | G21: 112 | I21: =sum(D21:H21) -> 338 | K21: ='Playoff Groups'!D18 -> Stuyvesant | L21: 106 | M21: 96 | N21: 44 | O21: 48 | Q21: =sum(L21:P21) -> 294
C22: Against | D22: =sum(D17:D21) -> 416 | E22: =sum(E17:E21) -> 284 | F22: =sum(F17:F21) -> 304 | G22: =sum(G17:G21) -> 342 | H22: =sum(H17:H21) -> 302 | K22: Against | L22: =sum(L17:L21) -> 382 | M22: =sum(M17:M21) -> 282 | N22: =sum(N17:N21) -> 266 | O22: =sum(O17:O21) -> 220 | P22: =sum(P17:P21) -> 244
C24: exile | K24: fiction
C25: =sum(D26:H30) -> 1296 | D25: =C26 -> PRISMS | E25: =C27 -> OCSA | F25: =C28 -> Dulles | G25: =C29 -> Clements | H25: =C30 -> Hunter | I25: Total | K25: =sum(L26:P30) -> 558 | L25: =K26 -> Churchill | M25: =K27 -> Middleton | N25: =K28 -> Lexington | O25: =K29 -> Tokay | P25: =K30 -> JP Stevens | Q25: Total
C26: ='Playoff Groups'!G14 -> PRISMS | E26: 114 | F26: 94 | G26: 98 | H26: 58 | I26: =sum(D26:H26) -> 364 | K26: ='Playoff Groups'!J14 -> Churchill | M26: 26 | N26: 30 | O26: 0 | P26: 36 | Q26: =sum(L26:P26) -> 92
C27: ='Playoff Groups'!G15 -> OCSA | D27: 10 | F27: 34 | G27: 58 | H27: 36 | I27: =sum(D27:H27) -> 138 | K27: ='Playoff Groups'!J15 -> Middleton | L27: 40 | N27: 52 | O27: 16 | P27: 36 | Q27: =sum(L27:P27) -> 144
C28: ='Playoff Groups'!G16 -> Dulles | D28: 78 | E28: 24 | G28: 56 | H28: 42 | I28: =sum(D28:H28) -> 200 | K28: ='Playoff Groups'!J16 -> Lexington | L28: 40 | M28: 14 | O28: 68 | P28: 48 | Q28: =sum(L28:P28) -> 170
C29: ='Playoff Groups'!G17 -> Clements | D29: 86 | E29: 34 | F29: 78 | H29: 130 | I29: =sum(D29:H29) -> 328 | K29: ='Playoff Groups'!J17 -> Tokay | L29: 0 | M29: 0 | N29: 8 | P29: 0 | Q29: =sum(L29:P29) -> 8
C30: ='Playoff Groups'!G18 -> Hunter | D30: 42 | E30: 102 | F30: 72 | G30: 50 | I30: =sum(D30:H30) -> 266 | K30: ='Playoff Groups'!J18 -> JP Stevens | L30: 30 | M30: 64 | N30: 18 | O30: 32 | Q30: =sum(L30:P30) -> 144
C31: Against | D31: =sum(D26:D30) -> 216 | E31: =sum(E26:E30) -> 274 | F31: =sum(F26:F30) -> 278 | G31: =sum(G26:G30) -> 262 | H31: =sum(H26:H30) -> 266 | K31: Against | L31: =sum(L26:L30) -> 110 | M31: =sum(M26:M30) -> 104 | N31: =sum(N26:N30) -> 108 | O31: =sum(O26:O30) -> 116 | P31: =sum(P26:P30) -> 120

Sheet Final Tournament Table
B2: Final Tournament Table
B3: teams are ranked by league points, point difference, then median-buchholz scale
D5: School Name | H5: Wins | I5: Ties | J5: Losses | K5: Point Difference | L5: League Points
C6: p-1 | D6: Lynbrook | H6: ='Team Hub'!F251 -> 9 | I6: 0 | J6: ='Team Hub'!G251 -> 1 | K6: ='Team Hub'!H252 -> 918 | L6: ='Team Hub'!E252-1 -> 24
C7: h-1 | D7: Amador Valley | H7: ='Team Hub'!F189 -> 8 | I7: 0 | J7: ='Team Hub'!G189 -> 2 | K7: ='Team Hub'!H190 -> 818 | L7: ='Team Hub'!E190-1 -> 22
C8: s-1 | D8: Interlake | H8: ='Team Hub'!F282 -> 8 | I8: 0 | J8: ='Team Hub'!G282 -> 2 | K8: ='Team Hub'!H283 -> 628 | L8: ='Team Hub'!E283-1 -> 21
C9: w-3 | D9: Frazer | H9: ='Team Hub'!T313 -> 8 | I9: 0 | J9: ='Team Hub'!U313 -> 2 | K9: ='Team Hub'!V314 -> 612 | L9: ='Team Hub'!S314-1 -> 20
C10: s-3 | D10: TJHSST | H10: ='Team Hub'!T282 -> 7 | I10: 0 | J10: ='Team Hub'!U282 -> 3 | K10: ='Team Hub'!V283 -> 456 | L10: ='Team Hub'!S283-1 -> 19
C11: c-2 | D11: Ward Melville | H11: ='Team Hub'!M65 -> 7 | I11: 0 | J11: ='Team Hub'!N65 -> 3 | K11: ='Team Hub'!O66 -> 230 | L11: ='Team Hub'!L66-1 -> 19
C12: p-3 | D12: Blair | H12: ='Team Hub'!T251 -> 6 | I12: 0 | J12: ='Team Hub'!U251 -> 4 | K12: ='Team Hub'!V252 -> 348 | L12: ='Team Hub'!S252-1 -> 17
C13: i-1 | D13: Arcadia | H13: ='Team Hub'!F220 -> 6 | I13: 0 | J13: ='Team Hub'!G220 -> 4 | K13: ='Team Hub'!H221 -> -44 | L13: ='Team Hub'!E221-1 -> 17
C14: f-2 | D14: Mission San Jose | H14: ='Team Hub'!M158 -> 6 | I14: 0 | J14: ='Team Hub'!N158 -> 4 | K14: ='Team Hub'!O159 -> 236 | L14: ='Team Hub'!L159-1 -> 16
C15: e-3 | D15: Mira Loma | H15: ='Team Hub'!T127 -> 6 | I15: 0 | J15: ='Team Hub'!U127 -> 4 | K15: ='Team Hub'!V128 -> 356 | L15: ='Team Hub'!S128-1 -> 15
C16: d-2 | D16: Canyon Crest | H16: ='Team Hub'!M96 -> 5 | I16: 0 | J16: ='Team Hub'!N96 -> 5 | K16: ='Team Hub'!O97 -> 336 | L16: ='Team Hub'!L97-1 -> 15
C17: i-2 | D17: University | H17: ='Team Hub'!M220 -> 6 | I17: 0 | J17: ='Team Hub'!N220 -> 4 | K17: ='Team Hub'!O221 -> 132 | L17: ='Team Hub'!L221-1 -> 15
C18: e-1 | D18: Wayzata | H18: ='Team Hub'!F127 -> 6 | I18: 0 | J18: ='Team Hub'!G127 -> 4 | K18: ='Team Hub'!H128 -> 100 | L18: ='Team Hub'!E128-1 -> 15
C19: d-3 | D19: WWPS | H19: ='Team Hub'!T96 -> 6 | I19: 0 | J19: ='Team Hub'!U96 -> 4 | K19: ='Team Hub'!V97 -> 10 | L19: ='Team Hub'!S97-1 -> 15
C20: f-3 | D20: PRISMS | H20: ='Team Hub'!T158 -> 6 | I20: 0 | J20: ='Team Hub'!U158 -> 4 | K20: ='Team Hub'!V159 -> 26 | L20: ='Team Hub'!S159-1 -> 14
C21: w-1 | D21: ASFA | H21: ='Team Hub'!F313 -> 5 | I21: 0 | J21: ='Team Hub'!G313 -> 5 | K21: ='Team Hub'!H314 -> 212 | L21: ='Team Hub'!E314-1 -> 13
C22: p-2 | D22: Saratoga | H22: ='Team Hub'!M251 -> 5 | I22: 0 | J22: ='Team Hub'!N251 -> 5 | K22: ='Team Hub'!O252 -> 134 | L22: ='Team Hub'!L252-1 -> 13
C23: f-1 | D23: Lakeside | H23: ='Team Hub'!F158 -> 5 | I23: 0 | J23: ='Team Hub'!G158 -> 5 | K23: ='Team Hub'!H159 -> -22 | L23: ='Team Hub'!E159-1 -> 13
C24: h-3 | D24: Stuyvesant | H24: ='Team Hub'!T189 -> 5 | I24: 0 | J24: ='Team Hub'!U189 -> 5 | K24: ='Team Hub'!V190 -> -302 | L24: ='Team Hub'!S190-1 -> 13
C25: a-2 | D25: Palo Alto | H25: ='Team Hub'!M34 -> 4 | I25: 0 | J25: ='Team Hub'!N34 -> 6 | K25: ='Team Hub'!O35 -> -178 | L25: ='Team Hub'!L35-1 -> 12
C26: d-1 | D26: OCSA | H26: ='Team Hub'!F96 -> 4 | I26: 0 | J26: ='Team Hub'!G96 -> 6 | K26: ='Team Hub'!H97 -> -472 | L26: ='Team Hub'!E97-1 -> 10
C27: i-3 | D27: Foothill | H27: ='Team Hub'!T220 -> 3 | I27: 0 | J27: ='Team Hub'!U220 -> 7 | K27: ='Team Hub'!V221 -> -198 | L27: ='Team Hub'!S221-1 -> 9
C28: a-3 | D28: Middleton | H28: ='Team Hub'!T34 -> 4 | I28: 0 | J28: ='Team Hub'!U34 -> 6 | K28: ='Team Hub'!V35 -> -776 | L28: ='Team Hub'!S35-1 -> 9
C29: h-2 | D29: Clements | H29: ='Team Hub'!M189 -> 3 | I29: 0 | J29: ='Team Hub'!N189 -> 7 | K29: ='Team Hub'!O190 -> -150 | L29: ='Team Hub'!L190-1 -> 7
C30: a-1 | D30: Hunter | H30: ='Team Hub'!F34 -> 3 | I30: 0 | J30: ='Team Hub'!G34 -> 7 | K30: ='Team Hub'!H35 -> -334 | L30: ='Team Hub'!E35-1 -> 7
C31: c-1 | D31: Lexington | H31: ='Team Hub'!F65 -> 3 | I31: 0 | J31: ='Team Hub'!G65 -> 7 | K31: ='Team Hub'!H66 -> -460 | L31: ='Team Hub'!E66-1 -> 6
C32: s-2 | D32: Winston Churchill | H32: ='Team Hub'!M282 -> 2 | I32: 1 | J32: ='Team Hub'!N282 -> 7 | K32: ='Team Hub'!O283 -> -726 | L32: ='Team Hub'!L283-1 -> 6
C33: w-2 | D33: JP Stevens | H33: ='Team Hub'!M313 -> 2 | I33: 0 | J33: ='Team Hub'!N313 -> 8 | K33: ='Team Hub'!O314 -> -798 | L33: ='Team Hub'!L314-1 -> 4
C34: e-2 | D34: Dulles | H34: ='Team Hub'!M127 -> 1 | I34: 0 | J34: ='Team Hub'!N127 -> 9 | K34: ='Team Hub'!O128 -> -168 | L34: ='Team Hub'!L128-1 -> 3
C35: c-3 | D35: Tokay | H35: ='Team Hub'!T65 -> 0 | I35: 1 | J35: ='Team Hub'!U65 -> 9 | K35: ='Team Hub'!V66 -> -928 | L35: ='Team Hub'!S66-1 -> 1

Sheet Playoff Seeding
B1: Team Rank | C1: Team Name | D1: League Points | E1: Raw Points | G1: Round Scores (in no particular order)
B2: 10 | C2: WWPS 1 | D2: 8 | E2: =sum(G2:M2) -> 572 | G2: ='Playoff Scoring'!D11 -> 34 | H2: ='Playoff Scoring'!E11 -> 70 | I2: ='Playoff Scoring'!F11 -> 106 | J2: ='Playoff Scoring'!H11 -> 76 | K2: ='Playoff Scoring'!I11 -> 286
B3: 15 | C3: Palo Alto | D3: 6 | E3: =sum(G3:M3) -> 980 | G3: ='Playoff Scoring'!D9 -> 154 | H3: ='Playoff Scoring'!F9 -> 72 | I3: ='Playoff Scoring'!G9 -> 120 | J3: ='Playoff Scoring'!H9 -> 144 | K3: ='Playoff Scoring'!I9 -> 490
B4: 18 | C4: Saratoga | D4: 6 | E4: =sum(G4:M4) -> 616 | G4: ='Playoff Scoring'!D12 -> 82 | H4: ='Playoff Scoring'!E12 -> 74 | I4: ='Playoff Scoring'!F12 -> 78 | J4: ='Playoff Scoring'!G12 -> 74 | K4: ='Playoff Scoring'!I12 -> 308
B5: 21 | C5: CCA 2 | D5: 6 | E5: =sum(G5:M5) -> 1896 | G5: ='Playoff Scoring'!D13 -> 400 | H5: ='Playoff Scoring'!E13 -> 314 | I5: ='Playoff Scoring'!F13 -> 380 | J5: ='Playoff Scoring'!G13 -> 402 | K5: ='Playoff Scoring'!H13 -> 400
B6: 30 | C6: Clovis North | D6: 4 | E6: =sum(G6:M6) -> 812 | G6: ='Playoff Scoring'!$E8 -> 88 | H6: ='Playoff Scoring'!F8 -> 124 | I6: ='Playoff Scoring'!G8 -> 110 | J6: ='Playoff Scoring'!H8 -> 84 | K6: ='Playoff Scoring'!I8 -> 406
B7: 44 | C7: Tokay | D7: 0 | E7: =sum(G7:M7) -> 812 | G7: ='Playoff Scoring'!D10 -> 130 | H7: ='Playoff Scoring'!E10 -> 82 | I7: ='Playoff Scoring'!G10 -> 98 | J7: ='Playoff Scoring'!H10 -> 96 | K7: ='Playoff Scoring'!I10 -> 406
B8: 3 | C8: Middleton 1 | D8: 10 | E8: =sum(G8:M8) -> 268 | G8: ='Playoff Scoring'!L10 -> 80 | H8: ='Playoff Scoring'!M10 -> 34 | I8: ='Playoff Scoring'!O10 -> -6 | J8: ='Playoff Scoring'!P10 -> 26 | K8: ='Playoff Scoring'!Q10 -> 134
B9: 11 | C9: TJHSST 1 | D9: 8 | E9: =sum(G9:M9) -> 640 | G9: ='Playoff Scoring'!L12 -> 86 | H9: ='Playoff Scoring'!M12 -> 82 | I9: ='Playoff Scoring'!N12 -> 98 | J9: ='Playoff Scoring'!O12 -> 54 | K9: ='Playoff Scoring'!Q12 -> 320
B10: 22 | C10: ASFA | D10: 6 | E10: =sum(G10:M10) -> 500 | G10: ='Playoff Scoring'!L9 -> 116 | H10: ='Playoff Scoring'!N9 -> 32 | I10: ='Playoff Scoring'!O9 -> 48 | J10: ='Playoff Scoring'!P9 -> 54 | K10: ='Playoff Scoring'!Q9 -> 250
B11: 34 | C11: California | D11: 4 | E11: =sum(G11:M11) -> 556 | G11: ='Playoff Scoring'!M8 -> 18 | H11: ='Playoff Scoring'!N8 -> 110 | I11: ='Playoff Scoring'!O8 -> 58 | J11: ='Playoff Scoring'!P8 -> 92 | K11: ='Playoff Scoring'!Q8 -> 278
B12: 37 | C12: Collierville 1 | D12: 2 | E12: =sum(G12:M12) -> 984 | G12: ='Playoff Scoring'!L11 -> 144 | H12: ='Playoff Scoring'!M11 -> 74 | I12: ='Playoff Scoring'!N11 -> 160 | J12: ='Playoff Scoring'!P11 -> 114 | K12: ='Playoff Scoring'!Q11 -> 492
B13: 46 | C13: Madison West 2 | D13: 0 | E13: =sum(G13:M13) -> 1474 | G13: ='Playoff Scoring'!L13 -> 426 | H13: ='Playoff Scoring'!M13 -> 208 | I13: ='Playoff Scoring'!N13 -> 400 | J13: ='Playoff Scoring'!O13 -> 154 | K13: ='Playoff Scoring'!P13 -> 286
B14: 1 | C14: Montgomery Blair 1 | D14: 10 | E14: =sum(G14:M14) -> 1648 | G14: ='Playoff Scoring'!D22 -> 416 | H14: ='Playoff Scoring'!E22 -> 284 | I14: ='Playoff Scoring'!F22 -> 304 | J14: ='Playoff Scoring'!G22 -> 342 | K14: ='Playoff Scoring'!H22 -> 302
B15: 19 | C15: Arcadia | D15: 6 | E15: =sum(G15:M15) -> 736 | G15: ='Playoff Scoring'!D20 -> 130 | H15: ='Playoff Scoring'!E20 -> 42 | I15: ='Playoff Scoring'!F20 -> 102 | J15: ='Playoff Scoring'!H20 -> 94 | K15: ='Playoff Scoring'!I20 -> 368
B16: 23 | C16: 'Iolani | D16: 6 | E16: =sum(G16:M16) -> 596 | G16: ='Playoff Scoring'!$E17 -> 94 | H16: ='Playoff Scoring'!F17 -> 58 | I16: ='Playoff Scoring'!G17 -> 58 | J16: ='Playoff Scoring'!H17 -> 88 | K16: ='Playoff Scoring'!I17 -> 298
B17: 24 | C17: Temple City | D17: 6 | E17: =sum(G17:M17) -> 676 | G17: ='Playoff Scoring'!D21 -> 100 | H17: ='Playoff Scoring'!E21 -> 24 | I17: ='Playoff Scoring'!F21 -> 102 | J17: ='Playoff Scoring'!G21 -> 112 | K17: ='Playoff Scoring'!I21 -> 338
B18: 39 | C18: Amador Valley | D18: 2 | E18: =sum(G18:M18) -> 592 | G18: ='Playoff Scoring'!D19 -> 78 | H18: ='Playoff Scoring'!E19 -> 124 | I18: ='Playoff Scoring'!G19 -> 70 | J18: ='Playoff Scoring'!H19 -> 24 | K18: ='Playoff Scoring'!I19 -> 296
B19: 48 | C19: Oak Avenue 2 | D19: 0 | E19: =sum(G19:M19) -> 696 | G19: ='Playoff Scoring'!D18 -> 108 | H19: ='Playoff Scoring'!F18 -> 42 | I19: ='Playoff Scoring'!G18 -> 102 | J19: ='Playoff Scoring'!H18 -> 96 | K19: ='Playoff Scoring'!I18 -> 348
B20: 6 | C20: Lynbrook 1 | D20: 10 | E20: =sum(G20:M20) -> 536 | G20: ='Playoff Scoring'!L18 -> 82 | H20: ='Playoff Scoring'!N18 -> 78 | I20: ='Playoff Scoring'!O18 -> 58 | J20: ='Playoff Scoring'!P18 -> 50 | K20: ='Playoff Scoring'!Q18 -> 268
B21: 12 | C21: Foothill | D21: 8 | E21: =sum(G21:M21) -> 1394 | G21: ='Playoff Scoring'!L22 -> 382 | H21: ='Playoff Scoring'!M22 -> 282 | I21: ='Playoff Scoring'!N22 -> 266 | J21: ='Playoff Scoring'!O22 -> 220 | K21: ='Playoff Scoring'!P22 -> 244
B22: 25 | C22: Whitney Young | D22: 6 | E22: =sum(G22:M22) -> 732 | G22: ='Playoff Scoring'!L20 -> 106 | H22: ='Playoff Scoring'!M20 -> 78 | I22: ='Playoff Scoring'!N20 -> 80 | J22: ='Playoff Scoring'!P20 -> 102 | K22: ='Playoff Scoring'!Q20 -> 366
B23: 31 | C23: Centennial | D23: 4 | E23: =sum(G23:M23) -> 588 | G23: ='Playoff Scoring'!L21 -> 106 | H23: ='Playoff Scoring'!M21 -> 96 | I23: ='Playoff Scoring'!N21 -> 44 | J23: ='Playoff Scoring'!O21 -> 48 | K23: ='Playoff Scoring'!Q21 -> 294
B24: 38 | C24: Middleton 2 | D24: 2 | E24: =sum(G24:M24) -> 340 | G24: ='Playoff Scoring'!M17 -> 42 | H24: ='Playoff Scoring'!N17 -> 64 | I24: ='Playoff Scoring'!O17 -> 22 | J24: ='Playoff Scoring'!P17 -> 42 | K24: ='Playoff Scoring'!Q17 -> 170
B25: 47 | C25: Collierville 2 | D25: 0 | E25: =sum(G25:M25) -> 592 | G25: ='Playoff Scoring'!L19 -> 88 | H25: ='Playoff Scoring'!M19 -> 66 | I25: ='Playoff Scoring'!O19 -> 92 | J25: ='Playoff Scoring'!P19 -> 50 | K25: ='Playoff Scoring'!Q19 -> 296
B26: 7 | C26: MSJ 1 | D26: 8 | E26: =sum(G26:M26) -> 656 | G26: ='Playoff Scoring'!D29 -> 86 | H26: ='Playoff Scoring'!E29 -> 34 | I26: ='Playoff Scoring'!F29 -> 78 | J26: ='Playoff Scoring'!H29 -> 130 | K26: ='Playoff Scoring'!I29 -> 328
B27: 14 | C27: Lynbrook 2 | D27: 8 | E27: =sum(G27:M27) -> 276 | G27: ='Playoff Scoring'!D27 -> 10 | H27: ='Playoff Scoring'!F27 -> 34 | I27: ='Playoff Scoring'!G27 -> 58 | J27: ='Playoff Scoring'!H27 -> 36 | K27: ='Playoff Scoring'!I27 -> 138
B28: 20 | C28: Princeton Unified | D28: 6 | E28: =sum(G28:M28) -> 532 | G28: ='Playoff Scoring'!D30 -> 42 | H28: ='Playoff Scoring'!E30 -> 102 | I28: ='Playoff Scoring'!F30 -> 72 | J28: ='Playoff Scoring'!G30 -> 50 | K28: ='Playoff Scoring'!I30 -> 266
B29: 27 | C29: Frazer 1 | D29: 4 | E29: =sum(G29:M29) -> 400 | G29: ='Playoff Scoring'!D28 -> 78 | H29: ='Playoff Scoring'!E28 -> 24 | I29: ='Playoff Scoring'!G28 -> 56 | J29: ='Playoff Scoring'!H28 -> 42 | K29: ='Playoff Scoring'!I28 -> 200
B30: 32 | C30: Montgomery Blair 2 | D30: 4 | E30: =sum(G30:M30) -> 1296 | G30: ='Playoff Scoring'!D31 -> 216 | H30: ='Playoff Scoring'!E31 -> 274 | I30: ='Playoff Scoring'!F31 -> 278 | J30: ='Playoff Scoring'!G31 -> 262 | K30: ='Playoff Scoring'!H31 -> 266
B31: 42 | C31: Stuyvesant | D31: 0 | E31: =sum(G31:M31) -> 728 | G31: ='Playoff Scoring'!$E26 -> 114 | H31: ='Playoff Scoring'!F26 -> 94 | I31: ='Playoff Scoring'!G26 -> 98 | J31: ='Playoff Scoring'!H26 -> 58 | K31: ='Playoff Scoring'!I26 -> 364
B32: 4 | C32: Wayzata | D32: 10 | E32: =sum(G32:M32) -> 340 | G32: ='Playoff Scoring'!L28 -> 40 | H32: ='Playoff Scoring'!M28 -> 14 | I32: ='Playoff Scoring'!O28 -> 68 | J32: ='Playoff Scoring'!P28 -> 48 | K32: ='Playoff Scoring'!Q28 -> 170
B33: 9 | C33: CCA 1 | D33: 8 | E33: =sum(G33:M33) -> 184 | G33: ='Playoff Scoring'!M26 -> 26 | H33: ='Playoff Scoring'!N26 -> 30 | I33: ='Playoff Scoring'!O26 -> 0 | J33: ='Playoff Scoring'!P26 -> 36 | K33: ='Playoff Scoring'!Q26 -> 92
B34: 28 | C34: Granada Hills | D34: 4 | E34: =sum(G34:M34) -> 558 | G34: ='Playoff Scoring'!L31 -> 110 | H34: ='Playoff Scoring'!M31 -> 104 | I34: ='Playoff Scoring'!N31 -> 108 | J34: ='Playoff Scoring'!O31 -> 116 | K34: ='Playoff Scoring'!P31 -> 120
B35: 29 | C35: Harvard Westlake | D35: 4 | E35: =sum(G35:M35) -> 16 | G35: ='Playoff Scoring'!L29 -> 0 | H35: ='Playoff Scoring'!M29 -> 0 | I35: ='Playoff Scoring'!N29 -> 8 | J35: ='Playoff Scoring'!P29 -> 0 | K35: ='Playoff Scoring'!Q29 -> 8
B36: 35 | C36: Frazer 2 | D36: 2 | E36: =sum(G36:M36) -> 288 | G36: ='Playoff Scoring'!L27 -> 40 | H36: ='Playoff Scoring'!N27 -> 52 | I36: ='Playoff Scoring'!O27 -> 16 | J36: ='Playoff Scoring'!P27 -> 36 | K36: ='Playoff Scoring'!Q27 -> 144
B37: 40 | C37: Hunter College | D37: 2 | E37: =sum(G37:M37) -> 288 | G37: ='Playoff Scoring'!L30 -> 30 | H37: ='Playoff Scoring'!M30 -> 64 | I37: ='Playoff Scoring'!N30 -> 18 | J37: ='Playoff Scoring'!O30 -> 32 | K37: ='Playoff Scoring'!Q30 -> 144
B38: 2 | C38: Clements | D38: 10 | E38: =sum(G38:M38) -> #REF! | G38: =#REF! -> #REF! | H38: =#REF! -> #REF! | I38: =#REF! -> #REF! | J38: =#REF! -> #REF! | K38: =#REF! -> #REF!
B39: 13 | C39: MSJ 2 | D39: 8 | E39: =sum(G39:M39) -> #REF! | G39: =#REF! -> #REF! | H39: =#REF! -> #REF! | I39: =#REF! -> #REF! | J39: =#REF! -> #REF! | K39: =#REF! -> #REF!
B40: 17 | C40: WWPN | D40: 6 | E40: =sum(G40:M40) -> #REF! | G40: =#REF! -> #REF! | H40: =#REF! -> #REF! | I40: =#REF! -> #REF! | J40: =#REF! -> #REF! | K40: =#REF! -> #REF!
...

Sheet Double Elimination Bracket
B1: DE1 | E1: DE2 | G1: DE3 | J1: DE4 | L1: DE5 | N1: DE6 | P1: FINALS BO3
B2: 12:40-13:15 PT | E2: 13:15-13:50 PT | G2: 13:50-14:25 PT | J2: 14:45-15:15 PT | L2: 15:15-15:45 PT | N2: 15:45-16:15 PT | P2: 16:15-17:15 PT | S2: 1st: | T2: Montgomery Blair 1
S3: 2nd: | T3: MSJ 1
A4: 1 | B4: Montgomery Blair 1 | C4: 98 | S4: 3rd: | T4: TJHSST 2
A5: AlbatrosInterlake | G5: Lexington | H5: 10 | S5: 4th: | T5: Lexington
A6: 8 | B6: Lexington | C6: 110 | S6: 5-6th: | T6: Clements, Middleton 1
G7: AlbatrosInterlake | L7: TJHSST 2 | M7: 40
A8: 4 | B8: Wayzata | C8: 46
A9: AlbatrosWinston Churchill | G9: TJHSST 2 | H9: 44
A10: 5 | B10: TJHSST 2 | C10: 100
L11: Cornelia Street | P11: MSJ 1 | Q11: 6 | R11: -8
A12: 2 | B12: Clements | C12: 48 | U12: Mods | V12: 52.81
A13: BottlWayzata | G13: MSJ 1 | H13: 102
A14: 7 | B14: MSJ 1 | C14: 122 | W14: Anurag S
G15: AlbatrosWinston Churchill | L15: MSJ 1 | M15: 104
A16: 3 | B16: Middleton 1 | C16: 128 | P16: Cornelia Street | T16: Montgomery Blair 1 | V16: 31
A17: BottlDulles | G17: Middleton 1 | H17: 24 | M17: LC-1 | N17: TJHSST 2 | O17: 26
A18: 6 | B18: Lynbrook 1 | C18: 62
I19: LA-1 | J19: Lexington | K19: 96
D20: LB-2 | E20: Lynbrook 1 | F20: 98
A21: 9 | B21: CCA 1 | C21: 78 | E21: BottlWayzata | G21: Lynbrook 1 | H21: 60 | J21: Cornelia Street | L21: Lexington | M21: 54 | N21: Cornelia Street | P21: Montgomery Blair 1 | Q21: 18 | R21: 22
A22: ChampagnWayzata | E22: Ward Melville | F22: 34
A23: 16 | B23: Ward Melville | C23: 102 | G23: ChampagnWayzata | J23: Clements | K23: 62
D24: LB-1 | E24: Clements | F24: 74
A25: 12 | B25: Foothill | C25: 18 | E25: BottlDulles | G25: Clements | H25: 68 | L25: Scott Street | N25: Montgomery Blair 1 | O25: 98
A26: ChampagnDulles | E26: MSJ 2 | F26: 28
A27: 13 | B27: MSJ 2 | C27: 50 | I27: LA-2 | J27: Middleton 1 | K27: 66
D28: LA-2 | E28: Wayzata | F28: 52
A29: 10 | B29: WWPS 1 | C29: 60 | E29: ChampagnWayzata | G29: Palo Alto | H29: 26 | J29: Scott Street | L29: Montgomery Blair 1 | M29: 94
A30: Daylight-1 | E30: Palo Alto | F30: 136
A31: 15 | B31: Palo Alto | C31: 86 | G31: ChampagnDulles | J31: Montgomery Blair 1 | K31: 96
D32: LA-1 | E32: Montgomery Blair 1 | F32: 150
A33: 11 | B33: TJHSST 1 | C33: 50 | E33: ChampagnDulles | G33: Montgomery Blair 1 | H33: 90
A34: Daylight-2 | E34: Lynbrook 2 | F34: 10
A35: 14 | B35: Lynbrook 2 | C35: 80

Sheet League Phase Overall Individual
A1: Catstats Hub | B1: gamesPlayed | C1: tuh | D1: buzzes | E1: ppg | F1: PP4TUH | G1: npg | H1: Total Negs | I1: accuracy
A2: Amador Valley rohan g [Amador Valley] | B2: 6 | C2: 138 | D2: 72 | E2: 28 | F2: =E2*B2*23/C2 -> 28 | G2: 2.33 | H2: =G2*B2 -> 13.98 | I2: 0.778
A3: Ward Melville harry g [Ward Melville] | B3: 6 | C3: 138 | D3: 54 | E3: 27.33 | F3: =E3*B3*23/C3 -> 27.33 | G3: 0.5 | H3: =G3*B3 -> 3 | I3: 0.815
A4: Frazer ajay s [Frazer] | B4: 6 | C4: 135 | D4: 45 | E4: 25.33 | F4: =E4*B4*23/C4 -> 25.892889 | G4: 0.33 | H4: =G4*B4 -> 1.98 | I4: 0.889
A5: TJHSST aaryan s [TJHSST] | B5: 6 | C5: 138 | D5: 51 | E5: 24.67 | F5: =E5*B5*23/C5 -> 24.67 | G5: 1 | H5: =G5*B5 -> 6 | I5: 0.843
A6: OCSA james c [OCSA] | B6: 6 | C6: 135 | D6: 54 | E6: 22.67 | F6: =E6*B6*23/C6 -> 23.173778 | G6: 1.17 | H6: =G6*B6 -> 7.02 | I6: 0.759
A7: Lakeside william w [Lakeside] | B7: 6 | C7: 136 | D7: 38 | E7: 22 | F7: =E7*B7*23/C7 -> 22.323529 | G7: 0.33 | H7: =G7*B7 -> 1.98 | I7: 0.921
A8: Wayzata kevin q [Wayzata] | B8: 3 | C8: 69 | D8: 26 | E8: 21.33 | F8: =E8*B8*23/C8 -> 21.33 | G8: 1.33 | H8: =G8*B8 -> 3.99 | I8: 0.769
A9: ASFA akhil b [ASFA] | B9: 6 | C9: 138 | D9: 77 | E9: 20.67 | F9: =E9*B9*23/C9 -> 20.67 | G9: 2.67 | H9: =G9*B9 -> 16.02 | I9: 0.61
A10: Interlake rishabh v [Interlake] | B10: 6 | C10: 138 | D10: 46 | E10: 20.67 | F10: =E10*B10*23/C10 -> 20.67 | G10: 1.17 | H10: =G10*B10 -> 7.02 | I10: 0.826
A11: Canyon Crest austin x [Canyon Crest] | B11: 6 | C11: 138 | D11: 50 | E11: 20.67 | F11: =E11*B11*23/C11 -> 20.67 | G11: 1 | H11: =G11*B11 -> 6 | I11: 0.74
A12: Palo Alto andrew w [Palo Alto] | B12: 6 | C12: 138 | D12: 41 | E12: 20.67 | F12: =E12*B12*23/C12 -> 20.67 | G12: 0.67 | H12: =G12*B12 -> 4.02 | I12: 0.854
A13: Mira Loma aatreyo b [Mira Loma] | B13: 6 | C13: 138 | D13: 53 | E13: 19.33 | F13: =E13*B13*23/C13 -> 19.33 | G13: 1.67 | H13: =G13*B13 -> 10.02 | I13: 0.736
... A132: Middleton elizabeth w [Middleton] | B132: 1 | C132: 23 | D132: 2 | E132: -4 | F132: =E132*B132*23/C132 -> -4 | G132: 1 | H132: =G132*B132 -> 1 | I132: 0

Sheet League Phase Individual Biology
A1: Catstats Hub | B1: gamesPlayed | C1: tuh | D1: buzzes | E1: ppg | F1: PP4TUH | G1: npg | H1: Total Negs | I1: accuracy
A2: Frazer ajay s [Frazer] | B2: 6 | C2: 23 | D2: 16 | E2: 10.67 | F2: =E2*B2*4/C2 -> 11.133913 | G2: 0 | H2: =G2*B2 -> 0 | I2: 1
A3: Lynbrook andrew l [Lynbrook] | B3: 6 | C3: 23 | D3: 18 | E3: 10 | F3: =E3*B3*4/C3 -> 10.434783 | G3: 0 | H3: =G3*B3 -> 0 | I3: 0.833
A4: Interlake evan w [Interlake] | B4: 6 | C4: 24 | D4: 19 | E4: 10 | F4: =E4*B4*4/C4 -> 10 | G4: 0.33 | H4: =G4*B4 -> 1.98 | I4: 0.895
A5: Blair meghna s [Blair] | B5: 6 | C5: 24 | D5: 17 | E5: 8.67 | F5: =E5*B5*4/C5 -> 8.67 | G5: 0.17 | H5: =G5*B5 -> 1.02 | I5: 0.824
A6: Arcadia avani a [Arcadia] | B6: 6 | C6: 24 | D6: 14 | E6: 8 | F6: =E6*B6*4/C6 -> 8 | G6: 0.17 | H6: =G6*B6 -> 1.02 | I6: 0.929
A7: Ward Melville anna x [Ward Melville] | B7: 5 | C7: 21 | D7: 10 | E7: 6.4 | F7: =E7*B7*4/C7 -> 6.0952381 | G7: 0 | H7: =G7*B7 -> 0 | I7: 0.8
A8: Stuyvesant philip z [Stuyvesant] | B8: 6 | C8: 24 | D8: 13 | E8: 6 | F8: =E8*B8*4/C8 -> 6 | G8: 0.33 | H8: =G8*B8 -> 1.98 | I8: 0.846
A9: Dulles ronuk g [Dulles] | B9: 6 | C9: 24 | D9: 14 | E9: 6 | F9: =E9*B9*4/C9 -> 6 | G9: 0.33 | H9: =G9*B9 -> 1.98 | I9: 0.786
A10: Wayzata warren w [Wayzata] | B10: 6 | C10: 24 | D10: 12 | E10: 5.33 | F10: =E10*B10*4/C10 -> 5.33 | G10: 0.33 | H10: =G10*B10 -> 1.98 | I10: 0.833
A11: Lakeside emma l [Lakeside] | B11: 4 | C11: 16 | D11: 9 | E11: 5 | F11: =E11*B11*4/C11 -> 5 | G11: 0.25 | H11: =G11*B11 -> 1 | I11: 0.667
A12: Canyon Crest austin x [Canyon Crest] | B12: 6 | C12: 23 | D12: 11 | E12: 4.67 | F12: =E12*B12*4/C12 -> 4.8730435 | G12: 0.17 | H12: =G12*B12 -> 1.02 | I12: 0.727
A13: Mission San Jose aravind m [Mission San Jose] | B13: 6 | C13: 24 | D13: 11 | E13: 4.67 | F13: =E13*B13*4/C13 -> 4.67 | G13: 0.33 | H13: =G13*B13 -> 1.98 | I13: 0.818
... A132: Middleton elizabeth w [Middleton] | B132: 1 | C132: 4 | D132: 1 | E132: -4 | F132: =E132*B132*4/C132 -> -4 | G132: 1 | H132: =G132*B132 -> 1 | I132: 0

Sheet League Phase Individual Chemist
A1: Catstats Hub | B1: gamesPlayed | C1: tuh | D1: buzzes | E1: ppg | F1: PP4TUH | G1: npg | H1: Total Negs | I1: accuracy
A2: WWPS sanjay o [WWPS] | B2: 6 | C2: 24 | D2: 17 | E2: 11.33 | F2: =E2*B2*4/C2 -> 11.33 | G2: 0 | H2: =G2*B2 -> 0 | I2: 1
A3: Lakeside william w [Lakeside] | B3: 6 | C3: 24 | D3: 16 | E3: 8 | F3: =E3*B3*4/C3 -> 8 | G3: 0.33 | H3: =G3*B3 -> 1.98 | I3: 0.875
A4: Amador Valley gaurav g [Amador Valley] | B4: 6 | C4: 24 | D4: 14 | E4: 8 | F4: =E4*B4*4/C4 -> 8 | G4: 0.17 | H4: =G4*B4 -> 1.02 | I4: 0.929
A5: TJHSST aaryan s [TJHSST] | B5: 6 | C5: 24 | D5: 18 | E5: 7.33 | F5: =E5*B5*4/C5 -> 7.33 | G5: 0.5 | H5: =G5*B5 -> 3 | I5: 0.778
A6: Lynbrook evan l [Lynbrook] | B6: 6 | C6: 24 | D6: 11 | E6: 7.33 | F6: =E6*B6*4/C6 -> 7.33 | G6: 0 | H6: =G6*B6 -> 0 | I6: 1
A7: Arcadia ethan w [Arcadia] | B7: 6 | C7: 24 | D7: 15 | E7: 6.67 | F7: =E7*B7*4/C7 -> 6.67 | G7: 0.33 | H7: =G7*B7 -> 1.98 | I7: 0.8
A8: OCSA james c [OCSA] | B8: 6 | C8: 24 | D8: 13 | E8: 6.67 | F8: =E8*B8*4/C8 -> 6.67 | G8: 0.17 | H8: =G8*B8 -> 1.02 | I8: 0.846
A9: Saratoga alex g [Saratoga] | B9: 6 | C9: 24 | D9: 11 | E9: 6.67 | F9: =E9*B9*4/C9 -> 6.67 | G9: 0 | H9: =G9*B9 -> 0 | I9: 0.909
A10: ASFA akhil b [ASFA] | B10: 6 | C10: 24 | D10: 18 | E10: 6 | F10: =E10*B10*4/C10 -> 6 | G10: 0.5 | H10: =G10*B10 -> 3 | I10: 0.667
A11: Wayzata sophie c [Wayzata] | B11: 2 | C11: 8 | D11: 4 | E11: 6 | F11: =E11*B11*4/C11 -> 6 | G11: 0 | H11: =G11*B11 -> 0 | I11: 0.75
A12: Ward Melville anna x [Ward Melville] | B12: 5 | C12: 20 | D12: 11 | E12: 5.6 | F12: =E12*B12*4/C12 -> 5.6 | G12: 0.4 | H12: =G12*B12 -> 2 | I12: 0.818
A13: Frazer jimmy j [Frazer] | B13: 5 | C13: 20 | D13: 10 | E13: 5.6 | F13: =E13*B13*4/C13 -> 5.6 | G13: 0.2 | H13: =G13*B13 -> 1 | I13: 0.8
... A132: OCSA dane b [OCSA] | B132: 1 | C132: 4 | D132: 1 | E132: -4 | F132: =E132*B132*4/C132 -> -4 | G132: 1 | H132: =G132*B132 -> 1 | I132: 0

Sheet League Phase Individual Energy
A1: Catstats Hub | B1: gamesPlayed | C1: tuh | D1: buzzes | E1: ppg | F1: PP3TUH | G1: npg | H1: Total Negs | I1: accuracy
A2: Lynbrook andrew l [Lynbrook] | B2: 6 | C2: 19 | D2: 8 | E2: 5.33 | F2: =E2*B2*3/C2 -> 5.0494737 | G2: 0 | H2: =G2*B2 -> 0 | I2: 1
A3: Ward Melville harry g [Ward Melville] | B3: 6 | C3: 17 | D3: 7 | E3: 4.67 | F3: =E3*B3*3/C3 -> 4.9447059 | G3: 0 | H3: =G3*B3 -> 0 | I3: 1
A4: Frazer ajay s [Frazer] | B4: 6 | C4: 18 | D4: 7 | E4: 4.67 | F4: =E4*B4*3/C4 -> 4.67 | G4: 0 | H4: =G4*B4 -> 0 | I4: 1
A5: Stuyvesant julien d [Stuyvesant] | B5: 5 | C5: 14 | D5: 5 | E5: 4 | F5: =E5*B5*3/C5 -> 4.2857143 | G5: 0 | H5: =G5*B5 -> 0 | I5: 1
A6: Mira Loma aatreyo b [Mira Loma] | B6: 6 | C6: 18 | D6: 8 | E6: 4 | F6: =E6*B6*3/C6 -> 4 | G6: 0.17 | H6: =G6*B6 -> 1.02 | I6: 0.875
A7: Mission San Jose aravind m [Mission San Jose] | B7: 6 | C7: 18 | D7: 6 | E7: 4 | F7: =E7*B7*3/C7 -> 4 | G7: 0 | H7: =G7*B7 -> 0 | I7: 1
A8: Ward Melville gunes s [Ward Melville] | B8: 1 | C8: 3 | D8: 1 | E8: 4 | F8: =E8*B8*3/C8 -> 4 | G8: 0 | H8: =G8*B8 -> 0 | I8: 1
A9: Lakeside william w [Lakeside] | B9: 6 | C9: 18 | D9: 7 | E9: 4 | F9: =E9*B9*3/C9 -> 4 | G9: 0 | H9: =G9*B9 -> 0 | I9: 0.857
A10: University timothy c [University] | B10: 6 | C10: 18 | D10: 7 | E10: 4 | F10: =E10*B10*3/C10 -> 4 | G10: 0 | H10: =G10*B10 -> 0 | I10: 0.857
A11: TJHSST aaryan s [TJHSST] | B11: 6 | C11: 18 | D11: 6 | E11: 4 | F11: =E11*B11*3/C11 -> 4 | G11: 0 | H11: =G11*B11 -> 0 | I11: 1
A12: Wayzata sophie c [Wayzata] | B12: 2 | C12: 6 | D12: 2 | E12: 4 | F12: =E12*B12*3/C12 -> 4 | G12: 0 | H12: =G12*B12 -> 0 | I12: 1
A13: Wayzata kevin q [Wayzata] | B13: 3 | C13: 9 | D13: 4 | E13: 4 | F13: =E13*B13*3/C13 -> 4 | G13: 0 | H13: =G13*B13 -> 0 | I13: 0.75
... A132: Stuyvesant cody c [Stuyvesant] | B132: 3 | C132: 8 | D132: 1 | E132: -1.33 | F132: =E132*B132*3/C132 -> -1.49625 | G132: 0.33 | H132: =G132*B132 -> 0.99 | I132: 0

Sheet League Phase Individual ESS
A1: Catstats Hub | B1: gamesPlayed | C1: tuh | D1: buzzes | E1: ppg | F1: PP4TUH | G1: npg | H1: Total Negs | I1: accuracy
A2: Interlake rishabh v [Interlake] | B2: 6 | C2: 24 | D2: 22 | E2: 10 | F2: =E2*B2*4/C2 -> 10 | G2: 0.5 | H2: =G2*B2 -> 3 | I2: 0.818
A3: Canyon Crest flora j [Canyon Crest] | B3: 6 | C3: 24 | D3: 19 | E3: 9.33 | F3: =E3*B3*4/C3 -> 9.33 | G3: 0.33 | H3: =G3*B3 -> 1.98 | I3: 0.842
A4: Mission San Jose advai s [Mission San Jose] | B4: 6 | C4: 24 | D4: 17 | E4: 8.67 | F4: =E4*B4*4/C4 -> 8.67 | G4: 0.33 | H4: =G4*B4 -> 1.98 | I4: 0.882
A5: Hunter camille p [Hunter] | B5: 6 | C5: 24 | D5: 14 | E5: 8 | F5: =E5*B5*4/C5 -> 8 | G5: 0 | H5: =G5*B5 -> 0 | I5: 0.857
A6: Foothill shashank v [Foothill] | B6: 6 | C6: 24 | D6: 16 | E6: 6.67 | F6: =E6*B6*4/C6 -> 6.67 | G6: 0.33 | H6: =G6*B6 -> 1.98 | I6: 0.75
A7: Amador Valley karthik a [Amador Valley] | B7: 5 | C7: 20 | D7: 8 | E7: 6.4 | F7: =E7*B7*4/C7 -> 6.4 | G7: 0 | H7: =G7*B7 -> 0 | I7: 1
A8: TJHSST aaryan s [TJHSST] | B8: 6 | C8: 24 | D8: 13 | E8: 6 | F8: =E8*B8*4/C8 -> 6 | G8: 0.33 | H8: =G8*B8 -> 1.98 | I8: 0.846
A9: Ward Melville jason y [Ward Melville] | B9: 5 | C9: 19 | D9: 7 | E9: 5.6 | F9: =E9*B9*4/C9 -> 5.8947368 | G9: 0 | H9: =G9*B9 -> 0 | I9: 1
A10: WWPS abhinav a [WWPS] | B10: 5 | C10: 20 | D10: 10 | E10: 5.6 | F10: =E10*B10*4/C10 -> 5.6 | G10: 0.2 | H10: =G10*B10 -> 1 | I10: 0.8
A11: Dulles shlok p [Dulles] | B11: 4 | C11: 15 | D11: 7 | E11: 5 | F11: =E11*B11*4/C11 -> 5.3333333 | G11: 0.25 | H11: =G11*B11 -> 1 | I11: 0.857
