Workbook

Sheet Prelim Rankings Unsorted
A1: Round:
A2: TEAMS | B2: 1 | C2: 2 | D2: 3 | E2: TOTAL POINTS
A3: Grammar Kids | B3: =IFERROR(__xludf.DUMMYFUNCTION("HLOOKUP($A3, IMPORTRANGE($B$40, CONCAT(VLOOKUP($A3, 'Match Names'!$A$1:$D$22, 2, FALSE),""!C1:R29"")), 29, FALSE)"),4.0) -> 4 | C3: =IFERROR(__xludf.DUMMYFUNCTION("HLOOKUP($A3, IMPORTRANGE($B$41, CONCAT(VLOOKUP($A3, 'Match Names'!$A$1:$D$22, 3, FALSE),""!C1:R29"")), 29, FALSE)"),28.0) -> 28 | D3: =IFERROR(__xludf.DUMMYFUNCTION("HLOOKUP($A3, IMPORTRANGE($B$42, CONCAT(VLOOKUP($A3, 'Match Names'!$A$1:$D$22, 4, FALSE),""!C1:R29"")), 29, FALSE)"),38.0) -> 38 | E3: =SUM(B3:D3) -> 70
A4: Deer Feeled | B4: =IFERROR(__xludf.DUMMYFUNCTION("HLOOKUP($A4, IMPORTRANGE($B$40, CONCAT(VLOOKUP($A4, 'Match Names'!$A$1:$D$22, 2, FALSE),""!C1:R29"")), 29, FALSE)"),206.0) -> 206 | C4: =IFERROR(__xludf.DUMMYFUNCTION("HLOOKUP($A4, IMPORTRANGE($B$41, CONCAT(VLOOKUP($A4, 'Match Names'!$A$1:$D$22, 3, FALSE),""!C1:R29"")), 29, FALSE)"),180.0) -> 180 | D4: =IFERROR(__xludf.DUMMYFUNCTION("HLOOKUP($A4, IMPORTRANGE($B$42, CONCAT(VLOOKUP($A4, 'Match Names'!$A$1:$D$22, 4, FALSE),""!C1:R29"")), 29, FALSE)"),42.0) -> 42 | E4: =SUM(B4:D4) -> 428
A5: Dear Field | B5: =IFERROR(__xludf.DUMMYFUNCTION("HLOOKUP($A5, IMPORTRANGE($B$40, CONCAT(VLOOKUP($A5, 'Match Names'!$A$1:$D$22, 2, FALSE),""!C1:R29"")), 29, FALSE)"),210.0) -> 210 | C5: =IFERROR(__xludf.DUMMYFUNCTION("HLOOKUP($A5, IMPORTRANGE($B$41, CONCAT(VLOOKUP($A5, 'Match Names'!$A$1:$D$22, 3, FALSE),""!C1:R29"")), 29, FALSE)"),78.0) -> 78 | D5: =IFERROR(__xludf.DUMMYFUNCTION("HLOOKUP($A5, IMPORTRANGE($B$42, CONCAT(VLOOKUP($A5, 'Match Names'!$A$1:$D$22, 4, FALSE),""!C1:R29"")), 29, FALSE)"),156.0) -> 156 | E5: =SUM(B5:D5) -> 444
A6: William Mason | B6: =IFERROR(__xludf.DUMMYFUNCTION("HLOOKUP($A6, IMPORTRANGE($B$40, CONCAT(VLOOKUP($A6, 'Match Names'!$A$1:$D$22, 2, FALSE),""!C1:R29"")), 29, FALSE)"),50.0) -> 50 | C6: =IFERROR(__xludf.DUMMYFUNCTION("HLOOKUP($A6, IMPORTRANGE($B$41, CONCAT(VLOOKUP($A6, 'Match Names'!$A$1:$D$22, 3, FALSE),""!C1:R29"")), 29, FALSE)"),24.0) -> 24 | D6: =IFERROR(__xludf.DUMMYFUNCTION("HLOOKUP($A6, IMPORTRANGE($B$42, CONCAT(VLOOKUP($A6, 'Match Names'!$A$1:$D$22, 4, FALSE),""!C1:R29"")), 29, FALSE)"),96.0) -> 96 | E6: =SUM(B6:D6) -> 170
A7: Scrubby Teletubbies | B7: =IFERROR(__xludf.DUMMYFUNCTION("HLOOKUP($A7, IMPORTRANGE($B$40, CONCAT(VLOOKUP($A7, 'Match Names'!$A$1:$D$22, 2, FALSE),""!C1:R29"")), 29, FALSE)"),224.0) -> 224 | C7: =IFERROR(__xludf.DUMMYFUNCTION("HLOOKUP($A7, IMPORTRANGE($B$41, CONCAT(VLOOKUP($A7, 'Match Names'!$A$1:$D$22, 3, FALSE),""!C1:R29"")), 29, FALSE)"),98.0) -> 98 | D7: =IFERROR(__xludf.DUMMYFUNCTION("HLOOKUP($A7, IMPORTRANGE($B$42, CONCAT(VLOOKUP($A7, 'Match Names'!$A$1:$D$22, 4, FALSE),""!C1:R29"")), 29, FALSE)"),56.0) -> 56 | E7: =SUM(B7:D7) -> 378
A8: U-235 Soup | B8: =IFERROR(__xludf.DUMMYFUNCTION("HLOOKUP($A8, IMPORTRANGE($B$40, CONCAT(VLOOKUP($A8, 'Match Names'!$A$1:$D$22, 2, FALSE),""!C1:R29"")), 29, FALSE)"),110.0) -> 110 | C8: =IFERROR(__xludf.DUMMYFUNCTION("HLOOKUP($A8, IMPORTRANGE($B$41, CONCAT(VLOOKUP($A8, 'Match Names'!$A$1:$D$22, 3, FALSE),""!C1:R29"")), 29, FALSE)"),194.0) -> 194 | D8: =IFERROR(__xludf.DUMMYFUNCTION("HLOOKUP($A8, IMPORTRANGE($B$42, CONCAT(VLOOKUP($A8, 'Match Names'!$A$1:$D$22, 4, FALSE),""!C1:R29"")), 29, FALSE)"),16.0) -> 16 | E8: =SUM(B8:D8) -> 320
A9: Galena Popsicles | B9: =IFERROR(__xludf.DUMMYFUNCTION("HLOOKUP($A9, IMPORTRANGE($B$40, CONCAT(VLOOKUP($A9, 'Match Names'!$A$1:$D$22, 2, FALSE),""!C1:R29"")), 29, FALSE)"),234.0) -> 234 | C9: =IFERROR(__xludf.DUMMYFUNCTION("HLOOKUP($A9, IMPORTRANGE($B$41, CONCAT(VLOOKUP($A9, 'Match Names'!$A$1:$D$22, 3, FALSE),""!C1:R29"")), 29, FALSE)"),222.0) -> 222 | D9: =IFERROR(__xludf.DUMMYFUNCTION("HLOOKUP($A9, IMPORTRANGE($B$42, CONCAT(VLOOKUP($A9, 'Match Names'!$A$1:$D$22, 4, FALSE),""!C1:R29"")), 29, FALSE)"),80.0) -> 80 | E9: =SUM(B9:D9) -> 536
A10: IDIOM | B10: =IFERROR(__xludf.DUMMYFUNCTION("HLOOKUP($A10, IMPORTRANGE($B$40, CONCAT(VLOOKUP($A10, 'Match Names'!$A$1:$D$22, 2, FALSE),""!C1:R29"")), 29, FALSE)"),210.0) -> 210 | C10: =IFERROR(__xludf.DUMMYFUNCTION("HLOOKUP($A10, IMPORTRANGE($B$41, CONCAT(VLOOKUP($A10, 'Match Names'!$A$1:$D$22, 3, FALSE),""!C1:R29"")), 29, FALSE)"),238.0) -> 238 | D10: =IFERROR(__xludf.DUMMYFUNCTION("HLOOKUP($A10, IMPORTRANGE($B$42, CONCAT(VLOOKUP($A10, 'Match Names'!$A$1:$D$22, 4, FALSE),""!C1:R29"")), 29, FALSE)"),164.0) -> 164 | E10: =SUM(B10:D10) -> 612
A11: Banana Corp | B11: =IFERROR(__xludf.DUMMYFUNCTION("HLOOKUP($A11, IMPORTRANGE($B$40, CONCAT(VLOOKUP($A11, 'Match Names'!$A$1:$D$22, 2, FALSE),""!C1:R29"")), 29, FALSE)"),304.0) -> 304 | C11: =IFERROR(__xludf.DUMMYFUNCTION("HLOOKUP($A11, IMPORTRANGE($B$41, CONCAT(VLOOKUP($A11, 'Match Names'!$A$1:$D$22, 3, FALSE),""!C1:R29"")), 29, FALSE)"),326.0) -> 326 | D11: =IFERROR(__xludf.DUMMYFUNCTION("HLOOKUP($A11, IMPORTRANGE($B$42, CONCAT(VLOOKUP($A11, 'Match Names'!$A$1:$D$22, 4, FALSE),""!C1:R29"")), 29, FALSE)"),114.0) -> 114 | E11: =SUM(B11:D11) -> 744
A12: The Catecholomines | B12: =IFERROR(__xludf.DUMMYFUNCTION("HLOOKUP($A12, IMPORTRANGE($B$40, CONCAT(VLOOKUP($A12, 'Match Names'!$A$1:$D$22, 2, FALSE),""!C1:R29"")), 29, FALSE)"),288.0) -> 288 | C12: =IFERROR(__xludf.DUMMYFUNCTION("HLOOKUP($A12, IMPORTRANGE($B$41, CONCAT(VLOOKUP($A12, 'Match Names'!$A$1:$D$22, 3, FALSE),""!C1:R29"")), 29, FALSE)"),276.0) -> 276 | D12: =IFERROR(__xludf.DUMMYFUNCTION("HLOOKUP($A12, IMPORTRANGE($B$42, CONCAT(VLOOKUP($A12, 'Match Names'!$A$1:$D$22, 4, FALSE),""!C1:R29"")), 29, FALSE)"),202.0) -> 202 | E12: =SUM(B12:D12) -> 766
A13: Be the Block of Bread | B13: =IFERROR(__xludf.DUMMYFUNCTION("HLOOKUP($A13, IMPORTRANGE($B$40, CONCAT(VLOOKUP($A13, 'Match Names'!$A$1:$D$22, 2, FALSE),""!C1:R29"")), 29, FALSE)"),116.0) -> 116 | C13: =IFERROR(__xludf.DUMMYFUNCTION("HLOOKUP($A13, IMPORTRANGE($B$41, CONCAT(VLOOKUP($A13, 'Match Names'!$A$1:$D$22, 3, FALSE),""!C1:R29"")), 29, FALSE)"),80.0) -> 80 | D13: =IFERROR(__xludf.DUMMYFUNCTION("HLOOKUP($A13, IMPORTRANGE($B$42, CONCAT(VLOOKUP($A13, 'Match Names'!$A$1:$D$22, 4, FALSE),""!C1:R29"")), 29, FALSE)"),48.0) -> 48 | E13: =SUM(B13:D13) -> 244
A14: The Mother Doers | B14: =IFERROR(__xludf.DUMMYFUNCTION("HLOOKUP($A14, IMPORTRANGE($B$40, CONCAT(VLOOKUP($A14, 'Match Names'!$A$1:$D$22, 2, FALSE),""!C1:R29"")), 29, FALSE)"),66.0) -> 66 | C14: =IFERROR(__xludf.DUMMYFUNCTION("HLOOKUP($A14, IMPORTRANGE($B$41, CONCAT(VLOOKUP($A14, 'Match Names'!$A$1:$D$22, 3, FALSE),""!C1:R29"")), 29, FALSE)"),183.0) -> 183 | D14: =IFERROR(__xludf.DUMMYFUNCTION("HLOOKUP($A14, IMPORTRANGE($B$42, CONCAT(VLOOKUP($A14, 'Match Names'!$A$1:$D$22, 4, FALSE),""!C1:R29"")), 29, FALSE)"),300.0) -> 300 | E14: =SUM(B14:D14) -> 549
A15: Jerry is a Nerd | B15: =IFERROR(__xludf.DUMMYFUNCTION("HLOOKUP($A15, IMPORTRANGE($B$40, CONCAT(VLOOKUP($A15, 'Match Names'!$A$1:$D$22, 2, FALSE),""!C1:R29"")), 29, FALSE)"),122.0) -> 122 | C15: =IFERROR(__xludf.DUMMYFUNCTION("HLOOKUP($A15, IMPORTRANGE($B$41, CONCAT(VLOOKUP($A15, 'Match Names'!$A$1:$D$22, 3, FALSE),""!C1:R29"")), 29, FALSE)"),204.0) -> 204 | D15: =IFERROR(__xludf.DUMMYFUNCTION("HLOOKUP($A15, IMPORTRANGE($B$42, CONCAT(VLOOKUP($A15, 'Match Names'!$A$1:$D$22, 4, FALSE),""!C1:R29"")), 29, FALSE)"),176.0) -> 176 | E15: =SUM(B15:D15) -> 502
A16: Hopkins | B16: =IFERROR(__xludf.DUMMYFUNCTION("HLOOKUP($A16, IMPORTRANGE($B$40, CONCAT(VLOOKUP($A16, 'Match Names'!$A$1:$D$22, 2, FALSE),""!C1:R29"")), 29, FALSE)"),12.0) -> 12 | C16: =IFERROR(__xludf.DUMMYFUNCTION("HLOOKUP($A16, IMPORTRANGE($B$41, CONCAT(VLOOKUP($A16, 'Match Names'!$A$1:$D$22, 3, FALSE),""!C1:R29"")), 29, FALSE)"),176.0) -> 176 | D16: =IFERROR(__xludf.DUMMYFUNCTION("HLOOKUP($A16, IMPORTRANGE($B$42, CONCAT(VLOOKUP($A16, 'Match Names'!$A$1:$D$22, 4, FALSE),""!C1:R29"")), 29, FALSE)"),44.0) -> 44 | E16: =SUM(B16:D16) -> 232
A17: Squishy Cats | B17: =IFERROR(__xludf.DUMMYFUNCTION("HLOOKUP($A17, IMPORTRANGE($B$40, CONCAT(VLOOKUP($A17, 'Match Names'!$A$1:$D$22, 2, FALSE),""!C1:R29"")), 29, FALSE)"),130.0) -> 130 | C17: =IFERROR(__xludf.DUMMYFUNCTION("HLOOKUP($A17, IMPORTRANGE($B$41, CONCAT(VLOOKUP($A17, 'Match Names'!$A$1:$D$22, 3, FALSE),""!C1:R29"")), 29, FALSE)"),98.0) -> 98 | D17: =IFERROR(__xludf.DUMMYFUNCTION("HLOOKUP($A17, IMPORTRANGE($B$42, CONCAT(VLOOKUP($A17, 'Match Names'!$A$1:$D$22, 4, FALSE),""!C1:R29"")), 29, FALSE)"),196.0) -> 196 | E17: =SUM(B17:D17) -> 424
A18: Degenerate Matter | B18: =IFERROR(__xludf.DUMMYFUNCTION("HLOOKUP($A18, IMPORTRANGE($B$40, CONCAT(VLOOKUP($A18, 'Match Names'!$A$1:$D$22, 2, FALSE),""!C1:R29"")), 29, FALSE)"),216.0) -> 216 | C18: =IFERROR(__xludf.DUMMYFUNCTION("HLOOKUP($A18, IMPORTRANGE($B$41, CONCAT(VLOOKUP($A18, 'Match Names'!$A$1:$D$22, 3, FALSE),""!C1:R29"")), 29, FALSE)"),42.0) -> 42 | D18: =IFERROR(__xludf.DUMMYFUNCTION("HLOOKUP($A18, IMPORTRANGE($B$42, CONCAT(VLOOKUP($A18, 'Match Names'!$A$1:$D$22, 4, FALSE),""!C1:R29"")), 29, FALSE)"),170.0) -> 170 | E18: =SUM(B18:D18) -> 428
A19: Bio and Chem Players Only Challenge | B19: =IFERROR(__xludf.DUMMYFUNCTION("HLOOKUP(""BCPOC"", IMPORTRANGE($B$40, CONCAT(VLOOKUP($A19, 'Match Names'!$A$1:$D$22, 2, FALSE),""!C1:R29"")), 29, FALSE)"),123.0) -> 123 | C19: =IFERROR(__xludf.DUMMYFUNCTION("HLOOKUP(""BCPOC"", IMPORTRANGE($B$41, CONCAT(VLOOKUP($A19, 'Match Names'!$A$1:$D$22, 3, FALSE),""!C1:R29"")), 29, FALSE)"),86.0) -> 86 | D19: =IFERROR(__xludf.DUMMYFUNCTION("HLOOKUP(""BCPOC"", IMPORTRANGE($B$42, CONCAT(VLOOKUP($A19, 'Match Names'!$A$1:$D$22, 4, FALSE),""!C1:R29"")), 29, FALSE)"),160.0) -> 160 | E19: =SUM(B19:D19) -> 369
A20: Sacramento Country Day School | B20: =IFERROR(__xludf.DUMMYFUNCTION("HLOOKUP(""SCD School"", IMPORTRANGE($B$40, CONCAT(VLOOKUP($A20, 'Match Names'!$A$1:$D$22, 2, FALSE),""!C1:R29"")), 29, FALSE)"),222.0) -> 222 | C20: =IFERROR(__xludf.DUMMYFUNCTION("HLOOKUP(""SCD School"", IMPORTRANGE($B$41, CONCAT(VLOOKUP($A20, 'Match Names'!$A$1:$D$22, 3, FALSE),""!C1:R29"")), 29, FALSE)"),198.0) -> 198 | D20: =IFERROR(__xludf.DUMMYFUNCTION("HLOOKUP(""SCD School"", IMPORTRANGE($B$42, CONCAT(VLOOKUP($A20, 'Match Names'!$A$1:$D$22, 4, FALSE),""!C1:R29"")), 29, FALSE)"),190.0) -> 190 | E20: =SUM(B20:D20) -> 610
A21: Orthonormal BASIS | B21: =IFERROR(__xludf.DUMMYFUNCTION("HLOOKUP($A21, IMPORTRANGE($B$40, CONCAT(VLOOKUP($A21, 'Match Names'!$A$1:$D$22, 2, FALSE),""!C1:R29"")), 29, FALSE)"),140.0) -> 140 | C21: =IFERROR(__xludf.DUMMYFUNCTION("HLOOKUP($A21, IMPORTRANGE($B$41, CONCAT(VLOOKUP($A21, 'Match Names'!$A$1:$D$22, 3, FALSE),""!C1:R29"")), 29, FALSE)"),56.0) -> 56 | D21: =IFERROR(__xludf.DUMMYFUNCTION("HLOOKUP($A21, IMPORTRANGE($B$42, CONCAT(VLOOKUP($A21, 'Match Names'!$A$1:$D$22, 4, FALSE),""!C1:R29"")), 29, FALSE)"),100.0) -> 100 | E21: =SUM(B21:D21) -> 296
A22: Blue Rhinobeetles | B22: =IFERROR(__xludf.DUMMYFUNCTION("HLOOKUP($A22, IMPORTRANGE($B$40, CONCAT(VLOOKUP($A22, 'Match Names'!$A$1:$D$22, 2, FALSE),""!C1:R29"")), 29, FALSE)"),252.0) -> 252 | C22: =IFERROR(__xludf.DUMMYFUNCTION("HLOOKUP($A22, IMPORTRANGE($B$41, CONCAT(VLOOKUP($A22, 'Match Names'!$A$1:$D$22, 3, FALSE),""!C1:R29"")), 29, FALSE)"),238.0) -> 238 | D22: =IFERROR(__xludf.DUMMYFUNCTION("HLOOKUP($A22, IMPORTRANGE($B$42, CONCAT(VLOOKUP($A22, 'Match Names'!$A$1:$D$22, 4, FALSE),""!C1:R29"")), 29, FALSE)"),322.0) -> 322 | E22: =SUM(B22:D22) -> 812
A23: Glastonbury | B23: =IFERROR(__xludf.DUMMYFUNCTION("HLOOKUP($A23, IMPORTRANGE($B$40, CONCAT(VLOOKUP($A23, 'Match Names'!$A$1:$D$22, 2, FALSE),""!C1:R29"")), 29, FALSE)"),16.0) -> 16 | C23: =IFERROR(__xludf.DUMMYFUNCTION("HLOOKUP($A23, IMPORTRANGE($B$41, CONCAT(VLOOKUP($A23, 'Match Names'!$A$1:$D$22, 3, FALSE),""!C1:R29"")), 29, FALSE)"),8.0) -> 8 | D23: =IFERROR(__xludf.DUMMYFUNCTION("HLOOKUP($A23, IMPORTRANGE($B$42, CONCAT(VLOOKUP($A23, 'Match Names'!$A$1:$D$22, 4, FALSE),""!C1:R29"")), 29, FALSE)"),12.0) -> 12 | E23: =SUM(B23:D23) -> 36
A40: Prelim Round 1 Spreadsheet | B40: https://docs.google.com/spreadsheets/d/1xIzECe7aNndzt0hqqFOHk_CBewZtwYpEZ1_9ljU4DrE/edit#gid=1640670551
A41: Prelim Round 2 Spreadsheet | B41: https://docs.google.com/spreadsheets/d/115_83cmXVItW0frF_mp6wnNfNAj63wlpF6v2wcXgJrU/edit#gid=0
A42: Prelim Round 3 Spreadsheet | B42: https://docs.google.com/spreadsheets/d/1epChxX7xpqa0FpCzekFs4W6lBQOnPeFmcxX2fWD6lc8/edit#gid=0

Sheet Prelim Rankings
B1: Prelims
A2: TEAMS | B2: 1 | C2: 2 | D2: 3 | E2: TOTAL POINTS
A3: {=SORT('Prelim Rankings Unsorted'!A3:E23, 5, FALSE, 1, TRUE)} -> Blue Rhinobeetles | B3: 252 | C3: 238 | D3: 322 | E3: 812
A4: The Catecholomines | B4: 288 | C4: 276 | D4: 202 | E4: 766
A5: Banana Corp | B5: 304 | C5: 326 | D5: 114 | E5: 744
A6: IDIOM | B6: 210 | C6: 238 | D6: 164 | E6: 612
A7: Sacramento Country Day School | B7: 222 | C7: 198 | D7: 190 | E7: 610
A8: The Mother Doers | B8: 66 | C8: 183 | D8: 300 | E8: 549
A9: Galena Popsicles | B9: 234 | C9: 222 | D9: 80 | E9: 536
A10: Jerry is a Nerd | B10: 122 | C10: 204 | D10: 176 | E10: 502
A11: Dear Field | B11: 210 | C11: 78 | D11: 156 | E11: 444
A12: Deer Feeled | B12: 206 | C12: 180 | D12: 42 | E12: 428
A13: Degenerate Matter | B13: 216 | C13: 42 | D13: 170 | E13: 428
A14: Squishy Cats | B14: 130 | C14: 98 | D14: 196 | E14: 424
A15: Scrubby Teletubbies | B15: 224 | C15: 98 | D15: 56 | E15: 378
... A23: Glastonbury | B23: 16 | C23: 8 | D23: 12 | E23: 36

Sheet Player Overall Stats Unsorted
A2: Player | B2: Discord Username | C2: Team | D2: TU Heard | E2: 4s | F2: 0s | G2: -4s | H2: PPG
A3: Daniel | B3: =VLOOKUP(CONCAT(A3, C3), 'Discord Username to Real Name'!C:D, 2, FALSE) -> DanielRocks(UrMom)#5639 | C3: Grammar Kids | D3: =IFERROR(__xludf.DUMMYFUNCTION("(23 - COUNTIF(IFERROR(ARRAYFORMULA(HLOOKUP($B3, IMPORTRANGE('Prelim Rankings Unsorted'!$B$40, CONCAT(VLOOKUP($C3, 'Match Names'!$A$1:$D$22, 2, FALSE), ""!C3:R29"")), ROW($A$1:$A$24), FALSE)), $AA$9:$AA$31), ""=X"")) + (23 - COUNTIF(IFERROR(ARRAYFORMULA(HL"&"OOKUP($B3, IMPORTRANGE('Prelim Rankings Unsorted'!$B$41, CONCAT(VLOOKUP($C3, 'Match Names'!$A$1:$D$22, 3, FALSE), ""!C3:R29"")), ROW($A$1:$A$24), FALSE)), $AA$9:$AA$31), ""=X"")) + (23 - COUNTIF(IFERROR(ARRAYFORMULA(HLOOKUP($B3, IMPORTRANGE('Prelim Rankin"&"gs Unsorted'!$B$42, CONCAT(VLOOKUP($C3, 'Match Names'!$A$1:$D$22, 4, FALSE), ""!C3:R29"")), ROW($A$1:$A$24), FALSE)), $AA$9:$AA$31), ""=X"")) + (23 - COUNTIF(IFERROR(ARRAYFORMULA(HLOOKUP($B3, IMPORTRANGE('Match Names'!$E$23, CONCAT(VLOOKUP($C3, 'Match Nam"&"es'!$1:$22, 5, FALSE), ""!C3:R29"")), ROW($A$1:$A$24), FALSE)), $AA$9:$AA$31), ""=X"")) + (23 - COUNTIF(IFERROR(ARRAYFORMULA(HLOOKUP($B3, IMPORTRANGE('Match Names'!$F$23, CONCAT(VLOOKUP($C3, 'Match Names'!$1:$22, 6, FALSE), ""!C3:R29"")), ROW($A$1:$A$24),"&" FALSE)), $AA$9:$AA$31), ""=X"")) + (23 - COUNTIF(IFERROR(ARRAYFORMULA(HLOOKUP($B3, IMPORTRANGE('Match Names'!$G$23, CONCAT(VLOOKUP($C3, 'Match Names'!$1:$22, 7, FALSE), ""!C3:R29"")), ROW($A$1:$A$24), FALSE)), $AA$9:$AA$31), ""=X"")) + (23 - COUNTIF(IFER"&"ROR(ARRAYFORMULA(HLOOKUP($B3, IMPORTRANGE('Match Names'!$H$23, CONCAT(VLOOKUP($C3, 'Match Names'!$1:$22, 8, FALSE), ""!C3:R29"")), ROW($A$1:$A$24), FALSE)), $AA$9:$AA$31), ""=X""))"),46.0) -> 46 | E3: =IFERROR(__xludf.DUMMYFUNCTION("COUNTIF(ARRAYFORMULA(HLOOKUP($B3, IMPORTRANGE('Prelim Rankings Unsorted'!$B$40, CONCAT(VLOOKUP($C3, 'Match Names'!$A$1:$D$22, 2, FALSE), ""!C3:R29"")), ROW($A$1:$A$24), FALSE)), ""=4"") + COUNTIF(ARRAYFORMULA(HLOOKUP($B3, IMPORTRANGE('Prelim Rankings Unso"&"rted'!$B$41, CONCAT(VLOOKUP($C3, 'Match Names'!$A$1:$D$22, 3, FALSE), ""!C3:R29"")), ROW($A$1:$A$24), FALSE)), ""=4"") + COUNTIF(ARRAYFORMULA(HLOOKUP($B3, IMPORTRANGE('Prelim Rankings Unsorted'!$B$42, CONCAT(VLOOKUP($C3, 'Match Names'!$A$1:$D$22, 4, FALSE"&"), ""!C3:R29"")), ROW($A$1:$A$24), FALSE)), ""=4"") + COUNTIF(ARRAYFORMULA(HLOOKUP($B3, IMPORTRANGE('Match Names'!$E$23, CONCAT(VLOOKUP($C3, 'Match Names'!$1:$22, 5, FALSE), ""!C3:R29"")), ROW($A$1:$A$24), FALSE)), ""=4"") + COUNTIF(ARRAYFORMULA(HLOOKUP($"&"B3, IMPORTRANGE('Match Names'!$F$23, CONCAT(VLOOKUP($C3, 'Match Names'!$1:$22, 6, FALSE), ""!C3:R29"")), ROW($A$1:$A$24), FALSE)), ""=4"") + COUNTIF(ARRAYFORMULA(HLOOKUP($B3, IMPORTRANGE('Match Names'!$G$23, CONCAT(VLOOKUP($C3, 'Match Names'!$1:$22, 7, FA"&"LSE), ""!C3:R29"")), ROW($A$1:$A$24), FALSE)), ""=4"") + COUNTIF(ARRAYFORMULA(HLOOKUP($B3, IMPORTRANGE('Match Names'!$H$23, CONCAT(VLOOKUP($C3, 'Match Names'!$1:$22, 8, FALSE), ""!C3:R29"")), ROW($A$1:$A$24), FALSE)), ""=4"")"),1.0) -> 1 | F3: =IFERROR(__xludf.DUMMYFUNCTION("COUNTIF(ARRAYFORMULA(HLOOKUP($B3, IMPORTRANGE('Prelim Rankings Unsorted'!$B$40, CONCAT(VLOOKUP($C3, 'Match Names'!$A$1:$D$22, 2, FALSE), ""!C3:R29"")), ROW($A$1:$A$24), FALSE)), ""=0"") + COUNTIF(ARRAYFORMULA(HLOOKUP($B3, IMPORTRANGE('Prelim Rankings Unso"&"rted'!$B$41, CONCAT(VLOOKUP($C3, 'Match Names'!$A$1:$D$22, 3, FALSE), ""!C3:R29"")), ROW($A$1:$A$24), FALSE)), ""=0"") + COUNTIF(ARRAYFORMULA(HLOOKUP($B3, IMPORTRANGE('Prelim Rankings Unsorted'!$B$42, CONCAT(VLOOKUP($C3, 'Match Names'!$A$1:$D$22, 4, FALSE"&"), ""!C3:R29"")), ROW($A$1:$A$24), FALSE)), ""=0"") + COUNTIF(ARRAYFORMULA(HLOOKUP($B3, IMPORTRANGE('Match Names'!$E$23, CONCAT(VLOOKUP($C3, 'Match Names'!$1:$22, 5, FALSE), ""!C3:R29"")), ROW($A$1:$A$24), FALSE)), ""=0"") + COUNTIF(ARRAYFORMULA(HLOOKUP($"&"B3, IMPORTRANGE('Match Names'!$F$23, CONCAT(VLOOKUP($C3, 'Match Names'!$1:$22, 6, FALSE), ""!C3:R29"")), ROW($A$1:$A$24), FALSE)), ""=0"") + COUNTIF(ARRAYFORMULA(HLOOKUP($B3, IMPORTRANGE('Match Names'!$G$23, CONCAT(VLOOKUP($C3, 'Match Names'!$1:$22, 7, FA"&"LSE), ""!C3:R29"")), ROW($A$1:$A$24), FALSE)), ""=0"") + COUNTIF(ARRAYFORMULA(HLOOKUP($B3, IMPORTRANGE('Match Names'!$H$23, CONCAT(VLOOKUP($C3, 'Match Names'!$1:$22, 8, FALSE), ""!C3:R29"")), ROW($A$1:$A$24), FALSE)), ""=0"")"),2.0) -> 2 | G3: =IFERROR(__xludf.DUMMYFUNCTION("COUNTIF(ARRAYFORMULA(HLOOKUP($B3, IMPORTRANGE('Prelim Rankings Unsorted'!$B$40, CONCAT(VLOOKUP($C3, 'Match Names'!$A$1:$D$22, 2, FALSE), ""!C3:R29"")), ROW($A$1:$A$24), FALSE)), ""=-4"") + COUNTIF(ARRAYFORMULA(HLOOKUP($B3, IMPORTRANGE('Prelim Rankings Uns"&"orted'!$B$41, CONCAT(VLOOKUP($C3, 'Match Names'!$A$1:$D$22, 3, FALSE), ""!C3:R29"")), ROW($A$1:$A$24), FALSE)), ""=-4"") + COUNTIF(ARRAYFORMULA(HLOOKUP($B3, IMPORTRANGE('Prelim Rankings Unsorted'!$B$42, CONCAT(VLOOKUP($C3, 'Match Names'!$A$1:$D$22, 4, FAL"&"SE), ""!C3:R29"")), ROW($A$1:$A$24), FALSE)), ""=-4"") + COUNTIF(ARRAYFORMULA(HLOOKUP($B3, IMPORTRANGE('Match Names'!$E$23, CONCAT(VLOOKUP($C3, 'Match Names'!$1:$22, 5, FALSE), ""!C3:R29"")), ROW($A$1:$A$24), FALSE)), ""=-4"") + COUNTIF(ARRAYFORMULA(HLOOK"&"UP($B3, IMPORTRANGE('Match Names'!$F$23, CONCAT(VLOOKUP($C3, 'Match Names'!$1:$22, 6, FALSE), ""!C3:R29"")), ROW($A$1:$A$24), FALSE)), ""=-4"") + COUNTIF(ARRAYFORMULA(HLOOKUP($B3, IMPORTRANGE('Match Names'!$G$23, CONCAT(VLOOKUP($C3, 'Match Names'!$1:$22, "&"7, FALSE), ""!C3:R29"")), ROW($A$1:$A$24), FALSE)), ""=-4"") + COUNTIF(ARRAYFORMULA(HLOOKUP($B3, IMPORTRANGE('Match Names'!$H$23, CONCAT(VLOOKUP($C3, 'Match Names'!$1:$22, 8, FALSE), ""!C3:R29"")), ROW($A$1:$A$24), FALSE)), ""=-4"")"),1.0) -> 1 | H3: =IFERROR(ROUND(((E3*4)+(G3*-4))/(D3/23), 2), 0) -> 0
A4: Running Runin | B4: =VLOOKUP(CONCAT(A4, C4), 'Discord Username to Real Name'!C:D, 2, FALSE) -> Running Runin#5021 | C4: Grammar Kids | D4: =IFERROR(__xludf.DUMMYFUNCTION("(23 - COUNTIF(IFERROR(ARRAYFORMULA(HLOOKUP($B4, IMPORTRANGE('Prelim Rankings Unsorted'!$B$40, CONCAT(VLOOKUP($C4, 'Match Names'!$A$1:$D$22, 2, FALSE), ""!C3:R29"")), ROW($A$1:$A$24), FALSE)), $AA$9:$AA$31), ""=X"")) + (23 - COUNTIF(IFERROR(ARRAYFORMULA(HL"&"OOKUP($B4, IMPORTRANGE('Prelim Rankings Unsorted'!$B$41, CONCAT(VLOOKUP($C4, 'Match Names'!$A$1:$D$22, 3, FALSE), ""!C3:R29"")), ROW($A$1:$A$24), FALSE)), $AA$9:$AA$31), ""=X"")) + (23 - COUNTIF(IFERROR(ARRAYFORMULA(HLOOKUP($B4, IMPORTRANGE('Prelim Rankin"&"gs Unsorted'!$B$42, CONCAT(VLOOKUP($C4, 'Match Names'!$A$1:$D$22, 4, FALSE), ""!C3:R29"")), ROW($A$1:$A$24), FALSE)), $AA$9:$AA$31), ""=X"")) + (23 - COUNTIF(IFERROR(ARRAYFORMULA(HLOOKUP($B4, IMPORTRANGE('Match Names'!$E$23, CONCAT(VLOOKUP($C4, 'Match Nam"&"es'!$1:$22, 5, FALSE), ""!C3:R29"")), ROW($A$1:$A$24), FALSE)), $AA$9:$AA$31), ""=X"")) + (23 - COUNTIF(IFERROR(ARRAYFORMULA(HLOOKUP($B4, IMPORTRANGE('Match Names'!$F$23, CONCAT(VLOOKUP($C4, 'Match Names'!$1:$22, 6, FALSE), ""!C3:R29"")), ROW($A$1:$A$24),"&" FALSE)), $AA$9:$AA$31), ""=X"")) + (23 - COUNTIF(IFERROR(ARRAYFORMULA(HLOOKUP($B4, IMPORTRANGE('Match Names'!$G$23, CONCAT(VLOOKUP($C4, 'Match Names'!$1:$22, 7, FALSE), ""!C3:R29"")), ROW($A$1:$A$24), FALSE)), $AA$9:$AA$31), ""=X"")) + (23 - COUNTIF(IFER"&"ROR(ARRAYFORMULA(HLOOKUP($B4, IMPORTRANGE('Match Names'!$H$23, CONCAT(VLOOKUP($C4, 'Match Names'!$1:$22, 8, FALSE), ""!C3:R29"")), ROW($A$1:$A$24), FALSE)), $AA$9:$AA$31), ""=X""))"),0.0) -> 0 | E4: =IFERROR(__xludf.DUMMYFUNCTION("COUNTIF(ARRAYFORMULA(HLOOKUP($B4, IMPORTRANGE('Prelim Rankings Unsorted'!$B$40, CONCAT(VLOOKUP($C4, 'Match Names'!$A$1:$D$22, 2, FALSE), ""!C3:R29"")), ROW($A$1:$A$24), FALSE)), ""=4"") + COUNTIF(ARRAYFORMULA(HLOOKUP($B4, IMPORTRANGE('Prelim Rankings Unso"&"rted'!$B$41, CONCAT(VLOOKUP($C4, 'Match Names'!$A$1:$D$22, 3, FALSE), ""!C3:R29"")), ROW($A$1:$A$24), FALSE)), ""=4"") + COUNTIF(ARRAYFORMULA(HLOOKUP($B4, IMPORTRANGE('Prelim Rankings Unsorted'!$B$42, CONCAT(VLOOKUP($C4, 'Match Names'!$A$1:$D$22, 4, FALSE"&"), ""!C3:R29"")), ROW($A$1:$A$24), FALSE)), ""=4"") + COUNTIF(ARRAYFORMULA(HLOOKUP($B4, IMPORTRANGE('Match Names'!$E$23, CONCAT(VLOOKUP($C4, 'Match Names'!$1:$22, 5, FALSE), ""!C3:R29"")), ROW($A$1:$A$24), FALSE)), ""=4"") + COUNTIF(ARRAYFORMULA(HLOOKUP($"&"B4, IMPORTRANGE('Match Names'!$F$23, CONCAT(VLOOKUP($C4, 'Match Names'!$1:$22, 6, FALSE), ""!C3:R29"")), ROW($A$1:$A$24), FALSE)), ""=4"") + COUNTIF(ARRAYFORMULA(HLOOKUP($B4, IMPORTRANGE('Match Names'!$G$23, CONCAT(VLOOKUP($C4, 'Match Names'!$1:$22, 7, FA"&"LSE), ""!C3:R29"")), ROW($A$1:$A$24), FALSE)), ""=4"") + COUNTIF(ARRAYFORMULA(HLOOKUP($B4, IMPORTRANGE('Match Names'!$H$23, CONCAT(VLOOKUP($C4, 'Match Names'!$1:$22, 8, FALSE), ""!C3:R29"")), ROW($A$1:$A$24), FALSE)), ""=4"")"),0.0) -> 0 | F4: =IFERROR(__xludf.DUMMYFUNCTION("COUNTIF(ARRAYFORMULA(HLOOKUP($B4, IMPORTRANGE('Prelim Rankings Unsorted'!$B$40, CONCAT(VLOOKUP($C4, 'Match Names'!$A$1:$D$22, 2, FALSE), ""!C3:R29"")), ROW($A$1:$A$24), FALSE)), ""=0"") + COUNTIF(ARRAYFORMULA(HLOOKUP($B4, IMPORTRANGE('Prelim Rankings Unso"&"rted'!$B$41, CONCAT(VLOOKUP($C4, 'Match Names'!$A$1:$D$22, 3, FALSE), ""!C3:R29"")), ROW($A$1:$A$24), FALSE)), ""=0"") + COUNTIF(ARRAYFORMULA(HLOOKUP($B4, IMPORTRANGE('Prelim Rankings Unsorted'!$B$42, CONCAT(VLOOKUP($C4, 'Match Names'!$A$1:$D$22, 4, FALSE"&"), ""!C3:R29"")), ROW($A$1:$A$24), FALSE)), ""=0"") + COUNTIF(ARRAYFORMULA(HLOOKUP($B4, IMPORTRANGE('Match Names'!$E$23, CONCAT(VLOOKUP($C4, 'Match Names'!$1:$22, 5, FALSE), ""!C3:R29"")), ROW($A$1:$A$24), FALSE)), ""=0"") + COUNTIF(ARRAYFORMULA(HLOOKUP($"&"B4, IMPORTRANGE('Match Names'!$F$23, CONCAT(VLOOKUP($C4, 'Match Names'!$1:$22, 6, FALSE), ""!C3:R29"")), ROW($A$1:$A$24), FALSE)), ""=0"") + COUNTIF(ARRAYFORMULA(HLOOKUP($B4, IMPORTRANGE('Match Names'!$G$23, CONCAT(VLOOKUP($C4, 'Match Names'!$1:$22, 7, FA"&"LSE), ""!C3:R29"")), ROW($A$1:$A$24), FALSE)), ""=0"") + COUNTIF(ARRAYFORMULA(HLOOKUP($B4, IMPORTRANGE('Match Names'!$H$23, CONCAT(VLOOKUP($C4, 'Match Names'!$1:$22, 8, FALSE), ""!C3:R29"")), ROW($A$1:$A$24), FALSE)), ""=0"")"),0.0) -> 0 | G4: =IFERROR(__xludf.DUMMYFUNCTION("COUNTIF(ARRAYFORMULA(HLOOKUP($B4, IMPORTRANGE('Prelim Rankings Unsorted'!$B$40, CONCAT(VLOOKUP($C4, 'Match Names'!$A$1:$D$22, 2, FALSE), ""!C3:R29"")), ROW($A$1:$A$24), FALSE)), ""=-4"") + COUNTIF(ARRAYFORMULA(HLOOKUP($B4, IMPORTRANGE('Prelim Rankings Uns"&"orted'!$B$41, CONCAT(VLOOKUP($C4, 'Match Names'!$A$1:$D$22, 3, FALSE), ""!C3:R29"")), ROW($A$1:$A$24), FALSE)), ""=-4"") + COUNTIF(ARRAYFORMULA(HLOOKUP($B4, IMPORTRANGE('Prelim Rankings Unsorted'!$B$42, CONCAT(VLOOKUP($C4, 'Match Names'!$A$1:$D$22, 4, FAL"&"SE), ""!C3:R29"")), ROW($A$1:$A$24), FALSE)), ""=-4"") + COUNTIF(ARRAYFORMULA(HLOOKUP($B4, IMPORTRANGE('Match Names'!$E$23, CONCAT(VLOOKUP($C4, 'Match Names'!$1:$22, 5, FALSE), ""!C3:R29"")), ROW($A$1:$A$24), FALSE)), ""=-4"") + COUNTIF(ARRAYFORMULA(HLOOK"&"UP($B4, IMPORTRANGE('Match Names'!$F$23, CONCAT(VLOOKUP($C4, 'Match Names'!$1:$22, 6, FALSE), ""!C3:R29"")), ROW($A$1:$A$24), FALSE)), ""=-4"") + COUNTIF(ARRAYFORMULA(HLOOKUP($B4, IMPORTRANGE('Match Names'!$G$23, CONCAT(VLOOKUP($C4, 'Match Names'!$1:$22, "&"7, FALSE), ""!C3:R29"")), ROW($A$1:$A$24), FALSE)), ""=-4"") + COUNTIF(ARRAYFORMULA(HLOOKUP($B4, IMPORTRANGE('Match Names'!$H$23, CONCAT(VLOOKUP($C4, 'Match Names'!$1:$22, 8, FALSE), ""!C3:R29"")), ROW($A$1:$A$24), FALSE)), ""=-4"")"),0.0) -> 0 | H4: =IFERROR(ROUND(((E4*4)+(G4*-4))/(D4/23), 2), 0) -> 0
A5: Ava | B5: =VLOOKUP(CONCAT(A5, C5), 'Discord Username to Real Name'!C:D, 2, FALSE) -> avaa#8678 | C5: Grammar Kids | D5: =IFERROR(__xludf.DUMMYFUNCTION("(23 - COUNTIF(IFERROR(ARRAYFORMULA(HLOOKUP($B5, IMPORTRANGE('Prelim Rankings Unsorted'!$B$40, CONCAT(VLOOKUP($C5, 'Match Names'!$A$1:$D$22, 2, FALSE), ""!C3:R29"")), ROW($A$1:$A$24), FALSE)), $AA$9:$AA$31), ""=X"")) + (23 - COUNTIF(IFERROR(ARRAYFORMULA(HL"&"OOKUP($B5, IMPORTRANGE('Prelim Rankings Unsorted'!$B$41, CONCAT(VLOOKUP($C5, 'Match Names'!$A$1:$D$22, 3, FALSE), ""!C3:R29"")), ROW($A$1:$A$24), FALSE)), $AA$9:$AA$31), ""=X"")) + (23 - COUNTIF(IFERROR(ARRAYFORMULA(HLOOKUP($B5, IMPORTRANGE('Prelim Rankin"&"gs Unsorted'!$B$42, CONCAT(VLOOKUP($C5, 'Match Names'!$A$1:$D$22, 4, FALSE), ""!C3:R29"")), ROW($A$1:$A$24), FALSE)), $AA$9:$AA$31), ""=X"")) + (23 - COUNTIF(IFERROR(ARRAYFORMULA(HLOOKUP($B5, IMPORTRANGE('Match Names'!$E$23, CONCAT(VLOOKUP($C5, 'Match Nam"&"es'!$1:$22, 5, FALSE), ""!C3:R29"")), ROW($A$1:$A$24), FALSE)), $AA$9:$AA$31), ""=X"")) + (23 - COUNTIF(IFERROR(ARRAYFORMULA(HLOOKUP($B5, IMPORTRANGE('Match Names'!$F$23, CONCAT(VLOOKUP($C5, 'Match Names'!$1:$22, 6, FALSE), ""!C3:R29"")), ROW($A$1:$A$24),"&" FALSE)), $AA$9:$AA$31), ""=X"")) + (23 - COUNTIF(IFERROR(ARRAYFORMULA(HLOOKUP($B5, IMPORTRANGE('Match Names'!$G$23, CONCAT(VLOOKUP($C5, 'Match Names'!$1:$22, 7, FALSE), ""!C3:R29"")), ROW($A$1:$A$24), FALSE)), $AA$9:$AA$31), ""=X"")) + (23 - COUNTIF(IFER"&"ROR(ARRAYFORMULA(HLOOKUP($B5, IMPORTRANGE('Match Names'!$H$23, CONCAT(VLOOKUP($C5, 'Match Names'!$1:$22, 8, FALSE), ""!C3:R29"")), ROW($A$1:$A$24), FALSE)), $AA$9:$AA$31), ""=X""))"),44.0) -> 44 | E5: =IFERROR(__xludf.DUMMYFUNCTION("COUNTIF(ARRAYFORMULA(HLOOKUP($B5, IMPORTRANGE('Prelim Rankings Unsorted'!$B$40, CONCAT(VLOOKUP($C5, 'Match Names'!$A$1:$D$22, 2, FALSE), ""!C3:R29"")), ROW($A$1:$A$24), FALSE)), ""=4"") + COUNTIF(ARRAYFORMULA(HLOOKUP($B5, IMPORTRANGE('Prelim Rankings Unso"&"rted'!$B$41, CONCAT(VLOOKUP($C5, 'Match Names'!$A$1:$D$22, 3, FALSE), ""!C3:R29"")), ROW($A$1:$A$24), FALSE)), ""=4"") + COUNTIF(ARRAYFORMULA(HLOOKUP($B5, IMPORTRANGE('Prelim Rankings Unsorted'!$B$42, CONCAT(VLOOKUP($C5, 'Match Names'!$A$1:$D$22, 4, FALSE"&"), ""!C3:R29"")), ROW($A$1:$A$24), FALSE)), ""=4"") + COUNTIF(ARRAYFORMULA(HLOOKUP($B5, IMPORTRANGE('Match Names'!$E$23, CONCAT(VLOOKUP($C5, 'Match Names'!$1:$22, 5, FALSE), ""!C3:R29"")), ROW($A$1:$A$24), FALSE)), ""=4"") + COUNTIF(ARRAYFORMULA(HLOOKUP($"&"B5, IMPORTRANGE('Match Names'!$F$23, CONCAT(VLOOKUP($C5, 'Match Names'!$1:$22, 6, FALSE), ""!C3:R29"")), ROW($A$1:$A$24), FALSE)), ""=4"") + COUNTIF(ARRAYFORMULA(HLOOKUP($B5, IMPORTRANGE('Match Names'!$G$23, CONCAT(VLOOKUP($C5, 'Match Names'!$1:$22, 7, FA"&"LSE), ""!C3:R29"")), ROW($A$1:$A$24), FALSE)), ""=4"") + COUNTIF(ARRAYFORMULA(HLOOKUP($B5, IMPORTRANGE('Match Names'!$H$23, CONCAT(VLOOKUP($C5, 'Match Names'!$1:$22, 8, FALSE), ""!C3:R29"")), ROW($A$1:$A$24), FALSE)), ""=4"")"),1.0) -> 1 | F5: =IFERROR(__xludf.DUMMYFUNCTION("COUNTIF(ARRAYFORMULA(HLOOKUP($B5, IMPORTRANGE('Prelim Rankings Unsorted'!$B$40, CONCAT(VLOOKUP($C5, 'Match Names'!$A$1:$D$22, 2, FALSE), ""!C3:R29"")), ROW($A$1:$A$24), FALSE)), ""=0"") + COUNTIF(ARRAYFORMULA(HLOOKUP($B5, IMPORTRANGE('Prelim Rankings Unso"&"rted'!$B$41, CONCAT(VLOOKUP($C5, 'Match Names'!$A$1:$D$22, 3, FALSE), ""!C3:R29"")), ROW($A$1:$A$24), FALSE)), ""=0"") + COUNTIF(ARRAYFORMULA(HLOOKUP($B5, IMPORTRANGE('Prelim Rankings Unsorted'!$B$42, CONCAT(VLOOKUP($C5, 'Match Names'!$A$1:$D$22, 4, FALSE"&"), ""!C3:R29"")), ROW($A$1:$A$24), FALSE)), ""=0"") + COUNTIF(ARRAYFORMULA(HLOOKUP($B5, IMPORTRANGE('Match Names'!$E$23, CONCAT(VLOOKUP($C5, 'Match Names'!$1:$22, 5, FALSE), ""!C3:R29"")), ROW($A$1:$A$24), FALSE)), ""=0"") + COUNTIF(ARRAYFORMULA(HLOOKUP($"&"B5, IMPORTRANGE('Match Names'!$F$23, CONCAT(VLOOKUP($C5, 'Match Names'!$1:$22, 6, FALSE), ""!C3:R29"")), ROW($A$1:$A$24), FALSE)), ""=0"") + COUNTIF(ARRAYFORMULA(HLOOKUP($B5, IMPORTRANGE('Match Names'!$G$23, CONCAT(VLOOKUP($C5, 'Match Names'!$1:$22, 7, FA"&"LSE), ""!C3:R29"")), ROW($A$1:$A$24), FALSE)), ""=0"") + COUNTIF(ARRAYFORMULA(HLOOKUP($B5, IMPORTRANGE('Match Names'!$H$23, CONCAT(VLOOKUP($C5, 'Match Names'!$1:$22, 8, FALSE), ""!C3:R29"")), ROW($A$1:$A$24), FALSE)), ""=0"")"),1.0) -> 1 | G5: =IFERROR(__xludf.DUMMYFUNCTION("COUNTIF(ARRAYFORMULA(HLOOKUP($B5, IMPORTRANGE('Prelim Rankings Unsorted'!$B$40, CONCAT(VLOOKUP($C5, 'Match Names'!$A$1:$D$22, 2, FALSE), ""!C3:R29"")), ROW($A$1:$A$24), FALSE)), ""=-4"") + COUNTIF(ARRAYFORMULA(HLOOKUP($B5, IMPORTRANGE('Prelim Rankings Uns"&"orted'!$B$41, CONCAT(VLOOKUP($C5, 'Match Names'!$A$1:$D$22, 3, FALSE), ""!C3:R29"")), ROW($A$1:$A$24), FALSE)), ""=-4"") + COUNTIF(ARRAYFORMULA(HLOOKUP($B5, IMPORTRANGE('Prelim Rankings Unsorted'!$B$42, CONCAT(VLOOKUP($C5, 'Match Names'!$A$1:$D$22, 4, FAL"&"SE), ""!C3:R29"")), ROW($A$1:$A$24), FALSE)), ""=-4"") + COUNTIF(ARRAYFORMULA(HLOOKUP($B5, IMPORTRANGE('Match Names'!$E$23, CONCAT(VLOOKUP($C5, 'Match Names'!$1:$22, 5, FALSE), ""!C3:R29"")), ROW($A$1:$A$24), FALSE)), ""=-4"") + COUNTIF(ARRAYFORMULA(HLOOK"&"UP($B5, IMPORTRANGE('Match Names'!$F$23, CONCAT(VLOOKUP($C5, 'Match Names'!$1:$22, 6, FALSE), ""!C3:R29"")), ROW($A$1:$A$24), FALSE)), ""=-4"") + COUNTIF(ARRAYFORMULA(HLOOKUP($B5, IMPORTRANGE('Match Names'!$G$23, CONCAT(VLOOKUP($C5, 'Match Names'!$1:$22, "&"7, FALSE), ""!C3:R29"")), ROW($A$1:$A$24), FALSE)), ""=-4"") + COUNTIF(ARRAYFORMULA(HLOOKUP($B5, IMPORTRANGE('Match Names'!$H$23, CONCAT(VLOOKUP($C5, 'Match Names'!$1:$22, 8, FALSE), ""!C3:R29"")), ROW($A$1:$A$24), FALSE)), ""=-4"")"),0.0) -> 0 | H5: =IFERROR(ROUND(((E5*4)+(G5*-4))/(D5/23), 2), 0) -> 2.09
A6: Kevin | B6: =VLOOKUP(CONCAT(A6, C6), 'Discord Username to Real Name'!C:D, 2, FALSE) -> Kevin Yang#3870 | C6: Grammar Kids | D6: =IFERROR(__xludf.DUMMYFUNCTION("(23 - COUNTIF(IFERROR(ARRAYFORMULA(HLOOKUP($B6, IMPORTRANGE('Prelim Rankings Unsorted'!$B$40, CONCAT(VLOOKUP($C6, 'Match Names'!$A$1:$D$22, 2, FALSE), ""!C3:R29"")), ROW($A$1:$A$24), FALSE)), $AA$9:$AA$31), ""=X"")) + (23 - COUNTIF(IFERROR(ARRAYFORMULA(HL"&"OOKUP($B6, IMPORTRANGE('Prelim Rankings Unsorted'!$B$41, CONCAT(VLOOKUP($C6, 'Match Names'!$A$1:$D$22, 3, FALSE), ""!C3:R29"")), ROW($A$1:$A$24), FALSE)), $AA$9:$AA$31), ""=X"")) + (23 - COUNTIF(IFERROR(ARRAYFORMULA(HLOOKUP($B6, IMPORTRANGE('Prelim Rankin"&"gs Unsorted'!$B$42, CONCAT(VLOOKUP($C6, 'Match Names'!$A$1:$D$22, 4, FALSE), ""!C3:R29"")), ROW($A$1:$A$24), FALSE)), $AA$9:$AA$31), ""=X"")) + (23 - COUNTIF(IFERROR(ARRAYFORMULA(HLOOKUP($B6, IMPORTRANGE('Match Names'!$E$23, CONCAT(VLOOKUP($C6, 'Match Nam"&"es'!$1:$22, 5, FALSE), ""!C3:R29"")), ROW($A$1:$A$24), FALSE)), $AA$9:$AA$31), ""=X"")) + (23 - COUNTIF(IFERROR(ARRAYFORMULA(HLOOKUP($B6, IMPORTRANGE('Match Names'!$F$23, CONCAT(VLOOKUP($C6, 'Match Names'!$1:$22, 6, FALSE), ""!C3:R29"")), ROW($A$1:$A$24),"&" FALSE)), $AA$9:$AA$31), ""=X"")) + (23 - COUNTIF(IFERROR(ARRAYFORMULA(HLOOKUP($B6, IMPORTRANGE('Match Names'!$G$23, CONCAT(VLOOKUP($C6, 'Match Names'!$1:$22, 7, FALSE), ""!C3:R29"")), ROW($A$1:$A$24), FALSE)), $AA$9:$AA$31), ""=X"")) + (23 - COUNTIF(IFER"&"ROR(ARRAYFORMULA(HLOOKUP($B6, IMPORTRANGE('Match Names'!$H$23, CONCAT(VLOOKUP($C6, 'Match Names'!$1:$22, 8, FALSE), ""!C3:R29"")), ROW($A$1:$A$24), FALSE)), $AA$9:$AA$31), ""=X""))"),69.0) -> 69 | E6: =IFERROR(__xludf.DUMMYFUNCTION("COUNTIF(ARRAYFORMULA(HLOOKUP($B6, IMPORTRANGE('Prelim Rankings Unsorted'!$B$40, CONCAT(VLOOKUP($C6, 'Match Names'!$A$1:$D$22, 2, FALSE), ""!C3:R29"")), ROW($A$1:$A$24), FALSE)), ""=4"") + COUNTIF(ARRAYFORMULA(HLOOKUP($B6, IMPORTRANGE('Prelim Rankings Unso"&"rted'!$B$41, CONCAT(VLOOKUP($C6, 'Match Names'!$A$1:$D$22, 3, FALSE), ""!C3:R29"")), ROW($A$1:$A$24), FALSE)), ""=4"") + COUNTIF(ARRAYFORMULA(HLOOKUP($B6, IMPORTRANGE('Prelim Rankings Unsorted'!$B$42, CONCAT(VLOOKUP($C6, 'Match Names'!$A$1:$D$22, 4, FALSE"&"), ""!C3:R29"")), ROW($A$1:$A$24), FALSE)), ""=4"") + COUNTIF(ARRAYFORMULA(HLOOKUP($B6, IMPORTRANGE('Match Names'!$E$23, CONCAT(VLOOKUP($C6, 'Match Names'!$1:$22, 5, FALSE), ""!C3:R29"")), ROW($A$1:$A$24), FALSE)), ""=4"") + COUNTIF(ARRAYFORMULA(HLOOKUP($"&"B6, IMPORTRANGE('Match Names'!$F$23, CONCAT(VLOOKUP($C6, 'Match Names'!$1:$22, 6, FALSE), ""!C3:R29"")), ROW($A$1:$A$24), FALSE)), ""=4"") + COUNTIF(ARRAYFORMULA(HLOOKUP($B6, IMPORTRANGE('Match Names'!$G$23, CONCAT(VLOOKUP($C6, 'Match Names'!$1:$22, 7, FA"&"LSE), ""!C3:R29"")), ROW($A$1:$A$24), FALSE)), ""=4"") + COUNTIF(ARRAYFORMULA(HLOOKUP($B6, IMPORTRANGE('Match Names'!$H$23, CONCAT(VLOOKUP($C6, 'Match Names'!$1:$22, 8, FALSE), ""!C3:R29"")), ROW($A$1:$A$24), FALSE)), ""=4"")"),3.0) -> 3 | F6: =IFERROR(__xludf.DUMMYFUNCTION("COUNTIF(ARRAYFORMULA(HLOOKUP($B6, IMPORTRANGE('Prelim Rankings Unsorted'!$B$40, CONCAT(VLOOKUP($C6, 'Match Names'!$A$1:$D$22, 2, FALSE), ""!C3:R29"")), ROW($A$1:$A$24), FALSE)), ""=0"") + COUNTIF(ARRAYFORMULA(HLOOKUP($B6, IMPORTRANGE('Prelim Rankings Unso"&"rted'!$B$41, CONCAT(VLOOKUP($C6, 'Match Names'!$A$1:$D$22, 3, FALSE), ""!C3:R29"")), ROW($A$1:$A$24), FALSE)), ""=0"") + COUNTIF(ARRAYFORMULA(HLOOKUP($B6, IMPORTRANGE('Prelim Rankings Unsorted'!$B$42, CONCAT(VLOOKUP($C6, 'Match Names'!$A$1:$D$22, 4, FALSE"&"), ""!C3:R29"")), ROW($A$1:$A$24), FALSE)), ""=0"") + COUNTIF(ARRAYFORMULA(HLOOKUP($B6, IMPORTRANGE('Match Names'!$E$23, CONCAT(VLOOKUP($C6, 'Match Names'!$1:$22, 5, FALSE), ""!C3:R29"")), ROW($A$1:$A$24), FALSE)), ""=0"") + COUNTIF(ARRAYFORMULA(HLOOKUP($"&"B6, IMPORTRANGE('Match Names'!$F$23, CONCAT(VLOOKUP($C6, 'Match Names'!$1:$22, 6, FALSE), ""!C3:R29"")), ROW($A$1:$A$24), FALSE)), ""=0"") + COUNTIF(ARRAYFORMULA(HLOOKUP($B6, IMPORTRANGE('Match Names'!$G$23, CONCAT(VLOOKUP($C6, 'Match Names'!$1:$22, 7, FA"&"LSE), ""!C3:R29"")), ROW($A$1:$A$24), FALSE)), ""=0"") + COUNTIF(ARRAYFORMULA(HLOOKUP($B6, IMPORTRANGE('Match Names'!$H$23, CONCAT(VLOOKUP($C6, 'Match Names'!$1:$22, 8, FALSE), ""!C3:R29"")), ROW($A$1:$A$24), FALSE)), ""=0"")"),1.0) -> 1 | G6: =IFERROR(__xludf.DUMMYFUNCTION("COUNTIF(ARRAYFORMULA(HLOOKUP($B6, IMPORTRANGE('Prelim Rankings Unsorted'!$B$40, CONCAT(VLOOKUP($C6, 'Match Names'!$A$1:$D$22, 2, FALSE), ""!C3:R29"")), ROW($A$1:$A$24), FALSE)), ""=-4"") + COUNTIF(ARRAYFORMULA(HLOOKUP($B6, IMPORTRANGE('Prelim Rankings Uns"&"orted'!$B$41, CONCAT(VLOOKUP($C6, 'Match Names'!$A$1:$D$22, 3, FALSE), ""!C3:R29"")), ROW($A$1:$A$24), FALSE)), ""=-4"") + COUNTIF(ARRAYFORMULA(HLOOKUP($B6, IMPORTRANGE('Prelim Rankings Unsorted'!$B$42, CONCAT(VLOOKUP($C6, 'Match Names'!$A$1:$D$22, 4, FAL"&"SE), ""!C3:R29"")), ROW($A$1:$A$24), FALSE)), ""=-4"") + COUNTIF(ARRAYFORMULA(HLOOKUP($B6, IMPORTRANGE('Match Names'!$E$23, CONCAT(VLOOKUP($C6, 'Match Names'!$1:$22, 5, FALSE), ""!C3:R29"")), ROW($A$1:$A$24), FALSE)), ""=-4"") + COUNTIF(ARRAYFORMULA(HLOOK"&"UP($B6, IMPORTRANGE('Match Names'!$F$23, CONCAT(VLOOKUP($C6, 'Match Names'!$1:$22, 6, FALSE), ""!C3:R29"")), ROW($A$1:$A$24), FALSE)), ""=-4"") + COUNTIF(ARRAYFORMULA(HLOOKUP($B6, IMPORTRANGE('Match Names'!$G$23, CONCAT(VLOOKUP($C6, 'Match Names'!$1:$22, "&"7, FALSE), ""!C3:R29"")), ROW($A$1:$A$24), FALSE)), ""=-4"") + COUNTIF(ARRAYFORMULA(HLOOKUP($B6, IMPORTRANGE('Match Names'!$H$23, CONCAT(VLOOKUP($C6, 'Match Names'!$1:$22, 8, FALSE), ""!C3:R29"")), ROW($A$1:$A$24), FALSE)), ""=-4"")"),0.0) -> 0 | H6: =IFERROR(ROUND(((E6*4)+(G6*-4))/(D6/23), 2), 0) -> 4
A7: Bulala | B7: =VLOOKUP(CONCAT(A7, C7), 'Discord Username to Real Name'!C:D, 2, FALSE) | C7: Grammar Kids | D7: =IFERROR(__xludf.DUMMYFUNCTION("(23 - COUNTIF(IFERROR(ARRAYFORMULA(HLOOKUP($B7, IMPORTRANGE('Prelim Rankings Unsorted'!$B$40, CONCAT(VLOOKUP($C7, 'Match Names'!$A$1:$D$22, 2, FALSE), ""!C3:R29"")), ROW($A$1:$A$24), FALSE)), $AA$9:$AA$31), ""=X"")) + (23 - COUNTIF(IFERROR(ARRAYFORMULA(HL"&"OOKUP($B7, IMPORTRANGE('Prelim Rankings Unsorted'!$B$41, CONCAT(VLOOKUP($C7, 'Match Names'!$A$1:$D$22, 3, FALSE), ""!C3:R29"")), ROW($A$1:$A$24), FALSE)), $AA$9:$AA$31), ""=X"")) + (23 - COUNTIF(IFERROR(ARRAYFORMULA(HLOOKUP($B7, IMPORTRANGE('Prelim Rankin"&"gs Unsorted'!$B$42, CONCAT(VLOOKUP($C7, 'Match Names'!$A$1:$D$22, 4, FALSE), ""!C3:R29"")), ROW($A$1:$A$24), FALSE)), $AA$9:$AA$31), ""=X"")) + (23 - COUNTIF(IFERROR(ARRAYFORMULA(HLOOKUP($B7, IMPORTRANGE('Match Names'!$E$23, CONCAT(VLOOKUP($C7, 'Match Nam"&"es'!$1:$22, 5, FALSE), ""!C3:R29"")), ROW($A$1:$A$24), FALSE)), $AA$9:$AA$31), ""=X"")) + (23 - COUNTIF(IFERROR(ARRAYFORMULA(HLOOKUP($B7, IMPORTRANGE('Match Names'!$F$23, CONCAT(VLOOKUP($C7, 'Match Names'!$1:$22, 6, FALSE), ""!C3:R29"")), ROW($A$1:$A$24),"&" FALSE)), $AA$9:$AA$31), ""=X"")) + (23 - COUNTIF(IFERROR(ARRAYFORMULA(HLOOKUP($B7, IMPORTRANGE('Match Names'!$G$23, CONCAT(VLOOKUP($C7, 'Match Names'!$1:$22, 7, FALSE), ""!C3:R29"")), ROW($A$1:$A$24), FALSE)), $AA$9:$AA$31), ""=X"")) + (23 - COUNTIF(IFER"&"ROR(ARRAYFORMULA(HLOOKUP($B7, IMPORTRANGE('Match Names'!$H$23, CONCAT(VLOOKUP($C7, 'Match Names'!$1:$22, 8, FALSE), ""!C3:R29"")), ROW($A$1:$A$24), FALSE)), $AA$9:$AA$31), ""=X""))"),0.0) -> 0 | E7: =IFERROR(__xludf.DUMMYFUNCTION("COUNTIF(ARRAYFORMULA(HLOOKUP($B7, IMPORTRANGE('Prelim Rankings Unsorted'!$B$40, CONCAT(VLOOKUP($C7, 'Match Names'!$A$1:$D$22, 2, FALSE), ""!C3:R29"")), ROW($A$1:$A$24), FALSE)), ""=4"") + COUNTIF(ARRAYFORMULA(HLOOKUP($B7, IMPORTRANGE('Prelim Rankings Unso"&"rted'!$B$41, CONCAT(VLOOKUP($C7, 'Match Names'!$A$1:$D$22, 3, FALSE), ""!C3:R29"")), ROW($A$1:$A$24), FALSE)), ""=4"") + COUNTIF(ARRAYFORMULA(HLOOKUP($B7, IMPORTRANGE('Prelim Rankings Unsorted'!$B$42, CONCAT(VLOOKUP($C7, 'Match Names'!$A$1:$D$22, 4, FALSE"&"), ""!C3:R29"")), ROW($A$1:$A$24), FALSE)), ""=4"") + COUNTIF(ARRAYFORMULA(HLOOKUP($B7, IMPORTRANGE('Match Names'!$E$23, CONCAT(VLOOKUP($C7, 'Match Names'!$1:$22, 5, FALSE), ""!C3:R29"")), ROW($A$1:$A$24), FALSE)), ""=4"") + COUNTIF(ARRAYFORMULA(HLOOKUP($"&"B7, IMPORTRANGE('Match Names'!$F$23, CONCAT(VLOOKUP($C7, 'Match Names'!$1:$22, 6, FALSE), ""!C3:R29"")), ROW($A$1:$A$24), FALSE)), ""=4"") + COUNTIF(ARRAYFORMULA(HLOOKUP($B7, IMPORTRANGE('Match Names'!$G$23, CONCAT(VLOOKUP($C7, 'Match Names'!$1:$22, 7, FA"&"LSE), ""!C3:R29"")), ROW($A$1:$A$24), FALSE)), ""=4"") + COUNTIF(ARRAYFORMULA(HLOOKUP($B7, IMPORTRANGE('Match Names'!$H$23, CONCAT(VLOOKUP($C7, 'Match Names'!$1:$22, 8, FALSE), ""!C3:R29"")), ROW($A$1:$A$24), FALSE)), ""=4"")"),0.0) -> 0 | F7: =IFERROR(__xludf.DUMMYFUNCTION("COUNTIF(ARRAYFORMULA(HLOOKUP($B7, IMPORTRANGE('Prelim Rankings Unsorted'!$B$40, CONCAT(VLOOKUP($C7, 'Match Names'!$A$1:$D$22, 2, FALSE), ""!C3:R29"")), ROW($A$1:$A$24), FALSE)), ""=0"") + COUNTIF(ARRAYFORMULA(HLOOKUP($B7, IMPORTRANGE('Prelim Rankings Unso"&"rted'!$B$41, CONCAT(VLOOKUP($C7, 'Match Names'!$A$1:$D$22, 3, FALSE), ""!C3:R29"")), ROW($A$1:$A$24), FALSE)), ""=0"") + COUNTIF(ARRAYFORMULA(HLOOKUP($B7, IMPORTRANGE('Prelim Rankings Unsorted'!$B$42, CONCAT(VLOOKUP($C7, 'Match Names'!$A$1:$D$22, 4, FALSE"&"), ""!C3:R29"")), ROW($A$1:$A$24), FALSE)), ""=0"") + COUNTIF(ARRAYFORMULA(HLOOKUP($B7, IMPORTRANGE('Match Names'!$E$23, CONCAT(VLOOKUP($C7, 'Match Names'!$1:$22, 5, FALSE), ""!C3:R29"")), ROW($A$1:$A$24), FALSE)), ""=0"") + COUNTIF(ARRAYFORMULA(HLOOKUP($"&"B7, IMPORTRANGE('Match Names'!$F$23, CONCAT(VLOOKUP($C7, 'Match Names'!$1:$22, 6, FALSE), ""!C3:R29"")), ROW($A$1:$A$24), FALSE)), ""=0"") + COUNTIF(ARRAYFORMULA(HLOOKUP($B7, IMPORTRANGE('Match Names'!$G$23, CONCAT(VLOOKUP($C7, 'Match Names'!$1:$22, 7, FA"&"LSE), ""!C3:R29"")), ROW($A$1:$A$24), FALSE)), ""=0"") + COUNTIF(ARRAYFORMULA(HLOOKUP($B7, IMPORTRANGE('Match Names'!$H$23, CONCAT(VLOOKUP($C7, 'Match Names'!$1:$22, 8, FALSE), ""!C3:R29"")), ROW($A$1:$A$24), FALSE)), ""=0"")"),0.0) -> 0 | G7: =IFERROR(__xludf.DUMMYFUNCTION("COUNTIF(ARRAYFORMULA(HLOOKUP($B7, IMPORTRANGE('Prelim Rankings Unsorted'!$B$40, CONCAT(VLOOKUP($C7, 'Match Names'!$A$1:$D$22, 2, FALSE), ""!C3:R29"")), ROW($A$1:$A$24), FALSE)), ""=-4"") + COUNTIF(ARRAYFORMULA(HLOOKUP($B7, IMPORTRANGE('Prelim Rankings Uns"&"orted'!$B$41, CONCAT(VLOOKUP($C7, 'Match Names'!$A$1:$D$22, 3, FALSE), ""!C3:R29"")), ROW($A$1:$A$24), FALSE)), ""=-4"") + COUNTIF(ARRAYFORMULA(HLOOKUP($B7, IMPORTRANGE('Prelim Rankings Unsorted'!$B$42, CONCAT(VLOOKUP($C7, 'Match Names'!$A$1:$D$22, 4, FAL"&"SE), ""!C3:R29"")), ROW($A$1:$A$24), FALSE)), ""=-4"") + COUNTIF(ARRAYFORMULA(HLOOKUP($B7, IMPORTRANGE('Match Names'!$E$23, CONCAT(VLOOKUP($C7, 'Match Names'!$1:$22, 5, FALSE), ""!C3:R29"")), ROW($A$1:$A$24), FALSE)), ""=-4"") + COUNTIF(ARRAYFORMULA(HLOOK"&"UP($B7, IMPORTRANGE('Match Names'!$F$23, CONCAT(VLOOKUP($C7, 'Match Names'!$1:$22, 6, FALSE), ""!C3:R29"")), ROW($A$1:$A$24), FALSE)), ""=-4"") + COUNTIF(ARRAYFORMULA(HLOOKUP($B7, IMPORTRANGE('Match Names'!$G$23, CONCAT(VLOOKUP($C7, 'Match Names'!$1:$22, "&"7, FALSE), ""!C3:R29"")), ROW($A$1:$A$24), FALSE)), ""=-4"") + COUNTIF(ARRAYFORMULA(HLOOKUP($B7, IMPORTRANGE('Match Names'!$H$23, CONCAT(VLOOKUP($C7, 'Match Names'!$1:$22, 8, FALSE), ""!C3:R29"")), ROW($A$1:$A$24), FALSE)), ""=-4"")"),0.0) -> 0 | H7: =IFERROR(ROUND(((E7*4)+(G7*-4))/(D7/23), 2), 0) -> 0
A8: Victoria | B8: =VLOOKUP(CONCAT(A8, C8), 'Discord Username to Real Name'!C:D, 2, FALSE) -> Victoria123#0687 | C8: Grammar Kids | D8: =IFERROR(__xludf.DUMMYFUNCTION("(23 - COUNTIF(IFERROR(ARRAYFORMULA(HLOOKUP($B8, IMPORTRANGE('Prelim Rankings Unsorted'!$B$40, CONCAT(VLOOKUP($C8, 'Match Names'!$A$1:$D$22, 2, FALSE), ""!C3:R29"")), ROW($A$1:$A$24), FALSE)), $AA$9:$AA$31), ""=X"")) + (23 - COUNTIF(IFERROR(ARRAYFORMULA(HL"&"OOKUP($B8, IMPORTRANGE('Prelim Rankings Unsorted'!$B$41, CONCAT(VLOOKUP($C8, 'Match Names'!$A$1:$D$22, 3, FALSE), ""!C3:R29"")), ROW($A$1:$A$24), FALSE)), $AA$9:$AA$31), ""=X"")) + (23 - COUNTIF(IFERROR(ARRAYFORMULA(HLOOKUP($B8, IMPORTRANGE('Prelim Rankin"&"gs Unsorted'!$B$42, CONCAT(VLOOKUP($C8, 'Match Names'!$A$1:$D$22, 4, FALSE), ""!C3:R29"")), ROW($A$1:$A$24), FALSE)), $AA$9:$AA$31), ""=X"")) + (23 - COUNTIF(IFERROR(ARRAYFORMULA(HLOOKUP($B8, IMPORTRANGE('Match Names'!$E$23, CONCAT(VLOOKUP($C8, 'Match Nam"&"es'!$1:$22, 5, FALSE), ""!C3:R29"")), ROW($A$1:$A$24), FALSE)), $AA$9:$AA$31), ""=X"")) + (23 - COUNTIF(IFERROR(ARRAYFORMULA(HLOOKUP($B8, IMPORTRANGE('Match Names'!$F$23, CONCAT(VLOOKUP($C8, 'Match Names'!$1:$22, 6, FALSE), ""!C3:R29"")), ROW($A$1:$A$24),"&" FALSE)), $AA$9:$AA$31), ""=X"")) + (23 - COUNTIF(IFERROR(ARRAYFORMULA(HLOOKUP($B8, IMPORTRANGE('Match Names'!$G$23, CONCAT(VLOOKUP($C8, 'Match Names'!$1:$22, 7, FALSE), ""!C3:R29"")), ROW($A$1:$A$24), FALSE)), $AA$9:$AA$31), ""=X"")) + (23 - COUNTIF(IFER"&"ROR(ARRAYFORMULA(HLOOKUP($B8, IMPORTRANGE('Match Names'!$H$23, CONCAT(VLOOKUP($C8, 'Match Names'!$1:$22, 8, FALSE), ""!C3:R29"")), ROW($A$1:$A$24), FALSE)), $AA$9:$AA$31), ""=X""))"),0.0) -> 0 | E8: =IFERROR(__xludf.DUMMYFUNCTION("COUNTIF(ARRAYFORMULA(HLOOKUP($B8, IMPORTRANGE('Prelim Rankings Unsorted'!$B$40, CONCAT(VLOOKUP($C8, 'Match Names'!$A$1:$D$22, 2, FALSE), ""!C3:R29"")), ROW($A$1:$A$24), FALSE)), ""=4"") + COUNTIF(ARRAYFORMULA(HLOOKUP($B8, IMPORTRANGE('Prelim Rankings Unso"&"rted'!$B$41, CONCAT(VLOOKUP($C8, 'Match Names'!$A$1:$D$22, 3, FALSE), ""!C3:R29"")), ROW($A$1:$A$24), FALSE)), ""=4"") + COUNTIF(ARRAYFORMULA(HLOOKUP($B8, IMPORTRANGE('Prelim Rankings Unsorted'!$B$42, CONCAT(VLOOKUP($C8, 'Match Names'!$A$1:$D$22, 4, FALSE"&"), ""!C3:R29"")), ROW($A$1:$A$24), FALSE)), ""=4"") + COUNTIF(ARRAYFORMULA(HLOOKUP($B8, IMPORTRANGE('Match Names'!$E$23, CONCAT(VLOOKUP($C8, 'Match Names'!$1:$22, 5, FALSE), ""!C3:R29"")), ROW($A$1:$A$24), FALSE)), ""=4"") + COUNTIF(ARRAYFORMULA(HLOOKUP($"&"B8, IMPORTRANGE('Match Names'!$F$23, CONCAT(VLOOKUP($C8, 'Match Names'!$1:$22, 6, FALSE), ""!C3:R29"")), ROW($A$1:$A$24), FALSE)), ""=4"") + COUNTIF(ARRAYFORMULA(HLOOKUP($B8, IMPORTRANGE('Match Names'!$G$23, CONCAT(VLOOKUP($C8, 'Match Names'!$1:$22, 7, FA"&"LSE), ""!C3:R29"")), ROW($A$1:$A$24), FALSE)), ""=4"") + COUNTIF(ARRAYFORMULA(HLOOKUP($B8, IMPORTRANGE('Match Names'!$H$23, CONCAT(VLOOKUP($C8, 'Match Names'!$1:$22, 8, FALSE), ""!C3:R29"")), ROW($A$1:$A$24), FALSE)), ""=4"")"),0.0) -> 0 | F8: =IFERROR(__xludf.DUMMYFUNCTION("COUNTIF(ARRAYFORMULA(HLOOKUP($B8, IMPORTRANGE('Prelim Rankings Unsorted'!$B$40, CONCAT(VLOOKUP($C8, 'Match Names'!$A$1:$D$22, 2, FALSE), ""!C3:R29"")), ROW($A$1:$A$24), FALSE)), ""=0"") + COUNTIF(ARRAYFORMULA(HLOOKUP($B8, IMPORTRANGE('Prelim Rankings Unso"&"rted'!$B$41, CONCAT(VLOOKUP($C8, 'Match Names'!$A$1:$D$22, 3, FALSE), ""!C3:R29"")), ROW($A$1:$A$24), FALSE)), ""=0"") + COUNTIF(ARRAYFORMULA(HLOOKUP($B8, IMPORTRANGE('Prelim Rankings Unsorted'!$B$42, CONCAT(VLOOKUP($C8, 'Match Names'!$A$1:$D$22, 4, FALSE"&"), ""!C3:R29"")), ROW($A$1:$A$24), FALSE)), ""=0"") + COUNTIF(ARRAYFORMULA(HLOOKUP($B8, IMPORTRANGE('Match Names'!$E$23, CONCAT(VLOOKUP($C8, 'Match Names'!$1:$22, 5, FALSE), ""!C3:R29"")), ROW($A$1:$A$24), FALSE)), ""=0"") + COUNTIF(ARRAYFORMULA(HLOOKUP($"&"B8, IMPORTRANGE('Match Names'!$F$23, CONCAT(VLOOKUP($C8, 'Match Names'!$1:$22, 6, FALSE), ""!C3:R29"")), ROW($A$1:$A$24), FALSE)), ""=0"") + COUNTIF(ARRAYFORMULA(HLOOKUP($B8, IMPORTRANGE('Match Names'!$G$23, CONCAT(VLOOKUP($C8, 'Match Names'!$1:$22, 7, FA"&"LSE), ""!C3:R29"")), ROW($A$1:$A$24), FALSE)), ""=0"") + COUNTIF(ARRAYFORMULA(HLOOKUP($B8, IMPORTRANGE('Match Names'!$H$23, CONCAT(VLOOKUP($C8, 'Match Names'!$1:$22, 8, FALSE), ""!C3:R29"")), ROW($A$1:$A$24), FALSE)), ""=0"")"),0.0) -> 0 | G8: =IFERROR(__xludf.DUMMYFUNCTION("COUNTIF(ARRAYFORMULA(HLOOKUP($B8, IMPORTRANGE('Prelim Rankings Unsorted'!$B$40, CONCAT(VLOOKUP($C8, 'Match Names'!$A$1:$D$22, 2, FALSE), ""!C3:R29"")), ROW($A$1:$A$24), FALSE)), ""=-4"") + COUNTIF(ARRAYFORMULA(HLOOKUP($B8, IMPORTRANGE('Prelim Rankings Uns"&"orted'!$B$41, CONCAT(VLOOKUP($C8, 'Match Names'!$A$1:$D$22, 3, FALSE), ""!C3:R29"")), ROW($A$1:$A$24), FALSE)), ""=-4"") + COUNTIF(ARRAYFORMULA(HLOOKUP($B8, IMPORTRANGE('Prelim Rankings Unsorted'!$B$42, CONCAT(VLOOKUP($C8, 'Match Names'!$A$1:$D$22, 4, FAL"&"SE), ""!C3:R29"")), ROW($A$1:$A$24), FALSE)), ""=-4"") + COUNTIF(ARRAYFORMULA(HLOOKUP($B8, IMPORTRANGE('Match Names'!$E$23, CONCAT(VLOOKUP($C8, 'Match Names'!$1:$22, 5, FALSE), ""!C3:R29"")), ROW($A$1:$A$24), FALSE)), ""=-4"") + COUNTIF(ARRAYFORMULA(HLOOK"&"UP($B8, IMPORTRANGE('Match Names'!$F$23, CONCAT(VLOOKUP($C8, 'Match Names'!$1:$22, 6, FALSE), ""!C3:R29"")), ROW($A$1:$A$24), FALSE)), ""=-4"") + COUNTIF(ARRAYFORMULA(HLOOKUP($B8, IMPORTRANGE('Match Names'!$G$23, CONCAT(VLOOKUP($C8, 'Match Names'!$1:$22, "&"7, FALSE), ""!C3:R29"")), ROW($A$1:$A$24), FALSE)), ""=-4"") + COUNTIF(ARRAYFORMULA(HLOOKUP($B8, IMPORTRANGE('Match Names'!$H$23, CONCAT(VLOOKUP($C8, 'Match Names'!$1:$22, 8, FALSE), ""!C3:R29"")), ROW($A$1:$A$24), FALSE)), ""=-4"")"),0.0) -> 0 | H8: =IFERROR(ROUND(((E8*4)+(G8*-4))/(D8/23), 2), 0) -> 0
A9: Jerry | B9: =VLOOKUP(CONCAT(A9, C9), 'Discord Username to Real Name'!C:D, 2, FALSE) -> IAmNotJerry#6312 | C9: Grammar Kids | D9: =IFERROR(__xludf.DUMMYFUNCTION("(23 - COUNTIF(IFERROR(ARRAYFORMULA(HLOOKUP($B9, IMPORTRANGE('Prelim Rankings Unsorted'!$B$40, CONCAT(VLOOKUP($C9, 'Match Names'!$A$1:$D$22, 2, FALSE), ""!C3:R29"")), ROW($A$1:$A$24), FALSE)), $AA$9:$AA$31), ""=X"")) + (23 - COUNTIF(IFERROR(ARRAYFORMULA(HL"&"OOKUP($B9, IMPORTRANGE('Prelim Rankings Unsorted'!$B$41, CONCAT(VLOOKUP($C9, 'Match Names'!$A$1:$D$22, 3, FALSE), ""!C3:R29"")), ROW($A$1:$A$24), FALSE)), $AA$9:$AA$31), ""=X"")) + (23 - COUNTIF(IFERROR(ARRAYFORMULA(HLOOKUP($B9, IMPORTRANGE('Prelim Rankin"&"gs Unsorted'!$B$42, CONCAT(VLOOKUP($C9, 'Match Names'!$A$1:$D$22, 4, FALSE), ""!C3:R29"")), ROW($A$1:$A$24), FALSE)), $AA$9:$AA$31), ""=X"")) + (23 - COUNTIF(IFERROR(ARRAYFORMULA(HLOOKUP($B9, IMPORTRANGE('Match Names'!$E$23, CONCAT(VLOOKUP($C9, 'Match Nam"&"es'!$1:$22, 5, FALSE), ""!C3:R29"")), ROW($A$1:$A$24), FALSE)), $AA$9:$AA$31), ""=X"")) + (23 - COUNTIF(IFERROR(ARRAYFORMULA(HLOOKUP($B9, IMPORTRANGE('Match Names'!$F$23, CONCAT(VLOOKUP($C9, 'Match Names'!$1:$22, 6, FALSE), ""!C3:R29"")), ROW($A$1:$A$24),"&" FALSE)), $AA$9:$AA$31), ""=X"")) + (23 - COUNTIF(IFERROR(ARRAYFORMULA(HLOOKUP($B9, IMPORTRANGE('Match Names'!$G$23, CONCAT(VLOOKUP($C9, 'Match Names'!$1:$22, 7, FALSE), ""!C3:R29"")), ROW($A$1:$A$24), FALSE)), $AA$9:$AA$31), ""=X"")) + (23 - COUNTIF(IFER"&"ROR(ARRAYFORMULA(HLOOKUP($B9, IMPORTRANGE('Match Names'!$H$23, CONCAT(VLOOKUP($C9, 'Match Names'!$1:$22, 8, FALSE), ""!C3:R29"")), ROW($A$1:$A$24), FALSE)), $AA$9:$AA$31), ""=X""))"),69.0) -> 69 | E9: =IFERROR(__xludf.DUMMYFUNCTION("COUNTIF(ARRAYFORMULA(HLOOKUP($B9, IMPORTRANGE('Prelim Rankings Unsorted'!$B$40, CONCAT(VLOOKUP($C9, 'Match Names'!$A$1:$D$22, 2, FALSE), ""!C3:R29"")), ROW($A$1:$A$24), FALSE)), ""=4"") + COUNTIF(ARRAYFORMULA(HLOOKUP($B9, IMPORTRANGE('Prelim Rankings Unso"&"rted'!$B$41, CONCAT(VLOOKUP($C9, 'Match Names'!$A$1:$D$22, 3, FALSE), ""!C3:R29"")), ROW($A$1:$A$24), FALSE)), ""=4"") + COUNTIF(ARRAYFORMULA(HLOOKUP($B9, IMPORTRANGE('Prelim Rankings Unsorted'!$B$42, CONCAT(VLOOKUP($C9, 'Match Names'!$A$1:$D$22, 4, FALSE"&"), ""!C3:R29"")), ROW($A$1:$A$24), FALSE)), ""=4"") + COUNTIF(ARRAYFORMULA(HLOOKUP($B9, IMPORTRANGE('Match Names'!$E$23, CONCAT(VLOOKUP($C9, 'Match Names'!$1:$22, 5, FALSE), ""!C3:R29"")), ROW($A$1:$A$24), FALSE)), ""=4"") + COUNTIF(ARRAYFORMULA(HLOOKUP($"&"B9, IMPORTRANGE('Match Names'!$F$23, CONCAT(VLOOKUP($C9, 'Match Names'!$1:$22, 6, FALSE), ""!C3:R29"")), ROW($A$1:$A$24), FALSE)), ""=4"") + COUNTIF(ARRAYFORMULA(HLOOKUP($B9, IMPORTRANGE('Match Names'!$G$23, CONCAT(VLOOKUP($C9, 'Match Names'!$1:$22, 7, FA"&"LSE), ""!C3:R29"")), ROW($A$1:$A$24), FALSE)), ""=4"") + COUNTIF(ARRAYFORMULA(HLOOKUP($B9, IMPORTRANGE('Match Names'!$H$23, CONCAT(VLOOKUP($C9, 'Match Names'!$1:$22, 8, FALSE), ""!C3:R29"")), ROW($A$1:$A$24), FALSE)), ""=4"")"),1.0) -> 1 | F9: =IFERROR(__xludf.DUMMYFUNCTION("COUNTIF(ARRAYFORMULA(HLOOKUP($B9, IMPORTRANGE('Prelim Rankings Unsorted'!$B$40, CONCAT(VLOOKUP($C9, 'Match Names'!$A$1:$D$22, 2, FALSE), ""!C3:R29"")), ROW($A$1:$A$24), FALSE)), ""=0"") + COUNTIF(ARRAYFORMULA(HLOOKUP($B9, IMPORTRANGE('Prelim Rankings Unso"&"rted'!$B$41, CONCAT(VLOOKUP($C9, 'Match Names'!$A$1:$D$22, 3, FALSE), ""!C3:R29"")), ROW($A$1:$A$24), FALSE)), ""=0"") + COUNTIF(ARRAYFORMULA(HLOOKUP($B9, IMPORTRANGE('Prelim Rankings Unsorted'!$B$42, CONCAT(VLOOKUP($C9, 'Match Names'!$A$1:$D$22, 4, FALSE"&"), ""!C3:R29"")), ROW($A$1:$A$24), FALSE)), ""=0"") + COUNTIF(ARRAYFORMULA(HLOOKUP($B9, IMPORTRANGE('Match Names'!$E$23, CONCAT(VLOOKUP($C9, 'Match Names'!$1:$22, 5, FALSE), ""!C3:R29"")), ROW($A$1:$A$24), FALSE)), ""=0"") + COUNTIF(ARRAYFORMULA(HLOOKUP($"&"B9, IMPORTRANGE('Match Names'!$F$23, CONCAT(VLOOKUP($C9, 'Match Names'!$1:$22, 6, FALSE), ""!C3:R29"")), ROW($A$1:$A$24), FALSE)), ""=0"") + COUNTIF(ARRAYFORMULA(HLOOKUP($B9, IMPORTRANGE('Match Names'!$G$23, CONCAT(VLOOKUP($C9, 'Match Names'!$1:$22, 7, FA"&"LSE), ""!C3:R29"")), ROW($A$1:$A$24), FALSE)), ""=0"") + COUNTIF(ARRAYFORMULA(HLOOKUP($B9, IMPORTRANGE('Match Names'!$H$23, CONCAT(VLOOKUP($C9, 'Match Names'!$1:$22, 8, FALSE), ""!C3:R29"")), ROW($A$1:$A$24), FALSE)), ""=0"")"),6.0) -> 6 | G9: =IFERROR(__xludf.DUMMYFUNCTION("COUNTIF(ARRAYFORMULA(HLOOKUP($B9, IMPORTRANGE('Prelim Rankings Unsorted'!$B$40, CONCAT(VLOOKUP($C9, 'Match Names'!$A$1:$D$22, 2, FALSE), ""!C3:R29"")), ROW($A$1:$A$24), FALSE)), ""=-4"") + COUNTIF(ARRAYFORMULA(HLOOKUP($B9, IMPORTRANGE('Prelim Rankings Uns"&"orted'!$B$41, CONCAT(VLOOKUP($C9, 'Match Names'!$A$1:$D$22, 3, FALSE), ""!C3:R29"")), ROW($A$1:$A$24), FALSE)), ""=-4"") + COUNTIF(ARRAYFORMULA(HLOOKUP($B9, IMPORTRANGE('Prelim Rankings Unsorted'!$B$42, CONCAT(VLOOKUP($C9, 'Match Names'!$A$1:$D$22, 4, FAL"&"SE), ""!C3:R29"")), ROW($A$1:$A$24), FALSE)), ""=-4"") + COUNTIF(ARRAYFORMULA(HLOOKUP($B9, IMPORTRANGE('Match Names'!$E$23, CONCAT(VLOOKUP($C9, 'Match Names'!$1:$22, 5, FALSE), ""!C3:R29"")), ROW($A$1:$A$24), FALSE)), ""=-4"") + COUNTIF(ARRAYFORMULA(HLOOK"&"UP($B9, IMPORTRANGE('Match Names'!$F$23, CONCAT(VLOOKUP($C9, 'Match Names'!$1:$22, 6, FALSE), ""!C3:R29"")), ROW($A$1:$A$24), FALSE)), ""=-4"") + COUNTIF(ARRAYFORMULA(HLOOKUP($B9, IMPORTRANGE('Match Names'!$G$23, CONCAT(VLOOKUP($C9, 'Match Names'!$1:$22, "&"7, FALSE), ""!C3:R29"")), ROW($A$1:$A$24), FALSE)), ""=-4"") + COUNTIF(ARRAYFORMULA(HLOOKUP($B9, IMPORTRANGE('Match Names'!$H$23, CONCAT(VLOOKUP($C9, 'Match Names'!$1:$22, 8, FALSE), ""!C3:R29"")), ROW($A$1:$A$24), FALSE)), ""=-4"")"),0.0) -> 0 | H9: =IFERROR(ROUND(((E9*4)+(G9*-4))/(D9/23), 2), 0) -> 1.33 | AA9: X
A10: haybales | B10: =VLOOKUP(CONCAT(A10, C10), 'Discord Username to Real Name'!C:D, 2, FALSE) -> haybales#0656 | C10: Deer Feeled | D10: =IFERROR(__xludf.DUMMYFUNCTION("(23 - COUNTIF(IFERROR(ARRAYFORMULA(HLOOKUP($B10, IMPORTRANGE('Prelim Rankings Unsorted'!$B$40, CONCAT(VLOOKUP($C10, 'Match Names'!$A$1:$D$22, 2, FALSE), ""!C3:R29"")), ROW($A$1:$A$24), FALSE)), $AA$9:$AA$31), ""=X"")) + (23 - COUNTIF(IFERROR(ARRAYFORMULA("&"HLOOKUP($B10, IMPORTRANGE('Prelim Rankings Unsorted'!$B$41, CONCAT(VLOOKUP($C10, 'Match Names'!$A$1:$D$22, 3, FALSE), ""!C3:R29"")), ROW($A$1:$A$24), FALSE)), $AA$9:$AA$31), ""=X"")) + (23 - COUNTIF(IFERROR(ARRAYFORMULA(HLOOKUP($B10, IMPORTRANGE('Prelim R"&"ankings Unsorted'!$B$42, CONCAT(VLOOKUP($C10, 'Match Names'!$A$1:$D$22, 4, FALSE), ""!C3:R29"")), ROW($A$1:$A$24), FALSE)), $AA$9:$AA$31), ""=X"")) + (23 - COUNTIF(IFERROR(ARRAYFORMULA(HLOOKUP($B10, IMPORTRANGE('Match Names'!$E$23, CONCAT(VLOOKUP($C10, 'M"&"atch Names'!$1:$22, 5, FALSE), ""!C3:R29"")), ROW($A$1:$A$24), FALSE)), $AA$9:$AA$31), ""=X"")) + (23 - COUNTIF(IFERROR(ARRAYFORMULA(HLOOKUP($B10, IMPORTRANGE('Match Names'!$F$23, CONCAT(VLOOKUP($C10, 'Match Names'!$1:$22, 6, FALSE), ""!C3:R29"")), ROW($A"&"$1:$A$24), FALSE)), $AA$9:$AA$31), ""=X"")) + (23 - COUNTIF(IFERROR(ARRAYFORMULA(HLOOKUP($B10, IMPORTRANGE('Match Names'!$G$23, CONCAT(VLOOKUP($C10, 'Match Names'!$1:$22, 7, FALSE), ""!C3:R29"")), ROW($A$1:$A$24), FALSE)), $AA$9:$AA$31), ""=X"")) + (23 - "&"COUNTIF(IFERROR(ARRAYFORMULA(HLOOKUP($B10, IMPORTRANGE('Match Names'!$H$23, CONCAT(VLOOKUP($C10, 'Match Names'!$1:$22, 8, FALSE), ""!C3:R29"")), ROW($A$1:$A$24), FALSE)), $AA$9:$AA$31), ""=X""))"),0.0) -> 0 | E10: =IFERROR(__xludf.DUMMYFUNCTION("COUNTIF(ARRAYFORMULA(HLOOKUP($B10, IMPORTRANGE('Prelim Rankings Unsorted'!$B$40, CONCAT(VLOOKUP($C10, 'Match Names'!$A$1:$D$22, 2, FALSE), ""!C3:R29"")), ROW($A$1:$A$24), FALSE)), ""=4"") + COUNTIF(ARRAYFORMULA(HLOOKUP($B10, IMPORTRANGE('Prelim Rankings U"&"nsorted'!$B$41, CONCAT(VLOOKUP($C10, 'Match Names'!$A$1:$D$22, 3, FALSE), ""!C3:R29"")), ROW($A$1:$A$24), FALSE)), ""=4"") + COUNTIF(ARRAYFORMULA(HLOOKUP($B10, IMPORTRANGE('Prelim Rankings Unsorted'!$B$42, CONCAT(VLOOKUP($C10, 'Match Names'!$A$1:$D$22, 4,"&" FALSE), ""!C3:R29"")), ROW($A$1:$A$24), FALSE)), ""=4"") + COUNTIF(ARRAYFORMULA(HLOOKUP($B10, IMPORTRANGE('Match Names'!$E$23, CONCAT(VLOOKUP($C10, 'Match Names'!$1:$22, 5, FALSE), ""!C3:R29"")), ROW($A$1:$A$24), FALSE)), ""=4"") + COUNTIF(ARRAYFORMULA(H"&"LOOKUP($B10, IMPORTRANGE('Match Names'!$F$23, CONCAT(VLOOKUP($C10, 'Match Names'!$1:$22, 6, FALSE), ""!C3:R29"")), ROW($A$1:$A$24), FALSE)), ""=4"") + COUNTIF(ARRAYFORMULA(HLOOKUP($B10, IMPORTRANGE('Match Names'!$G$23, CONCAT(VLOOKUP($C10, 'Match Names'!$"&"1:$22, 7, FALSE), ""!C3:R29"")), ROW($A$1:$A$24), FALSE)), ""=4"") + COUNTIF(ARRAYFORMULA(HLOOKUP($B10, IMPORTRANGE('Match Names'!$H$23, CONCAT(VLOOKUP($C10, 'Match Names'!$1:$22, 8, FALSE), ""!C3:R29"")), ROW($A$1:$A$24), FALSE)), ""=4"")"),0.0) -> 0 | F10: =IFERROR(__xludf.DUMMYFUNCTION("COUNTIF(ARRAYFORMULA(HLOOKUP($B10, IMPORTRANGE('Prelim Rankings Unsorted'!$B$40, CONCAT(VLOOKUP($C10, 'Match Names'!$A$1:$D$22, 2, FALSE), ""!C3:R29"")), ROW($A$1:$A$24), FALSE)), ""=0"") + COUNTIF(ARRAYFORMULA(HLOOKUP($B10, IMPORTRANGE('Prelim Rankings U"&"nsorted'!$B$41, CONCAT(VLOOKUP($C10, 'Match Names'!$A$1:$D$22, 3, FALSE), ""!C3:R29"")), ROW($A$1:$A$24), FALSE)), ""=0"") + COUNTIF(ARRAYFORMULA(HLOOKUP($B10, IMPORTRANGE('Prelim Rankings Unsorted'!$B$42, CONCAT(VLOOKUP($C10, 'Match Names'!$A$1:$D$22, 4,"&" FALSE), ""!C3:R29"")), ROW($A$1:$A$24), FALSE)), ""=0"") + COUNTIF(ARRAYFORMULA(HLOOKUP($B10, IMPORTRANGE('Match Names'!$E$23, CONCAT(VLOOKUP($C10, 'Match Names'!$1:$22, 5, FALSE), ""!C3:R29"")), ROW($A$1:$A$24), FALSE)), ""=0"") + COUNTIF(ARRAYFORMULA(H"&"LOOKUP($B10, IMPORTRANGE('Match Names'!$F$23, CONCAT(VLOOKUP($C10, 'Match Names'!$1:$22, 6, FALSE), ""!C3:R29"")), ROW($A$1:$A$24), FALSE)), ""=0"") + COUNTIF(ARRAYFORMULA(HLOOKUP($B10, IMPORTRANGE('Match Names'!$G$23, CONCAT(VLOOKUP($C10, 'Match Names'!$"&"1:$22, 7, FALSE), ""!C3:R29"")), ROW($A$1:$A$24), FALSE)), ""=0"") + COUNTIF(ARRAYFORMULA(HLOOKUP($B10, IMPORTRANGE('Match Names'!$H$23, CONCAT(VLOOKUP($C10, 'Match Names'!$1:$22, 8, FALSE), ""!C3:R29"")), ROW($A$1:$A$24), FALSE)), ""=0"")"),0.0) -> 0 | G10: =IFERROR(__xludf.DUMMYFUNCTION("COUNTIF(ARRAYFORMULA(HLOOKUP($B10, IMPORTRANGE('Prelim Rankings Unsorted'!$B$40, CONCAT(VLOOKUP($C10, 'Match Names'!$A$1:$D$22, 2, FALSE), ""!C3:R29"")), ROW($A$1:$A$24), FALSE)), ""=-4"") + COUNTIF(ARRAYFORMULA(HLOOKUP($B10, IMPORTRANGE('Prelim Rankings "&"Unsorted'!$B$41, CONCAT(VLOOKUP($C10, 'Match Names'!$A$1:$D$22, 3, FALSE), ""!C3:R29"")), ROW($A$1:$A$24), FALSE)), ""=-4"") + COUNTIF(ARRAYFORMULA(HLOOKUP($B10, IMPORTRANGE('Prelim Rankings Unsorted'!$B$42, CONCAT(VLOOKUP($C10, 'Match Names'!$A$1:$D$22, "&"4, FALSE), ""!C3:R29"")), ROW($A$1:$A$24), FALSE)), ""=-4"") + COUNTIF(ARRAYFORMULA(HLOOKUP($B10, IMPORTRANGE('Match Names'!$E$23, CONCAT(VLOOKUP($C10, 'Match Names'!$1:$22, 5, FALSE), ""!C3:R29"")), ROW($A$1:$A$24), FALSE)), ""=-4"") + COUNTIF(ARRAYFORMU"&"LA(HLOOKUP($B10, IMPORTRANGE('Match Names'!$F$23, CONCAT(VLOOKUP($C10, 'Match Names'!$1:$22, 6, FALSE), ""!C3:R29"")), ROW($A$1:$A$24), FALSE)), ""=-4"") + COUNTIF(ARRAYFORMULA(HLOOKUP($B10, IMPORTRANGE('Match Names'!$G$23, CONCAT(VLOOKUP($C10, 'Match Nam"&"es'!$1:$22, 7, FALSE), ""!C3:R29"")), ROW($A$1:$A$24), FALSE)), ""=-4"") + COUNTIF(ARRAYFORMULA(HLOOKUP($B10, IMPORTRANGE('Match Names'!$H$23, CONCAT(VLOOKUP($C10, 'Match Names'!$1:$22, 8, FALSE), ""!C3:R29"")), ROW($A$1:$A$24), FALSE)), ""=-4"")"),0.0) -> 0 | H10: =IFERROR(ROUND(((E10*4)+(G10*-4))/(D10/23), 2), 0) -> 0 | AA10: X
