Workbook

Sheet Raw
A1: id | B1: gameRecordId | C1: score | D1: whoBuzzedGID | E1: teamId | F1: teamName | G1: isTeamA | H1: isEmpty | I1: questionNum | J1: Cat
A2: 137011 | B2: 468 | C2: 14 | D2: 104495540205548736558 | E2: 12 | F2: =vlookup(E2,Teams!A:B,2,false) -> Davidson | G2: TRUE | H2: FALSE | I2: 1 | J2: =vlookup(I2,Cats!$A:$B,2,false) -> X | K2: {=unique(D2:D13931)} -> 104495540205548736558
A3: 137012 | B3: 468 | C3: 0 | D3: NULL | E3: 33 | F3: =vlookup(E3,Teams!A:B,2,false) -> NCSSM B | G3: FALSE | H3: TRUE | I3: 1 | J3: =vlookup(I3,Cats!$A:$B,2,false) -> X | K3: NULL
A4: 137013 | B4: 468 | C4: 14 | D4: 110168841047541949979 | E4: 12 | F4: =vlookup(E4,Teams!A:B,2,false) -> Davidson | G4: TRUE | H4: FALSE | I4: 2 | J4: =vlookup(I4,Cats!$A:$B,2,false) -> M | K4: 110168841047541949979
A5: 137014 | B5: 468 | C5: 0 | D5: 112292901990108303517 | E5: 33 | F5: =vlookup(E5,Teams!A:B,2,false) -> NCSSM B | G5: FALSE | H5: FALSE | I5: 2 | J5: =vlookup(I5,Cats!$A:$B,2,false) -> M | K5: 112292901990108303517
A6: 137015 | B6: 468 | C6: 14 | D6: 115276086652629571643 | E6: 12 | F6: =vlookup(E6,Teams!A:B,2,false) -> Davidson | G6: TRUE | H6: FALSE | I6: 3 | J6: =vlookup(I6,Cats!$A:$B,2,false) -> C | K6: 115276086652629571643
A7: 137016 | B7: 468 | C7: 0 | D7: NULL | E7: 33 | F7: =vlookup(E7,Teams!A:B,2,false) -> NCSSM B | G7: FALSE | H7: TRUE | I7: 3 | J7: =vlookup(I7,Cats!$A:$B,2,false) -> C | K7: 100047951893265954908
A8: 137017 | B8: 468 | C8: 14 | D8: 104495540205548736558 | E8: 12 | F8: =vlookup(E8,Teams!A:B,2,false) -> Davidson | G8: TRUE | H8: FALSE | I8: 4 | J8: =vlookup(I8,Cats!$A:$B,2,false) -> E | K8: 114613659765661937761
A9: 137018 | B9: 468 | C9: 0 | D9: NULL | E9: 33 | F9: =vlookup(E9,Teams!A:B,2,false) -> NCSSM B | G9: FALSE | H9: TRUE | I9: 4 | J9: =vlookup(I9,Cats!$A:$B,2,false) -> E | K9: 114801746103647609036
A10: 137019 | B10: 468 | C10: 14 | D10: 115276086652629571643 | E10: 12 | F10: =vlookup(E10,Teams!A:B,2,false) -> Davidson | G10: TRUE | H10: FALSE | I10: 5 | J10: =vlookup(I10,Cats!$A:$B,2,false) -> B | K10: 111867724755469328406
A11: 137020 | B11: 468 | C11: 0 | D11: NULL | E11: 33 | F11: =vlookup(E11,Teams!A:B,2,false) -> NCSSM B | G11: FALSE | H11: TRUE | I11: 5 | J11: =vlookup(I11,Cats!$A:$B,2,false) -> B | K11: 107520337771987267201
A12: 137021 | B12: 468 | C12: 0 | D12: NULL | E12: 12 | F12: =vlookup(E12,Teams!A:B,2,false) -> Davidson | G12: TRUE | H12: TRUE | I12: 6 | J12: =vlookup(I12,Cats!$A:$B,2,false) -> P | K12: 115701416956189742203
A13: 137022 | B13: 468 | C13: 14 | D13: 100047951893265954908 | E13: 33 | F13: =vlookup(E13,Teams!A:B,2,false) -> NCSSM B | G13: FALSE | H13: FALSE | I13: 6 | J13: =vlookup(I13,Cats!$A:$B,2,false) -> P | K13: 116174047268011279731
A14: 137023 | B14: 468 | C14: 14 | D14: 115276086652629571643 | E14: 12 | F14: =vlookup(E14,Teams!A:B,2,false) -> Davidson | G14: TRUE | H14: FALSE | I14: 7 | J14: =vlookup(I14,Cats!$A:$B,2,false) -> X | K14: 109119414141479472132
... A208: 137217 | B208: 472 | C208: 0 | D208: NULL | E208: 10 | F208: =vlookup(E208,Teams!A:B,2,false) -> Collierville | G208: TRUE | H208: TRUE | I208: 8 | J208: =vlookup(I208,Cats!$A:$B,2,false) -> M | K208: 104065900705702704789
A209: 137218 | B209: 472 | C209: 4 | D209: 116807051909331854620 | E209: 14 | F209: =vlookup(E209,Teams!A:B,2,false) -> Dulles | G209: FALSE | H209: FALSE | I209: 8 | J209: =vlookup(I209,Cats!$A:$B,2,false) -> M
A210: 137219 | B210: 472 | C210: 0 | D210: NULL | E210: 10 | F210: =vlookup(E210,Teams!A:B,2,false) -> Collierville | G210: TRUE | H210: TRUE | I210: 9 | J210: =vlookup(I210,Cats!$A:$B,2,false) -> C
A211: 137220 | B211: 472 | C211: 14 | D211: 114720212150770111881 | E211: 14 | F211: =vlookup(E211,Teams!A:B,2,false) -> Dulles | G211: FALSE | H211: FALSE | I211: 9 | J211: =vlookup(I211,Cats!$A:$B,2,false) -> C
A212: 137221 | B212: 472 | C212: 14 | D212: 102412219695323063157 | E212: 10 | F212: =vlookup(E212,Teams!A:B,2,false) -> Collierville | G212: TRUE | H212: FALSE | I212: 10 | J212: =vlookup(I212,Cats!$A:$B,2,false) -> E
A213: 137222 | B213: 472 | C213: 0 | D213: NULL | E213: 14 | F213: =vlookup(E213,Teams!A:B,2,false) -> Dulles | G213: FALSE | H213: TRUE | I213: 10 | J213: =vlookup(I213,Cats!$A:$B,2,false) -> E
A214: 137223 | B214: 472 | C214: 4 | D214: 108063248698294076855 | E214: 10 | F214: =vlookup(E214,Teams!A:B,2,false) -> Collierville | G214: TRUE | H214: FALSE | I214: 11 | J214: =vlookup(I214,Cats!$A:$B,2,false) -> B
A215: 137224 | B215: 472 | C215: 0 | D215: NULL | E215: 14 | F215: =vlookup(E215,Teams!A:B,2,false) -> Dulles | G215: FALSE | H215: TRUE | I215: 11 | J215: =vlookup(I215,Cats!$A:$B,2,false) -> B
A216: 137225 | B216: 472 | C216: 0 | D216: NULL | E216: 10 | F216: =vlookup(E216,Teams!A:B,2,false) -> Collierville | G216: TRUE | H216: TRUE | I216: 12 | J216: =vlookup(I216,Cats!$A:$B,2,false) -> P
A217: 137226 | B217: 472 | C217: 14 | D217: 114720212150770111881 | E217: 14 | F217: =vlookup(E217,Teams!A:B,2,false) -> Dulles | G217: FALSE | H217: FALSE | I217: 12 | J217: =vlookup(I217,Cats!$A:$B,2,false) -> P
A218: 137227 | B218: 472 | C218: 14 | D218: 104931437805203389949 | E218: 10 | F218: =vlookup(E218,Teams!A:B,2,false) -> Collierville | G218: TRUE | H218: FALSE | I218: 13 | J218: =vlookup(I218,Cats!$A:$B,2,false) -> X
A219: 137228 | B219: 472 | C219: 0 | D219: NULL | E219: 14 | F219: =vlookup(E219,Teams!A:B,2,false) -> Dulles | G219: FALSE | H219: TRUE | I219: 13 | J219: =vlookup(I219,Cats!$A:$B,2,false) -> X
A220: 137229 | B220: 472 | C220: 0 | D220: NULL | E220: 10 | F220: =vlookup(E220,Teams!A:B,2,false) -> Collierville | G220: TRUE | H220: TRUE | I220: 14 | J220: =vlookup(I220,Cats!$A:$B,2,false) -> M
... A6869: 143878 | B6869: 610 | C6869: 0 | D6869: 117280045524168167150 | E6869: 35 | F6869: =vlookup(E6869,Teams!A:B,2,false) -> NoHo | G6869: FALSE | H6869: FALSE | I6869: 24 | J6869: =vlookup(I6869,Cats!$A:$B,2,false) -> P

Sheet PrelimRaw
A1: id | B1: gameRecordId | C1: score | D1: whoBuzzedGID | E1: teamId | F1: teamName | G1: isTeamA | H1: isEmpty | I1: questionNum | J1: Cat
A2: 137011 | B2: 468 | C2: 14 | D2: 104495540205548736558 | E2: 12 | F2: =vlookup(E2,Teams!A:B,2,false) -> Davidson | G2: TRUE | H2: FALSE | I2: 1 | J2: =vlookup(I2,Cats!$A:$B,2,false) -> X
A3: 137012 | B3: 468 | C3: 0 | D3: NULL | E3: 33 | F3: =vlookup(E3,Teams!A:B,2,false) -> NCSSM B | G3: FALSE | H3: TRUE | I3: 1 | J3: =vlookup(I3,Cats!$A:$B,2,false) -> X
A4: 137013 | B4: 468 | C4: 14 | D4: 110168841047541949979 | E4: 12 | F4: =vlookup(E4,Teams!A:B,2,false) -> Davidson | G4: TRUE | H4: FALSE | I4: 2 | J4: =vlookup(I4,Cats!$A:$B,2,false) -> M
A5: 137014 | B5: 468 | C5: 0 | D5: 112292901990108303517 | E5: 33 | F5: =vlookup(E5,Teams!A:B,2,false) -> NCSSM B | G5: FALSE | H5: FALSE | I5: 2 | J5: =vlookup(I5,Cats!$A:$B,2,false) -> M
A6: 137015 | B6: 468 | C6: 14 | D6: 115276086652629571643 | E6: 12 | F6: =vlookup(E6,Teams!A:B,2,false) -> Davidson | G6: TRUE | H6: FALSE | I6: 3 | J6: =vlookup(I6,Cats!$A:$B,2,false) -> C
A7: 137016 | B7: 468 | C7: 0 | D7: NULL | E7: 33 | F7: =vlookup(E7,Teams!A:B,2,false) -> NCSSM B | G7: FALSE | H7: TRUE | I7: 3 | J7: =vlookup(I7,Cats!$A:$B,2,false) -> C
A8: 137017 | B8: 468 | C8: 14 | D8: 104495540205548736558 | E8: 12 | F8: =vlookup(E8,Teams!A:B,2,false) -> Davidson | G8: TRUE | H8: FALSE | I8: 4 | J8: =vlookup(I8,Cats!$A:$B,2,false) -> E
A9: 137018 | B9: 468 | C9: 0 | D9: NULL | E9: 33 | F9: =vlookup(E9,Teams!A:B,2,false) -> NCSSM B | G9: FALSE | H9: TRUE | I9: 4 | J9: =vlookup(I9,Cats!$A:$B,2,false) -> E
A10: 137019 | B10: 468 | C10: 14 | D10: 115276086652629571643 | E10: 12 | F10: =vlookup(E10,Teams!A:B,2,false) -> Davidson | G10: TRUE | H10: FALSE | I10: 5 | J10: =vlookup(I10,Cats!$A:$B,2,false) -> B
A11: 137020 | B11: 468 | C11: 0 | D11: NULL | E11: 33 | F11: =vlookup(E11,Teams!A:B,2,false) -> NCSSM B | G11: FALSE | H11: TRUE | I11: 5 | J11: =vlookup(I11,Cats!$A:$B,2,false) -> B
A12: 137021 | B12: 468 | C12: 0 | D12: NULL | E12: 12 | F12: =vlookup(E12,Teams!A:B,2,false) -> Davidson | G12: TRUE | H12: TRUE | I12: 6 | J12: =vlookup(I12,Cats!$A:$B,2,false) -> P
A13: 137022 | B13: 468 | C13: 14 | D13: 100047951893265954908 | E13: 33 | F13: =vlookup(E13,Teams!A:B,2,false) -> NCSSM B | G13: FALSE | H13: FALSE | I13: 6 | J13: =vlookup(I13,Cats!$A:$B,2,false) -> P
... A5765: 142774 | B5765: 587 | C5765: 0 | D5765: 110488059036326763108 | E5765: 32 | F5765: =vlookup(E5765,Teams!A:B,2,false) -> NCSSM A | G5765: FALSE | H5765: FALSE | I5765: 24 | J5765: =vlookup(I5765,Cats!$A:$B,2,false) -> P

Sheet Prelims
A1: ID | B1: Name | C1: Team | D1: GP | E1: TUH | F1: TU | G1: X | H1: Neg | I1: # Buzz | J1: % Buzz | K1: Acc | L1: Points | M1: PPG | N1: X PPG | O1: M PPG | P1: C PPG | Q1: E PPG | R1: B PPG | S1: P PPG
A2: 104421903707714227310 | B2: =vlookup($A2,Users!$B$1:$H1000,3,false) -> Anurag | C2: =vlookup($A2,Users!$B$1:$H1000,6,false) -> Centennial | D2: =vlookup($C2,Teams!$B:$D,3,false) -> 5 | E2: =D2*24 -> 120 | F2: =countifs(PrelimRaw!$D$1:$D1000,$A2,PrelimRaw!$C$1:$C1000,4)+countifs(PrelimRaw!$D$1:$D1000,$A2,PrelimRaw!$C$1:$C1000,14) -> 58 | G2: =countifs(PrelimRaw!$D$1:$D1000,$A2,PrelimRaw!$C$1:$C1000,0) -> 20 | H2: =countifs(PrelimRaw!$D$1:$D1000,$A2,PrelimRaw!$C$1:$C1000,-4) -> 5 | I2: =F2+G2+H2 -> 83 | J2: =I2/E2 -> 0.69166667 | K2: =iferror(F2/I2,0) -> 0.69879518 | L2: =4*F2-4*H2 -> 212 | M2: =L2/D2 -> 42.4 | N2: =vlookup($A2,'X-Risk'!$A:$M,13,false) -> 8 | O2: =vlookup($A2,Math!$A:$M,13,false) -> 7.2 | P2: =vlookup($A2,Chemistry!$A:$M,13,false) -> 12 | Q2: =vlookup($A2,EarthSpace!$A:$M,13,false) -> 1.6 | R2: =vlookup($A2,Biology!$A:$M,13,false) -> 5.6 | S2: =vlookup($A2,Physics!$A:$M,13,false) -> 8
A3: 101949633011269793228 | B3: =vlookup($A3,Users!$B$1:$H1000,3,false) -> Joshua | C3: =vlookup($A3,Users!$B$1:$H1000,6,false) -> Brookfield | D3: =vlookup($C3,Teams!$B:$D,3,false) -> 5 | E3: =D3*24 -> 120 | F3: =countifs(PrelimRaw!$D$1:$D1000,$A3,PrelimRaw!$C$1:$C1000,4)+countifs(PrelimRaw!$D$1:$D1000,$A3,PrelimRaw!$C$1:$C1000,14) -> 47 | G3: =countifs(PrelimRaw!$D$1:$D1000,$A3,PrelimRaw!$C$1:$C1000,0) -> 13 | H3: =countifs(PrelimRaw!$D$1:$D1000,$A3,PrelimRaw!$C$1:$C1000,-4) -> 0 | I3: =F3+G3+H3 -> 60 | J3: =I3/E3 -> 0.5 | K3: =iferror(F3/I3,0) -> 0.78333333 | L3: =4*F3-4*H3 -> 188 | M3: =L3/D3 -> 37.6 | N3: =vlookup($A3,'X-Risk'!$A:$M,13,false) -> 7.2 | O3: =vlookup($A3,Math!$A:$M,13,false) -> 4 | P3: =vlookup($A3,Chemistry!$A:$M,13,false) -> 5.6 | Q3: =vlookup($A3,EarthSpace!$A:$M,13,false) -> 5.6 | R3: =vlookup($A3,Biology!$A:$M,13,false) -> 5.6 | S3: =vlookup($A3,Physics!$A:$M,13,false) -> 9.6
A4: 106777291229721234908 | B4: =vlookup($A4,Users!$B$1:$H1000,3,false) -> Yufei | C4: =vlookup($A4,Users!$B$1:$H1000,6,false) -> University | D4: =vlookup($C4,Teams!$B:$D,3,false) -> 5 | E4: =D4*24 -> 120 | F4: =countifs(PrelimRaw!$D$1:$D1000,$A4,PrelimRaw!$C$1:$C1000,4)+countifs(PrelimRaw!$D$1:$D1000,$A4,PrelimRaw!$C$1:$C1000,14) -> 48 | G4: =countifs(PrelimRaw!$D$1:$D1000,$A4,PrelimRaw!$C$1:$C1000,0) -> 7 | H4: =countifs(PrelimRaw!$D$1:$D1000,$A4,PrelimRaw!$C$1:$C1000,-4) -> 6 | I4: =F4+G4+H4 -> 61 | J4: =I4/E4 -> 0.50833333 | K4: =iferror(F4/I4,0) -> 0.78688525 | L4: =4*F4-4*H4 -> 168 | M4: =L4/D4 -> 33.6 | N4: =vlookup($A4,'X-Risk'!$A:$M,13,false) -> 5.6 | O4: =vlookup($A4,Math!$A:$M,13,false) -> 4.8 | P4: =vlookup($A4,Chemistry!$A:$M,13,false) -> 6.4 | Q4: =vlookup($A4,EarthSpace!$A:$M,13,false) -> 5.6 | R4: =vlookup($A4,Biology!$A:$M,13,false) -> 6.4 | S4: =vlookup($A4,Physics!$A:$M,13,false) -> 4.8
A5: 100741934745181838949 | B5: =vlookup($A5,Users!$B$1:$H1000,3,false) -> Vishnu | C5: =vlookup($A5,Users!$B$1:$H1000,6,false) -> Lakeside | D5: =vlookup($C5,Teams!$B:$D,3,false) -> 5 | E5: =D5*24 -> 120 | F5: =countifs(PrelimRaw!$D$1:$D1000,$A5,PrelimRaw!$C$1:$C1000,4)+countifs(PrelimRaw!$D$1:$D1000,$A5,PrelimRaw!$C$1:$C1000,14) -> 43 | G5: =countifs(PrelimRaw!$D$1:$D1000,$A5,PrelimRaw!$C$1:$C1000,0) -> 11 | H5: =countifs(PrelimRaw!$D$1:$D1000,$A5,PrelimRaw!$C$1:$C1000,-4) -> 2 | I5: =F5+G5+H5 -> 56 | J5: =I5/E5 -> 0.46666667 | K5: =iferror(F5/I5,0) -> 0.76785714 | L5: =4*F5-4*H5 -> 164 | M5: =L5/D5 -> 32.8 | N5: =vlookup($A5,'X-Risk'!$A:$M,13,false) -> 4 | O5: =vlookup($A5,Math!$A:$M,13,false) -> 6.4 | P5: =vlookup($A5,Chemistry!$A:$M,13,false) -> 5.6 | Q5: =vlookup($A5,EarthSpace!$A:$M,13,false) -> 8.8 | R5: =vlookup($A5,Biology!$A:$M,13,false) -> 4 | S5: =vlookup($A5,Physics!$A:$M,13,false) -> 4
A6: 114720212150770111881 | B6: =vlookup($A6,Users!$B$1:$H1000,3,false) -> Viraj | C6: =vlookup($A6,Users!$B$1:$H1000,6,false) -> Dulles | D6: =vlookup($C6,Teams!$B:$D,3,false) -> 5 | E6: =D6*24 -> 120 | F6: =countifs(PrelimRaw!$D$1:$D1000,$A6,PrelimRaw!$C$1:$C1000,4)+countifs(PrelimRaw!$D$1:$D1000,$A6,PrelimRaw!$C$1:$C1000,14) -> 35 | G6: =countifs(PrelimRaw!$D$1:$D1000,$A6,PrelimRaw!$C$1:$C1000,0) -> 2 | H6: =countifs(PrelimRaw!$D$1:$D1000,$A6,PrelimRaw!$C$1:$C1000,-4) -> 1 | I6: =F6+G6+H6 -> 38 | J6: =I6/E6 -> 0.31666667 | K6: =iferror(F6/I6,0) -> 0.92105263 | L6: =4*F6-4*H6 -> 136 | M6: =L6/D6 -> 27.2 | N6: =vlookup($A6,'X-Risk'!$A:$M,13,false) -> 2.4 | O6: =vlookup($A6,Math!$A:$M,13,false) -> 3.2 | P6: =vlookup($A6,Chemistry!$A:$M,13,false) -> 12.8 | Q6: =vlookup($A6,EarthSpace!$A:$M,13,false) -> 1.6 | R6: =vlookup($A6,Biology!$A:$M,13,false) -> 1.6 | S6: =vlookup($A6,Physics!$A:$M,13,false) -> 5.6
A7: 108223652435775478403 | B7: =vlookup($A7,Users!$B$1:$H1000,3,false) -> Caleb | C7: =vlookup($A7,Users!$B$1:$H1000,6,false) -> Blair A | D7: =vlookup($C7,Teams!$B:$D,3,false) -> 5 | E7: =D7*24 -> 120 | F7: =countifs(PrelimRaw!$D$1:$D1000,$A7,PrelimRaw!$C$1:$C1000,4)+countifs(PrelimRaw!$D$1:$D1000,$A7,PrelimRaw!$C$1:$C1000,14) -> 43 | G7: =countifs(PrelimRaw!$D$1:$D1000,$A7,PrelimRaw!$C$1:$C1000,0) -> 5 | H7: =countifs(PrelimRaw!$D$1:$D1000,$A7,PrelimRaw!$C$1:$C1000,-4) -> 10 | I7: =F7+G7+H7 -> 58 | J7: =I7/E7 -> 0.48333333 | K7: =iferror(F7/I7,0) -> 0.74137931 | L7: =4*F7-4*H7 -> 132 | M7: =L7/D7 -> 26.4 | N7: =vlookup($A7,'X-Risk'!$A:$M,13,false) -> 4.8 | O7: =vlookup($A7,Math!$A:$M,13,false) -> 0.8 | P7: =vlookup($A7,Chemistry!$A:$M,13,false) -> 10.4 | Q7: =vlookup($A7,EarthSpace!$A:$M,13,false) -> 1.6 | R7: =vlookup($A7,Biology!$A:$M,13,false) -> 8.8 | S7: =vlookup($A7,Physics!$A:$M,13,false) -> 0
A8: 115589370929340579338 | B8: =vlookup($A8,Users!$B$1:$H1000,3,false) -> Aditya | C8: =vlookup($A8,Users!$B$1:$H1000,6,false) -> Mira Loma | D8: =vlookup($C8,Teams!$B:$D,3,false) -> 5 | E8: =D8*24 -> 120 | F8: =countifs(PrelimRaw!$D$1:$D1000,$A8,PrelimRaw!$C$1:$C1000,4)+countifs(PrelimRaw!$D$1:$D1000,$A8,PrelimRaw!$C$1:$C1000,14) -> 39 | G8: =countifs(PrelimRaw!$D$1:$D1000,$A8,PrelimRaw!$C$1:$C1000,0) -> 10 | H8: =countifs(PrelimRaw!$D$1:$D1000,$A8,PrelimRaw!$C$1:$C1000,-4) -> 6 | I8: =F8+G8+H8 -> 55 | J8: =I8/E8 -> 0.45833333 | K8: =iferror(F8/I8,0) -> 0.70909091 | L8: =4*F8-4*H8 -> 132 | M8: =L8/D8 -> 26.4 | N8: =vlookup($A8,'X-Risk'!$A:$M,13,false) -> 6.4 | O8: =vlookup($A8,Math!$A:$M,13,false) -> 2.4 | P8: =vlookup($A8,Chemistry!$A:$M,13,false) -> 3.2 | Q8: =vlookup($A8,EarthSpace!$A:$M,13,false) -> 3.2 | R8: =vlookup($A8,Biology!$A:$M,13,false) -> 10.4 | S8: =vlookup($A8,Physics!$A:$M,13,false) -> 0.8
A9: 105378163543476641273 | B9: =vlookup($A9,Users!$B$1:$H1000,3,false) -> Elias | C9: =vlookup($A9,Users!$B$1:$H1000,6,false) -> ASFA | D9: =vlookup($C9,Teams!$B:$D,3,false) -> 5 | E9: =D9*24 -> 120 | F9: =countifs(PrelimRaw!$D$1:$D1000,$A9,PrelimRaw!$C$1:$C1000,4)+countifs(PrelimRaw!$D$1:$D1000,$A9,PrelimRaw!$C$1:$C1000,14) -> 34 | G9: =countifs(PrelimRaw!$D$1:$D1000,$A9,PrelimRaw!$C$1:$C1000,0) -> 24 | H9: =countifs(PrelimRaw!$D$1:$D1000,$A9,PrelimRaw!$C$1:$C1000,-4) -> 3 | I9: =F9+G9+H9 -> 61 | J9: =I9/E9 -> 0.50833333 | K9: =iferror(F9/I9,0) -> 0.55737705 | L9: =4*F9-4*H9 -> 124 | M9: =L9/D9 -> 24.8 | N9: =vlookup($A9,'X-Risk'!$A:$M,13,false) -> 3.2 | O9: =vlookup($A9,Math!$A:$M,13,false) -> 7.2 | P9: =vlookup($A9,Chemistry!$A:$M,13,false) -> 8 | Q9: =vlookup($A9,EarthSpace!$A:$M,13,false) -> 5.6 | R9: =vlookup($A9,Biology!$A:$M,13,false) -> 0 | S9: =vlookup($A9,Physics!$A:$M,13,false) -> 0.8
A10: 100552342580135245961 | B10: =vlookup($A10,Users!$B$1:$H1000,3,false) -> Connor | C10: =vlookup($A10,Users!$B$1:$H1000,6,false) -> NoHo B | D10: =vlookup($C10,Teams!$B:$D,3,false) -> 5 | E10: =D10*24 -> 120 | F10: =countifs(PrelimRaw!$D$1:$D1000,$A10,PrelimRaw!$C$1:$C1000,4)+countifs(PrelimRaw!$D$1:$D1000,$A10,PrelimRaw!$C$1:$C1000,14) -> 35 | G10: =countifs(PrelimRaw!$D$1:$D1000,$A10,PrelimRaw!$C$1:$C1000,0) -> 19 | H10: =countifs(PrelimRaw!$D$1:$D1000,$A10,PrelimRaw!$C$1:$C1000,-4) -> 4 | I10: =F10+G10+H10 -> 58 | J10: =I10/E10 -> 0.48333333 | K10: =iferror(F10/I10,0) -> 0.60344828 | L10: =4*F10-4*H10 -> 124 | M10: =L10/D10 -> 24.8 | N10: =vlookup($A10,'X-Risk'!$A:$M,13,false) -> 4 | O10: =vlookup($A10,Math!$A:$M,13,false) -> 3.2 | P10: =vlookup($A10,Chemistry!$A:$M,13,false) -> 8.8 | Q10: =vlookup($A10,EarthSpace!$A:$M,13,false) -> 2.4 | R10: =vlookup($A10,Biology!$A:$M,13,false) -> 1.6 | S10: =vlookup($A10,Physics!$A:$M,13,false) -> 4.8
A11: 103951081173066298964 | B11: =vlookup($A11,Users!$B$1:$H1000,3,false) -> Harry | C11: =vlookup($A11,Users!$B$1:$H1000,6,false) -> Middleton | D11: =vlookup($C11,Teams!$B:$D,3,false) -> 5 | E11: =D11*24 -> 120 | F11: =countifs(PrelimRaw!$D$1:$D1000,$A11,PrelimRaw!$C$1:$C1000,4)+countifs(PrelimRaw!$D$1:$D1000,$A11,PrelimRaw!$C$1:$C1000,14) -> 30 | G11: =countifs(PrelimRaw!$D$1:$D1000,$A11,PrelimRaw!$C$1:$C1000,0) -> 7 | H11: =countifs(PrelimRaw!$D$1:$D1000,$A11,PrelimRaw!$C$1:$C1000,-4) -> 0 | I11: =F11+G11+H11 -> 37 | J11: =I11/E11 -> 0.30833333 | K11: =iferror(F11/I11,0) -> 0.81081081 | L11: =4*F11-4*H11 -> 120 | M11: =L11/D11 -> 24 | N11: =vlookup($A11,'X-Risk'!$A:$M,13,false) -> 5.6 | O11: =vlookup($A11,Math!$A:$M,13,false) -> 4.8 | P11: =vlookup($A11,Chemistry!$A:$M,13,false) -> 8.8 | Q11: =vlookup($A11,EarthSpace!$A:$M,13,false) -> 3.2 | R11: =vlookup($A11,Biology!$A:$M,13,false) -> 0.8 | S11: =vlookup($A11,Physics!$A:$M,13,false) -> 0.8
A12: 104714961629414741842 | B12: =vlookup($A12,Users!$B$1:$H1000,3,false) -> Evin | C12: =vlookup($A12,Users!$B$1:$H1000,6,false) -> Lexington A | D12: =vlookup($C12,Teams!$B:$D,3,false) -> 5 | E12: =D12*24 -> 120 | F12: =countifs(PrelimRaw!$D$1:$D1000,$A12,PrelimRaw!$C$1:$C1000,4)+countifs(PrelimRaw!$D$1:$D1000,$A12,PrelimRaw!$C$1:$C1000,14) -> 32 | G12: =countifs(PrelimRaw!$D$1:$D1000,$A12,PrelimRaw!$C$1:$C1000,0) -> 6 | H12: =countifs(PrelimRaw!$D$1:$D1000,$A12,PrelimRaw!$C$1:$C1000,-4) -> 3 | I12: =F12+G12+H12 -> 41 | J12: =I12/E12 -> 0.34166667 | K12: =iferror(F12/I12,0) -> 0.7804878 | L12: =4*F12-4*H12 -> 116 | M12: =L12/D12 -> 23.2 | N12: =vlookup($A12,'X-Risk'!$A:$M,13,false) -> 4.8 | O12: =vlookup($A12,Math!$A:$M,13,false) -> 7.2 | P12: =vlookup($A12,Chemistry!$A:$M,13,false) -> -0.8 | Q12: =vlookup($A12,EarthSpace!$A:$M,13,false) -> 0.8 | R12: =vlookup($A12,Biology!$A:$M,13,false) -> 1.6 | S12: =vlookup($A12,Physics!$A:$M,13,false) -> 9.6
A13: 105885321269112639389 | B13: =vlookup($A13,Users!$B$1:$H1000,3,false) -> Edward | C13: =vlookup($A13,Users!$B$1:$H1000,6,false) -> Shen | D13: =vlookup($C13,Teams!$B:$D,3,false) -> 5 | E13: =D13*24 -> 120 | F13: =countifs(PrelimRaw!$D$1:$D1000,$A13,PrelimRaw!$C$1:$C1000,4)+countifs(PrelimRaw!$D$1:$D1000,$A13,PrelimRaw!$C$1:$C1000,14) -> 30 | G13: =countifs(PrelimRaw!$D$1:$D1000,$A13,PrelimRaw!$C$1:$C1000,0) -> 12 | H13: =countifs(PrelimRaw!$D$1:$D1000,$A13,PrelimRaw!$C$1:$C1000,-4) -> 1 | I13: =F13+G13+H13 -> 43 | J13: =I13/E13 -> 0.35833333 | K13: =iferror(F13/I13,0) -> 0.69767442 | L13: =4*F13-4*H13 -> 116 | M13: =L13/D13 -> 23.2 | N13: =vlookup($A13,'X-Risk'!$A:$M,13,false) -> 2.4 | O13: =vlookup($A13,Math!$A:$M,13,false) -> 0.8 | P13: =vlookup($A13,Chemistry!$A:$M,13,false) -> 4 | Q13: =vlookup($A13,EarthSpace!$A:$M,13,false) -> 5.6 | R13: =vlookup($A13,Biology!$A:$M,13,false) -> 7.2 | S13: =vlookup($A13,Physics!$A:$M,13,false) -> 3.2
A14: 117280045524168167150 | B14: =vlookup($A14,Users!$B$1:$H1000,3,false) -> Boheng | C14: =vlookup($A14,Users!$B$1:$H1000,6,false) -> NoHo | D14: =vlookup($C14,Teams!$B:$D,3,false) -> 5 | E14: =D14*24 -> 120 | F14: =countifs(PrelimRaw!$D$1:$D1000,$A14,PrelimRaw!$C$1:$C1000,4)+countifs(PrelimRaw!$D$1:$D1000,$A14,PrelimRaw!$C$1:$C1000,14) -> 29 | G14: =countifs(PrelimRaw!$D$1:$D1000,$A14,PrelimRaw!$C$1:$C1000,0) -> 5 | H14: =countifs(PrelimRaw!$D$1:$D1000,$A14,PrelimRaw!$C$1:$C1000,-4) -> 0 | I14: =F14+G14+H14 -> 34 | J14: =I14/E14 -> 0.28333333 | K14: =iferror(F14/I14,0) -> 0.85294118 | L14: =4*F14-4*H14 -> 116 | M14: =L14/D14 -> 23.2 | N14: =vlookup($A14,'X-Risk'!$A:$M,13,false) -> 4 | O14: =vlookup($A14,Math!$A:$M,13,false) -> 9.6 | P14: =vlookup($A14,Chemistry!$A:$M,13,false) -> 1.6 | Q14: =vlookup($A14,EarthSpace!$A:$M,13,false) -> 0 | R14: =vlookup($A14,Biology!$A:$M,13,false) -> 0.8 | S14: =vlookup($A14,Physics!$A:$M,13,false) -> 6.4
A15: 100452237492909123862 | B15: =vlookup($A15,Users!$B$1:$H1000,3,false) -> Kaiwen | C15: =vlookup($A15,Users!$B$1:$H1000,6,false) -> Enloe B | D15: =vlookup($C15,Teams!$B:$D,3,false) -> 5 | E15: =D15*24 -> 120 | F15: =countifs(PrelimRaw!$D$1:$D1000,$A15,PrelimRaw!$C$1:$C1000,4)+countifs(PrelimRaw!$D$1:$D1000,$A15,PrelimRaw!$C$1:$C1000,14) -> 34 | G15: =countifs(PrelimRaw!$D$1:$D1000,$A15,PrelimRaw!$C$1:$C1000,0) -> 6 | H15: =countifs(PrelimRaw!$D$1:$D1000,$A15,PrelimRaw!$C$1:$C1000,-4) -> 6 | I15: =F15+G15+H15 -> 46 | J15: =I15/E15 -> 0.38333333 | K15: =iferror(F15/I15,0) -> 0.73913043 | L15: =4*F15-4*H15 -> 112 | M15: =L15/D15 -> 22.4 | N15: =vlookup($A15,'X-Risk'!$A:$M,13,false) -> 4 | O15: =vlookup($A15,Math!$A:$M,13,false) -> 0.8 | P15: =vlookup($A15,Chemistry!$A:$M,13,false) -> 7.2 | Q15: =vlookup($A15,EarthSpace!$A:$M,13,false) -> 2.4 | R15: =vlookup($A15,Biology!$A:$M,13,false) -> 0 | S15: =vlookup($A15,Physics!$A:$M,13,false) -> 8
A16: 106172791161887099127 | B16: =vlookup($A16,Users!$B$1:$H1000,3,false) -> Ryan | C16: =vlookup($A16,Users!$B$1:$H1000,6,false) -> Iolani | D16: =vlookup($C16,Teams!$B:$D,3,false) -> 5 | E16: =D16*24 -> 120 | F16: =countifs(PrelimRaw!$D$1:$D1000,$A16,PrelimRaw!$C$1:$C1000,4)+countifs(PrelimRaw!$D$1:$D1000,$A16,PrelimRaw!$C$1:$C1000,14) -> 26 | G16: =countifs(PrelimRaw!$D$1:$D1000,$A16,PrelimRaw!$C$1:$C1000,0) -> 19 | H16: =countifs(PrelimRaw!$D$1:$D1000,$A16,PrelimRaw!$C$1:$C1000,-4) -> 0 | I16: =F16+G16+H16 -> 45 | J16: =I16/E16 -> 0.375 | K16: =iferror(F16/I16,0) -> 0.57777778 | L16: =4*F16-4*H16 -> 104 | M16: =L16/D16 -> 20.8 | N16: =vlookup($A16,'X-Risk'!$A:$M,13,false) -> 3.2 | O16: =vlookup($A16,Math!$A:$M,13,false) -> 1.6 | P16: =vlookup($A16,Chemistry!$A:$M,13,false) -> 4.8 | Q16: =vlookup($A16,EarthSpace!$A:$M,13,false) -> 5.6 | R16: =vlookup($A16,Biology!$A:$M,13,false) -> 2.4 | S16: =vlookup($A16,Physics!$A:$M,13,false) -> 3.2
A17: 101259634814577741936 | B17: =vlookup($A17,Users!$B$1:$H1000,3,false) -> Samuel | C17: =vlookup($A17,Users!$B$1:$H1000,6,false) -> MSJ | D17: =vlookup($C17,Teams!$B:$D,3,false) -> 5 | E17: =D17*24 -> 120 | F17: =countifs(PrelimRaw!$D$1:$D1000,$A17,PrelimRaw!$C$1:$C1000,4)+countifs(PrelimRaw!$D$1:$D1000,$A17,PrelimRaw!$C$1:$C1000,14) -> 31 | G17: =countifs(PrelimRaw!$D$1:$D1000,$A17,PrelimRaw!$C$1:$C1000,0) -> 2 | H17: =countifs(PrelimRaw!$D$1:$D1000,$A17,PrelimRaw!$C$1:$C1000,-4) -> 6 | I17: =F17+G17+H17 -> 39 | J17: =I17/E17 -> 0.325 | K17: =iferror(F17/I17,0) -> 0.79487179 | L17: =4*F17-4*H17 -> 100 | M17: =L17/D17 -> 20 | N17: =vlookup($A17,'X-Risk'!$A:$M,13,false) -> 3.2 | O17: =vlookup($A17,Math!$A:$M,13,false) -> 7.2 | P17: =vlookup($A17,Chemistry!$A:$M,13,false) -> -0.8 | Q17: =vlookup($A17,EarthSpace!$A:$M,13,false) -> 2.4 | R17: =vlookup($A17,Biology!$A:$M,13,false) -> 0.8 | S17: =vlookup($A17,Physics!$A:$M,13,false) -> 8
A18: 100460385825974417248 | B18: =vlookup($A18,Users!$B$1:$H1000,3,false) -> Mason | C18: =vlookup($A18,Users!$B$1:$H1000,6,false) -> Westminster | D18: =vlookup($C18,Teams!$B:$D,3,false) -> 5 | E18: =D18*24 -> 120 | F18: =countifs(PrelimRaw!$D$1:$D1000,$A18,PrelimRaw!$C$1:$C1000,4)+countifs(PrelimRaw!$D$1:$D1000,$A18,PrelimRaw!$C$1:$C1000,14) -> 32 | G18: =countifs(PrelimRaw!$D$1:$D1000,$A18,PrelimRaw!$C$1:$C1000,0) -> 12 | H18: =countifs(PrelimRaw!$D$1:$D1000,$A18,PrelimRaw!$C$1:$C1000,-4) -> 7 | I18: =F18+G18+H18 -> 51 | J18: =I18/E18 -> 0.425 | K18: =iferror(F18/I18,0) -> 0.62745098 | L18: =4*F18-4*H18 -> 100 | M18: =L18/D18 -> 20 | N18: =vlookup($A18,'X-Risk'!$A:$M,13,false) -> 6.4 | O18: =vlookup($A18,Math!$A:$M,13,false) -> 0 | P18: =vlookup($A18,Chemistry!$A:$M,13,false) -> 1.6 | Q18: =vlookup($A18,EarthSpace!$A:$M,13,false) -> 3.2 | R18: =vlookup($A18,Biology!$A:$M,13,false) -> 5.6 | S18: =vlookup($A18,Physics!$A:$M,13,false) -> 3.2
A19: 115694056893101775002 | B19: =vlookup($A19,Users!$B$1:$H1000,3,false) -> Aaditya | C19: =vlookup($A19,Users!$B$1:$H1000,6,false) -> Cupertino | D19: =vlookup($C19,Teams!$B:$D,3,false) -> 5 | E19: =D19*24 -> 120 | F19: =countifs(PrelimRaw!$D$1:$D1000,$A19,PrelimRaw!$C$1:$C1000,4)+countifs(PrelimRaw!$D$1:$D1000,$A19,PrelimRaw!$C$1:$C1000,14) -> 26 | G19: =countifs(PrelimRaw!$D$1:$D1000,$A19,PrelimRaw!$C$1:$C1000,0) -> 7 | H19: =countifs(PrelimRaw!$D$1:$D1000,$A19,PrelimRaw!$C$1:$C1000,-4) -> 1 | I19: =F19+G19+H19 -> 34 | J19: =I19/E19 -> 0.28333333 | K19: =iferror(F19/I19,0) -> 0.76470588 | L19: =4*F19-4*H19 -> 100 | M19: =L19/D19 -> 20 | N19: =vlookup($A19,'X-Risk'!$A:$M,13,false) -> 4 | O19: =vlookup($A19,Math!$A:$M,13,false) -> 0 | P19: =vlookup($A19,Chemistry!$A:$M,13,false) -> 4.8 | Q19: =vlookup($A19,EarthSpace!$A:$M,13,false) -> 1.6 | R19: =vlookup($A19,Biology!$A:$M,13,false) -> 8.8 | S19: =vlookup($A19,Physics!$A:$M,13,false) -> 0.8
A20: 107077468607348826234 | B20: =vlookup($A20,Users!$B$1:$H1000,3,false) -> Colin | C20: =vlookup($A20,Users!$B$1:$H1000,6,false) -> Enloe A | D20: =vlookup($C20,Teams!$B:$D,3,false) -> 5 | E20: =D20*24 -> 120 | F20: =countifs(PrelimRaw!$D$1:$D1000,$A20,PrelimRaw!$C$1:$C1000,4)+countifs(PrelimRaw!$D$1:$D1000,$A20,PrelimRaw!$C$1:$C1000,14) -> 27 | G20: =countifs(PrelimRaw!$D$1:$D1000,$A20,PrelimRaw!$C$1:$C1000,0) -> 6 | H20: =countifs(PrelimRaw!$D$1:$D1000,$A20,PrelimRaw!$C$1:$C1000,-4) -> 4 | I20: =F20+G20+H20 -> 37 | J20: =I20/E20 -> 0.30833333 | K20: =iferror(F20/I20,0) -> 0.72972973 | L20: =4*F20-4*H20 -> 92 | M20: =L20/D20 -> 18.4 | N20: =vlookup($A20,'X-Risk'!$A:$M,13,false) -> 2.4 | O20: =vlookup($A20,Math!$A:$M,13,false) -> 2.4 | P20: =vlookup($A20,Chemistry!$A:$M,13,false) -> 4 | Q20: =vlookup($A20,EarthSpace!$A:$M,13,false) -> 0.8 | R20: =vlookup($A20,Biology!$A:$M,13,false) -> 0 | S20: =vlookup($A20,Physics!$A:$M,13,false) -> 8.8
A21: 107520337771987267201 | B21: =vlookup($A21,Users!$B$1:$H1000,3,false) -> Andrey | C21: =vlookup($A21,Users!$B$1:$H1000,6,false) -> Buchholz A | D21: =vlookup($C21,Teams!$B:$D,3,false) -> 5 | E21: =D21*24 -> 120 | F21: =countifs(PrelimRaw!$D$1:$D1000,$A21,PrelimRaw!$C$1:$C1000,4)+countifs(PrelimRaw!$D$1:$D1000,$A21,PrelimRaw!$C$1:$C1000,14) -> 30 | G21: =countifs(PrelimRaw!$D$1:$D1000,$A21,PrelimRaw!$C$1:$C1000,0) -> 6 | H21: =countifs(PrelimRaw!$D$1:$D1000,$A21,PrelimRaw!$C$1:$C1000,-4) -> 8 | I21: =F21+G21+H21 -> 44 | J21: =I21/E21 -> 0.36666667 | K21: =iferror(F21/I21,0) -> 0.68181818 | L21: =4*F21-4*H21 -> 88 | M21: =L21/D21 -> 17.6 | N21: =vlookup($A21,'X-Risk'!$A:$M,13,false) -> 2.4 | O21: =vlookup($A21,Math!$A:$M,13,false) -> 1.6 | P21: =vlookup($A21,Chemistry!$A:$M,13,false) -> 0.8 | Q21: =vlookup($A21,EarthSpace!$A:$M,13,false) -> 4.8 | R21: =vlookup($A21,Biology!$A:$M,13,false) -> 7.2 | S21: =vlookup($A21,Physics!$A:$M,13,false) -> 0.8
A22: 110844812019204409144 | B22: =vlookup($A22,Users!$B$1:$H1000,3,false) -> Jake | C22: =vlookup($A22,Users!$B$1:$H1000,6,false) -> Cupertino | D22: =vlookup($C22,Teams!$B:$D,3,false) -> 5 | E22: =D22*24 -> 120 | F22: =countifs(PrelimRaw!$D$1:$D1000,$A22,PrelimRaw!$C$1:$C1000,4)+countifs(PrelimRaw!$D$1:$D1000,$A22,PrelimRaw!$C$1:$C1000,14) -> 24 | G22: =countifs(PrelimRaw!$D$1:$D1000,$A22,PrelimRaw!$C$1:$C1000,0) -> 9 | H22: =countifs(PrelimRaw!$D$1:$D1000,$A22,PrelimRaw!$C$1:$C1000,-4) -> 2 | I22: =F22+G22+H22 -> 35 | J22: =I22/E22 -> 0.29166667 | K22: =iferror(F22/I22,0) -> 0.68571429 | L22: =4*F22-4*H22 -> 88 | M22: =L22/D22 -> 17.6 | N22: =vlookup($A22,'X-Risk'!$A:$M,13,false) -> 2.4 | O22: =vlookup($A22,Math!$A:$M,13,false) -> 5.6 | P22: =vlookup($A22,Chemistry!$A:$M,13,false) -> 1.6 | Q22: =vlookup($A22,EarthSpace!$A:$M,13,false) -> 1.6 | R22: =vlookup($A22,Biology!$A:$M,13,false) -> 0 | S22: =vlookup($A22,Physics!$A:$M,13,false) -> 6.4
A23: 110072705132871488717 | B23: =vlookup($A23,Users!$B$1:$H1000,3,false) -> Mihir | C23: =vlookup($A23,Users!$B$1:$H1000,6,false) -> Niskayuna | D23: =vlookup($C23,Teams!$B:$D,3,false) -> 5 | E23: =D23*24 -> 120 | F23: =countifs(PrelimRaw!$D$1:$D1000,$A23,PrelimRaw!$C$1:$C1000,4)+countifs(PrelimRaw!$D$1:$D1000,$A23,PrelimRaw!$C$1:$C1000,14) -> 21 | G23: =countifs(PrelimRaw!$D$1:$D1000,$A23,PrelimRaw!$C$1:$C1000,0) -> 34 | H23: =countifs(PrelimRaw!$D$1:$D1000,$A23,PrelimRaw!$C$1:$C1000,-4) -> 0 | I23: =F23+G23+H23 -> 55 | J23: =I23/E23 -> 0.45833333 | K23: =iferror(F23/I23,0) -> 0.38181818 | L23: =4*F23-4*H23 -> 84 | M23: =L23/D23 -> 16.8 | N23: =vlookup($A23,'X-Risk'!$A:$M,13,false) -> 4.8 | O23: =vlookup($A23,Math!$A:$M,13,false) -> 3.2 | P23: =vlookup($A23,Chemistry!$A:$M,13,false) -> 1.6 | Q23: =vlookup($A23,EarthSpace!$A:$M,13,false) -> 0.8 | R23: =vlookup($A23,Biology!$A:$M,13,false) -> 5.6 | S23: =vlookup($A23,Physics!$A:$M,13,false) -> 0.8
A24: 100662456472081319887 | B24: =vlookup($A24,Users!$B$1:$H1000,3,false) -> Daniel | C24: =vlookup($A24,Users!$B$1:$H1000,6,false) -> Lexington B | D24: =vlookup($C24,Teams!$B:$D,3,false) -> 5 | E24: =D24*24 -> 120 | F24: =countifs(PrelimRaw!$D$1:$D1000,$A24,PrelimRaw!$C$1:$C1000,4)+countifs(PrelimRaw!$D$1:$D1000,$A24,PrelimRaw!$C$1:$C1000,14) -> 24 | G24: =countifs(PrelimRaw!$D$1:$D1000,$A24,PrelimRaw!$C$1:$C1000,0) -> 14 | H24: =countifs(PrelimRaw!$D$1:$D1000,$A24,PrelimRaw!$C$1:$C1000,-4) -> 3 | I24: =F24+G24+H24 -> 41 | J24: =I24/E24 -> 0.34166667 | K24: =iferror(F24/I24,0) -> 0.58536585 | L24: =4*F24-4*H24 -> 84 | M24: =L24/D24 -> 16.8 | N24: =vlookup($A24,'X-Risk'!$A:$M,13,false) -> 4.8 | O24: =vlookup($A24,Math!$A:$M,13,false) -> 0 | P24: =vlookup($A24,Chemistry!$A:$M,13,false) -> 1.6 | Q24: =vlookup($A24,EarthSpace!$A:$M,13,false) -> 7.2 | R24: =vlookup($A24,Biology!$A:$M,13,false) -> 1.6 | S24: =vlookup($A24,Physics!$A:$M,13,false) -> 1.6
A25: 106913584674750189410 | B25: =vlookup($A25,Users!$B$1:$H1000,3,false) -> Alex | C25: =vlookup($A25,Users!$B$1:$H1000,6,false) -> NoHo | D25: =vlookup($C25,Teams!$B:$D,3,false) -> 5 | E25: =D25*24 -> 120 | F25: =countifs(PrelimRaw!$D$1:$D1000,$A25,PrelimRaw!$C$1:$C1000,4)+countifs(PrelimRaw!$D$1:$D1000,$A25,PrelimRaw!$C$1:$C1000,14) -> 25 | G25: =countifs(PrelimRaw!$D$1:$D1000,$A25,PrelimRaw!$C$1:$C1000,0) -> 6 | H25: =countifs(PrelimRaw!$D$1:$D1000,$A25,PrelimRaw!$C$1:$C1000,-4) -> 4 | I25: =F25+G25+H25 -> 35 | J25: =I25/E25 -> 0.29166667 | K25: =iferror(F25/I25,0) -> 0.71428571 | L25: =4*F25-4*H25 -> 84 | M25: =L25/D25 -> 16.8 | N25: =vlookup($A25,'X-Risk'!$A:$M,13,false) -> 5.6 | O25: =vlookup($A25,Math!$A:$M,13,false) -> 0 | P25: =vlookup($A25,Chemistry!$A:$M,13,false) -> 2.4 | Q25: =vlookup($A25,EarthSpace!$A:$M,13,false) -> 8.8 | R25: =vlookup($A25,Biology!$A:$M,13,false) -> -0.8 | S25: =vlookup($A25,Physics!$A:$M,13,false) -> 0.8
A26: 104495540205548736558 | B26: =vlookup($A26,Users!$B$1:$H1000,3,false) -> Emmy | C26: =vlookup($A26,Users!$B$1:$H1000,6,false) -> Davidson | D26: =vlookup($C26,Teams!$B:$D,3,false) -> 5 | E26: =D26*24 -> 120 | F26: =countifs(PrelimRaw!$D$1:$D1000,$A26,PrelimRaw!$C$1:$C1000,4)+countifs(PrelimRaw!$D$1:$D1000,$A26,PrelimRaw!$C$1:$C1000,14) -> 24 | G26: =countifs(PrelimRaw!$D$1:$D1000,$A26,PrelimRaw!$C$1:$C1000,0) -> 6 | H26: =countifs(PrelimRaw!$D$1:$D1000,$A26,PrelimRaw!$C$1:$C1000,-4) -> 4 | I26: =F26+G26+H26 -> 34 | J26: =I26/E26 -> 0.28333333 | K26: =iferror(F26/I26,0) -> 0.70588235 | L26: =4*F26-4*H26 -> 80 | M26: =L26/D26 -> 16 | N26: =vlookup($A26,'X-Risk'!$A:$M,13,false) -> 2.4 | O26: =vlookup($A26,Math!$A:$M,13,false) -> 0 | P26: =vlookup($A26,Chemistry!$A:$M,13,false) -> 2.4 | Q26: =vlookup($A26,EarthSpace!$A:$M,13,false) -> 8 | R26: =vlookup($A26,Biology!$A:$M,13,false) -> 0.8 | S26: =vlookup($A26,Physics!$A:$M,13,false) -> 2.4
A27: 117343382433914933310 | B27: =vlookup($A27,Users!$B$1:$H1000,3,false) -> Aneesh | C27: =vlookup($A27,Users!$B$1:$H1000,6,false) -> Wayzata | D27: =vlookup($C27,Teams!$B:$D,3,false) -> 5 | E27: =D27*24 -> 120 | F27: =countifs(PrelimRaw!$D$1:$D1000,$A27,PrelimRaw!$C$1:$C1000,4)+countifs(PrelimRaw!$D$1:$D1000,$A27,PrelimRaw!$C$1:$C1000,14) -> 23 | G27: =countifs(PrelimRaw!$D$1:$D1000,$A27,PrelimRaw!$C$1:$C1000,0) -> 8 | H27: =countifs(PrelimRaw!$D$1:$D1000,$A27,PrelimRaw!$C$1:$C1000,-4) -> 3 | I27: =F27+G27+H27 -> 34 | J27: =I27/E27 -> 0.28333333 | K27: =iferror(F27/I27,0) -> 0.67647059 | L27: =4*F27-4*H27 -> 80 | M27: =L27/D27 -> 16 | N27: =vlookup($A27,'X-Risk'!$A:$M,13,false) -> 2.4 | O27: =vlookup($A27,Math!$A:$M,13,false) -> 0 | P27: =vlookup($A27,Chemistry!$A:$M,13,false) -> 2.4 | Q27: =vlookup($A27,EarthSpace!$A:$M,13,false) -> 0.8 | R27: =vlookup($A27,Biology!$A:$M,13,false) -> 10.4 | S27: =vlookup($A27,Physics!$A:$M,13,false) -> 0
A28: 118074352666382404421 | B28: =vlookup($A28,Users!$B$1:$H1000,3,false) -> Harsh | C28: =vlookup($A28,Users!$B$1:$H1000,6,false) -> Green Hope | D28: =vlookup($C28,Teams!$B:$D,3,false) -> 5 | E28: =D28*24 -> 120 | F28: =countifs(PrelimRaw!$D$1:$D1000,$A28,PrelimRaw!$C$1:$C1000,4)+countifs(PrelimRaw!$D$1:$D1000,$A28,PrelimRaw!$C$1:$C1000,14) -> 21 | G28: =countifs(PrelimRaw!$D$1:$D1000,$A28,PrelimRaw!$C$1:$C1000,0) -> 13 | H28: =countifs(PrelimRaw!$D$1:$D1000,$A28,PrelimRaw!$C$1:$C1000,-4) -> 1 | I28: =F28+G28+H28 -> 35 | J28: =I28/E28 -> 0.29166667 | K28: =iferror(F28/I28,0) -> 0.6 | L28: =4*F28-4*H28 -> 80 | M28: =L28/D28 -> 16 | N28: =vlookup($A28,'X-Risk'!$A:$M,13,false) -> 0 | O28: =vlookup($A28,Math!$A:$M,13,false) -> 0 | P28: =vlookup($A28,Chemistry!$A:$M,13,false) -> 3.2 | Q28: =vlookup($A28,EarthSpace!$A:$M,13,false) -> 6.4 | R28: =vlookup($A28,Biology!$A:$M,13,false) -> 0.8 | S28: =vlookup($A28,Physics!$A:$M,13,false) -> 5.6
A29: 116807051909331854620 | B29: =vlookup($A29,Users!$B$1:$H1000,3,false) -> Rushil | C29: =vlookup($A29,Users!$B$1:$H1000,6,false) -> Dulles | D29: =vlookup($C29,Teams!$B:$D,3,false) -> 5 | E29: =D29*24 -> 120 | F29: =countifs(PrelimRaw!$D$1:$D1000,$A29,PrelimRaw!$C$1:$C1000,4)+countifs(PrelimRaw!$D$1:$D1000,$A29,PrelimRaw!$C$1:$C1000,14) -> 19 | G29: =countifs(PrelimRaw!$D$1:$D1000,$A29,PrelimRaw!$C$1:$C1000,0) -> 5 | H29: =countifs(PrelimRaw!$D$1:$D1000,$A29,PrelimRaw!$C$1:$C1000,-4) -> 0 | I29: =F29+G29+H29 -> 24 | J29: =I29/E29 -> 0.2 | K29: =iferror(F29/I29,0) -> 0.79166667 | L29: =4*F29-4*H29 -> 76 | M29: =L29/D29 -> 15.2 | N29: =vlookup($A29,'X-Risk'!$A:$M,13,false) -> 0.8 | O29: =vlookup($A29,Math!$A:$M,13,false) -> 4.8 | P29: =vlookup($A29,Chemistry!$A:$M,13,false) -> 0 | Q29: =vlookup($A29,EarthSpace!$A:$M,13,false) -> 2.4 | R29: =vlookup($A29,Biology!$A:$M,13,false) -> 0 | S29: =vlookup($A29,Physics!$A:$M,13,false) -> 7.2
A30: 115701416956189742203 | B30: =vlookup($A30,Users!$B$1:$H1000,3,false) -> Gugan | C30: =vlookup($A30,Users!$B$1:$H1000,6,false) -> Blair C | D30: =vlookup($C30,Teams!$B:$D,3,false) -> 5 | E30: =D30*24 -> 120 | F30: =countifs(PrelimRaw!$D$1:$D1000,$A30,PrelimRaw!$C$1:$C1000,4)+countifs(PrelimRaw!$D$1:$D1000,$A30,PrelimRaw!$C$1:$C1000,14) -> 18 | G30: =countifs(PrelimRaw!$D$1:$D1000,$A30,PrelimRaw!$C$1:$C1000,0) -> 10 | H30: =countifs(PrelimRaw!$D$1:$D1000,$A30,PrelimRaw!$C$1:$C1000,-4) -> 1 | I30: =F30+G30+H30 -> 29 | J30: =I30/E30 -> 0.24166667 | K30: =iferror(F30/I30,0) -> 0.62068966 | L30: =4*F30-4*H30 -> 68 | M30: =L30/D30 -> 13.6 | N30: =vlookup($A30,'X-Risk'!$A:$M,13,false) -> 3.2 | O30: =vlookup($A30,Math!$A:$M,13,false) -> 0.8 | P30: =vlookup($A30,Chemistry!$A:$M,13,false) -> 4 | Q30: =vlookup($A30,EarthSpace!$A:$M,13,false) -> 0.8 | R30: =vlookup($A30,Biology!$A:$M,13,false) -> 0 | S30: =vlookup($A30,Physics!$A:$M,13,false) -> 4.8
A31: 114036554181471873823 | B31: =vlookup($A31,Users!$B$1:$H1000,3,false) -> Aldric | C31: =vlookup($A31,Users!$B$1:$H1000,6,false) -> WWPN | D31: =vlookup($C31,Teams!$B:$D,3,false) -> 5 | E31: =D31*24 -> 120 | F31: =countifs(PrelimRaw!$D$1:$D1000,$A31,PrelimRaw!$C$1:$C1000,4)+countifs(PrelimRaw!$D$1:$D1000,$A31,PrelimRaw!$C$1:$C1000,14) -> 20 | G31: =countifs(PrelimRaw!$D$1:$D1000,$A31,PrelimRaw!$C$1:$C1000,0) -> 7 | H31: =countifs(PrelimRaw!$D$1:$D1000,$A31,PrelimRaw!$C$1:$C1000,-4) -> 3 | I31: =F31+G31+H31 -> 30 | J31: =I31/E31 -> 0.25 | K31: =iferror(F31/I31,0) -> 0.66666667 | L31: =4*F31-4*H31 -> 68 | M31: =L31/D31 -> 13.6 | N31: =vlookup($A31,'X-Risk'!$A:$M,13,false) -> 4.8 | O31: =vlookup($A31,Math!$A:$M,13,false) -> 0 | P31: =vlookup($A31,Chemistry!$A:$M,13,false) -> 0.8 | Q31: =vlookup($A31,EarthSpace!$A:$M,13,false) -> 4 | R31: =vlookup($A31,Biology!$A:$M,13,false) -> 0 | S31: =vlookup($A31,Physics!$A:$M,13,false) -> 4
A32: 116748200742147664071 | B32: =vlookup($A32,Users!$B$1:$H1000,3,false) -> Tristan | C32: =vlookup($A32,Users!$B$1:$H1000,6,false) -> Interlake B | D32: =vlookup($C32,Teams!$B:$D,3,false) -> 5 | E32: =D32*24 -> 120 | F32: =countifs(PrelimRaw!$D$1:$D1000,$A32,PrelimRaw!$C$1:$C1000,4)+countifs(PrelimRaw!$D$1:$D1000,$A32,PrelimRaw!$C$1:$C1000,14) -> 17 | G32: =countifs(PrelimRaw!$D$1:$D1000,$A32,PrelimRaw!$C$1:$C1000,0) -> 10 | H32: =countifs(PrelimRaw!$D$1:$D1000,$A32,PrelimRaw!$C$1:$C1000,-4) -> 0 | I32: =F32+G32+H32 -> 27 | J32: =I32/E32 -> 0.225 | K32: =iferror(F32/I32,0) -> 0.62962963 | L32: =4*F32-4*H32 -> 68 | M32: =L32/D32 -> 13.6 | N32: =vlookup($A32,'X-Risk'!$A:$M,13,false) -> 1.6 | O32: =vlookup($A32,Math!$A:$M,13,false) -> 8.8 | P32: =vlookup($A32,Chemistry!$A:$M,13,false) -> 0.8 | Q32: =vlookup($A32,EarthSpace!$A:$M,13,false) -> 0 | R32: =vlookup($A32,Biology!$A:$M,13,false) -> 0 | S32: =vlookup($A32,Physics!$A:$M,13,false) -> 2.4
A33: 100018707023206150456 | B33: =vlookup($A33,Users!$B$1:$H1000,3,false) -> Flora | C33: =vlookup($A33,Users!$B$1:$H1000,6,false) -> Canyon Crest | D33: =vlookup($C33,Teams!$B:$D,3,false) -> 5 | E33: =D33*24 -> 120 | F33: =countifs(PrelimRaw!$D$1:$D1000,$A33,PrelimRaw!$C$1:$C1000,4)+countifs(PrelimRaw!$D$1:$D1000,$A33,PrelimRaw!$C$1:$C1000,14) -> 19 | G33: =countifs(PrelimRaw!$D$1:$D1000,$A33,PrelimRaw!$C$1:$C1000,0) -> 12 | H33: =countifs(PrelimRaw!$D$1:$D1000,$A33,PrelimRaw!$C$1:$C1000,-4) -> 2 | I33: =F33+G33+H33 -> 33 | J33: =I33/E33 -> 0.275 | K33: =iferror(F33/I33,0) -> 0.57575758 | L33: =4*F33-4*H33 -> 68 | M33: =L33/D33 -> 13.6 | N33: =vlookup($A33,'X-Risk'!$A:$M,13,false) -> 2.4 | O33: =vlookup($A33,Math!$A:$M,13,false) -> 0 | P33: =vlookup($A33,Chemistry!$A:$M,13,false) -> 0.8 | Q33: =vlookup($A33,EarthSpace!$A:$M,13,false) -> 5.6 | R33: =vlookup($A33,Biology!$A:$M,13,false) -> 1.6 | S33: =vlookup($A33,Physics!$A:$M,13,false) -> 3.2
A34: 104616720600882690364 | B34: =vlookup($A34,Users!$B$1:$H1000,3,false) -> Kai | C34: =vlookup($A34,Users!$B$1:$H1000,6,false) -> Naperville North | D34: =vlookup($C34,Teams!$B:$D,3,false) -> 5 | E34: =D34*24 -> 120 | F34: =countifs(PrelimRaw!$D$1:$D1000,$A34,PrelimRaw!$C$1:$C1000,4)+countifs(PrelimRaw!$D$1:$D1000,$A34,PrelimRaw!$C$1:$C1000,14) -> 17 | G34: =countifs(PrelimRaw!$D$1:$D1000,$A34,PrelimRaw!$C$1:$C1000,0) -> 11 | H34: =countifs(PrelimRaw!$D$1:$D1000,$A34,PrelimRaw!$C$1:$C1000,-4) -> 0 | I34: =F34+G34+H34 -> 28 | J34: =I34/E34 -> 0.23333333 | K34: =iferror(F34/I34,0) -> 0.60714286 | L34: =4*F34-4*H34 -> 68 | M34: =L34/D34 -> 13.6 | N34: =vlookup($A34,'X-Risk'!$A:$M,13,false) -> 1.6 | O34: =vlookup($A34,Math!$A:$M,13,false) -> 3.2 | P34: =vlookup($A34,Chemistry!$A:$M,13,false) -> 1.6 | Q34: =vlookup($A34,EarthSpace!$A:$M,13,false) -> 1.6 | R34: =vlookup($A34,Biology!$A:$M,13,false) -> 0 | S34: =vlookup($A34,Physics!$A:$M,13,false) -> 5.6
A35: 108152382525909487295 | B35: =vlookup($A35,Users!$B$1:$H1000,3,false) -> Joseph | C35: =vlookup($A35,Users!$B$1:$H1000,6,false) -> RMHS | D35: =vlookup($C35,Teams!$B:$D,3,false) -> 5 | E35: =D35*24 -> 120 | F35: =countifs(PrelimRaw!$D$1:$D1000,$A35,PrelimRaw!$C$1:$C1000,4)+countifs(PrelimRaw!$D$1:$D1000,$A35,PrelimRaw!$C$1:$C1000,14) -> 25 | G35: =countifs(PrelimRaw!$D$1:$D1000,$A35,PrelimRaw!$C$1:$C1000,0) -> 16 | H35: =countifs(PrelimRaw!$D$1:$D1000,$A35,PrelimRaw!$C$1:$C1000,-4) -> 8 | I35: =F35+G35+H35 -> 49 | J35: =I35/E35 -> 0.40833333 | K35: =iferror(F35/I35,0) -> 0.51020408 | L35: =4*F35-4*H35 -> 68 | M35: =L35/D35 -> 13.6 | N35: =vlookup($A35,'X-Risk'!$A:$M,13,false) -> 1.6 | O35: =vlookup($A35,Math!$A:$M,13,false) -> 0 | P35: =vlookup($A35,Chemistry!$A:$M,13,false) -> 1.6 | Q35: =vlookup($A35,EarthSpace!$A:$M,13,false) -> 3.2 | R35: =vlookup($A35,Biology!$A:$M,13,false) -> 4 | S35: =vlookup($A35,Physics!$A:$M,13,false) -> 3.2
A36: 106220113041500550653 | B36: =vlookup($A36,Users!$B$1:$H1000,3,false) -> Rohan | C36: =vlookup($A36,Users!$B$1:$H1000,6,false) -> Ladue | D36: =vlookup($C36,Teams!$B:$D,3,false) -> 5 | E36: =D36*24 -> 120 | F36: =countifs(PrelimRaw!$D$1:$D1000,$A36,PrelimRaw!$C$1:$C1000,4)+countifs(PrelimRaw!$D$1:$D1000,$A36,PrelimRaw!$C$1:$C1000,14) -> 16 | G36: =countifs(PrelimRaw!$D$1:$D1000,$A36,PrelimRaw!$C$1:$C1000,0) -> 8 | H36: =countifs(PrelimRaw!$D$1:$D1000,$A36,PrelimRaw!$C$1:$C1000,-4) -> 0 | I36: =F36+G36+H36 -> 24 | J36: =I36/E36 -> 0.2 | K36: =iferror(F36/I36,0) -> 0.66666667 | L36: =4*F36-4*H36 -> 64 | M36: =L36/D36 -> 12.8 | N36: =vlookup($A36,'X-Risk'!$A:$M,13,false) -> 0.8 | O36: =vlookup($A36,Math!$A:$M,13,false) -> 0 | P36: =vlookup($A36,Chemistry!$A:$M,13,false) -> 7.2 | Q36: =vlookup($A36,EarthSpace!$A:$M,13,false) -> 0.8 | R36: =vlookup($A36,Biology!$A:$M,13,false) -> 2.4 | S36: =vlookup($A36,Physics!$A:$M,13,false) -> 1.6
A37: 113689800994596883699 | B37: =vlookup($A37,Users!$B$1:$H1000,3,false) -> Gokulanath | C37: =vlookup($A37,Users!$B$1:$H1000,6,false) -> MSJ | D37: =vlookup($C37,Teams!$B:$D,3,false) -> 5 | E37: =D37*24 -> 120 | F37: =countifs(PrelimRaw!$D$1:$D1000,$A37,PrelimRaw!$C$1:$C1000,4)+countifs(PrelimRaw!$D$1:$D1000,$A37,PrelimRaw!$C$1:$C1000,14) -> 16 | G37: =countifs(PrelimRaw!$D$1:$D1000,$A37,PrelimRaw!$C$1:$C1000,0) -> 2 | H37: =countifs(PrelimRaw!$D$1:$D1000,$A37,PrelimRaw!$C$1:$C1000,-4) -> 0 | I37: =F37+G37+H37 -> 18 | J37: =I37/E37 -> 0.15 | K37: =iferror(F37/I37,0) -> 0.88888889 | L37: =4*F37-4*H37 -> 64 | M37: =L37/D37 -> 12.8 | N37: =vlookup($A37,'X-Risk'!$A:$M,13,false) -> 0.8 | O37: =vlookup($A37,Math!$A:$M,13,false) -> 0 | P37: =vlookup($A37,Chemistry!$A:$M,13,false) -> 3.2 | Q37: =vlookup($A37,EarthSpace!$A:$M,13,false) -> 0.8 | R37: =vlookup($A37,Biology!$A:$M,13,false) -> 8 | S37: =vlookup($A37,Physics!$A:$M,13,false) -> 0
A38: 105596510344333656930 | B38: =vlookup($A38,Users!$B$1:$H1000,3,false) -> Evan | C38: =vlookup($A38,Users!$B$1:$H1000,6,false) -> Tesla STEM | D38: =vlookup($C38,Teams!$B:$D,3,false) -> 5 | E38: =D38*24 -> 120 | F38: =countifs(PrelimRaw!$D$1:$D1000,$A38,PrelimRaw!$C$1:$C1000,4)+countifs(PrelimRaw!$D$1:$D1000,$A38,PrelimRaw!$C$1:$C1000,14) -> 16 | G38: =countifs(PrelimRaw!$D$1:$D1000,$A38,PrelimRaw!$C$1:$C1000,0) -> 6 | H38: =countifs(PrelimRaw!$D$1:$D1000,$A38,PrelimRaw!$C$1:$C1000,-4) -> 0 | I38: =F38+G38+H38 -> 22 | J38: =I38/E38 -> 0.18333333 | K38: =iferror(F38/I38,0) -> 0.72727273 | L38: =4*F38-4*H38 -> 64 | M38: =L38/D38 -> 12.8 | N38: =vlookup($A38,'X-Risk'!$A:$M,13,false) -> 0 | O38: =vlookup($A38,Math!$A:$M,13,false) -> 6.4 | P38: =vlookup($A38,Chemistry!$A:$M,13,false) -> 0 | Q38: =vlookup($A38,EarthSpace!$A:$M,13,false) -> 0 | R38: =vlookup($A38,Biology!$A:$M,13,false) -> 0.8 | S38: =vlookup($A38,Physics!$A:$M,13,false) -> 5.6
A39: 104040670752305026947 | B39: =vlookup($A39,Users!$B$1:$H1000,3,false) -> Tanmay | C39: =vlookup($A39,Users!$B$1:$H1000,6,false) -> Lexington B | D39: =vlookup($C39,Teams!$B:$D,3,false) -> 5 | E39: =D39*24 -> 120 | F39: =countifs(PrelimRaw!$D$1:$D1000,$A39,PrelimRaw!$C$1:$C1000,4)+countifs(PrelimRaw!$D$1:$D1000,$A39,PrelimRaw!$C$1:$C1000,14) -> 16 | G39: =countifs(PrelimRaw!$D$1:$D1000,$A39,PrelimRaw!$C$1:$C1000,0) -> 3 | H39: =countifs(PrelimRaw!$D$1:$D1000,$A39,PrelimRaw!$C$1:$C1000,-4) -> 0 | I39: =F39+G39+H39 -> 19 | J39: =I39/E39 -> 0.15833333 | K39: =iferror(F39/I39,0) -> 0.84210526 | L39: =4*F39-4*H39 -> 64 | M39: =L39/D39 -> 12.8 | N39: =vlookup($A39,'X-Risk'!$A:$M,13,false) -> 1.6 | O39: =vlookup($A39,Math!$A:$M,13,false) -> 1.6 | P39: =vlookup($A39,Chemistry!$A:$M,13,false) -> 2.4 | Q39: =vlookup($A39,EarthSpace!$A:$M,13,false) -> 0 | R39: =vlookup($A39,Biology!$A:$M,13,false) -> 0 | S39: =vlookup($A39,Physics!$A:$M,13,false) -> 7.2
A40: 109155816154210333669 | B40: =vlookup($A40,Users!$B$1:$H1000,3,false) -> Phoenix | C40: =vlookup($A40,Users!$B$1:$H1000,6,false) -> Seven Lakes | D40: =vlookup($C40,Teams!$B:$D,3,false) -> 5 | E40: =D40*24 -> 120 | F40: =countifs(PrelimRaw!$D$1:$D1000,$A40,PrelimRaw!$C$1:$C1000,4)+countifs(PrelimRaw!$D$1:$D1000,$A40,PrelimRaw!$C$1:$C1000,14) -> 23 | G40: =countifs(PrelimRaw!$D$1:$D1000,$A40,PrelimRaw!$C$1:$C1000,0) -> 6 | H40: =countifs(PrelimRaw!$D$1:$D1000,$A40,PrelimRaw!$C$1:$C1000,-4) -> 7 | I40: =F40+G40+H40 -> 36 | J40: =I40/E40 -> 0.3 | K40: =iferror(F40/I40,0) -> 0.63888889 | L40: =4*F40-4*H40 -> 64 | M40: =L40/D40 -> 12.8 | N40: =vlookup($A40,'X-Risk'!$A:$M,13,false) -> 4 | O40: =vlookup($A40,Math!$A:$M,13,false) -> 0.8 | P40: =vlookup($A40,Chemistry!$A:$M,13,false) -> 6.4 | Q40: =vlookup($A40,EarthSpace!$A:$M,13,false) -> 0.8 | R40: =vlookup($A40,Biology!$A:$M,13,false) -> -0.8 | S40: =vlookup($A40,Physics!$A:$M,13,false) -> 1.6
...

Sheet Full
A1: ID | B1: Name | C1: Team | D1: GP | E1: TUH | F1: TU | G1: X | H1: Neg | I1: # Buzz | J1: % Buzz | K1: Acc | L1: Points | M1: PPG | N1: X PPG | O1: M PPG | P1: C PPG | Q1: E PPG | R1: B PPG | S1: P PPG
A2: 101949633011269793228 | B2: =vlookup($A2,Users!$B$1:$H1000,3,false) -> Joshua | C2: =vlookup($A2,Users!$B$1:$H1000,6,false) -> Brookfield | D2: =vlookup($C2,Teams!$B:$D,2,false) -> 7 | E2: =D2*24 -> 168 | F2: =countifs(Raw!$D$1:$D1000,$A2,Raw!$C$1:$C1000,4)+countifs(Raw!$D$1:$D1000,$A2,Raw!$C$1:$C1000,14) -> 61 | G2: =countifs(Raw!$D$1:$D1000,$A2,Raw!$C$1:$C1000,0) -> 25 | H2: =countifs(Raw!$D$1:$D1000,$A2,Raw!$C$1:$C1000,-4) -> 2 | I2: =F2+G2+H2 -> 88 | J2: =I2/E2 -> 0.52380952 | K2: =iferror(F2/I2,0) -> 0.69318182 | L2: =4*F2-4*H2 -> 236 | M2: =L2/D2 -> 33.714286 | N2: =vlookup($A2,'X-Risk Full'!$A:$M,13,false) -> 6.8571429 | O2: =vlookup($A2,'Math Full'!$A:$M,13,false) -> 5.1428571 | P2: =vlookup($A2,'Chemistry Full'!$A:$M,13,false) -> 2.8571429 | Q2: =vlookup($A2,'EarthSpace Full'!$A:$M,13,false) -> 6.2857143 | R2: =vlookup($A2,'Biology Full'!$A:$M,13,false) -> 4.5714286 | S2: =vlookup($A2,'Physics Full'!$A:$M,13,false) -> 8
A3: 100741934745181838949 | B3: =vlookup($A3,Users!$B$1:$H1000,3,false) -> Vishnu | C3: =vlookup($A3,Users!$B$1:$H1000,6,false) -> Lakeside | D3: =vlookup($C3,Teams!$B:$D,2,false) -> 5 | E3: =D3*24 -> 120 | F3: =countifs(Raw!$D$1:$D1000,$A3,Raw!$C$1:$C1000,4)+countifs(Raw!$D$1:$D1000,$A3,Raw!$C$1:$C1000,14) -> 43 | G3: =countifs(Raw!$D$1:$D1000,$A3,Raw!$C$1:$C1000,0) -> 11 | H3: =countifs(Raw!$D$1:$D1000,$A3,Raw!$C$1:$C1000,-4) -> 2 | I3: =F3+G3+H3 -> 56 | J3: =I3/E3 -> 0.46666667 | K3: =iferror(F3/I3,0) -> 0.76785714 | L3: =4*F3-4*H3 -> 164 | M3: =L3/D3 -> 32.8 | N3: =vlookup($A3,'X-Risk Full'!$A:$M,13,false) -> 4 | O3: =vlookup($A3,'Math Full'!$A:$M,13,false) -> 6.4 | P3: =vlookup($A3,'Chemistry Full'!$A:$M,13,false) -> 5.6 | Q3: =vlookup($A3,'EarthSpace Full'!$A:$M,13,false) -> 8.8 | R3: =vlookup($A3,'Biology Full'!$A:$M,13,false) -> 4 | S3: =vlookup($A3,'Physics Full'!$A:$M,13,false) -> 4
A4: 104421903707714227310 | B4: =vlookup($A4,Users!$B$1:$H1000,3,false) -> Anurag | C4: =vlookup($A4,Users!$B$1:$H1000,6,false) -> Centennial | D4: =vlookup($C4,Teams!$B:$D,2,false) -> 11 | E4: =D4*24 -> 264 | F4: =countifs(Raw!$D$1:$D1000,$A4,Raw!$C$1:$C1000,4)+countifs(Raw!$D$1:$D1000,$A4,Raw!$C$1:$C1000,14) -> 101 | G4: =countifs(Raw!$D$1:$D1000,$A4,Raw!$C$1:$C1000,0) -> 70 | H4: =countifs(Raw!$D$1:$D1000,$A4,Raw!$C$1:$C1000,-4) -> 11 | I4: =F4+G4+H4 -> 182 | J4: =I4/E4 -> 0.68939394 | K4: =iferror(F4/I4,0) -> 0.55494505 | L4: =4*F4-4*H4 -> 360 | M4: =L4/D4 -> 32.727273 | N4: =vlookup($A4,'X-Risk Full'!$A:$M,13,false) -> 5.8181818 | O4: =vlookup($A4,'Math Full'!$A:$M,13,false) -> 7.2727273 | P4: =vlookup($A4,'Chemistry Full'!$A:$M,13,false) -> 10.181818 | Q4: =vlookup($A4,'EarthSpace Full'!$A:$M,13,false) -> 2.5454545 | R4: =vlookup($A4,'Biology Full'!$A:$M,13,false) -> 2.1818182 | S4: =vlookup($A4,'Physics Full'!$A:$M,13,false) -> 4.7272727
A5: 106777291229721234908 | B5: =vlookup($A5,Users!$B$1:$H1000,3,false) -> Yufei | C5: =vlookup($A5,Users!$B$1:$H1000,6,false) -> University | D5: =vlookup($C5,Teams!$B:$D,2,false) -> 8 | E5: =D5*24 -> 192 | F5: =countifs(Raw!$D$1:$D1000,$A5,Raw!$C$1:$C1000,4)+countifs(Raw!$D$1:$D1000,$A5,Raw!$C$1:$C1000,14) -> 62 | G5: =countifs(Raw!$D$1:$D1000,$A5,Raw!$C$1:$C1000,0) -> 20 | H5: =countifs(Raw!$D$1:$D1000,$A5,Raw!$C$1:$C1000,-4) -> 8 | I5: =F5+G5+H5 -> 90 | J5: =I5/E5 -> 0.46875 | K5: =iferror(F5/I5,0) -> 0.68888889 | L5: =4*F5-4*H5 -> 216 | M5: =L5/D5 -> 27 | N5: =vlookup($A5,'X-Risk Full'!$A:$M,13,false) -> 5 | O5: =vlookup($A5,'Math Full'!$A:$M,13,false) -> 3.5 | P5: =vlookup($A5,'Chemistry Full'!$A:$M,13,false) -> 5 | Q5: =vlookup($A5,'EarthSpace Full'!$A:$M,13,false) -> 3.5 | R5: =vlookup($A5,'Biology Full'!$A:$M,13,false) -> 7 | S5: =vlookup($A5,'Physics Full'!$A:$M,13,false) -> 3
A6: 105378163543476641273 | B6: =vlookup($A6,Users!$B$1:$H1000,3,false) -> Elias | C6: =vlookup($A6,Users!$B$1:$H1000,6,false) -> ASFA | D6: =vlookup($C6,Teams!$B:$D,2,false) -> 5 | E6: =D6*24 -> 120 | F6: =countifs(Raw!$D$1:$D1000,$A6,Raw!$C$1:$C1000,4)+countifs(Raw!$D$1:$D1000,$A6,Raw!$C$1:$C1000,14) -> 34 | G6: =countifs(Raw!$D$1:$D1000,$A6,Raw!$C$1:$C1000,0) -> 24 | H6: =countifs(Raw!$D$1:$D1000,$A6,Raw!$C$1:$C1000,-4) -> 3 | I6: =F6+G6+H6 -> 61 | J6: =I6/E6 -> 0.50833333 | K6: =iferror(F6/I6,0) -> 0.55737705 | L6: =4*F6-4*H6 -> 124 | M6: =L6/D6 -> 24.8 | N6: =vlookup($A6,'X-Risk Full'!$A:$M,13,false) -> 3.2 | O6: =vlookup($A6,'Math Full'!$A:$M,13,false) -> 7.2 | P6: =vlookup($A6,'Chemistry Full'!$A:$M,13,false) -> 8 | Q6: =vlookup($A6,'EarthSpace Full'!$A:$M,13,false) -> 5.6 | R6: =vlookup($A6,'Biology Full'!$A:$M,13,false) -> 0 | S6: =vlookup($A6,'Physics Full'!$A:$M,13,false) -> 0.8
A7: 100552342580135245961 | B7: =vlookup($A7,Users!$B$1:$H1000,3,false) -> Connor | C7: =vlookup($A7,Users!$B$1:$H1000,6,false) -> NoHo B | D7: =vlookup($C7,Teams!$B:$D,2,false) -> 5 | E7: =D7*24 -> 120 | F7: =countifs(Raw!$D$1:$D1000,$A7,Raw!$C$1:$C1000,4)+countifs(Raw!$D$1:$D1000,$A7,Raw!$C$1:$C1000,14) -> 35 | G7: =countifs(Raw!$D$1:$D1000,$A7,Raw!$C$1:$C1000,0) -> 19 | H7: =countifs(Raw!$D$1:$D1000,$A7,Raw!$C$1:$C1000,-4) -> 4 | I7: =F7+G7+H7 -> 58 | J7: =I7/E7 -> 0.48333333 | K7: =iferror(F7/I7,0) -> 0.60344828 | L7: =4*F7-4*H7 -> 124 | M7: =L7/D7 -> 24.8 | N7: =vlookup($A7,'X-Risk Full'!$A:$M,13,false) -> 4 | O7: =vlookup($A7,'Math Full'!$A:$M,13,false) -> 3.2 | P7: =vlookup($A7,'Chemistry Full'!$A:$M,13,false) -> 8.8 | Q7: =vlookup($A7,'EarthSpace Full'!$A:$M,13,false) -> 2.4 | R7: =vlookup($A7,'Biology Full'!$A:$M,13,false) -> 1.6 | S7: =vlookup($A7,'Physics Full'!$A:$M,13,false) -> 4.8
A8: 103951081173066298964 | B8: =vlookup($A8,Users!$B$1:$H1000,3,false) -> Harry | C8: =vlookup($A8,Users!$B$1:$H1000,6,false) -> Middleton | D8: =vlookup($C8,Teams!$B:$D,2,false) -> 5 | E8: =D8*24 -> 120 | F8: =countifs(Raw!$D$1:$D1000,$A8,Raw!$C$1:$C1000,4)+countifs(Raw!$D$1:$D1000,$A8,Raw!$C$1:$C1000,14) -> 30 | G8: =countifs(Raw!$D$1:$D1000,$A8,Raw!$C$1:$C1000,0) -> 7 | H8: =countifs(Raw!$D$1:$D1000,$A8,Raw!$C$1:$C1000,-4) -> 0 | I8: =F8+G8+H8 -> 37 | J8: =I8/E8 -> 0.30833333 | K8: =iferror(F8/I8,0) -> 0.81081081 | L8: =4*F8-4*H8 -> 120 | M8: =L8/D8 -> 24 | N8: =vlookup($A8,'X-Risk Full'!$A:$M,13,false) -> 5.6 | O8: =vlookup($A8,'Math Full'!$A:$M,13,false) -> 4.8 | P8: =vlookup($A8,'Chemistry Full'!$A:$M,13,false) -> 8.8 | Q8: =vlookup($A8,'EarthSpace Full'!$A:$M,13,false) -> 3.2 | R8: =vlookup($A8,'Biology Full'!$A:$M,13,false) -> 0.8 | S8: =vlookup($A8,'Physics Full'!$A:$M,13,false) -> 0.8
A9: 105885321269112639389 | B9: =vlookup($A9,Users!$B$1:$H1000,3,false) -> Edward | C9: =vlookup($A9,Users!$B$1:$H1000,6,false) -> Shen | D9: =vlookup($C9,Teams!$B:$D,2,false) -> 5 | E9: =D9*24 -> 120 | F9: =countifs(Raw!$D$1:$D1000,$A9,Raw!$C$1:$C1000,4)+countifs(Raw!$D$1:$D1000,$A9,Raw!$C$1:$C1000,14) -> 30 | G9: =countifs(Raw!$D$1:$D1000,$A9,Raw!$C$1:$C1000,0) -> 12 | H9: =countifs(Raw!$D$1:$D1000,$A9,Raw!$C$1:$C1000,-4) -> 1 | I9: =F9+G9+H9 -> 43 | J9: =I9/E9 -> 0.35833333 | K9: =iferror(F9/I9,0) -> 0.69767442 | L9: =4*F9-4*H9 -> 116 | M9: =L9/D9 -> 23.2 | N9: =vlookup($A9,'X-Risk Full'!$A:$M,13,false) -> 2.4 | O9: =vlookup($A9,'Math Full'!$A:$M,13,false) -> 0.8 | P9: =vlookup($A9,'Chemistry Full'!$A:$M,13,false) -> 4 | Q9: =vlookup($A9,'EarthSpace Full'!$A:$M,13,false) -> 5.6 | R9: =vlookup($A9,'Biology Full'!$A:$M,13,false) -> 7.2 | S9: =vlookup($A9,'Physics Full'!$A:$M,13,false) -> 3.2
A10: 108223652435775478403 | B10: =vlookup($A10,Users!$B$1:$H1000,3,false) -> Caleb | C10: =vlookup($A10,Users!$B$1:$H1000,6,false) -> Blair A | D10: =vlookup($C10,Teams!$B:$D,2,false) -> 9 | E10: =D10*24 -> 216 | F10: =countifs(Raw!$D$1:$D1000,$A10,Raw!$C$1:$C1000,4)+countifs(Raw!$D$1:$D1000,$A10,Raw!$C$1:$C1000,14) -> 65 | G10: =countifs(Raw!$D$1:$D1000,$A10,Raw!$C$1:$C1000,0) -> 22 | H10: =countifs(Raw!$D$1:$D1000,$A10,Raw!$C$1:$C1000,-4) -> 13 | I10: =F10+G10+H10 -> 100 | J10: =I10/E10 -> 0.46296296 | K10: =iferror(F10/I10,0) -> 0.65 | L10: =4*F10-4*H10 -> 208 | M10: =L10/D10 -> 23.111111 | N10: =vlookup($A10,'X-Risk Full'!$A:$M,13,false) -> 5.3333333 | O10: =vlookup($A10,'Math Full'!$A:$M,13,false) -> 0.44444444 | P10: =vlookup($A10,'Chemistry Full'!$A:$M,13,false) -> 8 | Q10: =vlookup($A10,'EarthSpace Full'!$A:$M,13,false) -> 1.7777778 | R10: =vlookup($A10,'Biology Full'!$A:$M,13,false) -> 6.6666667 | S10: =vlookup($A10,'Physics Full'!$A:$M,13,false) -> 0.88888889
A11: 100452237492909123862 | B11: =vlookup($A11,Users!$B$1:$H1000,3,false) -> Kaiwen | C11: =vlookup($A11,Users!$B$1:$H1000,6,false) -> Enloe B | D11: =vlookup($C11,Teams!$B:$D,2,false) -> 7 | E11: =D11*24 -> 168 | F11: =countifs(Raw!$D$1:$D1000,$A11,Raw!$C$1:$C1000,4)+countifs(Raw!$D$1:$D1000,$A11,Raw!$C$1:$C1000,14) -> 43 | G11: =countifs(Raw!$D$1:$D1000,$A11,Raw!$C$1:$C1000,0) -> 14 | H11: =countifs(Raw!$D$1:$D1000,$A11,Raw!$C$1:$C1000,-4) -> 6 | I11: =F11+G11+H11 -> 63 | J11: =I11/E11 -> 0.375 | K11: =iferror(F11/I11,0) -> 0.68253968 | L11: =4*F11-4*H11 -> 148 | M11: =L11/D11 -> 21.142857 | N11: =vlookup($A11,'X-Risk Full'!$A:$M,13,false) -> 5.7142857 | O11: =vlookup($A11,'Math Full'!$A:$M,13,false) -> 1.1428571 | P11: =vlookup($A11,'Chemistry Full'!$A:$M,13,false) -> 5.7142857 | Q11: =vlookup($A11,'EarthSpace Full'!$A:$M,13,false) -> 2.2857143 | R11: =vlookup($A11,'Biology Full'!$A:$M,13,false) -> 0 | S11: =vlookup($A11,'Physics Full'!$A:$M,13,false) -> 6.2857143
A12: 106172791161887099127 | B12: =vlookup($A12,Users!$B$1:$H1000,3,false) -> Ryan | C12: =vlookup($A12,Users!$B$1:$H1000,6,false) -> Iolani | D12: =vlookup($C12,Teams!$B:$D,2,false) -> 5 | E12: =D12*24 -> 120 | F12: =countifs(Raw!$D$1:$D1000,$A12,Raw!$C$1:$C1000,4)+countifs(Raw!$D$1:$D1000,$A12,Raw!$C$1:$C1000,14) -> 26 | G12: =countifs(Raw!$D$1:$D1000,$A12,Raw!$C$1:$C1000,0) -> 19 | H12: =countifs(Raw!$D$1:$D1000,$A12,Raw!$C$1:$C1000,-4) -> 0 | I12: =F12+G12+H12 -> 45 | J12: =I12/E12 -> 0.375 | K12: =iferror(F12/I12,0) -> 0.57777778 | L12: =4*F12-4*H12 -> 104 | M12: =L12/D12 -> 20.8 | N12: =vlookup($A12,'X-Risk Full'!$A:$M,13,false) -> 3.2 | O12: =vlookup($A12,'Math Full'!$A:$M,13,false) -> 1.6 | P12: =vlookup($A12,'Chemistry Full'!$A:$M,13,false) -> 4.8 | Q12: =vlookup($A12,'EarthSpace Full'!$A:$M,13,false) -> 5.6 | R12: =vlookup($A12,'Biology Full'!$A:$M,13,false) -> 2.4 | S12: =vlookup($A12,'Physics Full'!$A:$M,13,false) -> 3.2
A13: 114720212150770111881 | B13: =vlookup($A13,Users!$B$1:$H1000,3,false) -> Viraj | C13: =vlookup($A13,Users!$B$1:$H1000,6,false) -> Dulles | D13: =vlookup($C13,Teams!$B:$D,2,false) -> 9 | E13: =D13*24 -> 216 | F13: =countifs(Raw!$D$1:$D1000,$A13,Raw!$C$1:$C1000,4)+countifs(Raw!$D$1:$D1000,$A13,Raw!$C$1:$C1000,14) -> 50 | G13: =countifs(Raw!$D$1:$D1000,$A13,Raw!$C$1:$C1000,0) -> 9 | H13: =countifs(Raw!$D$1:$D1000,$A13,Raw!$C$1:$C1000,-4) -> 5 | I13: =F13+G13+H13 -> 64 | J13: =I13/E13 -> 0.2962963 | K13: =iferror(F13/I13,0) -> 0.78125 | L13: =4*F13-4*H13 -> 180 | M13: =L13/D13 -> 20 | N13: =vlookup($A13,'X-Risk Full'!$A:$M,13,false) -> 2.2222222 | O13: =vlookup($A13,'Math Full'!$A:$M,13,false) -> 2.2222222 | P13: =vlookup($A13,'Chemistry Full'!$A:$M,13,false) -> 7.5555556 | Q13: =vlookup($A13,'EarthSpace Full'!$A:$M,13,false) -> 2.2222222 | R13: =vlookup($A13,'Biology Full'!$A:$M,13,false) -> 1.3333333 | S13: =vlookup($A13,'Physics Full'!$A:$M,13,false) -> 4.4444444
A14: 104714961629414741842 | B14: =vlookup($A14,Users!$B$1:$H1000,3,false) -> Evin | C14: =vlookup($A14,Users!$B$1:$H1000,6,false) -> Lexington A | D14: =vlookup($C14,Teams!$B:$D,2,false) -> 7 | E14: =D14*24 -> 168 | F14: =countifs(Raw!$D$1:$D1000,$A14,Raw!$C$1:$C1000,4)+countifs(Raw!$D$1:$D1000,$A14,Raw!$C$1:$C1000,14) -> 38 | G14: =countifs(Raw!$D$1:$D1000,$A14,Raw!$C$1:$C1000,0) -> 12 | H14: =countifs(Raw!$D$1:$D1000,$A14,Raw!$C$1:$C1000,-4) -> 3 | I14: =F14+G14+H14 -> 53 | J14: =I14/E14 -> 0.31547619 | K14: =iferror(F14/I14,0) -> 0.71698113 | L14: =4*F14-4*H14 -> 140 | M14: =L14/D14 -> 20 | N14: =vlookup($A14,'X-Risk Full'!$A:$M,13,false) -> 4.5714286 | O14: =vlookup($A14,'Math Full'!$A:$M,13,false) -> 6.2857143 | P14: =vlookup($A14,'Chemistry Full'!$A:$M,13,false) -> -0.57142857 | Q14: =vlookup($A14,'EarthSpace Full'!$A:$M,13,false) -> 1.1428571 | R14: =vlookup($A14,'Biology Full'!$A:$M,13,false) -> 1.1428571 | S14: =vlookup($A14,'Physics Full'!$A:$M,13,false) -> 7.4285714
A15: 100460385825974417248 | B15: =vlookup($A15,Users!$B$1:$H1000,3,false) -> Mason | C15: =vlookup($A15,Users!$B$1:$H1000,6,false) -> Westminster | D15: =vlookup($C15,Teams!$B:$D,2,false) -> 5 | E15: =D15*24 -> 120 | F15: =countifs(Raw!$D$1:$D1000,$A15,Raw!$C$1:$C1000,4)+countifs(Raw!$D$1:$D1000,$A15,Raw!$C$1:$C1000,14) -> 32 | G15: =countifs(Raw!$D$1:$D1000,$A15,Raw!$C$1:$C1000,0) -> 12 | H15: =countifs(Raw!$D$1:$D1000,$A15,Raw!$C$1:$C1000,-4) -> 7 | I15: =F15+G15+H15 -> 51 | J15: =I15/E15 -> 0.425 | K15: =iferror(F15/I15,0) -> 0.62745098 | L15: =4*F15-4*H15 -> 100 | M15: =L15/D15 -> 20 | N15: =vlookup($A15,'X-Risk Full'!$A:$M,13,false) -> 6.4 | O15: =vlookup($A15,'Math Full'!$A:$M,13,false) -> 0 | P15: =vlookup($A15,'Chemistry Full'!$A:$M,13,false) -> 1.6 | Q15: =vlookup($A15,'EarthSpace Full'!$A:$M,13,false) -> 3.2 | R15: =vlookup($A15,'Biology Full'!$A:$M,13,false) -> 5.6 | S15: =vlookup($A15,'Physics Full'!$A:$M,13,false) -> 3.2
