Workbook

Sheet Single Elimination
A1: ='Hidden Sheet'!B15 -> Interlakeside | B1: 68
A2: Cayuga 1 | C2: =IFS(B1>B3,A1,B3>B1,A3,B3=B1,) -> Interlakeside | D2: 70
A3: ='Hidden Sheet'!H59 -> Poolesville B | B3: 30
C4: Cayuga 1 | E4: =IFS(D2>D6,C2,D2<D6,C6,D2=D6,) -> Interlakeside | F4: 100
A5: ='Hidden Sheet'!D49 -> Enloe HS | B5: 18
A6: Cayuga 2 | C6: =IFS(B5>B7,A5,B7>B5,A7,B7=B5,) -> Buchholz A | D6: 30
A7: ='Hidden Sheet'!P32 -> Buchholz A | B7: 116
E8: Cayuga 1 | G8: =IFS(F4>F12,E4,F4<F12,E12,F4=F12,) -> Interlakeside | H8: 12
A9: ='Hidden Sheet'!N32 -> Poolesville HS | B9: 82
A10: Mohawk 1 | C10: =IFS(B9>B11,A9,B11>B9,A11,B11=B9,) -> Poolesville HS | D10: 88
A11: ='Hidden Sheet'!B59 -> Foothill A | B11: 28
C12: Cayuga 2 | E12: =IFS(D10>D14,C10,D10<D14,C14,D10=D14,) -> Poolesville HS | F12: 8
A13: ='Hidden Sheet'!B49 -> Iolani | B13: 32
A14: Mohawk 2 | C14: =IFS(B13>B15,A13,B15>B13,A15,B15=B13,) -> Mission San Jose | D14: 58
A15: ='Hidden Sheet'!D15 -> Mission San Jose | B15: 124
G16: Cayuga 1 | I16: =IFS(H8>H24,G8,H8<H24,G24,H8=H24,) -> Clements HS
A17: ='Hidden Sheet'!N15 -> Montgomery Blair HS | B17: 92
A18: Oneida 1 | C18: =IFS(B17>B19,A17,B19>B17,A19,B19=B17,) -> Montgomery Blair HS | D18: 44
A19: ='Hidden Sheet'!F59 -> Foothill B | B19: 12
C20: Mohawk 1 | E20: =IFS(D18>D22,C18,D18<D22,C22,D18=D22,) -> Montgomery Blair HS | F20: 38
A21: ='Hidden Sheet'!P49 -> North Hollywood | B21: 96
A22: Oneida 2 | C22: =IFS(B21>B23,A21,B23>B21,A23,B23=B21,) -> North Hollywood | D22: 30
A23: ='Hidden Sheet'!D32 -> University HS | B23: 74
E24: Cayuga 2 | G24: =IFS(F20>F28,E20,F20<F28,E28,F20=F28,) -> Clements HS | H24: 42
A25: ='Hidden Sheet'!B32 -> Davidson Academy | B25: 100
A26: Onondaga 1 | C26: =IFS(B25>B27,A25,B27>B25,A27,B27=B25,) -> Davidson Academy | D26: 14
A27: ='Hidden Sheet'!D59 -> Amador Valley A | B27: 60
C28: Mohawk 2 | E28: =IFS(D26>D30,C26,D26<D30,C30,D26=D30,) -> Clements HS | F28: 48
A29: ='Hidden Sheet'!N49 -> Clements HS | B29: 56
A30: Onondaga 2 | C30: =IFS(B29>B31,A29,B31>B29,A31,B31=B29,) -> Clements HS | D30: 76
A31: ='Hidden Sheet'!P15 -> Buchholz B | B31: 36

Sheet Round Robin
B1: Example Group
C4: =B7 -> Team 1 | D4: =B8 -> Team 2 | E4: =B9 -> Team 3 | F4: =B10 -> Team 4 | G4: PPG | H4: Points
J6: Order of Matchups:
B7: Team 1 | G7: =IFERROR(ROUND(AVERAGE(C7:F7),2),) | H7: ='Hidden Sheet'!Y5 | J7: Room 1 | K7: Room 2
B8: Team 2 | G8: =IFERROR(ROUND(AVERAGE(C8:F8),2),) | H8: ='Hidden Sheet'!Z5 | I8: RR1 | J8: Team 1 vs Team 2 | K8: Team 3 vs Team 4
B9: Team 3 | G9: =IFERROR(ROUND(AVERAGE(C9:F9),2),) | H9: ='Hidden Sheet'!AA5 | I9: RR2 | J9: Team 1 vs Team 3 | K9: Team 2 vs Team 4
B10: Team 4 | G10: =IFERROR(ROUND(AVERAGE(C10:F10),2),) | H10: ='Hidden Sheet'!AB5 | I10: RR3 | J10: Team 1 vs Team 4 | K10: Team 2 vs Team 3
B12: Cayuga | J12: Seneca
C15: =B18 -> Interlakeside | D15: =B19 -> Mission San Jose | E15: =B20 -> Sharon HS | F15: =B21 -> Science Academy B | G15: PPG | H15: Points | K15: =J18 -> Amador Valley B | L15: =J19 -> Buchholz B | M15: =J20 -> Montgomery Blair HS | N15: =J21 -> Science Academy A | O15: PPG | P15: Points
B18: Interlakeside | D18: 124 | E18: 124 | F18: 120 | G18: =IFERROR(ROUND(AVERAGE(C18:F18),2),) -> 122.67 | H18: ='Hidden Sheet'!D5 -> 6 | I18: =CONCATENATE(CONCAT("W: ",COUNTIF('Hidden Sheet'!D2:D4, 2)), (CONCAT(" T: ", COUNTIF('Hidden Sheet'!D2:D4, 1))), CONCAT(" L: ",COUNTIF('Hidden Sheet'!D2:D4, 0))) -> W: 3 T: 0 L: 0 | J18: Amador Valley B | L18: 24 | M18: 54 | N18: 42 | O18: =IFERROR(ROUND(AVERAGE(K18:N18),2),) -> 40 | P18: ='Hidden Sheet'!P5 -> 0 | Q18: =CONCATENATE(CONCAT("W: ",COUNTIF('Hidden Sheet'!P2:P4, 2)), (CONCAT(" T: ", COUNTIF('Hidden Sheet'!P2:P4, 1))), CONCAT(" L: ",COUNTIF('Hidden Sheet'!P2:P4, 0))) -> W: 0 T: 0 L: 3
B19: Mission San Jose | C19: 82 | E19: 62 | F19: 120 | G19: =IFERROR(ROUND(AVERAGE(C19:F19),2),) -> 88 | H19: ='Hidden Sheet'!E5 -> 4 | I19: =CONCATENATE(CONCAT("W: ",COUNTIF('Hidden Sheet'!E2:E4, 2)), (CONCAT(" T: ", COUNTIF('Hidden Sheet'!E2:E4, 1))), CONCAT(" L: ",COUNTIF('Hidden Sheet'!E2:E4, 0))) -> W: 2 T: 0 L: 1 | J19: Buchholz B | K19: 60 | M19: 18 | N19: 60 | O19: =IFERROR(ROUND(AVERAGE(K19:N19),2),) -> 46 | P19: ='Hidden Sheet'!Q5 -> 4 | Q19: =CONCATENATE(CONCAT("W: ",COUNTIF('Hidden Sheet'!Q2:Q4, 2)), (CONCAT(" T: ", COUNTIF('Hidden Sheet'!Q2:Q4, 1))), CONCAT(" L: ",COUNTIF('Hidden Sheet'!Q2:Q4, 0))) -> W: 2 T: 0 L: 1
B20: Sharon HS | C20: 14 | D20: 18 | F20: 2 | G20: =IFERROR(ROUND(AVERAGE(C20:F20),2),) -> 11.33 | H20: ='Hidden Sheet'!F5 -> 0 | I20: =CONCATENATE(CONCAT("W: ",COUNTIF('Hidden Sheet'!F2:F4, 2)), (CONCAT(" T: ", COUNTIF('Hidden Sheet'!F2:F4, 1))), CONCAT(" L: ",COUNTIF('Hidden Sheet'!F2:F4, 0))) -> W: 0 T: 0 L: 3 | J20: Montgomery Blair HS | K20: 114 | L20: 84 | N20: 144 | O20: =IFERROR(ROUND(AVERAGE(K20:N20),2),) -> 114 | P20: ='Hidden Sheet'!R5 -> 6 | Q20: =CONCATENATE(CONCAT("W: ",COUNTIF('Hidden Sheet'!R2:R4, 2)), (CONCAT(" T: ", COUNTIF('Hidden Sheet'!R2:R4, 1))), CONCAT(" L: ",COUNTIF('Hidden Sheet'!R2:R4, 0))) -> W: 3 T: 0 L: 0
B21: Science Academy B | C21: 22 | D21: 24 | E21: 20 | G21: =IFERROR(ROUND(AVERAGE(C21:F21),2),) -> 22 | H21: ='Hidden Sheet'!G5 -> 2 | I21: =CONCATENATE(CONCAT("W: ",COUNTIF('Hidden Sheet'!G2:G4, 2)), (CONCAT(" T: ", COUNTIF('Hidden Sheet'!G2:G4, 1))), CONCAT(" L: ",COUNTIF('Hidden Sheet'!G2:G4, 0))) -> W: 1 T: 0 L: 2 | J21: Science Academy A | K21: 54 | L21: 56 | M21: -12 | O21: =IFERROR(ROUND(AVERAGE(K21:N21),2),) -> 32.67 | P21: ='Hidden Sheet'!S5 -> 2 | Q21: =CONCATENATE(CONCAT("W: ",COUNTIF('Hidden Sheet'!S2:S4, 2)), (CONCAT(" T: ", COUNTIF('Hidden Sheet'!S2:S4, 1))), CONCAT(" L: ",COUNTIF('Hidden Sheet'!S2:S4, 0))) -> W: 1 T: 0 L: 2
B23: Onondaga | J23: Oneida
C26: =B29 -> University HS | D26: =B30 -> Davidson Academy | E26: =B31 -> James S. Rickards HS | F26: =B32 -> Amador Valley A | G26: PPG | H26: Points | K26: =J29 -> Buchholz A | L26: =J30 -> Foothill A | M26: =J31 -> Poolesville HS | N26: =J32 -> Venice HS | O26: PPG | P26: Points
B29: University HS | D29: 106 | E29: 130 | F29: 100 | G29: =IFERROR(ROUND(AVERAGE(C29:F29),2),) -> 112 | H29: ='Hidden Sheet'!D22 -> 4 | I29: =CONCATENATE(CONCAT("W: ",COUNTIF('Hidden Sheet'!D$19:D$21, 2)), (CONCAT(" T: ", COUNTIF('Hidden Sheet'!D$19:D$21, 1))), CONCAT(" L: ",COUNTIF('Hidden Sheet'!D$19:D$21, 0))) -> W: 2 T: 0 L: 1 | J29: Buchholz A | L29: 94 | M29: 12 | N29: 76 | O29: =IFERROR(ROUND(AVERAGE(K29:N29),2),) -> 60.67 | P29: ='Hidden Sheet'!P22 -> 4 | Q29: =CONCATENATE(CONCAT("W: ",COUNTIF('Hidden Sheet'!P19:P21, 2)), (CONCAT(" T: ", COUNTIF('Hidden Sheet'!P19:P21, 1))), CONCAT(" L: ",COUNTIF('Hidden Sheet'!P19:P21, 0))) -> W: 2 T: 0 L: 1
B30: Davidson Academy | C30: 114 | E30: 80 | F30: 104 | G30: =IFERROR(ROUND(AVERAGE(C30:F30),2),) -> 99.33 | H30: ='Hidden Sheet'!E22 -> 6 | I30: =CONCATENATE(CONCAT("W: ",COUNTIF('Hidden Sheet'!E$19:E$21, 2)), (CONCAT(" T: ", COUNTIF('Hidden Sheet'!E$19:E$21, 1))), CONCAT(" L: ",COUNTIF('Hidden Sheet'!E$19:E$21, 0))) -> W: 3 T: 0 L: 0 | J30: Foothill A | K30: 74 | M30: 44 | N30: 96 | O30: =IFERROR(ROUND(AVERAGE(K30:N30),2),) -> 71.33 | P30: ='Hidden Sheet'!Q22 -> 2 | Q30: =CONCATENATE(CONCAT("W: ",COUNTIF('Hidden Sheet'!Q19:Q21, 2)), (CONCAT(" T: ", COUNTIF('Hidden Sheet'!Q19:Q21, 1))), CONCAT(" L: ",COUNTIF('Hidden Sheet'!Q19:Q21, 0))) -> W: 1 T: 0 L: 2
B31: James S. Rickards HS | C31: 12 | D31: 28 | F31: 44 | G31: =IFERROR(ROUND(AVERAGE(C31:F31),2),) -> 28 | H31: ='Hidden Sheet'!F22 -> 0 | I31: =CONCATENATE(CONCAT("W: ",COUNTIF('Hidden Sheet'!F$19:F$21, 2)), (CONCAT(" T: ", COUNTIF('Hidden Sheet'!F$19:F$21, 1))), CONCAT(" L: ",COUNTIF('Hidden Sheet'!F$19:F$21, 0))) -> W: 0 T: 0 L: 3 | J31: Poolesville HS | K31: 200 | L31: 88 | N31: 92 | O31: =IFERROR(ROUND(AVERAGE(K31:N31),2),) -> 126.67 | P31: ='Hidden Sheet'!R22 -> 6 | Q31: =CONCATENATE(CONCAT("W: ",COUNTIF('Hidden Sheet'!R19:R21, 2)), (CONCAT(" T: ", COUNTIF('Hidden Sheet'!R19:R21, 1))), CONCAT(" L: ",COUNTIF('Hidden Sheet'!R19:R21, 0))) -> W: 3 T: 0 L: 0
B32: Amador Valley A | C32: 64 | D32: 62 | E32: 86 | G32: =IFERROR(ROUND(AVERAGE(C32:F32),2),) -> 70.67 | H32: ='Hidden Sheet'!G22 -> 2 | I32: =CONCATENATE(CONCAT("W: ",COUNTIF('Hidden Sheet'!G$19:G$21, 2)), (CONCAT(" T: ", COUNTIF('Hidden Sheet'!G$19:G$21, 1))), CONCAT(" L: ",COUNTIF('Hidden Sheet'!G$19:G$21, 0))) -> W: 1 T: 0 L: 2 | J32: Venice HS | K32: 20 | L32: 44 | M32: 34 | O32: =IFERROR(ROUND(AVERAGE(K32:N32),2),) -> 32.67 | P32: ='Hidden Sheet'!S22 -> 0 | Q32: =CONCATENATE(CONCAT("W: ",COUNTIF('Hidden Sheet'!S19:S21, 2)), (CONCAT(" T: ", COUNTIF('Hidden Sheet'!S19:S21, 1))), CONCAT(" L: ",COUNTIF('Hidden Sheet'!S19:S21, 0))) -> W: 0 T: 0 L: 3
B34: Mohawk | J34: Tuscarora
C37: =B40 -> CBA | D37: =B41 -> Enloe HS | E37: =B42 -> Iolani | F37: =B43 -> Poolesville B | G37: PPG | H37: Points | K37: =J40 -> North Hollywood | L37: =J41 -> Clements HS | M37: =J42 -> Foothill B | N37: =J43 -> Arcadia HS | O37: PPG | P37: Points
B40: CBA | D40: 22 | E40: 30 | F40: 16 | G40: =IFERROR(ROUND(AVERAGE(C40:F40),2),) -> 22.67 | H40: ='Hidden Sheet'!D39 -> 0 | I40: =CONCATENATE(CONCAT("W: ",COUNTIF('Hidden Sheet'!D36:D38, 2)), (CONCAT(" T: ", COUNTIF('Hidden Sheet'!D36:D38, 1))), CONCAT(" L: ",COUNTIF('Hidden Sheet'!D36:D38, 0))) -> W: 0 T: 0 L: 3 | J40: North Hollywood | L40: 90 | M40: 26 | N40: 62 | O40: =IFERROR(ROUND(AVERAGE(K40:N40),2),) -> 59.33 | P40: ='Hidden Sheet'!P39 -> 4 | Q40: =CONCATENATE(CONCAT("W: ",COUNTIF('Hidden Sheet'!P36:P38, 2)), (CONCAT(" T: ", COUNTIF('Hidden Sheet'!P36:P38, 1))), CONCAT(" L: ",COUNTIF('Hidden Sheet'!P36:P38, 0))) -> W: 2 T: 0 L: 1
B41: Enloe HS | C41: 52 | E41: 40 | F41: 28 | G41: =IFERROR(ROUND(AVERAGE(C41:F41),2),) -> 40 | H41: ='Hidden Sheet'!E39 -> 3 | I41: =CONCATENATE(CONCAT("W: ",COUNTIF('Hidden Sheet'!E36:E38, 2)), (CONCAT(" T: ", COUNTIF('Hidden Sheet'!E36:E38, 1))), CONCAT(" L: ",COUNTIF('Hidden Sheet'!E36:E38, 0))) -> W: 1 T: 1 L: 1 | J41: Clements HS | K41: 70 | M41: 134 | N41: 140 | O41: =IFERROR(ROUND(AVERAGE(K41:N41),2),) -> 114.67 | P41: ='Hidden Sheet'!Q39 -> 4 | Q41: =CONCATENATE(CONCAT("W: ",COUNTIF('Hidden Sheet'!Q36:Q38, 2)), (CONCAT(" T: ", COUNTIF('Hidden Sheet'!Q36:Q38, 1))), CONCAT(" L: ",COUNTIF('Hidden Sheet'!Q36:Q38, 0))) -> W: 2 T: 0 L: 1
B42: Iolani | C42: 94 | D42: 44 | F42: 76 | G42: =IFERROR(ROUND(AVERAGE(C42:F42),2),) -> 71.33 | H42: ='Hidden Sheet'!F39 -> 6 | I42: =CONCATENATE(CONCAT("W: ",COUNTIF('Hidden Sheet'!F36:F38, 2)), (CONCAT(" T: ", COUNTIF('Hidden Sheet'!F36:F38, 1))), CONCAT(" L: ",COUNTIF('Hidden Sheet'!F36:F38, 0))) -> W: 3 T: 0 L: 0 | J42: Foothill B | K42: 30 | L42: 16 | N42: 72 | O42: =IFERROR(ROUND(AVERAGE(K42:N42),2),) -> 39.33 | P42: ='Hidden Sheet'!R39 -> 4 | Q42: =CONCATENATE(CONCAT("W: ",COUNTIF('Hidden Sheet'!R36:R38, 2)), (CONCAT(" T: ", COUNTIF('Hidden Sheet'!R36:R38, 1))), CONCAT(" L: ",COUNTIF('Hidden Sheet'!R36:R38, 0))) -> W: 2 T: 0 L: 1
B43: Poolesville B | C43: 62 | D43: 28 | E43: 12 | G43: =IFERROR(ROUND(AVERAGE(C43:F43),2),) -> 34 | H43: ='Hidden Sheet'!G39 -> 3 | I43: =CONCATENATE(CONCAT("W: ",COUNTIF('Hidden Sheet'!G36:G38, 2)), (CONCAT(" T: ", COUNTIF('Hidden Sheet'!G36:G38, 1))), CONCAT(" L: ",COUNTIF('Hidden Sheet'!G36:G38, 0))) -> W: 1 T: 1 L: 1 | J43: Arcadia HS | K43: 30 | L43: 26 | M43: 26 | O43: =IFERROR(ROUND(AVERAGE(K43:N43),2),) -> 27.33 | P43: ='Hidden Sheet'!S39 -> 0 | Q43: =CONCATENATE(CONCAT("W: ",COUNTIF('Hidden Sheet'!S36:S38, 2)), (CONCAT(" T: ", COUNTIF('Hidden Sheet'!S36:S38, 1))), CONCAT(" L: ",COUNTIF('Hidden Sheet'!S36:S38, 0))) -> W: 0 T: 0 L: 3

Sheet Schedule
C1: HST | D1: PDT | E1: MDT | F1: CDT | G1: EDT
A2: Opening Ceremony | C2: 0.19444444 | D2: 0.31944444 | E2: 0.36111111 | F2: 0.40277778 | G2: 0.44444444
A3: Round Robin 1 | C3: 0.20833333 | D3: 0.33333333 | E3: 0.375 | F3: 0.41666667 | G3: 0.45833333
A4: Round Robin 2 | C4: 0.25 | D4: 0.375 | E4: 0.41666667 | F4: 0.45833333 | G4: 0.5
A5: Round Robin 3 | C5: 0.29166667 | D5: 0.41666667 | E5: 0.45833333 | F5: 0.5 | G5: 0.54166667
A6: Round of 16 | C6: 0.33333333 | D6: 0.45833333 | E6: 0.5 | F6: 0.54166667 | G6: 0.58333333
A7: Quarterfinals | C7: 0.375 | D7: 0.5 | E7: 0.54166667 | F7: 0.58333333 | G7: 0.625
A8: Semifinals | C8: 0.41666667 | D8: 0.54166667 | E8: 0.58333333 | F8: 0.625 | G8: 0.66666667
A9: Finals | C9: 0.45833333 | D9: 0.58333333 | E9: 0.625 | F9: 0.66666667 | G9: 0.70833333
A10: Awards Ceremony | C10: 0.5 | D10: 0.625 | E10: 0.66666667 | F10: 0.70833333 | G10: 0.75

Sheet Testing Data
B1: Group A | J1: Group B
C4: Team 1 | D4: Team 2 | E4: Team 3 | F4: Team 4 | G4: PPG | H4: Points | I4: Functioning Group | K4: Team 5 | L4: Team 6 | M4: Team 7 | N4: Team 8 | O4: PPG | P4: Points | Q4: Test data 3-way tie 1st
B7: Team 1 | D7: 96 | E7: 96 | F7: 96 | G7: 96 | H7: 0 | J7: Team 5 | L7: 104 | M7: 104 | N7: 100 | O7: 102.67 | P7: 4
B8: Team 2 | C8: 100 | E8: 104 | F8: 100 | G8: 101.33 | H8: 4 | J8: Team 6 | K8: 100 | M8: 100 | N8: 104 | O8: 101.33 | P8: 4
B9: Team 3 | C9: 100 | D9: 96 | F9: 104 | G9: 100 | H9: 4 | J9: Team 7 | K9: 100 | L9: 96 | N9: 96 | O9: 97.33 | P9: 0
B10: Team 4 | C10: 104 | D10: 104 | E10: 100 | G10: 102.67 | H10: 4 | J10: Team 8 | K10: 104 | L10: 96 | M10: 100 | O10: 100 | P10: 4
B12: Group C | J12: Group D
C15: Team 9 | D15: Team 10 | E15: Team 11 | F15: Team 12 | G15: PPG | H15: Points | K15: Team 13 | L15: Team 14 | M15: Team 15 | N15: Team 16 | O15: PPG | P15: Points
B18: Team 9 | D18: 100 | E18: 101 | F18: 101 | G18: 100.67 | H18: 6 | I18: Test data no ties | J18: Team 13 | L18: 104 | M18: 104 | N18: 104 | O18: 104 | P18: 6 | Q18: Test data 3-way tie 2nd
B19: Team 10 | C19: 80 | E19: 90 | F19: 65 | G19: 78.33 | H19: 4 | J19: Team 14 | K19: 92 | M19: 104 | N19: 100 | O19: 98.67 | P19: 2
B20: Team 11 | C20: 88 | D20: 88 | F20: 88 | G20: 88 | H20: 0 | J20: Team 15 | K20: 96 | L20: 100 | N20: 104 | O20: 100 | P20: 2
B21: Team 12 | C21: 39 | D21: 41 | E21: 105 | G21: 61.67 | H21: 2 | J21: Team 16 | K21: 100 | L21: 104 | M21: 100 | O21: 101.33 | P21: 2
B23: Group E | J23: Group F
C26: Team 17 | D26: Team 18 | E26: Team 19 | F26: Team 20 | G26: PPG | H26: Points | K26: Team 21 | L26: Team 22 | M26: Team 23 | N26: Team 24 | O26: PPG | P26: Points
B29: Team 17 | D29: 92 | E29: 92 | F29: 92 | G29: 92 | H29: 0 | I29: Test data 3-way tie 1st transposed | J29: Team 21 | L29: 96 | M29: 92 | N29: 84 | O29: 90.67 | P29: 2 | Q29: Test data 3-way tie 2nd transposed
B30: Team 18 | C30: 96 | E30: 100 | F30: 96 | G30: 97.33 | H30: 4 | J30: Team 22 | K30: 92 | M30: 96 | N30: 88 | O30: 92 | P30: 2
B31: Team 19 | C31: 96 | D31: 92 | F31: 100 | G31: 96 | H31: 4 | J31: Team 23 | K31: 96 | L31: 92 | N31: 92 | O31: 93.33 | P31: 2
B32: Team 20 | C32: 100 | D32: 100 | E32: 96 | G32: 98.67 | H32: 4 | J32: Team 24 | K32: 96 | L32: 96 | M32: 96 | O32: 96 | P32: 6

Sheet Hidden Sheet
A1: Group A | D1: ='Round Robin'!B18 -> Interlakeside | E1: ='Round Robin'!B19 -> Mission San Jose | F1: ='Round Robin'!B20 -> Sharon HS | G1: ='Round Robin'!B21 -> Science Academy B | H1: =LARGE(D5:G5,3) -> 2 | I1: =IFS(AND(H1=D5,D1<>B10,D1<>B13),D1,AND(H1=E5,E1<>B10,E1<>B13),E1,AND(H1=F5,F1<>B10,F1<>B13),F1,AND(H1=G5,G1<>B10,G1<>B13),G1) -> Science Academy B | M1: Group B | P1: ='Round Robin'!J18 -> Amador Valley B | Q1: ='Round Robin'!J19 -> Buchholz B | R1: ='Round Robin'!J20 -> Montgomery Blair HS | S1: ='Round Robin'!J21 -> Science Academy A | T1: =LARGE(P5:S5,3) -> 2 | U1: =IFS(AND(T1=P5,P1<>N10,P1<>N13),P1,AND(T1=Q5,Q1<>N10,Q1<>N13),Q1,AND(T1=R5,R1<>N10,R1<>N13),R1,AND(T1=S5,S1<>N10,S1<>N13),S1) -> Science Academy A
A2: ='Round Robin'!D18 -> 124 | B2: ='Round Robin'!C19 -> 82 | C2: 1v2 | D2: =IF(ISBLANK(A2),,IFS(A2>B2,2,A2=B2,1,A2<B2,0)) -> 2 | E2: =IF(ISBLANK(A2),,IFS(A2>B2,0,A2=B2,1,A2<B2,2)) -> 0 | F2: =IF(ISBLANK(A3),,IFS(A3>B3,0,A3=B3,1,A3<B3,2)) -> 0 | G2: =IF(ISBLANK(A4),,IFS(A4>B4,0,A4=B4,1,A4<B4,2)) -> 0 | H2: =LARGE(D5:G5,4) -> 0 | I2: =IF(H2=H1,IFS(AND(H2=D5,D1<>B10,D1<>B13,D1<>I1),D1,AND(H2=E5,E1<>B10,E1<>B13,E1<>I1),E1,AND(H2=F5,F1<>B10,F1<>B13,F1<>I1),F1,AND(H2=G5,G1<>B10,G1<>B13,G1<>I1),G1),) | M2: ='Round Robin'!L18 -> 24 | N2: ='Round Robin'!K19 -> 60 | O2: 1v2 | P2: =IF(ISBLANK(M2),,IFS(M2>N2,2,M2=N2,1,M2<N2,0)) -> 0 | Q2: =IF(ISBLANK(M2),,IFS(M2>N2,0,M2=N2,1,M2<N2,2)) -> 2 | R2: =IF(ISBLANK(M3),,IFS(M3>N3,0,M3=N3,1,M3<N3,2)) -> 2 | S2: =IF(ISBLANK(M4),,IFS(M4>N4,0,M4=N4,1,M4<N4,2)) -> 2 | T2: =LARGE(P5:S5,4) -> 0 | U2: =IF(T2=T1,IFS(AND(T2=P5,P1<>N10,P1<>N13,P1<>U1),P1,AND(T2=Q5,Q1<>N10,Q1<>N13,Q1<>U1),Q1,AND(T2=R5,R1<>N10,R1<>N13,R1<>U1),R1,AND(T2=S5,S1<>N10,S1<>N13,S1<>U1),S1),)
A3: ='Round Robin'!E18 -> 124 | B3: ='Round Robin'!C20 -> 14 | C3: 1v3 | D3: =IF(ISBLANK(A3),,IFS(A3>B3,2,A3=B3,1,A3<B3,0)) -> 2 | E3: =IF(ISBLANK(A5),,IFS(A5>B5,2,A5=B5,1,A5<B5,0)) -> 2 | F3: =IF(ISBLANK(A5),,IFS(A5>B5,0,A5=B5,1,A5<B5,2)) -> 0 | G3: =IF(ISBLANK(A6),,IFS(A6>B6,0,A6=B6,1,A6<B6,2)) -> 0 | H3: =IF(H2=H1,HLOOKUP(I1,D8:G9,2,FALSE)) -> FALSE | I3: =I1 -> Science Academy B | M3: ='Round Robin'!M18 -> 54 | N3: ='Round Robin'!K20 -> 114 | O3: 1v3 | P3: =IF(ISBLANK(M3),,IFS(M3>N3,2,M3=N3,1,M3<N3,0)) -> 0 | Q3: =IF(ISBLANK(M5),,IFS(M5>N5,2,M5=N5,1,M5<N5,0)) -> 0 | R3: =IF(ISBLANK(M5),,IFS(M5>N5,0,M5=N5,1,M5<N5,2)) -> 2 | S3: =IF(ISBLANK(M6),,IFS(M6>N6,0,M6=N6,1,M6<N6,2)) -> 0 | T3: =IF(T2=T1,HLOOKUP(U1,P8:S9,2,FALSE)) -> FALSE | U3: =U1 -> Science Academy A
A4: ='Round Robin'!F18 -> 120 | B4: ='Round Robin'!C21 -> 22 | C4: 1v4 | D4: =IF(ISBLANK(A4),,IFS(A4>B4,2,A4=B4,1,A4<B4,0)) -> 2 | E4: =IF(ISBLANK(A6),,IFS(A6>B6,2,A6=B6,1,A6<B6,0)) -> 2 | F4: =IF(ISBLANK(A7),,IFS(A7>B7,2,A7=B7,1,A7<B7,0)) -> 0 | G4: =IF(ISBLANK(A7),,IFS(A7>B7,0,A7=B7,1,A7<B7,2)) -> 2 | H4: =IF(H2=H1,HLOOKUP(I2,D8:G9,2,FALSE)) -> FALSE | I4: =I2 | M4: ='Round Robin'!N18 -> 42 | N4: ='Round Robin'!K21 -> 54 | O4: 1v4 | P4: =IF(ISBLANK(M4),,IFS(M4>N4,2,M4=N4,1,M4<N4,0)) -> 0 | Q4: =IF(ISBLANK(M6),,IFS(M6>N6,2,M6=N6,1,M6<N6,0)) -> 2 | R4: =IF(ISBLANK(M7),,IFS(M7>N7,2,M7=N7,1,M7<N7,0)) -> 2 | S4: =IF(ISBLANK(M7),,IFS(M7>N7,0,M7=N7,1,M7<N7,2)) -> 0 | T4: =IF(T2=T1,HLOOKUP(U2,P8:S9,2,FALSE)) -> FALSE | U4: =U2
A5: ='Round Robin'!E19 -> 62 | B5: ='Round Robin'!D20 -> 18 | C5: 2v3 | D5: =SUM(D2:D4) -> 6 | E5: =SUM(E2:E4) -> 4 | F5: =SUM(F2:F4) -> 0 | G5: =SUM(G2:G4) -> 2 | H5: =IFS(H3=FALSE,I1,H3>H4,I3,H3<H4,I4,H3=H4,CONCATENATE("Tie", I3, I4)) -> Science Academy B | I5: =IFS(H3>H4,H3,H4>H3,H4,H3=H4,H4) -> FALSE | M5: ='Round Robin'!M19 -> 18 | N5: ='Round Robin'!L20 -> 84 | O5: 2v3 | P5: =SUM(P2:P4) -> 0 | Q5: =SUM(Q2:Q4) -> 4 | R5: =SUM(R2:R4) -> 6 | S5: =SUM(S2:S4) -> 2 | T5: =IFS(T3=FALSE,U1,T3>T4,U3,T3<T4,U4,T3=T4,CONCATENATE("Tie", U3, U4)) -> Science Academy A | U5: =IFS(T3>T4,T3,T4>T3,T4,T3=T4,T4) -> FALSE
A6: ='Round Robin'!F19 -> 120 | B6: ='Round Robin'!D21 -> 24 | C6: 2v4 | F6: =IF(OR(D5="",E5="",F5="",G5="",G4="",F4="",E4="",D4="",D3="",D2="",E3="",E2="",F3="",F2="",G3="",G2=""),"",IFNA(IFS(AND(D7=E5,E1<>E7),'Round Robin'!D15,AND(D7=F5,F1<>E7),'Round Robin'!E15,AND(D7=G5,G1<>E7),'Round Robin'!F15),"")) | G6: =IF(OR(D5="",E5="",F5="",G5="",G4="",F4="",E4="",D4="",D3="",D2="",E3="",E2="",F3="",F2="",G3="",G2=""),"",IFNA(IFS(AND(D7=F5,F1<>E7,F1<>F7),'Round Robin'!E15,AND(D7=G5,G1<>E7,G1<>F7),'Round Robin'!F15),"")) | M6: ='Round Robin'!N19 -> 60 | N6: ='Round Robin'!L21 -> 56 | O6: 2v4 | R6: =IF(OR(P5="",Q5="",R5="",S5="",S4="",R4="",Q4="",P4="",P3="",P2="",Q3="",Q2="",R3="",R2="",S3="",S2=""),"",IFNA(IFS(AND(P7=Q5,Q1<>Q7),Q1,AND(P7=R5,R1<>Q7),R1,AND(P7=S5,S1<>Q7),S1),"")) | S6: =IF(OR(P5="",Q5="",R5="",S5="",S4="",R4="",Q4="",P4="",P3="",P2="",Q3="",Q2="",R3="",R2="",S3="",S2=""),"",IFNA(IFS(AND(P7=R5,R1<>Q7,R1<>R7),R1,AND(P7=S5,S1<>Q7,S1<>R7),S1),""))
A7: ='Round Robin'!F20 -> 2 | B7: ='Round Robin'!E21 -> 20 | C7: 3v4 | D7: =MAX(D5:G5) -> 6 | E7: =IF(OR(D5="",E5="",F5="",G5="",G4="",F4="",E4="",D4="",D3="",D2="",E3="",E2="",F3="",F2="",G3="",G2=""),"",IFS(D7=D5,'Round Robin'!C15,D7=E5,'Round Robin'!D15,D7=F5,'Round Robin'!E15,D7=G5,'Round Robin'!F15)) -> Interlakeside | F7: =IF(AND(F6<>E7),F6,"") | G7: =IF(AND(G6<>E7,G6<>F7),G6,"") | M7: ='Round Robin'!N20 -> 144 | N7: ='Round Robin'!M21 -> -12 | O7: 3v4 | P7: =MAX(P5:S5) -> 6 | Q7: =IF(OR(P5="",Q5="",R5="",S5="",S4="",R4="",Q4="",P4="",P3="",P2="",Q3="",Q2="",R3="",R2="",S3="",S2=""),"",IFS(P7=P5,'Round Robin'!K15,P7=Q5,'Round Robin'!L15,P7=R5,'Round Robin'!M15,P7=S5,'Round Robin'!N15)) -> Montgomery Blair HS | R7: =IF(R6<>Q7,R6,"") | S7: =IF(AND(S6<>Q7,S6<>R7),S6,"")
D8: =D1 -> Interlakeside | E8: =E1 -> Mission San Jose | F8: =F1 -> Sharon HS | G8: =G1 -> Science Academy B | P8: =P1 -> Amador Valley B | Q8: =Q1 -> Buchholz B | R8: =R1 -> Montgomery Blair HS | S8: =S1 -> Science Academy A
A9: =HLOOKUP(E7,D8:G9,2,FALSE) -> 122.67 | B9: =IFERROR(HLOOKUP(F7,D8:G9,2,FALSE),"") | C9: =IFERROR(HLOOKUP(G7,E8:L9,2,FALSE),"") | D9: ='Round Robin'!G18 -> 122.67 | E9: ='Round Robin'!G19 -> 88 | F9: ='Round Robin'!G20 -> 11.33 | G9: ='Round Robin'!G21 -> 22 | M9: =HLOOKUP(Q7,P8:S9,2,FALSE) -> 114 | N9: =IFERROR(HLOOKUP(R7,P8:S9,2,FALSE),"") | O9: =IFERROR(HLOOKUP(S7,Q8:T9,2,FALSE),"") | P9: ='Round Robin'!O18 -> 40 | Q9: ='Round Robin'!O19 -> 46 | R9: ='Round Robin'!O20 -> 114 | S9: ='Round Robin'!O21 -> 32.67
A10: =MAX(A9:C9) -> 122.67 | B10: =IFNA(HLOOKUP(A10,D9:G10,2,FALSE),"Cayuga #1") -> Interlakeside | D10: =D1 -> Interlakeside | E10: =E1 -> Mission San Jose | F10: =F1 -> Sharon HS | G10: =G1 -> Science Academy B | M10: =MAX(M9:O9) -> 114 | N10: =IFNA(HLOOKUP(M10,P9:S10,2,FALSE),"Seneca #1") -> Montgomery Blair HS | P10: =P1 -> Amador Valley B | Q10: =Q1 -> Buchholz B | R10: =R1 -> Montgomery Blair HS | S10: =S1 -> Science Academy A
F11: =IF(OR(D2="",E2="",F2="",G2="",G3="",F3="",E3="",D3="",D4="",D5="",E4="",E5="",F4="",F5="",G4="",G5=""),"",IFNA(IFS(AND(D12=E5,E1<>E12),E1,AND(D12=F5,F1<>E12),F1,AND(D12=G5,G1<>E12),G1),"")) | G11: =IF(OR(D2="",E2="",F2="",G2="",G3="",F3="",E3="",D3="",D4="",D5="",E4="",E5="",F4="",F5="",G4="",G5=""),"",IFNA(IFS(AND(D12=E5,E1<>E12,E1<>F12),E1,AND(D12=F5,F1<>E12,F1<>F12),F1,AND(D12=G5,G1<>E12,G1<>F12),G1),"")) | H11: =IF(OR(E5="",F5="",G5="",H5="",H4="",G4="",F4="",E4="",E3="",E2="",F3="",F2="",G3="",G2="",H3="",H2=""),"",IFNA(IFS(E7=F5,'Round Robin'!A15,E7=G5,'Round Robin'!B15,E7=H5,'Round Robin'!C15),"")) | R11: =IF(OR(P2="",Q2="",R2="",S2="",S3="",R3="",Q3="",P3="",P4="",P5="",Q4="",Q5="",R4="",R5="",S4="",S5=""),"",IFNA(IFS(AND(P12=Q5,Q1<>Q12),Q1,AND(P12=R5,R1<>Q12),R1,AND(P12=S5,S1<>Q12),S1),"")) | S11: =IF(OR(P2="",Q2="",R2="",S2="",S3="",R3="",Q3="",P3="",P4="",P5="",Q4="",Q5="",R4="",R5="",S4="",S5=""),"",IFNA(IFS(AND(P12=Q5,Q1<>Q12,Q1<>R12),Q1,AND(P12=R5,R1<>Q12,R1<>R12),R1,AND(P12=S5,S1<>Q12,S1<>R12),S1),""))
D12: =LARGE(D5:G5,2) -> 4 | E12: =IF(OR(D5="",E5="",F5="",G5="",G4="",F4="",E4="",D4="",D3="",D2="",E3="",E2="",F3="",F2="",G3="",G2=""),"",IFS(AND(D12=D5,D1<>B10),D1,AND(D12=E5,E1<>B10),E1,AND(D12=F5,F1<>B10),F1,AND(D12=G5,G1<>B10),G1)) -> Mission San Jose | F12: =IF(AND(F11<>E12,F11<>B10),F11,"") | G12: =IF(AND(G11<>E12,G11<>F12,G11<>B10),G11,"") | P12: =LARGE(P5:S5,2) -> 4 | Q12: =IF(OR(P5="",Q5="",R5="",S5="",S4="",R4="",Q4="",P4="",P3="",P2="",Q3="",Q2="",R3="",R2="",S3="",S2=""),"",IFS(AND(P12=P5,P1<>N10),P1,AND(P12=Q5,Q1<>N10),Q1,AND(P12=R5,R1<>N10),R1,AND(P12=S5,S1<>N10),S1)) -> Buchholz B | R12: =IF(AND(R11<>Q12,R11<>N10),R11,"") | S12: =IF(AND(S11<>Q12,S11<>R12,S11<>N10),S11,"")
A13: =MAX(E13:G13) -> 88 | B13: =IFNA(HLOOKUP(A13,D9:G10,2,FALSE),"Cayuga #2") -> Mission San Jose | E13: =IFNA(HLOOKUP(E12,D8:G9,2,FALSE),) -> 88 | F13: =IFNA(HLOOKUP(F12,D8:G9,2,FALSE),) | G13: =IFNA(HLOOKUP(G12,D8:G9,2,FALSE),) | M13: =MAX(Q13:S13) -> 46 | N13: =IFNA(HLOOKUP(M13,P9:S10,2,FALSE),"Seneca #2") -> Buchholz B | Q13: =IFNA(HLOOKUP(Q12,P8:S9,2,FALSE),) -> 46 | R13: =IFNA(HLOOKUP(R12,P8:S9,2,FALSE),) | S13: =IFNA(HLOOKUP(S12,P8:S9,2,FALSE),)
E14: =E12 -> Mission San Jose | F14: =F12 | G14: =G12 | Q14: =Q12 -> Buchholz B | R14: =R12 | S14: =S12
A15: 1st Place: | B15: =B10 -> Interlakeside | C15: 2nd Place: | D15: =B13 -> Mission San Jose | E15: 3rd Place: | F15: =IF(D15="Cayuga #2","Cayuga #3",H5) -> Science Academy B | M15: 1st Place: | N15: =N10 -> Montgomery Blair HS | O15: 2nd Place: | P15: =N13 -> Buchholz B | Q15: 3rd Place: | R15: =IF(P15="Seneca #2","Seneca #3",T5) -> Science Academy A
F16: =HLOOKUP(F15,D8:G9,2,FALSE) -> 22 | R16: =HLOOKUP(R15,P8:S9,2,FALSE) -> 32.67
A18: Group C | D18: ='Round Robin'!B29 -> University HS | E18: ='Round Robin'!B30 -> Davidson Academy | F18: ='Round Robin'!B31 -> James S. Rickards HS | G18: ='Round Robin'!B32 -> Amador Valley A | H18: =LARGE(D22:G22,3) -> 2 | I18: =IFS(AND(H18=D22,D18<>B27,D18<>B30),D18,AND(H18=E22,E18<>B27,E18<>B30),E18,AND(H18=F22,F18<>B27,F18<>B30),F18,AND(H18=G22,G18<>B27,G18<>B30),G18) -> Amador Valley A | M18: Group D | P18: ='Round Robin'!J29 -> Buchholz A | Q18: ='Round Robin'!J30 -> Foothill A | R18: ='Round Robin'!J31 -> Poolesville HS | S18: ='Round Robin'!J32 -> Venice HS | T18: =LARGE(P22:S22,3) -> 2 | U18: =IFS(AND(T18=P22,P18<>N27,P18<>N30),P18,AND(T18=Q22,Q18<>N27,Q18<>N30),Q18,AND(T18=R22,R18<>N27,R18<>N30),R18,AND(T18=S22,S18<>N27,S18<>N30),S18) -> Foothill A
A19: ='Round Robin'!D29 -> 106 | B19: ='Round Robin'!C30 -> 114 | C19: 1v2 | D19: =IF(ISBLANK(A19),,IFS(A19>B19,2,A19=B19,1,A19<B19,0)) -> 0 | E19: =IF(ISBLANK(A19),,IFS(A19>B19,0,A19=B19,1,A19<B19,2)) -> 2 | F19: =IF(ISBLANK(A20),,IFS(A20>B20,0,A20=B20,1,A20<B20,2)) -> 0 | G19: =IF(ISBLANK(A21),,IFS(A21>B21,0,A21=B21,1,A21<B21,2)) -> 0 | H19: =LARGE(D22:G22,4) -> 0 | I19: =IF(H19=H18,IFS(AND(H19=D22,D18<>B27,D18<>B30,D18<>I18),D18,AND(H19=E22,E18<>B27,E18<>B30,E18<>I18),E18,AND(H19=F22,F18<>B27,F18<>B30,F18<>I18),F18,AND(H19=G22,G18<>B27,G18<>B30,G18<>I18),G18),) | M19: ='Round Robin'!L29 -> 94 | N19: ='Round Robin'!K30 -> 74 | O19: 1v2 | P19: =IF(ISBLANK(M19),,IFS(M19>N19,2,M19=N19,1,M19<N19,0)) -> 2 | Q19: =IF(ISBLANK(M19),,IFS(M19>N19,0,M19=N19,1,M19<N19,2)) -> 0 | R19: =IF(ISBLANK(M20),,IFS(M20>N20,0,M20=N20,1,M20<N20,2)) -> 2 | S19: =IF(ISBLANK(M21),,IFS(M21>N21,0,M21=N21,1,M21<N21,2)) -> 0 | T19: =LARGE(P22:S22,4) -> 0 | U19: =IF(T19=T18,IFS(AND(T19=P22,P18<>N27,P18<>N30,P18<>U18),P18,AND(T19=Q22,Q18<>N27,Q18<>N30,Q18<>U18),Q18,AND(T19=R22,R18<>N27,R18<>N30,R18<>U18),R18,AND(T19=S22,S18<>N27,S18<>N30,S18<>U18),S18),)
A20: ='Round Robin'!E29 -> 130 | B20: ='Round Robin'!C31 -> 12 | C20: 1v3 | D20: =IF(ISBLANK(A20),,IFS(A20>B20,2,A20=B20,1,A20<B20,0)) -> 2 | E20: =IF(ISBLANK(A22),,IFS(A22>B22,2,A22=B22,1,A22<B22,0)) -> 2 | F20: =IF(ISBLANK(A22),,IFS(A22>B22,0,A22=B22,1,A22<B22,2)) -> 0 | G20: =IF(ISBLANK(A23),,IFS(A23>B23,0,A23=B23,1,A23<B23,2)) -> 0 | H20: =IF(H19=H18,HLOOKUP(I18,D25:G26,2,FALSE)) -> FALSE | I20: =I18 -> Amador Valley A | M20: ='Round Robin'!M29 -> 12 | N20: ='Round Robin'!K31 -> 200 | O20: 1v3 | P20: =IF(ISBLANK(M20),,IFS(M20>N20,2,M20=N20,1,M20<N20,0)) -> 0 | Q20: =IF(ISBLANK(M22),,IFS(M22>N22,2,M22=N22,1,M22<N22,0)) -> 0 | R20: =IF(ISBLANK(M22),,IFS(M22>N22,0,M22=N22,1,M22<N22,2)) -> 2 | S20: =IF(ISBLANK(M23),,IFS(M23>N23,0,M23=N23,1,M23<N23,2)) -> 0 | T20: =IF(T19=T18,HLOOKUP(U18,P25:S26,2,FALSE)) -> FALSE | U20: =U18 -> Foothill A
A21: ='Round Robin'!F29 -> 100 | B21: ='Round Robin'!C32 -> 64 | C21: 1v4 | D21: =IF(ISBLANK(A21),,IFS(A21>B21,2,A21=B21,1,A21<B21,0)) -> 2 | E21: =IF(ISBLANK(A23),,IFS(A23>B23,2,A23=B23,1,A23<B23,0)) -> 2 | F21: =IF(ISBLANK(A24),,IFS(A24>B24,2,A24=B24,1,A24<B24,0)) -> 0 | G21: =IF(ISBLANK(A24),,IFS(A24>B24,0,A24=B24,1,A24<B24,2)) -> 2 | H21: =IF(H19=H18,HLOOKUP(I19,D25:G26,2,FALSE)) -> FALSE | I21: =I19 | M21: ='Round Robin'!N29 -> 76 | N21: ='Round Robin'!K32 -> 20 | O21: 1v4 | P21: =IF(ISBLANK(M21),,IFS(M21>N21,2,M21=N21,1,M21<N21,0)) -> 2 | Q21: =IF(ISBLANK(M23),,IFS(M23>N23,2,M23=N23,1,M23<N23,0)) -> 2 | R21: =IF(ISBLANK(M24),,IFS(M24>N24,2,M24=N24,1,M24<N24,0)) -> 2 | S21: =IF(ISBLANK(M24),,IFS(M24>N24,0,M24=N24,1,M24<N24,2)) -> 0 | T21: =IF(T19=T18,HLOOKUP(U19,P25:S26,2,FALSE)) -> FALSE | U21: =U19
A22: ='Round Robin'!E30 -> 80 | B22: ='Round Robin'!D31 -> 28 | C22: 2v3 | D22: =SUM(D19:D21) -> 4 | E22: =SUM(E19:E21) -> 6 | F22: =SUM(F19:F21) -> 0 | G22: =SUM(G19:G21) -> 2 | H22: =IFS(H20=FALSE,I18,H20>H21,I20,H20<H21,I21,H20=H21,CONCATENATE("Tie", I20, I21)) -> Amador Valley A | I22: =IFS(H20>H21,H20,H21>H20,H21,H20=H21,H21) -> FALSE | M22: ='Round Robin'!M30 -> 44 | N22: ='Round Robin'!L31 -> 88 | O22: 2v3 | P22: =SUM(P19:P21) -> 4 | Q22: =SUM(Q19:Q21) -> 2 | R22: =SUM(R19:R21) -> 6 | S22: =SUM(S19:S21) -> 0 | T22: =IFS(T20=FALSE,U18,T20>T21,U20,T20<T21,U21,T20=T21,CONCATENATE("Tie", U20, U21)) -> Foothill A | U22: =IFS(T20>T21,T20,T21>T20,T21,T20=T21,T21) -> FALSE
A23: ='Round Robin'!F30 -> 104 | B23: ='Round Robin'!D32 -> 62 | C23: 2v4 | F23: =IF(OR(D22="",E22="",F22="",G22="",G21="",F21="",E21="",D21="",D20="",D19="",E20="",E19="",F20="",F19="",G20="",G19=""),"",IFNA(IFS(AND(D24=E22,E18<>E24),E18,AND(D24=F22,F18<>E24),F18,AND(D24=G22,G18<>E24),G18),"")) | G23: =IF(OR(D22="",E22="",F22="",G22="",G21="",F21="",E21="",D21="",D20="",D19="",E20="",E19="",F20="",F19="",G20="",G19=""),"",IFNA(IFS(AND(D24=F22,F18<>E24,F18<>F24),F18,AND(D24=G22,G18<>E24,G18<>F24),G18),"")) | M23: ='Round Robin'!N30 -> 96 | N23: ='Round Robin'!L32 -> 44 | O23: 2v4 | R23: =IF(OR(P22="",Q22="",R22="",S22="",S21="",R21="",Q21="",P21="",P20="",P19="",Q20="",Q19="",R20="",R19="",S20="",S19=""),"",IFNA(IFS(AND(P24=Q22,Q18<>Q24),Q18,AND(P24=R22,R18<>Q24),R18,AND(P24=S22,S18<>Q24),S18),"")) | S23: =IF(OR(P22="",Q22="",R22="",S22="",S21="",R21="",Q21="",P21="",P20="",P19="",Q20="",Q19="",R20="",R19="",S20="",S19=""),"",IFNA(IFS(AND(P24=R22,R18<>Q24,R18<>R24),R18,AND(P24=S22,S18<>Q24,S18<>R24),S18),""))
A24: ='Round Robin'!F31 -> 44 | B24: ='Round Robin'!E32 -> 86 | C24: 3v4 | D24: =MAX(D22:G22) -> 6 | E24: =IF(OR(D22="",E22="",F22="",G22="",G21="",F21="",E21="",D21="",D20="",D19="",E20="",E19="",F20="",F19="",G20="",G19=""),"",IFS(D24=D22,'Round Robin'!C26,D24=E22,'Round Robin'!D26,D24=F22,'Round Robin'!E26,D24=G22,'Round Robin'!F26)) -> Davidson Academy | F24: =IF(F23<>E24,F23,"") | G24: =IF(AND(G23<>E24,G23<>F24),G23,"") | M24: ='Round Robin'!N31 -> 92 | N24: ='Round Robin'!M32 -> 34 | O24: 3v4 | P24: =MAX(P22:S22) -> 6 | Q24: =IF(OR(P22="",Q22="",R22="",S22="",S21="",R21="",Q21="",P21="",P20="",P19="",Q20="",Q19="",R20="",R19="",S20="",S19=""),"",IFS(P24=P22,'Round Robin'!K26,P24=Q22,'Round Robin'!L26,P24=R22,'Round Robin'!M26,P24=S22,'Round Robin'!N26)) -> Poolesville HS | R24: =IF(R23<>Q24,R23,"") | S24: =IF(AND(S23<>Q24,S23<>R24),S23,"")
D25: =D18 -> University HS | E25: =E18 -> Davidson Academy | F25: =F18 -> James S. Rickards HS | G25: =G18 -> Amador Valley A | P25: =P18 -> Buchholz A | Q25: =Q18 -> Foothill A | R25: =R18 -> Poolesville HS | S25: =S18 -> Venice HS
A26: =HLOOKUP(E24,D25:G26,2,FALSE) -> 99.33 | B26: =IFERROR(HLOOKUP(F24,D25:G26,2,FALSE),"") | C26: =IFERROR(HLOOKUP(G24,E25:L26,2,FALSE),"") | D26: ='Round Robin'!G29 -> 112 | E26: ='Round Robin'!G30 -> 99.33 | F26: ='Round Robin'!G31 -> 28 | G26: ='Round Robin'!G32 -> 70.67 | M26: =HLOOKUP(Q24,P25:S26,2,FALSE) -> 126.67 | N26: =IFERROR(HLOOKUP(R24,P25:S26,2,FALSE),"") | O26: =IFERROR(HLOOKUP(S24,Q25:T26,2,FALSE),"") | P26: ='Round Robin'!O29 -> 60.67 | Q26: ='Round Robin'!O30 -> 71.33 | R26: ='Round Robin'!O31 -> 126.67 | S26: ='Round Robin'!O32 -> 32.67
A27: =MAX(A26:C26) -> 99.33 | B27: =IFNA(HLOOKUP(A27,D26:G27,2,FALSE),"Onondaga #1") -> Davidson Academy | D27: =D18 -> University HS | E27: =E18 -> Davidson Academy | F27: =F18 -> James S. Rickards HS | G27: =G18 -> Amador Valley A | M27: =MAX(M26:O26) -> 126.67 | N27: =IFNA(HLOOKUP(M27,P26:S27,2,FALSE),"Oneida #1") -> Poolesville HS | P27: =P18 -> Buchholz A | Q27: =Q18 -> Foothill A | R27: =R18 -> Poolesville HS | S27: =S18 -> Venice HS
F28: =IF(OR(D19="",E19="",F19="",G19="",G20="",F20="",E20="",D20="",D21="",D22="",E21="",E22="",F21="",F22="",G21="",G22=""),"",IFNA(IFS(AND(D29=E22,E18<>E29),E18,AND(D29=F22,F18<>E29),F18,AND(D29=G22,G18<>E29),G18),"")) | G28: =IF(OR(D19="",E19="",F19="",G19="",G20="",F20="",E20="",D20="",D21="",D22="",E21="",E22="",F21="",F22="",G21="",G22=""),"",IFNA(IFS(AND(D29=E22,E18<>E29,E18<>F29),E18,AND(D29=F22,F18<>E29,F18<>F29),F18,AND(D29=G22,G18<>E29,G18<>F29),G18),"")) | R28: =IF(OR(P19="",Q19="",R19="",S19="",S20="",R20="",Q20="",P20="",P21="",P22="",Q21="",Q22="",R21="",R22="",S21="",S22=""),"",IFNA(IFS(AND(P29=Q22,Q18<>Q29),Q18,AND(P29=R22,R18<>Q29),R18,AND(P29=S22,S18<>Q29),S18),"")) | S28: =IF(OR(P19="",Q19="",R19="",S19="",S20="",R20="",Q20="",P20="",P21="",P22="",Q21="",Q22="",R21="",R22="",S21="",S22=""),"",IFNA(IFS(AND(P29=Q22,Q18<>Q29,Q18<>R29),Q18,AND(P29=R22,R18<>Q29,R18<>R29),R18,AND(P29=S22,S18<>Q29,S18<>R29),S18),""))
D29: =LARGE(D22:G22,2) -> 4 | E29: =IF(OR(D22="",E22="",F22="",G22="",G21="",F21="",E21="",D21="",D20="",D19="",E20="",E19="",F20="",F19="",G20="",G19=""),"",IFS(AND(D29=D22,D18<>B27),D18,AND(D29=E22,E18<>B27),E18,AND(D29=F22,F18<>B27),F18,AND(D29=G22,G18<>B27),G18)) -> University HS | F29: =IF(AND(F28<>E29,F28<>B27),F28,"") | G29: =IF(AND(G28<>E29,G28<>F29,G28<>B27),G28,"") | P29: =LARGE(P22:S22,2) -> 4 | Q29: =IF(OR(P22="",Q22="",R22="",S22="",S21="",R21="",Q21="",P21="",P20="",P19="",Q20="",Q19="",R20="",R19="",S20="",S19=""),"",IFS(AND(P29=P22,P18<>N27),P18,AND(P29=Q22,Q18<>N27),Q18,AND(P29=R22,R18<>N27),R18,AND(P29=S22,S18<>N27),S18)) -> Buchholz A | R29: =IF(AND(R28<>Q29,R28<>N27),R28,"") | S29: =IF(AND(S28<>Q29,S28<>R29,S28<>N27),S28,"")
A30: =MAX(E30:G30) -> 112 | B30: =IFNA(HLOOKUP(A30,D26:G27,2,FALSE),"Onondaga #2") -> University HS | E30: =IFNA(HLOOKUP(E29,D25:G26,2,FALSE),) -> 112 | F30: =IFNA(HLOOKUP(F29,D25:G26,2,FALSE),) | G30: =IFNA(HLOOKUP(G29,D25:G26,2,FALSE),) | M30: =MAX(Q30:S30) -> 60.67 | N30: =IFNA(HLOOKUP(M30,P26:S27,2,FALSE),"Oneida #2") -> Buchholz A | Q30: =IFNA(HLOOKUP(Q29,P25:S26,2,FALSE),) -> 60.67 | R30: =IFNA(HLOOKUP(R29,P25:S26,2,FALSE),) | S30: =IFNA(HLOOKUP(S29,P25:S26,2,FALSE),)
E31: =E29 -> University HS | F31: =F29 | G31: =G29 | Q31: =Q29 -> Buchholz A | R31: =R29 | S31: =S29
A32: 1st Place: | B32: =B27 -> Davidson Academy | C32: 2nd Place: | D32: =B30 -> University HS | E32: 3rd Place: | F32: =IF(D32="Onondaga #2","Onondaga #3",H22) -> Amador Valley A | M32: 1st Place: | N32: =N27 -> Poolesville HS | O32: 2nd Place: | P32: =N30 -> Buchholz A | Q32: 3rd Place: | R32: =IF(P32="Oneida #2","Oneida #3",T22) -> Foothill A
F33: =HLOOKUP(F32,D25:G26,2,FALSE) -> 70.67 | R33: =HLOOKUP(R32,P25:S26,2,FALSE) -> 71.33
A35: Group E | D35: ='Round Robin'!B40 -> CBA | E35: ='Round Robin'!B41 -> Enloe HS | F35: ='Round Robin'!B42 -> Iolani | G35: ='Round Robin'!B43 -> Poolesville B | H35: =LARGE(D39:G39,3) -> 3 | I35: =IFS(AND(H35=D39,D35<>B44,D35<>B47),D35,AND(H35=E39,E35<>B44,E35<>B47),E35,AND(H35=F39,F35<>B44,F35<>B47),F35,AND(H35=G39,G35<>B44,G35<>B47),G35) -> Poolesville B | M35: Group F | P35: ='Round Robin'!J40 -> North Hollywood | Q35: ='Round Robin'!J41 -> Clements HS | R35: ='Round Robin'!J42 -> Foothill B | S35: ='Round Robin'!J43 -> Arcadia HS | T35: =LARGE(P39:S39,3) -> 4 | U35: =IFS(AND(T35=P39,P35<>N44,P35<>N47),P35,AND(T35=Q39,Q35<>N44,Q35<>N47),Q35,AND(T35=R39,R35<>N44,R35<>N47),R35,AND(T35=S39,S35<>N44,S35<>N47),S35) -> Foothill B
A36: ='Round Robin'!D40 -> 22 | B36: ='Round Robin'!C41 -> 52 | C36: 1v2 | D36: =IF(ISBLANK(A36),,IFS(A36>B36,2,A36=B36,1,A36<B36,0)) -> 0 | E36: =IF(ISBLANK(A36),,IFS(A36>B36,0,A36=B36,1,A36<B36,2)) -> 2 | F36: =IF(ISBLANK(A37),,IFS(A37>B37,0,A37=B37,1,A37<B37,2)) -> 2 | G36: =IF(ISBLANK(A38),,IFS(A38>B38,0,A38=B38,1,A38<B38,2)) -> 2 | H36: =LARGE(D39:G39,4) -> 0 | I36: =IF(H36=H35,IFS(AND(H36=D39,D35<>B44,D35<>B47,D35<>I35),D35,AND(H36=E39,E35<>B44,E35<>B47,E35<>I35),E35,AND(H36=F39,F35<>B44,F35<>B47,F35<>I35),F35,AND(H36=G39,G35<>B44,G35<>B47,G35<>I35),G35),) | M36: ='Round Robin'!L40 -> 90 | N36: ='Round Robin'!K41 -> 70 | O36: 1v2 | P36: =IF(ISBLANK(M36),,IFS(M36>N36,2,M36=N36,1,M36<N36,0)) -> 2 | Q36: =IF(ISBLANK(M36),,IFS(M36>N36,0,M36=N36,1,M36<N36,2)) -> 0 | R36: =IF(ISBLANK(M37),,IFS(M37>N37,0,M37=N37,1,M37<N37,2)) -> 2 | S36: =IF(ISBLANK(M38),,IFS(M38>N38,0,M38=N38,1,M38<N38,2)) -> 0 | T36: =LARGE(P39:S39,4) -> 0 | U36: =IF(T36=T35,IFS(AND(T36=P39,P35<>N44,P35<>N47,P35<>U35),P35,AND(T36=Q39,Q35<>N44,Q35<>N47,Q35<>U35),Q35,AND(T36=R39,R35<>N44,R35<>N47,R35<>U35),R35,AND(T36=S39,S35<>N44,S35<>N47,S35<>U35),S35),)
A37: ='Round Robin'!E40 -> 30 | B37: ='Round Robin'!C42 -> 94 | C37: 1v3 | D37: =IF(ISBLANK(A37),,IFS(A37>B37,2,A37=B37,1,A37<B37,0)) -> 0 | E37: =IF(ISBLANK(A39),,IFS(A39>B39,2,A39=B39,1,A39<B39,0)) -> 0 | F37: =IF(ISBLANK(A39),,IFS(A39>B39,0,A39=B39,1,A39<B39,2)) -> 2 | G37: =IF(ISBLANK(A40),,IFS(A40>B40,0,A40=B40,1,A40<B40,2)) -> 1 | H37: =IF(H36=H35,HLOOKUP(I35,D42:G43,2,FALSE)) -> FALSE | I37: =I35 -> Poolesville B | M37: ='Round Robin'!M40 -> 26 | N37: ='Round Robin'!K42 -> 30 | O37: 1v3 | P37: =IF(ISBLANK(M37),,IFS(M37>N37,2,M37=N37,1,M37<N37,0)) -> 0 | Q37: =IF(ISBLANK(M39),,IFS(M39>N39,2,M39=N39,1,M39<N39,0)) -> 2 | R37: =IF(ISBLANK(M39),,IFS(M39>N39,0,M39=N39,1,M39<N39,2)) -> 0 | S37: =IF(ISBLANK(M40),,IFS(M40>N40,0,M40=N40,1,M40<N40,2)) -> 0 | T37: =IF(T36=T35,HLOOKUP(U35,P42:S43,2,FALSE)) -> FALSE | U37: =U35 -> Foothill B
A38: ='Round Robin'!F40 -> 16 | B38: ='Round Robin'!C43 -> 62 | C38: 1v4 | D38: =IF(ISBLANK(A38),,IFS(A38>B38,2,A38=B38,1,A38<B38,0)) -> 0 | E38: =IF(ISBLANK(A40),,IFS(A40>B40,2,A40=B40,1,A40<B40,0)) -> 1 | F38: =IF(ISBLANK(A41),,IFS(A41>B41,2,A41=B41,1,A41<B41,0)) -> 2 | G38: =IF(ISBLANK(A41),,IFS(A41>B41,0,A41=B41,1,A41<B41,2)) -> 0 | H38: =IF(H36=H35,HLOOKUP(I36,D42:G43,2,FALSE)) -> FALSE | I38: =I36 | M38: ='Round Robin'!N40 -> 62 | N38: ='Round Robin'!K43 -> 30 | O38: 1v4 | P38: =IF(ISBLANK(M38),,IFS(M38>N38,2,M38=N38,1,M38<N38,0)) -> 2 | Q38: =IF(ISBLANK(M40),,IFS(M40>N40,2,M40=N40,1,M40<N40,0)) -> 2 | R38: =IF(ISBLANK(M41),,IFS(M41>N41,2,M41=N41,1,M41<N41,0)) -> 2 | S38: =IF(ISBLANK(M41),,IFS(M41>N41,0,M41=N41,1,M41<N41,2)) -> 0 | T38: =IF(T36=T35,HLOOKUP(U36,P42:S43,2,FALSE)) -> FALSE | U38: =U36
A39: ='Round Robin'!E41 -> 40 | B39: ='Round Robin'!D42 -> 44 | C39: 2v3 | D39: =SUM(D36:D38) -> 0 | E39: =SUM(E36:E38) -> 3 | F39: =SUM(F36:F38) -> 6 | G39: =SUM(G36:G38) -> 3 | H39: =IFS(H37=FALSE,I35,H37>H38,I37,H37<H38,I38,H37=H38,CONCATENATE("Tie", I37, I38)) -> Poolesville B | I39: =IFS(H37>H38,H37,H38>H37,H38,H37=H38,H38) -> FALSE | M39: ='Round Robin'!M41 -> 134 | N39: ='Round Robin'!L42 -> 16 | O39: 2v3 | P39: =SUM(P36:P38) -> 4 | Q39: =SUM(Q36:Q38) -> 4 | R39: =SUM(R36:R38) -> 4 | S39: =SUM(S36:S38) -> 0 | T39: =IFS(T37=FALSE,U35,T37>T38,U37,T37<T38,U38,T37=T38,CONCATENATE("Tie", U37, U38)) -> Foothill B | U39: =IFS(T37>T38,T37,T38>T37,T38,T37=T38,T38) -> FALSE
A40: ='Round Robin'!F41 -> 28 | B40: ='Round Robin'!D43 -> 28 | C40: 2v4 | F40: =IF(OR(D39="",E39="",F39="",G39="",G38="",F38="",E38="",D38="",D37="",D36="",E37="",E36="",F37="",F36="",G37="",G36=""),"",IFNA(IFS(AND(D41=E39,E35<>E41),E35,AND(D41=F39,F35<>E41),F35,AND(D41=G39,G35<>E41),G35),"")) | G40: =IF(OR(D39="",E39="",F39="",G39="",G38="",F38="",E38="",D38="",D37="",D36="",E37="",E36="",F37="",F36="",G37="",G36=""),"",IFNA(IFS(AND(D41=F39,F35<>E41,F35<>F41),F35,AND(D41=G39,G35<>E41,G35<>F41),G35),"")) | M40: ='Round Robin'!N41 -> 140 | N40: ='Round Robin'!L43 -> 26 | O40: 2v4 | R40: =IF(OR(P39="",Q39="",R39="",S39="",S38="",R38="",Q38="",P38="",P37="",P36="",Q37="",Q36="",R37="",R36="",S37="",S36=""),"",IFNA(IFS(AND(P41=Q39,Q35<>Q41),Q35,AND(P41=R39,R35<>Q41),R35,AND(P41=S39,S35<>Q41),S35),"")) -> Clements HS | S40: =IF(OR(P39="",Q39="",R39="",S39="",S38="",R38="",Q38="",P38="",P37="",P36="",Q37="",Q36="",R37="",R36="",S37="",S36=""),"",IFNA(IFS(AND(P41=R39,R35<>Q41,R35<>R41),R35,AND(P41=S39,S35<>Q41,S35<>R41),S35),"")) -> Foothill B
A41: ='Round Robin'!F42 -> 76 | B41: ='Round Robin'!E43 -> 12 | C41: 3v4 | D41: =MAX(D39:G39) -> 6 | E41: =IF(OR(D39="",E39="",F39="",G39="",G38="",F38="",E38="",D38="",D37="",D36="",E37="",E36="",F37="",F36="",G37="",G36=""),"",IFS(D41=D39,'Round Robin'!C37,D41=E39,'Round Robin'!D37,D41=F39,'Round Robin'!E37,D41=G39,'Round Robin'!F37)) -> Iolani | F41: =IF(F40<>E41,F40,"") | G41: =IF(AND(G40<>E41,G40<>F41),G40,"") | M41: ='Round Robin'!N42 -> 72 | N41: ='Round Robin'!M43 -> 26 | O41: 3v4 | P41: =MAX(P39:S39) -> 4 | Q41: =IF(OR(P39="",Q39="",R39="",S39="",S38="",R38="",Q38="",P38="",P37="",P36="",Q37="",Q36="",R37="",R36="",S37="",S36=""),"",IFS(P41=P39,'Round Robin'!K37,P41=Q39,'Round Robin'!L37,P41=R39,'Round Robin'!M37,P41=S39,'Round Robin'!N37)) -> North Hollywood | R41: =IF(R40<>Q41,R40,"") -> Clements HS | S41: =IF(AND(S40<>Q41,S40<>R41),S40,"") -> Foothill B
D42: =D35 -> CBA | E42: =E35 -> Enloe HS | F42: =F35 -> Iolani | G42: =G35 -> Poolesville B | P42: =P35 -> North Hollywood | Q42: =Q35 -> Clements HS | R42: =R35 -> Foothill B | S42: =S35 -> Arcadia HS
...
