Workbook

Sheet Tournament Information
B2: BUMS 2026 Tournament Information
B3: Hosted on January 24, 2026
C6: Time (All in PST) | D6: Round | F6: All Participating Teams
C7: 8:00 - 8:30 AM | D7: Opening Ceremony | F7: A1
C8: 8:30 - 9:05 AM | D8: RR1 | F8: A2
C9: 9:05 - 9:40 AM | D9: RR2 | F9: A3
C10: 9:40 - 10:15 AM | D10: RR3 | F10: A4
C11: 10:15 - 10:50 AM | D11: RR4 | F11: A5
C12: 10:50 - 11:25 AM | D12: RR5 | F12: A6
C13: 11:25 AM - 12:30 PM | D13: Lunch Break | F13: B1
C14: 12:30 - 1:05 PM | D14: DE1 | F14: B2
C15: 1:05 - 1:40 PM | D15: DE2 | F15: B3
C16: 1:40 - 2:15 PM | D16: DE3 | F16: B4
C17: 2:15 - 2:50 PM | D17: DE4 | F17: B5
... C23: 5:45 - 6:05 PM (or 5:10 - 5:30 PM) | D23: Closing and Award Ceremony | F23: C5
F24: C6
C25: Important Links | F25: D1
C26: Tournament Hub | F26: D2
C27: Rules and Info Document | F27: D3
C28: Discord Server | F28: D4
C29: Final Packets | F29: D5
C30: Packet Errata Form | F30: D6

Sheet RR Rooms
B2: RR Rooms
C5: Room | D5: RR1 | E5: RR2 | F5: RR3 | G5: RR4 | H5: RR5
D6: 8:30 - 9:05 AM | E6: 9:05 - 9:40 AM | F6: 9:40 - 10:15 AM | G6: 10:15 - 10:50 AM | H6: 10:50 - 11:25 AM
D8: Alzheimer's
C9: Ampere | D9: A1 vs. A2 | E9: A1 vs. A3 | F9: A1 vs. A4 | G9: A1 vs. A5 | H9: A1 - BYE
C10: Boltzmann | D10: A3 vs. A4 | E10: A4 - BYE | F10: A2 - BYE | G10: A2 vs. A4 | H10: A2 vs. A3
C11: Curie | D11: A5 - BYE | E11: A2 vs. A5 | F11: A3 vs. A5 | G11: A3 - BYE | H11: A4 vs. A5
D13: Bronchitis
C14: Dirac | D14: B1 vs. B2 | E14: B1 vs. B3 | F14: B1 vs. B4 | G14: B1 vs. B5 | H14: B1 vs. B6
C15: Einstein | D15: B3 vs. B4 | E15: B4 vs. B6 | F15: B2 vs. B6 | G15: B2 vs. B4 | H15: B2 vs. B3
C16: Feynman | D16: B5 vs. B6 | E16: B2 vs. B5 | F16: B3 vs. B5 | G16: B3 vs. B6 | H16: B4 vs. B5
D18: Creutzfeldt-Jakob
C19: Galileo | D19: C1 vs. C2 | E19: C1 vs. C3 | F19: C1 vs. C4 | G19: C1 vs. C5 | H19: C1 - BYE
C20: Heisenberg | D20: C3 vs. C4 | E20: C4 - BYE | F20: C2 - BYE | G20: C2 vs. C4 | H20: C2 vs. C3
C21: Ising | D21: C5 - BYE | E21: C2 vs. C5 | F21: C3 vs. C5 | G21: C3 - BYE | H21: C4 vs. C5
D23: Diabetes
C24: Joule | D24: D1 vs. D2 | E24: D1 vs. D3 | F24: D1 vs. D4 | G24: D1 vs. D5 | H24: D1 - BYE
C25: Kirchhoff | D25: D3 vs. D4 | E25: D4 - BYE | F25: D2 - BYE | G25: D2 vs. D4 | H25: D2 vs. D3
C26: Leibniz | D26: D5 - BYE | E26: D2 vs. D5 | F26: D3 vs. D5 | G26: D3 - BYE | H26: D4 vs. D5

Sheet RR Scoring
B2: RR Scoring
C5: Alzheimer's | F5: Scores | G5: A1 | H5: A2 | I5: A3 | J5: A4 | K5: A5 | L5: A6 | M5: Total
C6: A1 | D6: =VLOOKUP(C6,'Tournament Information'!$F$7:$G$30,2) | F6: A1 | M6: =SUM(G6:L6) -> 0
C7: A2 | D7: =VLOOKUP(C7,'Tournament Information'!$F$7:$G$30,2) | F7: A2 | M7: =SUM(G7:L7) -> 0
C8: A3 | D8: =VLOOKUP(C8,'Tournament Information'!$F$7:$G$30,2) | F8: A3 | M8: =SUM(G8:L8) -> 0
C9: A4 | D9: =VLOOKUP(C9,'Tournament Information'!$F$7:$G$30,2) | F9: A4 | M9: =SUM(G9:L9) -> 0
C10: A5 | D10: =VLOOKUP(C10,'Tournament Information'!$F$7:$G$30,2) | F10: A5 | M10: =SUM(G10:L10) -> 0
C11: A6 | D11: =VLOOKUP(C11,'Tournament Information'!$F$7:$G$30,2) | F11: A6 | M11: =SUM(G11:L11) -> 0
L12: Division bonus: | M12: =0.0211*SUM(M6:M11) -> 0
C14: Bronchitis | F14: Scores | G14: B1 | H14: B2 | I14: B3 | J14: B4 | K14: B5 | L14: B6 | M14: Total
C15: B1 | D15: =VLOOKUP(C15,'Tournament Information'!$F$7:$G$30,2) | F15: B1 | M15: =SUM(G15:L15) -> 0
C16: B2 | D16: =VLOOKUP(C16,'Tournament Information'!$F$7:$G$30,2) | F16: B2 | M16: =SUM(G16:L16) -> 0
C17: B3 | D17: =VLOOKUP(C17,'Tournament Information'!$F$7:$G$30,2) | F17: B3 | M17: =SUM(G17:L17) -> 0
C18: B4 | D18: =VLOOKUP(C18,'Tournament Information'!$F$7:$G$30,2) | F18: B4 | M18: =SUM(G18:L18) -> 0
C19: B5 | D19: =VLOOKUP(C19,'Tournament Information'!$F$7:$G$30,2) | F19: B5 | M19: =SUM(G19:L19) -> 0
C20: B6 | D20: =VLOOKUP(C20,'Tournament Information'!$F$7:$G$30,2) | F20: B6 | M20: =SUM(G20:L20) -> 0
L21: Division bonus: | M21: =0.0211*SUM(M15:M20) -> 0
C23: Creutzfeldt-Jakob | F23: Scores | G23: C1 | H23: C2 | I23: C3 | J23: C4 | K23: C5 | L23: C6 | M23: Total
C24: C1 | D24: =VLOOKUP(C24,'Tournament Information'!$F$7:$G$30,2) | F24: C1 | M24: =SUM(G24:L24) -> 0
C25: C2 | D25: =VLOOKUP(C25,'Tournament Information'!$F$7:$G$30,2) | F25: C2 | M25: =SUM(G25:L25) -> 0
C26: C3 | D26: =VLOOKUP(C26,'Tournament Information'!$F$7:$G$30,2) | F26: C3 | M26: =SUM(G26:L26) -> 0
C27: C4 | D27: =VLOOKUP(C27,'Tournament Information'!$F$7:$G$30,2) | F27: C4 | M27: =SUM(G27:L27) -> 0
C28: C5 | D28: =VLOOKUP(C28,'Tournament Information'!$F$7:$G$30,2) | F28: C5 | M28: =SUM(G28:L28) -> 0
C29: C6 | D29: =VLOOKUP(C29,'Tournament Information'!$F$7:$G$30,2) | F29: C6 | M29: =SUM(G29:L29) -> 0
L30: Division bonus: | M30: =0.0211*SUM(M24:M29) -> 0
C32: Diabetes | F32: Scores | G32: D1 | H32: D2 | I32: D3 | J32: D4 | K32: D5 | L32: D6 | M32: Total
C33: D1 | D33: =VLOOKUP(C33,'Tournament Information'!$F$7:$G$30,2) | F33: D1 | M33: =SUM(G33:L33) -> 0
C34: D2 | D34: =VLOOKUP(C34,'Tournament Information'!$F$7:$G$30,2) | F34: D2 | M34: =SUM(G34:L34) -> 0
C35: D3 | D35: =VLOOKUP(C35,'Tournament Information'!$F$7:$G$30,2) | F35: D3 | M35: =SUM(G35:L35) -> 0
C36: D4 | D36: =VLOOKUP(C36,'Tournament Information'!$F$7:$G$30,2) | F36: D4 | M36: =SUM(G36:L36) -> 0
C37: D5 | D37: =VLOOKUP(C37,'Tournament Information'!$F$7:$G$30,2) | F37: D5 | M37: =SUM(G37:L37) -> 0
C38: D6 | D38: =VLOOKUP(C38,'Tournament Information'!$F$7:$G$30,2) | F38: D6 | M38: =SUM(G38:L38) -> 0
L39: Division bonus: | M39: =0.0211*SUM(M33:M38) -> 0

Sheet RR Rankings (DE Seeds)
B2: RR Rankings
C5: Ranking | D5: Team | E5: Total Points | F5: Divisional Bonus | G5: Final RR Score
C6: 1 | D6: Evergreen | E6: =500+758 -> 1258 | F6: 51.906 | G6: =SUM(E6:F6) -> 1309.906
C7: =C6+1 -> 2 | D7: Hopkins A | E7: =400+588 -> 988 | F7: 40.2166 | G7: =5/4*SUM(E7:F7) -> 1285.2707
C8: =C7+1 -> 3 | D8: Liberty A | E8: =300+428 -> 728 | F8: 20.2982 | G8: =5/3*SUM(E8:F8) -> 1247.1637
C9: =C8+1 -> 4 | D9: Quail Valley | E9: =400+160+154+148+122+(50-28) -> 1006 | F9: 51.906 | G9: =SUM(E9:F9) -> 1057.906
C10: =C9+1 -> 5 | D10: BISV | E10: =400+100+172+104 -> 776 | F10: 40.2166 | G10: =5/4*SUM(E10:F10) -> 1020.2708
C11: =C10+1 -> 6 | D11: Oak Ave A | E11: =300+98+120+128+(50-48) -> 648 | F11: 42.3266 | G11: =5/4*SUM(E11:F11) -> 862.90825
C12: =C11+1 -> 7 | D12: Discovery | E12: =300+94+150+96 -> 640 | F12: 42.3266 | G12: =5/4*SUM(E12:F12) -> 852.90825
C13: =C12+1 -> 8 | D13: Horner | E13: 432 | F13: 20.2982 | G13: =5/3*SUM(E13:F13) -> 753.83033
C14: =C13+1 -> 9 | D14: Hopkins B | E14: 510 | F14: 42.3266 | G14: =5/4*SUM(E14:F14) -> 690.40825
C15: =C14+1 -> 10 | D15: ASFA | E15: 634 | F15: 51.906 | G15: =SUM(E15:F15) -> 685.906
C16: =C15+1 -> 11 | D16: Davidson | E16: 496 | F16: 40.2166 | G16: =5/4*SUM(E16:F16) -> 670.27075
C17: =C16+1 -> 12 | D17: Wayzata | E17: 338 | F17: 42.3266 | G17: =5/4*SUM(E17:F17) -> 475.40825
C18: =C17+1 -> 13 | D18: Hunter A | E18: 346 | F18: 51.906 | G18: =SUM(E18:F18) -> 397.906
C19: =C18+1 -> 14 | D19: Robert Frost | E19: 216 | F19: 20.2982 | G19: =5/3*SUM(E19:F19) -> 393.83033
C20: =C19+1 -> 15 | D20: Jeffrey Trail A | E20: 254 | F20: 42.3266 | G20: =5/4*SUM(E20:F20) -> 370.40825
C21: =C20+1 -> 16 | D21: Liberty B | E21: 172 | F21: 40.2166 | G21: =5/4*SUM(E21:F21) -> 265.27075
C22: =C21+1 -> 17 | D22: Telra | E22: 202 | F22: 51.906 | G22: =SUM(E22:F22) -> 253.906
C23: =C22+1 -> 18 | D23: Oak Ave B | E23: 48 | F23: 51.906 | G23: =SUM(E23:F23) -> 99.906
C24: =C23+1 -> 19 | D24: Frazer | E24: 36 | F24: 40.2166 | G24: =5/4*SUM(E24:F24) -> 95.27075
C25: =C24+1 -> 20 | D25: Hunter B | E25: 0 | F25: 20.2982 | G25: =5/3*SUM(E25:F25) -> 33.830333

Sheet DE Bracket
A1: DE Bracket
B2: DE1 | F2: DE2 | I2: DE3 | L2: DE4 | O2: DE5 | R2: DE6 | U2: DE7 | X2: DE8/9 | AA2: 1st place: | AB2: Evergreen
AA3: 2nd place: | AB3: Hopkins B
B4: 1 | C4: Evergreen | D4: 122 | AA4: 3rd place: | AB4: Hopkins A
B5: G1 (Ampere) | F5: Evergreen | G5: 132 | AA5: 4th place: | AB5: Davidson
B6: 16 | C6: Liberty B | D6: 36
F7: G9 (Ampere) | L7: Evergreen | M7: 102
B8: 4 | C8: Quail Valley | D8: 112
B9: G2 (Boltzmann) | F9: Hopkins B | G9: 62
B10: 13 | C10: Hunter A | D10: 24 | R10: Evergreen | S10: 50
L11: G21 (Ampere)
B12: 5 | C12: BISV | D12: 64
B13: G3 (Curie) | F13: Quail Valley | G13: 38
B14: 12 | C14: Wayzata | D14: 102
F15: G10 (Boltzmann) | L15: Wayzata | M15: 76
B16: 8 | C16: Horner | D16: 34
B17: G4 (Dirac) | F17: Wayzata | G17: 140
B18: 9 | C18: Hopkins B | D18: 60 | R18: G27 (Ampere) | X18: Evergreen | Y18: 8 | Z18: 64
B20: 7 | C20: Discovery | D20: 96
B21: G5 (Einstein) | F21: Davidson | G21: 116
B22: 10 | C22: ASFA | D22: 24
F23: G11 (Curie) | L23: Davidson | M23: 84
B24: 6 | C24: Oak Ave A | D24: 46
B25: G6 (Feynman) | F25: Liberty A | G25: 46
B26: 11 | C26: Davidson | D26: 92
L27: G22 (Boltzmann) | R27: Hopkins A | S27: 44 | X27: G30/31 (Solvay) | AB27: Winner: | AC27: Evergreen
B28: 14 | C28: Robert Frost | D28: 28
B29: G7 (Galileo) | F29: Discovery | G29: 76
B30: 3 | C30: Liberty A | D30: 102
F31: G12 (Dirac) | L31: Hopkins A | M31: 88
B32: 15 | C32: Jeffrey Trail A | D32: -14
B33: G8 (Heisenberg) | F33: Hopkins A | G33: 108
B34: 2 | C34: Hopkins A | D34: 162
O35: Davidson | P35: 60 | U35: Hopkins A | V35: 58
I36: Discovery | J36: 110
F37: Liberty B | G37: 48 | I37: G17 (Ampere) | L37: Discovery | M37: 20 | O37: G25 (Ampere) | R37: Davidson | S37: 40
F38: G13 (Einstein) | I38: Horner | J38: 36 | U38: G29 (Solvay) | X38: Hopkins B | Y38: 26 | Z38: 26
F39: Horner | G39: 52 | L39: G23 (Curie) | O39: BISV A | P39: 16
I40: Liberty A | J40: 72
F41: Hunter A | G41: 24 | I41: G18 (Boltzmann) | L41: BISV A | M41: 56 | R41: G28 (Boltzmann) | U41: Hopkins B | V41: 66
...
